File: data/beta_1-2-1_3.csv
SetName,Cycle,Time_S,Size_mm,Displacement_mm,Force_N,,Strain,Stress(Pascal),,%Strain,Stress(kPa),,,,Area(m^2)
Test1,1-Compress,0.000,6.011,-0,-0.004,,0,-50.9296,,0,-0.0509296,,,,7.85398e-5
Test1,1-Compress,0.367,5.969,0.042,0.003,,0.00698719,38.1972,,0.698719,0.0381972,,,,7.85398e-5
Test1,1-Compress,0.733,5.925,0.086,-0.004,,0.0143071,-50.9296,,1.43071,-0.0509296,,,,7.85398e-5
Test1,1-Compress,1.100,5.881,0.13,0.003,,0.021627,38.1972,,2.1627,0.0381972,,,,7.85398e-5
Test1,1-Compress,1.467,5.836,0.175,-0.004,,0.0291133,-50.9296,,2.91133,-0.0509296,,,,7.85398e-5
Test1,1-Compress,1.833,5.792,0.219,-0.004,,0.0364332,-50.9296,,3.64332,-0.0509296,,,,7.85398e-5
Test1,1-Compress,2.200,5.748,0.263,-0.004,,0.0437531,-50.9296,,4.37531,-0.0509296,,,,7.85398e-5
Test1,1-Compress,2.567,5.703,0.308,-0.004,,0.0512394,-50.9296,,5.12394,-0.0509296,,,,7.85398e-5
Test1,1-Compress,2.933,5.66,0.351,0.003,,0.0583929,38.1972,,5.83929,0.0381972,,,,7.85398e-5
Test1,1-Compress,3.300,5.616,0.395,0.010,,0.0657129,127.324,,6.57129,0.127324,,,,7.85398e-5
Test1,1-Compress,3.667,5.571,0.44,0.003,,0.0731991,38.1972,,7.31991,0.0381972,,,,7.85398e-5
Test1,1-Compress,4.033,5.528,0.483,-0.004,,0.0803527,-50.9296,,8.03527,-0.0509296,,,,7.85398e-5
Test1,1-Compress,4.400,5.483,0.528,-0.004,,0.087839,-50.9296,,8.7839,-0.0509296,,,,7.85398e-5
Test1,1-Compress,4.767,5.439,0.572,-0.004,,0.0951589,-50.9296,,9.51589,-0.0509296,,,,7.85398e-5
Test1,1-Compress,5.133,5.395,0.616,-0.004,,0.102479,-50.9296,,10.2479,-0.0509296,,,,7.85398e-5
Test1,1-Compress,5.500,5.351,0.66,0.003,,0.109799,38.1972,,10.9799,0.0381972,,,,7.85398e-5
Test1,1-Compress,5.867,5.306,0.705,0.003,,0.117285,38.1972,,11.7285,0.0381972,,,,7.85398e-5
Test1,1-Compress,6.233,5.263,0.748,-0.004,,0.124439,-50.9296,,12.4439,-0.0509296,,,,7.85398e-5
Test1,1-Compress,6.600,5.218,0.793,-0.004,,0.131925,-50.9296,,13.1925,-0.0509296,,,,7.85398e-5
Test1,1-Compress,6.967,5.174,0.837,-0.004,,0.139245,-50.9296,,13.9245,-0.0509296,,,,7.85398e-5
Test1,1-Compress,7.333,5.131,0.88,-0.004,,0.146398,-50.9296,,14.6398,-0.0509296,,,,7.85398e-5
Test1,1-Compress,7.700,5.086,0.925,0.003,,0.153885,38.1972,,15.3885,0.0381972,,,,7.85398e-5
Test1,1-Compress,8.067,5.041,0.97,0.003,,0.161371,38.1972,,16.1371,0.0381972,,,,7.85398e-5
Test1,1-Compress,8.433,4.998,1.013,0.010,,0.168524,127.324,,16.8524,0.127324,,,,7.85398e-5
Test1,1-Compress,8.800,4.953,1.058,0.003,,0.176011,38.1972,,17.6011,0.0381972,,,,7.85398e-5
Test1,1-Compress,9.167,4.909,1.102,-0.004,,0.183331,-50.9296,,18.3331,-0.0509296,,,,7.85398e-5
Test1,1-Compress,9.533,4.865,1.146,-0.004,,0.19065,-50.9296,,19.065,-0.0509296,,,,7.85398e-5
Test1,1-Compress,9.900,4.821,1.19,-0.004,,0.19797,-50.9296,,19.797,-0.0509296,,,,7.85398e-5
Test1,1-Compress,10.267,4.776,1.235,0.003,,0.205457,38.1972,,20.5457,0.0381972,,,,7.85398e-5
Test1,1-Compress,10.633,4.733,1.278,0.003,,0.21261,38.1972,,21.261,0.0381972,,,,7.85398e-5
Test1,1-Compress,11.000,4.688,1.323,0.010,,0.220096,127.324,,22.0096,0.127324,,,,7.85398e-5
Test1,1-Compress,11.367,4.644,1.367,0.003,,0.227416,38.1972,,22.7416,0.0381972,,,,7.85398e-5
Test1,1-Compress,11.733,4.601,1.41,-0.004,,0.23457,-50.9296,,23.457,-0.0509296,,,,7.85398e-5
Test1,1-Compress,12.100,4.556,1.455,-0.004,,0.242056,-50.9296,,24.2056,-0.0509296,,,,7.85398e-5
Test1,1-Compress,12.467,4.511,1.5,-0.004,,0.249543,-50.9296,,24.9543,-0.0509296,,,,7.85398e-5
Test1,1-Compress,12.833,4.468,1.543,0.003,,0.256696,38.1972,,25.6696,0.0381972,,,,7.85398e-5
Test1,1-Compress,13.200,4.423,1.588,0.010,,0.264182,127.324,,26.4182,0.127324,,,,7.85398e-5
Test1,1-Compress,13.567,4.379,1.632,0.003,,0.271502,38.1972,,27.1502,0.0381972,,,,7.85398e-5
Test1,1-Compress,13.933,4.336,1.675,-0.004,,0.278656,-50.9296,,27.8656,-0.0509296,,,,7.85398e-5
Test1,1-Compress,14.300,4.291,1.72,-0.004,,0.286142,-50.9296,,28.6142,-0.0509296,,,,7.85398e-5
Test1,1-Compress,14.667,4.246,1.765,-0.004,,0.293628,-50.9296,,29.3628,-0.0509296,,,,7.85398e-5
Test1,1-Compress,15.033,4.203,1.808,-0.004,,0.300782,-50.9296,,30.0782,-0.0509296,,,,7.85398e-5
Test1,1-Compress,15.400,4.158,1.853,0.003,,0.308268,38.1972,,30.8268,0.0381972,,,,7.85398e-5
Test1,1-Compress,15.767,4.114,1.897,0.010,,0.315588,127.324,,31.5588,0.127324,,,,7.85398e-5
Test1,1-Compress,16.133,4.071,1.94,0.003,,0.322742,38.1972,,32.2742,0.0381972,,,,7.85398e-5
Test1,1-Compress,16.500,4.026,1.985,-0.004,,0.330228,-50.9296,,33.0228,-0.0509296,,,,7.85398e-5
Test1,1-Compress,16.867,3.981,2.03,-0.004,,0.337714,-50.9296,,33.7714,-0.0509296,,,,7.85398e-5
Test1,1-Compress,17.233,3.938,2.073,-0.004,,0.344868,-50.9296,,34.4868,-0.0509296,,,,7.85398e-5
Test1,1-Compress,17.600,3.894,2.117,-0.004,,0.352188,-50.9296,,35.2188,-0.0509296,,,,7.85398e-5
Test1,1-Compress,17.967,3.849,2.162,0.003,,0.359674,38.1972,,35.9674,0.0381972,,,,7.85398e-5
Test1,1-Compress,18.333,3.806,2.205,0.010,,0.366827,127.324,,36.6827,0.127324,,,,7.85398e-5
Test1,1-Compress,18.700,3.761,2.25,0.010,,0.374314,127.324,,37.4314,0.127324,,,,7.85398e-5
Test1,1-Compress,19.067,3.716,2.295,-0.004,,0.3818,-50.9296,,38.18,-0.0509296,,,,7.85398e-5
Test1,1-Compress,19.433,3.673,2.338,-0.004,,0.388954,-50.9296,,38.8954,-0.0509296,,,,7.85398e-5
Test1,1-Compress,19.800,3.628,2.383,-0.004,,0.39644,-50.9296,,39.644,-0.0509296,,,,7.85398e-5
Test1,1-Compress,20.167,3.584,2.427,0.003,,0.40376,38.1972,,40.376,0.0381972,,,,7.85398e-5
Test1,1-Compress,20.533,3.541,2.47,0.003,,0.410913,38.1972,,41.0913,0.0381972,,,,7.85398e-5
Test1,1-Compress,20.900,3.496,2.515,0.010,,0.4184,127.324,,41.84,0.127324,,,,7.85398e-5
Test1,1-Compress,21.267,3.451,2.56,0.010,,0.425886,127.324,,42.5886,0.127324,,,,7.85398e-5
Test1,1-Compress,21.633,3.408,2.603,0.003,,0.433039,38.1972,,43.3039,0.0381972,,,,7.85398e-5
Test1,1-Compress,22.000,3.364,2.647,0.003,,0.440359,38.1972,,44.0359,0.0381972,,,,7.85398e-5
Test1,1-Compress,22.367,3.319,2.692,0.003,,0.447846,38.1972,,44.7846,0.0381972,,,,7.85398e-5
Test1,1-Compress,22.733,3.276,2.735,0.010,,0.454999,127.324,,45.4999,0.127324,,,,7.85398e-5
Test1,1-Compress,23.100,3.231,2.78,0.003,,0.462485,38.1972,,46.2485,0.0381972,,,,7.85398e-5
Test1,1-Compress,23.467,3.186,2.825,0.017,,0.469972,216.451,,46.9972,0.216451,,,,7.85398e-5
Test1,1-Compress,23.833,3.143,2.868,0.023,,0.477125,292.845,,47.7125,0.292845,,,,7.85398e-5
Test1,1-Compress,24.200,3.099,2.912,0.023,,0.484445,292.845,,48.4445,0.292845,,,,7.85398e-5
Test1,1-Compress,24.567,3.054,2.957,0.010,,0.491931,127.324,,49.1931,0.127324,,,,7.85398e-5
Test1,1-Compress,24.933,3.011,3,0.010,,0.499085,127.324,,49.9085,0.127324,,,,7.85398e-5
Test1,1-Compress,25.300,2.966,3.045,0.037,,0.506571,471.099,,50.6571,0.471099,,,,7.85398e-5
Test1,1-Compress,25.667,2.921,3.09,0.023,,0.514058,292.845,,51.4058,0.292845,,,,7.85398e-5
Test1,1-Compress,26.033,2.878,3.133,0.023,,0.521211,292.845,,52.1211,0.292845,,,,7.85398e-5
Test1,1-Compress,26.400,2.834,3.177,0.044,,0.528531,560.226,,52.8531,0.560226,,,,7.85398e-5
Test1,1-Compress,26.767,2.789,3.222,0.037,,0.536017,471.099,,53.6017,0.471099,,,,7.85398e-5
Test1,1-Compress,27.133,2.746,3.265,0.051,,0.543171,649.352,,54.3171,0.649352,,,,7.85398e-5
Test1,1-Compress,27.500,2.701,3.31,0.044,,0.550657,560.226,,55.0657,0.560226,,,,7.85398e-5
Test1,1-Compress,27.867,2.657,3.354,0.044,,0.557977,560.226,,55.7977,0.560226,,,,7.85398e-5
Test1,1-Compress,28.233,2.613,3.398,0.030,,0.565297,381.972,,56.5297,0.381972,,,,7.85398e-5
Test1,1-Compress,28.600,2.569,3.442,0.044,,0.572617,560.226,,57.2617,0.560226,,,,7.85398e-5
Test1,1-Compress,28.967,2.524,3.487,0.051,,0.580103,649.352,,58.0103,0.649352,,,,7.85398e-5
Test1,1-Compress,29.333,2.481,3.53,0.051,,0.587257,649.352,,58.7257,0.649352,,,,7.85398e-5
Test1,1-Compress,29.700,2.436,3.575,0.051,,0.594743,649.352,,59.4743,0.649352,,,,7.85398e-5
Test1,1-Recover,30.067,2.409,3.602,0.051,,0.599235,649.352,,59.9235,0.649352,,,,7.85398e-5
Test1,1-Recover,30.433,2.452,3.559,0.051,,0.592081,649.352,,59.2081,0.649352,,,,7.85398e-5
Test1,1-Recover,30.800,2.496,3.515,0.037,,0.584761,471.099,,58.4761,0.471099,,,,7.85398e-5
Test1,1-Recover,31.167,2.541,3.47,0.044,,0.577275,560.226,,57.7275,0.560226,,,,7.85398e-5
Test1,1-Recover,31.533,2.584,3.427,0.044,,0.570121,560.226,,57.0121,0.560226,,,,7.85398e-5
Test1,1-Recover,31.900,2.629,3.382,0.030,,0.562635,381.972,,56.2635,0.381972,,,,7.85398e-5
Test1,1-Recover,32.267,2.673,3.338,0.017,,0.555315,216.451,,55.5315,0.216451,,,,7.85398e-5
Test1,1-Recover,32.633,2.717,3.294,0.010,,0.547995,127.324,,54.7995,0.127324,,,,7.85398e-5
Test1,1-Recover,33.000,2.761,3.25,0.010,,0.540675,127.324,,54.0675,0.127324,,,,7.85398e-5
Test1,1-Recover,33.367,2.806,3.205,0.017,,0.533189,216.451,,53.3189,0.216451,,,,7.85398e-5
Test1,1-Recover,33.733,2.849,3.162,0.017,,0.526036,216.451,,52.6036,0.216451,,,,7.85398e-5
Test1,1-Recover,34.100,2.894,3.117,0.010,,0.518549,127.324,,51.8549,0.127324,,,,7.85398e-5
Test1,1-Recover,34.467,2.938,3.073,0.010,,0.511229,127.324,,51.1229,0.127324,,,,7.85398e-5
Test1,1-Recover,34.833,2.982,3.029,0.003,,0.503909,38.1972,,50.3909,0.0381972,,,,7.85398e-5
Test1,1-Recover,35.200,3.026,2.985,0.003,,0.49659,38.1972,,49.659,0.0381972,,,,7.85398e-5
Test1,1-Recover,35.567,3.071,2.94,0.003,,0.489103,38.1972,,48.9103,0.0381972,,,,7.85398e-5
Test1,1-Recover,35.933,3.114,2.897,0.010,,0.48195,127.324,,48.195,0.127324,,,,7.85398e-5
Test1,1-Recover,36.300,3.159,2.852,0.003,,0.474463,38.1972,,47.4463,0.0381972,,,,7.85398e-5
Test1,1-Recover,36.667,3.203,2.808,0.003,,0.467144,38.1972,,46.7144,0.0381972,,,,7.85398e-5
Test1,1-Recover,37.033,3.247,2.764,-0.004,,0.459824,-50.9296,,45.9824,-0.0509296,,,,7.85398e-5
Test1,1-Recover,37.400,3.291,2.72,0.003,,0.452504,38.1972,,45.2504,0.0381972,,,,7.85398e-5
Test1,1-Recover,37.767,3.336,2.675,0.003,,0.445017,38.1972,,44.5017,0.0381972,,,,7.85398e-5
Test1,1-Recover,38.133,3.379,2.632,0.003,,0.437864,38.1972,,43.7864,0.0381972,,,,7.85398e-5
Test1,1-Recover,38.500,3.424,2.587,0.010,,0.430378,127.324,,43.0378,0.127324,,,,7.85398e-5
Test1,1-Recover,38.867,3.468,2.543,0.003,,0.423058,38.1972,,42.3058,0.0381972,,,,7.85398e-5
Test1,1-Recover,39.233,3.512,2.499,-0.004,,0.415738,-50.9296,,41.5738,-0.0509296,,,,7.85398e-5
Test1,1-Recover,39.600,3.556,2.455,-0.004,,0.408418,-50.9296,,40.8418,-0.0509296,,,,7.85398e-5
Test1,1-Recover,39.967,3.601,2.41,-0.004,,0.400932,-50.9296,,40.0932,-0.0509296,,,,7.85398e-5
Test1,1-Recover,40.333,3.644,2.367,0.003,,0.393778,38.1972,,39.3778,0.0381972,,,,7.85398e-5
Test1,1-Recover,40.700,3.688,2.323,0.003,,0.386458,38.1972,,38.6458,0.0381972,,,,7.85398e-5
Test1,1-Recover,41.067,3.733,2.278,0.010,,0.378972,127.324,,37.8972,0.127324,,,,7.85398e-5
Test1,1-Recover,41.433,3.777,2.234,0.003,,0.371652,38.1972,,37.1652,0.0381972,,,,7.85398e-5
Test1,1-Recover,41.800,3.821,2.19,-0.004,,0.364332,-50.9296,,36.4332,-0.0509296,,,,7.85398e-5
Test1,1-Recover,42.167,3.866,2.145,-0.004,,0.356846,-50.9296,,35.6846,-0.0509296,,,,7.85398e-5
Test1,1-Recover,42.533,3.909,2.102,-0.004,,0.349692,-50.9296,,34.9692,-0.0509296,,,,7.85398e-5
Test1,1-Recover,42.900,3.954,2.057,0.003,,0.342206,38.1972,,34.2206,0.0381972,,,,7.85398e-5
Test1,1-Recover,43.267,3.998,2.013,0.003,,0.334886,38.1972,,33.4886,0.0381972,,,,7.85398e-5
Test1,1-Recover,43.633,4.042,1.969,0.010,,0.327566,127.324,,32.7566,0.127324,,,,7.85398e-5
Test1,1-Recover,44.000,4.086,1.925,-0.004,,0.320246,-50.9296,,32.0246,-0.0509296,,,,7.85398e-5
Test1,1-Recover,44.367,4.131,1.88,-0.004,,0.31276,-50.9296,,31.276,-0.0509296,,,,7.85398e-5
Test1,1-Recover,44.733,4.174,1.837,-0.004,,0.305606,-50.9296,,30.5606,-0.0509296,,,,7.85398e-5
Test1,1-Recover,45.100,4.218,1.793,-0.004,,0.298286,-50.9296,,29.8286,-0.0509296,,,,7.85398e-5
Test1,1-Recover,45.467,4.263,1.748,0.003,,0.2908,38.1972,,29.08,0.0381972,,,,7.85398e-5
Test1,1-Recover,45.833,4.307,1.704,0.003,,0.28348,38.1972,,28.348,0.0381972,,,,7.85398e-5
Test1,1-Recover,46.200,4.351,1.66,0.003,,0.27616,38.1972,,27.616,0.0381972,,,,7.85398e-5
Test1,1-Recover,46.567,4.396,1.615,-0.004,,0.268674,-50.9296,,26.8674,-0.0509296,,,,7.85398e-5
Test1,1-Recover,46.933,4.439,1.572,-0.004,,0.261521,-50.9296,,26.1521,-0.0509296,,,,7.85398e-5
Test1,1-Recover,47.300,4.484,1.527,-0.004,,0.254034,-50.9296,,25.4034,-0.0509296,,,,7.85398e-5
Test1,1-Recover,47.667,4.528,1.483,-0.004,,0.246714,-50.9296,,24.6714,-0.0509296,,,,7.85398e-5
Test1,1-Recover,48.033,4.571,1.44,0.003,,0.239561,38.1972,,23.9561,0.0381972,,,,7.85398e-5
Test1,1-Recover,48.400,4.616,1.395,0.003,,0.232075,38.1972,,23.2075,0.0381972,,,,7.85398e-5
Test1,1-Recover,48.767,4.661,1.35,0.003,,0.224588,38.1972,,22.4588,0.0381972,,,,7.85398e-5
Test1,1-Recover,49.133,4.704,1.307,-0.004,,0.217435,-50.9296,,21.7435,-0.0509296,,,,7.85398e-5
Test1,1-Recover,49.500,4.748,1.263,-0.004,,0.210115,-50.9296,,21.0115,-0.0509296,,,,7.85398e-5
Test1,1-Recover,49.867,4.793,1.218,-0.004,,0.202629,-50.9296,,20.2629,-0.0509296,,,,7.85398e-5
Test1,1-Recover,50.233,4.836,1.175,-0.004,,0.195475,-50.9296,,19.5475,-0.0509296,,,,7.85398e-5
Test1,1-Recover,50.600,4.881,1.13,0.003,,0.187989,38.1972,,18.7989,0.0381972,,,,7.85398e-5
Test1,1-Recover,50.967,4.925,1.086,0.010,,0.180669,127.324,,18.0669,0.127324,,,,7.85398e-5
Test1,1-Recover,51.333,4.969,1.042,0.003,,0.173349,38.1972,,17.3349,0.0381972,,,,7.85398e-5
Test1,1-Recover,51.700,5.013,0.998,-0.004,,0.166029,-50.9296,,16.6029,-0.0509296,,,,7.85398e-5
Test1,1-Recover,52.067,5.058,0.953,-0.004,,0.158543,-50.9296,,15.8543,-0.0509296,,,,7.85398e-5
Test1,1-Recover,52.433,5.101,0.91,-0.004,,0.151389,-50.9296,,15.1389,-0.0509296,,,,7.85398e-5
Test1,1-Recover,52.800,5.146,0.865,-0.004,,0.143903,-50.9296,,14.3903,-0.0509296,,,,7.85398e-5
Test1,1-Recover,53.167,5.191,0.82,0.003,,0.136417,38.1972,,13.6417,0.0381972,,,,7.85398e-5
Test1,1-Recover,53.533,5.234,0.777,0.003,,0.129263,38.1972,,12.9263,0.0381972,,,,7.85398e-5
Test1,1-Recover,53.900,5.278,0.733,-0.004,,0.121943,-50.9296,,12.1943,-0.0509296,,,,7.85398e-5
Test1,1-Recover,54.267,5.323,0.688,-0.004,,0.114457,-50.9296,,11.4457,-0.0509296,,,,7.85398e-5
Test1,1-Recover,54.633,5.366,0.645,-0.004,,0.107303,-50.9296,,10.7303,-0.0509296,,,,7.85398e-5
Test1,1-Recover,55.000,5.411,0.6,-0.004,,0.099817,-50.9296,,9.9817,-0.0509296,,,,7.85398e-5
Test1,1-Recover,55.367,5.455,0.556,-0.011,,0.0924971,-140.056,,9.24971,-0.140056,,,,7.85398e-5
Test1,1-Recover,55.733,5.499,0.512,-0.004,,0.0851772,-50.9296,,8.51772,-0.0509296,,,,7.85398e-5
Test1,1-Recover,56.100,5.543,0.468,-0.004,,0.0778573,-50.9296,,7.78573,-0.0509296,,,,7.85398e-5
Test1,1-Recover,56.467,5.588,0.423,-0.011,,0.070371,-140.056,,7.0371,-0.140056,,,,7.85398e-5
Test1,1-Recover,56.833,5.631,0.38,-0.004,,0.0632174,-50.9296,,6.32174,-0.0509296,,,,7.85398e-5
Test1,1-Recover,57.200,5.676,0.335,-0.004,,0.0557312,-50.9296,,5.57312,-0.0509296,,,,7.85398e-5
Test1,1-Recover,57.567,5.721,0.29,-0.011,,0.0482449,-140.056,,4.82449,-0.140056,,,,7.85398e-5
Test1,1-Recover,57.933,5.764,0.247,0.003,,0.0410913,38.1972,,4.10913,0.0381972,,,,7.85398e-5
Test1,1-Recover,58.300,5.808,0.203,-0.004,,0.0337714,-50.9296,,3.37714,-0.0509296,,,,7.85398e-5
Test1,1-Recover,58.667,5.853,0.158,0.003,,0.0262851,38.1972,,2.62851,0.0381972,,,,7.85398e-5
Test1,1-Recover,59.033,5.896,0.115,-0.004,,0.0191316,-50.9296,,1.91316,-0.0509296,,,,7.85398e-5
Test1,1-Recover,59.400,5.941,0.07,-0.004,,0.0116453,-50.9296,,1.16453,-0.0509296,,,,7.85398e-5
Test1,1-Recover,59.767,5.985,0.026,-0.004,,0.0043254,-50.9296,,0.43254,-0.0509296,,,,7.85398e-5
Test1,2-Compress,60.117,6.003,0.008,-0.004,,0.00133089,-50.9296,,0.133089,-0.0509296,,,,7.85398e-5
Test1,2-Compress,60.483,5.959,0.052,-0.004,,0.00865081,-50.9296,,0.865081,-0.0509296,,,,7.85398e-5
Test1,2-Compress,60.850,5.915,0.096,0.003,,0.0159707,38.1972,,1.59707,0.0381972,,,,7.85398e-5
Test1,2-Compress,61.217,5.87,0.141,0.003,,0.023457,38.1972,,2.3457,0.0381972,,,,7.85398e-5
Test1,2-Compress,61.583,5.827,0.184,-0.004,,0.0306105,-50.9296,,3.06105,-0.0509296,,,,7.85398e-5
Test1,2-Compress,61.950,5.783,0.228,-0.004,,0.0379305,-50.9296,,3.79305,-0.0509296,,,,7.85398e-5
Test1,2-Compress,62.317,5.738,0.273,-0.004,,0.0454167,-50.9296,,4.54167,-0.0509296,,,,7.85398e-5
Test1,2-Compress,62.683,5.695,0.316,-0.004,,0.0525703,-50.9296,,5.25703,-0.0509296,,,,7.85398e-5
Test1,2-Compress,63.050,5.65,0.361,-0.004,,0.0600566,-50.9296,,6.00566,-0.0509296,,,,7.85398e-5
Test1,2-Compress,63.417,5.606,0.405,0.003,,0.0673765,38.1972,,6.73765,0.0381972,,,,7.85398e-5
Test1,2-Compress,63.783,5.562,0.449,0.003,,0.0746964,38.1972,,7.46964,0.0381972,,,,7.85398e-5
Test1,2-Compress,64.150,5.518,0.493,0.003,,0.0820163,38.1972,,8.20163,0.0381972,,,,7.85398e-5
Test1,2-Compress,64.517,5.473,0.538,-0.004,,0.0895026,-50.9296,,8.95026,-0.0509296,,,,7.85398e-5
Test1,2-Compress,64.883,5.429,0.582,-0.004,,0.0968225,-50.9296,,9.68225,-0.0509296,,,,7.85398e-5
Test1,2-Compress,65.250,5.385,0.626,-0.004,,0.104142,-50.9296,,10.4142,-0.0509296,,,,7.85398e-5
Test1,2-Compress,65.617,5.34,0.671,-0.004,,0.111629,-50.9296,,11.1629,-0.0509296,,,,7.85398e-5
Test1,2-Compress,65.983,5.297,0.714,0.003,,0.118782,38.1972,,11.8782,0.0381972,,,,7.85398e-5
Test1,2-Compress,66.350,5.253,0.758,-0.004,,0.126102,-50.9296,,12.6102,-0.0509296,,,,7.85398e-5
Test1,2-Compress,66.717,5.208,0.803,0.003,,0.133588,38.1972,,13.3588,0.0381972,,,,7.85398e-5
Test1,2-Compress,67.083,5.165,0.846,-0.004,,0.140742,-50.9296,,14.0742,-0.0509296,,,,7.85398e-5
Test1,2-Compress,67.450,5.12,0.891,-0.004,,0.148228,-50.9296,,14.8228,-0.0509296,,,,7.85398e-5
Test1,2-Compress,67.817,5.076,0.935,-0.004,,0.155548,-50.9296,,15.5548,-0.0509296,,,,7.85398e-5
Test1,2-Compress,68.183,5.032,0.979,-0.004,,0.162868,-50.9296,,16.2868,-0.0509296,,,,7.85398e-5
Test1,2-Compress,68.550,4.988,1.023,0.003,,0.170188,38.1972,,17.0188,0.0381972,,,,7.85398e-5
Test1,2-Compress,68.917,4.943,1.068,0.003,,0.177674,38.1972,,17.7674,0.0381972,,,,7.85398e-5
Test1,2-Compress,69.283,4.9,1.111,-0.004,,0.184828,-50.9296,,18.4828,-0.0509296,,,,7.85398e-5
Test1,2-Compress,69.650,4.855,1.156,-0.004,,0.192314,-50.9296,,19.2314,-0.0509296,,,,7.85398e-5
Test1,2-Compress,70.017,4.81,1.201,-0.004,,0.1998,-50.9296,,19.98,-0.0509296,,,,7.85398e-5
Test1,2-Compress,70.383,4.767,1.244,-0.004,,0.206954,-50.9296,,20.6954,-0.0509296,,,,7.85398e-5
Test1,2-Compress,70.750,4.723,1.288,0.003,,0.214274,38.1972,,21.4274,0.0381972,,,,7.85398e-5
Test1,2-Compress,71.117,4.678,1.333,0.003,,0.22176,38.1972,,22.176,0.0381972,,,,7.85398e-5
Test1,2-Compress,71.483,4.635,1.376,0.010,,0.228914,127.324,,22.8914,0.127324,,,,7.85398e-5
Test1,2-Compress,71.850,4.59,1.421,-0.004,,0.2364,-50.9296,,23.64,-0.0509296,,,,7.85398e-5
Test1,2-Compress,72.217,4.546,1.465,-0.004,,0.24372,-50.9296,,24.372,-0.0509296,,,,7.85398e-5
Test1,2-Compress,72.583,4.502,1.509,-0.004,,0.25104,-50.9296,,25.104,-0.0509296,,,,7.85398e-5
Test1,2-Compress,72.950,4.458,1.553,-0.004,,0.25836,-50.9296,,25.836,-0.0509296,,,,7.85398e-5
Test1,2-Compress,73.317,4.413,1.598,0.003,,0.265846,38.1972,,26.5846,0.0381972,,,,7.85398e-5
Test1,2-Compress,73.683,4.37,1.641,0.003,,0.273,38.1972,,27.3,0.0381972,,,,7.85398e-5
Test1,2-Compress,74.050,4.325,1.686,0.003,,0.280486,38.1972,,28.0486,0.0381972,,,,7.85398e-5
Test1,2-Compress,74.417,4.281,1.73,-0.004,,0.287806,-50.9296,,28.7806,-0.0509296,,,,7.85398e-5
Test1,2-Compress,74.783,4.238,1.773,-0.004,,0.294959,-50.9296,,29.4959,-0.0509296,,,,7.85398e-5
Test1,2-Compress,75.150,4.193,1.818,-0.004,,0.302446,-50.9296,,30.2446,-0.0509296,,,,7.85398e-5
Test1,2-Compress,75.517,4.148,1.863,-0.004,,0.309932,-50.9296,,30.9932,-0.0509296,,,,7.85398e-5
Test1,2-Compress,75.883,4.105,1.906,0.003,,0.317085,38.1972,,31.7085,0.0381972,,,,7.85398e-5
Test1,2-Compress,76.250,4.06,1.951,0.010,,0.324572,127.324,,32.4572,0.127324,,,,7.85398e-5
Test1,2-Compress,76.617,4.016,1.995,0.003,,0.331892,38.1972,,33.1892,0.0381972,,,,7.85398e-5
Test1,2-Compress,76.983,3.972,2.039,-0.004,,0.339211,-50.9296,,33.9211,-0.0509296,,,,7.85398e-5
Test1,2-Compress,77.350,3.928,2.083,-0.004,,0.346531,-50.9296,,34.6531,-0.0509296,,,,7.85398e-5
Test1,2-Compress,77.717,3.883,2.128,0.003,,0.354018,38.1972,,35.4018,0.0381972,,,,7.85398e-5
Test1,2-Compress,78.083,3.84,2.171,-0.004,,0.361171,-50.9296,,36.1171,-0.0509296,,,,7.85398e-5
Test1,2-Compress,78.450,3.795,2.216,0.003,,0.368657,38.1972,,36.8657,0.0381972,,,,7.85398e-5
Test1,2-Compress,78.817,3.751,2.26,0.010,,0.375977,127.324,,37.5977,0.127324,,,,7.85398e-5
Test1,2-Compress,79.183,3.708,2.303,0.003,,0.383131,38.1972,,38.3131,0.0381972,,,,7.85398e-5
Test1,2-Compress,79.550,3.663,2.348,0.003,,0.390617,38.1972,,39.0617,0.0381972,,,,7.85398e-5
Test1,2-Compress,79.917,3.618,2.393,-0.004,,0.398103,-50.9296,,39.8103,-0.0509296,,,,7.85398e-5
Test1,2-Compress,80.283,3.575,2.436,-0.004,,0.405257,-50.9296,,40.5257,-0.0509296,,,,7.85398e-5
Test1,2-Compress,80.650,3.53,2.481,0.003,,0.412743,38.1972,,41.2743,0.0381972,,,,7.85398e-5
Test1,2-Compress,81.017,3.486,2.525,0.003,,0.420063,38.1972,,42.0063,0.0381972,,,,7.85398e-5
Test1,2-Compress,81.383,3.443,2.568,0.010,,0.427217,127.324,,42.7217,0.127324,,,,7.85398e-5
Test1,2-Compress,81.750,3.398,2.613,0.010,,0.434703,127.324,,43.4703,0.127324,,,,7.85398e-5
Test1,2-Compress,82.117,3.353,2.658,0.010,,0.442189,127.324,,44.2189,0.127324,,,,7.85398e-5
Test1,2-Compress,82.483,3.31,2.701,0.003,,0.449343,38.1972,,44.9343,0.0381972,,,,7.85398e-5
Test1,2-Compress,82.850,3.265,2.746,0.003,,0.456829,38.1972,,45.6829,0.0381972,,,,7.85398e-5
Test1,2-Compress,83.217,3.221,2.79,0.003,,0.464149,38.1972,,46.4149,0.0381972,,,,7.85398e-5
Test1,2-Compress,83.583,3.178,2.833,0.003,,0.471303,38.1972,,47.1303,0.0381972,,,,7.85398e-5
Test1,2-Compress,83.950,3.133,2.878,0.030,,0.478789,381.972,,47.8789,0.381972,,,,7.85398e-5
Test1,2-Compress,84.317,3.088,2.923,0.023,,0.486275,292.845,,48.6275,0.292845,,,,7.85398e-5
Test1,2-Compress,84.683,3.045,2.966,0.037,,0.493429,471.099,,49.3429,0.471099,,,,7.85398e-5
Test1,2-Compress,85.050,3.001,3.01,0.017,,0.500749,216.451,,50.0749,0.216451,,,,7.85398e-5
Test1,2-Compress,85.417,2.956,3.055,0.023,,0.508235,292.845,,50.8235,0.292845,,,,7.85398e-5
Test1,2-Compress,85.783,2.913,3.098,0.023,,0.515388,292.845,,51.5388,0.292845,,,,7.85398e-5
Test1,2-Compress,86.150,2.868,3.143,0.030,,0.522875,381.972,,52.2875,0.381972,,,,7.85398e-5
Test1,2-Compress,86.517,2.823,3.188,0.044,,0.530361,560.226,,53.0361,0.560226,,,,7.85398e-5
Test1,2-Compress,86.883,2.78,3.231,0.044,,0.537515,560.226,,53.7515,0.560226,,,,7.85398e-5
Test1,2-Compress,87.250,2.735,3.276,0.051,,0.545001,649.352,,54.5001,0.649352,,,,7.85398e-5
Test1,2-Compress,87.617,2.691,3.32,0.051,,0.552321,649.352,,55.2321,0.649352,,,,7.85398e-5
Test1,2-Compress,87.983,2.648,3.363,0.051,,0.559474,649.352,,55.9474,0.649352,,,,7.85398e-5
Test1,2-Compress,88.350,2.603,3.408,0.044,,0.566961,560.226,,56.6961,0.560226,,,,7.85398e-5
Test1,2-Compress,88.717,2.558,3.453,0.051,,0.574447,649.352,,57.4447,0.649352,,,,7.85398e-5
Test1,2-Compress,89.083,2.515,3.496,0.051,,0.5816,649.352,,58.16,0.649352,,,,7.85398e-5
Test1,2-Compress,89.450,2.471,3.54,0.051,,0.58892,649.352,,58.892,0.649352,,,,7.85398e-5
Test1,2-Compress,89.817,2.426,3.585,0.051,,0.596407,649.352,,59.6407,0.649352,,,,7.85398e-5
Test1,2-Recover,90.170,2.416,3.595,0.051,,0.59807,649.352,,59.807,0.649352,,,,7.85398e-5
Test1,2-Recover,90.537,2.46,3.551,0.051,,0.59075,649.352,,59.075,0.649352,,,,7.85398e-5
Test1,2-Recover,90.903,2.504,3.507,0.051,,0.58343,649.352,,58.343,0.649352,,,,7.85398e-5
Test1,2-Recover,91.270,2.548,3.463,0.044,,0.57611,560.226,,57.611,0.560226,,,,7.85398e-5
Test1,2-Recover,91.637,2.593,3.418,0.044,,0.568624,560.226,,56.8624,0.560226,,,,7.85398e-5
Test1,2-Recover,92.003,2.636,3.375,0.044,,0.561471,560.226,,56.1471,0.560226,,,,7.85398e-5
Test1,2-Recover,92.370,2.681,3.33,0.030,,0.553984,381.972,,55.3984,0.381972,,,,7.85398e-5
Test1,2-Recover,92.737,2.725,3.286,0.010,,0.546664,127.324,,54.6664,0.127324,,,,7.85398e-5
Test1,2-Recover,93.103,2.769,3.242,0.003,,0.539345,38.1972,,53.9345,0.0381972,,,,7.85398e-5
Test1,2-Recover,93.470,2.813,3.198,0.010,,0.532025,127.324,,53.2025,0.127324,,,,7.85398e-5
Test1,2-Recover,93.837,2.858,3.153,0.010,,0.524538,127.324,,52.4538,0.127324,,,,7.85398e-5
Test1,2-Recover,94.203,2.901,3.11,0.017,,0.517385,216.451,,51.7385,0.216451,,,,7.85398e-5
Test1,2-Recover,94.570,2.946,3.065,0.010,,0.509899,127.324,,50.9899,0.127324,,,,7.85398e-5
Test1,2-Recover,94.937,2.99,3.021,0.003,,0.502579,38.1972,,50.2579,0.0381972,,,,7.85398e-5
Test1,2-Recover,95.303,3.034,2.977,0.010,,0.495259,127.324,,49.5259,0.127324,,,,7.85398e-5
Test1,2-Recover,95.670,3.078,2.933,-0.004,,0.487939,-50.9296,,48.7939,-0.0509296,,,,7.85398e-5
Test1,2-Recover,96.037,3.123,2.888,0.003,,0.480453,38.1972,,48.0453,0.0381972,,,,7.85398e-5
Test1,2-Recover,96.403,3.166,2.845,0.010,,0.473299,127.324,,47.3299,0.127324,,,,7.85398e-5
Test1,2-Recover,96.770,3.211,2.8,0.010,,0.465813,127.324,,46.5813,0.127324,,,,7.85398e-5
Test1,2-Recover,97.137,3.255,2.756,0.003,,0.458493,38.1972,,45.8493,0.0381972,,,,7.85398e-5
Test1,2-Recover,97.503,3.299,2.712,0.003,,0.451173,38.1972,,45.1173,0.0381972,,,,7.85398e-5
Test1,2-Recover,97.870,3.343,2.668,-0.004,,0.443853,-50.9296,,44.3853,-0.0509296,,,,7.85398e-5
Test1,2-Recover,98.237,3.388,2.623,0.003,,0.436367,38.1972,,43.6367,0.0381972,,,,7.85398e-5
Test1,2-Recover,98.603,3.431,2.58,0.003,,0.429213,38.1972,,42.9213,0.0381972,,,,7.85398e-5
Test1,2-Recover,98.970,3.476,2.535,0.010,,0.421727,127.324,,42.1727,0.127324,,,,7.85398e-5
Test1,2-Recover,99.337,3.52,2.491,0.003,,0.414407,38.1972,,41.4407,0.0381972,,,,7.85398e-5
Test1,2-Recover,99.703,3.564,2.447,-0.004,,0.407087,-50.9296,,40.7087,-0.0509296,,,,7.85398e-5
Test1,2-Recover,100.070,3.608,2.403,-0.004,,0.399767,-50.9296,,39.9767,-0.0509296,,,,7.85398e-5
Test1,2-Recover,100.437,3.653,2.358,-0.004,,0.392281,-50.9296,,39.2281,-0.0509296,,,,7.85398e-5
Test1,2-Recover,100.803,3.696,2.315,-0.004,,0.385127,-50.9296,,38.5127,-0.0509296,,,,7.85398e-5
Test1,2-Recover,101.170,3.741,2.27,0.003,,0.377641,38.1972,,37.7641,0.0381972,,,,7.85398e-5
Test1,2-Recover,101.537,3.785,2.226,0.010,,0.370321,127.324,,37.0321,0.127324,,,,7.85398e-5
Test1,2-Recover,101.903,3.829,2.182,0.003,,0.363001,38.1972,,36.3001,0.0381972,,,,7.85398e-5
Test1,2-Recover,102.270,3.873,2.138,-0.004,,0.355681,-50.9296,,35.5681,-0.0509296,,,,7.85398e-5
Test1,2-Recover,102.637,3.918,2.093,-0.004,,0.348195,-50.9296,,34.8195,-0.0509296,,,,7.85398e-5
Test1,2-Recover,103.003,3.961,2.05,-0.004,,0.341041,-50.9296,,34.1041,-0.0509296,,,,7.85398e-5
Test1,2-Recover,103.370,4.006,2.005,0.003,,0.333555,38.1972,,33.3555,0.0381972,,,,7.85398e-5
Test1,2-Recover,103.737,4.05,1.961,0.010,,0.326235,127.324,,32.6235,0.127324,,,,7.85398e-5
Test1,2-Recover,104.103,4.094,1.917,0.010,,0.318915,127.324,,31.8915,0.127324,,,,7.85398e-5
Test1,2-Recover,104.470,4.138,1.873,0.003,,0.311595,38.1972,,31.1595,0.0381972,,,,7.85398e-5
Test1,2-Recover,104.837,4.183,1.828,-0.004,,0.304109,-50.9296,,30.4109,-0.0509296,,,,7.85398e-5
Test1,2-Recover,105.203,4.226,1.785,-0.004,,0.296956,-50.9296,,29.6956,-0.0509296,,,,7.85398e-5
Test1,2-Recover,105.570,4.271,1.74,-0.004,,0.289469,-50.9296,,28.9469,-0.0509296,,,,7.85398e-5
Test1,2-Recover,105.937,4.315,1.696,-0.004,,0.282149,-50.9296,,28.2149,-0.0509296,,,,7.85398e-5
Test1,2-Recover,106.303,4.358,1.653,0.003,,0.274996,38.1972,,27.4996,0.0381972,,,,7.85398e-5
Test1,2-Recover,106.670,4.403,1.608,0.010,,0.26751,127.324,,26.751,0.127324,,,,7.85398e-5
Test1,2-Recover,107.037,4.447,1.564,0.003,,0.26019,38.1972,,26.019,0.0381972,,,,7.85398e-5
Test1,2-Recover,107.403,4.491,1.52,-0.004,,0.25287,-50.9296,,25.287,-0.0509296,,,,7.85398e-5
Test1,2-Recover,107.770,4.536,1.475,-0.004,,0.245383,-50.9296,,24.5383,-0.0509296,,,,7.85398e-5
Test1,2-Recover,108.137,4.58,1.431,-0.004,,0.238064,-50.9296,,23.8064,-0.0509296,,,,7.85398e-5
Test1,2-Recover,108.503,4.624,1.387,0.003,,0.230744,38.1972,,23.0744,0.0381972,,,,7.85398e-5
Test1,2-Recover,108.870,4.668,1.343,0.003,,0.223424,38.1972,,22.3424,0.0381972,,,,7.85398e-5
Test1,2-Recover,109.237,4.713,1.298,0.003,,0.215937,38.1972,,21.5937,0.0381972,,,,7.85398e-5
Test1,2-Recover,109.603,4.756,1.255,0.003,,0.208784,38.1972,,20.8784,0.0381972,,,,7.85398e-5
Test1,2-Recover,109.970,4.801,1.21,-0.004,,0.201298,-50.9296,,20.1298,-0.0509296,,,,7.85398e-5
Test1,2-Recover,110.337,4.845,1.166,-0.004,,0.193978,-50.9296,,19.3978,-0.0509296,,,,7.85398e-5
Test1,2-Recover,110.703,4.888,1.123,-0.004,,0.186824,-50.9296,,18.6824,-0.0509296,,,,7.85398e-5
Test1,2-Recover,111.070,4.933,1.078,0.003,,0.179338,38.1972,,17.9338,0.0381972,,,,7.85398e-5
Test1,2-Recover,111.437,4.977,1.034,0.003,,0.172018,38.1972,,17.2018,0.0381972,,,,7.85398e-5
Test1,2-Recover,111.803,5.021,0.99,0.003,,0.164698,38.1972,,16.4698,0.0381972,,,,7.85398e-5
Test1,2-Recover,112.170,5.066,0.945,-0.004,,0.157212,-50.9296,,15.7212,-0.0509296,,,,7.85398e-5
Test1,2-Recover,112.537,5.11,0.901,-0.004,,0.149892,-50.9296,,14.9892,-0.0509296,,,,7.85398e-5
Test1,2-Recover,112.903,5.153,0.858,-0.004,,0.142738,-50.9296,,14.2738,-0.0509296,,,,7.85398e-5
Test1,2-Recover,113.270,5.198,0.813,-0.004,,0.135252,-50.9296,,13.5252,-0.0509296,,,,7.85398e-5
Test1,2-Recover,113.637,5.242,0.769,0.003,,0.127932,38.1972,,12.7932,0.0381972,,,,7.85398e-5
Test1,2-Recover,114.003,5.286,0.725,0.010,,0.120612,127.324,,12.0612,0.127324,,,,7.85398e-5
Test1,2-Recover,114.370,5.33,0.681,-0.004,,0.113292,-50.9296,,11.3292,-0.0509296,,,,7.85398e-5
Test1,2-Recover,114.737,5.375,0.636,-0.004,,0.105806,-50.9296,,10.5806,-0.0509296,,,,7.85398e-5
Test1,2-Recover,115.103,5.418,0.593,-0.004,,0.0986525,-50.9296,,9.86525,-0.0509296,,,,7.85398e-5
Test1,2-Recover,115.470,5.463,0.548,-0.004,,0.0911662,-50.9296,,9.11662,-0.0509296,,,,7.85398e-5
Test1,2-Recover,115.837,5.507,0.504,-0.004,,0.0838463,-50.9296,,8.38463,-0.0509296,,,,7.85398e-5
Test1,2-Recover,116.203,5.551,0.46,-0.004,,0.0765264,-50.9296,,7.65264,-0.0509296,,,,7.85398e-5
Test1,2-Recover,116.570,5.595,0.416,0.003,,0.0692065,38.1972,,6.92065,0.0381972,,,,7.85398e-5
Test1,2-Recover,116.937,5.64,0.371,0.003,,0.0617202,38.1972,,6.17202,0.0381972,,,,7.85398e-5
Test1,2-Recover,117.303,5.683,0.328,-0.004,,0.0545666,-50.9296,,5.45666,-0.0509296,,,,7.85398e-5
Test1,2-Recover,117.670,5.728,0.283,-0.004,,0.0470804,-50.9296,,4.70804,-0.0509296,,,,7.85398e-5
Test1,2-Recover,118.037,5.772,0.239,-0.004,,0.0397604,-50.9296,,3.97604,-0.0509296,,,,7.85398e-5
Test1,2-Recover,118.403,5.816,0.195,-0.004,,0.0324405,-50.9296,,3.24405,-0.0509296,,,,7.85398e-5
Test1,2-Recover,118.770,5.86,0.151,0.003,,0.0251206,38.1972,,2.51206,0.0381972,,,,7.85398e-5
Test1,2-Recover,119.137,5.905,0.106,0.003,,0.0176343,38.1972,,1.76343,0.0381972,,,,7.85398e-5
Test1,2-Recover,119.503,5.948,0.063,-0.004,,0.0104808,-50.9296,,1.04808,-0.0509296,,,,7.85398e-5
Test1,2-Recover,119.870,5.993,0.018,-0.004,,0.00299451,-50.9296,,0.299451,-0.0509296,,,,7.85398e-5
Test1,3-Compress,120.223,5.995,0.016,-0.004,,0.00266179,-50.9296,,0.266179,-0.0509296,,,,7.85398e-5
Test1,3-Compress,120.590,5.951,0.06,-0.004,,0.0099817,-50.9296,,0.99817,-0.0509296,,,,7.85398e-5
Test1,3-Compress,120.957,5.906,0.105,-0.004,,0.017468,-50.9296,,1.7468,-0.0509296,,,,7.85398e-5
Test1,3-Compress,121.323,5.863,0.148,0.003,,0.0246215,38.1972,,2.46215,0.0381972,,,,7.85398e-5
Test1,3-Compress,121.690,5.819,0.192,0.003,,0.0319414,38.1972,,3.19414,0.0381972,,,,7.85398e-5
Test1,3-Compress,122.057,5.774,0.237,-0.004,,0.0394277,-50.9296,,3.94277,-0.0509296,,,,7.85398e-5
Test1,3-Compress,122.423,5.73,0.281,-0.004,,0.0467476,-50.9296,,4.67476,-0.0509296,,,,7.85398e-5
Test1,3-Compress,122.790,5.686,0.325,-0.004,,0.0540675,-50.9296,,5.40675,-0.0509296,,,,7.85398e-5
Test1,3-Compress,123.157,5.641,0.37,-0.004,,0.0615538,-50.9296,,6.15538,-0.0509296,,,,7.85398e-5
Test1,3-Compress,123.523,5.598,0.413,-0.004,,0.0687074,-50.9296,,6.87074,-0.0509296,,,,7.85398e-5
Test1,3-Compress,123.890,5.554,0.457,0.003,,0.0760273,38.1972,,7.60273,0.0381972,,,,7.85398e-5
Test1,3-Compress,124.257,5.509,0.502,0.010,,0.0835136,127.324,,8.35136,0.127324,,,,7.85398e-5
Test1,3-Compress,124.623,5.465,0.546,0.003,,0.0908335,38.1972,,9.08335,0.0381972,,,,7.85398e-5
Test1,3-Compress,124.990,5.421,0.59,-0.004,,0.0981534,-50.9296,,9.81534,-0.0509296,,,,7.85398e-5
Test1,3-Compress,125.357,5.376,0.635,-0.004,,0.10564,-50.9296,,10.564,-0.0509296,,,,7.85398e-5
Test1,3-Compress,125.723,5.333,0.678,-0.004,,0.112793,-50.9296,,11.2793,-0.0509296,,,,7.85398e-5
Test1,3-Compress,126.090,5.289,0.722,0.003,,0.120113,38.1972,,12.0113,0.0381972,,,,7.85398e-5
Test1,3-Compress,126.457,5.244,0.767,0.003,,0.127599,38.1972,,12.7599,0.0381972,,,,7.85398e-5
Test1,3-Compress,126.823,5.2,0.811,0.003,,0.134919,38.1972,,13.4919,0.0381972,,,,7.85398e-5
Test1,3-Compress,127.190,5.156,0.855,0.003,,0.142239,38.1972,,14.2239,0.0381972,,,,7.85398e-5
Test1,3-Compress,127.557,5.111,0.9,-0.004,,0.149726,-50.9296,,14.9726,-0.0509296,,,,7.85398e-5
Test1,3-Compress,127.923,5.068,0.943,-0.004,,0.156879,-50.9296,,15.6879,-0.0509296,,,,7.85398e-5
Test1,3-Compress,128.290,5.024,0.987,-0.004,,0.164199,-50.9296,,16.4199,-0.0509296,,,,7.85398e-5
Test1,3-Compress,128.657,4.979,1.032,0.003,,0.171685,38.1972,,17.1685,0.0381972,,,,7.85398e-5
Test1,3-Compress,129.023,4.936,1.075,0.003,,0.178839,38.1972,,17.8839,0.0381972,,,,7.85398e-5
Test1,3-Compress,129.390,4.891,1.12,0.010,,0.186325,127.324,,18.6325,0.127324,,,,7.85398e-5
Test1,3-Compress,129.757,4.847,1.164,-0.004,,0.193645,-50.9296,,19.3645,-0.0509296,,,,7.85398e-5
Test1,3-Compress,130.123,4.803,1.208,-0.004,,0.200965,-50.9296,,20.0965,-0.0509296,,,,7.85398e-5
Test1,3-Compress,130.490,4.759,1.252,-0.004,,0.208285,-50.9296,,20.8285,-0.0509296,,,,7.85398e-5
Test1,3-Compress,130.857,4.714,1.297,-0.004,,0.215771,-50.9296,,21.5771,-0.0509296,,,,7.85398e-5
Test1,3-Compress,131.223,4.671,1.34,0.003,,0.222925,38.1972,,22.2925,0.0381972,,,,7.85398e-5
Test1,3-Compress,131.590,4.626,1.385,0.010,,0.230411,127.324,,23.0411,0.127324,,,,7.85398e-5
Test1,3-Compress,131.957,4.582,1.429,0.003,,0.237731,38.1972,,23.7731,0.0381972,,,,7.85398e-5
Test1,3-Compress,132.323,4.538,1.473,-0.004,,0.245051,-50.9296,,24.5051,-0.0509296,,,,7.85398e-5
Test1,3-Compress,132.690,4.494,1.517,-0.004,,0.252371,-50.9296,,25.2371,-0.0509296,,,,7.85398e-5
Test1,3-Compress,133.057,4.449,1.562,-0.004,,0.259857,-50.9296,,25.9857,-0.0509296,,,,7.85398e-5
Test1,3-Compress,133.423,4.406,1.605,-0.004,,0.26701,-50.9296,,26.701,-0.0509296,,,,7.85398e-5
Test1,3-Compress,133.790,4.361,1.65,0.003,,0.274497,38.1972,,27.4497,0.0381972,,,,7.85398e-5
Test1,3-Compress,134.157,4.317,1.694,0.010,,0.281817,127.324,,28.1817,0.127324,,,,7.85398e-5
Test1,3-Compress,134.523,4.273,1.738,0.010,,0.289137,127.324,,28.9137,0.127324,,,,7.85398e-5
Test1,3-Compress,134.890,4.229,1.782,-0.004,,0.296456,-50.9296,,29.6456,-0.0509296,,,,7.85398e-5
Test1,3-Compress,135.257,4.184,1.827,-0.004,,0.303943,-50.9296,,30.3943,-0.0509296,,,,7.85398e-5
Test1,3-Compress,135.623,4.141,1.87,-0.004,,0.311096,-50.9296,,31.1096,-0.0509296,,,,7.85398e-5
Test1,3-Compress,135.990,4.096,1.915,-0.004,,0.318583,-50.9296,,31.8583,-0.0509296,,,,7.85398e-5
Test1,3-Compress,136.357,4.052,1.959,0.003,,0.325903,38.1972,,32.5903,0.0381972,,,,7.85398e-5
Test1,3-Compress,136.723,4.009,2.002,0.010,,0.333056,127.324,,33.3056,0.127324,,,,7.85398e-5
Test1,3-Compress,137.090,3.964,2.047,0.003,,0.340542,38.1972,,34.0542,0.0381972,,,,7.85398e-5
Test1,3-Compress,137.457,3.919,2.092,-0.004,,0.348029,-50.9296,,34.8029,-0.0509296,,,,7.85398e-5
Test1,3-Compress,137.823,3.876,2.135,-0.004,,0.355182,-50.9296,,35.5182,-0.0509296,,,,7.85398e-5
Test1,3-Compress,138.190,3.831,2.18,-0.004,,0.362668,-50.9296,,36.2668,-0.0509296,,,,7.85398e-5
Test1,3-Compress,138.557,3.787,2.224,-0.004,,0.369988,-50.9296,,36.9988,-0.0509296,,,,7.85398e-5
Test1,3-Compress,138.923,3.743,2.268,0.003,,0.377308,38.1972,,37.7308,0.0381972,,,,7.85398e-5
Test1,3-Compress,139.290,3.699,2.312,0.010,,0.384628,127.324,,38.4628,0.127324,,,,7.85398e-5
Test1,3-Compress,139.657,3.654,2.357,0.010,,0.392114,127.324,,39.2114,0.127324,,,,7.85398e-5
Test1,3-Compress,140.023,3.611,2.4,-0.004,,0.399268,-50.9296,,39.9268,-0.0509296,,,,7.85398e-5
Test1,3-Compress,140.390,3.566,2.445,0.003,,0.406754,38.1972,,40.6754,0.0381972,,,,7.85398e-5
Test1,3-Compress,140.757,3.522,2.489,0.003,,0.414074,38.1972,,41.4074,0.0381972,,,,7.85398e-5
Test1,3-Compress,141.123,3.479,2.532,0.003,,0.421228,38.1972,,42.1228,0.0381972,,,,7.85398e-5
Test1,3-Compress,141.490,3.434,2.577,0.003,,0.428714,38.1972,,42.8714,0.0381972,,,,7.85398e-5
Test1,3-Compress,141.857,3.389,2.622,0.010,,0.4362,127.324,,43.62,0.127324,,,,7.85398e-5
Test1,3-Compress,142.223,3.346,2.665,0.017,,0.443354,216.451,,44.3354,0.216451,,,,7.85398e-5
Test1,3-Compress,142.590,3.301,2.71,0.010,,0.45084,127.324,,45.084,0.127324,,,,7.85398e-5
Test1,3-Compress,142.957,3.257,2.754,0.010,,0.45816,127.324,,45.816,0.127324,,,,7.85398e-5
Test1,3-Compress,143.323,3.214,2.797,0.010,,0.465314,127.324,,46.5314,0.127324,,,,7.85398e-5
Test1,3-Compress,143.690,3.169,2.842,0.023,,0.4728,292.845,,47.28,0.292845,,,,7.85398e-5
Test1,3-Compress,144.057,3.124,2.887,0.003,,0.480286,38.1972,,48.0286,0.0381972,,,,7.85398e-5
Test1,3-Compress,144.423,3.081,2.93,0.017,,0.48744,216.451,,48.744,0.216451,,,,7.85398e-5
Test1,3-Compress,144.790,3.036,2.975,0.037,,0.494926,471.099,,49.4926,0.471099,,,,7.85398e-5
Test1,3-Compress,145.157,2.992,3.019,0.030,,0.502246,381.972,,50.2246,0.381972,,,,7.85398e-5
Test1,3-Compress,145.523,2.949,3.062,0.023,,0.509399,292.845,,50.9399,0.292845,,,,7.85398e-5
Test1,3-Compress,145.890,2.904,3.107,0.037,,0.516886,471.099,,51.6886,0.471099,,,,7.85398e-5
Test1,3-Compress,146.257,2.859,3.152,0.023,,0.524372,292.845,,52.4372,0.292845,,,,7.85398e-5
Test1,3-Compress,146.623,2.816,3.195,0.010,,0.531526,127.324,,53.1526,0.127324,,,,7.85398e-5
Test1,3-Compress,146.990,2.772,3.239,0.044,,0.538845,560.226,,53.8845,0.560226,,,,7.85398e-5
Test1,3-Compress,147.357,2.727,3.284,0.044,,0.546332,560.226,,54.6332,0.560226,,,,7.85398e-5
Test1,3-Compress,147.723,2.684,3.327,0.051,,0.553485,649.352,,55.3485,0.649352,,,,7.85398e-5
Test1,3-Compress,148.090,2.639,3.372,0.051,,0.560972,649.352,,56.0972,0.649352,,,,7.85398e-5
Test1,3-Compress,148.457,2.594,3.417,0.051,,0.568458,649.352,,56.8458,0.649352,,,,7.85398e-5
Test1,3-Compress,148.823,2.551,3.46,0.051,,0.575611,649.352,,57.5611,0.649352,,,,7.85398e-5
Test1,3-Compress,149.190,2.506,3.505,0.051,,0.583098,649.352,,58.3098,0.649352,,,,7.85398e-5
Test1,3-Compress,149.557,2.462,3.549,0.051,,0.590418,649.352,,59.0418,0.649352,,,,7.85398e-5
Test1,3-Compress,149.923,2.419,3.592,0.051,,0.597571,649.352,,59.7571,0.649352,,,,7.85398e-5
Test1,3-Recover,150.267,2.423,3.588,0.051,,0.596906,649.352,,59.6906,0.649352,,,,7.85398e-5
Test1,3-Recover,150.633,2.467,3.544,0.051,,0.589586,649.352,,58.9586,0.649352,,,,7.85398e-5
Test1,3-Recover,151.000,2.511,3.5,0.051,,0.582266,649.352,,58.2266,0.649352,,,,7.85398e-5
Test1,3-Recover,151.367,2.556,3.455,0.051,,0.57478,649.352,,57.478,0.649352,,,,7.85398e-5
Test1,3-Recover,151.733,2.599,3.412,0.044,,0.567626,560.226,,56.7626,0.560226,,,,7.85398e-5
Test1,3-Recover,152.100,2.644,3.367,0.044,,0.56014,560.226,,56.014,0.560226,,,,7.85398e-5
Test1,3-Recover,152.467,2.688,3.323,0.037,,0.55282,471.099,,55.282,0.471099,,,,7.85398e-5
Test1,3-Recover,152.833,2.731,3.28,0.030,,0.545666,381.972,,54.5666,0.381972,,,,7.85398e-5
Test1,3-Recover,153.200,2.776,3.235,0.030,,0.53818,381.972,,53.818,0.381972,,,,7.85398e-5
Test1,3-Recover,153.567,2.821,3.19,0.010,,0.530694,127.324,,53.0694,0.127324,,,,7.85398e-5
Test1,3-Recover,153.933,2.864,3.147,0.010,,0.52354,127.324,,52.354,0.127324,,,,7.85398e-5
Test1,3-Recover,154.300,2.909,3.102,0.003,,0.516054,38.1972,,51.6054,0.0381972,,,,7.85398e-5
Test1,3-Recover,154.667,2.953,3.058,0.017,,0.508734,216.451,,50.8734,0.216451,,,,7.85398e-5
Test1,3-Recover,155.033,2.996,3.015,0.010,,0.50158,127.324,,50.158,0.127324,,,,7.85398e-5
Test1,3-Recover,155.400,3.041,2.97,0.010,,0.494094,127.324,,49.4094,0.127324,,,,7.85398e-5
Test1,3-Recover,155.767,3.086,2.925,0.003,,0.486608,38.1972,,48.6608,0.0381972,,,,7.85398e-5
Test1,3-Recover,156.133,3.129,2.882,0.003,,0.479454,38.1972,,47.9454,0.0381972,,,,7.85398e-5
Test1,3-Recover,156.500,3.174,2.837,0.003,,0.471968,38.1972,,47.1968,0.0381972,,,,7.85398e-5
Test1,3-Recover,156.867,3.218,2.793,0.010,,0.464648,127.324,,46.4648,0.127324,,,,7.85398e-5
Test1,3-Recover,157.233,3.261,2.75,0.017,,0.457495,216.451,,45.7495,0.216451,,,,7.85398e-5
Test1,3-Recover,157.600,3.306,2.705,0.003,,0.450008,38.1972,,45.0008,0.0381972,,,,7.85398e-5
Test1,3-Recover,157.967,3.35,2.661,-0.004,,0.442688,-50.9296,,44.2688,-0.0509296,,,,7.85398e-5
Test1,3-Recover,158.333,3.394,2.617,0.003,,0.435368,38.1972,,43.5368,0.0381972,,,,7.85398e-5
Test1,3-Recover,158.700,3.439,2.572,-0.004,,0.427882,-50.9296,,42.7882,-0.0509296,,,,7.85398e-5
Test1,3-Recover,159.067,3.483,2.528,0.003,,0.420562,38.1972,,42.0562,0.0381972,,,,7.85398e-5
Test1,3-Recover,159.433,3.526,2.485,0.003,,0.413409,38.1972,,41.3409,0.0381972,,,,7.85398e-5
Test1,3-Recover,159.800,3.571,2.44,0.010,,0.405922,127.324,,40.5922,0.127324,,,,7.85398e-5
Test1,3-Recover,160.167,3.615,2.396,0.003,,0.398603,38.1972,,39.8603,0.0381972,,,,7.85398e-5
Test1,3-Recover,160.533,3.659,2.352,0.003,,0.391283,38.1972,,39.1283,0.0381972,,,,7.85398e-5
Test1,3-Recover,160.900,3.704,2.307,-0.004,,0.383796,-50.9296,,38.3796,-0.0509296,,,,7.85398e-5
Test1,3-Recover,161.267,3.748,2.263,-0.004,,0.376476,-50.9296,,37.6476,-0.0509296,,,,7.85398e-5
Test1,3-Recover,161.633,3.791,2.22,0.003,,0.369323,38.1972,,36.9323,0.0381972,,,,7.85398e-5
Test1,3-Recover,162.000,3.836,2.175,0.010,,0.361837,127.324,,36.1837,0.127324,,,,7.85398e-5
Test1,3-Recover,162.367,3.88,2.131,0.003,,0.354517,38.1972,,35.4517,0.0381972,,,,7.85398e-5
Test1,3-Recover,162.733,3.924,2.087,-0.004,,0.347197,-50.9296,,34.7197,-0.0509296,,,,7.85398e-5
Test1,3-Recover,163.100,3.968,2.043,-0.004,,0.339877,-50.9296,,33.9877,-0.0509296,,,,7.85398e-5
Test1,3-Recover,163.467,4.013,1.998,-0.004,,0.332391,-50.9296,,33.2391,-0.0509296,,,,7.85398e-5
Test1,3-Recover,163.833,4.056,1.955,-0.004,,0.325237,-50.9296,,32.5237,-0.0509296,,,,7.85398e-5
Test1,3-Recover,164.200,4.101,1.91,0.003,,0.317751,38.1972,,31.7751,0.0381972,,,,7.85398e-5
Test1,3-Recover,164.567,4.145,1.866,0.010,,0.310431,127.324,,31.0431,0.127324,,,,7.85398e-5
Test1,3-Recover,164.933,4.189,1.822,0.010,,0.303111,127.324,,30.3111,0.127324,,,,7.85398e-5
Test1,3-Recover,165.300,4.233,1.778,-0.004,,0.295791,-50.9296,,29.5791,-0.0509296,,,,7.85398e-5
Test1,3-Recover,165.667,4.278,1.733,-0.004,,0.288305,-50.9296,,28.8305,-0.0509296,,,,7.85398e-5
Test1,3-Recover,166.033,4.321,1.69,-0.004,,0.281151,-50.9296,,28.1151,-0.0509296,,,,7.85398e-5
Test1,3-Recover,166.400,4.366,1.645,-0.004,,0.273665,-50.9296,,27.3665,-0.0509296,,,,7.85398e-5
Test1,3-Recover,166.767,4.41,1.601,0.003,,0.266345,38.1972,,26.6345,0.0381972,,,,7.85398e-5
Test1,3-Recover,167.133,4.454,1.557,0.003,,0.259025,38.1972,,25.9025,0.0381972,,,,7.85398e-5
Test1,3-Recover,167.500,4.498,1.513,0.003,,0.251705,38.1972,,25.1705,0.0381972,,,,7.85398e-5
Test1,3-Recover,167.867,4.543,1.468,-0.004,,0.244219,-50.9296,,24.4219,-0.0509296,,,,7.85398e-5
Test1,3-Recover,168.233,4.586,1.425,-0.004,,0.237065,-50.9296,,23.7065,-0.0509296,,,,7.85398e-5
Test1,3-Recover,168.600,4.631,1.38,-0.004,,0.229579,-50.9296,,22.9579,-0.0509296,,,,7.85398e-5
Test1,3-Recover,168.967,4.675,1.336,0.003,,0.222259,38.1972,,22.2259,0.0381972,,,,7.85398e-5
Test1,3-Recover,169.333,4.719,1.292,0.003,,0.214939,38.1972,,21.4939,0.0381972,,,,7.85398e-5
Test1,3-Recover,169.700,4.763,1.248,0.003,,0.207619,38.1972,,20.7619,0.0381972,,,,7.85398e-5
Test1,3-Recover,170.067,4.808,1.203,0.003,,0.200133,38.1972,,20.0133,0.0381972,,,,7.85398e-5
Test1,3-Recover,170.433,4.851,1.16,-0.004,,0.19298,-50.9296,,19.298,-0.0509296,,,,7.85398e-5
Test1,3-Recover,170.800,4.896,1.115,-0.004,,0.185493,-50.9296,,18.5493,-0.0509296,,,,7.85398e-5
Test1,3-Recover,171.167,4.94,1.071,-0.004,,0.178173,-50.9296,,17.8173,-0.0509296,,,,7.85398e-5
Test1,3-Recover,171.533,4.984,1.027,0.003,,0.170853,38.1972,,17.0853,0.0381972,,,,7.85398e-5
Test1,3-Recover,171.900,5.028,0.983,0.003,,0.163534,38.1972,,16.3534,0.0381972,,,,7.85398e-5
Test1,3-Recover,172.267,5.073,0.938,0.010,,0.156047,127.324,,15.6047,0.127324,,,,7.85398e-5
Test1,3-Recover,172.633,5.116,0.895,0.003,,0.148894,38.1972,,14.8894,0.0381972,,,,7.85398e-5
Test1,3-Recover,173.000,5.161,0.85,-0.004,,0.141407,-50.9296,,14.1407,-0.0509296,,,,7.85398e-5
Test1,3-Recover,173.367,5.205,0.806,-0.004,,0.134088,-50.9296,,13.4088,-0.0509296,,,,7.85398e-5
Test1,3-Recover,173.733,5.249,0.762,-0.004,,0.126768,-50.9296,,12.6768,-0.0509296,,,,7.85398e-5
Test1,3-Recover,174.100,5.293,0.718,0.003,,0.119448,38.1972,,11.9448,0.0381972,,,,7.85398e-5
Test1,3-Recover,174.467,5.338,0.673,0.003,,0.111961,38.1972,,11.1961,0.0381972,,,,7.85398e-5
Test1,3-Recover,174.833,5.381,0.63,0.003,,0.104808,38.1972,,10.4808,0.0381972,,,,7.85398e-5
Test1,3-Recover,175.200,5.426,0.585,-0.004,,0.0973216,-50.9296,,9.73216,-0.0509296,,,,7.85398e-5
Test1,3-Recover,175.567,5.47,0.541,-0.004,,0.0900017,-50.9296,,9.00017,-0.0509296,,,,7.85398e-5
Test1,3-Recover,175.933,5.514,0.497,-0.004,,0.0826818,-50.9296,,8.26818,-0.0509296,,,,7.85398e-5
Test1,3-Recover,176.300,5.558,0.453,-0.011,,0.0753618,-140.056,,7.53618,-0.140056,,,,7.85398e-5
Test1,3-Recover,176.667,5.603,0.408,0.003,,0.0678756,38.1972,,6.78756,0.0381972,,,,7.85398e-5
Test1,3-Recover,177.033,5.646,0.365,0.003,,0.060722,38.1972,,6.0722,0.0381972,,,,7.85398e-5
Test1,3-Recover,177.400,5.691,0.32,0.003,,0.0532357,38.1972,,5.32357,0.0381972,,,,7.85398e-5
Test1,3-Recover,177.767,5.735,0.276,-0.004,,0.0459158,-50.9296,,4.59158,-0.0509296,,,,7.85398e-5
Test1,3-Recover,178.133,5.779,0.232,-0.004,,0.0385959,-50.9296,,3.85959,-0.0509296,,,,7.85398e-5
Test1,3-Recover,178.500,5.823,0.188,-0.004,,0.031276,-50.9296,,3.1276,-0.0509296,,,,7.85398e-5
Test1,3-Recover,178.867,5.868,0.143,-0.004,,0.0237897,-50.9296,,2.37897,-0.0509296,,,,7.85398e-5
Test1,3-Recover,179.233,5.911,0.1,-0.011,,0.0166362,-140.056,,1.66362,-0.140056,,,,7.85398e-5
Test1,3-Recover,179.600,5.956,0.055,-0.004,,0.00914989,-50.9296,,0.914989,-0.0509296,,,,7.85398e-5
Test1,3-Recover,179.967,6,0.011,0.003,,0.00182998,38.1972,,0.182998,0.0381972,,,,7.85398e-5
Test1,3-Recover,180.100,6.011,-0,-0.004,,0,-50.9296,,0,-0.0509296,,,,7.85398e-5