File: data/beta_1-3-1_1.csv
SetName,Cycle,Time_S,Size_mm,Displacement_mm,Force_N,,Strain,Stress(Pascal),,%Strain,Stress(kPa),,,,Area(m^2)
Test1,1-Compress,0.000,6.744,-0,0.014,,0,178.254,,0,0.178254,,,,7.85398e-5
Test1,1-Compress,0.333,6.702,0.042,-0.007,,0.00622776,-89.1268,,0.622776,-0.0891268,,,,7.85398e-5
Test1,1-Compress,0.667,6.656,0.088,0.007,,0.0130486,89.1268,,1.30486,0.0891268,,,,7.85398e-5
Test1,1-Compress,1.000,6.611,0.133,0.007,,0.0197212,89.1268,,1.97212,0.0891268,,,,7.85398e-5
Test1,1-Compress,1.333,6.567,0.177,0.000,,0.0262456,0,,2.62456,0,,,,7.85398e-5
Test1,1-Compress,1.667,6.521,0.223,0.020,,0.0330664,254.648,,3.30664,0.254648,,,,7.85398e-5
Test1,1-Compress,2.000,6.476,0.268,-0.014,,0.039739,-178.254,,3.9739,-0.178254,,,,7.85398e-5
Test1,1-Compress,2.333,6.432,0.312,0.027,,0.0462633,343.775,,4.62633,0.343775,,,,7.85398e-5
Test1,1-Compress,2.667,6.386,0.358,-0.014,,0.0530842,-178.254,,5.30842,-0.178254,,,,7.85398e-5
Test1,1-Compress,3.000,6.341,0.403,0.007,,0.0597568,89.1268,,5.97568,0.0891268,,,,7.85398e-5
Test1,1-Compress,3.333,6.297,0.447,0.000,,0.0662811,0,,6.62811,0,,,,7.85398e-5
Test1,1-Compress,3.667,6.251,0.493,0.000,,0.073102,0,,7.3102,0,,,,7.85398e-5
Test1,1-Compress,4.000,6.206,0.538,0.007,,0.0797746,89.1268,,7.97746,0.0891268,,,,7.85398e-5
Test1,1-Compress,4.333,6.162,0.582,-0.007,,0.0862989,-89.1268,,8.62989,-0.0891268,,,,7.85398e-5
Test1,1-Compress,4.667,6.116,0.628,0.020,,0.0931198,254.648,,9.31198,0.254648,,,,7.85398e-5
Test1,1-Compress,5.000,6.071,0.673,-0.007,,0.0997924,-89.1268,,9.97924,-0.0891268,,,,7.85398e-5
Test1,1-Compress,5.333,6.026,0.718,0.007,,0.106465,89.1268,,10.6465,0.0891268,,,,7.85398e-5
Test1,1-Compress,5.667,5.981,0.763,0.007,,0.113138,89.1268,,11.3138,0.0891268,,,,7.85398e-5
Test1,1-Compress,6.000,5.936,0.808,0.007,,0.11981,89.1268,,11.981,0.0891268,,,,7.85398e-5
Test1,1-Compress,6.333,5.891,0.853,0.007,,0.126483,89.1268,,12.6483,0.0891268,,,,7.85398e-5
Test1,1-Compress,6.667,5.846,0.898,0.007,,0.133155,89.1268,,13.3155,0.0891268,,,,7.85398e-5
Test1,1-Compress,7.000,5.801,0.943,0.007,,0.139828,89.1268,,13.9828,0.0891268,,,,7.85398e-5
Test1,1-Compress,7.333,5.756,0.988,0.000,,0.146501,0,,14.6501,0,,,,7.85398e-5
Test1,1-Compress,7.667,5.71,1.034,0.007,,0.153321,89.1268,,15.3321,0.0891268,,,,7.85398e-5
Test1,1-Compress,8.000,5.666,1.078,-0.007,,0.159846,-89.1268,,15.9846,-0.0891268,,,,7.85398e-5
Test1,1-Compress,8.333,5.621,1.123,-0.007,,0.166518,-89.1268,,16.6518,-0.0891268,,,,7.85398e-5
Test1,1-Compress,8.667,5.575,1.169,0.000,,0.173339,0,,17.3339,0,,,,7.85398e-5
Test1,1-Compress,9.000,5.531,1.213,-0.007,,0.179864,-89.1268,,17.9864,-0.0891268,,,,7.85398e-5
Test1,1-Compress,9.333,5.486,1.258,0.000,,0.186536,0,,18.6536,0,,,,7.85398e-5
Test1,1-Compress,9.667,5.44,1.304,-0.014,,0.193357,-178.254,,19.3357,-0.178254,,,,7.85398e-5
Test1,1-Compress,10.000,5.396,1.348,0.000,,0.199881,0,,19.9881,0,,,,7.85398e-5
Test1,1-Compress,10.333,5.351,1.393,-0.014,,0.206554,-178.254,,20.6554,-0.178254,,,,7.85398e-5
Test1,1-Compress,10.667,5.305,1.439,-0.007,,0.213375,-89.1268,,21.3375,-0.0891268,,,,7.85398e-5
Test1,1-Compress,11.000,5.261,1.483,-0.014,,0.219899,-178.254,,21.9899,-0.178254,,,,7.85398e-5
Test1,1-Compress,11.333,5.216,1.528,-0.014,,0.226572,-178.254,,22.6572,-0.178254,,,,7.85398e-5
Test1,1-Compress,11.667,5.17,1.574,-0.007,,0.233393,-89.1268,,23.3393,-0.0891268,,,,7.85398e-5
Test1,1-Compress,12.000,5.126,1.618,-0.014,,0.239917,-178.254,,23.9917,-0.178254,,,,7.85398e-5
Test1,1-Compress,12.333,5.081,1.663,0.014,,0.24659,178.254,,24.659,0.178254,,,,7.85398e-5
Test1,1-Compress,12.667,5.035,1.709,-0.007,,0.25341,-89.1268,,25.341,-0.0891268,,,,7.85398e-5
Test1,1-Compress,13.000,4.99,1.754,0.014,,0.260083,178.254,,26.0083,0.178254,,,,7.85398e-5
Test1,1-Compress,13.333,4.946,1.798,0.000,,0.266607,0,,26.6607,0,,,,7.85398e-5
Test1,1-Compress,13.667,4.9,1.844,0.020,,0.273428,254.648,,27.3428,0.254648,,,,7.85398e-5
Test1,1-Compress,14.000,4.855,1.889,0.014,,0.280101,178.254,,28.0101,0.178254,,,,7.85398e-5
Test1,1-Compress,14.333,4.811,1.933,0.000,,0.286625,0,,28.6625,0,,,,7.85398e-5
Test1,1-Compress,14.667,4.765,1.979,0.014,,0.293446,178.254,,29.3446,0.178254,,,,7.85398e-5
Test1,1-Compress,15.000,4.72,2.024,0.000,,0.300119,0,,30.0119,0,,,,7.85398e-5
Test1,1-Compress,15.333,4.675,2.069,0.027,,0.306791,343.775,,30.6791,0.343775,,,,7.85398e-5
Test1,1-Compress,15.667,4.63,2.114,0.000,,0.313464,0,,31.3464,0,,,,7.85398e-5
Test1,1-Compress,16.000,4.585,2.159,0.020,,0.320136,254.648,,32.0136,0.254648,,,,7.85398e-5
Test1,1-Compress,16.333,4.54,2.204,-0.007,,0.326809,-89.1268,,32.6809,-0.0891268,,,,7.85398e-5
Test1,1-Compress,16.667,4.495,2.249,0.014,,0.333482,178.254,,33.3482,0.178254,,,,7.85398e-5
Test1,1-Compress,17.000,4.45,2.294,0.000,,0.340154,0,,34.0154,0,,,,7.85398e-5
Test1,1-Compress,17.333,4.406,2.338,0.000,,0.346679,0,,34.6679,0,,,,7.85398e-5
Test1,1-Compress,17.667,4.359,2.385,0.020,,0.353648,254.648,,35.3648,0.254648,,,,7.85398e-5
Test1,1-Compress,18.000,4.315,2.429,-0.014,,0.360172,-178.254,,36.0172,-0.178254,,,,7.85398e-5
Test1,1-Compress,18.333,4.27,2.474,0.007,,0.366845,89.1268,,36.6845,0.0891268,,,,7.85398e-5
Test1,1-Compress,18.667,4.224,2.52,-0.014,,0.373665,-178.254,,37.3665,-0.178254,,,,7.85398e-5
Test1,1-Compress,19.000,4.18,2.564,0.014,,0.38019,178.254,,38.019,0.178254,,,,7.85398e-5
Test1,1-Compress,19.333,4.135,2.609,-0.007,,0.386862,-89.1268,,38.6862,-0.0891268,,,,7.85398e-5
Test1,1-Compress,19.667,4.089,2.655,-0.007,,0.393683,-89.1268,,39.3683,-0.0891268,,,,7.85398e-5
Test1,1-Compress,20.000,4.045,2.699,0.000,,0.400208,0,,40.0208,0,,,,7.85398e-5
Test1,1-Compress,20.333,4,2.744,-0.007,,0.40688,-89.1268,,40.688,-0.0891268,,,,7.85398e-5
Test1,1-Compress,20.667,3.954,2.79,0.020,,0.413701,254.648,,41.3701,0.254648,,,,7.85398e-5
Test1,1-Compress,21.000,3.91,2.834,0.014,,0.420225,178.254,,42.0225,0.178254,,,,7.85398e-5
Test1,1-Compress,21.333,3.865,2.879,0.007,,0.426898,89.1268,,42.6898,0.0891268,,,,7.85398e-5
Test1,1-Compress,21.667,3.819,2.925,0.020,,0.433719,254.648,,43.3719,0.254648,,,,7.85398e-5
Test1,1-Compress,22.000,3.775,2.969,0.020,,0.440243,254.648,,44.0243,0.254648,,,,7.85398e-5
Test1,1-Compress,22.333,3.73,3.014,0.020,,0.446916,254.648,,44.6916,0.254648,,,,7.85398e-5
Test1,1-Compress,22.667,3.684,3.06,0.014,,0.453737,178.254,,45.3737,0.178254,,,,7.85398e-5
Test1,1-Compress,23.000,3.64,3.104,0.020,,0.460261,254.648,,46.0261,0.254648,,,,7.85398e-5
Test1,1-Compress,23.333,3.595,3.149,0.020,,0.466934,254.648,,46.6934,0.254648,,,,7.85398e-5
Test1,1-Compress,23.667,3.549,3.195,0.020,,0.473754,254.648,,47.3754,0.254648,,,,7.85398e-5
Test1,1-Compress,24.000,3.504,3.24,0.027,,0.480427,343.775,,48.0427,0.343775,,,,7.85398e-5
Test1,1-Compress,24.333,3.46,3.284,0.020,,0.486951,254.648,,48.6951,0.254648,,,,7.85398e-5
Test1,1-Compress,24.667,3.414,3.33,0.020,,0.493772,254.648,,49.3772,0.254648,,,,7.85398e-5
Test1,1-Compress,25.000,3.369,3.375,0.034,,0.500445,432.902,,50.0445,0.432902,,,,7.85398e-5
Test1,1-Compress,25.333,3.325,3.419,0.027,,0.506969,343.775,,50.6969,0.343775,,,,7.85398e-5
Test1,1-Compress,25.667,3.279,3.465,0.034,,0.51379,432.902,,51.379,0.432902,,,,7.85398e-5
Test1,1-Compress,26.000,3.234,3.51,0.034,,0.520463,432.902,,52.0463,0.432902,,,,7.85398e-5
Test1,1-Compress,26.333,3.19,3.554,0.034,,0.526987,432.902,,52.6987,0.432902,,,,7.85398e-5
Test1,1-Compress,26.667,3.144,3.6,0.034,,0.533808,432.902,,53.3808,0.432902,,,,7.85398e-5
Test1,1-Compress,27.000,3.099,3.645,0.034,,0.54048,432.902,,54.048,0.432902,,,,7.85398e-5
Test1,1-Compress,27.333,3.054,3.69,0.034,,0.547153,432.902,,54.7153,0.432902,,,,7.85398e-5
Test1,1-Compress,27.667,3.009,3.735,0.034,,0.553826,432.902,,55.3826,0.432902,,,,7.85398e-5
Test1,1-Compress,28.000,2.964,3.78,0.041,,0.560498,522.028,,56.0498,0.522028,,,,7.85398e-5
Test1,1-Compress,28.333,2.92,3.824,0.041,,0.567023,522.028,,56.7023,0.522028,,,,7.85398e-5
Test1,1-Compress,28.667,2.874,3.87,0.048,,0.573843,611.155,,57.3843,0.611155,,,,7.85398e-5
Test1,1-Compress,29.000,2.829,3.915,0.048,,0.580516,611.155,,58.0516,0.611155,,,,7.85398e-5
Test1,1-Compress,29.333,2.785,3.959,0.048,,0.58704,611.155,,58.704,0.611155,,,,7.85398e-5
Test1,1-Compress,29.667,2.738,4.006,0.048,,0.594009,611.155,,59.4009,0.611155,,,,7.85398e-5
Test1,1-Compress,30.000,2.698,4.046,0.048,,0.599941,611.155,,59.9941,0.611155,,,,7.85398e-5
Test1,1-Recover,30.333,2.738,4.006,0.048,,0.594009,611.155,,59.4009,0.611155,,,,7.85398e-5
Test1,1-Recover,30.667,2.784,3.96,0.041,,0.587189,522.028,,58.7189,0.522028,,,,7.85398e-5
Test1,1-Recover,31.000,2.828,3.916,0.041,,0.580664,522.028,,58.0664,0.522028,,,,7.85398e-5
Test1,1-Recover,31.333,2.873,3.871,0.034,,0.573992,432.902,,57.3992,0.432902,,,,7.85398e-5
Test1,1-Recover,31.667,2.919,3.825,0.034,,0.567171,432.902,,56.7171,0.432902,,,,7.85398e-5
Test1,1-Recover,32.000,2.964,3.78,0.034,,0.560498,432.902,,56.0498,0.432902,,,,7.85398e-5
Test1,1-Recover,32.333,3.008,3.736,0.027,,0.553974,343.775,,55.3974,0.343775,,,,7.85398e-5
Test1,1-Recover,32.667,3.054,3.69,0.027,,0.547153,343.775,,54.7153,0.343775,,,,7.85398e-5
Test1,1-Recover,33.000,3.099,3.645,0.020,,0.54048,254.648,,54.048,0.254648,,,,7.85398e-5
Test1,1-Recover,33.333,3.143,3.601,0.027,,0.533956,343.775,,53.3956,0.343775,,,,7.85398e-5
Test1,1-Recover,33.667,3.189,3.555,0.014,,0.527135,178.254,,52.7135,0.178254,,,,7.85398e-5
Test1,1-Recover,34.000,3.234,3.51,0.020,,0.520463,254.648,,52.0463,0.254648,,,,7.85398e-5
Test1,1-Recover,34.333,3.278,3.466,0.014,,0.513938,178.254,,51.3938,0.178254,,,,7.85398e-5
Test1,1-Recover,34.667,3.324,3.42,0.000,,0.507117,0,,50.7117,0,,,,7.85398e-5
Test1,1-Recover,35.000,3.369,3.375,0.020,,0.500445,254.648,,50.0445,0.254648,,,,7.85398e-5
Test1,1-Recover,35.333,3.414,3.33,0.000,,0.493772,0,,49.3772,0,,,,7.85398e-5
Test1,1-Recover,35.667,3.459,3.285,0.000,,0.4871,0,,48.71,0,,,,7.85398e-5
Test1,1-Recover,36.000,3.504,3.24,-0.014,,0.480427,-178.254,,48.0427,-0.178254,,,,7.85398e-5
Test1,1-Recover,36.333,3.548,3.196,-0.007,,0.473903,-89.1268,,47.3903,-0.0891268,,,,7.85398e-5
Test1,1-Recover,36.667,3.594,3.15,0.007,,0.467082,89.1268,,46.7082,0.0891268,,,,7.85398e-5
Test1,1-Recover,37.000,3.639,3.105,0.007,,0.460409,89.1268,,46.0409,0.0891268,,,,7.85398e-5
Test1,1-Recover,37.333,3.684,3.06,0.000,,0.453737,0,,45.3737,0,,,,7.85398e-5
Test1,1-Recover,37.667,3.73,3.014,0.014,,0.446916,178.254,,44.6916,0.178254,,,,7.85398e-5
Test1,1-Recover,38.000,3.774,2.97,0.014,,0.440391,178.254,,44.0391,0.178254,,,,7.85398e-5
Test1,1-Recover,38.333,3.819,2.925,0.020,,0.433719,254.648,,43.3719,0.254648,,,,7.85398e-5
Test1,1-Recover,38.667,3.865,2.879,0.014,,0.426898,178.254,,42.6898,0.178254,,,,7.85398e-5
Test1,1-Recover,39.000,3.909,2.835,0.007,,0.420374,89.1268,,42.0374,0.0891268,,,,7.85398e-5
Test1,1-Recover,39.333,3.954,2.79,0.000,,0.413701,0,,41.3701,0,,,,7.85398e-5
Test1,1-Recover,39.667,4,2.744,0.007,,0.40688,89.1268,,40.688,0.0891268,,,,7.85398e-5
Test1,1-Recover,40.000,4.044,2.7,0.000,,0.400356,0,,40.0356,0,,,,7.85398e-5
Test1,1-Recover,40.333,4.089,2.655,0.014,,0.393683,178.254,,39.3683,0.178254,,,,7.85398e-5
Test1,1-Recover,40.667,4.135,2.609,0.000,,0.386862,0,,38.6862,0,,,,7.85398e-5
Test1,1-Recover,41.000,4.179,2.565,0.014,,0.380338,178.254,,38.0338,0.178254,,,,7.85398e-5
Test1,1-Recover,41.333,4.224,2.52,-0.007,,0.373665,-89.1268,,37.3665,-0.0891268,,,,7.85398e-5
Test1,1-Recover,41.667,4.27,2.474,0.000,,0.366845,0,,36.6845,0,,,,7.85398e-5
Test1,1-Recover,42.000,4.314,2.43,0.007,,0.36032,89.1268,,36.032,0.0891268,,,,7.85398e-5
Test1,1-Recover,42.333,4.359,2.385,-0.014,,0.353648,-178.254,,35.3648,-0.178254,,,,7.85398e-5
Test1,1-Recover,42.667,4.405,2.339,0.020,,0.346827,254.648,,34.6827,0.254648,,,,7.85398e-5
Test1,1-Recover,43.000,4.45,2.294,-0.014,,0.340154,-178.254,,34.0154,-0.178254,,,,7.85398e-5
Test1,1-Recover,43.333,4.494,2.25,0.014,,0.33363,178.254,,33.363,0.178254,,,,7.85398e-5
Test1,1-Recover,43.667,4.54,2.204,-0.007,,0.326809,-89.1268,,32.6809,-0.0891268,,,,7.85398e-5
Test1,1-Recover,44.000,4.585,2.159,0.014,,0.320136,178.254,,32.0136,0.178254,,,,7.85398e-5
Test1,1-Recover,44.333,4.629,2.115,-0.007,,0.313612,-89.1268,,31.3612,-0.0891268,,,,7.85398e-5
Test1,1-Recover,44.667,4.675,2.069,-0.007,,0.306791,-89.1268,,30.6791,-0.0891268,,,,7.85398e-5
Test1,1-Recover,45.000,4.72,2.024,0.014,,0.300119,178.254,,30.0119,0.178254,,,,7.85398e-5
Test1,1-Recover,45.333,4.764,1.98,0.000,,0.293594,0,,29.3594,0,,,,7.85398e-5
Test1,1-Recover,45.667,4.81,1.934,0.014,,0.286773,178.254,,28.6773,0.178254,,,,7.85398e-5
Test1,1-Recover,46.000,4.855,1.889,0.007,,0.280101,89.1268,,28.0101,0.0891268,,,,7.85398e-5
Test1,1-Recover,46.333,4.9,1.844,0.014,,0.273428,178.254,,27.3428,0.178254,,,,7.85398e-5
Test1,1-Recover,46.667,4.945,1.799,-0.007,,0.266756,-89.1268,,26.6756,-0.0891268,,,,7.85398e-5
Test1,1-Recover,47.000,4.99,1.754,-0.014,,0.260083,-178.254,,26.0083,-0.178254,,,,7.85398e-5
Test1,1-Recover,47.333,5.034,1.71,0.000,,0.253559,0,,25.3559,0,,,,7.85398e-5
Test1,1-Recover,47.667,5.08,1.664,-0.014,,0.246738,-178.254,,24.6738,-0.178254,,,,7.85398e-5
Test1,1-Recover,48.000,5.125,1.619,0.007,,0.240065,89.1268,,24.0065,0.0891268,,,,7.85398e-5
Test1,1-Recover,48.333,5.169,1.575,-0.007,,0.233541,-89.1268,,23.3541,-0.0891268,,,,7.85398e-5
Test1,1-Recover,48.667,5.216,1.528,0.000,,0.226572,0,,22.6572,0,,,,7.85398e-5
Test1,1-Recover,49.000,5.26,1.484,0.007,,0.220047,89.1268,,22.0047,0.0891268,,,,7.85398e-5
Test1,1-Recover,49.333,5.305,1.439,0.007,,0.213375,89.1268,,21.3375,0.0891268,,,,7.85398e-5
Test1,1-Recover,49.667,5.351,1.393,0.007,,0.206554,89.1268,,20.6554,0.0891268,,,,7.85398e-5
Test1,1-Recover,50.000,5.395,1.349,-0.007,,0.20003,-89.1268,,20.003,-0.0891268,,,,7.85398e-5
Test1,1-Recover,50.333,5.44,1.304,0.014,,0.193357,178.254,,19.3357,0.178254,,,,7.85398e-5
Test1,1-Recover,50.667,5.486,1.258,-0.007,,0.186536,-89.1268,,18.6536,-0.0891268,,,,7.85398e-5
Test1,1-Recover,51.000,5.53,1.214,0.027,,0.180012,343.775,,18.0012,0.343775,,,,7.85398e-5
Test1,1-Recover,51.333,5.575,1.169,-0.014,,0.173339,-178.254,,17.3339,-0.178254,,,,7.85398e-5
Test1,1-Recover,51.667,5.621,1.123,0.034,,0.166518,432.902,,16.6518,0.432902,,,,7.85398e-5
Test1,1-Recover,52.000,5.665,1.079,0.027,,0.159994,343.775,,15.9994,0.343775,,,,7.85398e-5
Test1,1-Recover,52.333,5.71,1.034,0.007,,0.153321,89.1268,,15.3321,0.0891268,,,,7.85398e-5
Test1,1-Recover,52.667,5.756,0.988,0.020,,0.146501,254.648,,14.6501,0.254648,,,,7.85398e-5
Test1,1-Recover,53.000,5.8,0.944,0.020,,0.139976,254.648,,13.9976,0.254648,,,,7.85398e-5
Test1,1-Recover,53.333,5.845,0.899,0.020,,0.133304,254.648,,13.3304,0.254648,,,,7.85398e-5
Test1,1-Recover,53.667,5.891,0.853,-0.007,,0.126483,-89.1268,,12.6483,-0.0891268,,,,7.85398e-5
Test1,1-Recover,54.000,5.936,0.808,0.014,,0.11981,178.254,,11.981,0.178254,,,,7.85398e-5
Test1,1-Recover,54.333,5.98,0.764,-0.007,,0.113286,-89.1268,,11.3286,-0.0891268,,,,7.85398e-5
Test1,1-Recover,54.667,6.026,0.718,0.014,,0.106465,178.254,,10.6465,0.178254,,,,7.85398e-5
Test1,1-Recover,55.000,6.071,0.673,0.000,,0.0997924,0,,9.97924,0,,,,7.85398e-5
Test1,1-Recover,55.333,6.115,0.629,0.000,,0.0932681,0,,9.32681,0,,,,7.85398e-5
Test1,1-Recover,55.667,6.161,0.583,0.000,,0.0864472,0,,8.64472,0,,,,7.85398e-5
Test1,1-Recover,56.000,6.206,0.538,0.000,,0.0797746,0,,7.97746,0,,,,7.85398e-5
Test1,1-Recover,56.333,6.25,0.494,0.007,,0.0732503,89.1268,,7.32503,0.0891268,,,,7.85398e-5
Test1,1-Recover,56.667,6.296,0.448,0.000,,0.0664294,0,,6.64294,0,,,,7.85398e-5
Test1,1-Recover,57.000,6.341,0.403,0.020,,0.0597568,254.648,,5.97568,0.254648,,,,7.85398e-5
Test1,1-Recover,57.333,6.386,0.358,-0.014,,0.0530842,-178.254,,5.30842,-0.178254,,,,7.85398e-5
Test1,1-Recover,57.667,6.431,0.313,0.020,,0.0464116,254.648,,4.64116,0.254648,,,,7.85398e-5
Test1,1-Recover,58.000,6.476,0.268,-0.007,,0.039739,-89.1268,,3.9739,-0.0891268,,,,7.85398e-5
Test1,1-Recover,58.333,6.52,0.224,0.014,,0.0332147,178.254,,3.32147,0.178254,,,,7.85398e-5
Test1,1-Recover,58.667,6.566,0.178,0.020,,0.0263938,254.648,,2.63938,0.254648,,,,7.85398e-5
Test1,1-Recover,59.000,6.611,0.133,0.000,,0.0197212,0,,1.97212,0,,,,7.85398e-5
Test1,1-Recover,59.333,6.655,0.089,0.034,,0.0131969,432.902,,1.31969,0.432902,,,,7.85398e-5
Test1,1-Recover,59.667,6.702,0.042,0.000,,0.00622776,0,,0.622776,0,,,,7.85398e-5
Test1,1-Recover,60.000,6.744,-0,0.034,,0,432.902,,0,0.432902,,,,7.85398e-5
Test1,2-Compress,60.317,6.708,0.036,0.034,,0.00533808,432.902,,0.533808,0.432902,,,,7.85398e-5
Test1,2-Compress,60.650,6.663,0.081,-0.014,,0.0120107,-178.254,,1.20107,-0.178254,,,,7.85398e-5
Test1,2-Compress,60.983,6.619,0.125,0.034,,0.018535,432.902,,1.8535,0.432902,,,,7.85398e-5
Test1,2-Compress,61.317,6.573,0.171,0.000,,0.0253559,0,,2.53559,0,,,,7.85398e-5
Test1,2-Compress,61.650,6.528,0.216,0.027,,0.0320285,343.775,,3.20285,0.343775,,,,7.85398e-5
Test1,2-Compress,61.983,6.484,0.26,-0.007,,0.0385528,-89.1268,,3.85528,-0.0891268,,,,7.85398e-5
Test1,2-Compress,62.317,6.438,0.306,0.007,,0.0453737,89.1268,,4.53737,0.0891268,,,,7.85398e-5
Test1,2-Compress,62.650,6.393,0.351,0.007,,0.0520463,89.1268,,5.20463,0.0891268,,,,7.85398e-5
Test1,2-Compress,62.983,6.349,0.395,0.007,,0.0585706,89.1268,,5.85706,0.0891268,,,,7.85398e-5
Test1,2-Compress,63.317,6.303,0.441,0.007,,0.0653915,89.1268,,6.53915,0.0891268,,,,7.85398e-5
Test1,2-Compress,63.650,6.258,0.486,-0.007,,0.0720641,-89.1268,,7.20641,-0.0891268,,,,7.85398e-5
Test1,2-Compress,63.983,6.214,0.53,0.007,,0.0785884,89.1268,,7.85884,0.0891268,,,,7.85398e-5
Test1,2-Compress,64.317,6.167,0.577,-0.007,,0.0855575,-89.1268,,8.55575,-0.0891268,,,,7.85398e-5
Test1,2-Compress,64.650,6.123,0.621,0.000,,0.0920819,0,,9.20819,0,,,,7.85398e-5
Test1,2-Compress,64.983,6.078,0.666,0.000,,0.0987544,0,,9.87544,0,,,,7.85398e-5
Test1,2-Compress,65.317,6.032,0.712,-0.007,,0.105575,-89.1268,,10.5575,-0.0891268,,,,7.85398e-5
Test1,2-Compress,65.650,5.988,0.756,0.014,,0.1121,178.254,,11.21,0.178254,,,,7.85398e-5
Test1,2-Compress,65.983,5.943,0.801,-0.014,,0.118772,-178.254,,11.8772,-0.178254,,,,7.85398e-5
Test1,2-Compress,66.317,5.897,0.847,0.020,,0.125593,254.648,,12.5593,0.254648,,,,7.85398e-5
Test1,2-Compress,66.650,5.853,0.891,-0.007,,0.132117,-89.1268,,13.2117,-0.0891268,,,,7.85398e-5
Test1,2-Compress,66.983,5.808,0.936,0.014,,0.13879,178.254,,13.879,0.178254,,,,7.85398e-5
Test1,2-Compress,67.317,5.762,0.982,0.007,,0.145611,89.1268,,14.5611,0.0891268,,,,7.85398e-5
Test1,2-Compress,67.650,5.718,1.026,0.007,,0.152135,89.1268,,15.2135,0.0891268,,,,7.85398e-5
Test1,2-Compress,67.983,5.673,1.071,0.000,,0.158808,0,,15.8808,0,,,,7.85398e-5
Test1,2-Compress,68.317,5.627,1.117,-0.014,,0.165629,-178.254,,16.5629,-0.178254,,,,7.85398e-5
Test1,2-Compress,68.650,5.583,1.161,0.014,,0.172153,178.254,,17.2153,0.178254,,,,7.85398e-5
Test1,2-Compress,68.983,5.538,1.206,-0.007,,0.178826,-89.1268,,17.8826,-0.0891268,,,,7.85398e-5
Test1,2-Compress,69.317,5.492,1.252,0.014,,0.185647,178.254,,18.5647,0.178254,,,,7.85398e-5
Test1,2-Compress,69.650,5.447,1.297,0.007,,0.192319,89.1268,,19.2319,0.0891268,,,,7.85398e-5
Test1,2-Compress,69.983,5.403,1.341,0.007,,0.198843,89.1268,,19.8843,0.0891268,,,,7.85398e-5
Test1,2-Compress,70.317,5.357,1.387,0.000,,0.205664,0,,20.5664,0,,,,7.85398e-5
Test1,2-Compress,70.650,5.312,1.432,0.007,,0.212337,89.1268,,21.2337,0.0891268,,,,7.85398e-5
Test1,2-Compress,70.983,5.268,1.476,0.020,,0.218861,254.648,,21.8861,0.254648,,,,7.85398e-5
Test1,2-Compress,71.317,5.222,1.522,-0.007,,0.225682,-89.1268,,22.5682,-0.0891268,,,,7.85398e-5
Test1,2-Compress,71.650,5.177,1.567,0.007,,0.232355,89.1268,,23.2355,0.0891268,,,,7.85398e-5
Test1,2-Compress,71.983,5.132,1.612,-0.007,,0.239027,-89.1268,,23.9027,-0.0891268,,,,7.85398e-5
Test1,2-Compress,72.317,5.087,1.657,0.007,,0.2457,89.1268,,24.57,0.0891268,,,,7.85398e-5
Test1,2-Compress,72.650,5.042,1.702,0.000,,0.252372,0,,25.2372,0,,,,7.85398e-5
Test1,2-Compress,72.983,4.998,1.746,0.007,,0.258897,89.1268,,25.8897,0.0891268,,,,7.85398e-5
Test1,2-Compress,73.317,4.952,1.792,0.000,,0.265718,0,,26.5718,0,,,,7.85398e-5
Test1,2-Compress,73.650,4.907,1.837,-0.014,,0.27239,-178.254,,27.239,-0.178254,,,,7.85398e-5
Test1,2-Compress,73.983,4.863,1.881,-0.007,,0.278915,-89.1268,,27.8915,-0.0891268,,,,7.85398e-5
Test1,2-Compress,74.317,4.817,1.927,-0.014,,0.285735,-178.254,,28.5735,-0.178254,,,,7.85398e-5
Test1,2-Compress,74.650,4.772,1.972,0.007,,0.292408,89.1268,,29.2408,0.0891268,,,,7.85398e-5
Test1,2-Compress,74.983,4.727,2.017,-0.014,,0.299081,-178.254,,29.9081,-0.178254,,,,7.85398e-5
Test1,2-Compress,75.317,4.682,2.062,0.020,,0.305753,254.648,,30.5753,0.254648,,,,7.85398e-5
Test1,2-Compress,75.650,4.637,2.107,-0.007,,0.312426,-89.1268,,31.2426,-0.0891268,,,,7.85398e-5
Test1,2-Compress,75.983,4.592,2.152,0.000,,0.319098,0,,31.9098,0,,,,7.85398e-5
Test1,2-Compress,76.317,4.546,2.198,-0.014,,0.325919,-178.254,,32.5919,-0.178254,,,,7.85398e-5
Test1,2-Compress,76.650,4.502,2.242,-0.014,,0.332444,-178.254,,33.2444,-0.178254,,,,7.85398e-5
Test1,2-Compress,76.983,4.457,2.287,-0.007,,0.339116,-89.1268,,33.9116,-0.0891268,,,,7.85398e-5
Test1,2-Compress,77.317,4.411,2.333,0.007,,0.345937,89.1268,,34.5937,0.0891268,,,,7.85398e-5
Test1,2-Compress,77.650,4.367,2.377,0.007,,0.352461,89.1268,,35.2461,0.0891268,,,,7.85398e-5
Test1,2-Compress,77.983,4.322,2.422,0.007,,0.359134,89.1268,,35.9134,0.0891268,,,,7.85398e-5
Test1,2-Compress,78.317,4.276,2.468,0.020,,0.365955,254.648,,36.5955,0.254648,,,,7.85398e-5
Test1,2-Compress,78.650,4.232,2.512,0.007,,0.372479,89.1268,,37.2479,0.0891268,,,,7.85398e-5
Test1,2-Compress,78.983,4.187,2.557,0.020,,0.379152,254.648,,37.9152,0.254648,,,,7.85398e-5
Test1,2-Compress,79.317,4.141,2.603,0.020,,0.385973,254.648,,38.5973,0.254648,,,,7.85398e-5
Test1,2-Compress,79.650,4.097,2.647,0.014,,0.392497,178.254,,39.2497,0.178254,,,,7.85398e-5
Test1,2-Compress,79.983,4.052,2.692,0.020,,0.39917,254.648,,39.917,0.254648,,,,7.85398e-5
Test1,2-Compress,80.317,4.006,2.738,0.007,,0.405991,89.1268,,40.5991,0.0891268,,,,7.85398e-5
Test1,2-Compress,80.650,3.962,2.782,0.014,,0.412515,178.254,,41.2515,0.178254,,,,7.85398e-5
Test1,2-Compress,80.983,3.917,2.827,0.007,,0.419187,89.1268,,41.9187,0.0891268,,,,7.85398e-5
Test1,2-Compress,81.317,3.871,2.873,0.007,,0.426008,89.1268,,42.6008,0.0891268,,,,7.85398e-5
Test1,2-Compress,81.650,3.826,2.918,0.000,,0.432681,0,,43.2681,0,,,,7.85398e-5
Test1,2-Compress,81.983,3.782,2.962,0.007,,0.439205,89.1268,,43.9205,0.0891268,,,,7.85398e-5
Test1,2-Compress,82.317,3.736,3.008,0.027,,0.446026,343.775,,44.6026,0.343775,,,,7.85398e-5
Test1,2-Compress,82.650,3.691,3.053,0.000,,0.452699,0,,45.2699,0,,,,7.85398e-5
Test1,2-Compress,82.983,3.647,3.097,0.007,,0.459223,89.1268,,45.9223,0.0891268,,,,7.85398e-5
Test1,2-Compress,83.317,3.601,3.143,0.027,,0.466044,343.775,,46.6044,0.343775,,,,7.85398e-5
Test1,2-Compress,83.650,3.556,3.188,0.027,,0.472716,343.775,,47.2716,0.343775,,,,7.85398e-5
Test1,2-Compress,83.983,3.512,3.232,-0.007,,0.479241,-89.1268,,47.9241,-0.0891268,,,,7.85398e-5
Test1,2-Compress,84.317,3.466,3.278,0.020,,0.486062,254.648,,48.6062,0.254648,,,,7.85398e-5
Test1,2-Compress,84.650,3.421,3.323,0.034,,0.492734,432.902,,49.2734,0.432902,,,,7.85398e-5
Test1,2-Compress,84.983,3.377,3.367,0.020,,0.499259,254.648,,49.9259,0.254648,,,,7.85398e-5
Test1,2-Compress,85.317,3.331,3.413,0.034,,0.506079,432.902,,50.6079,0.432902,,,,7.85398e-5
Test1,2-Compress,85.650,3.286,3.458,0.041,,0.512752,522.028,,51.2752,0.522028,,,,7.85398e-5
Test1,2-Compress,85.983,3.242,3.502,0.034,,0.519276,432.902,,51.9276,0.432902,,,,7.85398e-5
Test1,2-Compress,86.317,3.195,3.549,0.041,,0.526246,522.028,,52.6246,0.522028,,,,7.85398e-5
Test1,2-Compress,86.650,3.151,3.593,0.048,,0.53277,611.155,,53.277,0.611155,,,,7.85398e-5
Test1,2-Compress,86.983,3.106,3.638,0.041,,0.539442,522.028,,53.9442,0.522028,,,,7.85398e-5
Test1,2-Compress,87.317,3.06,3.684,0.041,,0.546263,522.028,,54.6263,0.522028,,,,7.85398e-5
Test1,2-Compress,87.650,3.016,3.728,0.034,,0.552788,432.902,,55.2788,0.432902,,,,7.85398e-5
Test1,2-Compress,87.983,2.971,3.773,0.034,,0.55946,432.902,,55.946,0.432902,,,,7.85398e-5
Test1,2-Compress,88.317,2.925,3.819,0.034,,0.566281,432.902,,56.6281,0.432902,,,,7.85398e-5
Test1,2-Compress,88.650,2.881,3.863,0.034,,0.572805,432.902,,57.2805,0.432902,,,,7.85398e-5
Test1,2-Compress,88.983,2.836,3.908,0.034,,0.579478,432.902,,57.9478,0.432902,,,,7.85398e-5
Test1,2-Compress,89.317,2.79,3.954,0.034,,0.586299,432.902,,58.6299,0.432902,,,,7.85398e-5
Test1,2-Compress,89.650,2.746,3.998,0.034,,0.592823,432.902,,59.2823,0.432902,,,,7.85398e-5
Test1,2-Compress,89.983,2.701,4.043,0.041,,0.599496,522.028,,59.9496,0.522028,,,,7.85398e-5
Test1,2-Recover,90.303,2.729,4.015,0.034,,0.595344,432.902,,59.5344,0.432902,,,,7.85398e-5
Test1,2-Recover,90.637,2.775,3.969,0.034,,0.588523,432.902,,58.8523,0.432902,,,,7.85398e-5
Test1,2-Recover,90.970,2.819,3.925,0.034,,0.581999,432.902,,58.1999,0.432902,,,,7.85398e-5
Test1,2-Recover,91.303,2.864,3.88,0.034,,0.575326,432.902,,57.5326,0.432902,,,,7.85398e-5
Test1,2-Recover,91.637,2.91,3.834,0.034,,0.568505,432.902,,56.8505,0.432902,,,,7.85398e-5
Test1,2-Recover,91.970,2.954,3.79,0.034,,0.561981,432.902,,56.1981,0.432902,,,,7.85398e-5
Test1,2-Recover,92.303,2.999,3.745,0.027,,0.555308,343.775,,55.5308,0.343775,,,,7.85398e-5
Test1,2-Recover,92.637,3.045,3.699,0.041,,0.548488,522.028,,54.8488,0.522028,,,,7.85398e-5
Test1,2-Recover,92.970,3.089,3.655,0.041,,0.541963,522.028,,54.1963,0.522028,,,,7.85398e-5
Test1,2-Recover,93.303,3.134,3.61,0.034,,0.535291,432.902,,53.5291,0.432902,,,,7.85398e-5
Test1,2-Recover,93.637,3.18,3.564,0.034,,0.52847,432.902,,52.847,0.432902,,,,7.85398e-5
Test1,2-Recover,93.970,3.224,3.52,0.034,,0.521945,432.902,,52.1945,0.432902,,,,7.85398e-5
Test1,2-Recover,94.303,3.269,3.475,0.034,,0.515273,432.902,,51.5273,0.432902,,,,7.85398e-5
Test1,2-Recover,94.637,3.315,3.429,0.034,,0.508452,432.902,,50.8452,0.432902,,,,7.85398e-5
Test1,2-Recover,94.970,3.36,3.384,0.034,,0.501779,432.902,,50.1779,0.432902,,,,7.85398e-5
Test1,2-Recover,95.303,3.404,3.34,0.034,,0.495255,432.902,,49.5255,0.432902,,,,7.85398e-5
Test1,2-Recover,95.637,3.45,3.294,0.020,,0.488434,254.648,,48.8434,0.254648,,,,7.85398e-5
Test1,2-Recover,95.970,3.495,3.249,0.014,,0.481762,178.254,,48.1762,0.178254,,,,7.85398e-5
Test1,2-Recover,96.303,3.539,3.205,0.027,,0.475237,343.775,,47.5237,0.343775,,,,7.85398e-5
Test1,2-Recover,96.637,3.585,3.159,0.020,,0.468416,254.648,,46.8416,0.254648,,,,7.85398e-5
Test1,2-Recover,96.970,3.63,3.114,0.014,,0.461744,178.254,,46.1744,0.178254,,,,7.85398e-5
Test1,2-Recover,97.303,3.675,3.069,0.014,,0.455071,178.254,,45.5071,0.178254,,,,7.85398e-5
Test1,2-Recover,97.637,3.72,3.024,0.007,,0.448399,89.1268,,44.8399,0.0891268,,,,7.85398e-5
Test1,2-Recover,97.970,3.765,2.979,0.007,,0.441726,89.1268,,44.1726,0.0891268,,,,7.85398e-5
Test1,2-Recover,98.303,3.81,2.934,0.014,,0.435053,178.254,,43.5053,0.178254,,,,7.85398e-5
Test1,2-Recover,98.637,3.855,2.889,-0.007,,0.428381,-89.1268,,42.8381,-0.0891268,,,,7.85398e-5
Test1,2-Recover,98.970,3.9,2.844,-0.007,,0.421708,-89.1268,,42.1708,-0.0891268,,,,7.85398e-5
Test1,2-Recover,99.303,3.944,2.8,0.000,,0.415184,0,,41.5184,0,,,,7.85398e-5
Test1,2-Recover,99.637,3.991,2.753,0.000,,0.408215,0,,40.8215,0,,,,7.85398e-5
Test1,2-Recover,99.970,4.035,2.709,-0.007,,0.40169,-89.1268,,40.169,-0.0891268,,,,7.85398e-5
Test1,2-Recover,100.303,4.08,2.664,0.000,,0.395018,0,,39.5018,0,,,,7.85398e-5
Test1,2-Recover,100.637,4.126,2.618,-0.007,,0.388197,-89.1268,,38.8197,-0.0891268,,,,7.85398e-5
Test1,2-Recover,100.970,4.17,2.574,0.007,,0.381673,89.1268,,38.1673,0.0891268,,,,7.85398e-5
Test1,2-Recover,101.303,4.215,2.529,0.000,,0.375,0,,37.5,0,,,,7.85398e-5
Test1,2-Recover,101.637,4.261,2.483,0.000,,0.368179,0,,36.8179,0,,,,7.85398e-5
Test1,2-Recover,101.970,4.305,2.439,0.014,,0.361655,178.254,,36.1655,0.178254,,,,7.85398e-5
Test1,2-Recover,102.303,4.35,2.394,0.007,,0.354982,89.1268,,35.4982,0.0891268,,,,7.85398e-5
Test1,2-Recover,102.637,4.396,2.348,0.014,,0.348161,178.254,,34.8161,0.178254,,,,7.85398e-5
Test1,2-Recover,102.970,4.44,2.304,0.000,,0.341637,0,,34.1637,0,,,,7.85398e-5
Test1,2-Recover,103.303,4.485,2.259,0.000,,0.334964,0,,33.4964,0,,,,7.85398e-5
Test1,2-Recover,103.637,4.531,2.213,0.007,,0.328144,89.1268,,32.8144,0.0891268,,,,7.85398e-5
Test1,2-Recover,103.970,4.575,2.169,0.007,,0.321619,89.1268,,32.1619,0.0891268,,,,7.85398e-5
Test1,2-Recover,104.303,4.62,2.124,0.007,,0.314947,89.1268,,31.4947,0.0891268,,,,7.85398e-5
Test1,2-Recover,104.637,4.666,2.078,0.000,,0.308126,0,,30.8126,0,,,,7.85398e-5
Test1,2-Recover,104.970,4.711,2.033,0.020,,0.301453,254.648,,30.1453,0.254648,,,,7.85398e-5
Test1,2-Recover,105.303,4.755,1.989,0.000,,0.294929,0,,29.4929,0,,,,7.85398e-5
Test1,2-Recover,105.637,4.801,1.943,0.007,,0.288108,89.1268,,28.8108,0.0891268,,,,7.85398e-5
Test1,2-Recover,105.970,4.846,1.898,-0.014,,0.281435,-178.254,,28.1435,-0.178254,,,,7.85398e-5
Test1,2-Recover,106.303,4.89,1.854,0.014,,0.274911,178.254,,27.4911,0.178254,,,,7.85398e-5
Test1,2-Recover,106.637,4.936,1.808,-0.007,,0.26809,-89.1268,,26.809,-0.0891268,,,,7.85398e-5
Test1,2-Recover,106.970,4.981,1.763,0.000,,0.261418,0,,26.1418,0,,,,7.85398e-5
Test1,2-Recover,107.303,5.025,1.719,0.007,,0.254893,89.1268,,25.4893,0.0891268,,,,7.85398e-5
Test1,2-Recover,107.637,5.071,1.673,-0.014,,0.248072,-178.254,,24.8072,-0.178254,,,,7.85398e-5
Test1,2-Recover,107.970,5.116,1.628,0.020,,0.2414,254.648,,24.14,0.254648,,,,7.85398e-5
Test1,2-Recover,108.303,5.16,1.584,-0.014,,0.234875,-178.254,,23.4875,-0.178254,,,,7.85398e-5
Test1,2-Recover,108.637,5.206,1.538,0.000,,0.228055,0,,22.8055,0,,,,7.85398e-5
Test1,2-Recover,108.970,5.251,1.493,0.014,,0.221382,178.254,,22.1382,0.178254,,,,7.85398e-5
Test1,2-Recover,109.303,5.296,1.448,-0.007,,0.214709,-89.1268,,21.4709,-0.0891268,,,,7.85398e-5
Test1,2-Recover,109.637,5.341,1.403,0.014,,0.208037,178.254,,20.8037,0.178254,,,,7.85398e-5
Test1,2-Recover,109.970,5.386,1.358,-0.007,,0.201364,-89.1268,,20.1364,-0.0891268,,,,7.85398e-5
Test1,2-Recover,110.303,5.43,1.314,0.020,,0.19484,254.648,,19.484,0.254648,,,,7.85398e-5
Test1,2-Recover,110.637,5.476,1.268,0.000,,0.188019,0,,18.8019,0,,,,7.85398e-5
Test1,2-Recover,110.970,5.521,1.223,0.007,,0.181346,89.1268,,18.1346,0.0891268,,,,7.85398e-5
Test1,2-Recover,111.303,5.566,1.178,-0.007,,0.174674,-89.1268,,17.4674,-0.0891268,,,,7.85398e-5
Test1,2-Recover,111.637,5.612,1.132,0.000,,0.167853,0,,16.7853,0,,,,7.85398e-5
Test1,2-Recover,111.970,5.656,1.088,-0.007,,0.161329,-89.1268,,16.1329,-0.0891268,,,,7.85398e-5
Test1,2-Recover,112.303,5.701,1.043,-0.007,,0.154656,-89.1268,,15.4656,-0.0891268,,,,7.85398e-5
Test1,2-Recover,112.637,5.747,0.997,0.007,,0.147835,89.1268,,14.7835,0.0891268,,,,7.85398e-5
Test1,2-Recover,112.970,5.791,0.953,-0.007,,0.141311,-89.1268,,14.1311,-0.0891268,,,,7.85398e-5
Test1,2-Recover,113.303,5.836,0.908,0.014,,0.134638,178.254,,13.4638,0.178254,,,,7.85398e-5
Test1,2-Recover,113.637,5.882,0.862,0.000,,0.127817,0,,12.7817,0,,,,7.85398e-5
Test1,2-Recover,113.970,5.926,0.818,0.000,,0.121293,0,,12.1293,0,,,,7.85398e-5
Test1,2-Recover,114.303,5.971,0.773,0.014,,0.11462,178.254,,11.462,0.178254,,,,7.85398e-5
Test1,2-Recover,114.637,6.017,0.727,-0.007,,0.1078,-89.1268,,10.78,-0.0891268,,,,7.85398e-5
Test1,2-Recover,114.970,6.061,0.683,0.000,,0.101275,0,,10.1275,0,,,,7.85398e-5
Test1,2-Recover,115.303,6.106,0.638,0.000,,0.0946026,0,,9.46026,0,,,,7.85398e-5
Test1,2-Recover,115.637,6.152,0.592,0.020,,0.0877817,254.648,,8.77817,0.254648,,,,7.85398e-5
Test1,2-Recover,115.970,6.196,0.548,-0.014,,0.0812574,-178.254,,8.12574,-0.178254,,,,7.85398e-5
Test1,2-Recover,116.303,6.241,0.503,0.034,,0.0745848,432.902,,7.45848,0.432902,,,,7.85398e-5
Test1,2-Recover,116.637,6.287,0.457,-0.007,,0.0677639,-89.1268,,6.77639,-0.0891268,,,,7.85398e-5
Test1,2-Recover,116.970,6.332,0.412,0.027,,0.0610913,343.775,,6.10913,0.343775,,,,7.85398e-5
Test1,2-Recover,117.303,6.376,0.368,0.007,,0.054567,89.1268,,5.4567,0.0891268,,,,7.85398e-5
Test1,2-Recover,117.637,6.422,0.322,0.007,,0.0477461,89.1268,,4.77461,0.0891268,,,,7.85398e-5
Test1,2-Recover,117.970,6.467,0.277,0.007,,0.0410735,89.1268,,4.10735,0.0891268,,,,7.85398e-5
Test1,2-Recover,118.303,6.511,0.233,0.007,,0.0345492,89.1268,,3.45492,0.0891268,,,,7.85398e-5
Test1,2-Recover,118.637,6.557,0.187,0.020,,0.0277284,254.648,,2.77284,0.254648,,,,7.85398e-5
Test1,2-Recover,118.970,6.602,0.142,-0.014,,0.0210558,-178.254,,2.10558,-0.178254,,,,7.85398e-5
Test1,2-Recover,119.303,6.647,0.097,0.007,,0.0143832,89.1268,,1.43832,0.0891268,,,,7.85398e-5
Test1,2-Recover,119.637,6.692,0.052,-0.007,,0.00771056,-89.1268,,0.771056,-0.0891268,,,,7.85398e-5
Test1,2-Recover,119.970,6.737,0.007,0.000,,0.00103796,0,,0.103796,0,,,,7.85398e-5
Test1,3-Compress,120.280,6.718,0.026,-0.014,,0.00385528,-178.254,,0.385528,-0.178254,,,,7.85398e-5
Test1,3-Compress,120.613,6.674,0.07,0.000,,0.0103796,0,,1.03796,0,,,,7.85398e-5
Test1,3-Compress,120.947,6.628,0.116,0.007,,0.0172005,89.1268,,1.72005,0.0891268,,,,7.85398e-5
Test1,3-Compress,121.280,6.584,0.16,-0.014,,0.0237248,-178.254,,2.37248,-0.178254,,,,7.85398e-5
Test1,3-Compress,121.613,6.539,0.205,0.007,,0.0303974,89.1268,,3.03974,0.0891268,,,,7.85398e-5
Test1,3-Compress,121.947,6.493,0.251,-0.020,,0.0372183,-254.648,,3.72183,-0.254648,,,,7.85398e-5
Test1,3-Compress,122.280,6.449,0.295,0.020,,0.0437426,254.648,,4.37426,0.254648,,,,7.85398e-5
Test1,3-Compress,122.613,6.404,0.34,-0.014,,0.0504152,-178.254,,5.04152,-0.178254,,,,7.85398e-5
Test1,3-Compress,122.947,6.358,0.386,0.014,,0.0572361,178.254,,5.72361,0.178254,,,,7.85398e-5
Test1,3-Compress,123.280,6.313,0.431,0.000,,0.0639087,0,,6.39087,0,,,,7.85398e-5
Test1,3-Compress,123.613,6.269,0.475,0.000,,0.070433,0,,7.0433,0,,,,7.85398e-5
Test1,3-Compress,123.947,6.223,0.521,0.027,,0.0772539,343.775,,7.72539,0.343775,,,,7.85398e-5
Test1,3-Compress,124.280,6.178,0.566,-0.014,,0.0839265,-178.254,,8.39265,-0.178254,,,,7.85398e-5
Test1,3-Compress,124.613,6.134,0.61,0.034,,0.0904508,432.902,,9.04508,0.432902,,,,7.85398e-5
Test1,3-Compress,124.947,6.088,0.656,-0.007,,0.0972716,-89.1268,,9.72716,-0.0891268,,,,7.85398e-5
Test1,3-Compress,125.280,6.043,0.701,0.027,,0.103944,343.775,,10.3944,0.343775,,,,7.85398e-5
Test1,3-Compress,125.613,5.998,0.746,0.007,,0.110617,89.1268,,11.0617,0.0891268,,,,7.85398e-5
Test1,3-Compress,125.947,5.953,0.791,-0.007,,0.117289,-89.1268,,11.7289,-0.0891268,,,,7.85398e-5
Test1,3-Compress,126.280,5.908,0.836,0.020,,0.123962,254.648,,12.3962,0.254648,,,,7.85398e-5
Test1,3-Compress,126.613,5.863,0.881,0.007,,0.130635,89.1268,,13.0635,0.0891268,,,,7.85398e-5
Test1,3-Compress,126.947,5.818,0.926,0.014,,0.137307,178.254,,13.7307,0.178254,,,,7.85398e-5
Test1,3-Compress,127.280,5.773,0.971,-0.014,,0.14398,-178.254,,14.398,-0.178254,,,,7.85398e-5
Test1,3-Compress,127.613,5.728,1.016,0.000,,0.150652,0,,15.0652,0,,,,7.85398e-5
Test1,3-Compress,127.947,5.682,1.062,-0.007,,0.157473,-89.1268,,15.7473,-0.0891268,,,,7.85398e-5
Test1,3-Compress,128.280,5.638,1.106,0.000,,0.163998,0,,16.3998,0,,,,7.85398e-5
Test1,3-Compress,128.613,5.593,1.151,-0.007,,0.17067,-89.1268,,17.067,-0.0891268,,,,7.85398e-5
Test1,3-Compress,128.947,5.547,1.197,0.000,,0.177491,0,,17.7491,0,,,,7.85398e-5
Test1,3-Compress,129.280,5.503,1.241,0.007,,0.184015,89.1268,,18.4015,0.0891268,,,,7.85398e-5
Test1,3-Compress,129.613,5.458,1.286,0.007,,0.190688,89.1268,,19.0688,0.0891268,,,,7.85398e-5
Test1,3-Compress,129.947,5.412,1.332,0.007,,0.197509,89.1268,,19.7509,0.0891268,,,,7.85398e-5
Test1,3-Compress,130.280,5.367,1.377,-0.014,,0.204181,-178.254,,20.4181,-0.178254,,,,7.85398e-5
Test1,3-Compress,130.613,5.323,1.421,0.007,,0.210706,89.1268,,21.0706,0.0891268,,,,7.85398e-5
Test1,3-Compress,130.947,5.277,1.467,-0.007,,0.217527,-89.1268,,21.7527,-0.0891268,,,,7.85398e-5
Test1,3-Compress,131.280,5.232,1.512,-0.007,,0.224199,-89.1268,,22.4199,-0.0891268,,,,7.85398e-5
Test1,3-Compress,131.613,5.188,1.556,0.007,,0.230724,89.1268,,23.0724,0.0891268,,,,7.85398e-5
Test1,3-Compress,131.947,5.142,1.602,-0.014,,0.237544,-178.254,,23.7544,-0.178254,,,,7.85398e-5
Test1,3-Compress,132.280,5.098,1.646,0.020,,0.244069,254.648,,24.4069,0.254648,,,,7.85398e-5
Test1,3-Compress,132.613,5.053,1.691,-0.014,,0.250741,-178.254,,25.0741,-0.178254,,,,7.85398e-5
Test1,3-Compress,132.947,5.007,1.737,0.020,,0.257562,254.648,,25.7562,0.254648,,,,7.85398e-5
Test1,3-Compress,133.280,4.962,1.782,-0.007,,0.264235,-89.1268,,26.4235,-0.0891268,,,,7.85398e-5
Test1,3-Compress,133.613,4.918,1.826,0.000,,0.270759,0,,27.0759,0,,,,7.85398e-5
Test1,3-Compress,133.947,4.872,1.872,0.000,,0.27758,0,,27.758,0,,,,7.85398e-5
Test1,3-Compress,134.280,4.827,1.917,0.014,,0.284253,178.254,,28.4253,0.178254,,,,7.85398e-5
Test1,3-Compress,134.613,4.783,1.961,0.007,,0.290777,89.1268,,29.0777,0.0891268,,,,7.85398e-5
Test1,3-Compress,134.947,4.737,2.007,0.000,,0.297598,0,,29.7598,0,,,,7.85398e-5
Test1,3-Compress,135.280,4.692,2.052,0.014,,0.30427,178.254,,30.427,0.178254,,,,7.85398e-5
Test1,3-Compress,135.613,4.648,2.096,0.007,,0.310795,89.1268,,31.0795,0.0891268,,,,7.85398e-5
Test1,3-Compress,135.947,4.602,2.142,0.014,,0.317616,178.254,,31.7616,0.178254,,,,7.85398e-5
Test1,3-Compress,136.280,4.557,2.187,0.014,,0.324288,178.254,,32.4288,0.178254,,,,7.85398e-5
Test1,3-Compress,136.613,4.513,2.231,0.014,,0.330813,178.254,,33.0813,0.178254,,,,7.85398e-5
Test1,3-Compress,136.947,4.467,2.277,0.000,,0.337633,0,,33.7633,0,,,,7.85398e-5
Test1,3-Compress,137.280,4.422,2.322,0.007,,0.344306,89.1268,,34.4306,0.0891268,,,,7.85398e-5
Test1,3-Compress,137.613,4.377,2.367,0.007,,0.350979,89.1268,,35.0979,0.0891268,,,,7.85398e-5
Test1,3-Compress,137.947,4.332,2.412,0.000,,0.357651,0,,35.7651,0,,,,7.85398e-5
Test1,3-Compress,138.280,4.287,2.457,0.000,,0.364324,0,,36.4324,0,,,,7.85398e-5
Test1,3-Compress,138.613,4.242,2.502,-0.007,,0.370996,-89.1268,,37.0996,-0.0891268,,,,7.85398e-5
Test1,3-Compress,138.947,4.197,2.547,0.007,,0.377669,89.1268,,37.7669,0.0891268,,,,7.85398e-5
Test1,3-Compress,139.280,4.152,2.592,-0.007,,0.384342,-89.1268,,38.4342,-0.0891268,,,,7.85398e-5
Test1,3-Compress,139.613,4.107,2.637,0.000,,0.391014,0,,39.1014,0,,,,7.85398e-5
Test1,3-Compress,139.947,4.061,2.683,-0.007,,0.397835,-89.1268,,39.7835,-0.0891268,,,,7.85398e-5
Test1,3-Compress,140.280,4.017,2.727,0.000,,0.404359,0,,40.4359,0,,,,7.85398e-5
Test1,3-Compress,140.613,3.972,2.772,0.000,,0.411032,0,,41.1032,0,,,,7.85398e-5
Test1,3-Compress,140.947,3.926,2.818,-0.007,,0.417853,-89.1268,,41.7853,-0.0891268,,,,7.85398e-5
Test1,3-Compress,141.280,3.882,2.862,0.000,,0.424377,0,,42.4377,0,,,,7.85398e-5
Test1,3-Compress,141.613,3.837,2.907,0.027,,0.43105,343.775,,43.105,0.343775,,,,7.85398e-5
Test1,3-Compress,141.947,3.791,2.953,0.020,,0.437871,254.648,,43.7871,0.254648,,,,7.85398e-5
Test1,3-Compress,142.280,3.746,2.998,0.014,,0.444543,178.254,,44.4543,0.178254,,,,7.85398e-5
Test1,3-Compress,142.613,3.702,3.042,0.014,,0.451068,178.254,,45.1068,0.178254,,,,7.85398e-5
Test1,3-Compress,142.947,3.656,3.088,0.020,,0.457888,254.648,,45.7888,0.254648,,,,7.85398e-5
Test1,3-Compress,143.280,3.612,3.132,0.027,,0.464413,343.775,,46.4413,0.343775,,,,7.85398e-5
Test1,3-Compress,143.613,3.567,3.177,0.020,,0.471085,254.648,,47.1085,0.254648,,,,7.85398e-5
Test1,3-Compress,143.947,3.521,3.223,0.034,,0.477906,432.902,,47.7906,0.432902,,,,7.85398e-5
Test1,3-Compress,144.280,3.477,3.267,0.034,,0.484431,432.902,,48.4431,0.432902,,,,7.85398e-5
Test1,3-Compress,144.613,3.432,3.312,0.027,,0.491103,343.775,,49.1103,0.343775,,,,7.85398e-5
Test1,3-Compress,144.947,3.386,3.358,0.027,,0.497924,343.775,,49.7924,0.343775,,,,7.85398e-5
Test1,3-Compress,145.280,3.341,3.403,0.034,,0.504597,432.902,,50.4597,0.432902,,,,7.85398e-5
Test1,3-Compress,145.613,3.297,3.447,0.034,,0.511121,432.902,,51.1121,0.432902,,,,7.85398e-5
Test1,3-Compress,145.947,3.251,3.493,0.034,,0.517942,432.902,,51.7942,0.432902,,,,7.85398e-5
Test1,3-Compress,146.280,3.206,3.538,0.034,,0.524614,432.902,,52.4614,0.432902,,,,7.85398e-5
Test1,3-Compress,146.613,3.162,3.582,0.034,,0.531139,432.902,,53.1139,0.432902,,,,7.85398e-5
Test1,3-Compress,146.947,3.116,3.628,0.034,,0.53796,432.902,,53.796,0.432902,,,,7.85398e-5
Test1,3-Compress,147.280,3.071,3.673,0.034,,0.544632,432.902,,54.4632,0.432902,,,,7.85398e-5
Test1,3-Compress,147.613,3.026,3.718,0.034,,0.551305,432.902,,55.1305,0.432902,,,,7.85398e-5
Test1,3-Compress,147.947,2.981,3.763,0.034,,0.557977,432.902,,55.7977,0.432902,,,,7.85398e-5
Test1,3-Compress,148.280,2.936,3.808,0.034,,0.56465,432.902,,56.465,0.432902,,,,7.85398e-5
Test1,3-Compress,148.613,2.891,3.853,0.041,,0.571323,522.028,,57.1323,0.522028,,,,7.85398e-5
Test1,3-Compress,148.947,2.846,3.898,0.041,,0.577995,522.028,,57.7995,0.522028,,,,7.85398e-5
Test1,3-Compress,149.280,2.801,3.943,0.041,,0.584668,522.028,,58.4668,0.522028,,,,7.85398e-5
Test1,3-Compress,149.613,2.756,3.988,0.041,,0.59134,522.028,,59.134,0.522028,,,,7.85398e-5
Test1,3-Compress,149.947,2.71,4.034,0.041,,0.598161,522.028,,59.8161,0.522028,,,,7.85398e-5
Test1,3-Recover,150.267,2.72,4.024,0.048,,0.596679,611.155,,59.6679,0.611155,,,,7.85398e-5
Test1,3-Recover,150.600,2.764,3.98,0.048,,0.590154,611.155,,59.0154,0.611155,,,,7.85398e-5
Test1,3-Recover,150.933,2.809,3.935,0.048,,0.583482,611.155,,58.3482,0.611155,,,,7.85398e-5
Test1,3-Recover,151.267,2.855,3.889,0.041,,0.576661,522.028,,57.6661,0.522028,,,,7.85398e-5
Test1,3-Recover,151.600,2.899,3.845,0.034,,0.570136,432.902,,57.0136,0.432902,,,,7.85398e-5
Test1,3-Recover,151.933,2.944,3.8,0.041,,0.563464,522.028,,56.3464,0.522028,,,,7.85398e-5
Test1,3-Recover,152.267,2.989,3.755,0.034,,0.556791,432.902,,55.6791,0.432902,,,,7.85398e-5
Test1,3-Recover,152.600,3.034,3.71,0.034,,0.550119,432.902,,55.0119,0.432902,,,,7.85398e-5
Test1,3-Recover,152.933,3.079,3.665,0.034,,0.543446,432.902,,54.3446,0.432902,,,,7.85398e-5
Test1,3-Recover,153.267,3.125,3.619,0.034,,0.536625,432.902,,53.6625,0.432902,,,,7.85398e-5
Test1,3-Recover,153.600,3.169,3.575,0.034,,0.530101,432.902,,53.0101,0.432902,,,,7.85398e-5
Test1,3-Recover,153.933,3.214,3.53,0.034,,0.523428,432.902,,52.3428,0.432902,,,,7.85398e-5
Test1,3-Recover,154.267,3.26,3.484,0.034,,0.516607,432.902,,51.6607,0.432902,,,,7.85398e-5
Test1,3-Recover,154.600,3.304,3.44,0.020,,0.510083,254.648,,51.0083,0.254648,,,,7.85398e-5
Test1,3-Recover,154.933,3.349,3.395,0.034,,0.50341,432.902,,50.341,0.432902,,,,7.85398e-5
Test1,3-Recover,155.267,3.395,3.349,0.014,,0.49659,178.254,,49.659,0.178254,,,,7.85398e-5
Test1,3-Recover,155.600,3.44,3.304,0.014,,0.489917,178.254,,48.9917,0.178254,,,,7.85398e-5
Test1,3-Recover,155.933,3.484,3.26,0.020,,0.483393,254.648,,48.3393,0.254648,,,,7.85398e-5
Test1,3-Recover,156.267,3.53,3.214,0.000,,0.476572,0,,47.6572,0,,,,7.85398e-5
Test1,3-Recover,156.600,3.575,3.169,-0.007,,0.469899,-89.1268,,46.9899,-0.0891268,,,,7.85398e-5
Test1,3-Recover,156.933,3.619,3.125,0.014,,0.463375,178.254,,46.3375,0.178254,,,,7.85398e-5
Test1,3-Recover,157.267,3.665,3.079,-0.007,,0.456554,-89.1268,,45.6554,-0.0891268,,,,7.85398e-5
Test1,3-Recover,157.600,3.71,3.034,-0.014,,0.449881,-178.254,,44.9881,-0.178254,,,,7.85398e-5
Test1,3-Recover,157.933,3.754,2.99,-0.007,,0.443357,-89.1268,,44.3357,-0.0891268,,,,7.85398e-5
Test1,3-Recover,158.267,3.8,2.944,0.014,,0.436536,178.254,,43.6536,0.178254,,,,7.85398e-5
Test1,3-Recover,158.600,3.845,2.899,0.007,,0.429864,89.1268,,42.9864,0.0891268,,,,7.85398e-5
Test1,3-Recover,158.933,3.889,2.855,0.000,,0.423339,0,,42.3339,0,,,,7.85398e-5
Test1,3-Recover,159.267,3.935,2.809,0.014,,0.416518,178.254,,41.6518,0.178254,,,,7.85398e-5
Test1,3-Recover,159.600,3.98,2.764,-0.007,,0.409846,-89.1268,,40.9846,-0.0891268,,,,7.85398e-5
Test1,3-Recover,159.933,4.024,2.72,0.007,,0.403321,89.1268,,40.3321,0.0891268,,,,7.85398e-5
Test1,3-Recover,160.267,4.071,2.673,0.014,,0.396352,178.254,,39.6352,0.178254,,,,7.85398e-5
Test1,3-Recover,160.600,4.115,2.629,0.007,,0.389828,89.1268,,38.9828,0.0891268,,,,7.85398e-5
Test1,3-Recover,160.933,4.16,2.584,0.020,,0.383155,254.648,,38.3155,0.254648,,,,7.85398e-5
Test1,3-Recover,161.267,4.205,2.539,0.007,,0.376483,89.1268,,37.6483,0.0891268,,,,7.85398e-5
Test1,3-Recover,161.600,4.25,2.494,0.014,,0.36981,178.254,,36.981,0.178254,,,,7.85398e-5
Test1,3-Recover,161.933,4.295,2.449,0.007,,0.363138,89.1268,,36.3138,0.0891268,,,,7.85398e-5
Test1,3-Recover,162.267,4.34,2.404,0.000,,0.356465,0,,35.6465,0,,,,7.85398e-5
Test1,3-Recover,162.600,4.385,2.359,-0.007,,0.349792,-89.1268,,34.9792,-0.0891268,,,,7.85398e-5
Test1,3-Recover,162.933,4.43,2.314,0.000,,0.34312,0,,34.312,0,,,,7.85398e-5
Test1,3-Recover,163.267,4.476,2.268,0.000,,0.336299,0,,33.6299,0,,,,7.85398e-5
Test1,3-Recover,163.600,4.52,2.224,-0.014,,0.329775,-178.254,,32.9775,-0.178254,,,,7.85398e-5
Test1,3-Recover,163.933,4.565,2.179,0.014,,0.323102,178.254,,32.3102,0.178254,,,,7.85398e-5
Test1,3-Recover,164.267,4.611,2.133,-0.014,,0.316281,-178.254,,31.6281,-0.178254,,,,7.85398e-5
Test1,3-Recover,164.600,4.655,2.089,0.000,,0.309757,0,,30.9757,0,,,,7.85398e-5
Test1,3-Recover,164.933,4.7,2.044,0.000,,0.303084,0,,30.3084,0,,,,7.85398e-5
Test1,3-Recover,165.267,4.746,1.998,-0.014,,0.296263,-178.254,,29.6263,-0.178254,,,,7.85398e-5
Test1,3-Recover,165.600,4.79,1.954,0.007,,0.289739,89.1268,,28.9739,0.0891268,,,,7.85398e-5
Test1,3-Recover,165.933,4.835,1.909,-0.014,,0.283066,-178.254,,28.3066,-0.178254,,,,7.85398e-5
Test1,3-Recover,166.267,4.881,1.863,0.027,,0.276246,343.775,,27.6246,0.343775,,,,7.85398e-5
Test1,3-Recover,166.600,4.925,1.819,-0.007,,0.269721,-89.1268,,26.9721,-0.0891268,,,,7.85398e-5
Test1,3-Recover,166.933,4.97,1.774,0.014,,0.263049,178.254,,26.3049,0.178254,,,,7.85398e-5
Test1,3-Recover,167.267,5.016,1.728,0.000,,0.256228,0,,25.6228,0,,,,7.85398e-5
Test1,3-Recover,167.600,5.061,1.683,0.014,,0.249555,178.254,,24.9555,0.178254,,,,7.85398e-5
Test1,3-Recover,167.933,5.105,1.639,0.007,,0.243031,89.1268,,24.3031,0.0891268,,,,7.85398e-5
Test1,3-Recover,168.267,5.151,1.593,-0.007,,0.23621,-89.1268,,23.621,-0.0891268,,,,7.85398e-5
Test1,3-Recover,168.600,5.196,1.548,0.000,,0.229537,0,,22.9537,0,,,,7.85398e-5
Test1,3-Recover,168.933,5.24,1.504,0.014,,0.223013,178.254,,22.3013,0.178254,,,,7.85398e-5
Test1,3-Recover,169.267,5.286,1.458,0.000,,0.216192,0,,21.6192,0,,,,7.85398e-5
Test1,3-Recover,169.600,5.33,1.414,-0.007,,0.209668,-89.1268,,20.9668,-0.0891268,,,,7.85398e-5
Test1,3-Recover,169.933,5.375,1.369,0.000,,0.202995,0,,20.2995,0,,,,7.85398e-5
Test1,3-Recover,170.267,5.421,1.323,0.014,,0.196174,178.254,,19.6174,0.178254,,,,7.85398e-5
Test1,3-Recover,170.600,5.466,1.278,-0.007,,0.189502,-89.1268,,18.9502,-0.0891268,,,,7.85398e-5
Test1,3-Recover,170.933,5.51,1.234,0.000,,0.182977,0,,18.2977,0,,,,7.85398e-5
Test1,3-Recover,171.267,5.556,1.188,-0.007,,0.176157,-89.1268,,17.6157,-0.0891268,,,,7.85398e-5
Test1,3-Recover,171.600,5.601,1.143,0.007,,0.169484,89.1268,,16.9484,0.0891268,,,,7.85398e-5
Test1,3-Recover,171.933,5.645,1.099,0.007,,0.16296,89.1268,,16.296,0.0891268,,,,7.85398e-5
Test1,3-Recover,172.267,5.692,1.052,0.000,,0.155991,0,,15.5991,0,,,,7.85398e-5
Test1,3-Recover,172.600,5.736,1.008,0.014,,0.149466,178.254,,14.9466,0.178254,,,,7.85398e-5
Test1,3-Recover,172.933,5.781,0.963,0.014,,0.142794,178.254,,14.2794,0.178254,,,,7.85398e-5
Test1,3-Recover,173.267,5.826,0.918,0.020,,0.136121,254.648,,13.6121,0.254648,,,,7.85398e-5
Test1,3-Recover,173.600,5.871,0.873,0.014,,0.129448,178.254,,12.9448,0.178254,,,,7.85398e-5
Test1,3-Recover,173.933,5.916,0.828,0.027,,0.122776,343.775,,12.2776,0.343775,,,,7.85398e-5
Test1,3-Recover,174.267,5.961,0.783,0.000,,0.116103,0,,11.6103,0,,,,7.85398e-5
Test1,3-Recover,174.600,6.006,0.738,0.027,,0.109431,343.775,,10.9431,0.343775,,,,7.85398e-5
Test1,3-Recover,174.933,6.051,0.693,0.020,,0.102758,254.648,,10.2758,0.254648,,,,7.85398e-5
Test1,3-Recover,175.267,6.097,0.647,0.020,,0.0959371,254.648,,9.59371,0.254648,,,,7.85398e-5
Test1,3-Recover,175.600,6.141,0.603,0.014,,0.0894128,178.254,,8.94128,0.178254,,,,7.85398e-5
Test1,3-Recover,175.933,6.186,0.558,0.014,,0.0827402,178.254,,8.27402,0.178254,,,,7.85398e-5
Test1,3-Recover,176.267,6.232,0.512,0.014,,0.0759193,178.254,,7.59193,0.178254,,,,7.85398e-5
Test1,3-Recover,176.600,6.276,0.468,-0.014,,0.069395,-178.254,,6.9395,-0.178254,,,,7.85398e-5
Test1,3-Recover,176.933,6.321,0.423,0.007,,0.0627224,89.1268,,6.27224,0.0891268,,,,7.85398e-5
Test1,3-Recover,177.267,6.367,0.377,-0.007,,0.0559015,-89.1268,,5.59015,-0.0891268,,,,7.85398e-5
Test1,3-Recover,177.600,6.412,0.332,0.014,,0.0492289,178.254,,4.92289,0.178254,,,,7.85398e-5
Test1,3-Recover,177.933,6.456,0.288,-0.007,,0.0427046,-89.1268,,4.27046,-0.0891268,,,,7.85398e-5
Test1,3-Recover,178.267,6.502,0.242,0.000,,0.0358837,0,,3.58837,0,,,,7.85398e-5
Test1,3-Recover,178.600,6.547,0.197,0.000,,0.0292112,0,,2.92112,0,,,,7.85398e-5
Test1,3-Recover,178.933,6.591,0.153,-0.007,,0.0226868,-89.1268,,2.26868,-0.0891268,,,,7.85398e-5
Test1,3-Recover,179.267,6.637,0.107,0.027,,0.015866,343.775,,1.5866,0.343775,,,,7.85398e-5
Test1,3-Recover,179.600,6.682,0.062,-0.020,,0.00919336,-254.648,,0.919336,-0.254648,,,,7.85398e-5
Test1,3-Recover,179.933,6.726,0.018,0.020,,0.00266904,254.648,,0.266904,0.254648,,,,7.85398e-5
Test1,3-Recover,180.100,6.744,-0,-0.014,,0,-178.254,,0,-0.178254,,,,7.85398e-5