File: data/beta_1-0.25_1.csv
SetName,Cycle,Time_S,Size_mm,Displacement_mm,Force_N,,Strain,Stress(Pascal),,%Strain,Stress(kPa),,,,Area(m^2)
1:0.25 (rep 1),1-Compress,0,2.478,0,-0.004,,0,-50.9296,,0,-0.0509296,,,,7.85398e-5
1:0.25 (rep 1),1-Compress,0.367,2.46,0.018,0.002,,0.00726392,25.4648,,0.726392,0.0254648,,,,7.85398e-5
1:0.25 (rep 1),1-Compress,0.733,2.442,0.036,0.002,,0.0145278,25.4648,,1.45278,0.0254648,,,,7.85398e-5
1:0.25 (rep 1),1-Compress,1.1,2.424,0.054,0.016,,0.0217918,203.718,,2.17918,0.203718,,,,7.85398e-5
1:0.25 (rep 1),1-Compress,1.467,2.405,0.073,0.023,,0.0294592,292.845,,2.94592,0.292845,,,,7.85398e-5
1:0.25 (rep 1),1-Compress,1.833,2.388,0.09,0.002,,0.0363196,25.4648,,3.63196,0.0254648,,,,7.85398e-5
1:0.25 (rep 1),1-Compress,2.2,2.369,0.109,0.016,,0.0439871,203.718,,4.39871,0.203718,,,,7.85398e-5
1:0.25 (rep 1),1-Compress,2.567,2.351,0.127,0.009,,0.051251,114.592,,5.1251,0.114592,,,,7.85398e-5
1:0.25 (rep 1),1-Compress,2.933,2.333,0.145,0.002,,0.0585149,25.4648,,5.85149,0.0254648,,,,7.85398e-5
1:0.25 (rep 1),1-Compress,3.3,2.314,0.164,0.009,,0.0661824,114.592,,6.61824,0.114592,,,,7.85398e-5
1:0.25 (rep 1),1-Compress,3.667,2.296,0.182,0.023,,0.0734463,292.845,,7.34463,0.292845,,,,7.85398e-5
1:0.25 (rep 1),1-Compress,4.033,2.278,0.2,0.03,,0.0807103,381.972,,8.07103,0.381972,,,,7.85398e-5
1:0.25 (rep 1),1-Compress,4.4,2.26,0.218,0.023,,0.0879742,292.845,,8.79742,0.292845,,,,7.85398e-5
1:0.25 (rep 1),1-Compress,4.767,2.242,0.236,0.016,,0.0952381,203.718,,9.52381,0.203718,,,,7.85398e-5
1:0.25 (rep 1),1-Compress,5.133,2.224,0.254,0.009,,0.102502,114.592,,10.2502,0.114592,,,,7.85398e-5
1:0.25 (rep 1),1-Compress,5.5,2.205,0.273,0.009,,0.110169,114.592,,11.0169,0.114592,,,,7.85398e-5
1:0.25 (rep 1),1-Compress,5.867,2.187,0.291,0.023,,0.117433,292.845,,11.7433,0.292845,,,,7.85398e-5
1:0.25 (rep 1),1-Compress,6.233,2.169,0.309,0.036,,0.124697,458.366,,12.4697,0.458366,,,,7.85398e-5
1:0.25 (rep 1),1-Compress,6.6,2.151,0.327,0.05,,0.131961,636.62,,13.1961,0.63662,,,,7.85398e-5
1:0.25 (rep 1),1-Compress,6.967,2.132,0.346,0.043,,0.139629,547.493,,13.9629,0.547493,,,,7.85398e-5
1:0.25 (rep 1),1-Compress,7.333,2.114,0.364,0.036,,0.146893,458.366,,14.6893,0.458366,,,,7.85398e-5
1:0.25 (rep 1),1-Compress,7.7,2.096,0.382,0.036,,0.154157,458.366,,15.4157,0.458366,,,,7.85398e-5
1:0.25 (rep 1),1-Compress,8.067,2.077,0.401,0.05,,0.161824,636.62,,16.1824,0.63662,,,,7.85398e-5
1:0.25 (rep 1),1-Compress,8.433,2.06,0.418,0.036,,0.168684,458.366,,16.8684,0.458366,,,,7.85398e-5
1:0.25 (rep 1),1-Compress,8.8,2.041,0.437,0.043,,0.176352,547.493,,17.6352,0.547493,,,,7.85398e-5
1:0.25 (rep 1),1-Compress,9.167,2.023,0.455,0.05,,0.183616,636.62,,18.3616,0.63662,,,,7.85398e-5
1:0.25 (rep 1),1-Compress,9.533,2.005,0.473,0.05,,0.19088,636.62,,19.088,0.63662,,,,7.85398e-5
1:0.25 (rep 1),1-Compress,9.9,1.987,0.491,0.05,,0.198144,636.62,,19.8144,0.63662,,,,7.85398e-5
1:0.25 (rep 1),1-Compress,10.267,1.968,0.51,0.05,,0.205811,636.62,,20.5811,0.63662,,,,7.85398e-5
1:0.25 (rep 1),1-Compress,10.633,1.951,0.527,0.043,,0.212672,547.493,,21.2672,0.547493,,,,7.85398e-5
1:0.25 (rep 1),1-Compress,11,1.932,0.546,0.05,,0.220339,636.62,,22.0339,0.63662,,,,7.85398e-5
1:0.25 (rep 1),1-Compress,11.367,1.914,0.564,0.05,,0.227603,636.62,,22.7603,0.63662,,,,7.85398e-5
1:0.25 (rep 1),1-Compress,11.733,1.896,0.582,0.05,,0.234867,636.62,,23.4867,0.63662,,,,7.85398e-5
1:0.25 (rep 1),1-Compress,12.1,1.877,0.601,0.05,,0.242534,636.62,,24.2534,0.63662,,,,7.85398e-5
1:0.25 (rep 1),1-Compress,12.467,1.859,0.619,0.05,,0.249798,636.62,,24.9798,0.63662,,,,7.85398e-5
1:0.25 (rep 1),1-Compress,12.833,1.841,0.637,0.05,,0.257062,636.62,,25.7062,0.63662,,,,7.85398e-5
1:0.25 (rep 1),1-Compress,13.2,1.823,0.655,0.05,,0.264326,636.62,,26.4326,0.63662,,,,7.85398e-5
1:0.25 (rep 1),1-Compress,13.567,1.805,0.673,0.057,,0.27159,725.747,,27.159,0.725747,,,,7.85398e-5
1:0.25 (rep 1),1-Compress,13.933,1.787,0.691,0.05,,0.278854,636.62,,27.8854,0.63662,,,,7.85398e-5
1:0.25 (rep 1),1-Compress,14.3,1.768,0.71,0.05,,0.286521,636.62,,28.6521,0.63662,,,,7.85398e-5
1:0.25 (rep 1),1-Compress,14.667,1.75,0.728,0.05,,0.293785,636.62,,29.3785,0.63662,,,,7.85398e-5
1:0.25 (rep 1),1-Compress,15.033,1.732,0.746,0.05,,0.301049,636.62,,30.1049,0.63662,,,,7.85398e-5
1:0.25 (rep 1),1-Compress,15.4,1.714,0.764,0.05,,0.308313,636.62,,30.8313,0.63662,,,,7.85398e-5
1:0.25 (rep 1),1-Compress,15.767,1.695,0.783,0.05,,0.315981,636.62,,31.5981,0.63662,,,,7.85398e-5
1:0.25 (rep 1),1-Compress,16.133,1.677,0.801,0.05,,0.323245,636.62,,32.3245,0.63662,,,,7.85398e-5
1:0.25 (rep 1),1-Compress,16.5,1.659,0.819,0.05,,0.330508,636.62,,33.0508,0.63662,,,,7.85398e-5
1:0.25 (rep 1),1-Compress,16.867,1.64,0.838,0.05,,0.338176,636.62,,33.8176,0.63662,,,,7.85398e-5
1:0.25 (rep 1),1-Compress,17.233,1.623,0.855,0.057,,0.345036,725.747,,34.5036,0.725747,,,,7.85398e-5
1:0.25 (rep 1),1-Compress,17.6,1.604,0.874,0.05,,0.352704,636.62,,35.2704,0.63662,,,,7.85398e-5
1:0.25 (rep 1),1-Compress,17.967,1.586,0.892,0.057,,0.359968,725.747,,35.9968,0.725747,,,,7.85398e-5
1:0.25 (rep 1),1-Compress,18.333,1.568,0.91,0.05,,0.367232,636.62,,36.7232,0.63662,,,,7.85398e-5
1:0.25 (rep 1),1-Compress,18.7,1.55,0.928,0.057,,0.374496,725.747,,37.4496,0.725747,,,,7.85398e-5
1:0.25 (rep 1),1-Compress,19.067,1.532,0.946,0.07,,0.381759,891.268,,38.1759,0.891268,,,,7.85398e-5
1:0.25 (rep 1),1-Compress,19.433,1.514,0.964,0.064,,0.389023,814.873,,38.9023,0.814873,,,,7.85398e-5
1:0.25 (rep 1),1-Compress,19.8,1.495,0.983,0.064,,0.396691,814.873,,39.6691,0.814873,,,,7.85398e-5
1:0.25 (rep 1),1-Compress,20.167,1.477,1.001,0.057,,0.403955,725.747,,40.3955,0.725747,,,,7.85398e-5
1:0.25 (rep 1),1-Compress,20.533,1.459,1.019,0.057,,0.411219,725.747,,41.1219,0.725747,,,,7.85398e-5
1:0.25 (rep 1),1-Compress,20.9,1.44,1.038,0.057,,0.418886,725.747,,41.8886,0.725747,,,,7.85398e-5
1:0.25 (rep 1),1-Compress,21.267,1.422,1.056,0.077,,0.42615,980.395,,42.615,0.980395,,,,7.85398e-5
1:0.25 (rep 1),1-Compress,21.633,1.404,1.074,0.084,,0.433414,1069.52,,43.3414,1.06952,,,,7.85398e-5
1:0.25 (rep 1),1-Compress,22,1.386,1.092,0.098,,0.440678,1247.78,,44.0678,1.24778,,,,7.85398e-5
1:0.25 (rep 1),1-Compress,22.367,1.368,1.11,0.084,,0.447942,1069.52,,44.7942,1.06952,,,,7.85398e-5
1:0.25 (rep 1),1-Compress,22.733,1.35,1.128,0.098,,0.455206,1247.78,,45.5206,1.24778,,,,7.85398e-5
1:0.25 (rep 1),1-Compress,23.1,1.332,1.146,0.091,,0.46247,1158.65,,46.247,1.15865,,,,7.85398e-5
1:0.25 (rep 1),1-Compress,23.467,1.313,1.165,0.091,,0.470137,1158.65,,47.0137,1.15865,,,,7.85398e-5
1:0.25 (rep 1),1-Compress,23.833,1.295,1.183,0.104,,0.477401,1324.17,,47.7401,1.32417,,,,7.85398e-5
1:0.25 (rep 1),1-Compress,24.2,1.277,1.201,0.104,,0.484665,1324.17,,48.4665,1.32417,,,,7.85398e-5
1:0.25 (rep 1),1-Compress,24.567,1.258,1.22,0.104,,0.492333,1324.17,,49.2333,1.32417,,,,7.85398e-5
1:0.25 (rep 1),1-Compress,24.933,1.24,1.238,0.104,,0.499596,1324.17,,49.9596,1.32417,,,,7.85398e-5
1:0.25 (rep 1),1-Compress,25.3,1.222,1.256,0.104,,0.50686,1324.17,,50.686,1.32417,,,,7.85398e-5
1:0.25 (rep 1),1-Compress,25.667,1.204,1.274,0.104,,0.514124,1324.17,,51.4124,1.32417,,,,7.85398e-5
1:0.25 (rep 1),1-Compress,26.033,1.186,1.292,0.104,,0.521388,1324.17,,52.1388,1.32417,,,,7.85398e-5
1:0.25 (rep 1),1-Compress,26.4,1.168,1.31,0.104,,0.528652,1324.17,,52.8652,1.32417,,,,7.85398e-5
1:0.25 (rep 1),1-Compress,26.767,1.149,1.329,0.104,,0.53632,1324.17,,53.632,1.32417,,,,7.85398e-5
1:0.25 (rep 1),1-Compress,27.133,1.132,1.346,0.104,,0.54318,1324.17,,54.318,1.32417,,,,7.85398e-5
1:0.25 (rep 1),1-Compress,27.5,1.113,1.365,0.104,,0.550847,1324.17,,55.0847,1.32417,,,,7.85398e-5
1:0.25 (rep 1),1-Compress,27.867,1.095,1.383,0.104,,0.558111,1324.17,,55.8111,1.32417,,,,7.85398e-5
1:0.25 (rep 1),1-Compress,28.233,1.077,1.401,0.104,,0.565375,1324.17,,56.5375,1.32417,,,,7.85398e-5
1:0.25 (rep 1),1-Compress,28.6,1.058,1.42,0.104,,0.573043,1324.17,,57.3043,1.32417,,,,7.85398e-5
1:0.25 (rep 1),1-Compress,28.967,1.04,1.438,0.118,,0.580307,1502.42,,58.0307,1.50242,,,,7.85398e-5
1:0.25 (rep 1),1-Compress,29.333,1.022,1.456,0.118,,0.587571,1502.42,,58.7571,1.50242,,,,7.85398e-5
1:0.25 (rep 1),1-Compress,29.7,1.004,1.474,0.111,,0.594835,1413.3,,59.4835,1.4133,,,,7.85398e-5
1:0.25 (rep 1),1-Recover,30.067,0.993,1.485,0.111,,0.599274,1413.3,,59.9274,1.4133,,,,7.85398e-5
1:0.25 (rep 1),1-Recover,30.433,1.011,1.467,0.111,,0.59201,1413.3,,59.201,1.4133,,,,7.85398e-5
1:0.25 (rep 1),1-Recover,30.8,1.03,1.448,0.104,,0.584342,1324.17,,58.4342,1.32417,,,,7.85398e-5
1:0.25 (rep 1),1-Recover,31.167,1.048,1.43,0.104,,0.577078,1324.17,,57.7078,1.32417,,,,7.85398e-5
1:0.25 (rep 1),1-Recover,31.533,1.066,1.412,0.104,,0.569814,1324.17,,56.9814,1.32417,,,,7.85398e-5
1:0.25 (rep 1),1-Recover,31.9,1.084,1.394,0.104,,0.56255,1324.17,,56.255,1.32417,,,,7.85398e-5
1:0.25 (rep 1),1-Recover,32.267,1.103,1.375,0.104,,0.554883,1324.17,,55.4883,1.32417,,,,7.85398e-5
1:0.25 (rep 1),1-Recover,32.633,1.121,1.357,0.104,,0.547619,1324.17,,54.7619,1.32417,,,,7.85398e-5
1:0.25 (rep 1),1-Recover,33,1.139,1.339,0.104,,0.540355,1324.17,,54.0355,1.32417,,,,7.85398e-5
1:0.25 (rep 1),1-Recover,33.367,1.157,1.321,0.104,,0.533091,1324.17,,53.3091,1.32417,,,,7.85398e-5
1:0.25 (rep 1),1-Recover,33.733,1.175,1.303,0.098,,0.525827,1247.78,,52.5827,1.24778,,,,7.85398e-5
1:0.25 (rep 1),1-Recover,34.1,1.193,1.285,0.104,,0.518563,1324.17,,51.8563,1.32417,,,,7.85398e-5
1:0.25 (rep 1),1-Recover,34.467,1.212,1.266,0.104,,0.510896,1324.17,,51.0896,1.32417,,,,7.85398e-5
1:0.25 (rep 1),1-Recover,34.833,1.23,1.248,0.104,,0.503632,1324.17,,50.3632,1.32417,,,,7.85398e-5
1:0.25 (rep 1),1-Recover,35.2,1.248,1.23,0.104,,0.496368,1324.17,,49.6368,1.32417,,,,7.85398e-5
1:0.25 (rep 1),1-Recover,35.567,1.267,1.211,0.098,,0.488701,1247.78,,48.8701,1.24778,,,,7.85398e-5
1:0.25 (rep 1),1-Recover,35.933,1.284,1.194,0.077,,0.48184,980.395,,48.184,0.980395,,,,7.85398e-5
1:0.25 (rep 1),1-Recover,36.3,1.303,1.175,0.091,,0.474173,1158.65,,47.4173,1.15865,,,,7.85398e-5
1:0.25 (rep 1),1-Recover,36.667,1.321,1.157,0.084,,0.466909,1069.52,,46.6909,1.06952,,,,7.85398e-5
1:0.25 (rep 1),1-Recover,37.033,1.339,1.139,0.098,,0.459645,1247.78,,45.9645,1.24778,,,,7.85398e-5
1:0.25 (rep 1),1-Recover,37.4,1.358,1.12,0.07,,0.451977,891.268,,45.1977,0.891268,,,,7.85398e-5
1:0.25 (rep 1),1-Recover,37.767,1.375,1.103,0.057,,0.445117,725.747,,44.5117,0.725747,,,,7.85398e-5
1:0.25 (rep 1),1-Recover,38.133,1.394,1.084,0.057,,0.43745,725.747,,43.745,0.725747,,,,7.85398e-5
1:0.25 (rep 1),1-Recover,38.5,1.412,1.066,0.05,,0.430186,636.62,,43.0186,0.63662,,,,7.85398e-5
1:0.25 (rep 1),1-Recover,38.867,1.43,1.048,0.064,,0.422922,814.873,,42.2922,0.814873,,,,7.85398e-5
1:0.25 (rep 1),1-Recover,39.233,1.448,1.03,0.064,,0.415658,814.873,,41.5658,0.814873,,,,7.85398e-5
1:0.25 (rep 1),1-Recover,39.6,1.467,1.011,0.057,,0.40799,725.747,,40.799,0.725747,,,,7.85398e-5
1:0.25 (rep 1),1-Recover,39.967,1.485,0.993,0.05,,0.400726,636.62,,40.0726,0.63662,,,,7.85398e-5
1:0.25 (rep 1),1-Recover,40.333,1.503,0.975,0.05,,0.393462,636.62,,39.3462,0.63662,,,,7.85398e-5
1:0.25 (rep 1),1-Recover,40.7,1.521,0.957,0.057,,0.386199,725.747,,38.6199,0.725747,,,,7.85398e-5
1:0.25 (rep 1),1-Recover,41.067,1.54,0.938,0.05,,0.378531,636.62,,37.8531,0.63662,,,,7.85398e-5
1:0.25 (rep 1),1-Recover,41.433,1.558,0.92,0.05,,0.371267,636.62,,37.1267,0.63662,,,,7.85398e-5
1:0.25 (rep 1),1-Recover,41.8,1.576,0.902,0.05,,0.364003,636.62,,36.4003,0.63662,,,,7.85398e-5
1:0.25 (rep 1),1-Recover,42.167,1.594,0.884,0.05,,0.356739,636.62,,35.6739,0.63662,,,,7.85398e-5
1:0.25 (rep 1),1-Recover,42.533,1.612,0.866,0.05,,0.349475,636.62,,34.9475,0.63662,,,,7.85398e-5
1:0.25 (rep 1),1-Recover,42.9,1.63,0.848,0.05,,0.342211,636.62,,34.2211,0.63662,,,,7.85398e-5
1:0.25 (rep 1),1-Recover,43.267,1.649,0.829,0.05,,0.334544,636.62,,33.4544,0.63662,,,,7.85398e-5
1:0.25 (rep 1),1-Recover,43.633,1.667,0.811,0.05,,0.32728,636.62,,32.728,0.63662,,,,7.85398e-5
1:0.25 (rep 1),1-Recover,44,1.685,0.793,0.05,,0.320016,636.62,,32.0016,0.63662,,,,7.85398e-5
1:0.25 (rep 1),1-Recover,44.367,1.703,0.775,0.05,,0.312752,636.62,,31.2752,0.63662,,,,7.85398e-5
1:0.25 (rep 1),1-Recover,44.733,1.721,0.757,0.05,,0.305488,636.62,,30.5488,0.63662,,,,7.85398e-5
1:0.25 (rep 1),1-Recover,45.1,1.74,0.738,0.05,,0.297821,636.62,,29.7821,0.63662,,,,7.85398e-5
1:0.25 (rep 1),1-Recover,45.467,1.758,0.72,0.05,,0.290557,636.62,,29.0557,0.63662,,,,7.85398e-5
1:0.25 (rep 1),1-Recover,45.833,1.776,0.702,0.057,,0.283293,725.747,,28.3293,0.725747,,,,7.85398e-5
1:0.25 (rep 1),1-Recover,46.2,1.795,0.683,0.05,,0.275626,636.62,,27.5626,0.63662,,,,7.85398e-5
1:0.25 (rep 1),1-Recover,46.567,1.812,0.666,0.05,,0.268765,636.62,,26.8765,0.63662,,,,7.85398e-5
1:0.25 (rep 1),1-Recover,46.933,1.831,0.647,0.05,,0.261098,636.62,,26.1098,0.63662,,,,7.85398e-5
1:0.25 (rep 1),1-Recover,47.3,1.849,0.629,0.05,,0.253834,636.62,,25.3834,0.63662,,,,7.85398e-5
1:0.25 (rep 1),1-Recover,47.667,1.867,0.611,0.05,,0.24657,636.62,,24.657,0.63662,,,,7.85398e-5
1:0.25 (rep 1),1-Recover,48.033,1.885,0.593,0.05,,0.239306,636.62,,23.9306,0.63662,,,,7.85398e-5
1:0.25 (rep 1),1-Recover,48.4,1.903,0.575,0.05,,0.232042,636.62,,23.2042,0.63662,,,,7.85398e-5
1:0.25 (rep 1),1-Recover,48.767,1.922,0.556,0.043,,0.224374,547.493,,22.4374,0.547493,,,,7.85398e-5
1:0.25 (rep 1),1-Recover,49.133,1.94,0.538,0.043,,0.217111,547.493,,21.7111,0.547493,,,,7.85398e-5
1:0.25 (rep 1),1-Recover,49.5,1.958,0.52,0.05,,0.209847,636.62,,20.9847,0.63662,,,,7.85398e-5
1:0.25 (rep 1),1-Recover,49.867,1.977,0.501,0.043,,0.202179,547.493,,20.2179,0.547493,,,,7.85398e-5
1:0.25 (rep 1),1-Recover,50.233,1.995,0.483,0.05,,0.194915,636.62,,19.4915,0.63662,,,,7.85398e-5
1:0.25 (rep 1),1-Recover,50.6,2.013,0.465,0.043,,0.187651,547.493,,18.7651,0.547493,,,,7.85398e-5
1:0.25 (rep 1),1-Recover,50.967,2.031,0.447,0.043,,0.180387,547.493,,18.0387,0.547493,,,,7.85398e-5
1:0.25 (rep 1),1-Recover,51.333,2.049,0.429,0.043,,0.173123,547.493,,17.3123,0.547493,,,,7.85398e-5
1:0.25 (rep 1),1-Recover,51.7,2.067,0.411,0.043,,0.16586,547.493,,16.586,0.547493,,,,7.85398e-5
1:0.25 (rep 1),1-Recover,52.067,2.086,0.392,0.043,,0.158192,547.493,,15.8192,0.547493,,,,7.85398e-5
1:0.25 (rep 1),1-Recover,52.433,2.103,0.375,0.03,,0.151332,381.972,,15.1332,0.381972,,,,7.85398e-5
1:0.25 (rep 1),1-Recover,52.8,2.122,0.356,0.036,,0.143664,458.366,,14.3664,0.458366,,,,7.85398e-5
1:0.25 (rep 1),1-Recover,53.167,2.14,0.338,0.043,,0.1364,547.493,,13.64,0.547493,,,,7.85398e-5
1:0.25 (rep 1),1-Recover,53.533,2.158,0.32,0.009,,0.129136,114.592,,12.9136,0.114592,,,,7.85398e-5
1:0.25 (rep 1),1-Recover,53.9,2.177,0.301,0.036,,0.121469,458.366,,12.1469,0.458366,,,,7.85398e-5
1:0.25 (rep 1),1-Recover,54.267,2.195,0.283,0.043,,0.114205,547.493,,11.4205,0.547493,,,,7.85398e-5
1:0.25 (rep 1),1-Recover,54.633,2.213,0.265,0.03,,0.106941,381.972,,10.6941,0.381972,,,,7.85398e-5
1:0.25 (rep 1),1-Recover,55,2.231,0.247,0.036,,0.0996772,458.366,,9.96772,0.458366,,,,7.85398e-5
1:0.25 (rep 1),1-Recover,55.367,2.249,0.229,0.036,,0.0924132,458.366,,9.24132,0.458366,,,,7.85398e-5
1:0.25 (rep 1),1-Recover,55.733,2.267,0.211,0.016,,0.0851493,203.718,,8.51493,0.203718,,,,7.85398e-5
1:0.25 (rep 1),1-Recover,56.1,2.286,0.192,0.023,,0.0774818,292.845,,7.74818,0.292845,,,,7.85398e-5
1:0.25 (rep 1),1-Recover,56.467,2.304,0.174,0.023,,0.0702179,292.845,,7.02179,0.292845,,,,7.85398e-5
1:0.25 (rep 1),1-Recover,56.833,2.322,0.156,0.03,,0.062954,381.972,,6.2954,0.381972,,,,7.85398e-5
1:0.25 (rep 1),1-Recover,57.2,2.34,0.138,0.03,,0.0556901,381.972,,5.56901,0.381972,,,,7.85398e-5
1:0.25 (rep 1),1-Recover,57.567,2.359,0.119,0.016,,0.0480226,203.718,,4.80226,0.203718,,,,7.85398e-5
1:0.25 (rep 1),1-Recover,57.933,2.377,0.101,0.009,,0.0407587,114.592,,4.07587,0.114592,,,,7.85398e-5
1:0.25 (rep 1),1-Recover,58.3,2.395,0.083,0.002,,0.0334948,25.4648,,3.34948,0.0254648,,,,7.85398e-5
1:0.25 (rep 1),1-Recover,58.667,2.414,0.064,0.016,,0.0258273,203.718,,2.58273,0.203718,,,,7.85398e-5
1:0.25 (rep 1),1-Recover,59.033,2.431,0.047,0.016,,0.0189669,203.718,,1.89669,0.203718,,,,7.85398e-5
1:0.25 (rep 1),1-Recover,59.4,2.45,0.028,0.023,,0.0112994,292.845,,1.12994,0.292845,,,,7.85398e-5
1:0.25 (rep 1),1-Recover,59.767,2.468,0.01,0.023,,0.00403551,292.845,,0.403551,0.292845,,,,7.85398e-5
1:0.25 (rep 1),2-Compress,60.117,2.474,0.004,0.002,,0.00161421,25.4648,,0.161421,0.0254648,,,,7.85398e-5
1:0.25 (rep 1),2-Compress,60.483,2.457,0.021,0.009,,0.00847458,114.592,,0.847458,0.114592,,,,7.85398e-5
1:0.25 (rep 1),2-Compress,60.85,2.438,0.04,0.002,,0.0161421,25.4648,,1.61421,0.0254648,,,,7.85398e-5
1:0.25 (rep 1),2-Compress,61.217,2.42,0.058,0.002,,0.023406,25.4648,,2.3406,0.0254648,,,,7.85398e-5
1:0.25 (rep 1),2-Compress,61.583,2.402,0.076,0.023,,0.0306699,292.845,,3.06699,0.292845,,,,7.85398e-5
1:0.25 (rep 1),2-Compress,61.95,2.383,0.095,0.023,,0.0383374,292.845,,3.83374,0.292845,,,,7.85398e-5
1:0.25 (rep 1),2-Compress,62.317,2.365,0.113,0.03,,0.0456013,381.972,,4.56013,0.381972,,,,7.85398e-5
1:0.25 (rep 1),2-Compress,62.683,2.347,0.131,0.036,,0.0528652,458.366,,5.28652,0.458366,,,,7.85398e-5
1:0.25 (rep 1),2-Compress,63.05,2.328,0.15,0.009,,0.0605327,114.592,,6.05327,0.114592,,,,7.85398e-5
1:0.25 (rep 1),2-Compress,63.417,2.31,0.168,0.036,,0.0677966,458.366,,6.77966,0.458366,,,,7.85398e-5
1:0.25 (rep 1),2-Compress,63.783,2.292,0.186,0.023,,0.0750605,292.845,,7.50605,0.292845,,,,7.85398e-5
1:0.25 (rep 1),2-Compress,64.15,2.274,0.204,0.03,,0.0823245,381.972,,8.23245,0.381972,,,,7.85398e-5
1:0.25 (rep 1),2-Compress,64.517,2.256,0.222,0.043,,0.0895884,547.493,,8.95884,0.547493,,,,7.85398e-5
1:0.25 (rep 1),2-Compress,64.883,2.238,0.24,0.036,,0.0968523,458.366,,9.68523,0.458366,,,,7.85398e-5
1:0.25 (rep 1),2-Compress,65.25,2.22,0.258,0.05,,0.104116,636.62,,10.4116,0.63662,,,,7.85398e-5
1:0.25 (rep 1),2-Compress,65.617,2.201,0.277,0.036,,0.111784,458.366,,11.1784,0.458366,,,,7.85398e-5
1:0.25 (rep 1),2-Compress,65.983,2.183,0.295,0.043,,0.119048,547.493,,11.9048,0.547493,,,,7.85398e-5
1:0.25 (rep 1),2-Compress,66.35,2.165,0.313,0.043,,0.126312,547.493,,12.6312,0.547493,,,,7.85398e-5
1:0.25 (rep 1),2-Compress,66.717,2.146,0.332,0.043,,0.133979,547.493,,13.3979,0.547493,,,,7.85398e-5
1:0.25 (rep 1),2-Compress,67.083,2.129,0.349,0.043,,0.140839,547.493,,14.0839,0.547493,,,,7.85398e-5
1:0.25 (rep 1),2-Compress,67.45,2.11,0.368,0.05,,0.148507,636.62,,14.8507,0.63662,,,,7.85398e-5
1:0.25 (rep 1),2-Compress,67.817,2.092,0.386,0.05,,0.155771,636.62,,15.5771,0.63662,,,,7.85398e-5
1:0.25 (rep 1),2-Compress,68.183,2.074,0.404,0.05,,0.163035,636.62,,16.3035,0.63662,,,,7.85398e-5
1:0.25 (rep 1),2-Compress,68.55,2.056,0.422,0.05,,0.170299,636.62,,17.0299,0.63662,,,,7.85398e-5
1:0.25 (rep 1),2-Compress,68.917,2.037,0.441,0.05,,0.177966,636.62,,17.7966,0.63662,,,,7.85398e-5
1:0.25 (rep 1),2-Compress,69.283,2.02,0.458,0.05,,0.184826,636.62,,18.4826,0.63662,,,,7.85398e-5
1:0.25 (rep 1),2-Compress,69.65,2.001,0.477,0.05,,0.192494,636.62,,19.2494,0.63662,,,,7.85398e-5
1:0.25 (rep 1),2-Compress,70.017,1.983,0.495,0.05,,0.199758,636.62,,19.9758,0.63662,,,,7.85398e-5
1:0.25 (rep 1),2-Compress,70.383,1.965,0.513,0.05,,0.207022,636.62,,20.7022,0.63662,,,,7.85398e-5
1:0.25 (rep 1),2-Compress,70.75,1.946,0.532,0.05,,0.214689,636.62,,21.4689,0.63662,,,,7.85398e-5
1:0.25 (rep 1),2-Compress,71.117,1.928,0.55,0.05,,0.221953,636.62,,22.1953,0.63662,,,,7.85398e-5
1:0.25 (rep 1),2-Compress,71.483,1.91,0.568,0.05,,0.229217,636.62,,22.9217,0.63662,,,,7.85398e-5
1:0.25 (rep 1),2-Compress,71.85,1.892,0.586,0.05,,0.236481,636.62,,23.6481,0.63662,,,,7.85398e-5
1:0.25 (rep 1),2-Compress,72.217,1.873,0.605,0.05,,0.244149,636.62,,24.4149,0.63662,,,,7.85398e-5
1:0.25 (rep 1),2-Compress,72.583,1.855,0.623,0.05,,0.251412,636.62,,25.1412,0.63662,,,,7.85398e-5
1:0.25 (rep 1),2-Compress,72.95,1.837,0.641,0.05,,0.258676,636.62,,25.8676,0.63662,,,,7.85398e-5
1:0.25 (rep 1),2-Compress,73.317,1.819,0.659,0.05,,0.26594,636.62,,26.594,0.63662,,,,7.85398e-5
1:0.25 (rep 1),2-Compress,73.683,1.801,0.677,0.05,,0.273204,636.62,,27.3204,0.63662,,,,7.85398e-5
1:0.25 (rep 1),2-Compress,74.05,1.783,0.695,0.05,,0.280468,636.62,,28.0468,0.63662,,,,7.85398e-5
1:0.25 (rep 1),2-Compress,74.417,1.764,0.714,0.05,,0.288136,636.62,,28.8136,0.63662,,,,7.85398e-5
1:0.25 (rep 1),2-Compress,74.783,1.746,0.732,0.05,,0.2954,636.62,,29.54,0.63662,,,,7.85398e-5
1:0.25 (rep 1),2-Compress,75.15,1.728,0.75,0.057,,0.302663,725.747,,30.2663,0.725747,,,,7.85398e-5
1:0.25 (rep 1),2-Compress,75.517,1.709,0.769,0.05,,0.310331,636.62,,31.0331,0.63662,,,,7.85398e-5
1:0.25 (rep 1),2-Compress,75.883,1.692,0.786,0.057,,0.317191,725.747,,31.7191,0.725747,,,,7.85398e-5
1:0.25 (rep 1),2-Compress,76.25,1.673,0.805,0.05,,0.324859,636.62,,32.4859,0.63662,,,,7.85398e-5
1:0.25 (rep 1),2-Compress,76.617,1.655,0.823,0.057,,0.332123,725.747,,33.2123,0.725747,,,,7.85398e-5
1:0.25 (rep 1),2-Compress,76.983,1.637,0.841,0.05,,0.339387,636.62,,33.9387,0.63662,,,,7.85398e-5
1:0.25 (rep 1),2-Compress,77.35,1.619,0.859,0.07,,0.346651,891.268,,34.6651,0.891268,,,,7.85398e-5
1:0.25 (rep 1),2-Compress,77.717,1.601,0.877,0.057,,0.353914,725.747,,35.3914,0.725747,,,,7.85398e-5
1:0.25 (rep 1),2-Compress,78.083,1.583,0.895,0.057,,0.361178,725.747,,36.1178,0.725747,,,,7.85398e-5
1:0.25 (rep 1),2-Compress,78.45,1.564,0.914,0.057,,0.368846,725.747,,36.8846,0.725747,,,,7.85398e-5
1:0.25 (rep 1),2-Compress,78.817,1.546,0.932,0.057,,0.37611,725.747,,37.611,0.725747,,,,7.85398e-5
1:0.25 (rep 1),2-Compress,79.183,1.528,0.95,0.057,,0.383374,725.747,,38.3374,0.725747,,,,7.85398e-5
1:0.25 (rep 1),2-Compress,79.55,1.509,0.969,0.084,,0.391041,1069.52,,39.1041,1.06952,,,,7.85398e-5
1:0.25 (rep 1),2-Compress,79.917,1.491,0.987,0.07,,0.398305,891.268,,39.8305,0.891268,,,,7.85398e-5
1:0.25 (rep 1),2-Compress,80.283,1.473,1.005,0.07,,0.405569,891.268,,40.5569,0.891268,,,,7.85398e-5
1:0.25 (rep 1),2-Compress,80.65,1.455,1.023,0.077,,0.412833,980.395,,41.2833,0.980395,,,,7.85398e-5
1:0.25 (rep 1),2-Compress,81.017,1.436,1.042,0.057,,0.4205,725.747,,42.05,0.725747,,,,7.85398e-5
1:0.25 (rep 1),2-Compress,81.383,1.418,1.06,0.07,,0.427764,891.268,,42.7764,0.891268,,,,7.85398e-5
1:0.25 (rep 1),2-Compress,81.75,1.4,1.078,0.077,,0.435028,980.395,,43.5028,0.980395,,,,7.85398e-5
1:0.25 (rep 1),2-Compress,82.117,1.382,1.096,0.104,,0.442292,1324.17,,44.2292,1.32417,,,,7.85398e-5
1:0.25 (rep 1),2-Compress,82.483,1.364,1.114,0.084,,0.449556,1069.52,,44.9556,1.06952,,,,7.85398e-5
1:0.25 (rep 1),2-Compress,82.85,1.346,1.132,0.098,,0.45682,1247.78,,45.682,1.24778,,,,7.85398e-5
1:0.25 (rep 1),2-Compress,83.217,1.327,1.151,0.091,,0.464487,1158.65,,46.4487,1.15865,,,,7.85398e-5
1:0.25 (rep 1),2-Compress,83.583,1.309,1.169,0.091,,0.471751,1158.65,,47.1751,1.15865,,,,7.85398e-5
1:0.25 (rep 1),2-Compress,83.95,1.291,1.187,0.098,,0.479015,1247.78,,47.9015,1.24778,,,,7.85398e-5
1:0.25 (rep 1),2-Compress,84.317,1.272,1.206,0.098,,0.486683,1247.78,,48.6683,1.24778,,,,7.85398e-5
1:0.25 (rep 1),2-Compress,84.683,1.255,1.223,0.104,,0.493543,1324.17,,49.3543,1.32417,,,,7.85398e-5
1:0.25 (rep 1),2-Compress,85.05,1.236,1.242,0.104,,0.501211,1324.17,,50.1211,1.32417,,,,7.85398e-5
1:0.25 (rep 1),2-Compress,85.417,1.218,1.26,0.104,,0.508475,1324.17,,50.8475,1.32417,,,,7.85398e-5
1:0.25 (rep 1),2-Compress,85.783,1.2,1.278,0.104,,0.515738,1324.17,,51.5738,1.32417,,,,7.85398e-5
1:0.25 (rep 1),2-Compress,86.15,1.182,1.296,0.104,,0.523002,1324.17,,52.3002,1.32417,,,,7.85398e-5
1:0.25 (rep 1),2-Compress,86.517,1.164,1.314,0.104,,0.530266,1324.17,,53.0266,1.32417,,,,7.85398e-5
1:0.25 (rep 1),2-Compress,86.883,1.146,1.332,0.104,,0.53753,1324.17,,53.753,1.32417,,,,7.85398e-5
1:0.25 (rep 1),2-Compress,87.25,1.127,1.351,0.104,,0.545198,1324.17,,54.5198,1.32417,,,,7.85398e-5
1:0.25 (rep 1),2-Compress,87.617,1.109,1.369,0.104,,0.552462,1324.17,,55.2462,1.32417,,,,7.85398e-5
1:0.25 (rep 1),2-Compress,87.983,1.091,1.387,0.104,,0.559726,1324.17,,55.9726,1.32417,,,,7.85398e-5
1:0.25 (rep 1),2-Compress,88.35,1.073,1.405,0.104,,0.56699,1324.17,,56.699,1.32417,,,,7.85398e-5
1:0.25 (rep 1),2-Compress,88.717,1.054,1.424,0.104,,0.574657,1324.17,,57.4657,1.32417,,,,7.85398e-5
1:0.25 (rep 1),2-Compress,89.083,1.036,1.442,0.104,,0.581921,1324.17,,58.1921,1.32417,,,,7.85398e-5
1:0.25 (rep 1),2-Compress,89.45,1.018,1.46,0.111,,0.589185,1413.3,,58.9185,1.4133,,,,7.85398e-5
1:0.25 (rep 1),2-Compress,89.817,0.999,1.479,0.125,,0.596852,1591.55,,59.6852,1.59155,,,,7.85398e-5
1:0.25 (rep 1),2-Recover,90.17,0.997,1.481,0.118,,0.597659,1502.42,,59.7659,1.50242,,,,7.85398e-5
1:0.25 (rep 1),2-Recover,90.537,1.015,1.463,0.118,,0.590395,1502.42,,59.0395,1.50242,,,,7.85398e-5
1:0.25 (rep 1),2-Recover,90.903,1.033,1.445,0.111,,0.583132,1413.3,,58.3132,1.4133,,,,7.85398e-5
1:0.25 (rep 1),2-Recover,91.27,1.051,1.427,0.104,,0.575868,1324.17,,57.5868,1.32417,,,,7.85398e-5
1:0.25 (rep 1),2-Recover,91.637,1.069,1.409,0.104,,0.568604,1324.17,,56.8604,1.32417,,,,7.85398e-5
1:0.25 (rep 1),2-Recover,92.003,1.087,1.391,0.104,,0.56134,1324.17,,56.134,1.32417,,,,7.85398e-5
1:0.25 (rep 1),2-Recover,92.37,1.106,1.372,0.104,,0.553672,1324.17,,55.3672,1.32417,,,,7.85398e-5
1:0.25 (rep 1),2-Recover,92.737,1.124,1.354,0.104,,0.546408,1324.17,,54.6408,1.32417,,,,7.85398e-5
1:0.25 (rep 1),2-Recover,93.103,1.142,1.336,0.104,,0.539144,1324.17,,53.9144,1.32417,,,,7.85398e-5
1:0.25 (rep 1),2-Recover,93.47,1.16,1.318,0.104,,0.531881,1324.17,,53.1881,1.32417,,,,7.85398e-5
1:0.25 (rep 1),2-Recover,93.837,1.179,1.299,0.104,,0.524213,1324.17,,52.4213,1.32417,,,,7.85398e-5
1:0.25 (rep 1),2-Recover,94.203,1.197,1.281,0.104,,0.516949,1324.17,,51.6949,1.32417,,,,7.85398e-5
1:0.25 (rep 1),2-Recover,94.57,1.215,1.263,0.104,,0.509685,1324.17,,50.9685,1.32417,,,,7.85398e-5
1:0.25 (rep 1),2-Recover,94.937,1.234,1.244,0.104,,0.502018,1324.17,,50.2018,1.32417,,,,7.85398e-5
1:0.25 (rep 1),2-Recover,95.303,1.251,1.227,0.104,,0.495157,1324.17,,49.5157,1.32417,,,,7.85398e-5
1:0.25 (rep 1),2-Recover,95.67,1.27,1.208,0.091,,0.48749,1158.65,,48.749,1.15865,,,,7.85398e-5
1:0.25 (rep 1),2-Recover,96.037,1.288,1.19,0.098,,0.480226,1247.78,,48.0226,1.24778,,,,7.85398e-5
1:0.25 (rep 1),2-Recover,96.403,1.305,1.173,0.077,,0.473366,980.395,,47.3366,0.980395,,,,7.85398e-5
1:0.25 (rep 1),2-Recover,96.77,1.324,1.154,0.084,,0.465698,1069.52,,46.5698,1.06952,,,,7.85398e-5
1:0.25 (rep 1),2-Recover,97.137,1.342,1.136,0.084,,0.458434,1069.52,,45.8434,1.06952,,,,7.85398e-5
1:0.25 (rep 1),2-Recover,97.503,1.36,1.118,0.084,,0.45117,1069.52,,45.117,1.06952,,,,7.85398e-5
1:0.25 (rep 1),2-Recover,97.87,1.379,1.099,0.084,,0.443503,1069.52,,44.3503,1.06952,,,,7.85398e-5
1:0.25 (rep 1),2-Recover,98.237,1.397,1.081,0.064,,0.436239,814.873,,43.6239,0.814873,,,,7.85398e-5
1:0.25 (rep 1),2-Recover,98.603,1.415,1.063,0.057,,0.428975,725.747,,42.8975,0.725747,,,,7.85398e-5
1:0.25 (rep 1),2-Recover,98.97,1.434,1.044,0.05,,0.421308,636.62,,42.1308,0.63662,,,,7.85398e-5
1:0.25 (rep 1),2-Recover,99.337,1.452,1.026,0.064,,0.414044,814.873,,41.4044,0.814873,,,,7.85398e-5
1:0.25 (rep 1),2-Recover,99.703,1.47,1.008,0.05,,0.40678,636.62,,40.678,0.63662,,,,7.85398e-5
1:0.25 (rep 1),2-Recover,100.07,1.488,0.99,0.07,,0.399516,891.268,,39.9516,0.891268,,,,7.85398e-5
1:0.25 (rep 1),2-Recover,100.437,1.506,0.972,0.064,,0.392252,814.873,,39.2252,0.814873,,,,7.85398e-5
1:0.25 (rep 1),2-Recover,100.803,1.524,0.954,0.057,,0.384988,725.747,,38.4988,0.725747,,,,7.85398e-5
1:0.25 (rep 1),2-Recover,101.17,1.542,0.936,0.057,,0.377724,725.747,,37.7724,0.725747,,,,7.85398e-5
1:0.25 (rep 1),2-Recover,101.537,1.561,0.917,0.05,,0.370056,636.62,,37.0056,0.63662,,,,7.85398e-5
1:0.25 (rep 1),2-Recover,101.903,1.579,0.899,0.05,,0.362793,636.62,,36.2793,0.63662,,,,7.85398e-5
1:0.25 (rep 1),2-Recover,102.27,1.597,0.881,0.057,,0.355529,725.747,,35.5529,0.725747,,,,7.85398e-5
1:0.25 (rep 1),2-Recover,102.637,1.616,0.862,0.05,,0.347861,636.62,,34.7861,0.63662,,,,7.85398e-5
1:0.25 (rep 1),2-Recover,103.003,1.634,0.844,0.05,,0.340597,636.62,,34.0597,0.63662,,,,7.85398e-5
1:0.25 (rep 1),2-Recover,103.37,1.652,0.826,0.05,,0.333333,636.62,,33.3333,0.63662,,,,7.85398e-5
1:0.25 (rep 1),2-Recover,103.737,1.67,0.808,0.05,,0.326069,636.62,,32.6069,0.63662,,,,7.85398e-5
1:0.25 (rep 1),2-Recover,104.103,1.688,0.79,0.05,,0.318805,636.62,,31.8805,0.63662,,,,7.85398e-5
1:0.25 (rep 1),2-Recover,104.47,1.706,0.772,0.05,,0.311542,636.62,,31.1542,0.63662,,,,7.85398e-5
1:0.25 (rep 1),2-Recover,104.837,1.725,0.753,0.057,,0.303874,725.747,,30.3874,0.725747,,,,7.85398e-5
1:0.25 (rep 1),2-Recover,105.203,1.742,0.736,0.05,,0.297014,636.62,,29.7014,0.63662,,,,7.85398e-5
1:0.25 (rep 1),2-Recover,105.57,1.761,0.717,0.05,,0.289346,636.62,,28.9346,0.63662,,,,7.85398e-5
1:0.25 (rep 1),2-Recover,105.937,1.779,0.699,0.05,,0.282082,636.62,,28.2082,0.63662,,,,7.85398e-5
1:0.25 (rep 1),2-Recover,106.303,1.797,0.681,0.05,,0.274818,636.62,,27.4818,0.63662,,,,7.85398e-5
1:0.25 (rep 1),2-Recover,106.67,1.816,0.662,0.05,,0.267151,636.62,,26.7151,0.63662,,,,7.85398e-5
1:0.25 (rep 1),2-Recover,107.037,1.834,0.644,0.05,,0.259887,636.62,,25.9887,0.63662,,,,7.85398e-5
1:0.25 (rep 1),2-Recover,107.403,1.852,0.626,0.05,,0.252623,636.62,,25.2623,0.63662,,,,7.85398e-5
1:0.25 (rep 1),2-Recover,107.77,1.87,0.608,0.05,,0.245359,636.62,,24.5359,0.63662,,,,7.85398e-5
1:0.25 (rep 1),2-Recover,108.137,1.889,0.589,0.05,,0.237692,636.62,,23.7692,0.63662,,,,7.85398e-5
1:0.25 (rep 1),2-Recover,108.503,1.907,0.571,0.05,,0.230428,636.62,,23.0428,0.63662,,,,7.85398e-5
1:0.25 (rep 1),2-Recover,108.87,1.925,0.553,0.043,,0.223164,547.493,,22.3164,0.547493,,,,7.85398e-5
1:0.25 (rep 1),2-Recover,109.237,1.943,0.535,0.05,,0.2159,636.62,,21.59,0.63662,,,,7.85398e-5
1:0.25 (rep 1),2-Recover,109.603,1.961,0.517,0.043,,0.208636,547.493,,20.8636,0.547493,,,,7.85398e-5
1:0.25 (rep 1),2-Recover,109.97,1.979,0.499,0.036,,0.201372,458.366,,20.1372,0.458366,,,,7.85398e-5
1:0.25 (rep 1),2-Recover,110.337,1.998,0.48,0.05,,0.193705,636.62,,19.3705,0.63662,,,,7.85398e-5
1:0.25 (rep 1),2-Recover,110.703,2.016,0.462,0.05,,0.186441,636.62,,18.6441,0.63662,,,,7.85398e-5
1:0.25 (rep 1),2-Recover,111.07,2.034,0.444,0.03,,0.179177,381.972,,17.9177,0.381972,,,,7.85398e-5
1:0.25 (rep 1),2-Recover,111.437,2.053,0.425,0.05,,0.171509,636.62,,17.1509,0.63662,,,,7.85398e-5
1:0.25 (rep 1),2-Recover,111.803,2.07,0.408,0.03,,0.164649,381.972,,16.4649,0.381972,,,,7.85398e-5
1:0.25 (rep 1),2-Recover,112.17,2.089,0.389,0.036,,0.156981,458.366,,15.6981,0.458366,,,,7.85398e-5
1:0.25 (rep 1),2-Recover,112.537,2.107,0.371,0.03,,0.149718,381.972,,14.9718,0.381972,,,,7.85398e-5
1:0.25 (rep 1),2-Recover,112.903,2.125,0.353,0.043,,0.142454,547.493,,14.2454,0.547493,,,,7.85398e-5
1:0.25 (rep 1),2-Recover,113.27,2.143,0.335,0.016,,0.13519,203.718,,13.519,0.203718,,,,7.85398e-5
1:0.25 (rep 1),2-Recover,113.637,2.162,0.316,0.03,,0.127522,381.972,,12.7522,0.381972,,,,7.85398e-5
1:0.25 (rep 1),2-Recover,114.003,2.179,0.299,0.009,,0.120662,114.592,,12.0662,0.114592,,,,7.85398e-5
1:0.25 (rep 1),2-Recover,114.37,2.198,0.28,0.016,,0.112994,203.718,,11.2994,0.203718,,,,7.85398e-5
1:0.25 (rep 1),2-Recover,114.737,2.216,0.262,0.023,,0.10573,292.845,,10.573,0.292845,,,,7.85398e-5
1:0.25 (rep 1),2-Recover,115.103,2.234,0.244,0.023,,0.0984665,292.845,,9.84665,0.292845,,,,7.85398e-5
1:0.25 (rep 1),2-Recover,115.47,2.253,0.225,0.016,,0.090799,203.718,,9.0799,0.203718,,,,7.85398e-5
1:0.25 (rep 1),2-Recover,115.837,2.271,0.207,0.016,,0.0835351,203.718,,8.35351,0.203718,,,,7.85398e-5
1:0.25 (rep 1),2-Recover,116.203,2.289,0.189,0.009,,0.0762712,114.592,,7.62712,0.114592,,,,7.85398e-5
1:0.25 (rep 1),2-Recover,116.57,2.307,0.171,0.002,,0.0690073,25.4648,,6.90073,0.0254648,,,,7.85398e-5
1:0.25 (rep 1),2-Recover,116.937,2.326,0.152,0.023,,0.0613398,292.845,,6.13398,0.292845,,,,7.85398e-5
1:0.25 (rep 1),2-Recover,117.303,2.344,0.134,0.016,,0.0540759,203.718,,5.40759,0.203718,,,,7.85398e-5
1:0.25 (rep 1),2-Recover,117.67,2.362,0.116,0.016,,0.0468119,203.718,,4.68119,0.203718,,,,7.85398e-5
1:0.25 (rep 1),2-Recover,118.037,2.38,0.098,0.016,,0.039548,203.718,,3.9548,0.203718,,,,7.85398e-5
1:0.25 (rep 1),2-Recover,118.403,2.398,0.08,0.009,,0.0322841,114.592,,3.22841,0.114592,,,,7.85398e-5
1:0.25 (rep 1),2-Recover,118.77,2.416,0.062,0.002,,0.0250202,25.4648,,2.50202,0.0254648,,,,7.85398e-5
1:0.25 (rep 1),2-Recover,119.137,2.435,0.043,0.002,,0.0173527,25.4648,,1.73527,0.0254648,,,,7.85398e-5
1:0.25 (rep 1),2-Recover,119.503,2.453,0.025,0.016,,0.0100888,203.718,,1.00888,0.203718,,,,7.85398e-5
1:0.25 (rep 1),2-Recover,119.87,2.471,0.007,0.002,,0.00282486,25.4648,,0.282486,0.0254648,,,,7.85398e-5
1:0.25 (rep 1),3-Compress,120.223,2.471,0.007,0.023,,0.00282486,292.845,,0.282486,0.292845,,,,7.85398e-5
1:0.25 (rep 1),3-Compress,120.59,2.453,0.025,0.002,,0.0100888,25.4648,,1.00888,0.0254648,,,,7.85398e-5
1:0.25 (rep 1),3-Compress,120.957,2.434,0.044,0.009,,0.0177563,114.592,,1.77563,0.114592,,,,7.85398e-5
1:0.25 (rep 1),3-Compress,121.323,2.416,0.062,0.002,,0.0250202,25.4648,,2.50202,0.0254648,,,,7.85398e-5
1:0.25 (rep 1),3-Compress,121.69,2.398,0.08,0.002,,0.0322841,25.4648,,3.22841,0.0254648,,,,7.85398e-5
1:0.25 (rep 1),3-Compress,122.057,2.38,0.098,0.016,,0.039548,203.718,,3.9548,0.203718,,,,7.85398e-5
1:0.25 (rep 1),3-Compress,122.423,2.362,0.116,0.03,,0.0468119,381.972,,4.68119,0.381972,,,,7.85398e-5
1:0.25 (rep 1),3-Compress,122.79,2.344,0.134,0.03,,0.0540759,381.972,,5.40759,0.381972,,,,7.85398e-5
1:0.25 (rep 1),3-Compress,123.157,2.325,0.153,0.023,,0.0617433,292.845,,6.17433,0.292845,,,,7.85398e-5
1:0.25 (rep 1),3-Compress,123.523,2.307,0.171,0.016,,0.0690073,203.718,,6.90073,0.203718,,,,7.85398e-5
1:0.25 (rep 1),3-Compress,123.89,2.289,0.189,0.036,,0.0762712,458.366,,7.62712,0.458366,,,,7.85398e-5
1:0.25 (rep 1),3-Compress,124.257,2.27,0.208,0.023,,0.0839387,292.845,,8.39387,0.292845,,,,7.85398e-5
1:0.25 (rep 1),3-Compress,124.623,2.253,0.225,0.03,,0.090799,381.972,,9.0799,0.381972,,,,7.85398e-5
1:0.25 (rep 1),3-Compress,124.99,2.234,0.244,0.043,,0.0984665,547.493,,9.84665,0.547493,,,,7.85398e-5
1:0.25 (rep 1),3-Compress,125.357,2.216,0.262,0.036,,0.10573,458.366,,10.573,0.458366,,,,7.85398e-5
1:0.25 (rep 1),3-Compress,125.723,2.198,0.28,0.023,,0.112994,292.845,,11.2994,0.292845,,,,7.85398e-5
1:0.25 (rep 1),3-Compress,126.09,2.179,0.299,0.036,,0.120662,458.366,,12.0662,0.458366,,,,7.85398e-5
1:0.25 (rep 1),3-Compress,126.457,2.162,0.316,0.05,,0.127522,636.62,,12.7522,0.63662,,,,7.85398e-5
1:0.25 (rep 1),3-Compress,126.823,2.143,0.335,0.036,,0.13519,458.366,,13.519,0.458366,,,,7.85398e-5
1:0.25 (rep 1),3-Compress,127.19,2.125,0.353,0.036,,0.142454,458.366,,14.2454,0.458366,,,,7.85398e-5
1:0.25 (rep 1),3-Compress,127.557,2.107,0.371,0.05,,0.149718,636.62,,14.9718,0.63662,,,,7.85398e-5
1:0.25 (rep 1),3-Compress,127.923,2.089,0.389,0.043,,0.156981,547.493,,15.6981,0.547493,,,,7.85398e-5
1:0.25 (rep 1),3-Compress,128.29,2.07,0.408,0.05,,0.164649,636.62,,16.4649,0.63662,,,,7.85398e-5
1:0.25 (rep 1),3-Compress,128.657,2.052,0.426,0.05,,0.171913,636.62,,17.1913,0.63662,,,,7.85398e-5
1:0.25 (rep 1),3-Compress,129.023,2.034,0.444,0.057,,0.179177,725.747,,17.9177,0.725747,,,,7.85398e-5
1:0.25 (rep 1),3-Compress,129.39,2.016,0.462,0.05,,0.186441,636.62,,18.6441,0.63662,,,,7.85398e-5
1:0.25 (rep 1),3-Compress,129.757,1.997,0.481,0.05,,0.194108,636.62,,19.4108,0.63662,,,,7.85398e-5
1:0.25 (rep 1),3-Compress,130.123,1.979,0.499,0.05,,0.201372,636.62,,20.1372,0.63662,,,,7.85398e-5
1:0.25 (rep 1),3-Compress,130.49,1.961,0.517,0.05,,0.208636,636.62,,20.8636,0.63662,,,,7.85398e-5
1:0.25 (rep 1),3-Compress,130.857,1.943,0.535,0.05,,0.2159,636.62,,21.59,0.63662,,,,7.85398e-5
1:0.25 (rep 1),3-Compress,131.223,1.925,0.553,0.05,,0.223164,636.62,,22.3164,0.63662,,,,7.85398e-5
1:0.25 (rep 1),3-Compress,131.59,1.907,0.571,0.05,,0.230428,636.62,,23.0428,0.63662,,,,7.85398e-5
1:0.25 (rep 1),3-Compress,131.957,1.888,0.59,0.05,,0.238095,636.62,,23.8095,0.63662,,,,7.85398e-5
1:0.25 (rep 1),3-Compress,132.323,1.87,0.608,0.05,,0.245359,636.62,,24.5359,0.63662,,,,7.85398e-5
1:0.25 (rep 1),3-Compress,132.69,1.852,0.626,0.05,,0.252623,636.62,,25.2623,0.63662,,,,7.85398e-5
1:0.25 (rep 1),3-Compress,133.057,1.833,0.645,0.05,,0.260291,636.62,,26.0291,0.63662,,,,7.85398e-5
1:0.25 (rep 1),3-Compress,133.423,1.816,0.662,0.05,,0.267151,636.62,,26.7151,0.63662,,,,7.85398e-5
1:0.25 (rep 1),3-Compress,133.79,1.797,0.681,0.05,,0.274818,636.62,,27.4818,0.63662,,,,7.85398e-5
1:0.25 (rep 1),3-Compress,134.157,1.779,0.699,0.05,,0.282082,636.62,,28.2082,0.63662,,,,7.85398e-5
1:0.25 (rep 1),3-Compress,134.523,1.761,0.717,0.05,,0.289346,636.62,,28.9346,0.63662,,,,7.85398e-5
1:0.25 (rep 1),3-Compress,134.89,1.742,0.736,0.05,,0.297014,636.62,,29.7014,0.63662,,,,7.85398e-5
1:0.25 (rep 1),3-Compress,135.257,1.725,0.753,0.05,,0.303874,636.62,,30.3874,0.63662,,,,7.85398e-5
1:0.25 (rep 1),3-Compress,135.623,1.706,0.772,0.05,,0.311542,636.62,,31.1542,0.63662,,,,7.85398e-5
1:0.25 (rep 1),3-Compress,135.99,1.688,0.79,0.057,,0.318805,725.747,,31.8805,0.725747,,,,7.85398e-5
1:0.25 (rep 1),3-Compress,136.357,1.67,0.808,0.05,,0.326069,636.62,,32.6069,0.63662,,,,7.85398e-5
1:0.25 (rep 1),3-Compress,136.723,1.652,0.826,0.05,,0.333333,636.62,,33.3333,0.63662,,,,7.85398e-5
1:0.25 (rep 1),3-Compress,137.09,1.634,0.844,0.05,,0.340597,636.62,,34.0597,0.63662,,,,7.85398e-5
1:0.25 (rep 1),3-Compress,137.457,1.615,0.863,0.05,,0.348265,636.62,,34.8265,0.63662,,,,7.85398e-5
1:0.25 (rep 1),3-Compress,137.823,1.597,0.881,0.064,,0.355529,814.873,,35.5529,0.814873,,,,7.85398e-5
1:0.25 (rep 1),3-Compress,138.19,1.579,0.899,0.057,,0.362793,725.747,,36.2793,0.725747,,,,7.85398e-5
1:0.25 (rep 1),3-Compress,138.557,1.56,0.918,0.057,,0.37046,725.747,,37.046,0.725747,,,,7.85398e-5
1:0.25 (rep 1),3-Compress,138.923,1.542,0.936,0.057,,0.377724,725.747,,37.7724,0.725747,,,,7.85398e-5
1:0.25 (rep 1),3-Compress,139.29,1.524,0.954,0.05,,0.384988,636.62,,38.4988,0.63662,,,,7.85398e-5
1:0.25 (rep 1),3-Compress,139.657,1.506,0.972,0.057,,0.392252,725.747,,39.2252,0.725747,,,,7.85398e-5
1:0.25 (rep 1),3-Compress,140.023,1.488,0.99,0.077,,0.399516,980.395,,39.9516,0.980395,,,,7.85398e-5
1:0.25 (rep 1),3-Compress,140.39,1.47,1.008,0.07,,0.40678,891.268,,40.678,0.891268,,,,7.85398e-5
1:0.25 (rep 1),3-Compress,140.757,1.451,1.027,0.07,,0.414447,891.268,,41.4447,0.891268,,,,7.85398e-5
1:0.25 (rep 1),3-Compress,141.123,1.434,1.044,0.07,,0.421308,891.268,,42.1308,0.891268,,,,7.85398e-5
1:0.25 (rep 1),3-Compress,141.49,1.415,1.063,0.064,,0.428975,814.873,,42.8975,0.814873,,,,7.85398e-5
1:0.25 (rep 1),3-Compress,141.857,1.397,1.081,0.064,,0.436239,814.873,,43.6239,0.814873,,,,7.85398e-5
1:0.25 (rep 1),3-Compress,142.223,1.379,1.099,0.077,,0.443503,980.395,,44.3503,0.980395,,,,7.85398e-5
1:0.25 (rep 1),3-Compress,142.59,1.36,1.118,0.091,,0.45117,1158.65,,45.117,1.15865,,,,7.85398e-5
1:0.25 (rep 1),3-Compress,142.957,1.342,1.136,0.098,,0.458434,1247.78,,45.8434,1.24778,,,,7.85398e-5
1:0.25 (rep 1),3-Compress,143.323,1.324,1.154,0.098,,0.465698,1247.78,,46.5698,1.24778,,,,7.85398e-5
1:0.25 (rep 1),3-Compress,143.69,1.305,1.173,0.091,,0.473366,1158.65,,47.3366,1.15865,,,,7.85398e-5
1:0.25 (rep 1),3-Compress,144.057,1.288,1.19,0.104,,0.480226,1324.17,,48.0226,1.32417,,,,7.85398e-5
1:0.25 (rep 1),3-Compress,144.423,1.27,1.208,0.091,,0.48749,1158.65,,48.749,1.15865,,,,7.85398e-5
1:0.25 (rep 1),3-Compress,144.79,1.251,1.227,0.104,,0.495157,1324.17,,49.5157,1.32417,,,,7.85398e-5
1:0.25 (rep 1),3-Compress,145.157,1.233,1.245,0.104,,0.502421,1324.17,,50.2421,1.32417,,,,7.85398e-5
1:0.25 (rep 1),3-Compress,145.523,1.215,1.263,0.104,,0.509685,1324.17,,50.9685,1.32417,,,,7.85398e-5
1:0.25 (rep 1),3-Compress,145.89,1.197,1.281,0.104,,0.516949,1324.17,,51.6949,1.32417,,,,7.85398e-5
1:0.25 (rep 1),3-Compress,146.257,1.178,1.3,0.104,,0.524617,1324.17,,52.4617,1.32417,,,,7.85398e-5
1:0.25 (rep 1),3-Compress,146.623,1.16,1.318,0.104,,0.531881,1324.17,,53.1881,1.32417,,,,7.85398e-5
1:0.25 (rep 1),3-Compress,146.99,1.142,1.336,0.104,,0.539144,1324.17,,53.9144,1.32417,,,,7.85398e-5
1:0.25 (rep 1),3-Compress,147.357,1.123,1.355,0.104,,0.546812,1324.17,,54.6812,1.32417,,,,7.85398e-5
1:0.25 (rep 1),3-Compress,147.723,1.106,1.372,0.104,,0.553672,1324.17,,55.3672,1.32417,,,,7.85398e-5
1:0.25 (rep 1),3-Compress,148.09,1.087,1.391,0.104,,0.56134,1324.17,,56.134,1.32417,,,,7.85398e-5
1:0.25 (rep 1),3-Compress,148.457,1.069,1.409,0.104,,0.568604,1324.17,,56.8604,1.32417,,,,7.85398e-5
1:0.25 (rep 1),3-Compress,148.823,1.051,1.427,0.111,,0.575868,1413.3,,57.5868,1.4133,,,,7.85398e-5
1:0.25 (rep 1),3-Compress,149.19,1.033,1.445,0.104,,0.583132,1324.17,,58.3132,1.32417,,,,7.85398e-5
1:0.25 (rep 1),3-Compress,149.557,1.014,1.464,0.104,,0.590799,1324.17,,59.0799,1.32417,,,,7.85398e-5
1:0.25 (rep 1),3-Compress,149.923,0.997,1.481,0.118,,0.597659,1502.42,,59.7659,1.50242,,,,7.85398e-5
1:0.25 (rep 1),3-Recover,150.267,0.999,1.479,0.131,,0.596852,1667.94,,59.6852,1.66794,,,,7.85398e-5
1:0.25 (rep 1),3-Recover,150.633,1.017,1.461,0.118,,0.589588,1502.42,,58.9588,1.50242,,,,7.85398e-5
1:0.25 (rep 1),3-Recover,151,1.036,1.442,0.104,,0.581921,1324.17,,58.1921,1.32417,,,,7.85398e-5
1:0.25 (rep 1),3-Recover,151.367,1.054,1.424,0.111,,0.574657,1413.3,,57.4657,1.4133,,,,7.85398e-5
1:0.25 (rep 1),3-Recover,151.733,1.072,1.406,0.104,,0.567393,1324.17,,56.7393,1.32417,,,,7.85398e-5
1:0.25 (rep 1),3-Recover,152.1,1.09,1.388,0.104,,0.560129,1324.17,,56.0129,1.32417,,,,7.85398e-5
1:0.25 (rep 1),3-Recover,152.467,1.109,1.369,0.104,,0.552462,1324.17,,55.2462,1.32417,,,,7.85398e-5
1:0.25 (rep 1),3-Recover,152.833,1.127,1.351,0.104,,0.545198,1324.17,,54.5198,1.32417,,,,7.85398e-5
1:0.25 (rep 1),3-Recover,153.2,1.145,1.333,0.104,,0.537934,1324.17,,53.7934,1.32417,,,,7.85398e-5
1:0.25 (rep 1),3-Recover,153.567,1.164,1.314,0.104,,0.530266,1324.17,,53.0266,1.32417,,,,7.85398e-5
1:0.25 (rep 1),3-Recover,153.933,1.181,1.297,0.104,,0.523406,1324.17,,52.3406,1.32417,,,,7.85398e-5
1:0.25 (rep 1),3-Recover,154.3,1.2,1.278,0.104,,0.515738,1324.17,,51.5738,1.32417,,,,7.85398e-5
1:0.25 (rep 1),3-Recover,154.667,1.218,1.26,0.098,,0.508475,1247.78,,50.8475,1.24778,,,,7.85398e-5
1:0.25 (rep 1),3-Recover,155.033,1.236,1.242,0.098,,0.501211,1247.78,,50.1211,1.24778,,,,7.85398e-5
1:0.25 (rep 1),3-Recover,155.4,1.254,1.224,0.104,,0.493947,1324.17,,49.3947,1.32417,,,,7.85398e-5
1:0.25 (rep 1),3-Recover,155.767,1.272,1.206,0.098,,0.486683,1247.78,,48.6683,1.24778,,,,7.85398e-5
1:0.25 (rep 1),3-Recover,156.133,1.29,1.188,0.104,,0.479419,1324.17,,47.9419,1.32417,,,,7.85398e-5
1:0.25 (rep 1),3-Recover,156.5,1.309,1.169,0.07,,0.471751,891.268,,47.1751,0.891268,,,,7.85398e-5
1:0.25 (rep 1),3-Recover,156.867,1.327,1.151,0.064,,0.464487,814.873,,46.4487,0.814873,,,,7.85398e-5
1:0.25 (rep 1),3-Recover,157.233,1.345,1.133,0.064,,0.457224,814.873,,45.7224,0.814873,,,,7.85398e-5
1:0.25 (rep 1),3-Recover,157.6,1.364,1.114,0.07,,0.449556,891.268,,44.9556,0.891268,,,,7.85398e-5
1:0.25 (rep 1),3-Recover,157.967,1.382,1.096,0.07,,0.442292,891.268,,44.2292,0.891268,,,,7.85398e-5
1:0.25 (rep 1),3-Recover,158.333,1.4,1.078,0.07,,0.435028,891.268,,43.5028,0.891268,,,,7.85398e-5
1:0.25 (rep 1),3-Recover,158.7,1.418,1.06,0.057,,0.427764,725.747,,42.7764,0.725747,,,,7.85398e-5
1:0.25 (rep 1),3-Recover,159.067,1.436,1.042,0.057,,0.4205,725.747,,42.05,0.725747,,,,7.85398e-5
1:0.25 (rep 1),3-Recover,159.433,1.454,1.024,0.05,,0.413236,636.62,,41.3236,0.63662,,,,7.85398e-5
1:0.25 (rep 1),3-Recover,159.8,1.472,1.006,0.05,,0.405973,636.62,,40.5973,0.63662,,,,7.85398e-5
1:0.25 (rep 1),3-Recover,160.167,1.491,0.987,0.057,,0.398305,725.747,,39.8305,0.725747,,,,7.85398e-5
1:0.25 (rep 1),3-Recover,160.533,1.509,0.969,0.057,,0.391041,725.747,,39.1041,0.725747,,,,7.85398e-5
1:0.25 (rep 1),3-Recover,160.9,1.527,0.951,0.05,,0.383777,636.62,,38.3777,0.63662,,,,7.85398e-5
1:0.25 (rep 1),3-Recover,161.267,1.546,0.932,0.057,,0.37611,725.747,,37.611,0.725747,,,,7.85398e-5
1:0.25 (rep 1),3-Recover,161.633,1.564,0.914,0.057,,0.368846,725.747,,36.8846,0.725747,,,,7.85398e-5
1:0.25 (rep 1),3-Recover,162,1.582,0.896,0.05,,0.361582,636.62,,36.1582,0.63662,,,,7.85398e-5
1:0.25 (rep 1),3-Recover,162.367,1.601,0.877,0.057,,0.353914,725.747,,35.3914,0.725747,,,,7.85398e-5
1:0.25 (rep 1),3-Recover,162.733,1.618,0.86,0.05,,0.347054,636.62,,34.7054,0.63662,,,,7.85398e-5
1:0.25 (rep 1),3-Recover,163.1,1.636,0.842,0.05,,0.33979,636.62,,33.979,0.63662,,,,7.85398e-5
1:0.25 (rep 1),3-Recover,163.467,1.655,0.823,0.05,,0.332123,636.62,,33.2123,0.63662,,,,7.85398e-5
1:0.25 (rep 1),3-Recover,163.833,1.672,0.806,0.05,,0.325262,636.62,,32.5262,0.63662,,,,7.85398e-5
1:0.25 (rep 1),3-Recover,164.2,1.691,0.787,0.05,,0.317595,636.62,,31.7595,0.63662,,,,7.85398e-5
1:0.25 (rep 1),3-Recover,164.567,1.709,0.769,0.05,,0.310331,636.62,,31.0331,0.63662,,,,7.85398e-5
1:0.25 (rep 1),3-Recover,164.933,1.727,0.751,0.05,,0.303067,636.62,,30.3067,0.63662,,,,7.85398e-5
1:0.25 (rep 1),3-Recover,165.3,1.746,0.732,0.05,,0.2954,636.62,,29.54,0.63662,,,,7.85398e-5
1:0.25 (rep 1),3-Recover,165.667,1.764,0.714,0.05,,0.288136,636.62,,28.8136,0.63662,,,,7.85398e-5
1:0.25 (rep 1),3-Recover,166.033,1.782,0.696,0.05,,0.280872,636.62,,28.0872,0.63662,,,,7.85398e-5
1:0.25 (rep 1),3-Recover,166.4,1.8,0.678,0.05,,0.273608,636.62,,27.3608,0.63662,,,,7.85398e-5
1:0.25 (rep 1),3-Recover,166.767,1.819,0.659,0.05,,0.26594,636.62,,26.594,0.63662,,,,7.85398e-5
1:0.25 (rep 1),3-Recover,167.133,1.837,0.641,0.05,,0.258676,636.62,,25.8676,0.63662,,,,7.85398e-5
1:0.25 (rep 1),3-Recover,167.5,1.855,0.623,0.05,,0.251412,636.62,,25.1412,0.63662,,,,7.85398e-5
1:0.25 (rep 1),3-Recover,167.867,1.873,0.605,0.05,,0.244149,636.62,,24.4149,0.63662,,,,7.85398e-5
1:0.25 (rep 1),3-Recover,168.233,1.891,0.587,0.05,,0.236885,636.62,,23.6885,0.63662,,,,7.85398e-5
1:0.25 (rep 1),3-Recover,168.6,1.909,0.569,0.05,,0.229621,636.62,,22.9621,0.63662,,,,7.85398e-5
1:0.25 (rep 1),3-Recover,168.967,1.928,0.55,0.05,,0.221953,636.62,,22.1953,0.63662,,,,7.85398e-5
1:0.25 (rep 1),3-Recover,169.333,1.946,0.532,0.05,,0.214689,636.62,,21.4689,0.63662,,,,7.85398e-5
1:0.25 (rep 1),3-Recover,169.7,1.964,0.514,0.05,,0.207425,636.62,,20.7425,0.63662,,,,7.85398e-5
1:0.25 (rep 1),3-Recover,170.067,1.983,0.495,0.036,,0.199758,458.366,,19.9758,0.458366,,,,7.85398e-5
1:0.25 (rep 1),3-Recover,170.433,2,0.478,0.05,,0.192897,636.62,,19.2897,0.63662,,,,7.85398e-5
1:0.25 (rep 1),3-Recover,170.8,2.019,0.459,0.043,,0.18523,547.493,,18.523,0.547493,,,,7.85398e-5
1:0.25 (rep 1),3-Recover,171.167,2.037,0.441,0.03,,0.177966,381.972,,17.7966,0.381972,,,,7.85398e-5
1:0.25 (rep 1),3-Recover,171.533,2.055,0.423,0.05,,0.170702,636.62,,17.0702,0.63662,,,,7.85398e-5
1:0.25 (rep 1),3-Recover,171.9,2.073,0.405,0.043,,0.163438,547.493,,16.3438,0.547493,,,,7.85398e-5
1:0.25 (rep 1),3-Recover,172.267,2.092,0.386,0.036,,0.155771,458.366,,15.5771,0.458366,,,,7.85398e-5
1:0.25 (rep 1),3-Recover,172.633,2.109,0.369,0.036,,0.14891,458.366,,14.891,0.458366,,,,7.85398e-5
1:0.25 (rep 1),3-Recover,173,2.128,0.35,0.05,,0.141243,636.62,,14.1243,0.63662,,,,7.85398e-5
1:0.25 (rep 1),3-Recover,173.367,2.146,0.332,0.03,,0.133979,381.972,,13.3979,0.381972,,,,7.85398e-5
1:0.25 (rep 1),3-Recover,173.733,2.164,0.314,0.016,,0.126715,203.718,,12.6715,0.203718,,,,7.85398e-5
1:0.25 (rep 1),3-Recover,174.1,2.183,0.295,0.023,,0.119048,292.845,,11.9048,0.292845,,,,7.85398e-5
1:0.25 (rep 1),3-Recover,174.467,2.201,0.277,0.03,,0.111784,381.972,,11.1784,0.381972,,,,7.85398e-5
1:0.25 (rep 1),3-Recover,174.833,2.219,0.259,0.009,,0.10452,114.592,,10.452,0.114592,,,,7.85398e-5
1:0.25 (rep 1),3-Recover,175.2,2.237,0.241,0.023,,0.0972559,292.845,,9.72559,0.292845,,,,7.85398e-5
1:0.25 (rep 1),3-Recover,175.567,2.256,0.222,0.03,,0.0895884,381.972,,8.95884,0.381972,,,,7.85398e-5
1:0.25 (rep 1),3-Recover,175.933,2.274,0.204,0.016,,0.0823245,203.718,,8.23245,0.203718,,,,7.85398e-5
1:0.25 (rep 1),3-Recover,176.3,2.292,0.186,0.023,,0.0750605,292.845,,7.50605,0.292845,,,,7.85398e-5
1:0.25 (rep 1),3-Recover,176.667,2.31,0.168,0.002,,0.0677966,25.4648,,6.77966,0.0254648,,,,7.85398e-5
1:0.25 (rep 1),3-Recover,177.033,2.328,0.15,0.002,,0.0605327,25.4648,,6.05327,0.0254648,,,,7.85398e-5
1:0.25 (rep 1),3-Recover,177.4,2.346,0.132,0.009,,0.0532688,114.592,,5.32688,0.114592,,,,7.85398e-5
1:0.25 (rep 1),3-Recover,177.767,2.365,0.113,0.016,,0.0456013,203.718,,4.56013,0.203718,,,,7.85398e-5
1:0.25 (rep 1),3-Recover,178.133,2.383,0.095,0.03,,0.0383374,381.972,,3.83374,0.381972,,,,7.85398e-5
1:0.25 (rep 1),3-Recover,178.5,2.401,0.077,0.016,,0.0310734,203.718,,3.10734,0.203718,,,,7.85398e-5
1:0.25 (rep 1),3-Recover,178.867,2.42,0.058,0.009,,0.023406,114.592,,2.3406,0.114592,,,,7.85398e-5
1:0.25 (rep 1),3-Recover,179.233,2.437,0.041,0.002,,0.0165456,25.4648,,1.65456,0.0254648,,,,7.85398e-5
1:0.25 (rep 1),3-Recover,179.6,2.456,0.022,0.002,,0.00887813,25.4648,,0.887813,0.0254648,,,,7.85398e-5
1:0.25 (rep 1),3-Recover,179.967,2.474,0.004,0.016,,0.00161421,203.718,,0.161421,0.203718,,,,7.85398e-5
1:0.25 (rep 1),3-Recover,180.1,2.478,0,0.016,,0,203.718,,0,0.203718,,,,7.85398e-5