File: data/beta_1-0_2.csv
SetName,Cycle,Time_S,Size_mm,Displacement_mm,Force_N,,Strain,Stress(Pascal),,%Strain,Stress(kPa),,,,Area(m^2)
1:0 (rep 2),1-Compress,0,3.158,0,0.023,,0,292.845,,0,0.292845,,,,7.85398e-5
1:0 (rep 2),1-Compress,0.367,3.135,0.023,0.016,,0.00728309,203.718,,0.728309,0.203718,,,,7.85398e-5
1:0 (rep 2),1-Compress,0.733,3.112,0.046,0.016,,0.0145662,203.718,,1.45662,0.203718,,,,7.85398e-5
1:0 (rep 2),1-Compress,1.1,3.089,0.069,0.036,,0.0218493,458.366,,2.18493,0.458366,,,,7.85398e-5
1:0 (rep 2),1-Compress,1.467,3.065,0.093,0.023,,0.029449,292.845,,2.9449,0.292845,,,,7.85398e-5
1:0 (rep 2),1-Compress,1.833,3.043,0.115,0.036,,0.0364155,458.366,,3.64155,0.458366,,,,7.85398e-5
1:0 (rep 2),1-Compress,2.2,3.019,0.139,0.036,,0.0440152,458.366,,4.40152,0.458366,,,,7.85398e-5
1:0 (rep 2),1-Compress,2.567,2.996,0.162,0.05,,0.0512983,636.62,,5.12983,0.63662,,,,7.85398e-5
1:0 (rep 2),1-Compress,2.933,2.973,0.185,0.05,,0.0585814,636.62,,5.85814,0.63662,,,,7.85398e-5
1:0 (rep 2),1-Compress,3.3,2.95,0.208,0.05,,0.0658645,636.62,,6.58645,0.63662,,,,7.85398e-5
1:0 (rep 2),1-Compress,3.667,2.926,0.232,0.05,,0.0734642,636.62,,7.34642,0.63662,,,,7.85398e-5
1:0 (rep 2),1-Compress,4.033,2.904,0.254,0.05,,0.0804307,636.62,,8.04307,0.63662,,,,7.85398e-5
1:0 (rep 2),1-Compress,4.4,2.88,0.278,0.05,,0.0880304,636.62,,8.80304,0.63662,,,,7.85398e-5
1:0 (rep 2),1-Compress,4.767,2.857,0.301,0.05,,0.0953135,636.62,,9.53135,0.63662,,,,7.85398e-5
1:0 (rep 2),1-Compress,5.133,2.834,0.324,0.05,,0.102597,636.62,,10.2597,0.63662,,,,7.85398e-5
1:0 (rep 2),1-Compress,5.5,2.811,0.347,0.05,,0.10988,636.62,,10.988,0.63662,,,,7.85398e-5
1:0 (rep 2),1-Compress,5.867,2.787,0.371,0.05,,0.117479,636.62,,11.7479,0.63662,,,,7.85398e-5
1:0 (rep 2),1-Compress,6.233,2.764,0.394,0.05,,0.124763,636.62,,12.4763,0.63662,,,,7.85398e-5
1:0 (rep 2),1-Compress,6.6,2.741,0.417,0.05,,0.132046,636.62,,13.2046,0.63662,,,,7.85398e-5
1:0 (rep 2),1-Compress,6.967,2.718,0.44,0.057,,0.139329,725.747,,13.9329,0.725747,,,,7.85398e-5
1:0 (rep 2),1-Compress,7.333,2.694,0.464,0.05,,0.146928,636.62,,14.6928,0.63662,,,,7.85398e-5
1:0 (rep 2),1-Compress,7.7,2.671,0.487,0.05,,0.154212,636.62,,15.4212,0.63662,,,,7.85398e-5
1:0 (rep 2),1-Compress,8.067,2.648,0.51,0.05,,0.161495,636.62,,16.1495,0.63662,,,,7.85398e-5
1:0 (rep 2),1-Compress,8.433,2.625,0.533,0.057,,0.168778,725.747,,16.8778,0.725747,,,,7.85398e-5
1:0 (rep 2),1-Compress,8.8,2.602,0.556,0.057,,0.176061,725.747,,17.6061,0.725747,,,,7.85398e-5
1:0 (rep 2),1-Compress,9.167,2.578,0.58,0.05,,0.183661,636.62,,18.3661,0.63662,,,,7.85398e-5
1:0 (rep 2),1-Compress,9.533,2.556,0.602,0.05,,0.190627,636.62,,19.0627,0.63662,,,,7.85398e-5
1:0 (rep 2),1-Compress,9.9,2.532,0.626,0.07,,0.198227,891.268,,19.8227,0.891268,,,,7.85398e-5
1:0 (rep 2),1-Compress,10.267,2.509,0.649,0.077,,0.20551,980.395,,20.551,0.980395,,,,7.85398e-5
1:0 (rep 2),1-Compress,10.633,2.486,0.672,0.07,,0.212793,891.268,,21.2793,0.891268,,,,7.85398e-5
1:0 (rep 2),1-Compress,11,2.462,0.696,0.07,,0.220393,891.268,,22.0393,0.891268,,,,7.85398e-5
1:0 (rep 2),1-Compress,11.367,2.439,0.719,0.064,,0.227676,814.873,,22.7676,0.814873,,,,7.85398e-5
1:0 (rep 2),1-Compress,11.733,2.417,0.741,0.077,,0.234642,980.395,,23.4642,0.980395,,,,7.85398e-5
1:0 (rep 2),1-Compress,12.1,2.393,0.765,0.07,,0.242242,891.268,,24.2242,0.891268,,,,7.85398e-5
1:0 (rep 2),1-Compress,12.467,2.37,0.788,0.098,,0.249525,1247.78,,24.9525,1.24778,,,,7.85398e-5
1:0 (rep 2),1-Compress,12.833,2.347,0.811,0.098,,0.256808,1247.78,,25.6808,1.24778,,,,7.85398e-5
1:0 (rep 2),1-Compress,13.2,2.324,0.834,0.104,,0.264091,1324.17,,26.4091,1.32417,,,,7.85398e-5
1:0 (rep 2),1-Compress,13.567,2.3,0.858,0.104,,0.271691,1324.17,,27.1691,1.32417,,,,7.85398e-5
1:0 (rep 2),1-Compress,13.933,2.277,0.881,0.104,,0.278974,1324.17,,27.8974,1.32417,,,,7.85398e-5
1:0 (rep 2),1-Compress,14.3,2.254,0.904,0.104,,0.286257,1324.17,,28.6257,1.32417,,,,7.85398e-5
1:0 (rep 2),1-Compress,14.667,2.23,0.928,0.104,,0.293857,1324.17,,29.3857,1.32417,,,,7.85398e-5
1:0 (rep 2),1-Compress,15.033,2.207,0.951,0.104,,0.30114,1324.17,,30.114,1.32417,,,,7.85398e-5
1:0 (rep 2),1-Compress,15.4,2.184,0.974,0.104,,0.308423,1324.17,,30.8423,1.32417,,,,7.85398e-5
1:0 (rep 2),1-Compress,15.767,2.161,0.997,0.104,,0.315706,1324.17,,31.5706,1.32417,,,,7.85398e-5
1:0 (rep 2),1-Compress,16.133,2.138,1.02,0.111,,0.322989,1413.3,,32.2989,1.4133,,,,7.85398e-5
1:0 (rep 2),1-Compress,16.5,2.114,1.044,0.104,,0.330589,1324.17,,33.0589,1.32417,,,,7.85398e-5
1:0 (rep 2),1-Compress,16.867,2.091,1.067,0.104,,0.337872,1324.17,,33.7872,1.32417,,,,7.85398e-5
1:0 (rep 2),1-Compress,17.233,2.068,1.09,0.118,,0.345155,1502.42,,34.5155,1.50242,,,,7.85398e-5
1:0 (rep 2),1-Compress,17.6,2.045,1.113,0.125,,0.352438,1591.55,,35.2438,1.59155,,,,7.85398e-5
1:0 (rep 2),1-Compress,17.967,2.021,1.137,0.125,,0.360038,1591.55,,36.0038,1.59155,,,,7.85398e-5
1:0 (rep 2),1-Compress,18.333,1.999,1.159,0.131,,0.367004,1667.94,,36.7004,1.66794,,,,7.85398e-5
1:0 (rep 2),1-Compress,18.7,1.975,1.183,0.125,,0.374604,1591.55,,37.4604,1.59155,,,,7.85398e-5
1:0 (rep 2),1-Compress,19.067,1.952,1.206,0.125,,0.381887,1591.55,,38.1887,1.59155,,,,7.85398e-5
1:0 (rep 2),1-Compress,19.433,1.929,1.229,0.125,,0.38917,1591.55,,38.917,1.59155,,,,7.85398e-5
1:0 (rep 2),1-Compress,19.8,1.906,1.252,0.152,,0.396453,1935.32,,39.6453,1.93532,,,,7.85398e-5
1:0 (rep 2),1-Compress,20.167,1.882,1.276,0.159,,0.404053,2024.45,,40.4053,2.02445,,,,7.85398e-5
1:0 (rep 2),1-Compress,20.533,1.86,1.298,0.159,,0.41102,2024.45,,41.102,2.02445,,,,7.85398e-5
1:0 (rep 2),1-Compress,20.9,1.836,1.322,0.159,,0.418619,2024.45,,41.8619,2.02445,,,,7.85398e-5
1:0 (rep 2),1-Compress,21.267,1.813,1.345,0.159,,0.425902,2024.45,,42.5902,2.02445,,,,7.85398e-5
1:0 (rep 2),1-Compress,21.633,1.79,1.368,0.159,,0.433186,2024.45,,43.3186,2.02445,,,,7.85398e-5
1:0 (rep 2),1-Compress,22,1.766,1.392,0.159,,0.440785,2024.45,,44.0785,2.02445,,,,7.85398e-5
1:0 (rep 2),1-Compress,22.367,1.743,1.415,0.159,,0.448068,2024.45,,44.8068,2.02445,,,,7.85398e-5
1:0 (rep 2),1-Compress,22.733,1.72,1.438,0.159,,0.455351,2024.45,,45.5351,2.02445,,,,7.85398e-5
1:0 (rep 2),1-Compress,23.1,1.697,1.461,0.159,,0.462635,2024.45,,46.2635,2.02445,,,,7.85398e-5
1:0 (rep 2),1-Compress,23.467,1.673,1.485,0.159,,0.470234,2024.45,,47.0234,2.02445,,,,7.85398e-5
1:0 (rep 2),1-Compress,23.833,1.651,1.507,0.159,,0.477201,2024.45,,47.7201,2.02445,,,,7.85398e-5
1:0 (rep 2),1-Compress,24.2,1.627,1.531,0.172,,0.484801,2189.97,,48.4801,2.18997,,,,7.85398e-5
1:0 (rep 2),1-Compress,24.567,1.604,1.554,0.179,,0.492084,2279.1,,49.2084,2.2791,,,,7.85398e-5
1:0 (rep 2),1-Compress,24.933,1.581,1.577,0.186,,0.499367,2368.23,,49.9367,2.36823,,,,7.85398e-5
1:0 (rep 2),1-Compress,25.3,1.558,1.6,0.186,,0.50665,2368.23,,50.665,2.36823,,,,7.85398e-5
1:0 (rep 2),1-Compress,25.667,1.534,1.624,0.199,,0.51425,2533.75,,51.425,2.53375,,,,7.85398e-5
1:0 (rep 2),1-Compress,26.033,1.512,1.646,0.206,,0.521216,2622.87,,52.1216,2.62287,,,,7.85398e-5
1:0 (rep 2),1-Compress,26.4,1.488,1.67,0.213,,0.528816,2712,,52.8816,2.712,,,,7.85398e-5
1:0 (rep 2),1-Compress,26.767,1.465,1.693,0.213,,0.536099,2712,,53.6099,2.712,,,,7.85398e-5
1:0 (rep 2),1-Compress,27.133,1.442,1.716,0.213,,0.543382,2712,,54.3382,2.712,,,,7.85398e-5
1:0 (rep 2),1-Compress,27.5,1.419,1.739,0.206,,0.550665,2622.87,,55.0665,2.62287,,,,7.85398e-5
1:0 (rep 2),1-Compress,27.867,1.395,1.763,0.213,,0.558265,2712,,55.8265,2.712,,,,7.85398e-5
1:0 (rep 2),1-Compress,28.233,1.372,1.786,0.22,,0.565548,2801.13,,56.5548,2.80113,,,,7.85398e-5
1:0 (rep 2),1-Compress,28.6,1.349,1.809,0.227,,0.572831,2890.25,,57.2831,2.89025,,,,7.85398e-5
1:0 (rep 2),1-Compress,28.967,1.326,1.832,0.227,,0.580114,2890.25,,58.0114,2.89025,,,,7.85398e-5
1:0 (rep 2),1-Compress,29.333,1.303,1.855,0.22,,0.587397,2801.13,,58.7397,2.80113,,,,7.85398e-5
1:0 (rep 2),1-Compress,29.7,1.279,1.879,0.227,,0.594997,2890.25,,59.4997,2.89025,,,,7.85398e-5
1:0 (rep 2),1-Recover,30.067,1.266,1.892,0.227,,0.599113,2890.25,,59.9113,2.89025,,,,7.85398e-5
1:0 (rep 2),1-Recover,30.433,1.288,1.87,0.22,,0.592147,2801.13,,59.2147,2.80113,,,,7.85398e-5
1:0 (rep 2),1-Recover,30.8,1.312,1.846,0.233,,0.584547,2966.65,,58.4547,2.96665,,,,7.85398e-5
1:0 (rep 2),1-Recover,31.167,1.335,1.823,0.22,,0.577264,2801.13,,57.7264,2.80113,,,,7.85398e-5
1:0 (rep 2),1-Recover,31.533,1.358,1.8,0.213,,0.569981,2712,,56.9981,2.712,,,,7.85398e-5
1:0 (rep 2),1-Recover,31.9,1.381,1.777,0.213,,0.562698,2712,,56.2698,2.712,,,,7.85398e-5
1:0 (rep 2),1-Recover,32.267,1.405,1.753,0.206,,0.555098,2622.87,,55.5098,2.62287,,,,7.85398e-5
1:0 (rep 2),1-Recover,32.633,1.428,1.73,0.193,,0.547815,2457.35,,54.7815,2.45735,,,,7.85398e-5
1:0 (rep 2),1-Recover,33,1.451,1.707,0.193,,0.540532,2457.35,,54.0532,2.45735,,,,7.85398e-5
1:0 (rep 2),1-Recover,33.367,1.474,1.684,0.186,,0.533249,2368.23,,53.3249,2.36823,,,,7.85398e-5
1:0 (rep 2),1-Recover,33.733,1.497,1.661,0.165,,0.525966,2100.85,,52.5966,2.10085,,,,7.85398e-5
1:0 (rep 2),1-Recover,34.1,1.521,1.637,0.159,,0.518366,2024.45,,51.8366,2.02445,,,,7.85398e-5
1:0 (rep 2),1-Recover,34.467,1.544,1.614,0.165,,0.511083,2100.85,,51.1083,2.10085,,,,7.85398e-5
1:0 (rep 2),1-Recover,34.833,1.567,1.591,0.159,,0.5038,2024.45,,50.38,2.02445,,,,7.85398e-5
1:0 (rep 2),1-Recover,35.2,1.59,1.568,0.159,,0.496517,2024.45,,49.6517,2.02445,,,,7.85398e-5
1:0 (rep 2),1-Recover,35.567,1.614,1.544,0.159,,0.488917,2024.45,,48.8917,2.02445,,,,7.85398e-5
1:0 (rep 2),1-Recover,35.933,1.636,1.522,0.159,,0.481951,2024.45,,48.1951,2.02445,,,,7.85398e-5
1:0 (rep 2),1-Recover,36.3,1.66,1.498,0.159,,0.474351,2024.45,,47.4351,2.02445,,,,7.85398e-5
1:0 (rep 2),1-Recover,36.667,1.683,1.475,0.159,,0.467068,2024.45,,46.7068,2.02445,,,,7.85398e-5
1:0 (rep 2),1-Recover,37.033,1.706,1.452,0.152,,0.459785,1935.32,,45.9785,1.93532,,,,7.85398e-5
1:0 (rep 2),1-Recover,37.4,1.729,1.429,0.152,,0.452502,1935.32,,45.2502,1.93532,,,,7.85398e-5
1:0 (rep 2),1-Recover,37.767,1.753,1.405,0.152,,0.444902,1935.32,,44.4902,1.93532,,,,7.85398e-5
1:0 (rep 2),1-Recover,38.133,1.775,1.383,0.152,,0.437935,1935.32,,43.7935,1.93532,,,,7.85398e-5
1:0 (rep 2),1-Recover,38.5,1.799,1.359,0.138,,0.430336,1757.07,,43.0336,1.75707,,,,7.85398e-5
1:0 (rep 2),1-Recover,38.867,1.822,1.336,0.118,,0.423053,1502.42,,42.3053,1.50242,,,,7.85398e-5
1:0 (rep 2),1-Recover,39.233,1.845,1.313,0.104,,0.415769,1324.17,,41.5769,1.32417,,,,7.85398e-5
1:0 (rep 2),1-Recover,39.6,1.868,1.29,0.104,,0.408486,1324.17,,40.8486,1.32417,,,,7.85398e-5
1:0 (rep 2),1-Recover,39.967,1.892,1.266,0.111,,0.400887,1413.3,,40.0887,1.4133,,,,7.85398e-5
1:0 (rep 2),1-Recover,40.333,1.915,1.243,0.104,,0.393604,1324.17,,39.3604,1.32417,,,,7.85398e-5
1:0 (rep 2),1-Recover,40.7,1.938,1.22,0.104,,0.38632,1324.17,,38.632,1.32417,,,,7.85398e-5
1:0 (rep 2),1-Recover,41.067,1.962,1.196,0.104,,0.378721,1324.17,,37.8721,1.32417,,,,7.85398e-5
1:0 (rep 2),1-Recover,41.433,1.985,1.173,0.104,,0.371438,1324.17,,37.1438,1.32417,,,,7.85398e-5
1:0 (rep 2),1-Recover,41.8,2.008,1.15,0.104,,0.364155,1324.17,,36.4155,1.32417,,,,7.85398e-5
1:0 (rep 2),1-Recover,42.167,2.031,1.127,0.104,,0.356871,1324.17,,35.6871,1.32417,,,,7.85398e-5
1:0 (rep 2),1-Recover,42.533,2.054,1.104,0.104,,0.349588,1324.17,,34.9588,1.32417,,,,7.85398e-5
1:0 (rep 2),1-Recover,42.9,2.078,1.08,0.104,,0.341989,1324.17,,34.1989,1.32417,,,,7.85398e-5
1:0 (rep 2),1-Recover,43.267,2.101,1.057,0.098,,0.334706,1247.78,,33.4706,1.24778,,,,7.85398e-5
1:0 (rep 2),1-Recover,43.633,2.124,1.034,0.091,,0.327422,1158.65,,32.7422,1.15865,,,,7.85398e-5
1:0 (rep 2),1-Recover,44,2.147,1.011,0.091,,0.320139,1158.65,,32.0139,1.15865,,,,7.85398e-5
1:0 (rep 2),1-Recover,44.367,2.17,0.988,0.064,,0.312856,814.873,,31.2856,0.814873,,,,7.85398e-5
1:0 (rep 2),1-Recover,44.733,2.193,0.965,0.077,,0.305573,980.395,,30.5573,0.980395,,,,7.85398e-5
1:0 (rep 2),1-Recover,45.1,2.217,0.941,0.084,,0.297973,1069.52,,29.7973,1.06952,,,,7.85398e-5
1:0 (rep 2),1-Recover,45.467,2.24,0.918,0.077,,0.29069,980.395,,29.069,0.980395,,,,7.85398e-5
1:0 (rep 2),1-Recover,45.833,2.263,0.895,0.064,,0.283407,814.873,,28.3407,0.814873,,,,7.85398e-5
1:0 (rep 2),1-Recover,46.2,2.286,0.872,0.064,,0.276124,814.873,,27.6124,0.814873,,,,7.85398e-5
1:0 (rep 2),1-Recover,46.567,2.31,0.848,0.057,,0.268524,725.747,,26.8524,0.725747,,,,7.85398e-5
1:0 (rep 2),1-Recover,46.933,2.332,0.826,0.05,,0.261558,636.62,,26.1558,0.63662,,,,7.85398e-5
1:0 (rep 2),1-Recover,47.3,2.356,0.802,0.057,,0.253958,725.747,,25.3958,0.725747,,,,7.85398e-5
1:0 (rep 2),1-Recover,47.667,2.379,0.779,0.05,,0.246675,636.62,,24.6675,0.63662,,,,7.85398e-5
1:0 (rep 2),1-Recover,48.033,2.402,0.756,0.05,,0.239392,636.62,,23.9392,0.63662,,,,7.85398e-5
1:0 (rep 2),1-Recover,48.4,2.426,0.732,0.05,,0.231792,636.62,,23.1792,0.63662,,,,7.85398e-5
1:0 (rep 2),1-Recover,48.767,2.449,0.709,0.05,,0.224509,636.62,,22.4509,0.63662,,,,7.85398e-5
1:0 (rep 2),1-Recover,49.133,2.472,0.686,0.05,,0.217226,636.62,,21.7226,0.63662,,,,7.85398e-5
1:0 (rep 2),1-Recover,49.5,2.495,0.663,0.05,,0.209943,636.62,,20.9943,0.63662,,,,7.85398e-5
1:0 (rep 2),1-Recover,49.867,2.519,0.639,0.05,,0.202343,636.62,,20.2343,0.63662,,,,7.85398e-5
1:0 (rep 2),1-Recover,50.233,2.541,0.617,0.05,,0.195377,636.62,,19.5377,0.63662,,,,7.85398e-5
1:0 (rep 2),1-Recover,50.6,2.565,0.593,0.05,,0.187777,636.62,,18.7777,0.63662,,,,7.85398e-5
1:0 (rep 2),1-Recover,50.967,2.588,0.57,0.05,,0.180494,636.62,,18.0494,0.63662,,,,7.85398e-5
1:0 (rep 2),1-Recover,51.333,2.611,0.547,0.05,,0.173211,636.62,,17.3211,0.63662,,,,7.85398e-5
1:0 (rep 2),1-Recover,51.7,2.634,0.524,0.03,,0.165928,381.972,,16.5928,0.381972,,,,7.85398e-5
1:0 (rep 2),1-Recover,52.067,2.658,0.5,0.05,,0.158328,636.62,,15.8328,0.63662,,,,7.85398e-5
1:0 (rep 2),1-Recover,52.433,2.68,0.478,0.036,,0.151362,458.366,,15.1362,0.458366,,,,7.85398e-5
1:0 (rep 2),1-Recover,52.8,2.704,0.454,0.043,,0.143762,547.493,,14.3762,0.547493,,,,7.85398e-5
1:0 (rep 2),1-Recover,53.167,2.727,0.431,0.036,,0.136479,458.366,,13.6479,0.458366,,,,7.85398e-5
1:0 (rep 2),1-Recover,53.533,2.75,0.408,0.016,,0.129196,203.718,,12.9196,0.203718,,,,7.85398e-5
1:0 (rep 2),1-Recover,53.9,2.773,0.385,0.009,,0.121913,114.592,,12.1913,0.114592,,,,7.85398e-5
1:0 (rep 2),1-Recover,54.267,2.797,0.361,0.03,,0.114313,381.972,,11.4313,0.381972,,,,7.85398e-5
1:0 (rep 2),1-Recover,54.633,2.82,0.338,0.009,,0.10703,114.592,,10.703,0.114592,,,,7.85398e-5
1:0 (rep 2),1-Recover,55,2.843,0.315,0.036,,0.0997467,458.366,,9.97467,0.458366,,,,7.85398e-5
1:0 (rep 2),1-Recover,55.367,2.866,0.292,0.03,,0.0924636,381.972,,9.24636,0.381972,,,,7.85398e-5
1:0 (rep 2),1-Recover,55.733,2.889,0.269,0.016,,0.0851805,203.718,,8.51805,0.203718,,,,7.85398e-5
1:0 (rep 2),1-Recover,56.1,2.913,0.245,0.016,,0.0775807,203.718,,7.75807,0.203718,,,,7.85398e-5
1:0 (rep 2),1-Recover,56.467,2.936,0.222,0.002,,0.0702977,25.4648,,7.02977,0.0254648,,,,7.85398e-5
1:0 (rep 2),1-Recover,56.833,2.959,0.199,0.002,,0.0630146,25.4648,,6.30146,0.0254648,,,,7.85398e-5
1:0 (rep 2),1-Recover,57.2,2.982,0.176,0.009,,0.0557315,114.592,,5.57315,0.114592,,,,7.85398e-5
1:0 (rep 2),1-Recover,57.567,3.006,0.152,0.023,,0.0481317,292.845,,4.81317,0.292845,,,,7.85398e-5
1:0 (rep 2),1-Recover,57.933,3.028,0.13,0.016,,0.0411653,203.718,,4.11653,0.203718,,,,7.85398e-5
1:0 (rep 2),1-Recover,58.3,3.052,0.106,0.009,,0.0335655,114.592,,3.35655,0.114592,,,,7.85398e-5
1:0 (rep 2),1-Recover,58.667,3.075,0.083,0.009,,0.0262825,114.592,,2.62825,0.114592,,,,7.85398e-5
1:0 (rep 2),1-Recover,59.033,3.098,0.06,0.002,,0.0189994,25.4648,,1.89994,0.0254648,,,,7.85398e-5
1:0 (rep 2),1-Recover,59.4,3.121,0.037,0.002,,0.0117163,25.4648,,1.17163,0.0254648,,,,7.85398e-5
1:0 (rep 2),1-Recover,59.767,3.145,0.013,0.009,,0.00411653,114.592,,0.411653,0.114592,,,,7.85398e-5
1:0 (rep 2),2-Compress,60.117,3.153,0.005,0.009,,0.00158328,114.592,,0.158328,0.114592,,,,7.85398e-5
1:0 (rep 2),2-Compress,60.483,3.13,0.028,0.016,,0.00886637,203.718,,0.886637,0.203718,,,,7.85398e-5
1:0 (rep 2),2-Compress,60.85,3.107,0.051,0.009,,0.0161495,114.592,,1.61495,0.114592,,,,7.85398e-5
1:0 (rep 2),2-Compress,61.217,3.084,0.074,0.009,,0.0234326,114.592,,2.34326,0.114592,,,,7.85398e-5
1:0 (rep 2),2-Compress,61.583,3.06,0.098,0.002,,0.0310323,25.4648,,3.10323,0.0254648,,,,7.85398e-5
1:0 (rep 2),2-Compress,61.95,3.037,0.121,0.002,,0.0383154,25.4648,,3.83154,0.0254648,,,,7.85398e-5
1:0 (rep 2),2-Compress,62.317,3.014,0.144,0.002,,0.0455985,25.4648,,4.55985,0.0254648,,,,7.85398e-5
1:0 (rep 2),2-Compress,62.683,2.991,0.167,0.03,,0.0528816,381.972,,5.28816,0.381972,,,,7.85398e-5
1:0 (rep 2),2-Compress,63.05,2.968,0.19,0.043,,0.0601647,547.493,,6.01647,0.547493,,,,7.85398e-5
1:0 (rep 2),2-Compress,63.417,2.944,0.214,0.05,,0.0677644,636.62,,6.77644,0.63662,,,,7.85398e-5
1:0 (rep 2),2-Compress,63.783,2.921,0.237,0.03,,0.0750475,381.972,,7.50475,0.381972,,,,7.85398e-5
1:0 (rep 2),2-Compress,64.15,2.898,0.26,0.05,,0.0823306,636.62,,8.23306,0.63662,,,,7.85398e-5
1:0 (rep 2),2-Compress,64.517,2.875,0.283,0.03,,0.0896137,381.972,,8.96137,0.381972,,,,7.85398e-5
1:0 (rep 2),2-Compress,64.883,2.852,0.306,0.05,,0.0968968,636.62,,9.68968,0.63662,,,,7.85398e-5
1:0 (rep 2),2-Compress,65.25,2.828,0.33,0.05,,0.104497,636.62,,10.4497,0.63662,,,,7.85398e-5
1:0 (rep 2),2-Compress,65.617,2.805,0.353,0.05,,0.11178,636.62,,11.178,0.63662,,,,7.85398e-5
1:0 (rep 2),2-Compress,65.983,2.782,0.376,0.05,,0.119063,636.62,,11.9063,0.63662,,,,7.85398e-5
1:0 (rep 2),2-Compress,66.35,2.759,0.399,0.05,,0.126346,636.62,,12.6346,0.63662,,,,7.85398e-5
1:0 (rep 2),2-Compress,66.717,2.735,0.423,0.05,,0.133946,636.62,,13.3946,0.63662,,,,7.85398e-5
1:0 (rep 2),2-Compress,67.083,2.713,0.445,0.057,,0.140912,725.747,,14.0912,0.725747,,,,7.85398e-5
1:0 (rep 2),2-Compress,67.45,2.689,0.469,0.05,,0.148512,636.62,,14.8512,0.63662,,,,7.85398e-5
1:0 (rep 2),2-Compress,67.817,2.666,0.492,0.05,,0.155795,636.62,,15.5795,0.63662,,,,7.85398e-5
1:0 (rep 2),2-Compress,68.183,2.643,0.515,0.05,,0.163078,636.62,,16.3078,0.63662,,,,7.85398e-5
1:0 (rep 2),2-Compress,68.55,2.62,0.538,0.05,,0.170361,636.62,,17.0361,0.63662,,,,7.85398e-5
1:0 (rep 2),2-Compress,68.917,2.596,0.562,0.05,,0.177961,636.62,,17.7961,0.63662,,,,7.85398e-5
1:0 (rep 2),2-Compress,69.283,2.573,0.585,0.05,,0.185244,636.62,,18.5244,0.63662,,,,7.85398e-5
1:0 (rep 2),2-Compress,69.65,2.55,0.608,0.05,,0.192527,636.62,,19.2527,0.63662,,,,7.85398e-5
1:0 (rep 2),2-Compress,70.017,2.526,0.632,0.057,,0.200127,725.747,,20.0127,0.725747,,,,7.85398e-5
1:0 (rep 2),2-Compress,70.383,2.504,0.654,0.064,,0.207093,814.873,,20.7093,0.814873,,,,7.85398e-5
1:0 (rep 2),2-Compress,70.75,2.48,0.678,0.064,,0.214693,814.873,,21.4693,0.814873,,,,7.85398e-5
1:0 (rep 2),2-Compress,71.117,2.457,0.701,0.07,,0.221976,891.268,,22.1976,0.891268,,,,7.85398e-5
1:0 (rep 2),2-Compress,71.483,2.434,0.724,0.07,,0.229259,891.268,,22.9259,0.891268,,,,7.85398e-5
1:0 (rep 2),2-Compress,71.85,2.411,0.747,0.064,,0.236542,814.873,,23.6542,0.814873,,,,7.85398e-5
1:0 (rep 2),2-Compress,72.217,2.387,0.771,0.084,,0.244142,1069.52,,24.4142,1.06952,,,,7.85398e-5
1:0 (rep 2),2-Compress,72.583,2.365,0.793,0.07,,0.251108,891.268,,25.1108,0.891268,,,,7.85398e-5
1:0 (rep 2),2-Compress,72.95,2.341,0.817,0.104,,0.258708,1324.17,,25.8708,1.32417,,,,7.85398e-5
1:0 (rep 2),2-Compress,73.317,2.318,0.84,0.104,,0.265991,1324.17,,26.5991,1.32417,,,,7.85398e-5
1:0 (rep 2),2-Compress,73.683,2.295,0.863,0.104,,0.273274,1324.17,,27.3274,1.32417,,,,7.85398e-5
1:0 (rep 2),2-Compress,74.05,2.272,0.886,0.104,,0.280557,1324.17,,28.0557,1.32417,,,,7.85398e-5
1:0 (rep 2),2-Compress,74.417,2.248,0.91,0.104,,0.288157,1324.17,,28.8157,1.32417,,,,7.85398e-5
1:0 (rep 2),2-Compress,74.783,2.226,0.932,0.104,,0.295123,1324.17,,29.5123,1.32417,,,,7.85398e-5
1:0 (rep 2),2-Compress,75.15,2.202,0.956,0.104,,0.302723,1324.17,,30.2723,1.32417,,,,7.85398e-5
1:0 (rep 2),2-Compress,75.517,2.179,0.979,0.104,,0.310006,1324.17,,31.0006,1.32417,,,,7.85398e-5
1:0 (rep 2),2-Compress,75.883,2.156,1.002,0.104,,0.317289,1324.17,,31.7289,1.32417,,,,7.85398e-5
1:0 (rep 2),2-Compress,76.25,2.132,1.026,0.104,,0.324889,1324.17,,32.4889,1.32417,,,,7.85398e-5
1:0 (rep 2),2-Compress,76.617,2.109,1.049,0.104,,0.332172,1324.17,,33.2172,1.32417,,,,7.85398e-5
1:0 (rep 2),2-Compress,76.983,2.086,1.072,0.111,,0.339455,1413.3,,33.9455,1.4133,,,,7.85398e-5
1:0 (rep 2),2-Compress,77.35,2.063,1.095,0.111,,0.346738,1413.3,,34.6738,1.4133,,,,7.85398e-5
1:0 (rep 2),2-Compress,77.717,2.039,1.119,0.125,,0.354338,1591.55,,35.4338,1.59155,,,,7.85398e-5
1:0 (rep 2),2-Compress,78.083,2.017,1.141,0.125,,0.361305,1591.55,,36.1305,1.59155,,,,7.85398e-5
1:0 (rep 2),2-Compress,78.45,1.993,1.165,0.125,,0.368904,1591.55,,36.8904,1.59155,,,,7.85398e-5
1:0 (rep 2),2-Compress,78.817,1.97,1.188,0.131,,0.376187,1667.94,,37.6187,1.66794,,,,7.85398e-5
1:0 (rep 2),2-Compress,79.183,1.947,1.211,0.131,,0.383471,1667.94,,38.3471,1.66794,,,,7.85398e-5
1:0 (rep 2),2-Compress,79.55,1.924,1.234,0.138,,0.390754,1757.07,,39.0754,1.75707,,,,7.85398e-5
1:0 (rep 2),2-Compress,79.917,1.9,1.258,0.138,,0.398353,1757.07,,39.8353,1.75707,,,,7.85398e-5
1:0 (rep 2),2-Compress,80.283,1.878,1.28,0.145,,0.40532,1846.2,,40.532,1.8462,,,,7.85398e-5
1:0 (rep 2),2-Compress,80.65,1.854,1.304,0.159,,0.41292,2024.45,,41.292,2.02445,,,,7.85398e-5
1:0 (rep 2),2-Compress,81.017,1.831,1.327,0.159,,0.420203,2024.45,,42.0203,2.02445,,,,7.85398e-5
1:0 (rep 2),2-Compress,81.383,1.808,1.35,0.159,,0.427486,2024.45,,42.7486,2.02445,,,,7.85398e-5
1:0 (rep 2),2-Compress,81.75,1.785,1.373,0.159,,0.434769,2024.45,,43.4769,2.02445,,,,7.85398e-5
1:0 (rep 2),2-Compress,82.117,1.761,1.397,0.159,,0.442369,2024.45,,44.2369,2.02445,,,,7.85398e-5
1:0 (rep 2),2-Compress,82.483,1.738,1.42,0.159,,0.449652,2024.45,,44.9652,2.02445,,,,7.85398e-5
1:0 (rep 2),2-Compress,82.85,1.715,1.443,0.159,,0.456935,2024.45,,45.6935,2.02445,,,,7.85398e-5
1:0 (rep 2),2-Compress,83.217,1.692,1.466,0.159,,0.464218,2024.45,,46.4218,2.02445,,,,7.85398e-5
1:0 (rep 2),2-Compress,83.583,1.668,1.49,0.159,,0.471818,2024.45,,47.1818,2.02445,,,,7.85398e-5
1:0 (rep 2),2-Compress,83.95,1.645,1.513,0.165,,0.479101,2100.85,,47.9101,2.10085,,,,7.85398e-5
1:0 (rep 2),2-Compress,84.317,1.622,1.536,0.165,,0.486384,2100.85,,48.6384,2.10085,,,,7.85398e-5
1:0 (rep 2),2-Compress,84.683,1.599,1.559,0.165,,0.493667,2100.85,,49.3667,2.10085,,,,7.85398e-5
1:0 (rep 2),2-Compress,85.05,1.576,1.582,0.186,,0.50095,2368.23,,50.095,2.36823,,,,7.85398e-5
1:0 (rep 2),2-Compress,85.417,1.552,1.606,0.186,,0.50855,2368.23,,50.855,2.36823,,,,7.85398e-5
1:0 (rep 2),2-Compress,85.783,1.53,1.628,0.186,,0.515516,2368.23,,51.5516,2.36823,,,,7.85398e-5
1:0 (rep 2),2-Compress,86.15,1.506,1.652,0.199,,0.523116,2533.75,,52.3116,2.53375,,,,7.85398e-5
1:0 (rep 2),2-Compress,86.517,1.483,1.675,0.206,,0.530399,2622.87,,53.0399,2.62287,,,,7.85398e-5
1:0 (rep 2),2-Compress,86.883,1.46,1.698,0.213,,0.537682,2712,,53.7682,2.712,,,,7.85398e-5
1:0 (rep 2),2-Compress,87.25,1.436,1.722,0.213,,0.545282,2712,,54.5282,2.712,,,,7.85398e-5
1:0 (rep 2),2-Compress,87.617,1.413,1.745,0.206,,0.552565,2622.87,,55.2565,2.62287,,,,7.85398e-5
1:0 (rep 2),2-Compress,87.983,1.39,1.768,0.213,,0.559848,2712,,55.9848,2.712,,,,7.85398e-5
1:0 (rep 2),2-Compress,88.35,1.367,1.791,0.227,,0.567131,2890.25,,56.7131,2.89025,,,,7.85398e-5
1:0 (rep 2),2-Compress,88.717,1.344,1.814,0.233,,0.574414,2966.65,,57.4414,2.96665,,,,7.85398e-5
1:0 (rep 2),2-Compress,89.083,1.321,1.837,0.22,,0.581697,2801.13,,58.1697,2.80113,,,,7.85398e-5
1:0 (rep 2),2-Compress,89.45,1.298,1.86,0.22,,0.58898,2801.13,,58.898,2.80113,,,,7.85398e-5
1:0 (rep 2),2-Compress,89.817,1.274,1.884,0.227,,0.59658,2890.25,,59.658,2.89025,,,,7.85398e-5
1:0 (rep 2),2-Recover,90.17,1.27,1.888,0.24,,0.597847,3055.78,,59.7847,3.05578,,,,7.85398e-5
1:0 (rep 2),2-Recover,90.537,1.293,1.865,0.233,,0.590564,2966.65,,59.0564,2.96665,,,,7.85398e-5
1:0 (rep 2),2-Recover,90.903,1.316,1.842,0.227,,0.583281,2890.25,,58.3281,2.89025,,,,7.85398e-5
1:0 (rep 2),2-Recover,91.27,1.339,1.819,0.227,,0.575997,2890.25,,57.5997,2.89025,,,,7.85398e-5
1:0 (rep 2),2-Recover,91.637,1.363,1.795,0.213,,0.568398,2712,,56.8398,2.712,,,,7.85398e-5
1:0 (rep 2),2-Recover,92.003,1.385,1.773,0.213,,0.561431,2712,,56.1431,2.712,,,,7.85398e-5
1:0 (rep 2),2-Recover,92.37,1.409,1.749,0.213,,0.553832,2712,,55.3832,2.712,,,,7.85398e-5
1:0 (rep 2),2-Recover,92.737,1.432,1.726,0.199,,0.546548,2533.75,,54.6548,2.53375,,,,7.85398e-5
1:0 (rep 2),2-Recover,93.103,1.455,1.703,0.193,,0.539265,2457.35,,53.9265,2.45735,,,,7.85398e-5
1:0 (rep 2),2-Recover,93.47,1.478,1.68,0.179,,0.531982,2279.1,,53.1982,2.2791,,,,7.85398e-5
1:0 (rep 2),2-Recover,93.837,1.502,1.656,0.172,,0.524383,2189.97,,52.4383,2.18997,,,,7.85398e-5
1:0 (rep 2),2-Recover,94.203,1.525,1.633,0.165,,0.517099,2100.85,,51.7099,2.10085,,,,7.85398e-5
1:0 (rep 2),2-Recover,94.57,1.548,1.61,0.159,,0.509816,2024.45,,50.9816,2.02445,,,,7.85398e-5
1:0 (rep 2),2-Recover,94.937,1.571,1.587,0.159,,0.502533,2024.45,,50.2533,2.02445,,,,7.85398e-5
1:0 (rep 2),2-Recover,95.303,1.594,1.564,0.159,,0.49525,2024.45,,49.525,2.02445,,,,7.85398e-5
1:0 (rep 2),2-Recover,95.67,1.618,1.54,0.152,,0.48765,1935.32,,48.765,1.93532,,,,7.85398e-5
1:0 (rep 2),2-Recover,96.037,1.641,1.517,0.159,,0.480367,2024.45,,48.0367,2.02445,,,,7.85398e-5
1:0 (rep 2),2-Recover,96.403,1.664,1.494,0.159,,0.473084,2024.45,,47.3084,2.02445,,,,7.85398e-5
1:0 (rep 2),2-Recover,96.77,1.687,1.471,0.159,,0.465801,2024.45,,46.5801,2.02445,,,,7.85398e-5
1:0 (rep 2),2-Recover,97.137,1.711,1.447,0.152,,0.458201,1935.32,,45.8201,1.93532,,,,7.85398e-5
1:0 (rep 2),2-Recover,97.503,1.733,1.425,0.145,,0.451235,1846.2,,45.1235,1.8462,,,,7.85398e-5
1:0 (rep 2),2-Recover,97.87,1.757,1.401,0.138,,0.443635,1757.07,,44.3635,1.75707,,,,7.85398e-5
1:0 (rep 2),2-Recover,98.237,1.78,1.378,0.145,,0.436352,1846.2,,43.6352,1.8462,,,,7.85398e-5
1:0 (rep 2),2-Recover,98.603,1.803,1.355,0.125,,0.429069,1591.55,,42.9069,1.59155,,,,7.85398e-5
1:0 (rep 2),2-Recover,98.97,1.826,1.332,0.118,,0.421786,1502.42,,42.1786,1.50242,,,,7.85398e-5
1:0 (rep 2),2-Recover,99.337,1.85,1.308,0.111,,0.414186,1413.3,,41.4186,1.4133,,,,7.85398e-5
1:0 (rep 2),2-Recover,99.703,1.872,1.286,0.111,,0.40722,1413.3,,40.722,1.4133,,,,7.85398e-5
1:0 (rep 2),2-Recover,100.07,1.896,1.262,0.104,,0.39962,1324.17,,39.962,1.32417,,,,7.85398e-5
1:0 (rep 2),2-Recover,100.437,1.919,1.239,0.104,,0.392337,1324.17,,39.2337,1.32417,,,,7.85398e-5
1:0 (rep 2),2-Recover,100.803,1.942,1.216,0.104,,0.385054,1324.17,,38.5054,1.32417,,,,7.85398e-5
1:0 (rep 2),2-Recover,101.17,1.965,1.193,0.104,,0.377771,1324.17,,37.7771,1.32417,,,,7.85398e-5
1:0 (rep 2),2-Recover,101.537,1.989,1.169,0.104,,0.370171,1324.17,,37.0171,1.32417,,,,7.85398e-5
1:0 (rep 2),2-Recover,101.903,2.012,1.146,0.104,,0.362888,1324.17,,36.2888,1.32417,,,,7.85398e-5
1:0 (rep 2),2-Recover,102.27,2.035,1.123,0.104,,0.355605,1324.17,,35.5605,1.32417,,,,7.85398e-5
1:0 (rep 2),2-Recover,102.637,2.059,1.099,0.098,,0.348005,1247.78,,34.8005,1.24778,,,,7.85398e-5
1:0 (rep 2),2-Recover,103.003,2.081,1.077,0.098,,0.341039,1247.78,,34.1039,1.24778,,,,7.85398e-5
1:0 (rep 2),2-Recover,103.37,2.105,1.053,0.104,,0.333439,1324.17,,33.3439,1.32417,,,,7.85398e-5
1:0 (rep 2),2-Recover,103.737,2.128,1.03,0.098,,0.326156,1247.78,,32.6156,1.24778,,,,7.85398e-5
1:0 (rep 2),2-Recover,104.103,2.151,1.007,0.077,,0.318873,980.395,,31.8873,0.980395,,,,7.85398e-5
1:0 (rep 2),2-Recover,104.47,2.174,0.984,0.077,,0.31159,980.395,,31.159,0.980395,,,,7.85398e-5
1:0 (rep 2),2-Recover,104.837,2.198,0.96,0.064,,0.30399,814.873,,30.399,0.814873,,,,7.85398e-5
1:0 (rep 2),2-Recover,105.203,2.221,0.937,0.05,,0.296707,636.62,,29.6707,0.63662,,,,7.85398e-5
1:0 (rep 2),2-Recover,105.57,2.244,0.914,0.077,,0.289424,980.395,,28.9424,0.980395,,,,7.85398e-5
1:0 (rep 2),2-Recover,105.937,2.267,0.891,0.07,,0.282141,891.268,,28.2141,0.891268,,,,7.85398e-5
1:0 (rep 2),2-Recover,106.303,2.29,0.868,0.064,,0.274858,814.873,,27.4858,0.814873,,,,7.85398e-5
1:0 (rep 2),2-Recover,106.67,2.314,0.844,0.064,,0.267258,814.873,,26.7258,0.814873,,,,7.85398e-5
1:0 (rep 2),2-Recover,107.037,2.337,0.821,0.057,,0.259975,725.747,,25.9975,0.725747,,,,7.85398e-5
1:0 (rep 2),2-Recover,107.403,2.36,0.798,0.05,,0.252692,636.62,,25.2692,0.63662,,,,7.85398e-5
1:0 (rep 2),2-Recover,107.77,2.383,0.775,0.05,,0.245408,636.62,,24.5408,0.63662,,,,7.85398e-5
1:0 (rep 2),2-Recover,108.137,2.406,0.752,0.05,,0.238125,636.62,,23.8125,0.63662,,,,7.85398e-5
1:0 (rep 2),2-Recover,108.503,2.429,0.729,0.05,,0.230842,636.62,,23.0842,0.63662,,,,7.85398e-5
1:0 (rep 2),2-Recover,108.87,2.453,0.705,0.05,,0.223243,636.62,,22.3243,0.63662,,,,7.85398e-5
1:0 (rep 2),2-Recover,109.237,2.476,0.682,0.05,,0.215959,636.62,,21.5959,0.63662,,,,7.85398e-5
1:0 (rep 2),2-Recover,109.603,2.499,0.659,0.05,,0.208676,636.62,,20.8676,0.63662,,,,7.85398e-5
1:0 (rep 2),2-Recover,109.97,2.523,0.635,0.05,,0.201077,636.62,,20.1077,0.63662,,,,7.85398e-5
1:0 (rep 2),2-Recover,110.337,2.546,0.612,0.05,,0.193794,636.62,,19.3794,0.63662,,,,7.85398e-5
1:0 (rep 2),2-Recover,110.703,2.569,0.589,0.05,,0.18651,636.62,,18.651,0.63662,,,,7.85398e-5
1:0 (rep 2),2-Recover,111.07,2.592,0.566,0.05,,0.179227,636.62,,17.9227,0.63662,,,,7.85398e-5
1:0 (rep 2),2-Recover,111.437,2.616,0.542,0.05,,0.171628,636.62,,17.1628,0.63662,,,,7.85398e-5
1:0 (rep 2),2-Recover,111.803,2.638,0.52,0.043,,0.164661,547.493,,16.4661,0.547493,,,,7.85398e-5
1:0 (rep 2),2-Recover,112.17,2.662,0.496,0.023,,0.157061,292.845,,15.7061,0.292845,,,,7.85398e-5
1:0 (rep 2),2-Recover,112.537,2.685,0.473,0.03,,0.149778,381.972,,14.9778,0.381972,,,,7.85398e-5
1:0 (rep 2),2-Recover,112.903,2.708,0.45,0.03,,0.142495,381.972,,14.2495,0.381972,,,,7.85398e-5
1:0 (rep 2),2-Recover,113.27,2.731,0.427,0.043,,0.135212,547.493,,13.5212,0.547493,,,,7.85398e-5
1:0 (rep 2),2-Recover,113.637,2.755,0.403,0.023,,0.127612,292.845,,12.7612,0.292845,,,,7.85398e-5
1:0 (rep 2),2-Recover,114.003,2.777,0.381,0.016,,0.120646,203.718,,12.0646,0.203718,,,,7.85398e-5
1:0 (rep 2),2-Recover,114.37,2.801,0.357,0.023,,0.113046,292.845,,11.3046,0.292845,,,,7.85398e-5
1:0 (rep 2),2-Recover,114.737,2.824,0.334,0.002,,0.105763,25.4648,,10.5763,0.0254648,,,,7.85398e-5
1:0 (rep 2),2-Recover,115.103,2.847,0.311,0.009,,0.0984801,114.592,,9.84801,0.114592,,,,7.85398e-5
1:0 (rep 2),2-Recover,115.47,2.87,0.288,0.002,,0.091197,25.4648,,9.1197,0.0254648,,,,7.85398e-5
1:0 (rep 2),2-Recover,115.837,2.894,0.264,0.023,,0.0835972,292.845,,8.35972,0.292845,,,,7.85398e-5
1:0 (rep 2),2-Recover,116.203,2.917,0.241,0.016,,0.0763141,203.718,,7.63141,0.203718,,,,7.85398e-5
1:0 (rep 2),2-Recover,116.57,2.94,0.218,0.016,,0.069031,203.718,,6.9031,0.203718,,,,7.85398e-5
1:0 (rep 2),2-Recover,116.937,2.963,0.195,0.002,,0.0617479,25.4648,,6.17479,0.0254648,,,,7.85398e-5
1:0 (rep 2),2-Recover,117.303,2.986,0.172,0.002,,0.0544649,25.4648,,5.44649,0.0254648,,,,7.85398e-5
1:0 (rep 2),2-Recover,117.67,3.01,0.148,0.009,,0.0468651,114.592,,4.68651,0.114592,,,,7.85398e-5
1:0 (rep 2),2-Recover,118.037,3.033,0.125,0.009,,0.039582,114.592,,3.9582,0.114592,,,,7.85398e-5
1:0 (rep 2),2-Recover,118.403,3.056,0.102,0.023,,0.0322989,292.845,,3.22989,0.292845,,,,7.85398e-5
1:0 (rep 2),2-Recover,118.77,3.079,0.079,0.002,,0.0250158,25.4648,,2.50158,0.0254648,,,,7.85398e-5
1:0 (rep 2),2-Recover,119.137,3.103,0.055,0.009,,0.0174161,114.592,,1.74161,0.114592,,,,7.85398e-5
1:0 (rep 2),2-Recover,119.503,3.125,0.033,0.002,,0.0104497,25.4648,,1.04497,0.0254648,,,,7.85398e-5
1:0 (rep 2),2-Recover,119.87,3.149,0.009,0.002,,0.00284991,25.4648,,0.284991,0.0254648,,,,7.85398e-5
1:0 (rep 2),3-Compress,120.223,3.149,0.009,0.002,,0.00284991,25.4648,,0.284991,0.0254648,,,,7.85398e-5
1:0 (rep 2),3-Compress,120.59,3.126,0.032,0.016,,0.010133,203.718,,1.0133,0.203718,,,,7.85398e-5
1:0 (rep 2),3-Compress,120.957,3.102,0.056,0.016,,0.0177327,203.718,,1.77327,0.203718,,,,7.85398e-5
1:0 (rep 2),3-Compress,121.323,3.08,0.078,0.023,,0.0246992,292.845,,2.46992,0.292845,,,,7.85398e-5
1:0 (rep 2),3-Compress,121.69,3.056,0.102,0.016,,0.0322989,203.718,,3.22989,0.203718,,,,7.85398e-5
1:0 (rep 2),3-Compress,122.057,3.033,0.125,0.016,,0.039582,203.718,,3.9582,0.203718,,,,7.85398e-5
1:0 (rep 2),3-Compress,122.423,3.01,0.148,0.023,,0.0468651,292.845,,4.68651,0.292845,,,,7.85398e-5
1:0 (rep 2),3-Compress,122.79,2.987,0.171,0.03,,0.0541482,381.972,,5.41482,0.381972,,,,7.85398e-5
1:0 (rep 2),3-Compress,123.157,2.963,0.195,0.043,,0.0617479,547.493,,6.17479,0.547493,,,,7.85398e-5
1:0 (rep 2),3-Compress,123.523,2.94,0.218,0.05,,0.069031,636.62,,6.9031,0.63662,,,,7.85398e-5
1:0 (rep 2),3-Compress,123.89,2.917,0.241,0.043,,0.0763141,547.493,,7.63141,0.547493,,,,7.85398e-5
1:0 (rep 2),3-Compress,124.257,2.893,0.265,0.043,,0.0839139,547.493,,8.39139,0.547493,,,,7.85398e-5
1:0 (rep 2),3-Compress,124.623,2.871,0.287,0.05,,0.0908803,636.62,,9.08803,0.63662,,,,7.85398e-5
1:0 (rep 2),3-Compress,124.99,2.847,0.311,0.05,,0.0984801,636.62,,9.84801,0.63662,,,,7.85398e-5
1:0 (rep 2),3-Compress,125.357,2.824,0.334,0.043,,0.105763,547.493,,10.5763,0.547493,,,,7.85398e-5
1:0 (rep 2),3-Compress,125.723,2.801,0.357,0.05,,0.113046,636.62,,11.3046,0.63662,,,,7.85398e-5
1:0 (rep 2),3-Compress,126.09,2.778,0.38,0.05,,0.120329,636.62,,12.0329,0.63662,,,,7.85398e-5
1:0 (rep 2),3-Compress,126.457,2.754,0.404,0.05,,0.127929,636.62,,12.7929,0.63662,,,,7.85398e-5
1:0 (rep 2),3-Compress,126.823,2.732,0.426,0.05,,0.134896,636.62,,13.4896,0.63662,,,,7.85398e-5
1:0 (rep 2),3-Compress,127.19,2.708,0.45,0.05,,0.142495,636.62,,14.2495,0.63662,,,,7.85398e-5
1:0 (rep 2),3-Compress,127.557,2.685,0.473,0.05,,0.149778,636.62,,14.9778,0.63662,,,,7.85398e-5
1:0 (rep 2),3-Compress,127.923,2.662,0.496,0.05,,0.157061,636.62,,15.7061,0.63662,,,,7.85398e-5
1:0 (rep 2),3-Compress,128.29,2.639,0.519,0.05,,0.164345,636.62,,16.4345,0.63662,,,,7.85398e-5
1:0 (rep 2),3-Compress,128.657,2.615,0.543,0.05,,0.171944,636.62,,17.1944,0.63662,,,,7.85398e-5
1:0 (rep 2),3-Compress,129.023,2.592,0.566,0.05,,0.179227,636.62,,17.9227,0.63662,,,,7.85398e-5
1:0 (rep 2),3-Compress,129.39,2.569,0.589,0.05,,0.18651,636.62,,18.651,0.63662,,,,7.85398e-5
1:0 (rep 2),3-Compress,129.757,2.546,0.612,0.057,,0.193794,725.747,,19.3794,0.725747,,,,7.85398e-5
1:0 (rep 2),3-Compress,130.123,2.523,0.635,0.05,,0.201077,636.62,,20.1077,0.63662,,,,7.85398e-5
1:0 (rep 2),3-Compress,130.49,2.499,0.659,0.064,,0.208676,814.873,,20.8676,0.814873,,,,7.85398e-5
1:0 (rep 2),3-Compress,130.857,2.476,0.682,0.077,,0.215959,980.395,,21.5959,0.980395,,,,7.85398e-5
1:0 (rep 2),3-Compress,131.223,2.453,0.705,0.077,,0.223243,980.395,,22.3243,0.980395,,,,7.85398e-5
1:0 (rep 2),3-Compress,131.59,2.43,0.728,0.084,,0.230526,1069.52,,23.0526,1.06952,,,,7.85398e-5
1:0 (rep 2),3-Compress,131.957,2.406,0.752,0.091,,0.238125,1158.65,,23.8125,1.15865,,,,7.85398e-5
1:0 (rep 2),3-Compress,132.323,2.384,0.774,0.098,,0.245092,1247.78,,24.5092,1.24778,,,,7.85398e-5
1:0 (rep 2),3-Compress,132.69,2.36,0.798,0.057,,0.252692,725.747,,25.2692,0.725747,,,,7.85398e-5
1:0 (rep 2),3-Compress,133.057,2.337,0.821,0.091,,0.259975,1158.65,,25.9975,1.15865,,,,7.85398e-5
1:0 (rep 2),3-Compress,133.423,2.314,0.844,0.104,,0.267258,1324.17,,26.7258,1.32417,,,,7.85398e-5
1:0 (rep 2),3-Compress,133.79,2.291,0.867,0.104,,0.274541,1324.17,,27.4541,1.32417,,,,7.85398e-5
1:0 (rep 2),3-Compress,134.157,2.267,0.891,0.104,,0.282141,1324.17,,28.2141,1.32417,,,,7.85398e-5
1:0 (rep 2),3-Compress,134.523,2.245,0.913,0.104,,0.289107,1324.17,,28.9107,1.32417,,,,7.85398e-5
1:0 (rep 2),3-Compress,134.89,2.221,0.937,0.104,,0.296707,1324.17,,29.6707,1.32417,,,,7.85398e-5
1:0 (rep 2),3-Compress,135.257,2.198,0.96,0.104,,0.30399,1324.17,,30.399,1.32417,,,,7.85398e-5
1:0 (rep 2),3-Compress,135.623,2.175,0.983,0.104,,0.311273,1324.17,,31.1273,1.32417,,,,7.85398e-5
1:0 (rep 2),3-Compress,135.99,2.152,1.006,0.104,,0.318556,1324.17,,31.8556,1.32417,,,,7.85398e-5
1:0 (rep 2),3-Compress,136.357,2.128,1.03,0.104,,0.326156,1324.17,,32.6156,1.32417,,,,7.85398e-5
1:0 (rep 2),3-Compress,136.723,2.105,1.053,0.111,,0.333439,1413.3,,33.3439,1.4133,,,,7.85398e-5
1:0 (rep 2),3-Compress,137.09,2.082,1.076,0.104,,0.340722,1324.17,,34.0722,1.32417,,,,7.85398e-5
1:0 (rep 2),3-Compress,137.457,2.059,1.099,0.111,,0.348005,1413.3,,34.8005,1.4133,,,,7.85398e-5
1:0 (rep 2),3-Compress,137.823,2.035,1.123,0.104,,0.355605,1324.17,,35.5605,1.32417,,,,7.85398e-5
1:0 (rep 2),3-Compress,138.19,2.012,1.146,0.125,,0.362888,1591.55,,36.2888,1.59155,,,,7.85398e-5
1:0 (rep 2),3-Compress,138.557,1.989,1.169,0.138,,0.370171,1757.07,,37.0171,1.75707,,,,7.85398e-5
1:0 (rep 2),3-Compress,138.923,1.966,1.192,0.138,,0.377454,1757.07,,37.7454,1.75707,,,,7.85398e-5
1:0 (rep 2),3-Compress,139.29,1.943,1.215,0.138,,0.384737,1757.07,,38.4737,1.75707,,,,7.85398e-5
1:0 (rep 2),3-Compress,139.657,1.919,1.239,0.145,,0.392337,1846.2,,39.2337,1.8462,,,,7.85398e-5
1:0 (rep 2),3-Compress,140.023,1.897,1.261,0.145,,0.399303,1846.2,,39.9303,1.8462,,,,7.85398e-5
1:0 (rep 2),3-Compress,140.39,1.873,1.285,0.159,,0.406903,2024.45,,40.6903,2.02445,,,,7.85398e-5
1:0 (rep 2),3-Compress,140.757,1.85,1.308,0.152,,0.414186,1935.32,,41.4186,1.93532,,,,7.85398e-5
1:0 (rep 2),3-Compress,141.123,1.827,1.331,0.159,,0.421469,2024.45,,42.1469,2.02445,,,,7.85398e-5
1:0 (rep 2),3-Compress,141.49,1.803,1.355,0.159,,0.429069,2024.45,,42.9069,2.02445,,,,7.85398e-5
1:0 (rep 2),3-Compress,141.857,1.78,1.378,0.159,,0.436352,2024.45,,43.6352,2.02445,,,,7.85398e-5
1:0 (rep 2),3-Compress,142.223,1.757,1.401,0.159,,0.443635,2024.45,,44.3635,2.02445,,,,7.85398e-5
1:0 (rep 2),3-Compress,142.59,1.734,1.424,0.159,,0.450918,2024.45,,45.0918,2.02445,,,,7.85398e-5
1:0 (rep 2),3-Compress,142.957,1.711,1.447,0.159,,0.458201,2024.45,,45.8201,2.02445,,,,7.85398e-5
1:0 (rep 2),3-Compress,143.323,1.688,1.47,0.159,,0.465484,2024.45,,46.5484,2.02445,,,,7.85398e-5
1:0 (rep 2),3-Compress,143.69,1.665,1.493,0.159,,0.472768,2024.45,,47.2768,2.02445,,,,7.85398e-5
1:0 (rep 2),3-Compress,144.057,1.641,1.517,0.159,,0.480367,2024.45,,48.0367,2.02445,,,,7.85398e-5
1:0 (rep 2),3-Compress,144.423,1.618,1.54,0.172,,0.48765,2189.97,,48.765,2.18997,,,,7.85398e-5
1:0 (rep 2),3-Compress,144.79,1.595,1.563,0.186,,0.494934,2368.23,,49.4934,2.36823,,,,7.85398e-5
1:0 (rep 2),3-Compress,145.157,1.571,1.587,0.199,,0.502533,2533.75,,50.2533,2.53375,,,,7.85398e-5
1:0 (rep 2),3-Compress,145.523,1.548,1.61,0.199,,0.509816,2533.75,,50.9816,2.53375,,,,7.85398e-5
1:0 (rep 2),3-Compress,145.89,1.525,1.633,0.193,,0.517099,2457.35,,51.7099,2.45735,,,,7.85398e-5
1:0 (rep 2),3-Compress,146.257,1.502,1.656,0.186,,0.524383,2368.23,,52.4383,2.36823,,,,7.85398e-5
1:0 (rep 2),3-Compress,146.623,1.479,1.679,0.193,,0.531666,2457.35,,53.1666,2.45735,,,,7.85398e-5
1:0 (rep 2),3-Compress,146.99,1.455,1.703,0.206,,0.539265,2622.87,,53.9265,2.62287,,,,7.85398e-5
1:0 (rep 2),3-Compress,147.357,1.432,1.726,0.213,,0.546548,2712,,54.6548,2.712,,,,7.85398e-5
1:0 (rep 2),3-Compress,147.723,1.409,1.749,0.213,,0.553832,2712,,55.3832,2.712,,,,7.85398e-5
1:0 (rep 2),3-Compress,148.09,1.386,1.772,0.213,,0.561115,2712,,56.1115,2.712,,,,7.85398e-5
1:0 (rep 2),3-Compress,148.457,1.363,1.795,0.227,,0.568398,2890.25,,56.8398,2.89025,,,,7.85398e-5
1:0 (rep 2),3-Compress,148.823,1.34,1.818,0.227,,0.575681,2890.25,,57.5681,2.89025,,,,7.85398e-5
1:0 (rep 2),3-Compress,149.19,1.316,1.842,0.227,,0.583281,2890.25,,58.3281,2.89025,,,,7.85398e-5
1:0 (rep 2),3-Compress,149.557,1.293,1.865,0.233,,0.590564,2966.65,,59.0564,2.96665,,,,7.85398e-5
1:0 (rep 2),3-Compress,149.923,1.27,1.888,0.213,,0.597847,2712,,59.7847,2.712,,,,7.85398e-5
1:0 (rep 2),3-Recover,150.267,1.273,1.885,0.22,,0.596897,2801.13,,59.6897,2.80113,,,,7.85398e-5
1:0 (rep 2),3-Recover,150.633,1.296,1.862,0.254,,0.589614,3234.03,,58.9614,3.23403,,,,7.85398e-5
1:0 (rep 2),3-Recover,151,1.32,1.838,0.213,,0.582014,2712,,58.2014,2.712,,,,7.85398e-5
1:0 (rep 2),3-Recover,151.367,1.343,1.815,0.22,,0.574731,2801.13,,57.4731,2.80113,,,,7.85398e-5
1:0 (rep 2),3-Recover,151.733,1.366,1.792,0.199,,0.567448,2533.75,,56.7448,2.53375,,,,7.85398e-5
1:0 (rep 2),3-Recover,152.1,1.389,1.769,0.199,,0.560165,2533.75,,56.0165,2.53375,,,,7.85398e-5
1:0 (rep 2),3-Recover,152.467,1.412,1.746,0.213,,0.552882,2712,,55.2882,2.712,,,,7.85398e-5
1:0 (rep 2),3-Recover,152.833,1.436,1.722,0.213,,0.545282,2712,,54.5282,2.712,,,,7.85398e-5
1:0 (rep 2),3-Recover,153.2,1.459,1.699,0.199,,0.537999,2533.75,,53.7999,2.53375,,,,7.85398e-5
1:0 (rep 2),3-Recover,153.567,1.482,1.676,0.165,,0.530716,2100.85,,53.0716,2.10085,,,,7.85398e-5
1:0 (rep 2),3-Recover,153.933,1.505,1.653,0.165,,0.523433,2100.85,,52.3433,2.10085,,,,7.85398e-5
1:0 (rep 2),3-Recover,154.3,1.529,1.629,0.159,,0.515833,2024.45,,51.5833,2.02445,,,,7.85398e-5
1:0 (rep 2),3-Recover,154.667,1.552,1.606,0.152,,0.50855,1935.32,,50.855,1.93532,,,,7.85398e-5
1:0 (rep 2),3-Recover,155.033,1.575,1.583,0.159,,0.501267,2024.45,,50.1267,2.02445,,,,7.85398e-5
1:0 (rep 2),3-Recover,155.4,1.598,1.56,0.159,,0.493984,2024.45,,49.3984,2.02445,,,,7.85398e-5
1:0 (rep 2),3-Recover,155.767,1.622,1.536,0.159,,0.486384,2024.45,,48.6384,2.02445,,,,7.85398e-5
1:0 (rep 2),3-Recover,156.133,1.644,1.514,0.159,,0.479417,2024.45,,47.9417,2.02445,,,,7.85398e-5
1:0 (rep 2),3-Recover,156.5,1.668,1.49,0.159,,0.471818,2024.45,,47.1818,2.02445,,,,7.85398e-5
1:0 (rep 2),3-Recover,156.867,1.691,1.467,0.159,,0.464535,2024.45,,46.4535,2.02445,,,,7.85398e-5
1:0 (rep 2),3-Recover,157.233,1.714,1.444,0.159,,0.457251,2024.45,,45.7251,2.02445,,,,7.85398e-5
1:0 (rep 2),3-Recover,157.6,1.737,1.421,0.131,,0.449968,1667.94,,44.9968,1.66794,,,,7.85398e-5
1:0 (rep 2),3-Recover,157.967,1.761,1.397,0.138,,0.442369,1757.07,,44.2369,1.75707,,,,7.85398e-5
1:0 (rep 2),3-Recover,158.333,1.783,1.375,0.125,,0.435402,1591.55,,43.5402,1.59155,,,,7.85398e-5
1:0 (rep 2),3-Recover,158.7,1.807,1.351,0.131,,0.427802,1667.94,,42.7802,1.66794,,,,7.85398e-5
1:0 (rep 2),3-Recover,159.067,1.83,1.328,0.125,,0.420519,1591.55,,42.0519,1.59155,,,,7.85398e-5
1:0 (rep 2),3-Recover,159.433,1.853,1.305,0.118,,0.413236,1502.42,,41.3236,1.50242,,,,7.85398e-5
1:0 (rep 2),3-Recover,159.8,1.876,1.282,0.111,,0.405953,1413.3,,40.5953,1.4133,,,,7.85398e-5
1:0 (rep 2),3-Recover,160.167,1.9,1.258,0.104,,0.398353,1324.17,,39.8353,1.32417,,,,7.85398e-5
1:0 (rep 2),3-Recover,160.533,1.923,1.235,0.104,,0.39107,1324.17,,39.107,1.32417,,,,7.85398e-5
1:0 (rep 2),3-Recover,160.9,1.946,1.212,0.104,,0.383787,1324.17,,38.3787,1.32417,,,,7.85398e-5
1:0 (rep 2),3-Recover,161.267,1.969,1.189,0.104,,0.376504,1324.17,,37.6504,1.32417,,,,7.85398e-5
1:0 (rep 2),3-Recover,161.633,1.992,1.166,0.104,,0.369221,1324.17,,36.9221,1.32417,,,,7.85398e-5
1:0 (rep 2),3-Recover,162,2.016,1.142,0.104,,0.361621,1324.17,,36.1621,1.32417,,,,7.85398e-5
1:0 (rep 2),3-Recover,162.367,2.039,1.119,0.104,,0.354338,1324.17,,35.4338,1.32417,,,,7.85398e-5
1:0 (rep 2),3-Recover,162.733,2.062,1.096,0.098,,0.347055,1247.78,,34.7055,1.24778,,,,7.85398e-5
1:0 (rep 2),3-Recover,163.1,2.085,1.073,0.104,,0.339772,1324.17,,33.9772,1.32417,,,,7.85398e-5
1:0 (rep 2),3-Recover,163.467,2.109,1.049,0.084,,0.332172,1069.52,,33.2172,1.06952,,,,7.85398e-5
1:0 (rep 2),3-Recover,163.833,2.131,1.027,0.104,,0.325206,1324.17,,32.5206,1.32417,,,,7.85398e-5
1:0 (rep 2),3-Recover,164.2,2.155,1.003,0.091,,0.317606,1158.65,,31.7606,1.15865,,,,7.85398e-5
1:0 (rep 2),3-Recover,164.567,2.178,0.98,0.07,,0.310323,891.268,,31.0323,0.891268,,,,7.85398e-5
1:0 (rep 2),3-Recover,164.933,2.201,0.957,0.07,,0.30304,891.268,,30.304,0.891268,,,,7.85398e-5
1:0 (rep 2),3-Recover,165.3,2.224,0.934,0.05,,0.295757,636.62,,29.5757,0.63662,,,,7.85398e-5
1:0 (rep 2),3-Recover,165.667,2.248,0.91,0.057,,0.288157,725.747,,28.8157,0.725747,,,,7.85398e-5
1:0 (rep 2),3-Recover,166.033,2.27,0.888,0.05,,0.281191,636.62,,28.1191,0.63662,,,,7.85398e-5
1:0 (rep 2),3-Recover,166.4,2.294,0.864,0.084,,0.273591,1069.52,,27.3591,1.06952,,,,7.85398e-5
1:0 (rep 2),3-Recover,166.767,2.317,0.841,0.05,,0.266308,636.62,,26.6308,0.63662,,,,7.85398e-5
1:0 (rep 2),3-Recover,167.133,2.34,0.818,0.057,,0.259025,725.747,,25.9025,0.725747,,,,7.85398e-5
1:0 (rep 2),3-Recover,167.5,2.363,0.795,0.05,,0.251742,636.62,,25.1742,0.63662,,,,7.85398e-5
1:0 (rep 2),3-Recover,167.867,2.387,0.771,0.05,,0.244142,636.62,,24.4142,0.63662,,,,7.85398e-5
1:0 (rep 2),3-Recover,168.233,2.41,0.748,0.05,,0.236859,636.62,,23.6859,0.63662,,,,7.85398e-5
1:0 (rep 2),3-Recover,168.6,2.433,0.725,0.05,,0.229576,636.62,,22.9576,0.63662,,,,7.85398e-5
1:0 (rep 2),3-Recover,168.967,2.457,0.701,0.05,,0.221976,636.62,,22.1976,0.63662,,,,7.85398e-5
1:0 (rep 2),3-Recover,169.333,2.479,0.679,0.05,,0.215009,636.62,,21.5009,0.63662,,,,7.85398e-5
1:0 (rep 2),3-Recover,169.7,2.503,0.655,0.05,,0.20741,636.62,,20.741,0.63662,,,,7.85398e-5
1:0 (rep 2),3-Recover,170.067,2.526,0.632,0.05,,0.200127,636.62,,20.0127,0.63662,,,,7.85398e-5
1:0 (rep 2),3-Recover,170.433,2.549,0.609,0.05,,0.192844,636.62,,19.2844,0.63662,,,,7.85398e-5
1:0 (rep 2),3-Recover,170.8,2.572,0.586,0.05,,0.18556,636.62,,18.556,0.63662,,,,7.85398e-5
1:0 (rep 2),3-Recover,171.167,2.596,0.562,0.05,,0.177961,636.62,,17.7961,0.63662,,,,7.85398e-5
1:0 (rep 2),3-Recover,171.533,2.619,0.539,0.05,,0.170678,636.62,,17.0678,0.63662,,,,7.85398e-5
1:0 (rep 2),3-Recover,171.9,2.642,0.516,0.043,,0.163395,547.493,,16.3395,0.547493,,,,7.85398e-5
1:0 (rep 2),3-Recover,172.267,2.665,0.493,0.03,,0.156111,381.972,,15.6111,0.381972,,,,7.85398e-5
1:0 (rep 2),3-Recover,172.633,2.688,0.47,0.043,,0.148828,547.493,,14.8828,0.547493,,,,7.85398e-5
1:0 (rep 2),3-Recover,173,2.712,0.446,0.009,,0.141229,114.592,,14.1229,0.114592,,,,7.85398e-5
1:0 (rep 2),3-Recover,173.367,2.735,0.423,0.023,,0.133946,292.845,,13.3946,0.292845,,,,7.85398e-5
1:0 (rep 2),3-Recover,173.733,2.758,0.4,0.036,,0.126662,458.366,,12.6662,0.458366,,,,7.85398e-5
1:0 (rep 2),3-Recover,174.1,2.781,0.377,0.03,,0.119379,381.972,,11.9379,0.381972,,,,7.85398e-5
1:0 (rep 2),3-Recover,174.467,2.804,0.354,0.016,,0.112096,203.718,,11.2096,0.203718,,,,7.85398e-5
1:0 (rep 2),3-Recover,174.833,2.827,0.331,0.009,,0.104813,114.592,,10.4813,0.114592,,,,7.85398e-5
1:0 (rep 2),3-Recover,175.2,2.851,0.307,0.002,,0.0972134,25.4648,,9.72134,0.0254648,,,,7.85398e-5
1:0 (rep 2),3-Recover,175.567,2.874,0.284,0.009,,0.0899303,114.592,,8.99303,0.114592,,,,7.85398e-5
1:0 (rep 2),3-Recover,175.933,2.897,0.261,0.016,,0.0826472,203.718,,8.26472,0.203718,,,,7.85398e-5
1:0 (rep 2),3-Recover,176.3,2.921,0.237,0.016,,0.0750475,203.718,,7.50475,0.203718,,,,7.85398e-5
1:0 (rep 2),3-Recover,176.667,2.944,0.214,0.023,,0.0677644,292.845,,6.77644,0.292845,,,,7.85398e-5
1:0 (rep 2),3-Recover,177.033,2.967,0.191,0.009,,0.0604813,114.592,,6.04813,0.114592,,,,7.85398e-5
1:0 (rep 2),3-Recover,177.4,2.99,0.168,0.009,,0.0531982,114.592,,5.31982,0.114592,,,,7.85398e-5
1:0 (rep 2),3-Recover,177.767,3.014,0.144,0.002,,0.0455985,25.4648,,4.55985,0.0254648,,,,7.85398e-5
1:0 (rep 2),3-Recover,178.133,3.036,0.122,0.002,,0.038632,25.4648,,3.8632,0.0254648,,,,7.85398e-5
1:0 (rep 2),3-Recover,178.5,3.06,0.098,0.009,,0.0310323,114.592,,3.10323,0.114592,,,,7.85398e-5
1:0 (rep 2),3-Recover,178.867,3.083,0.075,0.002,,0.0237492,25.4648,,2.37492,0.0254648,,,,7.85398e-5
1:0 (rep 2),3-Recover,179.233,3.106,0.052,0.009,,0.0164661,114.592,,1.64661,0.114592,,,,7.85398e-5
1:0 (rep 2),3-Recover,179.6,3.129,0.029,0.002,,0.00918303,25.4648,,0.918303,0.0254648,,,,7.85398e-5
1:0 (rep 2),3-Recover,179.967,3.152,0.006,0.002,,0.00189994,25.4648,,0.189994,0.0254648,,,,7.85398e-5
1:0 (rep 2),3-Recover,180.1,3.158,0,0.016,,0,203.718,,0,0.203718,,,,7.85398e-5