File: data/beta_1-2-1_1.csv
SetName,Cycle,Time_S,Size_mm,Displacement_mm,Force_N,,Strain,Stress(Pascal),,%Strain,Stress(kPa),,,,Area(m^2)
Test1,1-Compress,0.000,6.123,-0,-0.021,,0,-267.38,,0,-0.26738,,,,7.85398e-5
Test1,1-Compress,0.333,6.085,0.038,-0.000,,0.00620611,0,,0.620611,0,,,,7.85398e-5
Test1,1-Compress,0.667,6.043,0.08,-0.007,,0.0130655,-89.1268,,1.30655,-0.0891268,,,,7.85398e-5
Test1,1-Compress,1.000,6.002,0.121,0.007,,0.0197616,89.1268,,1.97616,0.0891268,,,,7.85398e-5
Test1,1-Compress,1.333,5.962,0.161,-0.000,,0.0262943,0,,2.62943,0,,,,7.85398e-5
Test1,1-Compress,1.667,5.92,0.203,-0.000,,0.0331537,0,,3.31537,0,,,,7.85398e-5
Test1,1-Compress,2.000,5.88,0.243,0.013,,0.0396864,165.521,,3.96864,0.165521,,,,7.85398e-5
Test1,1-Compress,2.333,5.839,0.284,0.007,,0.0463825,89.1268,,4.63825,0.0891268,,,,7.85398e-5
Test1,1-Compress,2.667,5.797,0.326,-0.000,,0.0532419,0,,5.32419,0,,,,7.85398e-5
Test1,1-Compress,3.000,5.757,0.366,-0.000,,0.0597746,0,,5.97746,0,,,,7.85398e-5
Test1,1-Compress,3.333,5.717,0.406,-0.000,,0.0663074,0,,6.63074,0,,,,7.85398e-5
Test1,1-Compress,3.667,5.675,0.448,-0.000,,0.0731667,0,,7.31667,0,,,,7.85398e-5
Test1,1-Compress,4.000,5.634,0.489,0.007,,0.0798628,89.1268,,7.98628,0.0891268,,,,7.85398e-5
Test1,1-Compress,4.333,5.594,0.529,0.020,,0.0863956,254.648,,8.63956,0.254648,,,,7.85398e-5
Test1,1-Compress,4.667,5.552,0.571,0.020,,0.0932549,254.648,,9.32549,0.254648,,,,7.85398e-5
Test1,1-Compress,5.000,5.512,0.611,-0.000,,0.0997877,0,,9.97877,0,,,,7.85398e-5
Test1,1-Compress,5.333,5.471,0.652,0.007,,0.106484,89.1268,,10.6484,0.0891268,,,,7.85398e-5
Test1,1-Compress,5.667,5.429,0.694,-0.000,,0.113343,0,,11.3343,0,,,,7.85398e-5
Test1,1-Compress,6.000,5.389,0.734,-0.000,,0.119876,0,,11.9876,0,,,,7.85398e-5
Test1,1-Compress,6.333,5.349,0.774,-0.000,,0.126409,0,,12.6409,0,,,,7.85398e-5
Test1,1-Compress,6.667,5.307,0.816,0.007,,0.133268,89.1268,,13.3268,0.0891268,,,,7.85398e-5
Test1,1-Compress,7.000,5.266,0.857,0.007,,0.139964,89.1268,,13.9964,0.0891268,,,,7.85398e-5
Test1,1-Compress,7.333,5.226,0.897,0.007,,0.146497,89.1268,,14.6497,0.0891268,,,,7.85398e-5
Test1,1-Compress,7.667,5.184,0.939,-0.007,,0.153356,-89.1268,,15.3356,-0.0891268,,,,7.85398e-5
Test1,1-Compress,8.000,5.144,0.979,-0.014,,0.159889,-178.254,,15.9889,-0.178254,,,,7.85398e-5
Test1,1-Compress,8.333,5.103,1.02,-0.007,,0.166585,-89.1268,,16.6585,-0.0891268,,,,7.85398e-5
Test1,1-Compress,8.667,5.062,1.061,0.013,,0.173281,165.521,,17.3281,0.165521,,,,7.85398e-5
Test1,1-Compress,9.000,5.021,1.102,0.013,,0.179977,165.521,,17.9977,0.165521,,,,7.85398e-5
Test1,1-Compress,9.333,4.981,1.142,0.007,,0.18651,89.1268,,18.651,0.0891268,,,,7.85398e-5
Test1,1-Compress,9.667,4.939,1.184,0.007,,0.193369,89.1268,,19.3369,0.0891268,,,,7.85398e-5
Test1,1-Compress,10.000,4.899,1.224,0.007,,0.199902,89.1268,,19.9902,0.0891268,,,,7.85398e-5
Test1,1-Compress,10.333,4.858,1.265,0.013,,0.206598,165.521,,20.6598,0.165521,,,,7.85398e-5
Test1,1-Compress,10.667,4.816,1.307,-0.000,,0.213457,0,,21.3457,0,,,,7.85398e-5
Test1,1-Compress,11.000,4.776,1.347,-0.007,,0.21999,-89.1268,,21.999,-0.0891268,,,,7.85398e-5
Test1,1-Compress,11.333,4.736,1.387,-0.000,,0.226523,0,,22.6523,0,,,,7.85398e-5
Test1,1-Compress,11.667,4.694,1.429,0.013,,0.233382,165.521,,23.3382,0.165521,,,,7.85398e-5
Test1,1-Compress,12.000,4.653,1.47,-0.000,,0.240078,0,,24.0078,0,,,,7.85398e-5
Test1,1-Compress,12.333,4.613,1.51,-0.014,,0.246611,-178.254,,24.6611,-0.178254,,,,7.85398e-5
Test1,1-Compress,12.667,4.571,1.552,-0.007,,0.253471,-89.1268,,25.3471,-0.0891268,,,,7.85398e-5
Test1,1-Compress,13.000,4.531,1.592,0.013,,0.260003,165.521,,26.0003,0.165521,,,,7.85398e-5
Test1,1-Compress,13.333,4.49,1.633,-0.014,,0.266699,-178.254,,26.6699,-0.178254,,,,7.85398e-5
Test1,1-Compress,13.667,4.448,1.675,-0.007,,0.273559,-89.1268,,27.3559,-0.0891268,,,,7.85398e-5
Test1,1-Compress,14.000,4.408,1.715,-0.007,,0.280091,-89.1268,,28.0091,-0.0891268,,,,7.85398e-5
Test1,1-Compress,14.333,4.367,1.756,-0.000,,0.286788,0,,28.6788,0,,,,7.85398e-5
Test1,1-Compress,14.667,4.326,1.797,0.027,,0.293484,343.775,,29.3484,0.343775,,,,7.85398e-5
Test1,1-Compress,15.000,4.285,1.838,0.020,,0.30018,254.648,,30.018,0.254648,,,,7.85398e-5
Test1,1-Compress,15.333,4.244,1.879,0.034,,0.306876,432.902,,30.6876,0.432902,,,,7.85398e-5
Test1,1-Compress,15.667,4.203,1.92,0.027,,0.313572,343.775,,31.3572,0.343775,,,,7.85398e-5
Test1,1-Compress,16.000,4.163,1.96,0.027,,0.320105,343.775,,32.0105,0.343775,,,,7.85398e-5
Test1,1-Compress,16.333,4.122,2.001,0.020,,0.326801,254.648,,32.6801,0.254648,,,,7.85398e-5
Test1,1-Compress,16.667,4.08,2.043,0.027,,0.33366,343.775,,33.366,0.343775,,,,7.85398e-5
Test1,1-Compress,17.000,4.04,2.083,0.027,,0.340193,343.775,,34.0193,0.343775,,,,7.85398e-5
Test1,1-Compress,17.333,3.999,2.124,0.034,,0.346889,432.902,,34.6889,0.432902,,,,7.85398e-5
Test1,1-Compress,17.667,3.958,2.165,0.034,,0.353585,432.902,,35.3585,0.432902,,,,7.85398e-5
Test1,1-Compress,18.000,3.917,2.206,0.027,,0.360281,343.775,,36.0281,0.343775,,,,7.85398e-5
Test1,1-Compress,18.333,3.877,2.246,0.034,,0.366814,432.902,,36.6814,0.432902,,,,7.85398e-5
Test1,1-Compress,18.667,3.835,2.288,0.027,,0.373673,343.775,,37.3673,0.343775,,,,7.85398e-5
Test1,1-Compress,19.000,3.794,2.329,0.034,,0.380369,432.902,,38.0369,0.432902,,,,7.85398e-5
Test1,1-Compress,19.333,3.754,2.369,0.034,,0.386902,432.902,,38.6902,0.432902,,,,7.85398e-5
Test1,1-Compress,19.667,3.713,2.41,0.034,,0.393598,432.902,,39.3598,0.432902,,,,7.85398e-5
Test1,1-Compress,20.000,3.672,2.451,0.034,,0.400294,432.902,,40.0294,0.432902,,,,7.85398e-5
Test1,1-Compress,20.333,3.631,2.492,0.034,,0.40699,432.902,,40.699,0.432902,,,,7.85398e-5
Test1,1-Compress,20.667,3.59,2.533,0.034,,0.413686,432.902,,41.3686,0.432902,,,,7.85398e-5
Test1,1-Compress,21.000,3.549,2.574,0.041,,0.420382,522.028,,42.0382,0.522028,,,,7.85398e-5
Test1,1-Compress,21.333,3.509,2.614,0.041,,0.426915,522.028,,42.6915,0.522028,,,,7.85398e-5
Test1,1-Compress,21.667,3.467,2.656,0.041,,0.433774,522.028,,43.3774,0.522028,,,,7.85398e-5
Test1,1-Compress,22.000,3.427,2.696,0.047,,0.440307,598.423,,44.0307,0.598423,,,,7.85398e-5
Test1,1-Compress,22.333,3.386,2.737,0.047,,0.447003,598.423,,44.7003,0.598423,,,,7.85398e-5
Test1,1-Compress,22.667,3.344,2.779,0.047,,0.453862,598.423,,45.3862,0.598423,,,,7.85398e-5
Test1,1-Compress,23.000,3.304,2.819,0.041,,0.460395,522.028,,46.0395,0.522028,,,,7.85398e-5
Test1,1-Compress,23.333,3.263,2.86,0.047,,0.467091,598.423,,46.7091,0.598423,,,,7.85398e-5
Test1,1-Compress,23.667,3.222,2.901,0.041,,0.473787,522.028,,47.3787,0.522028,,,,7.85398e-5
Test1,1-Compress,24.000,3.181,2.942,0.034,,0.480483,432.902,,48.0483,0.432902,,,,7.85398e-5
Test1,1-Compress,24.333,3.141,2.982,0.034,,0.487016,432.902,,48.7016,0.432902,,,,7.85398e-5
Test1,1-Compress,24.667,3.099,3.024,0.034,,0.493876,432.902,,49.3876,0.432902,,,,7.85398e-5
Test1,1-Compress,25.000,3.058,3.065,0.034,,0.500572,432.902,,50.0572,0.432902,,,,7.85398e-5
Test1,1-Compress,25.333,3.018,3.105,0.034,,0.507104,432.902,,50.7104,0.432902,,,,7.85398e-5
Test1,1-Compress,25.667,2.977,3.146,0.034,,0.5138,432.902,,51.38,0.432902,,,,7.85398e-5
Test1,1-Compress,26.000,2.936,3.187,0.041,,0.520496,522.028,,52.0496,0.522028,,,,7.85398e-5
Test1,1-Compress,26.333,2.895,3.228,0.034,,0.527193,432.902,,52.7193,0.432902,,,,7.85398e-5
Test1,1-Compress,26.667,2.854,3.269,0.034,,0.533889,432.902,,53.3889,0.432902,,,,7.85398e-5
Test1,1-Compress,27.000,2.813,3.31,0.041,,0.540585,522.028,,54.0585,0.522028,,,,7.85398e-5
Test1,1-Compress,27.333,2.773,3.35,0.041,,0.547117,522.028,,54.7117,0.522028,,,,7.85398e-5
Test1,1-Compress,27.667,2.731,3.392,0.041,,0.553977,522.028,,55.3977,0.522028,,,,7.85398e-5
Test1,1-Compress,28.000,2.69,3.433,0.041,,0.560673,522.028,,56.0673,0.522028,,,,7.85398e-5
Test1,1-Compress,28.333,2.65,3.473,0.041,,0.567206,522.028,,56.7206,0.522028,,,,7.85398e-5
Test1,1-Compress,28.667,2.608,3.515,0.041,,0.574065,522.028,,57.4065,0.522028,,,,7.85398e-5
Test1,1-Compress,29.000,2.568,3.555,0.041,,0.580598,522.028,,58.0598,0.522028,,,,7.85398e-5
Test1,1-Compress,29.333,2.527,3.596,0.041,,0.587294,522.028,,58.7294,0.522028,,,,7.85398e-5
Test1,1-Compress,29.667,2.486,3.637,0.041,,0.59399,522.028,,59.399,0.522028,,,,7.85398e-5
Test1,1-Compress,30.000,2.449,3.674,0.047,,0.600033,598.423,,60.0033,0.598423,,,,7.85398e-5
Test1,1-Recover,30.333,2.486,3.637,0.047,,0.59399,598.423,,59.399,0.598423,,,,7.85398e-5
Test1,1-Recover,30.667,2.527,3.596,0.047,,0.587294,598.423,,58.7294,0.598423,,,,7.85398e-5
Test1,1-Recover,31.000,2.568,3.555,0.047,,0.580598,598.423,,58.0598,0.598423,,,,7.85398e-5
Test1,1-Recover,31.333,2.608,3.515,0.047,,0.574065,598.423,,57.4065,0.598423,,,,7.85398e-5
Test1,1-Recover,31.667,2.65,3.473,0.041,,0.567206,522.028,,56.7206,0.522028,,,,7.85398e-5
Test1,1-Recover,32.000,2.69,3.433,0.034,,0.560673,432.902,,56.0673,0.432902,,,,7.85398e-5
Test1,1-Recover,32.333,2.731,3.392,0.034,,0.553977,432.902,,55.3977,0.432902,,,,7.85398e-5
Test1,1-Recover,32.667,2.773,3.35,0.034,,0.547117,432.902,,54.7117,0.432902,,,,7.85398e-5
Test1,1-Recover,33.000,2.813,3.31,0.034,,0.540585,432.902,,54.0585,0.432902,,,,7.85398e-5
Test1,1-Recover,33.333,2.854,3.269,0.034,,0.533889,432.902,,53.3889,0.432902,,,,7.85398e-5
Test1,1-Recover,33.667,2.895,3.228,0.034,,0.527193,432.902,,52.7193,0.432902,,,,7.85398e-5
Test1,1-Recover,34.000,2.936,3.187,0.034,,0.520496,432.902,,52.0496,0.432902,,,,7.85398e-5
Test1,1-Recover,34.333,2.976,3.147,0.027,,0.513964,343.775,,51.3964,0.343775,,,,7.85398e-5
Test1,1-Recover,34.667,3.018,3.105,0.020,,0.507104,254.648,,50.7104,0.254648,,,,7.85398e-5
Test1,1-Recover,35.000,3.058,3.065,0.020,,0.500572,254.648,,50.0572,0.254648,,,,7.85398e-5
Test1,1-Recover,35.333,3.099,3.024,0.027,,0.493876,343.775,,49.3876,0.343775,,,,7.85398e-5
Test1,1-Recover,35.667,3.141,2.982,0.027,,0.487016,343.775,,48.7016,0.343775,,,,7.85398e-5
Test1,1-Recover,36.000,3.181,2.942,-0.007,,0.480483,-89.1268,,48.0483,-0.0891268,,,,7.85398e-5
Test1,1-Recover,36.333,3.221,2.902,-0.014,,0.473951,-178.254,,47.3951,-0.178254,,,,7.85398e-5
Test1,1-Recover,36.667,3.263,2.86,0.007,,0.467091,89.1268,,46.7091,0.0891268,,,,7.85398e-5
Test1,1-Recover,37.000,3.304,2.819,0.007,,0.460395,89.1268,,46.0395,0.0891268,,,,7.85398e-5
Test1,1-Recover,37.333,3.344,2.779,-0.014,,0.453862,-178.254,,45.3862,-0.178254,,,,7.85398e-5
Test1,1-Recover,37.667,3.386,2.737,-0.007,,0.447003,-89.1268,,44.7003,-0.0891268,,,,7.85398e-5
Test1,1-Recover,38.000,3.426,2.697,0.013,,0.44047,165.521,,44.047,0.165521,,,,7.85398e-5
Test1,1-Recover,38.333,3.467,2.656,0.007,,0.433774,89.1268,,43.3774,0.0891268,,,,7.85398e-5
Test1,1-Recover,38.667,3.509,2.614,0.013,,0.426915,165.521,,42.6915,0.165521,,,,7.85398e-5
Test1,1-Recover,39.000,3.549,2.574,-0.000,,0.420382,0,,42.0382,0,,,,7.85398e-5
Test1,1-Recover,39.333,3.59,2.533,0.007,,0.413686,89.1268,,41.3686,0.0891268,,,,7.85398e-5
Test1,1-Recover,39.667,3.631,2.492,0.013,,0.40699,165.521,,40.699,0.165521,,,,7.85398e-5
Test1,1-Recover,40.000,3.672,2.451,-0.000,,0.400294,0,,40.0294,0,,,,7.85398e-5
Test1,1-Recover,40.333,3.712,2.411,0.013,,0.393761,165.521,,39.3761,0.165521,,,,7.85398e-5
Test1,1-Recover,40.667,3.754,2.369,0.007,,0.386902,89.1268,,38.6902,0.0891268,,,,7.85398e-5
Test1,1-Recover,41.000,3.794,2.329,-0.000,,0.380369,0,,38.0369,0,,,,7.85398e-5
Test1,1-Recover,41.333,3.835,2.288,-0.000,,0.373673,0,,37.3673,0,,,,7.85398e-5
Test1,1-Recover,41.667,3.877,2.246,-0.007,,0.366814,-89.1268,,36.6814,-0.0891268,,,,7.85398e-5
Test1,1-Recover,42.000,3.917,2.206,-0.007,,0.360281,-89.1268,,36.0281,-0.0891268,,,,7.85398e-5
Test1,1-Recover,42.333,3.957,2.166,0.007,,0.353748,89.1268,,35.3748,0.0891268,,,,7.85398e-5
Test1,1-Recover,42.667,3.999,2.124,-0.000,,0.346889,0,,34.6889,0,,,,7.85398e-5
Test1,1-Recover,43.000,4.04,2.083,0.013,,0.340193,165.521,,34.0193,0.165521,,,,7.85398e-5
Test1,1-Recover,43.333,4.08,2.043,-0.007,,0.33366,-89.1268,,33.366,-0.0891268,,,,7.85398e-5
Test1,1-Recover,43.667,4.122,2.001,-0.021,,0.326801,-267.38,,32.6801,-0.26738,,,,7.85398e-5
Test1,1-Recover,44.000,4.162,1.961,0.007,,0.320268,89.1268,,32.0268,0.0891268,,,,7.85398e-5
Test1,1-Recover,44.333,4.203,1.92,-0.000,,0.313572,0,,31.3572,0,,,,7.85398e-5
Test1,1-Recover,44.667,4.244,1.879,0.007,,0.306876,89.1268,,30.6876,0.0891268,,,,7.85398e-5
Test1,1-Recover,45.000,4.285,1.838,-0.007,,0.30018,-89.1268,,30.018,-0.0891268,,,,7.85398e-5
Test1,1-Recover,45.333,4.326,1.797,-0.000,,0.293484,0,,29.3484,0,,,,7.85398e-5
Test1,1-Recover,45.667,4.367,1.756,0.013,,0.286788,165.521,,28.6788,0.165521,,,,7.85398e-5
Test1,1-Recover,46.000,4.407,1.716,0.007,,0.280255,89.1268,,28.0255,0.0891268,,,,7.85398e-5
Test1,1-Recover,46.333,4.448,1.675,0.007,,0.273559,89.1268,,27.3559,0.0891268,,,,7.85398e-5
Test1,1-Recover,46.667,4.49,1.633,0.007,,0.266699,89.1268,,26.6699,0.0891268,,,,7.85398e-5
Test1,1-Recover,47.000,4.53,1.593,0.013,,0.260167,165.521,,26.0167,0.165521,,,,7.85398e-5
Test1,1-Recover,47.333,4.571,1.552,-0.000,,0.253471,0,,25.3471,0,,,,7.85398e-5
Test1,1-Recover,47.667,4.612,1.511,0.007,,0.246774,89.1268,,24.6774,0.0891268,,,,7.85398e-5
Test1,1-Recover,48.000,4.653,1.47,-0.007,,0.240078,-89.1268,,24.0078,-0.0891268,,,,7.85398e-5
Test1,1-Recover,48.333,4.693,1.43,-0.007,,0.233546,-89.1268,,23.3546,-0.0891268,,,,7.85398e-5
Test1,1-Recover,48.667,4.735,1.388,-0.000,,0.226686,0,,22.6686,0,,,,7.85398e-5
Test1,1-Recover,49.000,4.776,1.347,-0.000,,0.21999,0,,21.999,0,,,,7.85398e-5
Test1,1-Recover,49.333,4.816,1.307,-0.007,,0.213457,-89.1268,,21.3457,-0.0891268,,,,7.85398e-5
Test1,1-Recover,49.667,4.858,1.265,-0.000,,0.206598,0,,20.6598,0,,,,7.85398e-5
Test1,1-Recover,50.000,4.899,1.224,0.007,,0.199902,89.1268,,19.9902,0.0891268,,,,7.85398e-5
Test1,1-Recover,50.333,4.939,1.184,0.013,,0.193369,165.521,,19.3369,0.165521,,,,7.85398e-5
Test1,1-Recover,50.667,4.98,1.143,0.007,,0.186673,89.1268,,18.6673,0.0891268,,,,7.85398e-5
Test1,1-Recover,51.000,5.021,1.102,-0.007,,0.179977,-89.1268,,17.9977,-0.0891268,,,,7.85398e-5
Test1,1-Recover,51.333,5.062,1.061,-0.000,,0.173281,0,,17.3281,0,,,,7.85398e-5
Test1,1-Recover,51.667,5.103,1.02,0.007,,0.166585,89.1268,,16.6585,0.0891268,,,,7.85398e-5
Test1,1-Recover,52.000,5.144,0.979,0.013,,0.159889,165.521,,15.9889,0.165521,,,,7.85398e-5
Test1,1-Recover,52.333,5.184,0.939,0.013,,0.153356,165.521,,15.3356,0.165521,,,,7.85398e-5
Test1,1-Recover,52.667,5.226,0.897,0.007,,0.146497,89.1268,,14.6497,0.0891268,,,,7.85398e-5
Test1,1-Recover,53.000,5.266,0.857,0.013,,0.139964,165.521,,13.9964,0.165521,,,,7.85398e-5
Test1,1-Recover,53.333,5.307,0.816,0.007,,0.133268,89.1268,,13.3268,0.0891268,,,,7.85398e-5
Test1,1-Recover,53.667,5.349,0.774,0.013,,0.126409,165.521,,12.6409,0.165521,,,,7.85398e-5
Test1,1-Recover,54.000,5.389,0.734,0.034,,0.119876,432.902,,11.9876,0.432902,,,,7.85398e-5
Test1,1-Recover,54.333,5.429,0.694,0.013,,0.113343,165.521,,11.3343,0.165521,,,,7.85398e-5
Test1,1-Recover,54.667,5.471,0.652,-0.000,,0.106484,0,,10.6484,0,,,,7.85398e-5
Test1,1-Recover,55.000,5.512,0.611,0.020,,0.0997877,254.648,,9.97877,0.254648,,,,7.85398e-5
Test1,1-Recover,55.333,5.552,0.571,-0.000,,0.0932549,0,,9.32549,0,,,,7.85398e-5
Test1,1-Recover,55.667,5.594,0.529,0.007,,0.0863956,89.1268,,8.63956,0.0891268,,,,7.85398e-5
Test1,1-Recover,56.000,5.634,0.489,-0.007,,0.0798628,-89.1268,,7.98628,-0.0891268,,,,7.85398e-5
Test1,1-Recover,56.333,5.675,0.448,0.007,,0.0731667,89.1268,,7.31667,0.0891268,,,,7.85398e-5
Test1,1-Recover,56.667,5.716,0.407,0.013,,0.0664707,165.521,,6.64707,0.165521,,,,7.85398e-5
Test1,1-Recover,57.000,5.757,0.366,-0.000,,0.0597746,0,,5.97746,0,,,,7.85398e-5
Test1,1-Recover,57.333,5.797,0.326,-0.000,,0.0532419,0,,5.32419,0,,,,7.85398e-5
Test1,1-Recover,57.667,5.839,0.284,0.007,,0.0463825,89.1268,,4.63825,0.0891268,,,,7.85398e-5
Test1,1-Recover,58.000,5.88,0.243,0.007,,0.0396864,89.1268,,3.96864,0.0891268,,,,7.85398e-5
Test1,1-Recover,58.333,5.92,0.203,0.007,,0.0331537,89.1268,,3.31537,0.0891268,,,,7.85398e-5
Test1,1-Recover,58.667,5.962,0.161,-0.000,,0.0262943,0,,2.62943,0,,,,7.85398e-5
Test1,1-Recover,59.000,6.002,0.121,0.007,,0.0197616,89.1268,,1.97616,0.0891268,,,,7.85398e-5
Test1,1-Recover,59.333,6.043,0.08,-0.000,,0.0130655,0,,1.30655,0,,,,7.85398e-5
Test1,1-Recover,59.667,6.085,0.038,0.020,,0.00620611,254.648,,0.620611,0.254648,,,,7.85398e-5
Test1,1-Recover,60.000,6.123,-0,0.027,,0,343.775,,0,0.343775,,,,7.85398e-5
Test1,2-Compress,60.317,6.09,0.033,-0.000,,0.00538951,0,,0.538951,0,,,,7.85398e-5
Test1,2-Compress,60.650,6.05,0.073,0.027,,0.0119223,343.775,,1.19223,0.343775,,,,7.85398e-5
Test1,2-Compress,60.983,6.01,0.113,0.013,,0.018455,165.521,,1.8455,0.165521,,,,7.85398e-5
Test1,2-Compress,61.317,5.968,0.155,0.027,,0.0253144,343.775,,2.53144,0.343775,,,,7.85398e-5
Test1,2-Compress,61.650,5.927,0.196,0.007,,0.0320105,89.1268,,3.20105,0.0891268,,,,7.85398e-5
Test1,2-Compress,61.983,5.887,0.236,-0.000,,0.0385432,0,,3.85432,0,,,,7.85398e-5
Test1,2-Compress,62.317,5.845,0.278,0.020,,0.0454026,254.648,,4.54026,0.254648,,,,7.85398e-5
Test1,2-Compress,62.650,5.805,0.318,0.013,,0.0519353,165.521,,5.19353,0.165521,,,,7.85398e-5
Test1,2-Compress,62.983,5.764,0.359,-0.000,,0.0586314,0,,5.86314,0,,,,7.85398e-5
Test1,2-Compress,63.317,5.723,0.4,0.013,,0.0653275,165.521,,6.53275,0.165521,,,,7.85398e-5
Test1,2-Compress,63.650,5.682,0.441,0.007,,0.0720235,89.1268,,7.20235,0.0891268,,,,7.85398e-5
Test1,2-Compress,63.983,5.642,0.481,0.013,,0.0785563,165.521,,7.85563,0.165521,,,,7.85398e-5
Test1,2-Compress,64.317,5.6,0.523,-0.000,,0.0854156,0,,8.54156,0,,,,7.85398e-5
Test1,2-Compress,64.650,5.56,0.563,-0.000,,0.0919484,0,,9.19484,0,,,,7.85398e-5
Test1,2-Compress,64.983,5.519,0.604,-0.000,,0.0986445,0,,9.86445,0,,,,7.85398e-5
Test1,2-Compress,65.317,5.477,0.646,-0.000,,0.105504,0,,10.5504,0,,,,7.85398e-5
Test1,2-Compress,65.650,5.437,0.686,0.007,,0.112037,89.1268,,11.2037,0.0891268,,,,7.85398e-5
Test1,2-Compress,65.983,5.396,0.727,0.007,,0.118733,89.1268,,11.8733,0.0891268,,,,7.85398e-5
Test1,2-Compress,66.317,5.355,0.768,-0.000,,0.125429,0,,12.5429,0,,,,7.85398e-5
Test1,2-Compress,66.650,5.314,0.809,-0.007,,0.132125,-89.1268,,13.2125,-0.0891268,,,,7.85398e-5
Test1,2-Compress,66.983,5.274,0.849,-0.000,,0.138658,0,,13.8658,0,,,,7.85398e-5
Test1,2-Compress,67.317,5.232,0.891,0.007,,0.145517,89.1268,,14.5517,0.0891268,,,,7.85398e-5
Test1,2-Compress,67.650,5.192,0.931,0.013,,0.15205,165.521,,15.205,0.165521,,,,7.85398e-5
Test1,2-Compress,67.983,5.151,0.972,-0.000,,0.158746,0,,15.8746,0,,,,7.85398e-5
Test1,2-Compress,68.317,5.109,1.014,-0.007,,0.165605,-89.1268,,16.5605,-0.0891268,,,,7.85398e-5
Test1,2-Compress,68.650,5.069,1.054,0.007,,0.172138,89.1268,,17.2138,0.0891268,,,,7.85398e-5
Test1,2-Compress,68.983,5.028,1.095,0.013,,0.178834,165.521,,17.8834,0.165521,,,,7.85398e-5
Test1,2-Compress,69.317,4.987,1.136,0.013,,0.18553,165.521,,18.553,0.165521,,,,7.85398e-5
Test1,2-Compress,69.650,4.946,1.177,0.013,,0.192226,165.521,,19.2226,0.165521,,,,7.85398e-5
Test1,2-Compress,69.983,4.906,1.217,0.013,,0.198759,165.521,,19.8759,0.165521,,,,7.85398e-5
Test1,2-Compress,70.317,4.864,1.259,0.020,,0.205618,254.648,,20.5618,0.254648,,,,7.85398e-5
Test1,2-Compress,70.650,4.823,1.3,0.007,,0.212314,89.1268,,21.2314,0.0891268,,,,7.85398e-5
Test1,2-Compress,70.983,4.783,1.34,-0.014,,0.218847,-178.254,,21.8847,-0.178254,,,,7.85398e-5
Test1,2-Compress,71.317,4.741,1.382,0.007,,0.225706,89.1268,,22.5706,0.0891268,,,,7.85398e-5
Test1,2-Compress,71.650,4.701,1.422,0.007,,0.232239,89.1268,,23.2239,0.0891268,,,,7.85398e-5
Test1,2-Compress,71.983,4.66,1.463,0.013,,0.238935,165.521,,23.8935,0.165521,,,,7.85398e-5
Test1,2-Compress,72.317,4.619,1.504,-0.000,,0.245631,0,,24.5631,0,,,,7.85398e-5
Test1,2-Compress,72.650,4.578,1.545,-0.000,,0.252327,0,,25.2327,0,,,,7.85398e-5
Test1,2-Compress,72.983,4.538,1.585,-0.007,,0.25886,-89.1268,,25.886,-0.0891268,,,,7.85398e-5
Test1,2-Compress,73.317,4.496,1.627,-0.000,,0.265719,0,,26.5719,0,,,,7.85398e-5
Test1,2-Compress,73.650,4.455,1.668,0.020,,0.272415,254.648,,27.2415,0.254648,,,,7.85398e-5
Test1,2-Compress,73.983,4.415,1.708,-0.000,,0.278948,0,,27.8948,0,,,,7.85398e-5
Test1,2-Compress,74.317,4.373,1.75,-0.000,,0.285808,0,,28.5808,0,,,,7.85398e-5
Test1,2-Compress,74.650,4.333,1.79,-0.007,,0.29234,-89.1268,,29.234,-0.0891268,,,,7.85398e-5
Test1,2-Compress,74.983,4.292,1.831,-0.007,,0.299036,-89.1268,,29.9036,-0.0891268,,,,7.85398e-5
Test1,2-Compress,75.317,4.251,1.872,-0.014,,0.305732,-178.254,,30.5732,-0.178254,,,,7.85398e-5
Test1,2-Compress,75.650,4.21,1.913,0.007,,0.312429,89.1268,,31.2429,0.0891268,,,,7.85398e-5
Test1,2-Compress,75.983,4.17,1.953,-0.000,,0.318961,0,,31.8961,0,,,,7.85398e-5
Test1,2-Compress,76.317,4.128,1.995,-0.007,,0.325821,-89.1268,,32.5821,-0.0891268,,,,7.85398e-5
Test1,2-Compress,76.650,4.087,2.036,-0.007,,0.332517,-89.1268,,33.2517,-0.0891268,,,,7.85398e-5
Test1,2-Compress,76.983,4.047,2.076,-0.007,,0.339049,-89.1268,,33.9049,-0.0891268,,,,7.85398e-5
Test1,2-Compress,77.317,4.005,2.118,-0.007,,0.345909,-89.1268,,34.5909,-0.0891268,,,,7.85398e-5
Test1,2-Compress,77.650,3.965,2.158,-0.007,,0.352442,-89.1268,,35.2442,-0.0891268,,,,7.85398e-5
Test1,2-Compress,77.983,3.924,2.199,-0.000,,0.359138,0,,35.9138,0,,,,7.85398e-5
Test1,2-Compress,78.317,3.883,2.24,0.007,,0.365834,89.1268,,36.5834,0.0891268,,,,7.85398e-5
Test1,2-Compress,78.650,3.842,2.281,0.020,,0.37253,254.648,,37.253,0.254648,,,,7.85398e-5
Test1,2-Compress,78.983,3.802,2.321,0.013,,0.379063,165.521,,37.9063,0.165521,,,,7.85398e-5
Test1,2-Compress,79.317,3.76,2.363,0.027,,0.385922,343.775,,38.5922,0.343775,,,,7.85398e-5
Test1,2-Compress,79.650,3.719,2.404,0.020,,0.392618,254.648,,39.2618,0.254648,,,,7.85398e-5
Test1,2-Compress,79.983,3.679,2.444,0.027,,0.399151,343.775,,39.9151,0.343775,,,,7.85398e-5
Test1,2-Compress,80.317,3.637,2.486,0.027,,0.40601,343.775,,40.601,0.343775,,,,7.85398e-5
Test1,2-Compress,80.650,3.597,2.526,0.041,,0.412543,522.028,,41.2543,0.522028,,,,7.85398e-5
Test1,2-Compress,80.983,3.556,2.567,0.020,,0.419239,254.648,,41.9239,0.254648,,,,7.85398e-5
Test1,2-Compress,81.317,3.515,2.608,0.027,,0.425935,343.775,,42.5935,0.343775,,,,7.85398e-5
Test1,2-Compress,81.650,3.474,2.649,0.027,,0.432631,343.775,,43.2631,0.343775,,,,7.85398e-5
Test1,2-Compress,81.983,3.434,2.689,0.034,,0.439164,432.902,,43.9164,0.432902,,,,7.85398e-5
Test1,2-Compress,82.317,3.392,2.731,0.034,,0.446023,432.902,,44.6023,0.432902,,,,7.85398e-5
Test1,2-Compress,82.650,3.351,2.772,0.027,,0.452719,343.775,,45.2719,0.343775,,,,7.85398e-5
Test1,2-Compress,82.983,3.311,2.812,0.034,,0.459252,432.902,,45.9252,0.432902,,,,7.85398e-5
Test1,2-Compress,83.317,3.269,2.854,0.034,,0.466111,432.902,,46.6111,0.432902,,,,7.85398e-5
Test1,2-Compress,83.650,3.229,2.894,0.034,,0.472644,432.902,,47.2644,0.432902,,,,7.85398e-5
Test1,2-Compress,83.983,3.188,2.935,0.034,,0.47934,432.902,,47.934,0.432902,,,,7.85398e-5
Test1,2-Compress,84.317,3.147,2.976,0.034,,0.486036,432.902,,48.6036,0.432902,,,,7.85398e-5
Test1,2-Compress,84.650,3.106,3.017,0.041,,0.492732,522.028,,49.2732,0.522028,,,,7.85398e-5
Test1,2-Compress,84.983,3.066,3.057,0.034,,0.499265,432.902,,49.9265,0.432902,,,,7.85398e-5
Test1,2-Compress,85.317,3.024,3.099,0.034,,0.506124,432.902,,50.6124,0.432902,,,,7.85398e-5
Test1,2-Compress,85.650,2.984,3.139,0.041,,0.512657,522.028,,51.2657,0.522028,,,,7.85398e-5
Test1,2-Compress,85.983,2.943,3.18,0.034,,0.519353,432.902,,51.9353,0.432902,,,,7.85398e-5
Test1,2-Compress,86.317,2.901,3.222,0.041,,0.526213,522.028,,52.6213,0.522028,,,,7.85398e-5
Test1,2-Compress,86.650,2.861,3.262,0.041,,0.532745,522.028,,53.2745,0.522028,,,,7.85398e-5
Test1,2-Compress,86.983,2.821,3.302,0.041,,0.539278,522.028,,53.9278,0.522028,,,,7.85398e-5
Test1,2-Compress,87.317,2.779,3.344,0.047,,0.546138,598.423,,54.6138,0.598423,,,,7.85398e-5
Test1,2-Compress,87.650,2.738,3.385,0.041,,0.552834,522.028,,55.2834,0.522028,,,,7.85398e-5
Test1,2-Compress,87.983,2.698,3.425,0.041,,0.559366,522.028,,55.9366,0.522028,,,,7.85398e-5
Test1,2-Compress,88.317,2.656,3.467,0.041,,0.566226,522.028,,56.6226,0.522028,,,,7.85398e-5
Test1,2-Compress,88.650,2.616,3.507,0.034,,0.572758,432.902,,57.2758,0.432902,,,,7.85398e-5
Test1,2-Compress,88.983,2.575,3.548,0.034,,0.579455,432.902,,57.9455,0.432902,,,,7.85398e-5
Test1,2-Compress,89.317,2.533,3.59,0.034,,0.586314,432.902,,58.6314,0.432902,,,,7.85398e-5
Test1,2-Compress,89.650,2.493,3.63,0.034,,0.592847,432.902,,59.2847,0.432902,,,,7.85398e-5
Test1,2-Compress,89.983,2.453,3.67,0.034,,0.599379,432.902,,59.9379,0.432902,,,,7.85398e-5
Test1,2-Recover,90.303,2.477,3.646,0.034,,0.59546,432.902,,59.546,0.432902,,,,7.85398e-5
Test1,2-Recover,90.637,2.519,3.604,0.034,,0.5886,432.902,,58.86,0.432902,,,,7.85398e-5
Test1,2-Recover,90.970,2.559,3.564,0.034,,0.582068,432.902,,58.2068,0.432902,,,,7.85398e-5
Test1,2-Recover,91.303,2.6,3.523,0.034,,0.575372,432.902,,57.5372,0.432902,,,,7.85398e-5
Test1,2-Recover,91.637,2.642,3.481,0.034,,0.568512,432.902,,56.8512,0.432902,,,,7.85398e-5
Test1,2-Recover,91.970,2.682,3.441,0.034,,0.561979,432.902,,56.1979,0.432902,,,,7.85398e-5
Test1,2-Recover,92.303,2.723,3.4,0.034,,0.555283,432.902,,55.5283,0.432902,,,,7.85398e-5
Test1,2-Recover,92.637,2.764,3.359,0.013,,0.548587,165.521,,54.8587,0.165521,,,,7.85398e-5
Test1,2-Recover,92.970,2.805,3.318,-0.000,,0.541891,0,,54.1891,0,,,,7.85398e-5
Test1,2-Recover,93.303,2.845,3.278,-0.000,,0.535358,0,,53.5358,0,,,,7.85398e-5
Test1,2-Recover,93.637,2.887,3.236,0.013,,0.528499,165.521,,52.8499,0.165521,,,,7.85398e-5
Test1,2-Recover,93.970,2.927,3.196,0.007,,0.521966,89.1268,,52.1966,0.0891268,,,,7.85398e-5
Test1,2-Recover,94.303,2.968,3.155,0.020,,0.51527,254.648,,51.527,0.254648,,,,7.85398e-5
Test1,2-Recover,94.637,3.01,3.113,0.013,,0.508411,165.521,,50.8411,0.165521,,,,7.85398e-5
Test1,2-Recover,94.970,3.05,3.073,0.020,,0.501878,254.648,,50.1878,0.254648,,,,7.85398e-5
Test1,2-Recover,95.303,3.09,3.033,0.013,,0.495345,165.521,,49.5345,0.165521,,,,7.85398e-5
Test1,2-Recover,95.637,3.132,2.991,0.013,,0.488486,165.521,,48.8486,0.165521,,,,7.85398e-5
Test1,2-Recover,95.970,3.173,2.95,0.013,,0.48179,165.521,,48.179,0.165521,,,,7.85398e-5
Test1,2-Recover,96.303,3.213,2.91,0.013,,0.475257,165.521,,47.5257,0.165521,,,,7.85398e-5
Test1,2-Recover,96.637,3.255,2.868,-0.000,,0.468398,0,,46.8398,0,,,,7.85398e-5
Test1,2-Recover,96.970,3.295,2.828,0.013,,0.461865,165.521,,46.1865,0.165521,,,,7.85398e-5
Test1,2-Recover,97.303,3.336,2.787,0.007,,0.455169,89.1268,,45.5169,0.0891268,,,,7.85398e-5
Test1,2-Recover,97.637,3.378,2.745,-0.007,,0.44831,-89.1268,,44.831,-0.0891268,,,,7.85398e-5
Test1,2-Recover,97.970,3.418,2.705,-0.000,,0.441777,0,,44.1777,0,,,,7.85398e-5
Test1,2-Recover,98.303,3.458,2.665,-0.007,,0.435244,-89.1268,,43.5244,-0.0891268,,,,7.85398e-5
Test1,2-Recover,98.637,3.5,2.623,-0.007,,0.428385,-89.1268,,42.8385,-0.0891268,,,,7.85398e-5
Test1,2-Recover,98.970,3.541,2.582,0.007,,0.421689,89.1268,,42.1689,0.0891268,,,,7.85398e-5
Test1,2-Recover,99.303,3.581,2.542,0.007,,0.415156,89.1268,,41.5156,0.0891268,,,,7.85398e-5
Test1,2-Recover,99.637,3.623,2.5,-0.014,,0.408297,-178.254,,40.8297,-0.178254,,,,7.85398e-5
Test1,2-Recover,99.970,3.663,2.46,-0.007,,0.401764,-89.1268,,40.1764,-0.0891268,,,,7.85398e-5
Test1,2-Recover,100.303,3.704,2.419,-0.014,,0.395068,-178.254,,39.5068,-0.178254,,,,7.85398e-5
Test1,2-Recover,100.637,3.746,2.377,-0.007,,0.388208,-89.1268,,38.8208,-0.0891268,,,,7.85398e-5
Test1,2-Recover,100.970,3.786,2.337,-0.000,,0.381676,0,,38.1676,0,,,,7.85398e-5
Test1,2-Recover,101.303,3.827,2.296,0.007,,0.37498,89.1268,,37.498,0.0891268,,,,7.85398e-5
Test1,2-Recover,101.637,3.868,2.255,0.007,,0.368284,89.1268,,36.8284,0.0891268,,,,7.85398e-5
Test1,2-Recover,101.970,3.909,2.214,-0.007,,0.361587,-89.1268,,36.1587,-0.0891268,,,,7.85398e-5
Test1,2-Recover,102.303,3.949,2.174,0.013,,0.355055,165.521,,35.5055,0.165521,,,,7.85398e-5
Test1,2-Recover,102.637,3.991,2.132,0.020,,0.348195,254.648,,34.8195,0.254648,,,,7.85398e-5
Test1,2-Recover,102.970,4.031,2.092,0.007,,0.341663,89.1268,,34.1663,0.0891268,,,,7.85398e-5
Test1,2-Recover,103.303,4.072,2.051,0.020,,0.334967,254.648,,33.4967,0.254648,,,,7.85398e-5
Test1,2-Recover,103.637,4.113,2.01,-0.000,,0.32827,0,,32.827,0,,,,7.85398e-5
Test1,2-Recover,103.970,4.154,1.969,0.020,,0.321574,254.648,,32.1574,0.254648,,,,7.85398e-5
Test1,2-Recover,104.303,4.194,1.929,-0.007,,0.315042,-89.1268,,31.5042,-0.0891268,,,,7.85398e-5
Test1,2-Recover,104.637,4.236,1.887,-0.000,,0.308182,0,,30.8182,0,,,,7.85398e-5
Test1,2-Recover,104.970,4.277,1.846,-0.000,,0.301486,0,,30.1486,0,,,,7.85398e-5
Test1,2-Recover,105.303,4.317,1.806,-0.000,,0.294953,0,,29.4953,0,,,,7.85398e-5
Test1,2-Recover,105.637,4.359,1.764,-0.014,,0.288094,-178.254,,28.8094,-0.178254,,,,7.85398e-5
Test1,2-Recover,105.970,4.399,1.724,0.013,,0.281561,165.521,,28.1561,0.165521,,,,7.85398e-5
Test1,2-Recover,106.303,4.44,1.683,0.007,,0.274865,89.1268,,27.4865,0.0891268,,,,7.85398e-5
Test1,2-Recover,106.637,4.481,1.642,0.013,,0.268169,165.521,,26.8169,0.165521,,,,7.85398e-5
Test1,2-Recover,106.970,4.522,1.601,-0.000,,0.261473,0,,26.1473,0,,,,7.85398e-5
Test1,2-Recover,107.303,4.563,1.56,0.007,,0.254777,89.1268,,25.4777,0.0891268,,,,7.85398e-5
Test1,2-Recover,107.637,4.604,1.519,0.007,,0.248081,89.1268,,24.8081,0.0891268,,,,7.85398e-5
Test1,2-Recover,107.970,4.645,1.478,0.007,,0.241385,89.1268,,24.1385,0.0891268,,,,7.85398e-5
Test1,2-Recover,108.303,4.685,1.438,0.020,,0.234852,254.648,,23.4852,0.254648,,,,7.85398e-5
Test1,2-Recover,108.637,4.727,1.396,0.020,,0.227993,254.648,,22.7993,0.254648,,,,7.85398e-5
Test1,2-Recover,108.970,4.767,1.356,0.020,,0.22146,254.648,,22.146,0.254648,,,,7.85398e-5
Test1,2-Recover,109.303,4.808,1.315,0.020,,0.214764,254.648,,21.4764,0.254648,,,,7.85398e-5
Test1,2-Recover,109.637,4.849,1.274,0.007,,0.208068,89.1268,,20.8068,0.0891268,,,,7.85398e-5
Test1,2-Recover,109.970,4.89,1.233,0.013,,0.201372,165.521,,20.1372,0.165521,,,,7.85398e-5
Test1,2-Recover,110.303,4.931,1.192,0.020,,0.194676,254.648,,19.4676,0.254648,,,,7.85398e-5
Test1,2-Recover,110.637,4.972,1.151,0.007,,0.18798,89.1268,,18.798,0.0891268,,,,7.85398e-5
Test1,2-Recover,110.970,5.013,1.11,0.020,,0.181284,254.648,,18.1284,0.254648,,,,7.85398e-5
Test1,2-Recover,111.303,5.053,1.07,0.020,,0.174751,254.648,,17.4751,0.254648,,,,7.85398e-5
Test1,2-Recover,111.637,5.095,1.028,0.007,,0.167892,89.1268,,16.7892,0.0891268,,,,7.85398e-5
Test1,2-Recover,111.970,5.135,0.988,0.007,,0.161359,89.1268,,16.1359,0.0891268,,,,7.85398e-5
Test1,2-Recover,112.303,5.176,0.947,-0.000,,0.154663,0,,15.4663,0,,,,7.85398e-5
Test1,2-Recover,112.637,5.217,0.906,0.007,,0.147967,89.1268,,14.7967,0.0891268,,,,7.85398e-5
Test1,2-Recover,112.970,5.258,0.865,0.007,,0.141271,89.1268,,14.1271,0.0891268,,,,7.85398e-5
Test1,2-Recover,113.303,5.298,0.825,-0.000,,0.134738,0,,13.4738,0,,,,7.85398e-5
Test1,2-Recover,113.637,5.34,0.783,-0.000,,0.127878,0,,12.7878,0,,,,7.85398e-5
Test1,2-Recover,113.970,5.381,0.742,0.007,,0.121182,89.1268,,12.1182,0.0891268,,,,7.85398e-5
Test1,2-Recover,114.303,5.421,0.702,0.007,,0.11465,89.1268,,11.465,0.0891268,,,,7.85398e-5
Test1,2-Recover,114.637,5.463,0.66,0.013,,0.10779,165.521,,10.779,0.165521,,,,7.85398e-5
Test1,2-Recover,114.970,5.503,0.62,0.013,,0.101258,165.521,,10.1258,0.165521,,,,7.85398e-5
Test1,2-Recover,115.303,5.544,0.579,0.013,,0.0945615,165.521,,9.45615,0.165521,,,,7.85398e-5
Test1,2-Recover,115.637,5.586,0.537,0.007,,0.0877021,89.1268,,8.77021,0.0891268,,,,7.85398e-5
Test1,2-Recover,115.970,5.626,0.497,0.007,,0.0811694,89.1268,,8.11694,0.0891268,,,,7.85398e-5
Test1,2-Recover,116.303,5.666,0.457,0.007,,0.0746366,89.1268,,7.46366,0.0891268,,,,7.85398e-5
Test1,2-Recover,116.637,5.708,0.415,0.013,,0.0677772,165.521,,6.77772,0.165521,,,,7.85398e-5
Test1,2-Recover,116.970,5.749,0.374,0.013,,0.0610812,165.521,,6.10812,0.165521,,,,7.85398e-5
Test1,2-Recover,117.303,5.789,0.334,0.020,,0.0545484,254.648,,5.45484,0.254648,,,,7.85398e-5
Test1,2-Recover,117.637,5.831,0.292,0.013,,0.047689,165.521,,4.7689,0.165521,,,,7.85398e-5
Test1,2-Recover,117.970,5.871,0.252,0.020,,0.0411563,254.648,,4.11563,0.254648,,,,7.85398e-5
Test1,2-Recover,118.303,5.912,0.211,0.020,,0.0344602,254.648,,3.44602,0.254648,,,,7.85398e-5
Test1,2-Recover,118.637,5.954,0.169,0.020,,0.0276008,254.648,,2.76008,0.254648,,,,7.85398e-5
Test1,2-Recover,118.970,5.994,0.129,0.013,,0.0210681,165.521,,2.10681,0.165521,,,,7.85398e-5
Test1,2-Recover,119.303,6.034,0.089,0.020,,0.0145354,254.648,,1.45354,0.254648,,,,7.85398e-5
Test1,2-Recover,119.637,6.076,0.047,0.013,,0.00767598,165.521,,0.767598,0.165521,,,,7.85398e-5
Test1,2-Recover,119.970,6.117,0.006,0.013,,0.000979912,165.521,,0.0979912,0.165521,,,,7.85398e-5
Test1,3-Compress,120.280,6.1,0.023,0.013,,0.00375633,165.521,,0.375633,0.165521,,,,7.85398e-5
Test1,3-Compress,120.613,6.059,0.064,0.007,,0.0104524,89.1268,,1.04524,0.0891268,,,,7.85398e-5
Test1,3-Compress,120.947,6.018,0.105,-0.000,,0.0171485,0,,1.71485,0,,,,7.85398e-5
Test1,3-Compress,121.280,5.977,0.146,-0.000,,0.0238445,0,,2.38445,0,,,,7.85398e-5
Test1,3-Compress,121.613,5.937,0.186,-0.000,,0.0303773,0,,3.03773,0,,,,7.85398e-5
Test1,3-Compress,121.947,5.895,0.228,0.007,,0.0372366,89.1268,,3.72366,0.0891268,,,,7.85398e-5
Test1,3-Compress,122.280,5.855,0.268,0.007,,0.0437694,89.1268,,4.37694,0.0891268,,,,7.85398e-5
Test1,3-Compress,122.613,5.814,0.309,-0.000,,0.0504655,0,,5.04655,0,,,,7.85398e-5
Test1,3-Compress,122.947,5.772,0.351,0.013,,0.0573248,165.521,,5.73248,0.165521,,,,7.85398e-5
Test1,3-Compress,123.280,5.732,0.391,0.007,,0.0638576,89.1268,,6.38576,0.0891268,,,,7.85398e-5
Test1,3-Compress,123.613,5.691,0.432,-0.000,,0.0705537,0,,7.05537,0,,,,7.85398e-5
Test1,3-Compress,123.947,5.65,0.473,0.013,,0.0772497,165.521,,7.72497,0.165521,,,,7.85398e-5
Test1,3-Compress,124.280,5.609,0.514,0.007,,0.0839458,89.1268,,8.39458,0.0891268,,,,7.85398e-5
Test1,3-Compress,124.613,5.568,0.555,0.007,,0.0906418,89.1268,,9.06418,0.0891268,,,,7.85398e-5
Test1,3-Compress,124.947,5.527,0.596,0.013,,0.0973379,165.521,,9.73379,0.165521,,,,7.85398e-5
Test1,3-Compress,125.280,5.487,0.636,0.013,,0.103871,165.521,,10.3871,0.165521,,,,7.85398e-5
Test1,3-Compress,125.613,5.446,0.677,0.013,,0.110567,165.521,,11.0567,0.165521,,,,7.85398e-5
Test1,3-Compress,125.947,5.404,0.719,0.007,,0.117426,89.1268,,11.7426,0.0891268,,,,7.85398e-5
Test1,3-Compress,126.280,5.364,0.759,0.020,,0.123959,254.648,,12.3959,0.254648,,,,7.85398e-5
Test1,3-Compress,126.613,5.323,0.8,0.020,,0.130655,254.648,,13.0655,0.254648,,,,7.85398e-5
Test1,3-Compress,126.947,5.282,0.841,0.034,,0.137351,432.902,,13.7351,0.432902,,,,7.85398e-5
Test1,3-Compress,127.280,5.241,0.882,-0.000,,0.144047,0,,14.4047,0,,,,7.85398e-5
Test1,3-Compress,127.613,5.201,0.922,0.027,,0.15058,343.775,,15.058,0.343775,,,,7.85398e-5
Test1,3-Compress,127.947,5.159,0.964,0.013,,0.157439,165.521,,15.7439,0.165521,,,,7.85398e-5
Test1,3-Compress,128.280,5.118,1.005,-0.000,,0.164135,0,,16.4135,0,,,,7.85398e-5
Test1,3-Compress,128.613,5.078,1.045,-0.000,,0.170668,0,,17.0668,0,,,,7.85398e-5
Test1,3-Compress,128.947,5.036,1.087,-0.000,,0.177527,0,,17.7527,0,,,,7.85398e-5
Test1,3-Compress,129.280,4.996,1.127,-0.000,,0.18406,0,,18.406,0,,,,7.85398e-5
Test1,3-Compress,129.613,4.955,1.168,-0.007,,0.190756,-89.1268,,19.0756,-0.0891268,,,,7.85398e-5
Test1,3-Compress,129.947,4.914,1.209,-0.000,,0.197452,0,,19.7452,0,,,,7.85398e-5
Test1,3-Compress,130.280,4.873,1.25,-0.007,,0.204148,-89.1268,,20.4148,-0.0891268,,,,7.85398e-5
Test1,3-Compress,130.613,4.833,1.29,-0.000,,0.210681,0,,21.0681,0,,,,7.85398e-5
Test1,3-Compress,130.947,4.791,1.332,-0.000,,0.21754,0,,21.754,0,,,,7.85398e-5
Test1,3-Compress,131.280,4.75,1.373,0.013,,0.224236,165.521,,22.4236,0.165521,,,,7.85398e-5
Test1,3-Compress,131.613,4.71,1.413,-0.000,,0.230769,0,,23.0769,0,,,,7.85398e-5
Test1,3-Compress,131.947,4.668,1.455,-0.000,,0.237629,0,,23.7629,0,,,,7.85398e-5
Test1,3-Compress,132.280,4.628,1.495,-0.000,,0.244161,0,,24.4161,0,,,,7.85398e-5
Test1,3-Compress,132.613,4.587,1.536,0.007,,0.250857,89.1268,,25.0857,0.0891268,,,,7.85398e-5
Test1,3-Compress,132.947,4.546,1.577,-0.000,,0.257553,0,,25.7553,0,,,,7.85398e-5
Test1,3-Compress,133.280,4.505,1.618,0.013,,0.26425,165.521,,26.425,0.165521,,,,7.85398e-5
Test1,3-Compress,133.613,4.465,1.658,0.007,,0.270782,89.1268,,27.0782,0.0891268,,,,7.85398e-5
Test1,3-Compress,133.947,4.423,1.7,0.020,,0.277642,254.648,,27.7642,0.254648,,,,7.85398e-5
Test1,3-Compress,134.280,4.382,1.741,0.013,,0.284338,165.521,,28.4338,0.165521,,,,7.85398e-5
Test1,3-Compress,134.613,4.342,1.781,-0.000,,0.29087,0,,29.087,0,,,,7.85398e-5
Test1,3-Compress,134.947,4.3,1.823,-0.000,,0.29773,0,,29.773,0,,,,7.85398e-5
Test1,3-Compress,135.280,4.26,1.863,0.013,,0.304263,165.521,,30.4263,0.165521,,,,7.85398e-5
Test1,3-Compress,135.613,4.219,1.904,0.007,,0.310959,89.1268,,31.0959,0.0891268,,,,7.85398e-5
Test1,3-Compress,135.947,4.178,1.945,-0.007,,0.317655,-89.1268,,31.7655,-0.0891268,,,,7.85398e-5
Test1,3-Compress,136.280,4.137,1.986,-0.000,,0.324351,0,,32.4351,0,,,,7.85398e-5
Test1,3-Compress,136.613,4.097,2.026,-0.000,,0.330884,0,,33.0884,0,,,,7.85398e-5
Test1,3-Compress,136.947,4.055,2.068,-0.000,,0.337743,0,,33.7743,0,,,,7.85398e-5
Test1,3-Compress,137.280,4.014,2.109,-0.000,,0.344439,0,,34.4439,0,,,,7.85398e-5
Test1,3-Compress,137.613,3.974,2.149,-0.000,,0.350972,0,,35.0972,0,,,,7.85398e-5
Test1,3-Compress,137.947,3.932,2.191,0.007,,0.357831,89.1268,,35.7831,0.0891268,,,,7.85398e-5
Test1,3-Compress,138.280,3.892,2.231,0.007,,0.364364,89.1268,,36.4364,0.0891268,,,,7.85398e-5
Test1,3-Compress,138.613,3.851,2.272,0.013,,0.37106,165.521,,37.106,0.165521,,,,7.85398e-5
Test1,3-Compress,138.947,3.81,2.313,-0.000,,0.377756,0,,37.7756,0,,,,7.85398e-5
Test1,3-Compress,139.280,3.769,2.354,-0.000,,0.384452,0,,38.4452,0,,,,7.85398e-5
Test1,3-Compress,139.613,3.729,2.394,0.007,,0.390985,89.1268,,39.0985,0.0891268,,,,7.85398e-5
Test1,3-Compress,139.947,3.687,2.436,0.007,,0.397844,89.1268,,39.7844,0.0891268,,,,7.85398e-5
Test1,3-Compress,140.280,3.647,2.476,-0.000,,0.404377,0,,40.4377,0,,,,7.85398e-5
Test1,3-Compress,140.613,3.606,2.517,-0.007,,0.411073,-89.1268,,41.1073,-0.0891268,,,,7.85398e-5
Test1,3-Compress,140.947,3.564,2.559,-0.007,,0.417932,-89.1268,,41.7932,-0.0891268,,,,7.85398e-5
Test1,3-Compress,141.280,3.524,2.599,-0.007,,0.424465,-89.1268,,42.4465,-0.0891268,,,,7.85398e-5
Test1,3-Compress,141.613,3.483,2.64,-0.000,,0.431161,0,,43.1161,0,,,,7.85398e-5
Test1,3-Compress,141.947,3.442,2.681,-0.014,,0.437857,-178.254,,43.7857,-0.178254,,,,7.85398e-5
Test1,3-Compress,142.280,3.401,2.722,0.027,,0.444553,343.775,,44.4553,0.343775,,,,7.85398e-5
Test1,3-Compress,142.613,3.361,2.762,0.034,,0.451086,432.902,,45.1086,0.432902,,,,7.85398e-5
Test1,3-Compress,142.947,3.319,2.804,0.034,,0.457945,432.902,,45.7945,0.432902,,,,7.85398e-5
Test1,3-Compress,143.280,3.279,2.844,0.027,,0.464478,343.775,,46.4478,0.343775,,,,7.85398e-5
Test1,3-Compress,143.613,3.238,2.885,0.013,,0.471174,165.521,,47.1174,0.165521,,,,7.85398e-5
Test1,3-Compress,143.947,3.196,2.927,0.034,,0.478034,432.902,,47.8034,0.432902,,,,7.85398e-5
Test1,3-Compress,144.280,3.156,2.967,0.034,,0.484566,432.902,,48.4566,0.432902,,,,7.85398e-5
Test1,3-Compress,144.613,3.116,3.007,0.027,,0.491099,343.775,,49.1099,0.343775,,,,7.85398e-5
Test1,3-Compress,144.947,3.074,3.049,0.034,,0.497959,432.902,,49.7959,0.432902,,,,7.85398e-5
Test1,3-Compress,145.280,3.033,3.09,0.034,,0.504655,432.902,,50.4655,0.432902,,,,7.85398e-5
Test1,3-Compress,145.613,2.993,3.13,0.034,,0.511187,432.902,,51.1187,0.432902,,,,7.85398e-5
Test1,3-Compress,145.947,2.951,3.172,0.027,,0.518047,343.775,,51.8047,0.343775,,,,7.85398e-5
Test1,3-Compress,146.280,2.911,3.212,0.034,,0.524579,432.902,,52.4579,0.432902,,,,7.85398e-5
Test1,3-Compress,146.613,2.87,3.253,0.034,,0.531276,432.902,,53.1276,0.432902,,,,7.85398e-5
Test1,3-Compress,146.947,2.828,3.295,0.034,,0.538135,432.902,,53.8135,0.432902,,,,7.85398e-5
Test1,3-Compress,147.280,2.788,3.335,0.034,,0.544668,432.902,,54.4668,0.432902,,,,7.85398e-5
Test1,3-Compress,147.613,2.748,3.375,0.034,,0.5512,432.902,,55.12,0.432902,,,,7.85398e-5
Test1,3-Compress,147.947,2.706,3.417,0.034,,0.55806,432.902,,55.806,0.432902,,,,7.85398e-5
Test1,3-Compress,148.280,2.665,3.458,0.034,,0.564756,432.902,,56.4756,0.432902,,,,7.85398e-5
Test1,3-Compress,148.613,2.625,3.498,0.034,,0.571289,432.902,,57.1289,0.432902,,,,7.85398e-5
Test1,3-Compress,148.947,2.583,3.54,0.034,,0.578148,432.902,,57.8148,0.432902,,,,7.85398e-5
Test1,3-Compress,149.280,2.543,3.58,0.034,,0.584681,432.902,,58.4681,0.432902,,,,7.85398e-5
Test1,3-Compress,149.613,2.502,3.621,0.041,,0.591377,522.028,,59.1377,0.522028,,,,7.85398e-5
Test1,3-Compress,149.947,2.46,3.663,0.041,,0.598236,522.028,,59.8236,0.522028,,,,7.85398e-5
Test1,3-Recover,150.267,2.469,3.654,0.041,,0.596766,522.028,,59.6766,0.522028,,,,7.85398e-5
Test1,3-Recover,150.600,2.509,3.614,0.041,,0.590234,522.028,,59.0234,0.522028,,,,7.85398e-5
Test1,3-Recover,150.933,2.55,3.573,0.041,,0.583537,522.028,,58.3537,0.522028,,,,7.85398e-5
Test1,3-Recover,151.267,2.591,3.532,0.041,,0.576841,522.028,,57.6841,0.522028,,,,7.85398e-5
Test1,3-Recover,151.600,2.632,3.491,0.027,,0.570145,343.775,,57.0145,0.343775,,,,7.85398e-5
Test1,3-Recover,151.933,2.672,3.451,0.020,,0.563613,254.648,,56.3613,0.254648,,,,7.85398e-5
Test1,3-Recover,152.267,2.714,3.409,0.020,,0.556753,254.648,,55.6753,0.254648,,,,7.85398e-5
Test1,3-Recover,152.600,2.755,3.368,0.020,,0.550057,254.648,,55.0057,0.254648,,,,7.85398e-5
Test1,3-Recover,152.933,2.795,3.328,0.027,,0.543524,343.775,,54.3524,0.343775,,,,7.85398e-5
Test1,3-Recover,153.267,2.837,3.286,0.013,,0.536665,165.521,,53.6665,0.165521,,,,7.85398e-5
Test1,3-Recover,153.600,2.877,3.246,0.020,,0.530132,254.648,,53.0132,0.254648,,,,7.85398e-5
Test1,3-Recover,153.933,2.918,3.205,0.020,,0.523436,254.648,,52.3436,0.254648,,,,7.85398e-5
Test1,3-Recover,154.267,2.959,3.164,0.020,,0.51674,254.648,,51.674,0.254648,,,,7.85398e-5
Test1,3-Recover,154.600,3,3.123,0.020,,0.510044,254.648,,51.0044,0.254648,,,,7.85398e-5
Test1,3-Recover,154.933,3.04,3.083,0.013,,0.503511,165.521,,50.3511,0.165521,,,,7.85398e-5
Test1,3-Recover,155.267,3.082,3.041,-0.000,,0.496652,0,,49.6652,0,,,,7.85398e-5
Test1,3-Recover,155.600,3.122,3.001,0.007,,0.490119,89.1268,,49.0119,0.0891268,,,,7.85398e-5
Test1,3-Recover,155.933,3.163,2.96,-0.007,,0.483423,-89.1268,,48.3423,-0.0891268,,,,7.85398e-5
Test1,3-Recover,156.267,3.205,2.918,-0.007,,0.476564,-89.1268,,47.6564,-0.0891268,,,,7.85398e-5
Test1,3-Recover,156.600,3.245,2.878,-0.007,,0.470031,-89.1268,,47.0031,-0.0891268,,,,7.85398e-5
Test1,3-Recover,156.933,3.286,2.837,-0.014,,0.463335,-178.254,,46.3335,-0.178254,,,,7.85398e-5
Test1,3-Recover,157.267,3.327,2.796,-0.007,,0.456639,-89.1268,,45.6639,-0.0891268,,,,7.85398e-5
Test1,3-Recover,157.600,3.368,2.755,-0.000,,0.449943,0,,44.9943,0,,,,7.85398e-5
Test1,3-Recover,157.933,3.408,2.715,-0.007,,0.44341,-89.1268,,44.341,-0.0891268,,,,7.85398e-5
Test1,3-Recover,158.267,3.45,2.673,0.007,,0.436551,89.1268,,43.6551,0.0891268,,,,7.85398e-5
Test1,3-Recover,158.600,3.49,2.633,-0.007,,0.430018,-89.1268,,43.0018,-0.0891268,,,,7.85398e-5
Test1,3-Recover,158.933,3.531,2.592,-0.000,,0.423322,0,,42.3322,0,,,,7.85398e-5
Test1,3-Recover,159.267,3.573,2.55,-0.007,,0.416463,-89.1268,,41.6463,-0.0891268,,,,7.85398e-5
Test1,3-Recover,159.600,3.613,2.51,0.007,,0.40993,89.1268,,40.993,0.0891268,,,,7.85398e-5
Test1,3-Recover,159.933,3.654,2.469,0.020,,0.403234,254.648,,40.3234,0.254648,,,,7.85398e-5
Test1,3-Recover,160.267,3.695,2.428,-0.000,,0.396538,0,,39.6538,0,,,,7.85398e-5
Test1,3-Recover,160.600,3.736,2.387,0.007,,0.389842,89.1268,,38.9842,0.0891268,,,,7.85398e-5
Test1,3-Recover,160.933,3.776,2.347,0.013,,0.383309,165.521,,38.3309,0.165521,,,,7.85398e-5
Test1,3-Recover,161.267,3.818,2.305,-0.007,,0.376449,-89.1268,,37.6449,-0.0891268,,,,7.85398e-5
Test1,3-Recover,161.600,3.858,2.265,0.007,,0.369917,89.1268,,36.9917,0.0891268,,,,7.85398e-5
Test1,3-Recover,161.933,3.899,2.224,-0.007,,0.363221,-89.1268,,36.3221,-0.0891268,,,,7.85398e-5
Test1,3-Recover,162.267,3.941,2.182,-0.007,,0.356361,-89.1268,,35.6361,-0.0891268,,,,7.85398e-5
Test1,3-Recover,162.600,3.981,2.142,-0.000,,0.349829,0,,34.9829,0,,,,7.85398e-5
Test1,3-Recover,162.933,4.022,2.101,-0.007,,0.343132,-89.1268,,34.3132,-0.0891268,,,,7.85398e-5
Test1,3-Recover,163.267,4.063,2.06,0.007,,0.336436,89.1268,,33.6436,0.0891268,,,,7.85398e-5
Test1,3-Recover,163.600,4.104,2.019,-0.000,,0.32974,0,,32.974,0,,,,7.85398e-5
Test1,3-Recover,163.933,4.144,1.979,0.007,,0.323208,89.1268,,32.3208,0.0891268,,,,7.85398e-5
Test1,3-Recover,164.267,4.186,1.937,-0.000,,0.316348,0,,31.6348,0,,,,7.85398e-5
Test1,3-Recover,164.600,4.227,1.896,0.007,,0.309652,89.1268,,30.9652,0.0891268,,,,7.85398e-5
Test1,3-Recover,164.933,4.267,1.856,0.013,,0.303119,165.521,,30.3119,0.165521,,,,7.85398e-5
Test1,3-Recover,165.267,4.308,1.815,0.020,,0.296423,254.648,,29.6423,0.254648,,,,7.85398e-5
Test1,3-Recover,165.600,4.349,1.774,0.020,,0.289727,254.648,,28.9727,0.254648,,,,7.85398e-5
Test1,3-Recover,165.933,4.39,1.733,0.013,,0.283031,165.521,,28.3031,0.165521,,,,7.85398e-5
Test1,3-Recover,166.267,4.431,1.692,0.020,,0.276335,254.648,,27.6335,0.254648,,,,7.85398e-5
Test1,3-Recover,166.600,4.472,1.651,0.013,,0.269639,165.521,,26.9639,0.165521,,,,7.85398e-5
Test1,3-Recover,166.933,4.512,1.611,-0.000,,0.263106,0,,26.3106,0,,,,7.85398e-5
Test1,3-Recover,167.267,4.554,1.569,0.013,,0.256247,165.521,,25.6247,0.165521,,,,7.85398e-5
Test1,3-Recover,167.600,4.595,1.528,0.020,,0.249551,254.648,,24.9551,0.254648,,,,7.85398e-5
Test1,3-Recover,167.933,4.635,1.488,0.013,,0.243018,165.521,,24.3018,0.165521,,,,7.85398e-5
Test1,3-Recover,168.267,4.677,1.446,0.020,,0.236159,254.648,,23.6159,0.254648,,,,7.85398e-5
Test1,3-Recover,168.600,4.717,1.406,0.007,,0.229626,89.1268,,22.9626,0.0891268,,,,7.85398e-5
Test1,3-Recover,168.933,4.758,1.365,-0.000,,0.22293,0,,22.293,0,,,,7.85398e-5
Test1,3-Recover,169.267,4.799,1.324,0.013,,0.216234,165.521,,21.6234,0.165521,,,,7.85398e-5
Test1,3-Recover,169.600,4.84,1.283,0.007,,0.209538,89.1268,,20.9538,0.0891268,,,,7.85398e-5
Test1,3-Recover,169.933,4.88,1.243,0.007,,0.203005,89.1268,,20.3005,0.0891268,,,,7.85398e-5
Test1,3-Recover,170.267,4.922,1.201,-0.000,,0.196146,0,,19.6146,0,,,,7.85398e-5
Test1,3-Recover,170.600,4.963,1.16,0.007,,0.18945,89.1268,,18.945,0.0891268,,,,7.85398e-5
Test1,3-Recover,170.933,5.003,1.12,0.007,,0.182917,89.1268,,18.2917,0.0891268,,,,7.85398e-5
Test1,3-Recover,171.267,5.045,1.078,0.007,,0.176057,89.1268,,17.6057,0.0891268,,,,7.85398e-5
Test1,3-Recover,171.600,5.085,1.038,0.013,,0.169525,165.521,,16.9525,0.165521,,,,7.85398e-5
Test1,3-Recover,171.933,5.126,0.997,0.013,,0.162829,165.521,,16.2829,0.165521,,,,7.85398e-5
Test1,3-Recover,172.267,5.167,0.956,0.013,,0.156133,165.521,,15.6133,0.165521,,,,7.85398e-5
Test1,3-Recover,172.600,5.208,0.915,0.013,,0.149437,165.521,,14.9437,0.165521,,,,7.85398e-5
Test1,3-Recover,172.933,5.248,0.875,0.007,,0.142904,89.1268,,14.2904,0.0891268,,,,7.85398e-5
Test1,3-Recover,173.267,5.29,0.833,0.013,,0.136044,165.521,,13.6044,0.165521,,,,7.85398e-5
Test1,3-Recover,173.600,5.33,0.793,0.020,,0.129512,254.648,,12.9512,0.254648,,,,7.85398e-5
Test1,3-Recover,173.933,5.371,0.752,0.020,,0.122816,254.648,,12.2816,0.254648,,,,7.85398e-5
Test1,3-Recover,174.267,5.413,0.71,0.007,,0.115956,89.1268,,11.5956,0.0891268,,,,7.85398e-5
Test1,3-Recover,174.600,5.453,0.67,0.013,,0.109423,165.521,,10.9423,0.165521,,,,7.85398e-5
Test1,3-Recover,174.933,5.494,0.629,0.020,,0.102727,254.648,,10.2727,0.254648,,,,7.85398e-5
Test1,3-Recover,175.267,5.535,0.588,0.020,,0.0960314,254.648,,9.60314,0.254648,,,,7.85398e-5
Test1,3-Recover,175.600,5.576,0.547,0.020,,0.0893353,254.648,,8.93353,0.254648,,,,7.85398e-5
Test1,3-Recover,175.933,5.616,0.507,0.013,,0.0828025,165.521,,8.28025,0.165521,,,,7.85398e-5
Test1,3-Recover,176.267,5.658,0.465,0.020,,0.0759432,254.648,,7.59432,0.254648,,,,7.85398e-5
Test1,3-Recover,176.600,5.698,0.425,0.013,,0.0694104,165.521,,6.94104,0.165521,,,,7.85398e-5
Test1,3-Recover,176.933,5.739,0.384,0.013,,0.0627144,165.521,,6.27144,0.165521,,,,7.85398e-5
Test1,3-Recover,177.267,5.781,0.342,-0.000,,0.055855,0,,5.5855,0,,,,7.85398e-5
Test1,3-Recover,177.600,5.821,0.302,-0.000,,0.0493222,0,,4.93222,0,,,,7.85398e-5
Test1,3-Recover,177.933,5.861,0.262,0.007,,0.0427895,89.1268,,4.27895,0.0891268,,,,7.85398e-5
Test1,3-Recover,178.267,5.903,0.22,0.007,,0.0359301,89.1268,,3.59301,0.0891268,,,,7.85398e-5
Test1,3-Recover,178.600,5.944,0.179,0.007,,0.029234,89.1268,,2.9234,0.0891268,,,,7.85398e-5
Test1,3-Recover,178.933,5.984,0.139,0.013,,0.0227013,165.521,,2.27013,0.165521,,,,7.85398e-5
Test1,3-Recover,179.267,6.026,0.097,-0.000,,0.0158419,0,,1.58419,0,,,,7.85398e-5
Test1,3-Recover,179.600,6.066,0.057,0.013,,0.00930916,165.521,,0.930916,0.165521,,,,7.85398e-5
Test1,3-Recover,179.933,6.107,0.016,0.020,,0.0026131,254.648,,0.26131,0.254648,,,,7.85398e-5
Test1,3-Recover,180.100,6.123,-0,0.027,,0,343.775,,0,0.343775,,,,7.85398e-5