File: data/beta_1-1-1_1.csv
SetName,Cycle,Time_S,Size_mm,Displacement_mm,Force_N,,Strain,Stress(Pascal),,%Strain,Stress(kPa),,,,Area(m^2)
Test1,1-Compress,0.000,3.923,-0,-0.007,,0,-89.1268,,0,-0.0891268,,,,7.85398e-5
Test1,1-Compress,0.333,3.898,0.025,-0.007,,0.00637267,-89.1268,,0.637267,-0.0891268,,,,7.85398e-5
Test1,1-Compress,0.667,3.871,0.052,-0.000,,0.0132552,0,,1.32552,0,,,,7.85398e-5
Test1,1-Compress,1.000,3.845,0.078,-0.000,,0.0198827,0,,1.98827,0,,,,7.85398e-5
Test1,1-Compress,1.333,3.819,0.104,0.007,,0.0265103,89.1268,,2.65103,0.0891268,,,,7.85398e-5
Test1,1-Compress,1.667,3.793,0.13,0.007,,0.0331379,89.1268,,3.31379,0.0891268,,,,7.85398e-5
Test1,1-Compress,2.000,3.767,0.156,0.007,,0.0397655,89.1268,,3.97655,0.0891268,,,,7.85398e-5
Test1,1-Compress,2.333,3.741,0.182,0.013,,0.0463931,165.521,,4.63931,0.165521,,,,7.85398e-5
Test1,1-Compress,2.667,3.714,0.209,0.013,,0.0532756,165.521,,5.32756,0.165521,,,,7.85398e-5
Test1,1-Compress,3.000,3.688,0.235,0.013,,0.0599031,165.521,,5.99031,0.165521,,,,7.85398e-5
Test1,1-Compress,3.333,3.662,0.261,0.007,,0.0665307,89.1268,,6.65307,0.0891268,,,,7.85398e-5
Test1,1-Compress,3.667,3.636,0.287,0.007,,0.0731583,89.1268,,7.31583,0.0891268,,,,7.85398e-5
Test1,1-Compress,4.000,3.609,0.314,-0.000,,0.0800408,0,,8.00408,0,,,,7.85398e-5
Test1,1-Compress,4.333,3.583,0.34,-0.000,,0.0866684,0,,8.66684,0,,,,7.85398e-5
Test1,1-Compress,4.667,3.557,0.366,0.007,,0.0932959,89.1268,,9.32959,0.0891268,,,,7.85398e-5
Test1,1-Compress,5.000,3.531,0.392,-0.000,,0.0999235,0,,9.99235,0,,,,7.85398e-5
Test1,1-Compress,5.333,3.505,0.418,0.013,,0.106551,165.521,,10.6551,0.165521,,,,7.85398e-5
Test1,1-Compress,5.667,3.478,0.445,0.013,,0.113434,165.521,,11.3434,0.165521,,,,7.85398e-5
Test1,1-Compress,6.000,3.452,0.471,0.007,,0.120061,89.1268,,12.0061,0.0891268,,,,7.85398e-5
Test1,1-Compress,6.333,3.426,0.497,0.007,,0.126689,89.1268,,12.6689,0.0891268,,,,7.85398e-5
Test1,1-Compress,6.667,3.4,0.523,-0.000,,0.133316,0,,13.3316,0,,,,7.85398e-5
Test1,1-Compress,7.000,3.374,0.549,0.027,,0.139944,343.775,,13.9944,0.343775,,,,7.85398e-5
Test1,1-Compress,7.333,3.348,0.575,0.027,,0.146572,343.775,,14.6572,0.343775,,,,7.85398e-5
Test1,1-Compress,7.667,3.321,0.602,0.020,,0.153454,254.648,,15.3454,0.254648,,,,7.85398e-5
Test1,1-Compress,8.000,3.295,0.628,0.007,,0.160082,89.1268,,16.0082,0.0891268,,,,7.85398e-5
Test1,1-Compress,8.333,3.269,0.654,0.020,,0.166709,254.648,,16.6709,0.254648,,,,7.85398e-5
Test1,1-Compress,8.667,3.242,0.681,0.027,,0.173592,343.775,,17.3592,0.343775,,,,7.85398e-5
Test1,1-Compress,9.000,3.217,0.706,0.020,,0.179964,254.648,,17.9964,0.254648,,,,7.85398e-5
Test1,1-Compress,9.333,3.191,0.732,0.034,,0.186592,432.902,,18.6592,0.432902,,,,7.85398e-5
Test1,1-Compress,9.667,3.164,0.759,0.027,,0.193474,343.775,,19.3474,0.343775,,,,7.85398e-5
Test1,1-Compress,10.000,3.138,0.785,0.027,,0.200102,343.775,,20.0102,0.343775,,,,7.85398e-5
Test1,1-Compress,10.333,3.112,0.811,0.034,,0.20673,432.902,,20.673,0.432902,,,,7.85398e-5
Test1,1-Compress,10.667,3.085,0.838,0.034,,0.213612,432.902,,21.3612,0.432902,,,,7.85398e-5
Test1,1-Compress,11.000,3.059,0.864,0.027,,0.22024,343.775,,22.024,0.343775,,,,7.85398e-5
Test1,1-Compress,11.333,3.034,0.889,0.027,,0.226612,343.775,,22.6612,0.343775,,,,7.85398e-5
Test1,1-Compress,11.667,3.007,0.916,0.034,,0.233495,432.902,,23.3495,0.432902,,,,7.85398e-5
Test1,1-Compress,12.000,2.981,0.942,0.027,,0.240122,343.775,,24.0122,0.343775,,,,7.85398e-5
Test1,1-Compress,12.333,2.955,0.968,0.034,,0.24675,432.902,,24.675,0.432902,,,,7.85398e-5
Test1,1-Compress,12.667,2.928,0.995,0.034,,0.253632,432.902,,25.3632,0.432902,,,,7.85398e-5
Test1,1-Compress,13.000,2.902,1.021,0.034,,0.26026,432.902,,26.026,0.432902,,,,7.85398e-5
Test1,1-Compress,13.333,2.876,1.047,0.034,,0.266888,432.902,,26.6888,0.432902,,,,7.85398e-5
Test1,1-Compress,13.667,2.85,1.073,0.034,,0.273515,432.902,,27.3515,0.432902,,,,7.85398e-5
Test1,1-Compress,14.000,2.824,1.099,0.034,,0.280143,432.902,,28.0143,0.432902,,,,7.85398e-5
Test1,1-Compress,14.333,2.797,1.126,0.034,,0.287025,432.902,,28.7025,0.432902,,,,7.85398e-5
Test1,1-Compress,14.667,2.771,1.152,0.034,,0.293653,432.902,,29.3653,0.432902,,,,7.85398e-5
Test1,1-Compress,15.000,2.745,1.178,0.034,,0.30028,432.902,,30.028,0.432902,,,,7.85398e-5
Test1,1-Compress,15.333,2.719,1.204,0.041,,0.306908,522.028,,30.6908,0.522028,,,,7.85398e-5
Test1,1-Compress,15.667,2.692,1.231,0.041,,0.31379,522.028,,31.379,0.522028,,,,7.85398e-5
Test1,1-Compress,16.000,2.666,1.257,0.041,,0.320418,522.028,,32.0418,0.522028,,,,7.85398e-5
Test1,1-Compress,16.333,2.64,1.283,0.041,,0.327046,522.028,,32.7046,0.522028,,,,7.85398e-5
Test1,1-Compress,16.667,2.614,1.309,0.034,,0.333673,432.902,,33.3673,0.432902,,,,7.85398e-5
Test1,1-Compress,17.000,2.588,1.335,0.041,,0.340301,522.028,,34.0301,0.522028,,,,7.85398e-5
Test1,1-Compress,17.333,2.562,1.361,0.047,,0.346928,598.423,,34.6928,0.598423,,,,7.85398e-5
Test1,1-Compress,17.667,2.535,1.388,0.041,,0.353811,522.028,,35.3811,0.522028,,,,7.85398e-5
Test1,1-Compress,18.000,2.509,1.414,0.041,,0.360438,522.028,,36.0438,0.522028,,,,7.85398e-5
Test1,1-Compress,18.333,2.483,1.44,0.041,,0.367066,522.028,,36.7066,0.522028,,,,7.85398e-5
Test1,1-Compress,18.667,2.457,1.466,0.034,,0.373694,432.902,,37.3694,0.432902,,,,7.85398e-5
Test1,1-Compress,19.000,2.43,1.493,0.034,,0.380576,432.902,,38.0576,0.432902,,,,7.85398e-5
Test1,1-Compress,19.333,2.405,1.518,0.034,,0.386949,432.902,,38.6949,0.432902,,,,7.85398e-5
Test1,1-Compress,19.667,2.378,1.545,0.034,,0.393831,432.902,,39.3831,0.432902,,,,7.85398e-5
Test1,1-Compress,20.000,2.352,1.571,0.034,,0.400459,432.902,,40.0459,0.432902,,,,7.85398e-5
Test1,1-Compress,20.333,2.326,1.597,0.034,,0.407086,432.902,,40.7086,0.432902,,,,7.85398e-5
Test1,1-Compress,20.667,2.299,1.624,0.034,,0.413969,432.902,,41.3969,0.432902,,,,7.85398e-5
Test1,1-Compress,21.000,2.273,1.65,0.034,,0.420596,432.902,,42.0596,0.432902,,,,7.85398e-5
Test1,1-Compress,21.333,2.248,1.675,0.034,,0.426969,432.902,,42.6969,0.432902,,,,7.85398e-5
Test1,1-Compress,21.667,2.221,1.702,0.034,,0.433852,432.902,,43.3852,0.432902,,,,7.85398e-5
Test1,1-Compress,22.000,2.195,1.728,0.034,,0.440479,432.902,,44.0479,0.432902,,,,7.85398e-5
Test1,1-Compress,22.333,2.169,1.754,0.034,,0.447107,432.902,,44.7107,0.432902,,,,7.85398e-5
Test1,1-Compress,22.667,2.142,1.781,0.034,,0.453989,432.902,,45.3989,0.432902,,,,7.85398e-5
Test1,1-Compress,23.000,2.116,1.807,0.041,,0.460617,522.028,,46.0617,0.522028,,,,7.85398e-5
Test1,1-Compress,23.333,2.091,1.832,0.041,,0.46699,522.028,,46.699,0.522028,,,,7.85398e-5
Test1,1-Compress,23.667,2.063,1.86,0.041,,0.474127,522.028,,47.4127,0.522028,,,,7.85398e-5
Test1,1-Compress,24.000,2.038,1.885,0.041,,0.4805,522.028,,48.05,0.522028,,,,7.85398e-5
Test1,1-Compress,24.333,2.012,1.911,0.041,,0.487127,522.028,,48.7127,0.522028,,,,7.85398e-5
Test1,1-Compress,24.667,1.985,1.938,0.047,,0.49401,598.423,,49.401,0.598423,,,,7.85398e-5
Test1,1-Compress,25.000,1.959,1.964,0.047,,0.500637,598.423,,50.0637,0.598423,,,,7.85398e-5
Test1,1-Compress,25.333,1.933,1.99,0.047,,0.507265,598.423,,50.7265,0.598423,,,,7.85398e-5
Test1,1-Compress,25.667,1.906,2.017,0.047,,0.514147,598.423,,51.4147,0.598423,,,,7.85398e-5
Test1,1-Compress,26.000,1.881,2.042,0.041,,0.52052,522.028,,52.052,0.522028,,,,7.85398e-5
Test1,1-Compress,26.333,1.855,2.068,0.041,,0.527148,522.028,,52.7148,0.522028,,,,7.85398e-5
Test1,1-Compress,26.667,1.828,2.095,0.054,,0.53403,687.549,,53.403,0.687549,,,,7.85398e-5
Test1,1-Compress,27.000,1.802,2.121,0.034,,0.540658,432.902,,54.0658,0.432902,,,,7.85398e-5
Test1,1-Compress,27.333,1.776,2.147,0.041,,0.547285,522.028,,54.7285,0.522028,,,,7.85398e-5
Test1,1-Compress,27.667,1.749,2.174,0.054,,0.554168,687.549,,55.4168,0.687549,,,,7.85398e-5
Test1,1-Compress,28.000,1.724,2.199,0.041,,0.56054,522.028,,56.054,0.522028,,,,7.85398e-5
Test1,1-Compress,28.333,1.698,2.225,0.034,,0.567168,432.902,,56.7168,0.432902,,,,7.85398e-5
Test1,1-Compress,28.667,1.671,2.252,0.047,,0.57405,598.423,,57.405,0.598423,,,,7.85398e-5
Test1,1-Compress,29.000,1.645,2.278,0.047,,0.580678,598.423,,58.0678,0.598423,,,,7.85398e-5
Test1,1-Compress,29.333,1.619,2.304,0.041,,0.587306,522.028,,58.7306,0.522028,,,,7.85398e-5
Test1,1-Compress,29.667,1.592,2.331,0.047,,0.594188,598.423,,59.4188,0.598423,,,,7.85398e-5
Test1,1-Compress,30.000,1.569,2.354,0.041,,0.600051,522.028,,60.0051,0.522028,,,,7.85398e-5
Test1,1-Recover,30.333,1.593,2.33,0.041,,0.593933,522.028,,59.3933,0.522028,,,,7.85398e-5
Test1,1-Recover,30.667,1.62,2.303,0.041,,0.587051,522.028,,58.7051,0.522028,,,,7.85398e-5
Test1,1-Recover,31.000,1.645,2.278,0.041,,0.580678,522.028,,58.0678,0.522028,,,,7.85398e-5
Test1,1-Recover,31.333,1.671,2.252,0.041,,0.57405,522.028,,57.405,0.522028,,,,7.85398e-5
Test1,1-Recover,31.667,1.698,2.225,0.041,,0.567168,522.028,,56.7168,0.522028,,,,7.85398e-5
Test1,1-Recover,32.000,1.724,2.199,0.041,,0.56054,522.028,,56.054,0.522028,,,,7.85398e-5
Test1,1-Recover,32.333,1.75,2.173,0.041,,0.553913,522.028,,55.3913,0.522028,,,,7.85398e-5
Test1,1-Recover,32.667,1.777,2.146,0.047,,0.54703,598.423,,54.703,0.598423,,,,7.85398e-5
Test1,1-Recover,33.000,1.802,2.121,0.047,,0.540658,598.423,,54.0658,0.598423,,,,7.85398e-5
Test1,1-Recover,33.333,1.829,2.094,0.054,,0.533775,687.549,,53.3775,0.687549,,,,7.85398e-5
Test1,1-Recover,33.667,1.855,2.068,0.041,,0.527148,522.028,,52.7148,0.522028,,,,7.85398e-5
Test1,1-Recover,34.000,1.881,2.042,0.041,,0.52052,522.028,,52.052,0.522028,,,,7.85398e-5
Test1,1-Recover,34.333,1.907,2.016,0.041,,0.513892,522.028,,51.3892,0.522028,,,,7.85398e-5
Test1,1-Recover,34.667,1.934,1.989,0.041,,0.50701,522.028,,50.701,0.522028,,,,7.85398e-5
Test1,1-Recover,35.000,1.96,1.963,0.034,,0.500382,432.902,,50.0382,0.432902,,,,7.85398e-5
Test1,1-Recover,35.333,1.986,1.937,0.034,,0.493755,432.902,,49.3755,0.432902,,,,7.85398e-5
Test1,1-Recover,35.667,2.012,1.911,0.034,,0.487127,432.902,,48.7127,0.432902,,,,7.85398e-5
Test1,1-Recover,36.000,2.038,1.885,0.034,,0.4805,432.902,,48.05,0.432902,,,,7.85398e-5
Test1,1-Recover,36.333,2.064,1.859,0.034,,0.473872,432.902,,47.3872,0.432902,,,,7.85398e-5
Test1,1-Recover,36.667,2.091,1.832,0.034,,0.46699,432.902,,46.699,0.432902,,,,7.85398e-5
Test1,1-Recover,37.000,2.117,1.806,0.034,,0.460362,432.902,,46.0362,0.432902,,,,7.85398e-5
Test1,1-Recover,37.333,2.143,1.78,0.034,,0.453734,432.902,,45.3734,0.432902,,,,7.85398e-5
Test1,1-Recover,37.667,2.17,1.753,0.034,,0.446852,432.902,,44.6852,0.432902,,,,7.85398e-5
Test1,1-Recover,38.000,2.195,1.728,0.034,,0.440479,432.902,,44.0479,0.432902,,,,7.85398e-5
Test1,1-Recover,38.333,2.222,1.701,0.034,,0.433597,432.902,,43.3597,0.432902,,,,7.85398e-5
Test1,1-Recover,38.667,2.248,1.675,0.034,,0.426969,432.902,,42.6969,0.432902,,,,7.85398e-5
Test1,1-Recover,39.000,2.274,1.649,0.041,,0.420342,522.028,,42.0342,0.522028,,,,7.85398e-5
Test1,1-Recover,39.333,2.3,1.623,0.041,,0.413714,522.028,,41.3714,0.522028,,,,7.85398e-5
Test1,1-Recover,39.667,2.327,1.596,0.034,,0.406832,432.902,,40.6832,0.432902,,,,7.85398e-5
Test1,1-Recover,40.000,2.353,1.57,0.034,,0.400204,432.902,,40.0204,0.432902,,,,7.85398e-5
Test1,1-Recover,40.333,2.379,1.544,0.034,,0.393576,432.902,,39.3576,0.432902,,,,7.85398e-5
Test1,1-Recover,40.667,2.405,1.518,0.041,,0.386949,522.028,,38.6949,0.522028,,,,7.85398e-5
Test1,1-Recover,41.000,2.431,1.492,0.034,,0.380321,432.902,,38.0321,0.432902,,,,7.85398e-5
Test1,1-Recover,41.333,2.457,1.466,0.034,,0.373694,432.902,,37.3694,0.432902,,,,7.85398e-5
Test1,1-Recover,41.667,2.484,1.439,0.034,,0.366811,432.902,,36.6811,0.432902,,,,7.85398e-5
Test1,1-Recover,42.000,2.51,1.413,0.027,,0.360184,343.775,,36.0184,0.343775,,,,7.85398e-5
Test1,1-Recover,42.333,2.536,1.387,0.034,,0.353556,432.902,,35.3556,0.432902,,,,7.85398e-5
Test1,1-Recover,42.667,2.562,1.361,0.020,,0.346928,254.648,,34.6928,0.254648,,,,7.85398e-5
Test1,1-Recover,43.000,2.589,1.334,0.034,,0.340046,432.902,,34.0046,0.432902,,,,7.85398e-5
Test1,1-Recover,43.333,2.614,1.309,0.027,,0.333673,343.775,,33.3673,0.343775,,,,7.85398e-5
Test1,1-Recover,43.667,2.641,1.282,0.020,,0.326791,254.648,,32.6791,0.254648,,,,7.85398e-5
Test1,1-Recover,44.000,2.667,1.256,0.027,,0.320163,343.775,,32.0163,0.343775,,,,7.85398e-5
Test1,1-Recover,44.333,2.693,1.23,0.007,,0.313536,89.1268,,31.3536,0.0891268,,,,7.85398e-5
Test1,1-Recover,44.667,2.72,1.203,0.013,,0.306653,165.521,,30.6653,0.165521,,,,7.85398e-5
Test1,1-Recover,45.000,2.746,1.177,0.013,,0.300025,165.521,,30.0025,0.165521,,,,7.85398e-5
Test1,1-Recover,45.333,2.772,1.151,-0.000,,0.293398,0,,29.3398,0,,,,7.85398e-5
Test1,1-Recover,45.667,2.798,1.125,0.007,,0.28677,89.1268,,28.677,0.0891268,,,,7.85398e-5
Test1,1-Recover,46.000,2.824,1.099,-0.000,,0.280143,0,,28.0143,0,,,,7.85398e-5
Test1,1-Recover,46.333,2.85,1.073,-0.014,,0.273515,-178.254,,27.3515,-0.178254,,,,7.85398e-5
Test1,1-Recover,46.667,2.877,1.046,0.007,,0.266633,89.1268,,26.6633,0.0891268,,,,7.85398e-5
Test1,1-Recover,47.000,2.903,1.02,0.007,,0.260005,89.1268,,26.0005,0.0891268,,,,7.85398e-5
Test1,1-Recover,47.333,2.929,0.994,-0.014,,0.253378,-178.254,,25.3378,-0.178254,,,,7.85398e-5
Test1,1-Recover,47.667,2.955,0.968,-0.007,,0.24675,-89.1268,,24.675,-0.0891268,,,,7.85398e-5
Test1,1-Recover,48.000,2.981,0.942,-0.007,,0.240122,-89.1268,,24.0122,-0.0891268,,,,7.85398e-5
Test1,1-Recover,48.333,3.007,0.916,-0.014,,0.233495,-178.254,,23.3495,-0.178254,,,,7.85398e-5
Test1,1-Recover,48.667,3.034,0.889,-0.000,,0.226612,0,,22.6612,0,,,,7.85398e-5
Test1,1-Recover,49.000,3.06,0.863,-0.000,,0.219985,0,,21.9985,0,,,,7.85398e-5
Test1,1-Recover,49.333,3.086,0.837,-0.000,,0.213357,0,,21.3357,0,,,,7.85398e-5
Test1,1-Recover,49.667,3.113,0.81,0.013,,0.206475,165.521,,20.6475,0.165521,,,,7.85398e-5
Test1,1-Recover,50.000,3.139,0.784,0.007,,0.199847,89.1268,,19.9847,0.0891268,,,,7.85398e-5
Test1,1-Recover,50.333,3.164,0.759,0.013,,0.193474,165.521,,19.3474,0.165521,,,,7.85398e-5
Test1,1-Recover,50.667,3.191,0.732,0.013,,0.186592,165.521,,18.6592,0.165521,,,,7.85398e-5
Test1,1-Recover,51.000,3.217,0.706,0.007,,0.179964,89.1268,,17.9964,0.0891268,,,,7.85398e-5
Test1,1-Recover,51.333,3.243,0.68,0.007,,0.173337,89.1268,,17.3337,0.0891268,,,,7.85398e-5
Test1,1-Recover,51.667,3.27,0.653,-0.007,,0.166454,-89.1268,,16.6454,-0.0891268,,,,7.85398e-5
Test1,1-Recover,52.000,3.296,0.627,-0.000,,0.159827,0,,15.9827,0,,,,7.85398e-5
Test1,1-Recover,52.333,3.322,0.601,-0.007,,0.153199,-89.1268,,15.3199,-0.0891268,,,,7.85398e-5
Test1,1-Recover,52.667,3.349,0.574,-0.007,,0.146317,-89.1268,,14.6317,-0.0891268,,,,7.85398e-5
Test1,1-Recover,53.000,3.374,0.549,-0.007,,0.139944,-89.1268,,13.9944,-0.0891268,,,,7.85398e-5
Test1,1-Recover,53.333,3.4,0.523,-0.014,,0.133316,-178.254,,13.3316,-0.178254,,,,7.85398e-5
Test1,1-Recover,53.667,3.427,0.496,-0.014,,0.126434,-178.254,,12.6434,-0.178254,,,,7.85398e-5
Test1,1-Recover,54.000,3.453,0.47,-0.014,,0.119806,-178.254,,11.9806,-0.178254,,,,7.85398e-5
Test1,1-Recover,54.333,3.479,0.444,-0.007,,0.113179,-89.1268,,11.3179,-0.0891268,,,,7.85398e-5
Test1,1-Recover,54.667,3.506,0.417,-0.007,,0.106296,-89.1268,,10.6296,-0.0891268,,,,7.85398e-5
Test1,1-Recover,55.000,3.531,0.392,-0.000,,0.0999235,0,,9.99235,0,,,,7.85398e-5
Test1,1-Recover,55.333,3.557,0.366,-0.007,,0.0932959,-89.1268,,9.32959,-0.0891268,,,,7.85398e-5
Test1,1-Recover,55.667,3.584,0.339,0.007,,0.0864135,89.1268,,8.64135,0.0891268,,,,7.85398e-5
Test1,1-Recover,56.000,3.61,0.313,-0.007,,0.0797859,-89.1268,,7.97859,-0.0891268,,,,7.85398e-5
Test1,1-Recover,56.333,3.636,0.287,-0.007,,0.0731583,-89.1268,,7.31583,-0.0891268,,,,7.85398e-5
Test1,1-Recover,56.667,3.663,0.26,0.020,,0.0662758,254.648,,6.62758,0.254648,,,,7.85398e-5
Test1,1-Recover,57.000,3.689,0.234,-0.000,,0.0596482,0,,5.96482,0,,,,7.85398e-5
Test1,1-Recover,57.333,3.714,0.209,0.020,,0.0532756,254.648,,5.32756,0.254648,,,,7.85398e-5
Test1,1-Recover,57.667,3.741,0.182,0.020,,0.0463931,254.648,,4.63931,0.254648,,,,7.85398e-5
Test1,1-Recover,58.000,3.767,0.156,-0.000,,0.0397655,0,,3.97655,0,,,,7.85398e-5
Test1,1-Recover,58.333,3.793,0.13,-0.007,,0.0331379,-89.1268,,3.31379,-0.0891268,,,,7.85398e-5
Test1,1-Recover,58.667,3.82,0.103,-0.000,,0.0262554,0,,2.62554,0,,,,7.85398e-5
Test1,1-Recover,59.000,3.846,0.077,-0.000,,0.0196278,0,,1.96278,0,,,,7.85398e-5
Test1,1-Recover,59.333,3.872,0.051,-0.000,,0.0130003,0,,1.30003,0,,,,7.85398e-5
Test1,1-Recover,59.667,3.899,0.024,-0.000,,0.00611777,0,,0.611777,0,,,,7.85398e-5
Test1,1-Recover,60.000,3.923,-0,-0.007,,0,-89.1268,,0,-0.0891268,,,,7.85398e-5
Test1,2-Compress,60.317,3.901,0.022,-0.000,,0.00560795,0,,0.560795,0,,,,7.85398e-5
Test1,2-Compress,60.650,3.876,0.047,-0.000,,0.0119806,0,,1.19806,0,,,,7.85398e-5
Test1,2-Compress,60.983,3.849,0.074,0.013,,0.0188631,165.521,,1.88631,0.165521,,,,7.85398e-5
Test1,2-Compress,61.317,3.823,0.1,-0.000,,0.0254907,0,,2.54907,0,,,,7.85398e-5
Test1,2-Compress,61.650,3.797,0.126,-0.007,,0.0321183,-89.1268,,3.21183,-0.0891268,,,,7.85398e-5
Test1,2-Compress,61.983,3.771,0.152,-0.007,,0.0387459,-89.1268,,3.87459,-0.0891268,,,,7.85398e-5
Test1,2-Compress,62.317,3.744,0.179,-0.007,,0.0456283,-89.1268,,4.56283,-0.0891268,,,,7.85398e-5
Test1,2-Compress,62.650,3.718,0.205,0.007,,0.0522559,89.1268,,5.22559,0.0891268,,,,7.85398e-5
Test1,2-Compress,62.983,3.692,0.231,-0.007,,0.0588835,-89.1268,,5.88835,-0.0891268,,,,7.85398e-5
Test1,2-Compress,63.317,3.666,0.257,-0.007,,0.0655111,-89.1268,,6.55111,-0.0891268,,,,7.85398e-5
Test1,2-Compress,63.650,3.64,0.283,-0.014,,0.0721387,-178.254,,7.21387,-0.178254,,,,7.85398e-5
Test1,2-Compress,63.983,3.614,0.309,-0.014,,0.0787663,-178.254,,7.87663,-0.178254,,,,7.85398e-5
Test1,2-Compress,64.317,3.587,0.336,-0.007,,0.0856487,-89.1268,,8.56487,-0.0891268,,,,7.85398e-5
Test1,2-Compress,64.650,3.561,0.362,-0.007,,0.0922763,-89.1268,,9.22763,-0.0891268,,,,7.85398e-5
Test1,2-Compress,64.983,3.535,0.388,-0.000,,0.0989039,0,,9.89039,0,,,,7.85398e-5
Test1,2-Compress,65.317,3.508,0.415,0.007,,0.105786,89.1268,,10.5786,0.0891268,,,,7.85398e-5
Test1,2-Compress,65.650,3.482,0.441,-0.000,,0.112414,0,,11.2414,0,,,,7.85398e-5
Test1,2-Compress,65.983,3.456,0.467,-0.000,,0.119042,0,,11.9042,0,,,,7.85398e-5
Test1,2-Compress,66.317,3.43,0.493,0.027,,0.125669,343.775,,12.5669,0.343775,,,,7.85398e-5
Test1,2-Compress,66.650,3.404,0.519,0.007,,0.132297,89.1268,,13.2297,0.0891268,,,,7.85398e-5
Test1,2-Compress,66.983,3.378,0.545,0.013,,0.138924,165.521,,13.8924,0.165521,,,,7.85398e-5
Test1,2-Compress,67.317,3.351,0.572,0.027,,0.145807,343.775,,14.5807,0.343775,,,,7.85398e-5
Test1,2-Compress,67.650,3.325,0.598,0.013,,0.152434,165.521,,15.2434,0.165521,,,,7.85398e-5
Test1,2-Compress,67.983,3.299,0.624,0.020,,0.159062,254.648,,15.9062,0.254648,,,,7.85398e-5
Test1,2-Compress,68.317,3.273,0.65,0.007,,0.16569,89.1268,,16.569,0.0891268,,,,7.85398e-5
Test1,2-Compress,68.650,3.247,0.676,0.020,,0.172317,254.648,,17.2317,0.254648,,,,7.85398e-5
Test1,2-Compress,68.983,3.221,0.702,0.007,,0.178945,89.1268,,17.8945,0.0891268,,,,7.85398e-5
Test1,2-Compress,69.317,3.194,0.729,0.007,,0.185827,89.1268,,18.5827,0.0891268,,,,7.85398e-5
Test1,2-Compress,69.650,3.168,0.755,0.020,,0.192455,254.648,,19.2455,0.254648,,,,7.85398e-5
Test1,2-Compress,69.983,3.142,0.781,0.007,,0.199082,89.1268,,19.9082,0.0891268,,,,7.85398e-5
Test1,2-Compress,70.317,3.116,0.807,0.007,,0.20571,89.1268,,20.571,0.0891268,,,,7.85398e-5
Test1,2-Compress,70.650,3.089,0.834,0.020,,0.212592,254.648,,21.2592,0.254648,,,,7.85398e-5
Test1,2-Compress,70.983,3.064,0.859,0.020,,0.218965,254.648,,21.8965,0.254648,,,,7.85398e-5
Test1,2-Compress,71.317,3.037,0.886,0.034,,0.225848,432.902,,22.5848,0.432902,,,,7.85398e-5
Test1,2-Compress,71.650,3.011,0.912,0.013,,0.232475,165.521,,23.2475,0.165521,,,,7.85398e-5
Test1,2-Compress,71.983,2.985,0.938,0.020,,0.239103,254.648,,23.9103,0.254648,,,,7.85398e-5
Test1,2-Compress,72.317,2.958,0.965,0.034,,0.245985,432.902,,24.5985,0.432902,,,,7.85398e-5
Test1,2-Compress,72.650,2.932,0.991,0.034,,0.252613,432.902,,25.2613,0.432902,,,,7.85398e-5
Test1,2-Compress,72.983,2.906,1.017,0.034,,0.25924,432.902,,25.924,0.432902,,,,7.85398e-5
Test1,2-Compress,73.317,2.88,1.043,0.027,,0.265868,343.775,,26.5868,0.343775,,,,7.85398e-5
Test1,2-Compress,73.650,2.854,1.069,0.041,,0.272496,522.028,,27.2496,0.522028,,,,7.85398e-5
Test1,2-Compress,73.983,2.828,1.095,0.027,,0.279123,343.775,,27.9123,0.343775,,,,7.85398e-5
Test1,2-Compress,74.317,2.801,1.122,0.034,,0.286006,432.902,,28.6006,0.432902,,,,7.85398e-5
Test1,2-Compress,74.650,2.775,1.148,0.034,,0.292633,432.902,,29.2633,0.432902,,,,7.85398e-5
Test1,2-Compress,74.983,2.749,1.174,0.034,,0.299261,432.902,,29.9261,0.432902,,,,7.85398e-5
Test1,2-Compress,75.317,2.723,1.2,0.034,,0.305888,432.902,,30.5888,0.432902,,,,7.85398e-5
Test1,2-Compress,75.650,2.696,1.227,0.034,,0.312771,432.902,,31.2771,0.432902,,,,7.85398e-5
Test1,2-Compress,75.983,2.671,1.252,0.034,,0.319144,432.902,,31.9144,0.432902,,,,7.85398e-5
Test1,2-Compress,76.317,2.644,1.279,0.034,,0.326026,432.902,,32.6026,0.432902,,,,7.85398e-5
Test1,2-Compress,76.650,2.618,1.305,0.034,,0.332654,432.902,,33.2654,0.432902,,,,7.85398e-5
Test1,2-Compress,76.983,2.592,1.331,0.034,,0.339281,432.902,,33.9281,0.432902,,,,7.85398e-5
Test1,2-Compress,77.317,2.565,1.358,0.034,,0.346164,432.902,,34.6164,0.432902,,,,7.85398e-5
Test1,2-Compress,77.650,2.539,1.384,0.034,,0.352791,432.902,,35.2791,0.432902,,,,7.85398e-5
Test1,2-Compress,77.983,2.514,1.409,0.034,,0.359164,432.902,,35.9164,0.432902,,,,7.85398e-5
Test1,2-Compress,78.317,2.487,1.436,0.034,,0.366046,432.902,,36.6046,0.432902,,,,7.85398e-5
Test1,2-Compress,78.650,2.461,1.462,0.034,,0.372674,432.902,,37.2674,0.432902,,,,7.85398e-5
Test1,2-Compress,78.983,2.435,1.488,0.034,,0.379302,432.902,,37.9302,0.432902,,,,7.85398e-5
Test1,2-Compress,79.317,2.408,1.515,0.041,,0.386184,522.028,,38.6184,0.522028,,,,7.85398e-5
Test1,2-Compress,79.650,2.382,1.541,0.041,,0.392812,522.028,,39.2812,0.522028,,,,7.85398e-5
Test1,2-Compress,79.983,2.356,1.567,0.041,,0.399439,522.028,,39.9439,0.522028,,,,7.85398e-5
Test1,2-Compress,80.317,2.329,1.594,0.041,,0.406322,522.028,,40.6322,0.522028,,,,7.85398e-5
Test1,2-Compress,80.650,2.304,1.619,0.041,,0.412694,522.028,,41.2694,0.522028,,,,7.85398e-5
Test1,2-Compress,80.983,2.278,1.645,0.041,,0.419322,522.028,,41.9322,0.522028,,,,7.85398e-5
Test1,2-Compress,81.317,2.251,1.672,0.041,,0.426204,522.028,,42.6204,0.522028,,,,7.85398e-5
Test1,2-Compress,81.650,2.225,1.698,0.047,,0.432832,598.423,,43.2832,0.598423,,,,7.85398e-5
Test1,2-Compress,81.983,2.199,1.724,0.041,,0.43946,522.028,,43.946,0.522028,,,,7.85398e-5
Test1,2-Compress,82.317,2.172,1.751,0.034,,0.446342,432.902,,44.6342,0.432902,,,,7.85398e-5
Test1,2-Compress,82.650,2.147,1.776,0.041,,0.452715,522.028,,45.2715,0.522028,,,,7.85398e-5
Test1,2-Compress,82.983,2.121,1.802,0.041,,0.459342,522.028,,45.9342,0.522028,,,,7.85398e-5
Test1,2-Compress,83.317,2.094,1.829,0.034,,0.466225,432.902,,46.6225,0.432902,,,,7.85398e-5
Test1,2-Compress,83.650,2.068,1.855,0.034,,0.472852,432.902,,47.2852,0.432902,,,,7.85398e-5
Test1,2-Compress,83.983,2.042,1.881,0.034,,0.47948,432.902,,47.948,0.432902,,,,7.85398e-5
Test1,2-Compress,84.317,2.015,1.908,0.034,,0.486362,432.902,,48.6362,0.432902,,,,7.85398e-5
Test1,2-Compress,84.650,1.989,1.934,0.034,,0.49299,432.902,,49.299,0.432902,,,,7.85398e-5
Test1,2-Compress,84.983,1.964,1.959,0.034,,0.499363,432.902,,49.9363,0.432902,,,,7.85398e-5
Test1,2-Compress,85.317,1.937,1.986,0.034,,0.506245,432.902,,50.6245,0.432902,,,,7.85398e-5
Test1,2-Compress,85.650,1.911,2.012,0.041,,0.512873,522.028,,51.2873,0.522028,,,,7.85398e-5
Test1,2-Compress,85.983,1.885,2.038,0.034,,0.5195,432.902,,51.95,0.432902,,,,7.85398e-5
Test1,2-Compress,86.317,1.858,2.065,0.034,,0.526383,432.902,,52.6383,0.432902,,,,7.85398e-5
Test1,2-Compress,86.650,1.832,2.091,0.034,,0.53301,432.902,,53.301,0.432902,,,,7.85398e-5
Test1,2-Compress,86.983,1.806,2.117,0.034,,0.539638,432.902,,53.9638,0.432902,,,,7.85398e-5
Test1,2-Compress,87.317,1.78,2.143,0.041,,0.546266,522.028,,54.6266,0.522028,,,,7.85398e-5
Test1,2-Compress,87.650,1.754,2.169,0.041,,0.552893,522.028,,55.2893,0.522028,,,,7.85398e-5
Test1,2-Compress,87.983,1.728,2.195,0.041,,0.559521,522.028,,55.9521,0.522028,,,,7.85398e-5
Test1,2-Compress,88.317,1.701,2.222,0.041,,0.566403,522.028,,56.6403,0.522028,,,,7.85398e-5
Test1,2-Compress,88.650,1.675,2.248,0.047,,0.573031,598.423,,57.3031,0.598423,,,,7.85398e-5
Test1,2-Compress,88.983,1.649,2.274,0.041,,0.579658,522.028,,57.9658,0.522028,,,,7.85398e-5
Test1,2-Compress,89.317,1.622,2.301,0.047,,0.586541,598.423,,58.6541,0.598423,,,,7.85398e-5
Test1,2-Compress,89.650,1.597,2.326,0.054,,0.592914,687.549,,59.2914,0.687549,,,,7.85398e-5
Test1,2-Compress,89.983,1.57,2.353,0.047,,0.599796,598.423,,59.9796,0.598423,,,,7.85398e-5
Test1,2-Recover,90.303,1.588,2.335,0.047,,0.595208,598.423,,59.5208,0.598423,,,,7.85398e-5
Test1,2-Recover,90.637,1.614,2.309,0.047,,0.58858,598.423,,58.858,0.598423,,,,7.85398e-5
Test1,2-Recover,90.970,1.64,2.283,0.047,,0.581953,598.423,,58.1953,0.598423,,,,7.85398e-5
Test1,2-Recover,91.303,1.666,2.257,0.047,,0.575325,598.423,,57.5325,0.598423,,,,7.85398e-5
Test1,2-Recover,91.637,1.693,2.23,0.041,,0.568443,522.028,,56.8443,0.522028,,,,7.85398e-5
Test1,2-Recover,91.970,1.719,2.204,0.034,,0.561815,432.902,,56.1815,0.432902,,,,7.85398e-5
Test1,2-Recover,92.303,1.745,2.178,0.034,,0.555187,432.902,,55.5187,0.432902,,,,7.85398e-5
Test1,2-Recover,92.637,1.771,2.152,0.034,,0.54856,432.902,,54.856,0.432902,,,,7.85398e-5
Test1,2-Recover,92.970,1.797,2.126,0.034,,0.541932,432.902,,54.1932,0.432902,,,,7.85398e-5
Test1,2-Recover,93.303,1.823,2.1,0.034,,0.535305,432.902,,53.5305,0.432902,,,,7.85398e-5
Test1,2-Recover,93.637,1.85,2.073,0.034,,0.528422,432.902,,52.8422,0.432902,,,,7.85398e-5
Test1,2-Recover,93.970,1.876,2.047,0.034,,0.521795,432.902,,52.1795,0.432902,,,,7.85398e-5
Test1,2-Recover,94.303,1.902,2.021,0.034,,0.515167,432.902,,51.5167,0.432902,,,,7.85398e-5
Test1,2-Recover,94.637,1.929,1.994,0.034,,0.508284,432.902,,50.8284,0.432902,,,,7.85398e-5
Test1,2-Recover,94.970,1.955,1.968,0.034,,0.501657,432.902,,50.1657,0.432902,,,,7.85398e-5
Test1,2-Recover,95.303,1.98,1.943,0.034,,0.495284,432.902,,49.5284,0.432902,,,,7.85398e-5
Test1,2-Recover,95.637,2.007,1.916,0.034,,0.488402,432.902,,48.8402,0.432902,,,,7.85398e-5
Test1,2-Recover,95.970,2.033,1.89,0.041,,0.481774,522.028,,48.1774,0.522028,,,,7.85398e-5
Test1,2-Recover,96.303,2.059,1.864,0.041,,0.475147,522.028,,47.5147,0.522028,,,,7.85398e-5
Test1,2-Recover,96.637,2.086,1.837,0.041,,0.468264,522.028,,46.8264,0.522028,,,,7.85398e-5
Test1,2-Recover,96.970,2.112,1.811,0.041,,0.461637,522.028,,46.1637,0.522028,,,,7.85398e-5
Test1,2-Recover,97.303,2.137,1.786,0.047,,0.455264,598.423,,45.5264,0.598423,,,,7.85398e-5
Test1,2-Recover,97.637,2.164,1.759,0.041,,0.448381,522.028,,44.8381,0.522028,,,,7.85398e-5
Test1,2-Recover,97.970,2.19,1.733,0.041,,0.441754,522.028,,44.1754,0.522028,,,,7.85398e-5
Test1,2-Recover,98.303,2.216,1.707,0.047,,0.435126,598.423,,43.5126,0.598423,,,,7.85398e-5
Test1,2-Recover,98.637,2.243,1.68,0.041,,0.428244,522.028,,42.8244,0.522028,,,,7.85398e-5
Test1,2-Recover,98.970,2.269,1.654,0.034,,0.421616,432.902,,42.1616,0.432902,,,,7.85398e-5
Test1,2-Recover,99.303,2.295,1.628,0.034,,0.414989,432.902,,41.4989,0.432902,,,,7.85398e-5
Test1,2-Recover,99.637,2.322,1.601,0.034,,0.408106,432.902,,40.8106,0.432902,,,,7.85398e-5
Test1,2-Recover,99.970,2.347,1.576,0.034,,0.401733,432.902,,40.1733,0.432902,,,,7.85398e-5
Test1,2-Recover,100.303,2.373,1.55,0.034,,0.395106,432.902,,39.5106,0.432902,,,,7.85398e-5
Test1,2-Recover,100.637,2.4,1.523,0.027,,0.388223,343.775,,38.8223,0.343775,,,,7.85398e-5
Test1,2-Recover,100.970,2.426,1.497,0.034,,0.381596,432.902,,38.1596,0.432902,,,,7.85398e-5
Test1,2-Recover,101.303,2.452,1.471,0.020,,0.374968,254.648,,37.4968,0.254648,,,,7.85398e-5
Test1,2-Recover,101.637,2.479,1.444,0.034,,0.368086,432.902,,36.8086,0.432902,,,,7.85398e-5
Test1,2-Recover,101.970,2.505,1.418,0.013,,0.361458,165.521,,36.1458,0.165521,,,,7.85398e-5
Test1,2-Recover,102.303,2.53,1.393,0.027,,0.355085,343.775,,35.5085,0.343775,,,,7.85398e-5
Test1,2-Recover,102.637,2.557,1.366,0.013,,0.348203,165.521,,34.8203,0.165521,,,,7.85398e-5
Test1,2-Recover,102.970,2.583,1.34,0.020,,0.341575,254.648,,34.1575,0.254648,,,,7.85398e-5
Test1,2-Recover,103.303,2.609,1.314,0.020,,0.334948,254.648,,33.4948,0.254648,,,,7.85398e-5
Test1,2-Recover,103.637,2.636,1.287,-0.007,,0.328065,-89.1268,,32.8065,-0.0891268,,,,7.85398e-5
Test1,2-Recover,103.970,2.662,1.261,0.034,,0.321438,432.902,,32.1438,0.432902,,,,7.85398e-5
Test1,2-Recover,104.303,2.688,1.235,0.007,,0.31481,89.1268,,31.481,0.0891268,,,,7.85398e-5
Test1,2-Recover,104.637,2.714,1.209,-0.007,,0.308183,-89.1268,,30.8183,-0.0891268,,,,7.85398e-5
Test1,2-Recover,104.970,2.74,1.183,0.007,,0.301555,89.1268,,30.1555,0.0891268,,,,7.85398e-5
Test1,2-Recover,105.303,2.766,1.157,0.020,,0.294927,254.648,,29.4927,0.254648,,,,7.85398e-5
Test1,2-Recover,105.637,2.793,1.13,0.007,,0.288045,89.1268,,28.8045,0.0891268,,,,7.85398e-5
Test1,2-Recover,105.970,2.819,1.104,0.007,,0.281417,89.1268,,28.1417,0.0891268,,,,7.85398e-5
Test1,2-Recover,106.303,2.845,1.078,0.013,,0.27479,165.521,,27.479,0.165521,,,,7.85398e-5
Test1,2-Recover,106.637,2.872,1.051,0.027,,0.267907,343.775,,26.7907,0.343775,,,,7.85398e-5
Test1,2-Recover,106.970,2.897,1.026,0.007,,0.261535,89.1268,,26.1535,0.0891268,,,,7.85398e-5
Test1,2-Recover,107.303,2.923,1,0.013,,0.254907,165.521,,25.4907,0.165521,,,,7.85398e-5
Test1,2-Recover,107.637,2.95,0.973,0.013,,0.248024,165.521,,24.8024,0.165521,,,,7.85398e-5
Test1,2-Recover,107.970,2.976,0.947,0.007,,0.241397,89.1268,,24.1397,0.0891268,,,,7.85398e-5
Test1,2-Recover,108.303,3.002,0.921,-0.000,,0.234769,0,,23.4769,0,,,,7.85398e-5
Test1,2-Recover,108.637,3.029,0.894,-0.000,,0.227887,0,,22.7887,0,,,,7.85398e-5
Test1,2-Recover,108.970,3.055,0.868,-0.000,,0.221259,0,,22.1259,0,,,,7.85398e-5
Test1,2-Recover,109.303,3.081,0.842,-0.007,,0.214632,-89.1268,,21.4632,-0.0891268,,,,7.85398e-5
Test1,2-Recover,109.637,3.107,0.816,-0.000,,0.208004,0,,20.8004,0,,,,7.85398e-5
Test1,2-Recover,109.970,3.133,0.79,-0.007,,0.201376,-89.1268,,20.1376,-0.0891268,,,,7.85398e-5
Test1,2-Recover,110.303,3.159,0.764,-0.007,,0.194749,-89.1268,,19.4749,-0.0891268,,,,7.85398e-5
Test1,2-Recover,110.637,3.186,0.737,-0.007,,0.187866,-89.1268,,18.7866,-0.0891268,,,,7.85398e-5
Test1,2-Recover,110.970,3.212,0.711,-0.014,,0.181239,-178.254,,18.1239,-0.178254,,,,7.85398e-5
Test1,2-Recover,111.303,3.238,0.685,-0.014,,0.174611,-178.254,,17.4611,-0.178254,,,,7.85398e-5
Test1,2-Recover,111.637,3.264,0.659,-0.014,,0.167984,-178.254,,16.7984,-0.178254,,,,7.85398e-5
Test1,2-Recover,111.970,3.29,0.633,-0.014,,0.161356,-178.254,,16.1356,-0.178254,,,,7.85398e-5
Test1,2-Recover,112.303,3.316,0.607,-0.007,,0.154729,-89.1268,,15.4729,-0.0891268,,,,7.85398e-5
Test1,2-Recover,112.637,3.343,0.58,-0.007,,0.147846,-89.1268,,14.7846,-0.0891268,,,,7.85398e-5
Test1,2-Recover,112.970,3.369,0.554,-0.014,,0.141218,-178.254,,14.1218,-0.178254,,,,7.85398e-5
Test1,2-Recover,113.303,3.395,0.528,-0.000,,0.134591,0,,13.4591,0,,,,7.85398e-5
Test1,2-Recover,113.637,3.422,0.501,0.013,,0.127708,165.521,,12.7708,0.165521,,,,7.85398e-5
Test1,2-Recover,113.970,3.448,0.475,-0.000,,0.121081,0,,12.1081,0,,,,7.85398e-5
Test1,2-Recover,114.303,3.474,0.449,-0.000,,0.114453,0,,11.4453,0,,,,7.85398e-5
Test1,2-Recover,114.637,3.5,0.423,-0.000,,0.107826,0,,10.7826,0,,,,7.85398e-5
Test1,2-Recover,114.970,3.526,0.397,-0.007,,0.101198,-89.1268,,10.1198,-0.0891268,,,,7.85398e-5
Test1,2-Recover,115.303,3.552,0.371,-0.007,,0.0945705,-89.1268,,9.45705,-0.0891268,,,,7.85398e-5
Test1,2-Recover,115.637,3.579,0.344,-0.007,,0.087688,-89.1268,,8.7688,-0.0891268,,,,7.85398e-5
Test1,2-Recover,115.970,3.605,0.318,-0.007,,0.0810604,-89.1268,,8.10604,-0.0891268,,,,7.85398e-5
Test1,2-Recover,116.303,3.631,0.292,0.007,,0.0744328,89.1268,,7.44328,0.0891268,,,,7.85398e-5
Test1,2-Recover,116.637,3.657,0.266,0.013,,0.0678053,165.521,,6.78053,0.165521,,,,7.85398e-5
Test1,2-Recover,116.970,3.683,0.24,-0.007,,0.0611777,-89.1268,,6.11777,-0.0891268,,,,7.85398e-5
Test1,2-Recover,117.303,3.709,0.214,-0.000,,0.0545501,0,,5.45501,0,,,,7.85398e-5
Test1,2-Recover,117.637,3.736,0.187,-0.007,,0.0476676,-89.1268,,4.76676,-0.0891268,,,,7.85398e-5
Test1,2-Recover,117.970,3.762,0.161,-0.014,,0.04104,-178.254,,4.104,-0.178254,,,,7.85398e-5
Test1,2-Recover,118.303,3.788,0.135,-0.000,,0.0344124,0,,3.44124,0,,,,7.85398e-5
Test1,2-Recover,118.637,3.814,0.109,-0.007,,0.0277849,-89.1268,,2.77849,-0.0891268,,,,7.85398e-5
Test1,2-Recover,118.970,3.841,0.082,0.020,,0.0209024,254.648,,2.09024,0.254648,,,,7.85398e-5
Test1,2-Recover,119.303,3.866,0.057,-0.000,,0.0145297,0,,1.45297,0,,,,7.85398e-5
Test1,2-Recover,119.637,3.893,0.03,-0.000,,0.00764721,0,,0.764721,0,,,,7.85398e-5
Test1,2-Recover,119.970,3.919,0.004,-0.000,,0.00101963,0,,0.101963,0,,,,7.85398e-5
Test1,3-Compress,120.280,3.908,0.015,0.013,,0.0038236,165.521,,0.38236,0.165521,,,,7.85398e-5
Test1,3-Compress,120.613,3.881,0.042,-0.000,,0.0107061,0,,1.07061,0,,,,7.85398e-5
Test1,3-Compress,120.947,3.855,0.068,-0.007,,0.0173337,-89.1268,,1.73337,-0.0891268,,,,7.85398e-5
Test1,3-Compress,121.280,3.829,0.094,0.007,,0.0239613,89.1268,,2.39613,0.0891268,,,,7.85398e-5
Test1,3-Compress,121.613,3.803,0.12,0.007,,0.0305888,89.1268,,3.05888,0.0891268,,,,7.85398e-5
Test1,3-Compress,121.947,3.776,0.147,0.007,,0.0374713,89.1268,,3.74713,0.0891268,,,,7.85398e-5
Test1,3-Compress,122.280,3.75,0.173,-0.000,,0.0440989,0,,4.40989,0,,,,7.85398e-5
Test1,3-Compress,122.613,3.724,0.199,0.007,,0.0507265,89.1268,,5.07265,0.0891268,,,,7.85398e-5
Test1,3-Compress,122.947,3.698,0.225,-0.000,,0.0573541,0,,5.73541,0,,,,7.85398e-5
Test1,3-Compress,123.280,3.672,0.251,0.007,,0.0639816,89.1268,,6.39816,0.0891268,,,,7.85398e-5
Test1,3-Compress,123.613,3.646,0.277,-0.000,,0.0706092,0,,7.06092,0,,,,7.85398e-5
Test1,3-Compress,123.947,3.619,0.304,-0.000,,0.0774917,0,,7.74917,0,,,,7.85398e-5
Test1,3-Compress,124.280,3.593,0.33,0.013,,0.0841193,165.521,,8.41193,0.165521,,,,7.85398e-5
Test1,3-Compress,124.613,3.567,0.356,0.013,,0.0907469,165.521,,9.07469,0.165521,,,,7.85398e-5
Test1,3-Compress,124.947,3.541,0.382,-0.000,,0.0973745,0,,9.73745,0,,,,7.85398e-5
Test1,3-Compress,125.280,3.515,0.408,-0.000,,0.104002,0,,10.4002,0,,,,7.85398e-5
Test1,3-Compress,125.613,3.489,0.434,-0.000,,0.11063,0,,11.063,0,,,,7.85398e-5
Test1,3-Compress,125.947,3.462,0.461,-0.000,,0.117512,0,,11.7512,0,,,,7.85398e-5
Test1,3-Compress,126.280,3.436,0.487,0.007,,0.12414,89.1268,,12.414,0.0891268,,,,7.85398e-5
Test1,3-Compress,126.613,3.41,0.513,0.007,,0.130767,89.1268,,13.0767,0.0891268,,,,7.85398e-5
Test1,3-Compress,126.947,3.383,0.54,-0.007,,0.13765,-89.1268,,13.765,-0.0891268,,,,7.85398e-5
Test1,3-Compress,127.280,3.357,0.566,-0.000,,0.144277,0,,14.4277,0,,,,7.85398e-5
Test1,3-Compress,127.613,3.331,0.592,0.007,,0.150905,89.1268,,15.0905,0.0891268,,,,7.85398e-5
Test1,3-Compress,127.947,3.305,0.618,-0.007,,0.157533,-89.1268,,15.7533,-0.0891268,,,,7.85398e-5
Test1,3-Compress,128.280,3.279,0.644,0.020,,0.16416,254.648,,16.416,0.254648,,,,7.85398e-5
Test1,3-Compress,128.613,3.253,0.67,0.007,,0.170788,89.1268,,17.0788,0.0891268,,,,7.85398e-5
Test1,3-Compress,128.947,3.226,0.697,0.020,,0.17767,254.648,,17.767,0.254648,,,,7.85398e-5
Test1,3-Compress,129.280,3.2,0.723,-0.007,,0.184298,-89.1268,,18.4298,-0.0891268,,,,7.85398e-5
Test1,3-Compress,129.613,3.174,0.749,0.007,,0.190925,89.1268,,19.0925,0.0891268,,,,7.85398e-5
Test1,3-Compress,129.947,3.148,0.775,0.027,,0.197553,343.775,,19.7553,0.343775,,,,7.85398e-5
Test1,3-Compress,130.280,3.122,0.801,0.027,,0.20418,343.775,,20.418,0.343775,,,,7.85398e-5
Test1,3-Compress,130.613,3.096,0.827,0.034,,0.210808,432.902,,21.0808,0.432902,,,,7.85398e-5
Test1,3-Compress,130.947,3.069,0.854,0.034,,0.217691,432.902,,21.7691,0.432902,,,,7.85398e-5
Test1,3-Compress,131.280,3.043,0.88,0.027,,0.224318,343.775,,22.4318,0.343775,,,,7.85398e-5
Test1,3-Compress,131.613,3.017,0.906,0.034,,0.230946,432.902,,23.0946,0.432902,,,,7.85398e-5
Test1,3-Compress,131.947,2.99,0.933,0.027,,0.237828,343.775,,23.7828,0.343775,,,,7.85398e-5
Test1,3-Compress,132.280,2.964,0.959,0.034,,0.244456,432.902,,24.4456,0.432902,,,,7.85398e-5
Test1,3-Compress,132.613,2.939,0.984,0.034,,0.250828,432.902,,25.0828,0.432902,,,,7.85398e-5
Test1,3-Compress,132.947,2.912,1.011,0.034,,0.257711,432.902,,25.7711,0.432902,,,,7.85398e-5
Test1,3-Compress,133.280,2.886,1.037,0.034,,0.264339,432.902,,26.4339,0.432902,,,,7.85398e-5
Test1,3-Compress,133.613,2.86,1.063,0.034,,0.270966,432.902,,27.0966,0.432902,,,,7.85398e-5
Test1,3-Compress,133.947,2.833,1.09,0.034,,0.277849,432.902,,27.7849,0.432902,,,,7.85398e-5
Test1,3-Compress,134.280,2.807,1.116,0.034,,0.284476,432.902,,28.4476,0.432902,,,,7.85398e-5
Test1,3-Compress,134.613,2.782,1.141,0.034,,0.290849,432.902,,29.0849,0.432902,,,,7.85398e-5
Test1,3-Compress,134.947,2.755,1.168,0.034,,0.297731,432.902,,29.7731,0.432902,,,,7.85398e-5
Test1,3-Compress,135.280,2.729,1.194,0.034,,0.304359,432.902,,30.4359,0.432902,,,,7.85398e-5
Test1,3-Compress,135.613,2.703,1.22,0.034,,0.310986,432.902,,31.0986,0.432902,,,,7.85398e-5
Test1,3-Compress,135.947,2.676,1.247,0.034,,0.317869,432.902,,31.7869,0.432902,,,,7.85398e-5
Test1,3-Compress,136.280,2.65,1.273,0.041,,0.324497,522.028,,32.4497,0.522028,,,,7.85398e-5
Test1,3-Compress,136.613,2.624,1.299,0.041,,0.331124,522.028,,33.1124,0.522028,,,,7.85398e-5
Test1,3-Compress,136.947,2.597,1.326,0.034,,0.338007,432.902,,33.8007,0.432902,,,,7.85398e-5
Test1,3-Compress,137.280,2.572,1.351,0.041,,0.344379,522.028,,34.4379,0.522028,,,,7.85398e-5
Test1,3-Compress,137.613,2.546,1.377,0.041,,0.351007,522.028,,35.1007,0.522028,,,,7.85398e-5
Test1,3-Compress,137.947,2.519,1.404,0.041,,0.357889,522.028,,35.7889,0.522028,,,,7.85398e-5
Test1,3-Compress,138.280,2.493,1.43,0.047,,0.364517,598.423,,36.4517,0.598423,,,,7.85398e-5
Test1,3-Compress,138.613,2.467,1.456,0.041,,0.371145,522.028,,37.1145,0.522028,,,,7.85398e-5
Test1,3-Compress,138.947,2.44,1.483,0.047,,0.378027,598.423,,37.8027,0.598423,,,,7.85398e-5
Test1,3-Compress,139.280,2.414,1.509,0.047,,0.384655,598.423,,38.4655,0.598423,,,,7.85398e-5
Test1,3-Compress,139.613,2.389,1.534,0.041,,0.391027,522.028,,39.1027,0.522028,,,,7.85398e-5
Test1,3-Compress,139.947,2.362,1.561,0.041,,0.39791,522.028,,39.791,0.522028,,,,7.85398e-5
Test1,3-Compress,140.280,2.336,1.587,0.034,,0.404537,432.902,,40.4537,0.432902,,,,7.85398e-5
Test1,3-Compress,140.613,2.31,1.613,0.034,,0.411165,432.902,,41.1165,0.432902,,,,7.85398e-5
Test1,3-Compress,140.947,2.283,1.64,0.034,,0.418047,432.902,,41.8047,0.432902,,,,7.85398e-5
Test1,3-Compress,141.280,2.257,1.666,0.034,,0.424675,432.902,,42.4675,0.432902,,,,7.85398e-5
Test1,3-Compress,141.613,2.231,1.692,0.034,,0.431303,432.902,,43.1303,0.432902,,,,7.85398e-5
Test1,3-Compress,141.947,2.205,1.718,0.034,,0.43793,432.902,,43.793,0.432902,,,,7.85398e-5
Test1,3-Compress,142.280,2.179,1.744,0.034,,0.444558,432.902,,44.4558,0.432902,,,,7.85398e-5
Test1,3-Compress,142.613,2.153,1.77,0.034,,0.451185,432.902,,45.1185,0.432902,,,,7.85398e-5
Test1,3-Compress,142.947,2.126,1.797,0.034,,0.458068,432.902,,45.8068,0.432902,,,,7.85398e-5
Test1,3-Compress,143.280,2.1,1.823,0.034,,0.464695,432.902,,46.4695,0.432902,,,,7.85398e-5
Test1,3-Compress,143.613,2.074,1.849,0.034,,0.471323,432.902,,47.1323,0.432902,,,,7.85398e-5
Test1,3-Compress,143.947,2.047,1.876,0.034,,0.478205,432.902,,47.8205,0.432902,,,,7.85398e-5
Test1,3-Compress,144.280,2.022,1.901,0.041,,0.484578,522.028,,48.4578,0.522028,,,,7.85398e-5
Test1,3-Compress,144.613,1.996,1.927,0.041,,0.491206,522.028,,49.1206,0.522028,,,,7.85398e-5
Test1,3-Compress,144.947,1.969,1.954,0.041,,0.498088,522.028,,49.8088,0.522028,,,,7.85398e-5
Test1,3-Compress,145.280,1.943,1.98,0.041,,0.504716,522.028,,50.4716,0.522028,,,,7.85398e-5
Test1,3-Compress,145.613,1.917,2.006,0.047,,0.511343,598.423,,51.1343,0.598423,,,,7.85398e-5
Test1,3-Compress,145.947,1.89,2.033,0.047,,0.518226,598.423,,51.8226,0.598423,,,,7.85398e-5
Test1,3-Compress,146.280,1.864,2.059,0.047,,0.524853,598.423,,52.4853,0.598423,,,,7.85398e-5
Test1,3-Compress,146.613,1.838,2.085,0.047,,0.531481,598.423,,53.1481,0.598423,,,,7.85398e-5
Test1,3-Compress,146.947,1.812,2.111,0.054,,0.538109,687.549,,53.8109,0.687549,,,,7.85398e-5
Test1,3-Compress,147.280,1.786,2.137,0.041,,0.544736,522.028,,54.4736,0.522028,,,,7.85398e-5
Test1,3-Compress,147.613,1.76,2.163,0.054,,0.551364,687.549,,55.1364,0.687549,,,,7.85398e-5
Test1,3-Compress,147.947,1.733,2.19,0.054,,0.558246,687.549,,55.8246,0.687549,,,,7.85398e-5
Test1,3-Compress,148.280,1.707,2.216,0.041,,0.564874,522.028,,56.4874,0.522028,,,,7.85398e-5
Test1,3-Compress,148.613,1.681,2.242,0.061,,0.571501,776.676,,57.1501,0.776676,,,,7.85398e-5
Test1,3-Compress,148.947,1.655,2.268,0.054,,0.578129,687.549,,57.8129,0.687549,,,,7.85398e-5
Test1,3-Compress,149.280,1.629,2.294,0.054,,0.584757,687.549,,58.4757,0.687549,,,,7.85398e-5
Test1,3-Compress,149.613,1.603,2.32,0.054,,0.591384,687.549,,59.1384,0.687549,,,,7.85398e-5
Test1,3-Compress,149.947,1.576,2.347,0.047,,0.598267,598.423,,59.8267,0.598423,,,,7.85398e-5
Test1,3-Recover,150.280,1.583,2.34,0.047,,0.596482,598.423,,59.6482,0.598423,,,,7.85398e-5
Test1,3-Recover,150.613,1.608,2.315,0.041,,0.59011,522.028,,59.011,0.522028,,,,7.85398e-5
Test1,3-Recover,150.947,1.635,2.288,0.041,,0.583227,522.028,,58.3227,0.522028,,,,7.85398e-5
Test1,3-Recover,151.280,1.661,2.262,0.041,,0.5766,522.028,,57.66,0.522028,,,,7.85398e-5
Test1,3-Recover,151.613,1.687,2.236,0.041,,0.569972,522.028,,56.9972,0.522028,,,,7.85398e-5
Test1,3-Recover,151.947,1.714,2.209,0.034,,0.563089,432.902,,56.3089,0.432902,,,,7.85398e-5
Test1,3-Recover,152.280,1.74,2.183,0.041,,0.556462,522.028,,55.6462,0.522028,,,,7.85398e-5
Test1,3-Recover,152.613,1.766,2.157,0.041,,0.549834,522.028,,54.9834,0.522028,,,,7.85398e-5
Test1,3-Recover,152.947,1.792,2.131,0.041,,0.543207,522.028,,54.3207,0.522028,,,,7.85398e-5
Test1,3-Recover,153.280,1.818,2.105,0.041,,0.536579,522.028,,53.6579,0.522028,,,,7.85398e-5
Test1,3-Recover,153.613,1.844,2.079,0.041,,0.529952,522.028,,52.9952,0.522028,,,,7.85398e-5
Test1,3-Recover,153.947,1.871,2.052,0.047,,0.523069,598.423,,52.3069,0.598423,,,,7.85398e-5
Test1,3-Recover,154.280,1.897,2.026,0.047,,0.516441,598.423,,51.6441,0.598423,,,,7.85398e-5
Test1,3-Recover,154.613,1.923,2,0.041,,0.509814,522.028,,50.9814,0.522028,,,,7.85398e-5
Test1,3-Recover,154.947,1.95,1.973,0.047,,0.502931,598.423,,50.2931,0.598423,,,,7.85398e-5
Test1,3-Recover,155.280,1.975,1.948,0.041,,0.496559,522.028,,49.6559,0.522028,,,,7.85398e-5
Test1,3-Recover,155.613,2.001,1.922,0.041,,0.489931,522.028,,48.9931,0.522028,,,,7.85398e-5
Test1,3-Recover,155.947,2.028,1.895,0.034,,0.483049,432.902,,48.3049,0.432902,,,,7.85398e-5
Test1,3-Recover,156.280,2.054,1.869,0.034,,0.476421,432.902,,47.6421,0.432902,,,,7.85398e-5
Test1,3-Recover,156.613,2.08,1.843,0.034,,0.469794,432.902,,46.9794,0.432902,,,,7.85398e-5
Test1,3-Recover,156.947,2.107,1.816,0.034,,0.462911,432.902,,46.2911,0.432902,,,,7.85398e-5
Test1,3-Recover,157.280,2.133,1.79,0.034,,0.456283,432.902,,45.6283,0.432902,,,,7.85398e-5
Test1,3-Recover,157.613,2.159,1.764,0.034,,0.449656,432.902,,44.9656,0.432902,,,,7.85398e-5
Test1,3-Recover,157.947,2.185,1.738,0.034,,0.443028,432.902,,44.3028,0.432902,,,,7.85398e-5
Test1,3-Recover,158.280,2.211,1.712,0.034,,0.436401,432.902,,43.6401,0.432902,,,,7.85398e-5
Test1,3-Recover,158.613,2.237,1.686,0.034,,0.429773,432.902,,42.9773,0.432902,,,,7.85398e-5
Test1,3-Recover,158.947,2.264,1.659,0.034,,0.422891,432.902,,42.2891,0.432902,,,,7.85398e-5
Test1,3-Recover,159.280,2.29,1.633,0.034,,0.416263,432.902,,41.6263,0.432902,,,,7.85398e-5
Test1,3-Recover,159.613,2.316,1.607,0.034,,0.409635,432.902,,40.9635,0.432902,,,,7.85398e-5
Test1,3-Recover,159.947,2.342,1.581,0.034,,0.403008,432.902,,40.3008,0.432902,,,,7.85398e-5
Test1,3-Recover,160.280,2.368,1.555,0.034,,0.39638,432.902,,39.638,0.432902,,,,7.85398e-5
Test1,3-Recover,160.613,2.394,1.529,0.041,,0.389753,522.028,,38.9753,0.522028,,,,7.85398e-5
Test1,3-Recover,160.947,2.421,1.502,0.041,,0.38287,522.028,,38.287,0.522028,,,,7.85398e-5
Test1,3-Recover,161.280,2.447,1.476,0.034,,0.376243,432.902,,37.6243,0.432902,,,,7.85398e-5
Test1,3-Recover,161.613,2.473,1.45,0.027,,0.369615,343.775,,36.9615,0.343775,,,,7.85398e-5
Test1,3-Recover,161.947,2.5,1.423,0.041,,0.362733,522.028,,36.2733,0.522028,,,,7.85398e-5
Test1,3-Recover,162.280,2.525,1.398,0.034,,0.35636,432.902,,35.636,0.432902,,,,7.85398e-5
Test1,3-Recover,162.613,2.552,1.371,0.013,,0.349477,165.521,,34.9477,0.165521,,,,7.85398e-5
Test1,3-Recover,162.947,2.578,1.345,0.027,,0.34285,343.775,,34.285,0.343775,,,,7.85398e-5
Test1,3-Recover,163.280,2.604,1.319,0.013,,0.336222,165.521,,33.6222,0.165521,,,,7.85398e-5
Test1,3-Recover,163.613,2.63,1.293,0.027,,0.329595,343.775,,32.9595,0.343775,,,,7.85398e-5
Test1,3-Recover,163.947,2.657,1.266,0.020,,0.322712,254.648,,32.2712,0.254648,,,,7.85398e-5
Test1,3-Recover,164.280,2.683,1.24,0.034,,0.316085,432.902,,31.6085,0.432902,,,,7.85398e-5
Test1,3-Recover,164.613,2.709,1.214,0.020,,0.309457,254.648,,30.9457,0.254648,,,,7.85398e-5
Test1,3-Recover,164.947,2.735,1.188,0.020,,0.302829,254.648,,30.2829,0.254648,,,,7.85398e-5
Test1,3-Recover,165.280,2.761,1.162,0.020,,0.296202,254.648,,29.6202,0.254648,,,,7.85398e-5
Test1,3-Recover,165.613,2.787,1.136,0.013,,0.289574,165.521,,28.9574,0.165521,,,,7.85398e-5
Test1,3-Recover,165.947,2.814,1.109,0.027,,0.282692,343.775,,28.2692,0.343775,,,,7.85398e-5
Test1,3-Recover,166.280,2.84,1.083,-0.000,,0.276064,0,,27.6064,0,,,,7.85398e-5
Test1,3-Recover,166.613,2.866,1.057,0.007,,0.269437,89.1268,,26.9437,0.0891268,,,,7.85398e-5
Test1,3-Recover,166.947,2.892,1.031,0.020,,0.262809,254.648,,26.2809,0.254648,,,,7.85398e-5
Test1,3-Recover,167.280,2.919,1.004,0.013,,0.255927,165.521,,25.5927,0.165521,,,,7.85398e-5
Test1,3-Recover,167.613,2.945,0.978,-0.007,,0.249299,-89.1268,,24.9299,-0.0891268,,,,7.85398e-5
Test1,3-Recover,167.947,2.971,0.952,-0.014,,0.242671,-178.254,,24.2671,-0.178254,,,,7.85398e-5
Test1,3-Recover,168.280,2.997,0.926,-0.014,,0.236044,-178.254,,23.6044,-0.178254,,,,7.85398e-5
Test1,3-Recover,168.613,3.023,0.9,-0.014,,0.229416,-178.254,,22.9416,-0.178254,,,,7.85398e-5
Test1,3-Recover,168.947,3.05,0.873,0.007,,0.222534,89.1268,,22.2534,0.0891268,,,,7.85398e-5
Test1,3-Recover,169.280,3.076,0.847,-0.014,,0.215906,-178.254,,21.5906,-0.178254,,,,7.85398e-5
Test1,3-Recover,169.613,3.102,0.821,-0.014,,0.209279,-178.254,,20.9279,-0.178254,,,,7.85398e-5
Test1,3-Recover,169.947,3.128,0.795,-0.007,,0.202651,-89.1268,,20.2651,-0.0891268,,,,7.85398e-5
Test1,3-Recover,170.280,3.154,0.769,0.007,,0.196023,89.1268,,19.6023,0.0891268,,,,7.85398e-5
Test1,3-Recover,170.613,3.18,0.743,-0.000,,0.189396,0,,18.9396,0,,,,7.85398e-5
Test1,3-Recover,170.947,3.207,0.716,0.013,,0.182513,165.521,,18.2513,0.165521,,,,7.85398e-5
Test1,3-Recover,171.280,3.233,0.69,0.013,,0.175886,165.521,,17.5886,0.165521,,,,7.85398e-5
Test1,3-Recover,171.613,3.259,0.664,-0.007,,0.169258,-89.1268,,16.9258,-0.0891268,,,,7.85398e-5
Test1,3-Recover,171.947,3.285,0.638,-0.000,,0.162631,0,,16.2631,0,,,,7.85398e-5
Test1,3-Recover,172.280,3.312,0.611,-0.000,,0.155748,0,,15.5748,0,,,,7.85398e-5
Test1,3-Recover,172.613,3.337,0.586,0.013,,0.149375,165.521,,14.9375,0.165521,,,,7.85398e-5
Test1,3-Recover,172.947,3.364,0.559,-0.000,,0.142493,0,,14.2493,0,,,,7.85398e-5
Test1,3-Recover,173.280,3.39,0.533,0.013,,0.135865,165.521,,13.5865,0.165521,,,,7.85398e-5
Test1,3-Recover,173.613,3.416,0.507,-0.007,,0.129238,-89.1268,,12.9238,-0.0891268,,,,7.85398e-5
Test1,3-Recover,173.947,3.443,0.48,-0.007,,0.122355,-89.1268,,12.2355,-0.0891268,,,,7.85398e-5
Test1,3-Recover,174.280,3.469,0.454,-0.007,,0.115728,-89.1268,,11.5728,-0.0891268,,,,7.85398e-5
Test1,3-Recover,174.613,3.495,0.428,-0.007,,0.1091,-89.1268,,10.91,-0.0891268,,,,7.85398e-5
Test1,3-Recover,174.947,3.521,0.402,-0.000,,0.102473,0,,10.2473,0,,,,7.85398e-5
Test1,3-Recover,175.280,3.547,0.376,-0.014,,0.095845,-178.254,,9.5845,-0.178254,,,,7.85398e-5
Test1,3-Recover,175.613,3.573,0.35,-0.007,,0.0892174,-89.1268,,8.92174,-0.0891268,,,,7.85398e-5
Test1,3-Recover,175.947,3.6,0.323,-0.000,,0.0823349,0,,8.23349,0,,,,7.85398e-5
Test1,3-Recover,176.280,3.626,0.297,-0.000,,0.0757074,0,,7.57074,0,,,,7.85398e-5
Test1,3-Recover,176.613,3.652,0.271,-0.000,,0.0690798,0,,6.90798,0,,,,7.85398e-5
Test1,3-Recover,176.947,3.679,0.244,-0.014,,0.0621973,-178.254,,6.21973,-0.178254,,,,7.85398e-5
Test1,3-Recover,177.280,3.704,0.219,-0.000,,0.0558246,0,,5.58246,0,,,,7.85398e-5
Test1,3-Recover,177.613,3.73,0.193,-0.000,,0.049197,0,,4.9197,0,,,,7.85398e-5
Test1,3-Recover,177.947,3.757,0.166,0.013,,0.0423146,165.521,,4.23146,0.165521,,,,7.85398e-5
Test1,3-Recover,178.280,3.783,0.14,0.007,,0.035687,89.1268,,3.5687,0.0891268,,,,7.85398e-5
Test1,3-Recover,178.613,3.809,0.114,-0.000,,0.0290594,0,,2.90594,0,,,,7.85398e-5
Test1,3-Recover,178.947,3.836,0.087,0.013,,0.0221769,165.521,,2.21769,0.165521,,,,7.85398e-5
Test1,3-Recover,179.280,3.862,0.061,-0.007,,0.0155493,-89.1268,,1.55493,-0.0891268,,,,7.85398e-5
Test1,3-Recover,179.613,3.887,0.036,0.007,,0.00917665,89.1268,,0.917665,0.0891268,,,,7.85398e-5
Test1,3-Recover,179.947,3.914,0.009,0.007,,0.00229416,89.1268,,0.229416,0.0891268,,,,7.85398e-5
Test1,3-Recover,180.113,3.923,-0,0.007,,0,89.1268,,0,0.0891268,,,,7.85398e-5