File: data/beta_1-2-1_2.csv
SetName,Cycle,Time_S,Size_mm,Displacement_mm,Force_N,,Strain,Stress(Pascal),,%Strain,Stress(kPa),,,,Area(m^2)
Test1,1-Compress,0.000,5.741,-0,-0.015,,0,-190.986,,0,-0.190986,,,,7.85398e-5
Test1,1-Compress,0.333,5.705,0.036,-0.002,,0.00627068,-25.4648,,0.627068,-0.0254648,,,,7.85398e-5
Test1,1-Compress,0.667,5.665,0.076,-0.002,,0.0132381,-25.4648,,1.32381,-0.0254648,,,,7.85398e-5
Test1,1-Compress,1.000,5.628,0.113,0.005,,0.019683,63.662,,1.9683,0.063662,,,,7.85398e-5
Test1,1-Compress,1.333,5.59,0.151,0.005,,0.026302,63.662,,2.6302,0.063662,,,,7.85398e-5
Test1,1-Compress,1.667,5.551,0.19,0.012,,0.0330953,152.789,,3.30953,0.152789,,,,7.85398e-5
Test1,1-Compress,2.000,5.513,0.228,-0.002,,0.0397143,-25.4648,,3.97143,-0.0254648,,,,7.85398e-5
Test1,1-Compress,2.333,5.475,0.266,0.005,,0.0463334,63.662,,4.63334,0.063662,,,,7.85398e-5
Test1,1-Compress,2.667,5.436,0.305,0.012,,0.0531266,152.789,,5.31266,0.152789,,,,7.85398e-5
Test1,1-Compress,3.000,5.397,0.344,0.005,,0.0599199,63.662,,5.99199,0.063662,,,,7.85398e-5
Test1,1-Compress,3.333,5.36,0.381,0.012,,0.0663647,152.789,,6.63647,0.152789,,,,7.85398e-5
Test1,1-Compress,3.667,5.321,0.42,0.005,,0.073158,63.662,,7.3158,0.063662,,,,7.85398e-5
Test1,1-Compress,4.000,5.283,0.458,-0.002,,0.079777,-25.4648,,7.9777,-0.0254648,,,,7.85398e-5
Test1,1-Compress,4.333,5.245,0.496,-0.002,,0.0863961,-25.4648,,8.63961,-0.0254648,,,,7.85398e-5
Test1,1-Compress,4.667,5.205,0.536,-0.002,,0.0933635,-25.4648,,9.33635,-0.0254648,,,,7.85398e-5
Test1,1-Compress,5.000,5.168,0.573,0.012,,0.0998084,152.789,,9.98084,0.152789,,,,7.85398e-5
Test1,1-Compress,5.333,5.13,0.611,-0.002,,0.106427,-25.4648,,10.6427,-0.0254648,,,,7.85398e-5
Test1,1-Compress,5.667,5.091,0.65,0.005,,0.113221,63.662,,11.3221,0.063662,,,,7.85398e-5
Test1,1-Compress,6.000,5.053,0.688,0.012,,0.11984,152.789,,11.984,0.152789,,,,7.85398e-5
Test1,1-Compress,6.333,5.015,0.726,0.012,,0.126459,152.789,,12.6459,0.152789,,,,7.85398e-5
Test1,1-Compress,6.667,4.976,0.765,0.005,,0.133252,63.662,,13.3252,0.063662,,,,7.85398e-5
Test1,1-Compress,7.000,4.937,0.804,0.005,,0.140045,63.662,,14.0045,0.063662,,,,7.85398e-5
Test1,1-Compress,7.333,4.9,0.841,0.005,,0.14649,63.662,,14.649,0.063662,,,,7.85398e-5
Test1,1-Compress,7.667,4.861,0.88,0.012,,0.153283,152.789,,15.3283,0.152789,,,,7.85398e-5
Test1,1-Compress,8.000,4.823,0.918,-0.002,,0.159902,-25.4648,,15.9902,-0.0254648,,,,7.85398e-5
Test1,1-Compress,8.333,4.785,0.956,0.012,,0.166522,152.789,,16.6522,0.152789,,,,7.85398e-5
Test1,1-Compress,8.667,4.745,0.996,-0.002,,0.173489,-25.4648,,17.3489,-0.0254648,,,,7.85398e-5
Test1,1-Compress,9.000,4.708,1.033,0.012,,0.179934,152.789,,17.9934,0.152789,,,,7.85398e-5
Test1,1-Compress,9.333,4.67,1.071,-0.002,,0.186553,-25.4648,,18.6553,-0.0254648,,,,7.85398e-5
Test1,1-Compress,9.667,4.631,1.11,0.012,,0.193346,152.789,,19.3346,0.152789,,,,7.85398e-5
Test1,1-Compress,10.000,4.593,1.148,0.005,,0.199965,63.662,,19.9965,0.063662,,,,7.85398e-5
Test1,1-Compress,10.333,4.555,1.186,0.005,,0.206584,63.662,,20.6584,0.063662,,,,7.85398e-5
Test1,1-Compress,10.667,4.516,1.225,0.012,,0.213377,152.789,,21.3377,0.152789,,,,7.85398e-5
Test1,1-Compress,11.000,4.477,1.264,-0.002,,0.220171,-25.4648,,22.0171,-0.0254648,,,,7.85398e-5
Test1,1-Compress,11.333,4.44,1.301,-0.002,,0.226616,-25.4648,,22.6616,-0.0254648,,,,7.85398e-5
Test1,1-Compress,11.667,4.401,1.34,0.005,,0.233409,63.662,,23.3409,0.063662,,,,7.85398e-5
Test1,1-Compress,12.000,4.363,1.378,0.005,,0.240028,63.662,,24.0028,0.063662,,,,7.85398e-5
Test1,1-Compress,12.333,4.325,1.416,-0.009,,0.246647,-114.592,,24.6647,-0.114592,,,,7.85398e-5
Test1,1-Compress,12.667,4.285,1.456,-0.009,,0.253614,-114.592,,25.3614,-0.114592,,,,7.85398e-5
Test1,1-Compress,13.000,4.248,1.493,0.005,,0.260059,63.662,,26.0059,0.063662,,,,7.85398e-5
Test1,1-Compress,13.333,4.209,1.532,0.005,,0.266852,63.662,,26.6852,0.063662,,,,7.85398e-5
Test1,1-Compress,13.667,4.171,1.57,0.005,,0.273472,63.662,,27.3472,0.063662,,,,7.85398e-5
Test1,1-Compress,14.000,4.133,1.608,-0.002,,0.280091,-25.4648,,28.0091,-0.0254648,,,,7.85398e-5
Test1,1-Compress,14.333,4.095,1.646,-0.002,,0.28671,-25.4648,,28.671,-0.0254648,,,,7.85398e-5
Test1,1-Compress,14.667,4.056,1.685,0.012,,0.293503,152.789,,29.3503,0.152789,,,,7.85398e-5
Test1,1-Compress,15.000,4.017,1.724,0.012,,0.300296,152.789,,30.0296,0.152789,,,,7.85398e-5
Test1,1-Compress,15.333,3.98,1.761,0.025,,0.306741,318.31,,30.6741,0.31831,,,,7.85398e-5
Test1,1-Compress,15.667,3.941,1.8,0.012,,0.313534,152.789,,31.3534,0.152789,,,,7.85398e-5
Test1,1-Compress,16.000,3.903,1.838,0.025,,0.320153,318.31,,32.0153,0.31831,,,,7.85398e-5
Test1,1-Compress,16.333,3.865,1.876,0.025,,0.326772,318.31,,32.6772,0.31831,,,,7.85398e-5
Test1,1-Compress,16.667,3.825,1.916,0.019,,0.33374,241.916,,33.374,0.241916,,,,7.85398e-5
Test1,1-Compress,17.000,3.787,1.954,0.019,,0.340359,241.916,,34.0359,0.241916,,,,7.85398e-5
Test1,1-Compress,17.333,3.749,1.992,0.025,,0.346978,318.31,,34.6978,0.31831,,,,7.85398e-5
Test1,1-Compress,17.667,3.711,2.03,0.019,,0.353597,241.916,,35.3597,0.241916,,,,7.85398e-5
Test1,1-Compress,18.000,3.673,2.068,0.019,,0.360216,241.916,,36.0216,0.241916,,,,7.85398e-5
Test1,1-Compress,18.333,3.635,2.106,0.012,,0.366835,152.789,,36.6835,0.152789,,,,7.85398e-5
Test1,1-Compress,18.667,3.595,2.146,0.025,,0.373802,318.31,,37.3802,0.31831,,,,7.85398e-5
Test1,1-Compress,19.000,3.557,2.184,0.032,,0.380422,407.437,,38.0422,0.407437,,,,7.85398e-5
Test1,1-Compress,19.333,3.519,2.222,0.019,,0.387041,241.916,,38.7041,0.241916,,,,7.85398e-5
Test1,1-Compress,19.667,3.48,2.261,0.039,,0.393834,496.564,,39.3834,0.496564,,,,7.85398e-5
Test1,1-Compress,20.000,3.443,2.298,0.032,,0.400279,407.437,,40.0279,0.407437,,,,7.85398e-5
Test1,1-Compress,20.333,3.404,2.337,0.039,,0.407072,496.564,,40.7072,0.496564,,,,7.85398e-5
Test1,1-Compress,20.667,3.365,2.376,0.032,,0.413865,407.437,,41.3865,0.407437,,,,7.85398e-5
Test1,1-Compress,21.000,3.327,2.414,0.032,,0.420484,407.437,,42.0484,0.407437,,,,7.85398e-5
Test1,1-Compress,21.333,3.289,2.452,0.039,,0.427103,496.564,,42.7103,0.496564,,,,7.85398e-5
Test1,1-Compress,21.667,3.251,2.49,0.046,,0.433722,585.69,,43.3722,0.58569,,,,7.85398e-5
Test1,1-Compress,22.000,3.212,2.529,0.046,,0.440516,585.69,,44.0516,0.58569,,,,7.85398e-5
Test1,1-Compress,22.333,3.175,2.566,0.046,,0.44696,585.69,,44.696,0.58569,,,,7.85398e-5
Test1,1-Compress,22.667,3.135,2.606,0.046,,0.453928,585.69,,45.3928,0.58569,,,,7.85398e-5
Test1,1-Compress,23.000,3.097,2.644,0.046,,0.460547,585.69,,46.0547,0.58569,,,,7.85398e-5
Test1,1-Compress,23.333,3.059,2.682,0.053,,0.467166,674.817,,46.7166,0.674817,,,,7.85398e-5
Test1,1-Compress,23.667,3.02,2.721,0.046,,0.473959,585.69,,47.3959,0.58569,,,,7.85398e-5
Test1,1-Compress,24.000,2.983,2.758,0.053,,0.480404,674.817,,48.0404,0.674817,,,,7.85398e-5
Test1,1-Compress,24.333,2.944,2.797,0.039,,0.487197,496.564,,48.7197,0.496564,,,,7.85398e-5
Test1,1-Compress,24.667,2.905,2.836,0.039,,0.493991,496.564,,49.3991,0.496564,,,,7.85398e-5
Test1,1-Compress,25.000,2.867,2.874,0.039,,0.50061,496.564,,50.061,0.496564,,,,7.85398e-5
Test1,1-Compress,25.333,2.829,2.912,0.039,,0.507229,496.564,,50.7229,0.496564,,,,7.85398e-5
Test1,1-Compress,25.667,2.79,2.951,0.039,,0.514022,496.564,,51.4022,0.496564,,,,7.85398e-5
Test1,1-Compress,26.000,2.752,2.989,0.039,,0.520641,496.564,,52.0641,0.496564,,,,7.85398e-5
Test1,1-Compress,26.333,2.715,3.026,0.039,,0.527086,496.564,,52.7086,0.496564,,,,7.85398e-5
Test1,1-Compress,26.667,2.675,3.066,0.039,,0.534053,496.564,,53.4053,0.496564,,,,7.85398e-5
Test1,1-Compress,27.000,2.637,3.104,0.039,,0.540672,496.564,,54.0672,0.496564,,,,7.85398e-5
Test1,1-Compress,27.333,2.599,3.142,0.039,,0.547291,496.564,,54.7291,0.496564,,,,7.85398e-5
Test1,1-Compress,27.667,2.56,3.181,0.039,,0.554085,496.564,,55.4085,0.496564,,,,7.85398e-5
Test1,1-Compress,28.000,2.523,3.218,0.039,,0.56053,496.564,,56.053,0.496564,,,,7.85398e-5
Test1,1-Compress,28.333,2.484,3.257,0.039,,0.567323,496.564,,56.7323,0.496564,,,,7.85398e-5
Test1,1-Compress,28.667,2.445,3.296,0.046,,0.574116,585.69,,57.4116,0.58569,,,,7.85398e-5
Test1,1-Compress,29.000,2.407,3.334,0.046,,0.580735,585.69,,58.0735,0.58569,,,,7.85398e-5
Test1,1-Compress,29.333,2.369,3.372,0.046,,0.587354,585.69,,58.7354,0.58569,,,,7.85398e-5
Test1,1-Compress,29.667,2.33,3.411,0.046,,0.594147,585.69,,59.4147,0.58569,,,,7.85398e-5
Test1,1-Compress,30.000,2.296,3.445,0.053,,0.60007,674.817,,60.007,0.674817,,,,7.85398e-5
Test1,1-Recover,30.333,2.33,3.411,0.053,,0.594147,674.817,,59.4147,0.674817,,,,7.85398e-5
Test1,1-Recover,30.667,2.369,3.372,0.053,,0.587354,674.817,,58.7354,0.674817,,,,7.85398e-5
Test1,1-Recover,31.000,2.407,3.334,0.053,,0.580735,674.817,,58.0735,0.674817,,,,7.85398e-5
Test1,1-Recover,31.333,2.445,3.296,0.046,,0.574116,585.69,,57.4116,0.58569,,,,7.85398e-5
Test1,1-Recover,31.667,2.484,3.257,0.046,,0.567323,585.69,,56.7323,0.58569,,,,7.85398e-5
Test1,1-Recover,32.000,2.523,3.218,0.046,,0.56053,585.69,,56.053,0.58569,,,,7.85398e-5
Test1,1-Recover,32.333,2.56,3.181,0.046,,0.554085,585.69,,55.4085,0.58569,,,,7.85398e-5
Test1,1-Recover,32.667,2.599,3.142,0.039,,0.547291,496.564,,54.7291,0.496564,,,,7.85398e-5
Test1,1-Recover,33.000,2.637,3.104,0.039,,0.540672,496.564,,54.0672,0.496564,,,,7.85398e-5
Test1,1-Recover,33.333,2.675,3.066,0.039,,0.534053,496.564,,53.4053,0.496564,,,,7.85398e-5
Test1,1-Recover,33.667,2.715,3.026,0.039,,0.527086,496.564,,52.7086,0.496564,,,,7.85398e-5
Test1,1-Recover,34.000,2.752,2.989,0.039,,0.520641,496.564,,52.0641,0.496564,,,,7.85398e-5
Test1,1-Recover,34.333,2.79,2.951,0.039,,0.514022,496.564,,51.4022,0.496564,,,,7.85398e-5
Test1,1-Recover,34.667,2.829,2.912,0.039,,0.507229,496.564,,50.7229,0.496564,,,,7.85398e-5
Test1,1-Recover,35.000,2.867,2.874,0.039,,0.50061,496.564,,50.061,0.496564,,,,7.85398e-5
Test1,1-Recover,35.333,2.905,2.836,0.039,,0.493991,496.564,,49.3991,0.496564,,,,7.85398e-5
Test1,1-Recover,35.667,2.944,2.797,0.032,,0.487197,407.437,,48.7197,0.407437,,,,7.85398e-5
Test1,1-Recover,36.000,2.983,2.758,0.039,,0.480404,496.564,,48.0404,0.496564,,,,7.85398e-5
Test1,1-Recover,36.333,3.02,2.721,0.012,,0.473959,152.789,,47.3959,0.152789,,,,7.85398e-5
Test1,1-Recover,36.667,3.059,2.682,0.005,,0.467166,63.662,,46.7166,0.063662,,,,7.85398e-5
Test1,1-Recover,37.000,3.097,2.644,0.005,,0.460547,63.662,,46.0547,0.063662,,,,7.85398e-5
Test1,1-Recover,37.333,3.135,2.606,0.025,,0.453928,318.31,,45.3928,0.31831,,,,7.85398e-5
Test1,1-Recover,37.667,3.175,2.566,0.012,,0.44696,152.789,,44.696,0.152789,,,,7.85398e-5
Test1,1-Recover,38.000,3.212,2.529,0.005,,0.440516,63.662,,44.0516,0.063662,,,,7.85398e-5
Test1,1-Recover,38.333,3.251,2.49,0.025,,0.433722,318.31,,43.3722,0.31831,,,,7.85398e-5
Test1,1-Recover,38.667,3.289,2.452,0.025,,0.427103,318.31,,42.7103,0.31831,,,,7.85398e-5
Test1,1-Recover,39.000,3.328,2.413,0.012,,0.42031,152.789,,42.031,0.152789,,,,7.85398e-5
Test1,1-Recover,39.333,3.365,2.376,0.019,,0.413865,241.916,,41.3865,0.241916,,,,7.85398e-5
Test1,1-Recover,39.667,3.404,2.337,0.025,,0.407072,318.31,,40.7072,0.31831,,,,7.85398e-5
Test1,1-Recover,40.000,3.443,2.298,0.025,,0.400279,318.31,,40.0279,0.31831,,,,7.85398e-5
Test1,1-Recover,40.333,3.48,2.261,0.019,,0.393834,241.916,,39.3834,0.241916,,,,7.85398e-5
Test1,1-Recover,40.667,3.52,2.221,0.019,,0.386866,241.916,,38.6866,0.241916,,,,7.85398e-5
Test1,1-Recover,41.000,3.557,2.184,0.019,,0.380422,241.916,,38.0422,0.241916,,,,7.85398e-5
Test1,1-Recover,41.333,3.596,2.145,0.012,,0.373628,152.789,,37.3628,0.152789,,,,7.85398e-5
Test1,1-Recover,41.667,3.635,2.106,0.005,,0.366835,63.662,,36.6835,0.063662,,,,7.85398e-5
Test1,1-Recover,42.000,3.672,2.069,0.005,,0.36039,63.662,,36.039,0.063662,,,,7.85398e-5
Test1,1-Recover,42.333,3.711,2.03,-0.002,,0.353597,-25.4648,,35.3597,-0.0254648,,,,7.85398e-5
Test1,1-Recover,42.667,3.749,1.992,-0.002,,0.346978,-25.4648,,34.6978,-0.0254648,,,,7.85398e-5
Test1,1-Recover,43.000,3.788,1.953,-0.002,,0.340185,-25.4648,,34.0185,-0.0254648,,,,7.85398e-5
Test1,1-Recover,43.333,3.825,1.916,0.005,,0.33374,63.662,,33.374,0.063662,,,,7.85398e-5
Test1,1-Recover,43.667,3.864,1.877,-0.009,,0.326947,-114.592,,32.6947,-0.114592,,,,7.85398e-5
Test1,1-Recover,44.000,3.903,1.838,-0.002,,0.320153,-25.4648,,32.0153,-0.0254648,,,,7.85398e-5
Test1,1-Recover,44.333,3.94,1.801,-0.009,,0.313708,-114.592,,31.3708,-0.114592,,,,7.85398e-5
Test1,1-Recover,44.667,3.98,1.761,0.005,,0.306741,63.662,,30.6741,0.063662,,,,7.85398e-5
Test1,1-Recover,45.000,4.017,1.724,-0.002,,0.300296,-25.4648,,30.0296,-0.0254648,,,,7.85398e-5
Test1,1-Recover,45.333,4.056,1.685,0.005,,0.293503,63.662,,29.3503,0.063662,,,,7.85398e-5
Test1,1-Recover,45.667,4.095,1.646,0.005,,0.28671,63.662,,28.671,0.063662,,,,7.85398e-5
Test1,1-Recover,46.000,4.133,1.608,-0.002,,0.280091,-25.4648,,28.0091,-0.0254648,,,,7.85398e-5
Test1,1-Recover,46.333,4.171,1.57,-0.002,,0.273472,-25.4648,,27.3472,-0.0254648,,,,7.85398e-5
Test1,1-Recover,46.667,4.209,1.532,0.005,,0.266852,63.662,,26.6852,0.063662,,,,7.85398e-5
Test1,1-Recover,47.000,4.248,1.493,0.012,,0.260059,152.789,,26.0059,0.152789,,,,7.85398e-5
Test1,1-Recover,47.333,4.285,1.456,0.012,,0.253614,152.789,,25.3614,0.152789,,,,7.85398e-5
Test1,1-Recover,47.667,4.325,1.416,0.005,,0.246647,63.662,,24.6647,0.063662,,,,7.85398e-5
Test1,1-Recover,48.000,4.363,1.378,0.012,,0.240028,152.789,,24.0028,0.152789,,,,7.85398e-5
Test1,1-Recover,48.333,4.401,1.34,0.005,,0.233409,63.662,,23.3409,0.063662,,,,7.85398e-5
Test1,1-Recover,48.667,4.44,1.301,0.005,,0.226616,63.662,,22.6616,0.063662,,,,7.85398e-5
Test1,1-Recover,49.000,4.477,1.264,0.005,,0.220171,63.662,,22.0171,0.063662,,,,7.85398e-5
Test1,1-Recover,49.333,4.516,1.225,0.012,,0.213377,152.789,,21.3377,0.152789,,,,7.85398e-5
Test1,1-Recover,49.667,4.555,1.186,-0.002,,0.206584,-25.4648,,20.6584,-0.0254648,,,,7.85398e-5
Test1,1-Recover,50.000,4.593,1.148,-0.002,,0.199965,-25.4648,,19.9965,-0.0254648,,,,7.85398e-5
Test1,1-Recover,50.333,4.631,1.11,0.012,,0.193346,152.789,,19.3346,0.152789,,,,7.85398e-5
Test1,1-Recover,50.667,4.67,1.071,-0.002,,0.186553,-25.4648,,18.6553,-0.0254648,,,,7.85398e-5
Test1,1-Recover,51.000,4.708,1.033,-0.002,,0.179934,-25.4648,,17.9934,-0.0254648,,,,7.85398e-5
Test1,1-Recover,51.333,4.745,0.996,0.005,,0.173489,63.662,,17.3489,0.063662,,,,7.85398e-5
Test1,1-Recover,51.667,4.785,0.956,-0.002,,0.166522,-25.4648,,16.6522,-0.0254648,,,,7.85398e-5
Test1,1-Recover,52.000,4.823,0.918,0.019,,0.159902,241.916,,15.9902,0.241916,,,,7.85398e-5
Test1,1-Recover,52.333,4.861,0.88,-0.002,,0.153283,-25.4648,,15.3283,-0.0254648,,,,7.85398e-5
Test1,1-Recover,52.667,4.9,0.841,0.012,,0.14649,152.789,,14.649,0.152789,,,,7.85398e-5
Test1,1-Recover,53.000,4.937,0.804,-0.009,,0.140045,-114.592,,14.0045,-0.114592,,,,7.85398e-5
Test1,1-Recover,53.333,4.976,0.765,0.012,,0.133252,152.789,,13.3252,0.152789,,,,7.85398e-5
Test1,1-Recover,53.667,5.015,0.726,-0.002,,0.126459,-25.4648,,12.6459,-0.0254648,,,,7.85398e-5
Test1,1-Recover,54.000,5.053,0.688,0.005,,0.11984,63.662,,11.984,0.063662,,,,7.85398e-5
Test1,1-Recover,54.333,5.091,0.65,0.012,,0.113221,152.789,,11.3221,0.152789,,,,7.85398e-5
Test1,1-Recover,54.667,5.13,0.611,0.019,,0.106427,241.916,,10.6427,0.241916,,,,7.85398e-5
Test1,1-Recover,55.000,5.168,0.573,0.005,,0.0998084,63.662,,9.98084,0.063662,,,,7.85398e-5
Test1,1-Recover,55.333,5.205,0.536,-0.002,,0.0933635,-25.4648,,9.33635,-0.0254648,,,,7.85398e-5
Test1,1-Recover,55.667,5.245,0.496,0.005,,0.0863961,63.662,,8.63961,0.063662,,,,7.85398e-5
Test1,1-Recover,56.000,5.283,0.458,0.012,,0.079777,152.789,,7.9777,0.152789,,,,7.85398e-5
Test1,1-Recover,56.333,5.321,0.42,0.012,,0.073158,152.789,,7.3158,0.152789,,,,7.85398e-5
Test1,1-Recover,56.667,5.36,0.381,-0.002,,0.0663647,-25.4648,,6.63647,-0.0254648,,,,7.85398e-5
Test1,1-Recover,57.000,5.397,0.344,-0.009,,0.0599199,-114.592,,5.99199,-0.114592,,,,7.85398e-5
Test1,1-Recover,57.333,5.436,0.305,0.005,,0.0531266,63.662,,5.31266,0.063662,,,,7.85398e-5
Test1,1-Recover,57.667,5.475,0.266,-0.002,,0.0463334,-25.4648,,4.63334,-0.0254648,,,,7.85398e-5
Test1,1-Recover,58.000,5.513,0.228,0.019,,0.0397143,241.916,,3.97143,0.241916,,,,7.85398e-5
Test1,1-Recover,58.333,5.551,0.19,0.005,,0.0330953,63.662,,3.30953,0.063662,,,,7.85398e-5
Test1,1-Recover,58.667,5.59,0.151,-0.009,,0.026302,-114.592,,2.6302,-0.114592,,,,7.85398e-5
Test1,1-Recover,59.000,5.628,0.113,0.012,,0.019683,152.789,,1.9683,0.152789,,,,7.85398e-5
Test1,1-Recover,59.333,5.665,0.076,0.012,,0.0132381,152.789,,1.32381,0.152789,,,,7.85398e-5
Test1,1-Recover,59.667,5.705,0.036,0.019,,0.00627068,241.916,,0.627068,0.241916,,,,7.85398e-5
Test1,1-Recover,60.000,5.741,-0,0.019,,0,241.916,,0,0.241916,,,,7.85398e-5
Test1,2-Compress,60.317,5.71,0.031,-0.002,,0.00539976,-25.4648,,0.539976,-0.0254648,,,,7.85398e-5
Test1,2-Compress,60.650,5.672,0.069,0.019,,0.0120188,241.916,,1.20188,0.241916,,,,7.85398e-5
Test1,2-Compress,60.983,5.634,0.107,0.005,,0.0186379,63.662,,1.86379,0.063662,,,,7.85398e-5
Test1,2-Compress,61.317,5.595,0.146,0.012,,0.0254311,152.789,,2.54311,0.152789,,,,7.85398e-5
Test1,2-Compress,61.650,5.557,0.184,0.012,,0.0320502,152.789,,3.20502,0.152789,,,,7.85398e-5
Test1,2-Compress,61.983,5.519,0.222,0.012,,0.0386692,152.789,,3.86692,0.152789,,,,7.85398e-5
Test1,2-Compress,62.317,5.48,0.261,0.019,,0.0454625,241.916,,4.54625,0.241916,,,,7.85398e-5
Test1,2-Compress,62.650,5.442,0.299,-0.002,,0.0520815,-25.4648,,5.20815,-0.0254648,,,,7.85398e-5
Test1,2-Compress,62.983,5.404,0.337,0.012,,0.0587006,152.789,,5.87006,0.152789,,,,7.85398e-5
Test1,2-Compress,63.317,5.365,0.376,0.025,,0.0654938,318.31,,6.54938,0.31831,,,,7.85398e-5
Test1,2-Compress,63.650,5.327,0.414,0.019,,0.0721129,241.916,,7.21129,0.241916,,,,7.85398e-5
Test1,2-Compress,63.983,5.289,0.452,0.012,,0.0787319,152.789,,7.87319,0.152789,,,,7.85398e-5
Test1,2-Compress,64.317,5.25,0.491,0.005,,0.0855252,63.662,,8.55252,0.063662,,,,7.85398e-5
Test1,2-Compress,64.650,5.212,0.529,-0.002,,0.0921442,-25.4648,,9.21442,-0.0254648,,,,7.85398e-5
Test1,2-Compress,64.983,5.174,0.567,-0.009,,0.0987633,-114.592,,9.87633,-0.114592,,,,7.85398e-5
Test1,2-Compress,65.317,5.135,0.606,-0.002,,0.105557,-25.4648,,10.5557,-0.0254648,,,,7.85398e-5
Test1,2-Compress,65.650,5.097,0.644,0.019,,0.112176,241.916,,11.2176,0.241916,,,,7.85398e-5
Test1,2-Compress,65.983,5.059,0.682,0.005,,0.118795,63.662,,11.8795,0.063662,,,,7.85398e-5
Test1,2-Compress,66.317,5.02,0.721,0.019,,0.125588,241.916,,12.5588,0.241916,,,,7.85398e-5
Test1,2-Compress,66.650,4.982,0.759,-0.002,,0.132207,-25.4648,,13.2207,-0.0254648,,,,7.85398e-5
Test1,2-Compress,66.983,4.944,0.797,0.005,,0.138826,63.662,,13.8826,0.063662,,,,7.85398e-5
Test1,2-Compress,67.317,4.905,0.836,0.005,,0.145619,63.662,,14.5619,0.063662,,,,7.85398e-5
Test1,2-Compress,67.650,4.867,0.874,0.005,,0.152238,63.662,,15.2238,0.063662,,,,7.85398e-5
Test1,2-Compress,67.983,4.829,0.912,0.005,,0.158857,63.662,,15.8857,0.063662,,,,7.85398e-5
Test1,2-Compress,68.317,4.79,0.951,-0.002,,0.165651,-25.4648,,16.5651,-0.0254648,,,,7.85398e-5
Test1,2-Compress,68.650,4.752,0.989,-0.009,,0.17227,-114.592,,17.227,-0.114592,,,,7.85398e-5
Test1,2-Compress,68.983,4.714,1.027,-0.002,,0.178889,-25.4648,,17.8889,-0.0254648,,,,7.85398e-5
Test1,2-Compress,69.317,4.675,1.066,0.005,,0.185682,63.662,,18.5682,0.063662,,,,7.85398e-5
Test1,2-Compress,69.650,4.637,1.104,0.012,,0.192301,152.789,,19.2301,0.152789,,,,7.85398e-5
Test1,2-Compress,69.983,4.599,1.142,0.005,,0.19892,63.662,,19.892,0.063662,,,,7.85398e-5
Test1,2-Compress,70.317,4.56,1.181,0.012,,0.205713,152.789,,20.5713,0.152789,,,,7.85398e-5
Test1,2-Compress,70.650,4.522,1.219,0.019,,0.212332,241.916,,21.2332,0.241916,,,,7.85398e-5
Test1,2-Compress,70.983,4.484,1.257,0.012,,0.218951,152.789,,21.8951,0.152789,,,,7.85398e-5
Test1,2-Compress,71.317,4.445,1.296,0.019,,0.225745,241.916,,22.5745,0.241916,,,,7.85398e-5
Test1,2-Compress,71.650,4.407,1.334,0.012,,0.232364,152.789,,23.2364,0.152789,,,,7.85398e-5
Test1,2-Compress,71.983,4.369,1.372,-0.002,,0.238983,-25.4648,,23.8983,-0.0254648,,,,7.85398e-5
Test1,2-Compress,72.317,4.33,1.411,0.019,,0.245776,241.916,,24.5776,0.241916,,,,7.85398e-5
Test1,2-Compress,72.650,4.292,1.449,0.019,,0.252395,241.916,,25.2395,0.241916,,,,7.85398e-5
Test1,2-Compress,72.983,4.254,1.487,0.012,,0.259014,152.789,,25.9014,0.152789,,,,7.85398e-5
Test1,2-Compress,73.317,4.215,1.526,-0.002,,0.265807,-25.4648,,26.5807,-0.0254648,,,,7.85398e-5
Test1,2-Compress,73.650,4.176,1.565,0.012,,0.272601,152.789,,27.2601,0.152789,,,,7.85398e-5
Test1,2-Compress,73.983,4.139,1.602,0.005,,0.279045,63.662,,27.9045,0.063662,,,,7.85398e-5
Test1,2-Compress,74.317,4.1,1.641,-0.002,,0.285839,-25.4648,,28.5839,-0.0254648,,,,7.85398e-5
Test1,2-Compress,74.650,4.062,1.679,0.012,,0.292458,152.789,,29.2458,0.152789,,,,7.85398e-5
Test1,2-Compress,74.983,4.024,1.717,0.005,,0.299077,63.662,,29.9077,0.063662,,,,7.85398e-5
Test1,2-Compress,75.317,3.984,1.757,0.005,,0.306044,63.662,,30.6044,0.063662,,,,7.85398e-5
Test1,2-Compress,75.650,3.947,1.794,-0.002,,0.312489,-25.4648,,31.2489,-0.0254648,,,,7.85398e-5
Test1,2-Compress,75.983,3.909,1.832,-0.002,,0.319108,-25.4648,,31.9108,-0.0254648,,,,7.85398e-5
Test1,2-Compress,76.317,3.87,1.871,-0.009,,0.325901,-114.592,,32.5901,-0.114592,,,,7.85398e-5
Test1,2-Compress,76.650,3.832,1.909,0.005,,0.33252,63.662,,33.252,0.063662,,,,7.85398e-5
Test1,2-Compress,76.983,3.794,1.947,-0.002,,0.33914,-25.4648,,33.914,-0.0254648,,,,7.85398e-5
Test1,2-Compress,77.317,3.755,1.986,-0.009,,0.345933,-114.592,,34.5933,-0.114592,,,,7.85398e-5
Test1,2-Compress,77.650,3.716,2.025,-0.009,,0.352726,-114.592,,35.2726,-0.114592,,,,7.85398e-5
Test1,2-Compress,77.983,3.679,2.062,0.005,,0.359171,63.662,,35.9171,0.063662,,,,7.85398e-5
Test1,2-Compress,78.317,3.64,2.101,0.012,,0.365964,152.789,,36.5964,0.152789,,,,7.85398e-5
Test1,2-Compress,78.650,3.602,2.139,-0.002,,0.372583,-25.4648,,37.2583,-0.0254648,,,,7.85398e-5
Test1,2-Compress,78.983,3.564,2.177,0.012,,0.379202,152.789,,37.9202,0.152789,,,,7.85398e-5
Test1,2-Compress,79.317,3.524,2.217,0.025,,0.38617,318.31,,38.617,0.31831,,,,7.85398e-5
Test1,2-Compress,79.650,3.487,2.254,0.025,,0.392615,318.31,,39.2615,0.31831,,,,7.85398e-5
Test1,2-Compress,79.983,3.449,2.292,0.039,,0.399234,496.564,,39.9234,0.496564,,,,7.85398e-5
Test1,2-Compress,80.317,3.41,2.331,0.032,,0.406027,407.437,,40.6027,0.407437,,,,7.85398e-5
Test1,2-Compress,80.650,3.372,2.369,0.025,,0.412646,318.31,,41.2646,0.31831,,,,7.85398e-5
Test1,2-Compress,80.983,3.334,2.407,0.032,,0.419265,407.437,,41.9265,0.407437,,,,7.85398e-5
Test1,2-Compress,81.317,3.295,2.446,0.039,,0.426058,496.564,,42.6058,0.496564,,,,7.85398e-5
Test1,2-Compress,81.650,3.256,2.485,0.039,,0.432851,496.564,,43.2851,0.496564,,,,7.85398e-5
Test1,2-Compress,81.983,3.219,2.522,0.039,,0.439296,496.564,,43.9296,0.496564,,,,7.85398e-5
Test1,2-Compress,82.317,3.18,2.561,0.039,,0.44609,496.564,,44.609,0.496564,,,,7.85398e-5
Test1,2-Compress,82.650,3.142,2.599,0.039,,0.452709,496.564,,45.2709,0.496564,,,,7.85398e-5
Test1,2-Compress,82.983,3.104,2.637,0.039,,0.459328,496.564,,45.9328,0.496564,,,,7.85398e-5
Test1,2-Compress,83.317,3.064,2.677,0.039,,0.466295,496.564,,46.6295,0.496564,,,,7.85398e-5
Test1,2-Compress,83.650,3.027,2.714,0.039,,0.47274,496.564,,47.274,0.496564,,,,7.85398e-5
Test1,2-Compress,83.983,2.988,2.753,0.039,,0.479533,496.564,,47.9533,0.496564,,,,7.85398e-5
Test1,2-Compress,84.317,2.95,2.791,0.039,,0.486152,496.564,,48.6152,0.496564,,,,7.85398e-5
Test1,2-Compress,84.650,2.912,2.829,0.039,,0.492771,496.564,,49.2771,0.496564,,,,7.85398e-5
Test1,2-Compress,84.983,2.874,2.867,0.046,,0.49939,585.69,,49.939,0.58569,,,,7.85398e-5
Test1,2-Compress,85.317,2.835,2.906,0.046,,0.506184,585.69,,50.6184,0.58569,,,,7.85398e-5
Test1,2-Compress,85.650,2.796,2.945,0.046,,0.512977,585.69,,51.2977,0.58569,,,,7.85398e-5
Test1,2-Compress,85.983,2.759,2.982,0.046,,0.519422,585.69,,51.9422,0.58569,,,,7.85398e-5
Test1,2-Compress,86.317,2.72,3.021,0.053,,0.526215,674.817,,52.6215,0.674817,,,,7.85398e-5
Test1,2-Compress,86.650,2.682,3.059,0.053,,0.532834,674.817,,53.2834,0.674817,,,,7.85398e-5
Test1,2-Compress,86.983,2.644,3.097,0.053,,0.539453,674.817,,53.9453,0.674817,,,,7.85398e-5
Test1,2-Compress,87.317,2.604,3.137,0.053,,0.54642,674.817,,54.642,0.674817,,,,7.85398e-5
Test1,2-Compress,87.650,2.567,3.174,0.053,,0.552865,674.817,,55.2865,0.674817,,,,7.85398e-5
Test1,2-Compress,87.983,2.528,3.213,0.046,,0.559659,585.69,,55.9659,0.58569,,,,7.85398e-5
Test1,2-Compress,88.317,2.49,3.251,0.046,,0.566278,585.69,,56.6278,0.58569,,,,7.85398e-5
Test1,2-Compress,88.650,2.452,3.289,0.039,,0.572897,496.564,,57.2897,0.496564,,,,7.85398e-5
Test1,2-Compress,88.983,2.414,3.327,0.046,,0.579516,585.69,,57.9516,0.58569,,,,7.85398e-5
Test1,2-Compress,89.317,2.375,3.366,0.059,,0.586309,751.211,,58.6309,0.751211,,,,7.85398e-5
Test1,2-Compress,89.650,2.336,3.405,0.059,,0.593102,751.211,,59.3102,0.751211,,,,7.85398e-5
Test1,2-Compress,89.983,2.299,3.442,0.059,,0.599547,751.211,,59.9547,0.751211,,,,7.85398e-5
Test1,2-Recover,90.303,2.323,3.418,0.046,,0.595367,585.69,,59.5367,0.58569,,,,7.85398e-5
Test1,2-Recover,90.637,2.361,3.38,0.046,,0.588748,585.69,,58.8748,0.58569,,,,7.85398e-5
Test1,2-Recover,90.970,2.4,3.341,0.046,,0.581954,585.69,,58.1954,0.58569,,,,7.85398e-5
Test1,2-Recover,91.303,2.437,3.304,0.046,,0.575509,585.69,,57.5509,0.58569,,,,7.85398e-5
Test1,2-Recover,91.637,2.477,3.264,0.039,,0.568542,496.564,,56.8542,0.496564,,,,7.85398e-5
Test1,2-Recover,91.970,2.515,3.226,0.039,,0.561923,496.564,,56.1923,0.496564,,,,7.85398e-5
Test1,2-Recover,92.303,2.553,3.188,0.039,,0.555304,496.564,,55.5304,0.496564,,,,7.85398e-5
Test1,2-Recover,92.637,2.592,3.149,0.039,,0.548511,496.564,,54.8511,0.496564,,,,7.85398e-5
Test1,2-Recover,92.970,2.629,3.112,0.039,,0.542066,496.564,,54.2066,0.496564,,,,7.85398e-5
Test1,2-Recover,93.303,2.668,3.073,0.046,,0.535273,585.69,,53.5273,0.58569,,,,7.85398e-5
Test1,2-Recover,93.637,2.707,3.034,0.046,,0.528479,585.69,,52.8479,0.58569,,,,7.85398e-5
Test1,2-Recover,93.970,2.745,2.996,0.039,,0.52186,496.564,,52.186,0.496564,,,,7.85398e-5
Test1,2-Recover,94.303,2.783,2.958,0.046,,0.515241,585.69,,51.5241,0.58569,,,,7.85398e-5
Test1,2-Recover,94.637,2.822,2.919,0.046,,0.508448,585.69,,50.8448,0.58569,,,,7.85398e-5
Test1,2-Recover,94.970,2.86,2.881,0.046,,0.501829,585.69,,50.1829,0.58569,,,,7.85398e-5
Test1,2-Recover,95.303,2.897,2.844,0.046,,0.495384,585.69,,49.5384,0.58569,,,,7.85398e-5
Test1,2-Recover,95.637,2.937,2.804,0.046,,0.488417,585.69,,48.8417,0.58569,,,,7.85398e-5
Test1,2-Recover,95.970,2.975,2.766,0.046,,0.481798,585.69,,48.1798,0.58569,,,,7.85398e-5
Test1,2-Recover,96.303,3.013,2.728,0.039,,0.475179,496.564,,47.5179,0.496564,,,,7.85398e-5
Test1,2-Recover,96.637,3.052,2.689,0.032,,0.468385,407.437,,46.8385,0.407437,,,,7.85398e-5
Test1,2-Recover,96.970,3.089,2.652,0.039,,0.46194,496.564,,46.194,0.496564,,,,7.85398e-5
Test1,2-Recover,97.303,3.128,2.613,0.025,,0.455147,318.31,,45.5147,0.31831,,,,7.85398e-5
Test1,2-Recover,97.637,3.167,2.574,0.025,,0.448354,318.31,,44.8354,0.31831,,,,7.85398e-5
Test1,2-Recover,97.970,3.205,2.536,0.032,,0.441735,407.437,,44.1735,0.407437,,,,7.85398e-5
Test1,2-Recover,98.303,3.243,2.498,0.025,,0.435116,318.31,,43.5116,0.31831,,,,7.85398e-5
Test1,2-Recover,98.637,3.282,2.459,0.012,,0.428323,152.789,,42.8323,0.152789,,,,7.85398e-5
Test1,2-Recover,98.970,3.32,2.421,0.019,,0.421704,241.916,,42.1704,0.241916,,,,7.85398e-5
Test1,2-Recover,99.303,3.357,2.384,0.005,,0.415259,63.662,,41.5259,0.063662,,,,7.85398e-5
Test1,2-Recover,99.637,3.397,2.344,0.019,,0.408291,241.916,,40.8291,0.241916,,,,7.85398e-5
Test1,2-Recover,99.970,3.435,2.306,-0.002,,0.401672,-25.4648,,40.1672,-0.0254648,,,,7.85398e-5
Test1,2-Recover,100.303,3.473,2.268,0.005,,0.395053,63.662,,39.5053,0.063662,,,,7.85398e-5
Test1,2-Recover,100.637,3.512,2.229,0.005,,0.38826,63.662,,38.826,0.063662,,,,7.85398e-5
Test1,2-Recover,100.970,3.549,2.192,-0.009,,0.381815,-114.592,,38.1815,-0.114592,,,,7.85398e-5
Test1,2-Recover,101.303,3.588,2.153,-0.002,,0.375022,-25.4648,,37.5022,-0.0254648,,,,7.85398e-5
Test1,2-Recover,101.637,3.627,2.114,0.012,,0.368229,152.789,,36.8229,0.152789,,,,7.85398e-5
Test1,2-Recover,101.970,3.665,2.076,0.005,,0.361609,63.662,,36.1609,0.063662,,,,7.85398e-5
Test1,2-Recover,102.303,3.703,2.038,-0.002,,0.35499,-25.4648,,35.499,-0.0254648,,,,7.85398e-5
Test1,2-Recover,102.637,3.742,1.999,0.012,,0.348197,152.789,,34.8197,0.152789,,,,7.85398e-5
Test1,2-Recover,102.970,3.78,1.961,0.005,,0.341578,63.662,,34.1578,0.063662,,,,7.85398e-5
Test1,2-Recover,103.303,3.817,1.924,0.005,,0.335133,63.662,,33.5133,0.063662,,,,7.85398e-5
Test1,2-Recover,103.637,3.857,1.884,0.005,,0.328166,63.662,,32.8166,0.063662,,,,7.85398e-5
Test1,2-Recover,103.970,3.895,1.846,0.012,,0.321547,152.789,,32.1547,0.152789,,,,7.85398e-5
Test1,2-Recover,104.303,3.933,1.808,0.005,,0.314928,63.662,,31.4928,0.063662,,,,7.85398e-5
Test1,2-Recover,104.637,3.972,1.769,0.019,,0.308134,241.916,,30.8134,0.241916,,,,7.85398e-5
Test1,2-Recover,104.970,4.01,1.731,0.012,,0.301515,152.789,,30.1515,0.152789,,,,7.85398e-5
Test1,2-Recover,105.303,4.048,1.693,0.005,,0.294896,63.662,,29.4896,0.063662,,,,7.85398e-5
Test1,2-Recover,105.637,4.087,1.654,0.019,,0.288103,241.916,,28.8103,0.241916,,,,7.85398e-5
Test1,2-Recover,105.970,4.125,1.616,0.019,,0.281484,241.916,,28.1484,0.241916,,,,7.85398e-5
Test1,2-Recover,106.303,4.163,1.578,0.012,,0.274865,152.789,,27.4865,0.152789,,,,7.85398e-5
Test1,2-Recover,106.637,4.202,1.539,-0.002,,0.268072,-25.4648,,26.8072,-0.0254648,,,,7.85398e-5
Test1,2-Recover,106.970,4.24,1.501,0.012,,0.261453,152.789,,26.1453,0.152789,,,,7.85398e-5
Test1,2-Recover,107.303,4.277,1.464,0.005,,0.255008,63.662,,25.5008,0.063662,,,,7.85398e-5
Test1,2-Recover,107.637,4.317,1.424,0.005,,0.24804,63.662,,24.804,0.063662,,,,7.85398e-5
Test1,2-Recover,107.970,4.355,1.386,-0.002,,0.241421,-25.4648,,24.1421,-0.0254648,,,,7.85398e-5
Test1,2-Recover,108.303,4.393,1.348,-0.002,,0.234802,-25.4648,,23.4802,-0.0254648,,,,7.85398e-5
Test1,2-Recover,108.637,4.432,1.309,0.005,,0.228009,63.662,,22.8009,0.063662,,,,7.85398e-5
Test1,2-Recover,108.970,4.47,1.271,-0.009,,0.22139,-114.592,,22.139,-0.114592,,,,7.85398e-5
Test1,2-Recover,109.303,4.508,1.233,-0.009,,0.214771,-114.592,,21.4771,-0.114592,,,,7.85398e-5
Test1,2-Recover,109.637,4.547,1.194,0.005,,0.207978,63.662,,20.7978,0.063662,,,,7.85398e-5
Test1,2-Recover,109.970,4.585,1.156,0.019,,0.201359,241.916,,20.1359,0.241916,,,,7.85398e-5
Test1,2-Recover,110.303,4.623,1.118,0.012,,0.19474,152.789,,19.474,0.152789,,,,7.85398e-5
Test1,2-Recover,110.637,4.662,1.079,0.005,,0.187946,63.662,,18.7946,0.063662,,,,7.85398e-5
Test1,2-Recover,110.970,4.7,1.041,0.005,,0.181327,63.662,,18.1327,0.063662,,,,7.85398e-5
Test1,2-Recover,111.303,4.738,1.003,0.005,,0.174708,63.662,,17.4708,0.063662,,,,7.85398e-5
Test1,2-Recover,111.637,4.777,0.964,0.012,,0.167915,152.789,,16.7915,0.152789,,,,7.85398e-5
Test1,2-Recover,111.970,4.815,0.926,0.005,,0.161296,63.662,,16.1296,0.063662,,,,7.85398e-5
Test1,2-Recover,112.303,4.853,0.888,0.005,,0.154677,63.662,,15.4677,0.063662,,,,7.85398e-5
Test1,2-Recover,112.637,4.892,0.849,0.005,,0.147884,63.662,,14.7884,0.063662,,,,7.85398e-5
Test1,2-Recover,112.970,4.93,0.811,0.019,,0.141265,241.916,,14.1265,0.241916,,,,7.85398e-5
Test1,2-Recover,113.303,4.968,0.773,-0.002,,0.134646,-25.4648,,13.4646,-0.0254648,,,,7.85398e-5
Test1,2-Recover,113.637,5.007,0.734,0.012,,0.127852,152.789,,12.7852,0.152789,,,,7.85398e-5
Test1,2-Recover,113.970,5.045,0.696,0.012,,0.121233,152.789,,12.1233,0.152789,,,,7.85398e-5
Test1,2-Recover,114.303,5.083,0.658,0.005,,0.114614,63.662,,11.4614,0.063662,,,,7.85398e-5
Test1,2-Recover,114.637,5.122,0.619,0.005,,0.107821,63.662,,10.7821,0.063662,,,,7.85398e-5
Test1,2-Recover,114.970,5.16,0.581,-0.002,,0.101202,-25.4648,,10.1202,-0.0254648,,,,7.85398e-5
Test1,2-Recover,115.303,5.198,0.543,0.005,,0.0945828,63.662,,9.45828,0.063662,,,,7.85398e-5
Test1,2-Recover,115.637,5.237,0.504,0.005,,0.0877896,63.662,,8.77896,0.063662,,,,7.85398e-5
Test1,2-Recover,115.970,5.275,0.466,0.005,,0.0811705,63.662,,8.11705,0.063662,,,,7.85398e-5
Test1,2-Recover,116.303,5.313,0.428,-0.002,,0.0745515,-25.4648,,7.45515,-0.0254648,,,,7.85398e-5
Test1,2-Recover,116.637,5.352,0.389,-0.002,,0.0677582,-25.4648,,6.77582,-0.0254648,,,,7.85398e-5
Test1,2-Recover,116.970,5.39,0.351,0.019,,0.0611392,241.916,,6.11392,0.241916,,,,7.85398e-5
Test1,2-Recover,117.303,5.428,0.313,0.012,,0.0545201,152.789,,5.45201,0.152789,,,,7.85398e-5
Test1,2-Recover,117.637,5.467,0.274,0.019,,0.0477269,241.916,,4.77269,0.241916,,,,7.85398e-5
Test1,2-Recover,117.970,5.505,0.236,0.019,,0.0411078,241.916,,4.11078,0.241916,,,,7.85398e-5
Test1,2-Recover,118.303,5.543,0.198,0.012,,0.0344888,152.789,,3.44888,0.152789,,,,7.85398e-5
Test1,2-Recover,118.637,5.582,0.159,0.005,,0.0276955,63.662,,2.76955,0.063662,,,,7.85398e-5
Test1,2-Recover,118.970,5.62,0.121,0.012,,0.0210765,152.789,,2.10765,0.152789,,,,7.85398e-5
Test1,2-Recover,119.303,5.658,0.083,0.025,,0.0144574,318.31,,1.44574,0.31831,,,,7.85398e-5
Test1,2-Recover,119.637,5.697,0.044,0.005,,0.00766417,63.662,,0.766417,0.063662,,,,7.85398e-5
Test1,2-Recover,119.970,5.735,0.006,0.005,,0.00104511,63.662,,0.104511,0.063662,,,,7.85398e-5
Test1,3-Compress,120.280,5.719,0.022,0.012,,0.00383209,152.789,,0.383209,0.152789,,,,7.85398e-5
Test1,3-Compress,120.613,5.681,0.06,0.012,,0.0104511,152.789,,1.04511,0.152789,,,,7.85398e-5
Test1,3-Compress,120.947,5.642,0.099,0.005,,0.0172444,63.662,,1.72444,0.063662,,,,7.85398e-5
Test1,3-Compress,121.280,5.604,0.137,0.005,,0.0238634,63.662,,2.38634,0.063662,,,,7.85398e-5
Test1,3-Compress,121.613,5.566,0.175,0.019,,0.0304825,241.916,,3.04825,0.241916,,,,7.85398e-5
Test1,3-Compress,121.947,5.527,0.214,0.012,,0.0372757,152.789,,3.72757,0.152789,,,,7.85398e-5
Test1,3-Compress,122.280,5.489,0.252,0.012,,0.0438948,152.789,,4.38948,0.152789,,,,7.85398e-5
Test1,3-Compress,122.613,5.451,0.29,0.005,,0.0505138,63.662,,5.05138,0.063662,,,,7.85398e-5
Test1,3-Compress,122.947,5.412,0.329,-0.002,,0.0573071,-25.4648,,5.73071,-0.0254648,,,,7.85398e-5
Test1,3-Compress,123.280,5.374,0.367,-0.002,,0.0639261,-25.4648,,6.39261,-0.0254648,,,,7.85398e-5
Test1,3-Compress,123.613,5.336,0.405,0.012,,0.0705452,152.789,,7.05452,0.152789,,,,7.85398e-5
Test1,3-Compress,123.947,5.297,0.444,0.005,,0.0773384,63.662,,7.73384,0.063662,,,,7.85398e-5
Test1,3-Compress,124.280,5.259,0.482,-0.002,,0.0839575,-25.4648,,8.39575,-0.0254648,,,,7.85398e-5
Test1,3-Compress,124.613,5.221,0.52,0.019,,0.0905766,241.916,,9.05766,0.241916,,,,7.85398e-5
Test1,3-Compress,124.947,5.182,0.559,0.005,,0.0973698,63.662,,9.73698,0.063662,,,,7.85398e-5
Test1,3-Compress,125.280,5.144,0.597,0.005,,0.103989,63.662,,10.3989,0.063662,,,,7.85398e-5
Test1,3-Compress,125.613,5.106,0.635,0.005,,0.110608,63.662,,11.0608,0.063662,,,,7.85398e-5
Test1,3-Compress,125.947,5.067,0.674,-0.002,,0.117401,-25.4648,,11.7401,-0.0254648,,,,7.85398e-5
Test1,3-Compress,126.280,5.029,0.712,0.012,,0.12402,152.789,,12.402,0.152789,,,,7.85398e-5
Test1,3-Compress,126.613,4.991,0.75,0.005,,0.130639,63.662,,13.0639,0.063662,,,,7.85398e-5
Test1,3-Compress,126.947,4.952,0.789,0.005,,0.137433,63.662,,13.7433,0.063662,,,,7.85398e-5
Test1,3-Compress,127.280,4.914,0.827,-0.002,,0.144052,-25.4648,,14.4052,-0.0254648,,,,7.85398e-5
Test1,3-Compress,127.613,4.876,0.865,0.005,,0.150671,63.662,,15.0671,0.063662,,,,7.85398e-5
Test1,3-Compress,127.947,4.837,0.904,0.012,,0.157464,152.789,,15.7464,0.152789,,,,7.85398e-5
Test1,3-Compress,128.280,4.799,0.942,0.012,,0.164083,152.789,,16.4083,0.152789,,,,7.85398e-5
Test1,3-Compress,128.613,4.761,0.98,0.025,,0.170702,318.31,,17.0702,0.31831,,,,7.85398e-5
Test1,3-Compress,128.947,4.722,1.019,0.019,,0.177495,241.916,,17.7495,0.241916,,,,7.85398e-5
Test1,3-Compress,129.280,4.684,1.057,0.005,,0.184114,63.662,,18.4114,0.063662,,,,7.85398e-5
Test1,3-Compress,129.613,4.646,1.095,0.005,,0.190733,63.662,,19.0733,0.063662,,,,7.85398e-5
Test1,3-Compress,129.947,4.607,1.134,-0.002,,0.197527,-25.4648,,19.7527,-0.0254648,,,,7.85398e-5
Test1,3-Compress,130.280,4.569,1.172,0.019,,0.204146,241.916,,20.4146,0.241916,,,,7.85398e-5
Test1,3-Compress,130.613,4.531,1.21,0.005,,0.210765,63.662,,21.0765,0.063662,,,,7.85398e-5
Test1,3-Compress,130.947,4.492,1.249,0.012,,0.217558,152.789,,21.7558,0.152789,,,,7.85398e-5
Test1,3-Compress,131.280,4.454,1.287,0.005,,0.224177,63.662,,22.4177,0.063662,,,,7.85398e-5
Test1,3-Compress,131.613,4.416,1.325,0.005,,0.230796,63.662,,23.0796,0.063662,,,,7.85398e-5
Test1,3-Compress,131.947,4.377,1.364,-0.002,,0.237589,-25.4648,,23.7589,-0.0254648,,,,7.85398e-5
Test1,3-Compress,132.280,4.339,1.402,0.005,,0.244208,63.662,,24.4208,0.063662,,,,7.85398e-5
Test1,3-Compress,132.613,4.301,1.44,-0.002,,0.250827,-25.4648,,25.0827,-0.0254648,,,,7.85398e-5
Test1,3-Compress,132.947,4.262,1.479,-0.002,,0.257621,-25.4648,,25.7621,-0.0254648,,,,7.85398e-5
Test1,3-Compress,133.280,4.224,1.517,-0.009,,0.26424,-114.592,,26.424,-0.114592,,,,7.85398e-5
Test1,3-Compress,133.613,4.186,1.555,-0.002,,0.270859,-25.4648,,27.0859,-0.0254648,,,,7.85398e-5
Test1,3-Compress,133.947,4.147,1.594,-0.002,,0.277652,-25.4648,,27.7652,-0.0254648,,,,7.85398e-5
Test1,3-Compress,134.280,4.109,1.632,-0.002,,0.284271,-25.4648,,28.4271,-0.0254648,,,,7.85398e-5
Test1,3-Compress,134.613,4.071,1.67,-0.009,,0.29089,-114.592,,29.089,-0.114592,,,,7.85398e-5
Test1,3-Compress,134.947,4.032,1.709,-0.009,,0.297683,-114.592,,29.7683,-0.114592,,,,7.85398e-5
Test1,3-Compress,135.280,3.994,1.747,-0.002,,0.304302,-25.4648,,30.4302,-0.0254648,,,,7.85398e-5
Test1,3-Compress,135.613,3.956,1.785,0.005,,0.310921,63.662,,31.0921,0.063662,,,,7.85398e-5
Test1,3-Compress,135.947,3.917,1.824,0.019,,0.317715,241.916,,31.7715,0.241916,,,,7.85398e-5
Test1,3-Compress,136.280,3.879,1.862,0.019,,0.324334,241.916,,32.4334,0.241916,,,,7.85398e-5
Test1,3-Compress,136.613,3.841,1.9,0.025,,0.330953,318.31,,33.0953,0.31831,,,,7.85398e-5
Test1,3-Compress,136.947,3.802,1.939,0.025,,0.337746,318.31,,33.7746,0.31831,,,,7.85398e-5
Test1,3-Compress,137.280,3.764,1.977,0.019,,0.344365,241.916,,34.4365,0.241916,,,,7.85398e-5
Test1,3-Compress,137.613,3.726,2.015,0.019,,0.350984,241.916,,35.0984,0.241916,,,,7.85398e-5
Test1,3-Compress,137.947,3.687,2.054,0.019,,0.357777,241.916,,35.7777,0.241916,,,,7.85398e-5
Test1,3-Compress,138.280,3.648,2.093,0.025,,0.364571,318.31,,36.4571,0.31831,,,,7.85398e-5
Test1,3-Compress,138.613,3.611,2.13,0.012,,0.371016,152.789,,37.1016,0.152789,,,,7.85398e-5
Test1,3-Compress,138.947,3.572,2.169,0.012,,0.377809,152.789,,37.7809,0.152789,,,,7.85398e-5
Test1,3-Compress,139.280,3.534,2.207,0.032,,0.384428,407.437,,38.4428,0.407437,,,,7.85398e-5
Test1,3-Compress,139.613,3.496,2.245,0.025,,0.391047,318.31,,39.1047,0.31831,,,,7.85398e-5
Test1,3-Compress,139.947,3.456,2.285,0.019,,0.398014,241.916,,39.8014,0.241916,,,,7.85398e-5
Test1,3-Compress,140.280,3.419,2.322,0.032,,0.404459,407.437,,40.4459,0.407437,,,,7.85398e-5
Test1,3-Compress,140.613,3.381,2.36,0.032,,0.411078,407.437,,41.1078,0.407437,,,,7.85398e-5
Test1,3-Compress,140.947,3.342,2.399,0.032,,0.417871,407.437,,41.7871,0.407437,,,,7.85398e-5
Test1,3-Compress,141.280,3.304,2.437,0.039,,0.424491,496.564,,42.4491,0.496564,,,,7.85398e-5
Test1,3-Compress,141.613,3.266,2.475,0.039,,0.43111,496.564,,43.111,0.496564,,,,7.85398e-5
Test1,3-Compress,141.947,3.227,2.514,0.046,,0.437903,585.69,,43.7903,0.58569,,,,7.85398e-5
Test1,3-Compress,142.280,3.188,2.553,0.039,,0.444696,496.564,,44.4696,0.496564,,,,7.85398e-5
Test1,3-Compress,142.613,3.151,2.59,0.046,,0.451141,585.69,,45.1141,0.58569,,,,7.85398e-5
Test1,3-Compress,142.947,3.112,2.629,0.046,,0.457934,585.69,,45.7934,0.58569,,,,7.85398e-5
Test1,3-Compress,143.280,3.074,2.667,0.046,,0.464553,585.69,,46.4553,0.58569,,,,7.85398e-5
Test1,3-Compress,143.613,3.036,2.705,0.053,,0.471172,674.817,,47.1172,0.674817,,,,7.85398e-5
Test1,3-Compress,143.947,2.996,2.745,0.046,,0.47814,585.69,,47.814,0.58569,,,,7.85398e-5
Test1,3-Compress,144.280,2.959,2.782,0.046,,0.484585,585.69,,48.4585,0.58569,,,,7.85398e-5
Test1,3-Compress,144.613,2.921,2.82,0.039,,0.491204,496.564,,49.1204,0.496564,,,,7.85398e-5
Test1,3-Compress,144.947,2.882,2.859,0.046,,0.497997,585.69,,49.7997,0.58569,,,,7.85398e-5
Test1,3-Compress,145.280,2.844,2.897,0.046,,0.504616,585.69,,50.4616,0.58569,,,,7.85398e-5
Test1,3-Compress,145.613,2.806,2.935,0.046,,0.511235,585.69,,51.1235,0.58569,,,,7.85398e-5
Test1,3-Compress,145.947,2.767,2.974,0.039,,0.518028,496.564,,51.8028,0.496564,,,,7.85398e-5
Test1,3-Compress,146.280,2.728,3.013,0.039,,0.524821,496.564,,52.4821,0.496564,,,,7.85398e-5
Test1,3-Compress,146.613,2.691,3.05,0.039,,0.531266,496.564,,53.1266,0.496564,,,,7.85398e-5
Test1,3-Compress,146.947,2.652,3.089,0.039,,0.53806,496.564,,53.806,0.496564,,,,7.85398e-5
Test1,3-Compress,147.280,2.614,3.127,0.046,,0.544679,585.69,,54.4679,0.58569,,,,7.85398e-5
Test1,3-Compress,147.613,2.576,3.165,0.039,,0.551298,496.564,,55.1298,0.496564,,,,7.85398e-5
Test1,3-Compress,147.947,2.536,3.205,0.046,,0.558265,585.69,,55.8265,0.58569,,,,7.85398e-5
Test1,3-Compress,148.280,2.499,3.242,0.046,,0.56471,585.69,,56.471,0.58569,,,,7.85398e-5
Test1,3-Compress,148.613,2.46,3.281,0.046,,0.571503,585.69,,57.1503,0.58569,,,,7.85398e-5
Test1,3-Compress,148.947,2.422,3.319,0.046,,0.578122,585.69,,57.8122,0.58569,,,,7.85398e-5
Test1,3-Compress,149.280,2.384,3.357,0.046,,0.584741,585.69,,58.4741,0.58569,,,,7.85398e-5
Test1,3-Compress,149.613,2.346,3.395,0.046,,0.59136,585.69,,59.136,0.58569,,,,7.85398e-5
Test1,3-Compress,149.947,2.307,3.434,0.046,,0.598154,585.69,,59.8154,0.58569,,,,7.85398e-5
Test1,3-Recover,150.267,2.315,3.426,0.046,,0.59676,585.69,,59.676,0.58569,,,,7.85398e-5
Test1,3-Recover,150.600,2.352,3.389,0.046,,0.590315,585.69,,59.0315,0.58569,,,,7.85398e-5
Test1,3-Recover,150.933,2.391,3.35,0.046,,0.583522,585.69,,58.3522,0.58569,,,,7.85398e-5
Test1,3-Recover,151.267,2.429,3.312,0.046,,0.576903,585.69,,57.6903,0.58569,,,,7.85398e-5
Test1,3-Recover,151.600,2.467,3.274,0.046,,0.570284,585.69,,57.0284,0.58569,,,,7.85398e-5
Test1,3-Recover,151.933,2.505,3.236,0.053,,0.563665,674.817,,56.3665,0.674817,,,,7.85398e-5
Test1,3-Recover,152.267,2.544,3.197,0.053,,0.556872,674.817,,55.6872,0.674817,,,,7.85398e-5
Test1,3-Recover,152.600,2.583,3.158,0.053,,0.550078,674.817,,55.0078,0.674817,,,,7.85398e-5
Test1,3-Recover,152.933,2.621,3.12,0.053,,0.543459,674.817,,54.3459,0.674817,,,,7.85398e-5
Test1,3-Recover,153.267,2.659,3.082,0.046,,0.53684,585.69,,53.684,0.58569,,,,7.85398e-5
Test1,3-Recover,153.600,2.697,3.044,0.046,,0.530221,585.69,,53.0221,0.58569,,,,7.85398e-5
Test1,3-Recover,153.933,2.735,3.006,0.039,,0.523602,496.564,,52.3602,0.496564,,,,7.85398e-5
Test1,3-Recover,154.267,2.775,2.966,0.039,,0.516635,496.564,,51.6635,0.496564,,,,7.85398e-5
Test1,3-Recover,154.600,2.813,2.928,0.039,,0.510016,496.564,,51.0016,0.496564,,,,7.85398e-5
Test1,3-Recover,154.933,2.851,2.89,0.039,,0.503397,496.564,,50.3397,0.496564,,,,7.85398e-5
Test1,3-Recover,155.267,2.889,2.852,0.039,,0.496778,496.564,,49.6778,0.496564,,,,7.85398e-5
Test1,3-Recover,155.600,2.927,2.814,0.039,,0.490159,496.564,,49.0159,0.496564,,,,7.85398e-5
Test1,3-Recover,155.933,2.965,2.776,0.039,,0.483539,496.564,,48.3539,0.496564,,,,7.85398e-5
Test1,3-Recover,156.267,3.005,2.736,0.032,,0.476572,407.437,,47.6572,0.407437,,,,7.85398e-5
Test1,3-Recover,156.600,3.043,2.698,0.032,,0.469953,407.437,,46.9953,0.407437,,,,7.85398e-5
Test1,3-Recover,156.933,3.081,2.66,0.039,,0.463334,496.564,,46.3334,0.496564,,,,7.85398e-5
Test1,3-Recover,157.267,3.119,2.622,0.019,,0.456715,241.916,,45.6715,0.241916,,,,7.85398e-5
Test1,3-Recover,157.600,3.157,2.584,0.019,,0.450096,241.916,,45.0096,0.241916,,,,7.85398e-5
Test1,3-Recover,157.933,3.195,2.546,0.012,,0.443477,152.789,,44.3477,0.152789,,,,7.85398e-5
Test1,3-Recover,158.267,3.235,2.506,0.032,,0.436509,407.437,,43.6509,0.407437,,,,7.85398e-5
Test1,3-Recover,158.600,3.273,2.468,-0.002,,0.42989,-25.4648,,42.989,-0.0254648,,,,7.85398e-5
Test1,3-Recover,158.933,3.311,2.43,-0.009,,0.423271,-114.592,,42.3271,-0.114592,,,,7.85398e-5
Test1,3-Recover,159.267,3.35,2.391,0.005,,0.416478,63.662,,41.6478,0.063662,,,,7.85398e-5
Test1,3-Recover,159.600,3.387,2.354,0.025,,0.410033,318.31,,41.0033,0.31831,,,,7.85398e-5
Test1,3-Recover,159.933,3.425,2.316,0.025,,0.403414,318.31,,40.3414,0.31831,,,,7.85398e-5
Test1,3-Recover,160.267,3.465,2.276,0.012,,0.396447,152.789,,39.6447,0.152789,,,,7.85398e-5
Test1,3-Recover,160.600,3.503,2.238,0.019,,0.389828,241.916,,38.9828,0.241916,,,,7.85398e-5
Test1,3-Recover,160.933,3.541,2.2,0.019,,0.383209,241.916,,38.3209,0.241916,,,,7.85398e-5
Test1,3-Recover,161.267,3.58,2.161,0.019,,0.376415,241.916,,37.6415,0.241916,,,,7.85398e-5
Test1,3-Recover,161.600,3.617,2.124,0.019,,0.36997,241.916,,36.997,0.241916,,,,7.85398e-5
Test1,3-Recover,161.933,3.656,2.085,0.025,,0.363177,318.31,,36.3177,0.31831,,,,7.85398e-5
Test1,3-Recover,162.267,3.695,2.046,0.005,,0.356384,63.662,,35.6384,0.063662,,,,7.85398e-5
Test1,3-Recover,162.600,3.733,2.008,0.019,,0.349765,241.916,,34.9765,0.241916,,,,7.85398e-5
Test1,3-Recover,162.933,3.771,1.97,0.005,,0.343146,63.662,,34.3146,0.063662,,,,7.85398e-5
Test1,3-Recover,163.267,3.81,1.931,0.005,,0.336353,63.662,,33.6353,0.063662,,,,7.85398e-5
Test1,3-Recover,163.600,3.848,1.893,-0.002,,0.329733,-25.4648,,32.9733,-0.0254648,,,,7.85398e-5
Test1,3-Recover,163.933,3.885,1.856,0.012,,0.323289,152.789,,32.3289,0.152789,,,,7.85398e-5
Test1,3-Recover,164.267,3.925,1.816,0.005,,0.316321,63.662,,31.6321,0.063662,,,,7.85398e-5
Test1,3-Recover,164.600,3.963,1.778,-0.002,,0.309702,-25.4648,,30.9702,-0.0254648,,,,7.85398e-5
Test1,3-Recover,164.933,4.001,1.74,0.005,,0.303083,63.662,,30.3083,0.063662,,,,7.85398e-5
Test1,3-Recover,165.267,4.04,1.701,0.005,,0.29629,63.662,,29.629,0.063662,,,,7.85398e-5
Test1,3-Recover,165.600,4.077,1.664,0.012,,0.289845,152.789,,28.9845,0.152789,,,,7.85398e-5
Test1,3-Recover,165.933,4.116,1.625,0.005,,0.283052,63.662,,28.3052,0.063662,,,,7.85398e-5
Test1,3-Recover,166.267,4.155,1.586,-0.002,,0.276258,-25.4648,,27.6258,-0.0254648,,,,7.85398e-5
Test1,3-Recover,166.600,4.193,1.548,-0.009,,0.269639,-114.592,,26.9639,-0.114592,,,,7.85398e-5
Test1,3-Recover,166.933,4.231,1.51,-0.002,,0.26302,-25.4648,,26.302,-0.0254648,,,,7.85398e-5
Test1,3-Recover,167.267,4.27,1.471,0.012,,0.256227,152.789,,25.6227,0.152789,,,,7.85398e-5
Test1,3-Recover,167.600,4.308,1.433,-0.002,,0.249608,-25.4648,,24.9608,-0.0254648,,,,7.85398e-5
Test1,3-Recover,167.933,4.345,1.396,0.005,,0.243163,63.662,,24.3163,0.063662,,,,7.85398e-5
Test1,3-Recover,168.267,4.385,1.356,0.012,,0.236196,152.789,,23.6196,0.152789,,,,7.85398e-5
Test1,3-Recover,168.600,4.423,1.318,0.005,,0.229577,63.662,,22.9577,0.063662,,,,7.85398e-5
Test1,3-Recover,168.933,4.461,1.28,0.005,,0.222958,63.662,,22.2958,0.063662,,,,7.85398e-5
Test1,3-Recover,169.267,4.5,1.241,0.012,,0.216164,152.789,,21.6164,0.152789,,,,7.85398e-5
Test1,3-Recover,169.600,4.538,1.203,-0.002,,0.209545,-25.4648,,20.9545,-0.0254648,,,,7.85398e-5
Test1,3-Recover,169.933,4.576,1.165,0.005,,0.202926,63.662,,20.2926,0.063662,,,,7.85398e-5
Test1,3-Recover,170.267,4.615,1.126,-0.002,,0.196133,-25.4648,,19.6133,-0.0254648,,,,7.85398e-5
Test1,3-Recover,170.600,4.653,1.088,0.019,,0.189514,241.916,,18.9514,0.241916,,,,7.85398e-5
Test1,3-Recover,170.933,4.691,1.05,0.005,,0.182895,63.662,,18.2895,0.063662,,,,7.85398e-5
Test1,3-Recover,171.267,4.73,1.011,0.012,,0.176102,152.789,,17.6102,0.152789,,,,7.85398e-5
Test1,3-Recover,171.600,4.768,0.973,0.012,,0.169483,152.789,,16.9483,0.152789,,,,7.85398e-5
Test1,3-Recover,171.933,4.805,0.936,0.005,,0.163038,63.662,,16.3038,0.063662,,,,7.85398e-5
Test1,3-Recover,172.267,4.845,0.896,-0.009,,0.15607,-114.592,,15.607,-0.114592,,,,7.85398e-5
Test1,3-Recover,172.600,4.883,0.858,-0.009,,0.149451,-114.592,,14.9451,-0.114592,,,,7.85398e-5
Test1,3-Recover,172.933,4.921,0.82,-0.002,,0.142832,-25.4648,,14.2832,-0.0254648,,,,7.85398e-5
Test1,3-Recover,173.267,4.96,0.781,-0.002,,0.136039,-25.4648,,13.6039,-0.0254648,,,,7.85398e-5
Test1,3-Recover,173.600,4.998,0.743,-0.009,,0.12942,-114.592,,12.942,-0.114592,,,,7.85398e-5
Test1,3-Recover,173.933,5.036,0.705,-0.009,,0.122801,-114.592,,12.2801,-0.114592,,,,7.85398e-5
Test1,3-Recover,174.267,5.075,0.666,0.005,,0.116008,63.662,,11.6008,0.063662,,,,7.85398e-5
Test1,3-Recover,174.600,5.113,0.628,0.012,,0.109389,152.789,,10.9389,0.152789,,,,7.85398e-5
Test1,3-Recover,174.933,5.151,0.59,-0.009,,0.10277,-114.592,,10.277,-0.114592,,,,7.85398e-5
Test1,3-Recover,175.267,5.19,0.551,-0.002,,0.0959763,-25.4648,,9.59763,-0.0254648,,,,7.85398e-5
Test1,3-Recover,175.600,5.228,0.513,0.012,,0.0893573,152.789,,8.93573,0.152789,,,,7.85398e-5
Test1,3-Recover,175.933,5.266,0.475,0.012,,0.0827382,152.789,,8.27382,0.152789,,,,7.85398e-5
Test1,3-Recover,176.267,5.305,0.436,0.012,,0.075945,152.789,,7.5945,0.152789,,,,7.85398e-5
Test1,3-Recover,176.600,5.343,0.398,-0.002,,0.0693259,-25.4648,,6.93259,-0.0254648,,,,7.85398e-5
Test1,3-Recover,176.933,5.381,0.36,0.012,,0.0627068,152.789,,6.27068,0.152789,,,,7.85398e-5
Test1,3-Recover,177.267,5.42,0.321,0.005,,0.0559136,63.662,,5.59136,0.063662,,,,7.85398e-5
Test1,3-Recover,177.600,5.458,0.283,0.005,,0.0492945,63.662,,4.92945,0.063662,,,,7.85398e-5
Test1,3-Recover,177.933,5.496,0.245,-0.002,,0.0426755,-25.4648,,4.26755,-0.0254648,,,,7.85398e-5
Test1,3-Recover,178.267,5.535,0.206,0.005,,0.0358823,63.662,,3.58823,0.063662,,,,7.85398e-5
Test1,3-Recover,178.600,5.573,0.168,-0.002,,0.0292632,-25.4648,,2.92632,-0.0254648,,,,7.85398e-5
Test1,3-Recover,178.933,5.611,0.13,0.012,,0.0226441,152.789,,2.26441,0.152789,,,,7.85398e-5
Test1,3-Recover,179.267,5.65,0.091,0.005,,0.0158509,63.662,,1.58509,0.063662,,,,7.85398e-5
Test1,3-Recover,179.600,5.688,0.053,0.005,,0.00923184,63.662,,0.923184,0.063662,,,,7.85398e-5
Test1,3-Recover,179.933,5.726,0.015,-0.002,,0.00261279,-25.4648,,0.261279,-0.0254648,,,,7.85398e-5
Test1,3-Recover,180.100,5.741,-0,0.005,,0,63.662,,0,0.063662,,,,7.85398e-5