File: data/beta_1-0.25_2.csv
SetName,Cycle,Time_S,Size_mm,Displacement_mm,Force_N,,Strain,Stress(Pascal),,%Strain,Stress(kPa),,,,Area(m^2)
1:0.25 (rep 2),1-Compress,0,3.181,0,0.05,,0,636.62,,0,0.63662,,,,7.85398e-5
1:0.25 (rep 2),1-Compress,0.367,3.158,0.023,0.05,,0.00723043,636.62,,0.723043,0.63662,,,,7.85398e-5
1:0.25 (rep 2),1-Compress,0.733,3.135,0.046,0.05,,0.0144609,636.62,,1.44609,0.63662,,,,7.85398e-5
1:0.25 (rep 2),1-Compress,1.1,3.112,0.069,0.05,,0.0216913,636.62,,2.16913,0.63662,,,,7.85398e-5
1:0.25 (rep 2),1-Compress,1.467,3.088,0.093,0.05,,0.0292361,636.62,,2.92361,0.63662,,,,7.85398e-5
1:0.25 (rep 2),1-Compress,1.833,3.065,0.116,0.05,,0.0364665,636.62,,3.64665,0.63662,,,,7.85398e-5
1:0.25 (rep 2),1-Compress,2.2,3.042,0.139,0.057,,0.043697,725.747,,4.3697,0.725747,,,,7.85398e-5
1:0.25 (rep 2),1-Compress,2.567,3.018,0.163,0.05,,0.0512417,636.62,,5.12417,0.63662,,,,7.85398e-5
1:0.25 (rep 2),1-Compress,2.933,2.995,0.186,0.05,,0.0584722,636.62,,5.84722,0.63662,,,,7.85398e-5
1:0.25 (rep 2),1-Compress,3.3,2.971,0.21,0.05,,0.066017,636.62,,6.6017,0.63662,,,,7.85398e-5
1:0.25 (rep 2),1-Compress,3.667,2.948,0.233,0.057,,0.0732474,725.747,,7.32474,0.725747,,,,7.85398e-5
1:0.25 (rep 2),1-Compress,4.033,2.925,0.256,0.05,,0.0804778,636.62,,8.04778,0.63662,,,,7.85398e-5
1:0.25 (rep 2),1-Compress,4.4,2.901,0.28,0.05,,0.0880226,636.62,,8.80226,0.63662,,,,7.85398e-5
1:0.25 (rep 2),1-Compress,4.767,2.878,0.303,0.064,,0.0952531,814.873,,9.52531,0.814873,,,,7.85398e-5
1:0.25 (rep 2),1-Compress,5.133,2.855,0.326,0.064,,0.102483,814.873,,10.2483,0.814873,,,,7.85398e-5
1:0.25 (rep 2),1-Compress,5.5,2.831,0.35,0.064,,0.110028,814.873,,11.0028,0.814873,,,,7.85398e-5
1:0.25 (rep 2),1-Compress,5.867,2.807,0.374,0.057,,0.117573,725.747,,11.7573,0.725747,,,,7.85398e-5
1:0.25 (rep 2),1-Compress,6.233,2.785,0.396,0.057,,0.124489,725.747,,12.4489,0.725747,,,,7.85398e-5
1:0.25 (rep 2),1-Compress,6.6,2.761,0.42,0.057,,0.132034,725.747,,13.2034,0.725747,,,,7.85398e-5
1:0.25 (rep 2),1-Compress,6.967,2.737,0.444,0.057,,0.139579,725.747,,13.9579,0.725747,,,,7.85398e-5
1:0.25 (rep 2),1-Compress,7.333,2.714,0.467,0.077,,0.146809,980.395,,14.6809,0.980395,,,,7.85398e-5
1:0.25 (rep 2),1-Compress,7.7,2.691,0.49,0.098,,0.15404,1247.78,,15.404,1.24778,,,,7.85398e-5
1:0.25 (rep 2),1-Compress,8.067,2.667,0.514,0.091,,0.161584,1158.65,,16.1584,1.15865,,,,7.85398e-5
1:0.25 (rep 2),1-Compress,8.433,2.644,0.537,0.104,,0.168815,1324.17,,16.8815,1.32417,,,,7.85398e-5
1:0.25 (rep 2),1-Compress,8.8,2.621,0.56,0.104,,0.176045,1324.17,,17.6045,1.32417,,,,7.85398e-5
1:0.25 (rep 2),1-Compress,9.167,2.597,0.584,0.104,,0.18359,1324.17,,18.359,1.32417,,,,7.85398e-5
1:0.25 (rep 2),1-Compress,9.533,2.574,0.607,0.098,,0.19082,1247.78,,19.082,1.24778,,,,7.85398e-5
1:0.25 (rep 2),1-Compress,9.9,2.551,0.63,0.098,,0.198051,1247.78,,19.8051,1.24778,,,,7.85398e-5
1:0.25 (rep 2),1-Compress,10.267,2.527,0.654,0.104,,0.205596,1324.17,,20.5596,1.32417,,,,7.85398e-5
1:0.25 (rep 2),1-Compress,10.633,2.504,0.677,0.104,,0.212826,1324.17,,21.2826,1.32417,,,,7.85398e-5
1:0.25 (rep 2),1-Compress,11,2.481,0.7,0.104,,0.220057,1324.17,,22.0057,1.32417,,,,7.85398e-5
1:0.25 (rep 2),1-Compress,11.367,2.457,0.724,0.104,,0.227601,1324.17,,22.7601,1.32417,,,,7.85398e-5
1:0.25 (rep 2),1-Compress,11.733,2.434,0.747,0.104,,0.234832,1324.17,,23.4832,1.32417,,,,7.85398e-5
1:0.25 (rep 2),1-Compress,12.1,2.411,0.77,0.098,,0.242062,1247.78,,24.2062,1.24778,,,,7.85398e-5
1:0.25 (rep 2),1-Compress,12.467,2.387,0.794,0.104,,0.249607,1324.17,,24.9607,1.32417,,,,7.85398e-5
1:0.25 (rep 2),1-Compress,12.833,2.364,0.817,0.104,,0.256837,1324.17,,25.6837,1.32417,,,,7.85398e-5
1:0.25 (rep 2),1-Compress,13.2,2.34,0.841,0.104,,0.264382,1324.17,,26.4382,1.32417,,,,7.85398e-5
1:0.25 (rep 2),1-Compress,13.567,2.317,0.864,0.104,,0.271613,1324.17,,27.1613,1.32417,,,,7.85398e-5
1:0.25 (rep 2),1-Compress,13.933,2.294,0.887,0.104,,0.278843,1324.17,,27.8843,1.32417,,,,7.85398e-5
1:0.25 (rep 2),1-Compress,14.3,2.27,0.911,0.104,,0.286388,1324.17,,28.6388,1.32417,,,,7.85398e-5
1:0.25 (rep 2),1-Compress,14.667,2.247,0.934,0.111,,0.293618,1413.3,,29.3618,1.4133,,,,7.85398e-5
1:0.25 (rep 2),1-Compress,15.033,2.224,0.957,0.131,,0.300849,1667.94,,30.0849,1.66794,,,,7.85398e-5
1:0.25 (rep 2),1-Compress,15.4,2.2,0.981,0.118,,0.308394,1502.42,,30.8394,1.50242,,,,7.85398e-5
1:0.25 (rep 2),1-Compress,15.767,2.176,1.005,0.118,,0.315938,1502.42,,31.5938,1.50242,,,,7.85398e-5
1:0.25 (rep 2),1-Compress,16.133,2.154,1.027,0.111,,0.322854,1413.3,,32.2854,1.4133,,,,7.85398e-5
1:0.25 (rep 2),1-Compress,16.5,2.13,1.051,0.104,,0.330399,1324.17,,33.0399,1.32417,,,,7.85398e-5
1:0.25 (rep 2),1-Compress,16.867,2.106,1.075,0.111,,0.337944,1413.3,,33.7944,1.4133,,,,7.85398e-5
1:0.25 (rep 2),1-Compress,17.233,2.083,1.098,0.118,,0.345174,1502.42,,34.5174,1.50242,,,,7.85398e-5
1:0.25 (rep 2),1-Compress,17.6,2.06,1.121,0.138,,0.352405,1757.07,,35.2405,1.75707,,,,7.85398e-5
1:0.25 (rep 2),1-Compress,17.967,2.036,1.145,0.131,,0.35995,1667.94,,35.995,1.66794,,,,7.85398e-5
1:0.25 (rep 2),1-Compress,18.333,2.013,1.168,0.131,,0.36718,1667.94,,36.718,1.66794,,,,7.85398e-5
1:0.25 (rep 2),1-Compress,18.7,1.99,1.191,0.138,,0.374411,1757.07,,37.4411,1.75707,,,,7.85398e-5
1:0.25 (rep 2),1-Compress,19.067,1.966,1.215,0.145,,0.381955,1846.2,,38.1955,1.8462,,,,7.85398e-5
1:0.25 (rep 2),1-Compress,19.433,1.943,1.238,0.159,,0.389186,2024.45,,38.9186,2.02445,,,,7.85398e-5
1:0.25 (rep 2),1-Compress,19.8,1.92,1.261,0.159,,0.396416,2024.45,,39.6416,2.02445,,,,7.85398e-5
1:0.25 (rep 2),1-Compress,20.167,1.896,1.285,0.159,,0.403961,2024.45,,40.3961,2.02445,,,,7.85398e-5
1:0.25 (rep 2),1-Compress,20.533,1.873,1.308,0.159,,0.411191,2024.45,,41.1191,2.02445,,,,7.85398e-5
1:0.25 (rep 2),1-Compress,20.9,1.85,1.331,0.159,,0.418422,2024.45,,41.8422,2.02445,,,,7.85398e-5
1:0.25 (rep 2),1-Compress,21.267,1.826,1.355,0.159,,0.425967,2024.45,,42.5967,2.02445,,,,7.85398e-5
1:0.25 (rep 2),1-Compress,21.633,1.803,1.378,0.159,,0.433197,2024.45,,43.3197,2.02445,,,,7.85398e-5
1:0.25 (rep 2),1-Compress,22,1.78,1.401,0.159,,0.440428,2024.45,,44.0428,2.02445,,,,7.85398e-5
1:0.25 (rep 2),1-Compress,22.367,1.756,1.425,0.159,,0.447972,2024.45,,44.7972,2.02445,,,,7.85398e-5
1:0.25 (rep 2),1-Compress,22.733,1.733,1.448,0.152,,0.455203,1935.32,,45.5203,1.93532,,,,7.85398e-5
1:0.25 (rep 2),1-Compress,23.1,1.709,1.472,0.152,,0.462748,1935.32,,46.2748,1.93532,,,,7.85398e-5
1:0.25 (rep 2),1-Compress,23.467,1.686,1.495,0.159,,0.469978,2024.45,,46.9978,2.02445,,,,7.85398e-5
1:0.25 (rep 2),1-Compress,23.833,1.663,1.518,0.159,,0.477208,2024.45,,47.7208,2.02445,,,,7.85398e-5
1:0.25 (rep 2),1-Compress,24.2,1.639,1.542,0.159,,0.484753,2024.45,,48.4753,2.02445,,,,7.85398e-5
1:0.25 (rep 2),1-Compress,24.567,1.616,1.565,0.165,,0.491984,2100.85,,49.1984,2.10085,,,,7.85398e-5
1:0.25 (rep 2),1-Compress,24.933,1.593,1.588,0.159,,0.499214,2024.45,,49.9214,2.02445,,,,7.85398e-5
1:0.25 (rep 2),1-Compress,25.3,1.569,1.612,0.165,,0.506759,2100.85,,50.6759,2.10085,,,,7.85398e-5
1:0.25 (rep 2),1-Compress,25.667,1.545,1.636,0.165,,0.514304,2100.85,,51.4304,2.10085,,,,7.85398e-5
1:0.25 (rep 2),1-Compress,26.033,1.523,1.658,0.172,,0.52122,2189.97,,52.122,2.18997,,,,7.85398e-5
1:0.25 (rep 2),1-Compress,26.4,1.499,1.682,0.206,,0.528765,2622.87,,52.8765,2.62287,,,,7.85398e-5
1:0.25 (rep 2),1-Compress,26.767,1.475,1.706,0.213,,0.536309,2712,,53.6309,2.712,,,,7.85398e-5
1:0.25 (rep 2),1-Compress,27.133,1.452,1.729,0.206,,0.54354,2622.87,,54.354,2.62287,,,,7.85398e-5
1:0.25 (rep 2),1-Compress,27.5,1.429,1.752,0.186,,0.55077,2368.23,,55.077,2.36823,,,,7.85398e-5
1:0.25 (rep 2),1-Compress,27.867,1.405,1.776,0.186,,0.558315,2368.23,,55.8315,2.36823,,,,7.85398e-5
1:0.25 (rep 2),1-Compress,28.233,1.382,1.799,0.193,,0.565545,2457.35,,56.5545,2.45735,,,,7.85398e-5
1:0.25 (rep 2),1-Compress,28.6,1.359,1.822,0.206,,0.572776,2622.87,,57.2776,2.62287,,,,7.85398e-5
1:0.25 (rep 2),1-Compress,28.967,1.336,1.845,0.213,,0.580006,2712,,58.0006,2.712,,,,7.85398e-5
1:0.25 (rep 2),1-Compress,29.333,1.312,1.869,0.213,,0.587551,2712,,58.7551,2.712,,,,7.85398e-5
1:0.25 (rep 2),1-Compress,29.7,1.289,1.892,0.213,,0.594782,2712,,59.4782,2.712,,,,7.85398e-5
1:0.25 (rep 2),1-Recover,30.067,1.275,1.906,0.213,,0.599183,2712,,59.9183,2.712,,,,7.85398e-5
1:0.25 (rep 2),1-Recover,30.433,1.298,1.883,0.199,,0.591952,2533.75,,59.1952,2.53375,,,,7.85398e-5
1:0.25 (rep 2),1-Recover,30.8,1.321,1.86,0.199,,0.584722,2533.75,,58.4722,2.53375,,,,7.85398e-5
1:0.25 (rep 2),1-Recover,31.167,1.345,1.836,0.206,,0.577177,2622.87,,57.7177,2.62287,,,,7.85398e-5
1:0.25 (rep 2),1-Recover,31.533,1.368,1.813,0.213,,0.569947,2712,,56.9947,2.712,,,,7.85398e-5
1:0.25 (rep 2),1-Recover,31.9,1.392,1.789,0.213,,0.562402,2712,,56.2402,2.712,,,,7.85398e-5
1:0.25 (rep 2),1-Recover,32.267,1.415,1.766,0.199,,0.555171,2533.75,,55.5171,2.53375,,,,7.85398e-5
1:0.25 (rep 2),1-Recover,32.633,1.438,1.743,0.186,,0.547941,2368.23,,54.7941,2.36823,,,,7.85398e-5
1:0.25 (rep 2),1-Recover,33,1.462,1.719,0.165,,0.540396,2100.85,,54.0396,2.10085,,,,7.85398e-5
1:0.25 (rep 2),1-Recover,33.367,1.485,1.696,0.165,,0.533166,2100.85,,53.3166,2.10085,,,,7.85398e-5
1:0.25 (rep 2),1-Recover,33.733,1.508,1.673,0.159,,0.525935,2024.45,,52.5935,2.02445,,,,7.85398e-5
1:0.25 (rep 2),1-Recover,34.1,1.532,1.649,0.165,,0.51839,2100.85,,51.839,2.10085,,,,7.85398e-5
1:0.25 (rep 2),1-Recover,34.467,1.555,1.626,0.159,,0.51116,2024.45,,51.116,2.02445,,,,7.85398e-5
1:0.25 (rep 2),1-Recover,34.833,1.578,1.603,0.159,,0.50393,2024.45,,50.393,2.02445,,,,7.85398e-5
1:0.25 (rep 2),1-Recover,35.2,1.602,1.579,0.152,,0.496385,1935.32,,49.6385,1.93532,,,,7.85398e-5
1:0.25 (rep 2),1-Recover,35.567,1.626,1.555,0.159,,0.48884,2024.45,,48.884,2.02445,,,,7.85398e-5
1:0.25 (rep 2),1-Recover,35.933,1.648,1.533,0.159,,0.481924,2024.45,,48.1924,2.02445,,,,7.85398e-5
1:0.25 (rep 2),1-Recover,36.3,1.672,1.509,0.159,,0.474379,2024.45,,47.4379,2.02445,,,,7.85398e-5
1:0.25 (rep 2),1-Recover,36.667,1.696,1.485,0.159,,0.466834,2024.45,,46.6834,2.02445,,,,7.85398e-5
1:0.25 (rep 2),1-Recover,37.033,1.719,1.462,0.152,,0.459604,1935.32,,45.9604,1.93532,,,,7.85398e-5
1:0.25 (rep 2),1-Recover,37.4,1.742,1.439,0.145,,0.452373,1846.2,,45.2373,1.8462,,,,7.85398e-5
1:0.25 (rep 2),1-Recover,37.767,1.766,1.415,0.152,,0.444829,1935.32,,44.4829,1.93532,,,,7.85398e-5
1:0.25 (rep 2),1-Recover,38.133,1.789,1.392,0.145,,0.437598,1846.2,,43.7598,1.8462,,,,7.85398e-5
1:0.25 (rep 2),1-Recover,38.5,1.812,1.369,0.145,,0.430368,1846.2,,43.0368,1.8462,,,,7.85398e-5
1:0.25 (rep 2),1-Recover,38.867,1.836,1.345,0.118,,0.422823,1502.42,,42.2823,1.50242,,,,7.85398e-5
1:0.25 (rep 2),1-Recover,39.233,1.859,1.322,0.111,,0.415593,1413.3,,41.5593,1.4133,,,,7.85398e-5
1:0.25 (rep 2),1-Recover,39.6,1.882,1.299,0.104,,0.408362,1324.17,,40.8362,1.32417,,,,7.85398e-5
1:0.25 (rep 2),1-Recover,39.967,1.906,1.275,0.118,,0.400817,1502.42,,40.0817,1.50242,,,,7.85398e-5
1:0.25 (rep 2),1-Recover,40.333,1.929,1.252,0.118,,0.393587,1502.42,,39.3587,1.50242,,,,7.85398e-5
1:0.25 (rep 2),1-Recover,40.7,1.952,1.229,0.104,,0.386356,1324.17,,38.6356,1.32417,,,,7.85398e-5
1:0.25 (rep 2),1-Recover,41.067,1.976,1.205,0.111,,0.378812,1413.3,,37.8812,1.4133,,,,7.85398e-5
1:0.25 (rep 2),1-Recover,41.433,1.999,1.182,0.104,,0.371581,1324.17,,37.1581,1.32417,,,,7.85398e-5
1:0.25 (rep 2),1-Recover,41.8,2.022,1.159,0.104,,0.364351,1324.17,,36.4351,1.32417,,,,7.85398e-5
1:0.25 (rep 2),1-Recover,42.167,2.046,1.135,0.104,,0.356806,1324.17,,35.6806,1.32417,,,,7.85398e-5
1:0.25 (rep 2),1-Recover,42.533,2.069,1.112,0.104,,0.349576,1324.17,,34.9576,1.32417,,,,7.85398e-5
1:0.25 (rep 2),1-Recover,42.9,2.093,1.088,0.104,,0.342031,1324.17,,34.2031,1.32417,,,,7.85398e-5
1:0.25 (rep 2),1-Recover,43.267,2.116,1.065,0.104,,0.3348,1324.17,,33.48,1.32417,,,,7.85398e-5
1:0.25 (rep 2),1-Recover,43.633,2.139,1.042,0.104,,0.32757,1324.17,,32.757,1.32417,,,,7.85398e-5
1:0.25 (rep 2),1-Recover,44,2.163,1.018,0.104,,0.320025,1324.17,,32.0025,1.32417,,,,7.85398e-5
1:0.25 (rep 2),1-Recover,44.367,2.186,0.995,0.104,,0.312795,1324.17,,31.2795,1.32417,,,,7.85398e-5
1:0.25 (rep 2),1-Recover,44.733,2.209,0.972,0.091,,0.305564,1158.65,,30.5564,1.15865,,,,7.85398e-5
1:0.25 (rep 2),1-Recover,45.1,2.233,0.948,0.098,,0.298019,1247.78,,29.8019,1.24778,,,,7.85398e-5
1:0.25 (rep 2),1-Recover,45.467,2.257,0.924,0.104,,0.290475,1324.17,,29.0475,1.32417,,,,7.85398e-5
1:0.25 (rep 2),1-Recover,45.833,2.279,0.902,0.098,,0.283559,1247.78,,28.3559,1.24778,,,,7.85398e-5
1:0.25 (rep 2),1-Recover,46.2,2.303,0.878,0.104,,0.276014,1324.17,,27.6014,1.32417,,,,7.85398e-5
1:0.25 (rep 2),1-Recover,46.567,2.327,0.854,0.091,,0.268469,1158.65,,26.8469,1.15865,,,,7.85398e-5
1:0.25 (rep 2),1-Recover,46.933,2.35,0.831,0.064,,0.261239,814.873,,26.1239,0.814873,,,,7.85398e-5
1:0.25 (rep 2),1-Recover,47.3,2.373,0.808,0.084,,0.254008,1069.52,,25.4008,1.06952,,,,7.85398e-5
1:0.25 (rep 2),1-Recover,47.667,2.396,0.785,0.084,,0.246778,1069.52,,24.6778,1.06952,,,,7.85398e-5
1:0.25 (rep 2),1-Recover,48.033,2.42,0.761,0.084,,0.239233,1069.52,,23.9233,1.06952,,,,7.85398e-5
1:0.25 (rep 2),1-Recover,48.4,2.443,0.738,0.07,,0.232003,891.268,,23.2003,0.891268,,,,7.85398e-5
1:0.25 (rep 2),1-Recover,48.767,2.467,0.714,0.057,,0.224458,725.747,,22.4458,0.725747,,,,7.85398e-5
1:0.25 (rep 2),1-Recover,49.133,2.49,0.691,0.057,,0.217227,725.747,,21.7227,0.725747,,,,7.85398e-5
1:0.25 (rep 2),1-Recover,49.5,2.513,0.668,0.05,,0.209997,636.62,,20.9997,0.63662,,,,7.85398e-5
1:0.25 (rep 2),1-Recover,49.867,2.537,0.644,0.064,,0.202452,814.873,,20.2452,0.814873,,,,7.85398e-5
1:0.25 (rep 2),1-Recover,50.233,2.56,0.621,0.07,,0.195222,891.268,,19.5222,0.891268,,,,7.85398e-5
1:0.25 (rep 2),1-Recover,50.6,2.583,0.598,0.057,,0.187991,725.747,,18.7991,0.725747,,,,7.85398e-5
1:0.25 (rep 2),1-Recover,50.967,2.607,0.574,0.05,,0.180446,636.62,,18.0446,0.63662,,,,7.85398e-5
1:0.25 (rep 2),1-Recover,51.333,2.63,0.551,0.05,,0.173216,636.62,,17.3216,0.63662,,,,7.85398e-5
1:0.25 (rep 2),1-Recover,51.7,2.653,0.528,0.05,,0.165986,636.62,,16.5986,0.63662,,,,7.85398e-5
1:0.25 (rep 2),1-Recover,52.067,2.677,0.504,0.05,,0.158441,636.62,,15.8441,0.63662,,,,7.85398e-5
1:0.25 (rep 2),1-Recover,52.433,2.7,0.481,0.05,,0.15121,636.62,,15.121,0.63662,,,,7.85398e-5
1:0.25 (rep 2),1-Recover,52.8,2.723,0.458,0.05,,0.14398,636.62,,14.398,0.63662,,,,7.85398e-5
1:0.25 (rep 2),1-Recover,53.167,2.747,0.434,0.05,,0.136435,636.62,,13.6435,0.63662,,,,7.85398e-5
1:0.25 (rep 2),1-Recover,53.533,2.77,0.411,0.05,,0.129205,636.62,,12.9205,0.63662,,,,7.85398e-5
1:0.25 (rep 2),1-Recover,53.9,2.794,0.387,0.05,,0.12166,636.62,,12.166,0.63662,,,,7.85398e-5
1:0.25 (rep 2),1-Recover,54.267,2.817,0.364,0.05,,0.114429,636.62,,11.4429,0.63662,,,,7.85398e-5
1:0.25 (rep 2),1-Recover,54.633,2.84,0.341,0.05,,0.107199,636.62,,10.7199,0.63662,,,,7.85398e-5
1:0.25 (rep 2),1-Recover,55,2.864,0.317,0.05,,0.0996542,636.62,,9.96542,0.63662,,,,7.85398e-5
1:0.25 (rep 2),1-Recover,55.367,2.888,0.293,0.05,,0.0921094,636.62,,9.21094,0.63662,,,,7.85398e-5
1:0.25 (rep 2),1-Recover,55.733,2.91,0.271,0.05,,0.0851933,636.62,,8.51933,0.63662,,,,7.85398e-5
1:0.25 (rep 2),1-Recover,56.1,2.934,0.247,0.05,,0.0776485,636.62,,7.76485,0.63662,,,,7.85398e-5
1:0.25 (rep 2),1-Recover,56.467,2.957,0.224,0.05,,0.0704181,636.62,,7.04181,0.63662,,,,7.85398e-5
1:0.25 (rep 2),1-Recover,56.833,2.981,0.2,0.05,,0.0628733,636.62,,6.28733,0.63662,,,,7.85398e-5
1:0.25 (rep 2),1-Recover,57.2,3.004,0.177,0.036,,0.0556429,458.366,,5.56429,0.458366,,,,7.85398e-5
1:0.25 (rep 2),1-Recover,57.567,3.027,0.154,0.05,,0.0484124,636.62,,4.84124,0.63662,,,,7.85398e-5
1:0.25 (rep 2),1-Recover,57.933,3.051,0.13,0.05,,0.0408677,636.62,,4.08677,0.63662,,,,7.85398e-5
1:0.25 (rep 2),1-Recover,58.3,3.074,0.107,0.043,,0.0336372,547.493,,3.36372,0.547493,,,,7.85398e-5
1:0.25 (rep 2),1-Recover,58.667,3.098,0.083,0.036,,0.0260924,458.366,,2.60924,0.458366,,,,7.85398e-5
1:0.25 (rep 2),1-Recover,59.033,3.12,0.061,0.043,,0.0191764,547.493,,1.91764,0.547493,,,,7.85398e-5
1:0.25 (rep 2),1-Recover,59.4,3.144,0.037,0.043,,0.0116316,547.493,,1.16316,0.547493,,,,7.85398e-5
1:0.25 (rep 2),1-Recover,59.767,3.168,0.013,0.03,,0.00408677,381.972,,0.408677,0.381972,,,,7.85398e-5
1:0.25 (rep 2),2-Compress,60.117,3.176,0.005,0.05,,0.00157183,636.62,,0.157183,0.63662,,,,7.85398e-5
1:0.25 (rep 2),2-Compress,60.483,3.153,0.028,0.05,,0.00880226,636.62,,0.880226,0.63662,,,,7.85398e-5
1:0.25 (rep 2),2-Compress,60.85,3.13,0.051,0.043,,0.0160327,547.493,,1.60327,0.547493,,,,7.85398e-5
1:0.25 (rep 2),2-Compress,61.217,3.106,0.075,0.05,,0.0235775,636.62,,2.35775,0.63662,,,,7.85398e-5
1:0.25 (rep 2),2-Compress,61.583,3.083,0.098,0.05,,0.0308079,636.62,,3.08079,0.63662,,,,7.85398e-5
1:0.25 (rep 2),2-Compress,61.95,3.059,0.122,0.05,,0.0383527,636.62,,3.83527,0.63662,,,,7.85398e-5
1:0.25 (rep 2),2-Compress,62.317,3.036,0.145,0.05,,0.0455831,636.62,,4.55831,0.63662,,,,7.85398e-5
1:0.25 (rep 2),2-Compress,62.683,3.013,0.168,0.05,,0.0528136,636.62,,5.28136,0.63662,,,,7.85398e-5
1:0.25 (rep 2),2-Compress,63.05,2.989,0.192,0.05,,0.0603584,636.62,,6.03584,0.63662,,,,7.85398e-5
1:0.25 (rep 2),2-Compress,63.417,2.966,0.215,0.05,,0.0675888,636.62,,6.75888,0.63662,,,,7.85398e-5
1:0.25 (rep 2),2-Compress,63.783,2.943,0.238,0.05,,0.0748192,636.62,,7.48192,0.63662,,,,7.85398e-5
1:0.25 (rep 2),2-Compress,64.15,2.919,0.262,0.05,,0.082364,636.62,,8.2364,0.63662,,,,7.85398e-5
1:0.25 (rep 2),2-Compress,64.517,2.896,0.285,0.05,,0.0895945,636.62,,8.95945,0.63662,,,,7.85398e-5
1:0.25 (rep 2),2-Compress,64.883,2.873,0.308,0.05,,0.0968249,636.62,,9.68249,0.63662,,,,7.85398e-5
1:0.25 (rep 2),2-Compress,65.25,2.849,0.332,0.05,,0.10437,636.62,,10.437,0.63662,,,,7.85398e-5
1:0.25 (rep 2),2-Compress,65.617,2.825,0.356,0.05,,0.111914,636.62,,11.1914,0.63662,,,,7.85398e-5
1:0.25 (rep 2),2-Compress,65.983,2.803,0.378,0.057,,0.118831,725.747,,11.8831,0.725747,,,,7.85398e-5
1:0.25 (rep 2),2-Compress,66.35,2.779,0.402,0.05,,0.126375,636.62,,12.6375,0.63662,,,,7.85398e-5
1:0.25 (rep 2),2-Compress,66.717,2.756,0.425,0.057,,0.133606,725.747,,13.3606,0.725747,,,,7.85398e-5
1:0.25 (rep 2),2-Compress,67.083,2.732,0.449,0.05,,0.141151,636.62,,14.1151,0.63662,,,,7.85398e-5
1:0.25 (rep 2),2-Compress,67.45,2.709,0.472,0.057,,0.148381,725.747,,14.8381,0.725747,,,,7.85398e-5
1:0.25 (rep 2),2-Compress,67.817,2.686,0.495,0.07,,0.155611,891.268,,15.5611,0.891268,,,,7.85398e-5
1:0.25 (rep 2),2-Compress,68.183,2.662,0.519,0.084,,0.163156,1069.52,,16.3156,1.06952,,,,7.85398e-5
1:0.25 (rep 2),2-Compress,68.55,2.639,0.542,0.07,,0.170387,891.268,,17.0387,0.891268,,,,7.85398e-5
1:0.25 (rep 2),2-Compress,68.917,2.615,0.566,0.07,,0.177931,891.268,,17.7931,0.891268,,,,7.85398e-5
1:0.25 (rep 2),2-Compress,69.283,2.592,0.589,0.077,,0.185162,980.395,,18.5162,0.980395,,,,7.85398e-5
1:0.25 (rep 2),2-Compress,69.65,2.569,0.612,0.05,,0.192392,636.62,,19.2392,0.63662,,,,7.85398e-5
1:0.25 (rep 2),2-Compress,70.017,2.545,0.636,0.091,,0.199937,1158.65,,19.9937,1.15865,,,,7.85398e-5
1:0.25 (rep 2),2-Compress,70.383,2.522,0.659,0.07,,0.207168,891.268,,20.7168,0.891268,,,,7.85398e-5
1:0.25 (rep 2),2-Compress,70.75,2.499,0.682,0.091,,0.214398,1158.65,,21.4398,1.15865,,,,7.85398e-5
1:0.25 (rep 2),2-Compress,71.117,2.475,0.706,0.098,,0.221943,1247.78,,22.1943,1.24778,,,,7.85398e-5
1:0.25 (rep 2),2-Compress,71.483,2.452,0.729,0.098,,0.229173,1247.78,,22.9173,1.24778,,,,7.85398e-5
1:0.25 (rep 2),2-Compress,71.85,2.429,0.752,0.104,,0.236404,1324.17,,23.6404,1.32417,,,,7.85398e-5
1:0.25 (rep 2),2-Compress,72.217,2.405,0.776,0.104,,0.243948,1324.17,,24.3948,1.32417,,,,7.85398e-5
1:0.25 (rep 2),2-Compress,72.583,2.382,0.799,0.098,,0.251179,1247.78,,25.1179,1.24778,,,,7.85398e-5
1:0.25 (rep 2),2-Compress,72.95,2.359,0.822,0.104,,0.258409,1324.17,,25.8409,1.32417,,,,7.85398e-5
1:0.25 (rep 2),2-Compress,73.317,2.335,0.846,0.104,,0.265954,1324.17,,26.5954,1.32417,,,,7.85398e-5
1:0.25 (rep 2),2-Compress,73.683,2.312,0.869,0.104,,0.273185,1324.17,,27.3185,1.32417,,,,7.85398e-5
1:0.25 (rep 2),2-Compress,74.05,2.288,0.893,0.104,,0.280729,1324.17,,28.0729,1.32417,,,,7.85398e-5
1:0.25 (rep 2),2-Compress,74.417,2.265,0.916,0.104,,0.28796,1324.17,,28.796,1.32417,,,,7.85398e-5
1:0.25 (rep 2),2-Compress,74.783,2.242,0.939,0.104,,0.29519,1324.17,,29.519,1.32417,,,,7.85398e-5
1:0.25 (rep 2),2-Compress,75.15,2.218,0.963,0.104,,0.302735,1324.17,,30.2735,1.32417,,,,7.85398e-5
1:0.25 (rep 2),2-Compress,75.517,2.195,0.986,0.104,,0.309965,1324.17,,30.9965,1.32417,,,,7.85398e-5
1:0.25 (rep 2),2-Compress,75.883,2.172,1.009,0.104,,0.317196,1324.17,,31.7196,1.32417,,,,7.85398e-5
1:0.25 (rep 2),2-Compress,76.25,2.148,1.033,0.104,,0.324741,1324.17,,32.4741,1.32417,,,,7.85398e-5
1:0.25 (rep 2),2-Compress,76.617,2.125,1.056,0.111,,0.331971,1413.3,,33.1971,1.4133,,,,7.85398e-5
1:0.25 (rep 2),2-Compress,76.983,2.101,1.08,0.111,,0.339516,1413.3,,33.9516,1.4133,,,,7.85398e-5
1:0.25 (rep 2),2-Compress,77.35,2.078,1.103,0.111,,0.346746,1413.3,,34.6746,1.4133,,,,7.85398e-5
1:0.25 (rep 2),2-Compress,77.717,2.055,1.126,0.118,,0.353977,1502.42,,35.3977,1.50242,,,,7.85398e-5
1:0.25 (rep 2),2-Compress,78.083,2.031,1.15,0.131,,0.361522,1667.94,,36.1522,1.66794,,,,7.85398e-5
1:0.25 (rep 2),2-Compress,78.45,2.008,1.173,0.131,,0.368752,1667.94,,36.8752,1.66794,,,,7.85398e-5
1:0.25 (rep 2),2-Compress,78.817,1.984,1.197,0.125,,0.376297,1591.55,,37.6297,1.59155,,,,7.85398e-5
1:0.25 (rep 2),2-Compress,79.183,1.962,1.219,0.118,,0.383213,1502.42,,38.3213,1.50242,,,,7.85398e-5
1:0.25 (rep 2),2-Compress,79.55,1.938,1.243,0.125,,0.390758,1591.55,,39.0758,1.59155,,,,7.85398e-5
1:0.25 (rep 2),2-Compress,79.917,1.914,1.267,0.138,,0.398302,1757.07,,39.8302,1.75707,,,,7.85398e-5
1:0.25 (rep 2),2-Compress,80.283,1.891,1.29,0.145,,0.405533,1846.2,,40.5533,1.8462,,,,7.85398e-5
1:0.25 (rep 2),2-Compress,80.65,1.868,1.313,0.152,,0.412763,1935.32,,41.2763,1.93532,,,,7.85398e-5
1:0.25 (rep 2),2-Compress,81.017,1.844,1.337,0.159,,0.420308,2024.45,,42.0308,2.02445,,,,7.85398e-5
1:0.25 (rep 2),2-Compress,81.383,1.821,1.36,0.159,,0.427539,2024.45,,42.7539,2.02445,,,,7.85398e-5
1:0.25 (rep 2),2-Compress,81.75,1.798,1.383,0.159,,0.434769,2024.45,,43.4769,2.02445,,,,7.85398e-5
1:0.25 (rep 2),2-Compress,82.117,1.774,1.407,0.159,,0.442314,2024.45,,44.2314,2.02445,,,,7.85398e-5
1:0.25 (rep 2),2-Compress,82.483,1.751,1.43,0.159,,0.449544,2024.45,,44.9544,2.02445,,,,7.85398e-5
1:0.25 (rep 2),2-Compress,82.85,1.728,1.453,0.159,,0.456775,2024.45,,45.6775,2.02445,,,,7.85398e-5
1:0.25 (rep 2),2-Compress,83.217,1.704,1.477,0.159,,0.464319,2024.45,,46.4319,2.02445,,,,7.85398e-5
1:0.25 (rep 2),2-Compress,83.583,1.681,1.5,0.159,,0.47155,2024.45,,47.155,2.02445,,,,7.85398e-5
1:0.25 (rep 2),2-Compress,83.95,1.657,1.524,0.159,,0.479095,2024.45,,47.9095,2.02445,,,,7.85398e-5
1:0.25 (rep 2),2-Compress,84.317,1.634,1.547,0.159,,0.486325,2024.45,,48.6325,2.02445,,,,7.85398e-5
1:0.25 (rep 2),2-Compress,84.683,1.611,1.57,0.165,,0.493555,2100.85,,49.3555,2.10085,,,,7.85398e-5
1:0.25 (rep 2),2-Compress,85.05,1.587,1.594,0.159,,0.5011,2024.45,,50.11,2.02445,,,,7.85398e-5
1:0.25 (rep 2),2-Compress,85.417,1.564,1.617,0.152,,0.508331,1935.32,,50.8331,1.93532,,,,7.85398e-5
1:0.25 (rep 2),2-Compress,85.783,1.541,1.64,0.159,,0.515561,2024.45,,51.5561,2.02445,,,,7.85398e-5
1:0.25 (rep 2),2-Compress,86.15,1.517,1.664,0.165,,0.523106,2100.85,,52.3106,2.10085,,,,7.85398e-5
1:0.25 (rep 2),2-Compress,86.517,1.494,1.687,0.172,,0.530336,2189.97,,53.0336,2.18997,,,,7.85398e-5
1:0.25 (rep 2),2-Compress,86.883,1.47,1.711,0.199,,0.537881,2533.75,,53.7881,2.53375,,,,7.85398e-5
1:0.25 (rep 2),2-Compress,87.25,1.447,1.734,0.213,,0.545112,2712,,54.5112,2.712,,,,7.85398e-5
1:0.25 (rep 2),2-Compress,87.617,1.424,1.757,0.206,,0.552342,2622.87,,55.2342,2.62287,,,,7.85398e-5
1:0.25 (rep 2),2-Compress,87.983,1.401,1.78,0.193,,0.559572,2457.35,,55.9572,2.45735,,,,7.85398e-5
1:0.25 (rep 2),2-Compress,88.35,1.377,1.804,0.186,,0.567117,2368.23,,56.7117,2.36823,,,,7.85398e-5
1:0.25 (rep 2),2-Compress,88.717,1.353,1.828,0.199,,0.574662,2533.75,,57.4662,2.53375,,,,7.85398e-5
1:0.25 (rep 2),2-Compress,89.083,1.331,1.85,0.206,,0.581578,2622.87,,58.1578,2.62287,,,,7.85398e-5
1:0.25 (rep 2),2-Compress,89.45,1.307,1.874,0.213,,0.589123,2712,,58.9123,2.712,,,,7.85398e-5
1:0.25 (rep 2),2-Compress,89.817,1.283,1.898,0.213,,0.596668,2712,,59.6668,2.712,,,,7.85398e-5
1:0.25 (rep 2),2-Recover,90.17,1.279,1.902,0.213,,0.597925,2712,,59.7925,2.712,,,,7.85398e-5
1:0.25 (rep 2),2-Recover,90.537,1.303,1.878,0.206,,0.59038,2622.87,,59.038,2.62287,,,,7.85398e-5
1:0.25 (rep 2),2-Recover,90.903,1.325,1.856,0.186,,0.583464,2368.23,,58.3464,2.36823,,,,7.85398e-5
1:0.25 (rep 2),2-Recover,91.27,1.349,1.832,0.193,,0.57592,2457.35,,57.592,2.45735,,,,7.85398e-5
1:0.25 (rep 2),2-Recover,91.637,1.373,1.808,0.206,,0.568375,2622.87,,56.8375,2.62287,,,,7.85398e-5
1:0.25 (rep 2),2-Recover,92.003,1.396,1.785,0.213,,0.561144,2712,,56.1144,2.712,,,,7.85398e-5
1:0.25 (rep 2),2-Recover,92.37,1.419,1.762,0.179,,0.553914,2279.1,,55.3914,2.2791,,,,7.85398e-5
1:0.25 (rep 2),2-Recover,92.737,1.443,1.738,0.179,,0.546369,2279.1,,54.6369,2.2791,,,,7.85398e-5
1:0.25 (rep 2),2-Recover,93.103,1.466,1.715,0.172,,0.539139,2189.97,,53.9139,2.18997,,,,7.85398e-5
1:0.25 (rep 2),2-Recover,93.47,1.489,1.692,0.159,,0.531908,2024.45,,53.1908,2.02445,,,,7.85398e-5
1:0.25 (rep 2),2-Recover,93.837,1.513,1.668,0.159,,0.524363,2024.45,,52.4363,2.02445,,,,7.85398e-5
1:0.25 (rep 2),2-Recover,94.203,1.536,1.645,0.152,,0.517133,1935.32,,51.7133,1.93532,,,,7.85398e-5
1:0.25 (rep 2),2-Recover,94.57,1.559,1.622,0.159,,0.509903,2024.45,,50.9903,2.02445,,,,7.85398e-5
1:0.25 (rep 2),2-Recover,94.937,1.583,1.598,0.159,,0.502358,2024.45,,50.2358,2.02445,,,,7.85398e-5
1:0.25 (rep 2),2-Recover,95.303,1.606,1.575,0.159,,0.495127,2024.45,,49.5127,2.02445,,,,7.85398e-5
1:0.25 (rep 2),2-Recover,95.67,1.63,1.551,0.159,,0.487583,2024.45,,48.7583,2.02445,,,,7.85398e-5
1:0.25 (rep 2),2-Recover,96.037,1.653,1.528,0.159,,0.480352,2024.45,,48.0352,2.02445,,,,7.85398e-5
1:0.25 (rep 2),2-Recover,96.403,1.676,1.505,0.159,,0.473122,2024.45,,47.3122,2.02445,,,,7.85398e-5
1:0.25 (rep 2),2-Recover,96.77,1.7,1.481,0.159,,0.465577,2024.45,,46.5577,2.02445,,,,7.85398e-5
1:0.25 (rep 2),2-Recover,97.137,1.723,1.458,0.152,,0.458346,1935.32,,45.8346,1.93532,,,,7.85398e-5
1:0.25 (rep 2),2-Recover,97.503,1.746,1.435,0.152,,0.451116,1935.32,,45.1116,1.93532,,,,7.85398e-5
1:0.25 (rep 2),2-Recover,97.87,1.769,1.412,0.131,,0.443886,1667.94,,44.3886,1.66794,,,,7.85398e-5
1:0.25 (rep 2),2-Recover,98.237,1.793,1.388,0.138,,0.436341,1757.07,,43.6341,1.75707,,,,7.85398e-5
1:0.25 (rep 2),2-Recover,98.603,1.816,1.365,0.138,,0.42911,1757.07,,42.911,1.75707,,,,7.85398e-5
1:0.25 (rep 2),2-Recover,98.97,1.84,1.341,0.131,,0.421566,1667.94,,42.1566,1.66794,,,,7.85398e-5
1:0.25 (rep 2),2-Recover,99.337,1.863,1.318,0.111,,0.414335,1413.3,,41.4335,1.4133,,,,7.85398e-5
1:0.25 (rep 2),2-Recover,99.703,1.886,1.295,0.111,,0.407105,1413.3,,40.7105,1.4133,,,,7.85398e-5
1:0.25 (rep 2),2-Recover,100.07,1.91,1.271,0.104,,0.39956,1324.17,,39.956,1.32417,,,,7.85398e-5
1:0.25 (rep 2),2-Recover,100.437,1.933,1.248,0.104,,0.392329,1324.17,,39.2329,1.32417,,,,7.85398e-5
1:0.25 (rep 2),2-Recover,100.803,1.956,1.225,0.118,,0.385099,1502.42,,38.5099,1.50242,,,,7.85398e-5
1:0.25 (rep 2),2-Recover,101.17,1.98,1.201,0.104,,0.377554,1324.17,,37.7554,1.32417,,,,7.85398e-5
1:0.25 (rep 2),2-Recover,101.537,2.003,1.178,0.104,,0.370324,1324.17,,37.0324,1.32417,,,,7.85398e-5
1:0.25 (rep 2),2-Recover,101.903,2.026,1.155,0.104,,0.363093,1324.17,,36.3093,1.32417,,,,7.85398e-5
1:0.25 (rep 2),2-Recover,102.27,2.05,1.131,0.104,,0.355549,1324.17,,35.5549,1.32417,,,,7.85398e-5
1:0.25 (rep 2),2-Recover,102.637,2.074,1.107,0.104,,0.348004,1324.17,,34.8004,1.32417,,,,7.85398e-5
1:0.25 (rep 2),2-Recover,103.003,2.096,1.085,0.104,,0.341088,1324.17,,34.1088,1.32417,,,,7.85398e-5
1:0.25 (rep 2),2-Recover,103.37,2.12,1.061,0.104,,0.333543,1324.17,,33.3543,1.32417,,,,7.85398e-5
1:0.25 (rep 2),2-Recover,103.737,2.144,1.037,0.104,,0.325998,1324.17,,32.5998,1.32417,,,,7.85398e-5
1:0.25 (rep 2),2-Recover,104.103,2.167,1.014,0.104,,0.318768,1324.17,,31.8768,1.32417,,,,7.85398e-5
1:0.25 (rep 2),2-Recover,104.47,2.19,0.991,0.104,,0.311537,1324.17,,31.1537,1.32417,,,,7.85398e-5
1:0.25 (rep 2),2-Recover,104.837,2.214,0.967,0.091,,0.303992,1158.65,,30.3992,1.15865,,,,7.85398e-5
1:0.25 (rep 2),2-Recover,105.203,2.237,0.944,0.084,,0.296762,1069.52,,29.6762,1.06952,,,,7.85398e-5
1:0.25 (rep 2),2-Recover,105.57,2.261,0.92,0.104,,0.289217,1324.17,,28.9217,1.32417,,,,7.85398e-5
1:0.25 (rep 2),2-Recover,105.937,2.284,0.897,0.104,,0.281987,1324.17,,28.1987,1.32417,,,,7.85398e-5
1:0.25 (rep 2),2-Recover,106.303,2.307,0.874,0.091,,0.274756,1158.65,,27.4756,1.15865,,,,7.85398e-5
1:0.25 (rep 2),2-Recover,106.67,2.33,0.851,0.091,,0.267526,1158.65,,26.7526,1.15865,,,,7.85398e-5
1:0.25 (rep 2),2-Recover,107.037,2.354,0.827,0.084,,0.259981,1069.52,,25.9981,1.06952,,,,7.85398e-5
1:0.25 (rep 2),2-Recover,107.403,2.377,0.804,0.07,,0.252751,891.268,,25.2751,0.891268,,,,7.85398e-5
1:0.25 (rep 2),2-Recover,107.77,2.4,0.781,0.05,,0.24552,636.62,,24.552,0.63662,,,,7.85398e-5
1:0.25 (rep 2),2-Recover,108.137,2.424,0.757,0.064,,0.237975,814.873,,23.7975,0.814873,,,,7.85398e-5
1:0.25 (rep 2),2-Recover,108.503,2.447,0.734,0.077,,0.230745,980.395,,23.0745,0.980395,,,,7.85398e-5
1:0.25 (rep 2),2-Recover,108.87,2.471,0.71,0.064,,0.2232,814.873,,22.32,0.814873,,,,7.85398e-5
1:0.25 (rep 2),2-Recover,109.237,2.494,0.687,0.064,,0.21597,814.873,,21.597,0.814873,,,,7.85398e-5
1:0.25 (rep 2),2-Recover,109.603,2.517,0.664,0.05,,0.208739,636.62,,20.8739,0.63662,,,,7.85398e-5
1:0.25 (rep 2),2-Recover,109.97,2.541,0.64,0.05,,0.201195,636.62,,20.1195,0.63662,,,,7.85398e-5
1:0.25 (rep 2),2-Recover,110.337,2.564,0.617,0.05,,0.193964,636.62,,19.3964,0.63662,,,,7.85398e-5
1:0.25 (rep 2),2-Recover,110.703,2.587,0.594,0.064,,0.186734,814.873,,18.6734,0.814873,,,,7.85398e-5
1:0.25 (rep 2),2-Recover,111.07,2.611,0.57,0.064,,0.179189,814.873,,17.9189,0.814873,,,,7.85398e-5
1:0.25 (rep 2),2-Recover,111.437,2.634,0.547,0.057,,0.171959,725.747,,17.1959,0.725747,,,,7.85398e-5
1:0.25 (rep 2),2-Recover,111.803,2.657,0.524,0.05,,0.164728,636.62,,16.4728,0.63662,,,,7.85398e-5
1:0.25 (rep 2),2-Recover,112.17,2.681,0.5,0.05,,0.157183,636.62,,15.7183,0.63662,,,,7.85398e-5
1:0.25 (rep 2),2-Recover,112.537,2.705,0.476,0.05,,0.149638,636.62,,14.9638,0.63662,,,,7.85398e-5
1:0.25 (rep 2),2-Recover,112.903,2.727,0.454,0.05,,0.142722,636.62,,14.2722,0.63662,,,,7.85398e-5
1:0.25 (rep 2),2-Recover,113.27,2.751,0.43,0.057,,0.135178,725.747,,13.5178,0.725747,,,,7.85398e-5
1:0.25 (rep 2),2-Recover,113.637,2.775,0.406,0.05,,0.127633,636.62,,12.7633,0.63662,,,,7.85398e-5
1:0.25 (rep 2),2-Recover,114.003,2.798,0.383,0.05,,0.120402,636.62,,12.0402,0.63662,,,,7.85398e-5
1:0.25 (rep 2),2-Recover,114.37,2.821,0.36,0.05,,0.113172,636.62,,11.3172,0.63662,,,,7.85398e-5
1:0.25 (rep 2),2-Recover,114.737,2.845,0.336,0.05,,0.105627,636.62,,10.5627,0.63662,,,,7.85398e-5
1:0.25 (rep 2),2-Recover,115.103,2.868,0.313,0.05,,0.0983967,636.62,,9.83967,0.63662,,,,7.85398e-5
1:0.25 (rep 2),2-Recover,115.47,2.891,0.29,0.043,,0.0911663,547.493,,9.11663,0.547493,,,,7.85398e-5
1:0.25 (rep 2),2-Recover,115.837,2.915,0.266,0.05,,0.0836215,636.62,,8.36215,0.63662,,,,7.85398e-5
1:0.25 (rep 2),2-Recover,116.203,2.938,0.243,0.05,,0.0763911,636.62,,7.63911,0.63662,,,,7.85398e-5
1:0.25 (rep 2),2-Recover,116.57,2.961,0.22,0.05,,0.0691606,636.62,,6.91606,0.63662,,,,7.85398e-5
1:0.25 (rep 2),2-Recover,116.937,2.985,0.196,0.05,,0.0616158,636.62,,6.16158,0.63662,,,,7.85398e-5
1:0.25 (rep 2),2-Recover,117.303,3.008,0.173,0.05,,0.0543854,636.62,,5.43854,0.63662,,,,7.85398e-5
1:0.25 (rep 2),2-Recover,117.67,3.031,0.15,0.036,,0.047155,458.366,,4.7155,0.458366,,,,7.85398e-5
1:0.25 (rep 2),2-Recover,118.037,3.055,0.126,0.043,,0.0396102,547.493,,3.96102,0.547493,,,,7.85398e-5
1:0.25 (rep 2),2-Recover,118.403,3.078,0.103,0.043,,0.0323798,547.493,,3.23798,0.547493,,,,7.85398e-5
1:0.25 (rep 2),2-Recover,118.77,3.102,0.079,0.043,,0.024835,547.493,,2.4835,0.547493,,,,7.85398e-5
1:0.25 (rep 2),2-Recover,119.137,3.125,0.056,0.036,,0.0176045,458.366,,1.76045,0.458366,,,,7.85398e-5
1:0.25 (rep 2),2-Recover,119.503,3.148,0.033,0.03,,0.0103741,381.972,,1.03741,0.381972,,,,7.85398e-5
1:0.25 (rep 2),2-Recover,119.87,3.172,0.009,0.009,,0.0028293,114.592,,0.28293,0.114592,,,,7.85398e-5
1:0.25 (rep 2),3-Compress,120.213,3.173,0.008,0.036,,0.00251493,458.366,,0.251493,0.458366,,,,7.85398e-5
1:0.25 (rep 2),3-Compress,120.58,3.149,0.032,0.05,,0.0100597,636.62,,1.00597,0.63662,,,,7.85398e-5
1:0.25 (rep 2),3-Compress,120.947,3.126,0.055,0.043,,0.0172902,547.493,,1.72902,0.547493,,,,7.85398e-5
1:0.25 (rep 2),3-Compress,121.313,3.103,0.078,0.05,,0.0245206,636.62,,2.45206,0.63662,,,,7.85398e-5
1:0.25 (rep 2),3-Compress,121.68,3.079,0.102,0.05,,0.0320654,636.62,,3.20654,0.63662,,,,7.85398e-5
1:0.25 (rep 2),3-Compress,122.047,3.056,0.125,0.05,,0.0392958,636.62,,3.92958,0.63662,,,,7.85398e-5
1:0.25 (rep 2),3-Compress,122.413,3.033,0.148,0.05,,0.0465262,636.62,,4.65262,0.63662,,,,7.85398e-5
1:0.25 (rep 2),3-Compress,122.78,3.009,0.172,0.057,,0.054071,725.747,,5.4071,0.725747,,,,7.85398e-5
1:0.25 (rep 2),3-Compress,123.147,2.986,0.195,0.05,,0.0613015,636.62,,6.13015,0.63662,,,,7.85398e-5
1:0.25 (rep 2),3-Compress,123.513,2.963,0.218,0.05,,0.0685319,636.62,,6.85319,0.63662,,,,7.85398e-5
1:0.25 (rep 2),3-Compress,123.88,2.939,0.242,0.05,,0.0760767,636.62,,7.60767,0.63662,,,,7.85398e-5
1:0.25 (rep 2),3-Compress,124.247,2.915,0.266,0.05,,0.0836215,636.62,,8.36215,0.63662,,,,7.85398e-5
1:0.25 (rep 2),3-Compress,124.613,2.892,0.289,0.05,,0.0908519,636.62,,9.08519,0.63662,,,,7.85398e-5
1:0.25 (rep 2),3-Compress,124.98,2.869,0.312,0.05,,0.0980824,636.62,,9.80824,0.63662,,,,7.85398e-5
1:0.25 (rep 2),3-Compress,125.347,2.845,0.336,0.05,,0.105627,636.62,,10.5627,0.63662,,,,7.85398e-5
1:0.25 (rep 2),3-Compress,125.713,2.822,0.359,0.057,,0.112858,725.747,,11.2858,0.725747,,,,7.85398e-5
1:0.25 (rep 2),3-Compress,126.08,2.799,0.382,0.064,,0.120088,814.873,,12.0088,0.814873,,,,7.85398e-5
1:0.25 (rep 2),3-Compress,126.447,2.775,0.406,0.05,,0.127633,636.62,,12.7633,0.63662,,,,7.85398e-5
1:0.25 (rep 2),3-Compress,126.813,2.752,0.429,0.05,,0.134863,636.62,,13.4863,0.63662,,,,7.85398e-5
1:0.25 (rep 2),3-Compress,127.18,2.728,0.453,0.057,,0.142408,725.747,,14.2408,0.725747,,,,7.85398e-5
1:0.25 (rep 2),3-Compress,127.547,2.705,0.476,0.057,,0.149638,725.747,,14.9638,0.725747,,,,7.85398e-5
1:0.25 (rep 2),3-Compress,127.913,2.682,0.499,0.057,,0.156869,725.747,,15.6869,0.725747,,,,7.85398e-5
1:0.25 (rep 2),3-Compress,128.28,2.658,0.523,0.064,,0.164414,814.873,,16.4414,0.814873,,,,7.85398e-5
1:0.25 (rep 2),3-Compress,128.647,2.635,0.546,0.057,,0.171644,725.747,,17.1644,0.725747,,,,7.85398e-5
1:0.25 (rep 2),3-Compress,129.013,2.612,0.569,0.077,,0.178875,980.395,,17.8875,0.980395,,,,7.85398e-5
1:0.25 (rep 2),3-Compress,129.38,2.589,0.592,0.064,,0.186105,814.873,,18.6105,0.814873,,,,7.85398e-5
1:0.25 (rep 2),3-Compress,129.747,2.565,0.616,0.057,,0.19365,725.747,,19.365,0.725747,,,,7.85398e-5
1:0.25 (rep 2),3-Compress,130.113,2.542,0.639,0.07,,0.20088,891.268,,20.088,0.891268,,,,7.85398e-5
1:0.25 (rep 2),3-Compress,130.48,2.519,0.662,0.077,,0.208111,980.395,,20.8111,0.980395,,,,7.85398e-5
1:0.25 (rep 2),3-Compress,130.847,2.495,0.686,0.091,,0.215655,1158.65,,21.5655,1.15865,,,,7.85398e-5
1:0.25 (rep 2),3-Compress,131.213,2.472,0.709,0.098,,0.222886,1247.78,,22.2886,1.24778,,,,7.85398e-5
1:0.25 (rep 2),3-Compress,131.58,2.448,0.733,0.098,,0.230431,1247.78,,23.0431,1.24778,,,,7.85398e-5
1:0.25 (rep 2),3-Compress,131.947,2.425,0.756,0.104,,0.237661,1324.17,,23.7661,1.32417,,,,7.85398e-5
1:0.25 (rep 2),3-Compress,132.313,2.402,0.779,0.104,,0.244892,1324.17,,24.4892,1.32417,,,,7.85398e-5
1:0.25 (rep 2),3-Compress,132.68,2.378,0.803,0.104,,0.252436,1324.17,,25.2436,1.32417,,,,7.85398e-5
1:0.25 (rep 2),3-Compress,133.047,2.355,0.826,0.104,,0.259667,1324.17,,25.9667,1.32417,,,,7.85398e-5
1:0.25 (rep 2),3-Compress,133.413,2.332,0.849,0.104,,0.266897,1324.17,,26.6897,1.32417,,,,7.85398e-5
1:0.25 (rep 2),3-Compress,133.78,2.308,0.873,0.104,,0.274442,1324.17,,27.4442,1.32417,,,,7.85398e-5
1:0.25 (rep 2),3-Compress,134.147,2.284,0.897,0.104,,0.281987,1324.17,,28.1987,1.32417,,,,7.85398e-5
1:0.25 (rep 2),3-Compress,134.513,2.261,0.92,0.104,,0.289217,1324.17,,28.9217,1.32417,,,,7.85398e-5
1:0.25 (rep 2),3-Compress,134.88,2.238,0.943,0.104,,0.296448,1324.17,,29.6448,1.32417,,,,7.85398e-5
1:0.25 (rep 2),3-Compress,135.247,2.214,0.967,0.104,,0.303992,1324.17,,30.3992,1.32417,,,,7.85398e-5
1:0.25 (rep 2),3-Compress,135.613,2.191,0.99,0.104,,0.311223,1324.17,,31.1223,1.32417,,,,7.85398e-5
1:0.25 (rep 2),3-Compress,135.98,2.168,1.013,0.104,,0.318453,1324.17,,31.8453,1.32417,,,,7.85398e-5
1:0.25 (rep 2),3-Compress,136.347,2.144,1.037,0.104,,0.325998,1324.17,,32.5998,1.32417,,,,7.85398e-5
1:0.25 (rep 2),3-Compress,136.713,2.121,1.06,0.111,,0.333229,1413.3,,33.3229,1.4133,,,,7.85398e-5
1:0.25 (rep 2),3-Compress,137.08,2.097,1.084,0.111,,0.340773,1413.3,,34.0773,1.4133,,,,7.85398e-5
1:0.25 (rep 2),3-Compress,137.447,2.074,1.107,0.111,,0.348004,1413.3,,34.8004,1.4133,,,,7.85398e-5
1:0.25 (rep 2),3-Compress,137.813,2.051,1.13,0.104,,0.355234,1324.17,,35.5234,1.32417,,,,7.85398e-5
1:0.25 (rep 2),3-Compress,138.18,2.028,1.153,0.111,,0.362465,1413.3,,36.2465,1.4133,,,,7.85398e-5
1:0.25 (rep 2),3-Compress,138.547,2.004,1.177,0.125,,0.370009,1591.55,,37.0009,1.59155,,,,7.85398e-5
1:0.25 (rep 2),3-Compress,138.913,1.981,1.2,0.131,,0.37724,1667.94,,37.724,1.66794,,,,7.85398e-5
1:0.25 (rep 2),3-Compress,139.28,1.958,1.223,0.125,,0.38447,1591.55,,38.447,1.59155,,,,7.85398e-5
1:0.25 (rep 2),3-Compress,139.647,1.934,1.247,0.152,,0.392015,1935.32,,39.2015,1.93532,,,,7.85398e-5
1:0.25 (rep 2),3-Compress,140.013,1.911,1.27,0.125,,0.399246,1591.55,,39.9246,1.59155,,,,7.85398e-5
1:0.25 (rep 2),3-Compress,140.38,1.888,1.293,0.138,,0.406476,1757.07,,40.6476,1.75707,,,,7.85398e-5
1:0.25 (rep 2),3-Compress,140.747,1.864,1.317,0.125,,0.414021,1591.55,,41.4021,1.59155,,,,7.85398e-5
1:0.25 (rep 2),3-Compress,141.113,1.841,1.34,0.152,,0.421251,1935.32,,42.1251,1.93532,,,,7.85398e-5
1:0.25 (rep 2),3-Compress,141.48,1.817,1.364,0.159,,0.428796,2024.45,,42.8796,2.02445,,,,7.85398e-5
1:0.25 (rep 2),3-Compress,141.847,1.794,1.387,0.159,,0.436026,2024.45,,43.6026,2.02445,,,,7.85398e-5
1:0.25 (rep 2),3-Compress,142.213,1.771,1.41,0.159,,0.443257,2024.45,,44.3257,2.02445,,,,7.85398e-5
1:0.25 (rep 2),3-Compress,142.58,1.747,1.434,0.159,,0.450802,2024.45,,45.0802,2.02445,,,,7.85398e-5
1:0.25 (rep 2),3-Compress,142.947,1.724,1.457,0.159,,0.458032,2024.45,,45.8032,2.02445,,,,7.85398e-5
1:0.25 (rep 2),3-Compress,143.313,1.701,1.48,0.152,,0.465262,1935.32,,46.5262,1.93532,,,,7.85398e-5
1:0.25 (rep 2),3-Compress,143.68,1.677,1.504,0.159,,0.472807,2024.45,,47.2807,2.02445,,,,7.85398e-5
1:0.25 (rep 2),3-Compress,144.047,1.653,1.528,0.152,,0.480352,1935.32,,48.0352,1.93532,,,,7.85398e-5
1:0.25 (rep 2),3-Compress,144.413,1.631,1.55,0.159,,0.487268,2024.45,,48.7268,2.02445,,,,7.85398e-5
1:0.25 (rep 2),3-Compress,144.78,1.607,1.574,0.159,,0.494813,2024.45,,49.4813,2.02445,,,,7.85398e-5
1:0.25 (rep 2),3-Compress,145.147,1.583,1.598,0.159,,0.502358,2024.45,,50.2358,2.02445,,,,7.85398e-5
1:0.25 (rep 2),3-Compress,145.513,1.56,1.621,0.159,,0.509588,2024.45,,50.9588,2.02445,,,,7.85398e-5
1:0.25 (rep 2),3-Compress,145.88,1.537,1.644,0.172,,0.516819,2189.97,,51.6819,2.18997,,,,7.85398e-5
1:0.25 (rep 2),3-Compress,146.247,1.513,1.668,0.159,,0.524363,2024.45,,52.4363,2.02445,,,,7.85398e-5
1:0.25 (rep 2),3-Compress,146.613,1.49,1.691,0.172,,0.531594,2189.97,,53.1594,2.18997,,,,7.85398e-5
1:0.25 (rep 2),3-Compress,146.98,1.467,1.714,0.179,,0.538824,2279.1,,53.8824,2.2791,,,,7.85398e-5
1:0.25 (rep 2),3-Compress,147.347,1.443,1.738,0.206,,0.546369,2622.87,,54.6369,2.62287,,,,7.85398e-5
1:0.25 (rep 2),3-Compress,147.713,1.42,1.761,0.213,,0.553599,2712,,55.3599,2.712,,,,7.85398e-5
1:0.25 (rep 2),3-Compress,148.08,1.397,1.784,0.206,,0.56083,2622.87,,56.083,2.62287,,,,7.85398e-5
1:0.25 (rep 2),3-Compress,148.447,1.373,1.808,0.193,,0.568375,2457.35,,56.8375,2.45735,,,,7.85398e-5
1:0.25 (rep 2),3-Compress,148.813,1.35,1.831,0.193,,0.575605,2457.35,,57.5605,2.45735,,,,7.85398e-5
1:0.25 (rep 2),3-Compress,149.18,1.327,1.854,0.193,,0.582836,2457.35,,58.2836,2.45735,,,,7.85398e-5
1:0.25 (rep 2),3-Compress,149.547,1.303,1.878,0.206,,0.59038,2622.87,,59.038,2.62287,,,,7.85398e-5
1:0.25 (rep 2),3-Compress,149.913,1.28,1.901,0.213,,0.597611,2712,,59.7611,2.712,,,,7.85398e-5
1:0.25 (rep 2),3-Recover,150.267,1.283,1.898,0.213,,0.596668,2712,,59.6668,2.712,,,,7.85398e-5
1:0.25 (rep 2),3-Recover,150.633,1.305,1.876,0.213,,0.589752,2712,,58.9752,2.712,,,,7.85398e-5
1:0.25 (rep 2),3-Recover,151,1.329,1.852,0.206,,0.582207,2622.87,,58.2207,2.62287,,,,7.85398e-5
1:0.25 (rep 2),3-Recover,151.367,1.353,1.828,0.186,,0.574662,2368.23,,57.4662,2.36823,,,,7.85398e-5
1:0.25 (rep 2),3-Recover,151.733,1.376,1.805,0.193,,0.567432,2457.35,,56.7432,2.45735,,,,7.85398e-5
1:0.25 (rep 2),3-Recover,152.1,1.399,1.782,0.199,,0.560201,2533.75,,56.0201,2.53375,,,,7.85398e-5
1:0.25 (rep 2),3-Recover,152.467,1.423,1.758,0.186,,0.552656,2368.23,,55.2656,2.36823,,,,7.85398e-5
1:0.25 (rep 2),3-Recover,152.833,1.446,1.735,0.165,,0.545426,2100.85,,54.5426,2.10085,,,,7.85398e-5
1:0.25 (rep 2),3-Recover,153.2,1.469,1.712,0.165,,0.538196,2100.85,,53.8196,2.10085,,,,7.85398e-5
1:0.25 (rep 2),3-Recover,153.567,1.493,1.688,0.165,,0.530651,2100.85,,53.0651,2.10085,,,,7.85398e-5
1:0.25 (rep 2),3-Recover,153.933,1.516,1.665,0.145,,0.52342,1846.2,,52.342,1.8462,,,,7.85398e-5
1:0.25 (rep 2),3-Recover,154.3,1.54,1.641,0.159,,0.515876,2024.45,,51.5876,2.02445,,,,7.85398e-5
1:0.25 (rep 2),3-Recover,154.667,1.563,1.618,0.165,,0.508645,2100.85,,50.8645,2.10085,,,,7.85398e-5
1:0.25 (rep 2),3-Recover,155.033,1.586,1.595,0.159,,0.501415,2024.45,,50.1415,2.02445,,,,7.85398e-5
1:0.25 (rep 2),3-Recover,155.4,1.61,1.571,0.159,,0.49387,2024.45,,49.387,2.02445,,,,7.85398e-5
1:0.25 (rep 2),3-Recover,155.767,1.634,1.547,0.152,,0.486325,1935.32,,48.6325,1.93532,,,,7.85398e-5
1:0.25 (rep 2),3-Recover,156.133,1.656,1.525,0.152,,0.479409,1935.32,,47.9409,1.93532,,,,7.85398e-5
1:0.25 (rep 2),3-Recover,156.5,1.68,1.501,0.159,,0.471864,2024.45,,47.1864,2.02445,,,,7.85398e-5
1:0.25 (rep 2),3-Recover,156.867,1.703,1.478,0.159,,0.464634,2024.45,,46.4634,2.02445,,,,7.85398e-5
1:0.25 (rep 2),3-Recover,157.233,1.727,1.454,0.152,,0.457089,1935.32,,45.7089,1.93532,,,,7.85398e-5
1:0.25 (rep 2),3-Recover,157.6,1.75,1.431,0.125,,0.449859,1591.55,,44.9859,1.59155,,,,7.85398e-5
1:0.25 (rep 2),3-Recover,157.967,1.773,1.408,0.125,,0.442628,1591.55,,44.2628,1.59155,,,,7.85398e-5
1:0.25 (rep 2),3-Recover,158.333,1.797,1.384,0.111,,0.435083,1413.3,,43.5083,1.4133,,,,7.85398e-5
1:0.25 (rep 2),3-Recover,158.7,1.82,1.361,0.118,,0.427853,1502.42,,42.7853,1.50242,,,,7.85398e-5
1:0.25 (rep 2),3-Recover,159.067,1.843,1.338,0.131,,0.420622,1667.94,,42.0622,1.66794,,,,7.85398e-5
1:0.25 (rep 2),3-Recover,159.433,1.866,1.315,0.125,,0.413392,1591.55,,41.3392,1.59155,,,,7.85398e-5
1:0.25 (rep 2),3-Recover,159.8,1.89,1.291,0.118,,0.405847,1502.42,,40.5847,1.50242,,,,7.85398e-5
1:0.25 (rep 2),3-Recover,160.167,1.914,1.267,0.111,,0.398302,1413.3,,39.8302,1.4133,,,,7.85398e-5
1:0.25 (rep 2),3-Recover,160.533,1.936,1.245,0.104,,0.391386,1324.17,,39.1386,1.32417,,,,7.85398e-5
1:0.25 (rep 2),3-Recover,160.9,1.96,1.221,0.111,,0.383842,1413.3,,38.3842,1.4133,,,,7.85398e-5
1:0.25 (rep 2),3-Recover,161.267,1.984,1.197,0.111,,0.376297,1413.3,,37.6297,1.4133,,,,7.85398e-5
1:0.25 (rep 2),3-Recover,161.633,2.007,1.174,0.104,,0.369066,1324.17,,36.9066,1.32417,,,,7.85398e-5
1:0.25 (rep 2),3-Recover,162,2.03,1.151,0.104,,0.361836,1324.17,,36.1836,1.32417,,,,7.85398e-5
1:0.25 (rep 2),3-Recover,162.367,2.054,1.127,0.104,,0.354291,1324.17,,35.4291,1.32417,,,,7.85398e-5
1:0.25 (rep 2),3-Recover,162.733,2.077,1.104,0.104,,0.347061,1324.17,,34.7061,1.32417,,,,7.85398e-5
1:0.25 (rep 2),3-Recover,163.1,2.1,1.081,0.104,,0.33983,1324.17,,33.983,1.32417,,,,7.85398e-5
1:0.25 (rep 2),3-Recover,163.467,2.124,1.057,0.104,,0.332285,1324.17,,33.2285,1.32417,,,,7.85398e-5
1:0.25 (rep 2),3-Recover,163.833,2.147,1.034,0.098,,0.325055,1247.78,,32.5055,1.24778,,,,7.85398e-5
1:0.25 (rep 2),3-Recover,164.2,2.171,1.01,0.098,,0.31751,1247.78,,31.751,1.24778,,,,7.85398e-5
1:0.25 (rep 2),3-Recover,164.567,2.194,0.987,0.098,,0.31028,1247.78,,31.028,1.24778,,,,7.85398e-5
1:0.25 (rep 2),3-Recover,164.933,2.217,0.964,0.098,,0.303049,1247.78,,30.3049,1.24778,,,,7.85398e-5
1:0.25 (rep 2),3-Recover,165.3,2.241,0.94,0.084,,0.295505,1069.52,,29.5505,1.06952,,,,7.85398e-5
1:0.25 (rep 2),3-Recover,165.667,2.264,0.917,0.064,,0.288274,814.873,,28.8274,0.814873,,,,7.85398e-5
1:0.25 (rep 2),3-Recover,166.033,2.287,0.894,0.098,,0.281044,1247.78,,28.1044,1.24778,,,,7.85398e-5
1:0.25 (rep 2),3-Recover,166.4,2.311,0.87,0.091,,0.273499,1158.65,,27.3499,1.15865,,,,7.85398e-5
1:0.25 (rep 2),3-Recover,166.767,2.334,0.847,0.077,,0.266268,980.395,,26.6268,0.980395,,,,7.85398e-5
1:0.25 (rep 2),3-Recover,167.133,2.357,0.824,0.077,,0.259038,980.395,,25.9038,0.980395,,,,7.85398e-5
1:0.25 (rep 2),3-Recover,167.5,2.381,0.8,0.064,,0.251493,814.873,,25.1493,0.814873,,,,7.85398e-5
1:0.25 (rep 2),3-Recover,167.867,2.404,0.777,0.057,,0.244263,725.747,,24.4263,0.725747,,,,7.85398e-5
1:0.25 (rep 2),3-Recover,168.233,2.427,0.754,0.05,,0.237032,636.62,,23.7032,0.63662,,,,7.85398e-5
1:0.25 (rep 2),3-Recover,168.6,2.451,0.73,0.064,,0.229488,814.873,,22.9488,0.814873,,,,7.85398e-5
1:0.25 (rep 2),3-Recover,168.967,2.474,0.707,0.07,,0.222257,891.268,,22.2257,0.891268,,,,7.85398e-5
1:0.25 (rep 2),3-Recover,169.333,2.497,0.684,0.057,,0.215027,725.747,,21.5027,0.725747,,,,7.85398e-5
1:0.25 (rep 2),3-Recover,169.7,2.521,0.66,0.057,,0.207482,725.747,,20.7482,0.725747,,,,7.85398e-5
1:0.25 (rep 2),3-Recover,170.067,2.545,0.636,0.057,,0.199937,725.747,,19.9937,0.725747,,,,7.85398e-5
1:0.25 (rep 2),3-Recover,170.433,2.567,0.614,0.05,,0.193021,636.62,,19.3021,0.63662,,,,7.85398e-5
1:0.25 (rep 2),3-Recover,170.8,2.591,0.59,0.057,,0.185476,725.747,,18.5476,0.725747,,,,7.85398e-5
1:0.25 (rep 2),3-Recover,171.167,2.615,0.566,0.05,,0.177931,636.62,,17.7931,0.63662,,,,7.85398e-5
1:0.25 (rep 2),3-Recover,171.533,2.638,0.543,0.05,,0.170701,636.62,,17.0701,0.63662,,,,7.85398e-5
1:0.25 (rep 2),3-Recover,171.9,2.661,0.52,0.05,,0.163471,636.62,,16.3471,0.63662,,,,7.85398e-5
1:0.25 (rep 2),3-Recover,172.267,2.685,0.496,0.05,,0.155926,636.62,,15.5926,0.63662,,,,7.85398e-5
1:0.25 (rep 2),3-Recover,172.633,2.708,0.473,0.05,,0.148695,636.62,,14.8695,0.63662,,,,7.85398e-5
1:0.25 (rep 2),3-Recover,173,2.731,0.45,0.05,,0.141465,636.62,,14.1465,0.63662,,,,7.85398e-5
1:0.25 (rep 2),3-Recover,173.367,2.755,0.426,0.05,,0.13392,636.62,,13.392,0.63662,,,,7.85398e-5
1:0.25 (rep 2),3-Recover,173.733,2.778,0.403,0.05,,0.12669,636.62,,12.669,0.63662,,,,7.85398e-5
1:0.25 (rep 2),3-Recover,174.1,2.802,0.379,0.05,,0.119145,636.62,,11.9145,0.63662,,,,7.85398e-5
1:0.25 (rep 2),3-Recover,174.467,2.825,0.356,0.05,,0.111914,636.62,,11.1914,0.63662,,,,7.85398e-5
1:0.25 (rep 2),3-Recover,174.833,2.848,0.333,0.05,,0.104684,636.62,,10.4684,0.63662,,,,7.85398e-5
1:0.25 (rep 2),3-Recover,175.2,2.872,0.309,0.05,,0.0971393,636.62,,9.71393,0.63662,,,,7.85398e-5
1:0.25 (rep 2),3-Recover,175.567,2.895,0.286,0.05,,0.0899088,636.62,,8.99088,0.63662,,,,7.85398e-5
1:0.25 (rep 2),3-Recover,175.933,2.918,0.263,0.05,,0.0826784,636.62,,8.26784,0.63662,,,,7.85398e-5
1:0.25 (rep 2),3-Recover,176.3,2.942,0.239,0.05,,0.0751336,636.62,,7.51336,0.63662,,,,7.85398e-5
1:0.25 (rep 2),3-Recover,176.667,2.965,0.216,0.05,,0.0679032,636.62,,6.79032,0.63662,,,,7.85398e-5
1:0.25 (rep 2),3-Recover,177.033,2.988,0.193,0.05,,0.0606727,636.62,,6.06727,0.63662,,,,7.85398e-5
1:0.25 (rep 2),3-Recover,177.4,3.012,0.169,0.05,,0.0531279,636.62,,5.31279,0.63662,,,,7.85398e-5
1:0.25 (rep 2),3-Recover,177.767,3.035,0.146,0.05,,0.0458975,636.62,,4.58975,0.63662,,,,7.85398e-5
1:0.25 (rep 2),3-Recover,178.133,3.058,0.123,0.023,,0.0386671,292.845,,3.86671,0.292845,,,,7.85398e-5
1:0.25 (rep 2),3-Recover,178.5,3.082,0.099,0.03,,0.0311223,381.972,,3.11223,0.381972,,,,7.85398e-5
1:0.25 (rep 2),3-Recover,178.867,3.105,0.076,0.036,,0.0238919,458.366,,2.38919,0.458366,,,,7.85398e-5
1:0.25 (rep 2),3-Recover,179.233,3.128,0.053,0.043,,0.0166614,547.493,,1.66614,0.547493,,,,7.85398e-5
1:0.25 (rep 2),3-Recover,179.6,3.152,0.029,0.03,,0.00911663,381.972,,0.911663,0.381972,,,,7.85398e-5
1:0.25 (rep 2),3-Recover,179.967,3.176,0.005,0.036,,0.00157183,458.366,,0.157183,0.458366,,,,7.85398e-5
1:0.25 (rep 2),3-Recover,180.1,3.181,0,0.036,,0,458.366,,0,0.458366,,,,7.85398e-5