File: data/beta_1-1_3.csv
SetName,Cycle,Time_S,Size_mm,Displacement_mm,Force_N,,Strain,Stress(Pascal),,%Strain,Stress(kPa),,,,Area(m^2)
1:1 (rep 3),1-Compress,0,2.815,0,-0.004,,0,-50.9296,,0,-0.0509296,,,,7.85398e-5
1:1 (rep 3),1-Compress,0.367,2.794,0.021,-0.004,,0.00746004,-50.9296,,0.746004,-0.0509296,,,,7.85398e-5
1:1 (rep 3),1-Compress,0.733,2.774,0.041,-0.004,,0.0145648,-50.9296,,1.45648,-0.0509296,,,,7.85398e-5
1:1 (rep 3),1-Compress,1.1,2.754,0.061,-0.004,,0.0216696,-50.9296,,2.16696,-0.0509296,,,,7.85398e-5
1:1 (rep 3),1-Compress,1.467,2.732,0.083,0.009,,0.0294849,114.592,,2.94849,0.114592,,,,7.85398e-5
1:1 (rep 3),1-Compress,1.833,2.712,0.103,0.016,,0.0365897,203.718,,3.65897,0.203718,,,,7.85398e-5
1:1 (rep 3),1-Compress,2.2,2.691,0.124,0.002,,0.0440497,25.4648,,4.40497,0.0254648,,,,7.85398e-5
1:1 (rep 3),1-Compress,2.567,2.67,0.145,-0.004,,0.0515098,-50.9296,,5.15098,-0.0509296,,,,7.85398e-5
1:1 (rep 3),1-Compress,2.933,2.65,0.165,-0.004,,0.0586146,-50.9296,,5.86146,-0.0509296,,,,7.85398e-5
1:1 (rep 3),1-Compress,3.3,2.629,0.186,-0.004,,0.0660746,-50.9296,,6.60746,-0.0509296,,,,7.85398e-5
1:1 (rep 3),1-Compress,3.667,2.608,0.207,0.002,,0.0735346,25.4648,,7.35346,0.0254648,,,,7.85398e-5
1:1 (rep 3),1-Compress,4.033,2.588,0.227,0.002,,0.0806394,25.4648,,8.06394,0.0254648,,,,7.85398e-5
1:1 (rep 3),1-Compress,4.4,2.567,0.248,0.009,,0.0880995,114.592,,8.80995,0.114592,,,,7.85398e-5
1:1 (rep 3),1-Compress,4.767,2.546,0.269,0.002,,0.0955595,25.4648,,9.55595,0.0254648,,,,7.85398e-5
1:1 (rep 3),1-Compress,5.133,2.526,0.289,0.002,,0.102664,25.4648,,10.2664,0.0254648,,,,7.85398e-5
1:1 (rep 3),1-Compress,5.5,2.505,0.31,0.002,,0.110124,25.4648,,11.0124,0.0254648,,,,7.85398e-5
1:1 (rep 3),1-Compress,5.867,2.484,0.331,-0.004,,0.117584,-50.9296,,11.7584,-0.0509296,,,,7.85398e-5
1:1 (rep 3),1-Compress,6.233,2.464,0.351,0.002,,0.124689,25.4648,,12.4689,0.0254648,,,,7.85398e-5
1:1 (rep 3),1-Compress,6.6,2.443,0.372,0.002,,0.132149,25.4648,,13.2149,0.0254648,,,,7.85398e-5
1:1 (rep 3),1-Compress,6.967,2.422,0.393,0.009,,0.139609,114.592,,13.9609,0.114592,,,,7.85398e-5
1:1 (rep 3),1-Compress,7.333,2.402,0.413,0.002,,0.146714,25.4648,,14.6714,0.0254648,,,,7.85398e-5
1:1 (rep 3),1-Compress,7.7,2.381,0.434,-0.004,,0.154174,-50.9296,,15.4174,-0.0509296,,,,7.85398e-5
1:1 (rep 3),1-Compress,8.067,2.36,0.455,0.002,,0.161634,25.4648,,16.1634,0.0254648,,,,7.85398e-5
1:1 (rep 3),1-Compress,8.433,2.34,0.475,-0.004,,0.168739,-50.9296,,16.8739,-0.0509296,,,,7.85398e-5
1:1 (rep 3),1-Compress,8.8,2.319,0.496,0.002,,0.176199,25.4648,,17.6199,0.0254648,,,,7.85398e-5
1:1 (rep 3),1-Compress,9.167,2.298,0.517,0.002,,0.183659,25.4648,,18.3659,0.0254648,,,,7.85398e-5
1:1 (rep 3),1-Compress,9.533,2.278,0.537,0.016,,0.190764,203.718,,19.0764,0.203718,,,,7.85398e-5
1:1 (rep 3),1-Compress,9.9,2.257,0.558,-0.004,,0.198224,-50.9296,,19.8224,-0.0509296,,,,7.85398e-5
1:1 (rep 3),1-Compress,10.267,2.236,0.579,0.002,,0.205684,25.4648,,20.5684,0.0254648,,,,7.85398e-5
1:1 (rep 3),1-Compress,10.633,2.216,0.599,0.002,,0.212789,25.4648,,21.2789,0.0254648,,,,7.85398e-5
1:1 (rep 3),1-Compress,11,2.195,0.62,0.002,,0.220249,25.4648,,22.0249,0.0254648,,,,7.85398e-5
1:1 (rep 3),1-Compress,11.367,2.174,0.641,0.002,,0.227709,25.4648,,22.7709,0.0254648,,,,7.85398e-5
1:1 (rep 3),1-Compress,11.733,2.154,0.661,0.009,,0.234813,114.592,,23.4813,0.114592,,,,7.85398e-5
1:1 (rep 3),1-Compress,12.1,2.133,0.682,0.009,,0.242274,114.592,,24.2274,0.114592,,,,7.85398e-5
1:1 (rep 3),1-Compress,12.467,2.112,0.703,0.009,,0.249734,114.592,,24.9734,0.114592,,,,7.85398e-5
1:1 (rep 3),1-Compress,12.833,2.092,0.723,0.002,,0.256838,25.4648,,25.6838,0.0254648,,,,7.85398e-5
1:1 (rep 3),1-Compress,13.2,2.071,0.744,0.002,,0.264298,25.4648,,26.4298,0.0254648,,,,7.85398e-5
1:1 (rep 3),1-Compress,13.567,2.05,0.765,0.002,,0.271758,25.4648,,27.1758,0.0254648,,,,7.85398e-5
1:1 (rep 3),1-Compress,13.933,2.03,0.785,0.002,,0.278863,25.4648,,27.8863,0.0254648,,,,7.85398e-5
1:1 (rep 3),1-Compress,14.3,2.009,0.806,0.009,,0.286323,114.592,,28.6323,0.114592,,,,7.85398e-5
1:1 (rep 3),1-Compress,14.667,1.988,0.827,0.009,,0.293783,114.592,,29.3783,0.114592,,,,7.85398e-5
1:1 (rep 3),1-Compress,15.033,1.968,0.847,0.009,,0.300888,114.592,,30.0888,0.114592,,,,7.85398e-5
1:1 (rep 3),1-Compress,15.4,1.947,0.868,0.009,,0.308348,114.592,,30.8348,0.114592,,,,7.85398e-5
1:1 (rep 3),1-Compress,15.767,1.926,0.889,0.002,,0.315808,25.4648,,31.5808,0.0254648,,,,7.85398e-5
1:1 (rep 3),1-Compress,16.133,1.906,0.909,0.002,,0.322913,25.4648,,32.2913,0.0254648,,,,7.85398e-5
1:1 (rep 3),1-Compress,16.5,1.885,0.93,0.002,,0.330373,25.4648,,33.0373,0.0254648,,,,7.85398e-5
1:1 (rep 3),1-Compress,16.867,1.864,0.951,0.009,,0.337833,114.592,,33.7833,0.114592,,,,7.85398e-5
1:1 (rep 3),1-Compress,17.233,1.844,0.971,0.016,,0.344938,203.718,,34.4938,0.203718,,,,7.85398e-5
1:1 (rep 3),1-Compress,17.6,1.823,0.992,0.009,,0.352398,114.592,,35.2398,0.114592,,,,7.85398e-5
1:1 (rep 3),1-Compress,17.967,1.802,1.013,0.002,,0.359858,25.4648,,35.9858,0.0254648,,,,7.85398e-5
1:1 (rep 3),1-Compress,18.333,1.782,1.033,0.009,,0.366963,114.592,,36.6963,0.114592,,,,7.85398e-5
1:1 (rep 3),1-Compress,18.7,1.761,1.054,0.002,,0.374423,25.4648,,37.4423,0.0254648,,,,7.85398e-5
1:1 (rep 3),1-Compress,19.067,1.74,1.075,0.002,,0.381883,25.4648,,38.1883,0.0254648,,,,7.85398e-5
1:1 (rep 3),1-Compress,19.433,1.72,1.095,0.009,,0.388988,114.592,,38.8988,0.114592,,,,7.85398e-5
1:1 (rep 3),1-Compress,19.8,1.699,1.116,0.016,,0.396448,203.718,,39.6448,0.203718,,,,7.85398e-5
1:1 (rep 3),1-Compress,20.167,1.678,1.137,0.016,,0.403908,203.718,,40.3908,0.203718,,,,7.85398e-5
1:1 (rep 3),1-Compress,20.533,1.658,1.157,0.009,,0.411012,114.592,,41.1012,0.114592,,,,7.85398e-5
1:1 (rep 3),1-Compress,20.9,1.637,1.178,0.002,,0.418472,25.4648,,41.8472,0.0254648,,,,7.85398e-5
1:1 (rep 3),1-Compress,21.267,1.616,1.199,0.002,,0.425933,25.4648,,42.5933,0.0254648,,,,7.85398e-5
1:1 (rep 3),1-Compress,21.633,1.596,1.219,0.002,,0.433037,25.4648,,43.3037,0.0254648,,,,7.85398e-5
1:1 (rep 3),1-Compress,22,1.575,1.24,0.009,,0.440497,114.592,,44.0497,0.114592,,,,7.85398e-5
1:1 (rep 3),1-Compress,22.367,1.554,1.261,0.009,,0.447957,114.592,,44.7957,0.114592,,,,7.85398e-5
1:1 (rep 3),1-Compress,22.733,1.534,1.281,0.023,,0.455062,292.845,,45.5062,0.292845,,,,7.85398e-5
1:1 (rep 3),1-Compress,23.1,1.513,1.302,0.016,,0.462522,203.718,,46.2522,0.203718,,,,7.85398e-5
1:1 (rep 3),1-Compress,23.467,1.492,1.323,0.002,,0.469982,25.4648,,46.9982,0.0254648,,,,7.85398e-5
1:1 (rep 3),1-Compress,23.833,1.472,1.343,0.002,,0.477087,25.4648,,47.7087,0.0254648,,,,7.85398e-5
1:1 (rep 3),1-Compress,24.2,1.451,1.364,0.023,,0.484547,292.845,,48.4547,0.292845,,,,7.85398e-5
1:1 (rep 3),1-Compress,24.567,1.43,1.385,0.016,,0.492007,203.718,,49.2007,0.203718,,,,7.85398e-5
1:1 (rep 3),1-Compress,24.933,1.41,1.405,0.023,,0.499112,292.845,,49.9112,0.292845,,,,7.85398e-5
1:1 (rep 3),1-Compress,25.3,1.389,1.426,0.023,,0.506572,292.845,,50.6572,0.292845,,,,7.85398e-5
1:1 (rep 3),1-Compress,25.667,1.368,1.447,0.016,,0.514032,203.718,,51.4032,0.203718,,,,7.85398e-5
1:1 (rep 3),1-Compress,26.033,1.348,1.467,0.016,,0.521137,203.718,,52.1137,0.203718,,,,7.85398e-5
1:1 (rep 3),1-Compress,26.4,1.327,1.488,0.016,,0.528597,203.718,,52.8597,0.203718,,,,7.85398e-5
1:1 (rep 3),1-Compress,26.767,1.305,1.51,0.009,,0.536412,114.592,,53.6412,0.114592,,,,7.85398e-5
1:1 (rep 3),1-Compress,27.133,1.286,1.529,0.036,,0.543162,458.366,,54.3162,0.458366,,,,7.85398e-5
1:1 (rep 3),1-Compress,27.5,1.265,1.55,0.036,,0.550622,458.366,,55.0622,0.458366,,,,7.85398e-5
1:1 (rep 3),1-Compress,27.867,1.244,1.571,0.023,,0.558082,292.845,,55.8082,0.292845,,,,7.85398e-5
1:1 (rep 3),1-Compress,28.233,1.224,1.591,0.03,,0.565187,381.972,,56.5187,0.381972,,,,7.85398e-5
1:1 (rep 3),1-Compress,28.6,1.203,1.612,0.036,,0.572647,458.366,,57.2647,0.458366,,,,7.85398e-5
1:1 (rep 3),1-Compress,28.967,1.182,1.633,0.036,,0.580107,458.366,,58.0107,0.458366,,,,7.85398e-5
1:1 (rep 3),1-Compress,29.333,1.162,1.653,0.036,,0.587211,458.366,,58.7211,0.458366,,,,7.85398e-5
1:1 (rep 3),1-Compress,29.7,1.14,1.675,0.03,,0.595027,381.972,,59.5027,0.381972,,,,7.85398e-5
1:1 (rep 3),1-Recover,30.067,1.128,1.687,0.036,,0.59929,458.366,,59.929,0.458366,,,,7.85398e-5
1:1 (rep 3),1-Recover,30.433,1.149,1.666,0.043,,0.591829,547.493,,59.1829,0.547493,,,,7.85398e-5
1:1 (rep 3),1-Recover,30.8,1.169,1.646,0.03,,0.584725,381.972,,58.4725,0.381972,,,,7.85398e-5
1:1 (rep 3),1-Recover,31.167,1.19,1.625,0.023,,0.577265,292.845,,57.7265,0.292845,,,,7.85398e-5
1:1 (rep 3),1-Recover,31.533,1.211,1.604,0.03,,0.569805,381.972,,56.9805,0.381972,,,,7.85398e-5
1:1 (rep 3),1-Recover,31.9,1.231,1.584,0.009,,0.5627,114.592,,56.27,0.114592,,,,7.85398e-5
1:1 (rep 3),1-Recover,32.267,1.252,1.563,0.036,,0.55524,458.366,,55.524,0.458366,,,,7.85398e-5
1:1 (rep 3),1-Recover,32.633,1.273,1.542,0.03,,0.54778,381.972,,54.778,0.381972,,,,7.85398e-5
1:1 (rep 3),1-Recover,33,1.293,1.522,0.03,,0.540675,381.972,,54.0675,0.381972,,,,7.85398e-5
1:1 (rep 3),1-Recover,33.367,1.314,1.501,0.016,,0.533215,203.718,,53.3215,0.203718,,,,7.85398e-5
1:1 (rep 3),1-Recover,33.733,1.335,1.48,0.002,,0.525755,25.4648,,52.5755,0.0254648,,,,7.85398e-5
1:1 (rep 3),1-Recover,34.1,1.355,1.46,0.016,,0.51865,203.718,,51.865,0.203718,,,,7.85398e-5
1:1 (rep 3),1-Recover,34.467,1.376,1.439,0.009,,0.51119,114.592,,51.119,0.114592,,,,7.85398e-5
1:1 (rep 3),1-Recover,34.833,1.397,1.418,0.03,,0.50373,381.972,,50.373,0.381972,,,,7.85398e-5
1:1 (rep 3),1-Recover,35.2,1.417,1.398,0.03,,0.496625,381.972,,49.6625,0.381972,,,,7.85398e-5
1:1 (rep 3),1-Recover,35.567,1.438,1.377,0.016,,0.489165,203.718,,48.9165,0.203718,,,,7.85398e-5
1:1 (rep 3),1-Recover,35.933,1.459,1.356,0.009,,0.481705,114.592,,48.1705,0.114592,,,,7.85398e-5
1:1 (rep 3),1-Recover,36.3,1.479,1.336,0.009,,0.4746,114.592,,47.46,0.114592,,,,7.85398e-5
1:1 (rep 3),1-Recover,36.667,1.501,1.314,0.002,,0.466785,25.4648,,46.6785,0.0254648,,,,7.85398e-5
1:1 (rep 3),1-Recover,37.033,1.521,1.294,0.009,,0.45968,114.592,,45.968,0.114592,,,,7.85398e-5
1:1 (rep 3),1-Recover,37.4,1.541,1.274,0.016,,0.452575,203.718,,45.2575,0.203718,,,,7.85398e-5
1:1 (rep 3),1-Recover,37.767,1.563,1.252,0.016,,0.44476,203.718,,44.476,0.203718,,,,7.85398e-5
1:1 (rep 3),1-Recover,38.133,1.583,1.232,0.009,,0.437655,114.592,,43.7655,0.114592,,,,7.85398e-5
1:1 (rep 3),1-Recover,38.5,1.603,1.212,0.002,,0.430551,25.4648,,43.0551,0.0254648,,,,7.85398e-5
1:1 (rep 3),1-Recover,38.867,1.625,1.19,0.002,,0.422735,25.4648,,42.2735,0.0254648,,,,7.85398e-5
1:1 (rep 3),1-Recover,39.233,1.645,1.17,0.002,,0.415631,25.4648,,41.5631,0.0254648,,,,7.85398e-5
1:1 (rep 3),1-Recover,39.6,1.666,1.149,0.016,,0.408171,203.718,,40.8171,0.203718,,,,7.85398e-5
1:1 (rep 3),1-Recover,39.967,1.687,1.128,0.023,,0.40071,292.845,,40.071,0.292845,,,,7.85398e-5
1:1 (rep 3),1-Recover,40.333,1.707,1.108,0.016,,0.393606,203.718,,39.3606,0.203718,,,,7.85398e-5
1:1 (rep 3),1-Recover,40.7,1.728,1.087,0.009,,0.386146,114.592,,38.6146,0.114592,,,,7.85398e-5
1:1 (rep 3),1-Recover,41.067,1.749,1.066,0.002,,0.378686,25.4648,,37.8686,0.0254648,,,,7.85398e-5
1:1 (rep 3),1-Recover,41.433,1.769,1.046,0.002,,0.371581,25.4648,,37.1581,0.0254648,,,,7.85398e-5
1:1 (rep 3),1-Recover,41.8,1.79,1.025,0.002,,0.364121,25.4648,,36.4121,0.0254648,,,,7.85398e-5
1:1 (rep 3),1-Recover,42.167,1.811,1.004,0.016,,0.356661,203.718,,35.6661,0.203718,,,,7.85398e-5
1:1 (rep 3),1-Recover,42.533,1.831,0.984,0.002,,0.349556,25.4648,,34.9556,0.0254648,,,,7.85398e-5
1:1 (rep 3),1-Recover,42.9,1.852,0.963,0.016,,0.342096,203.718,,34.2096,0.203718,,,,7.85398e-5
1:1 (rep 3),1-Recover,43.267,1.873,0.942,0.002,,0.334636,25.4648,,33.4636,0.0254648,,,,7.85398e-5
1:1 (rep 3),1-Recover,43.633,1.893,0.922,0.002,,0.327531,25.4648,,32.7531,0.0254648,,,,7.85398e-5
1:1 (rep 3),1-Recover,44,1.914,0.901,0.002,,0.320071,25.4648,,32.0071,0.0254648,,,,7.85398e-5
1:1 (rep 3),1-Recover,44.367,1.935,0.88,0.009,,0.312611,114.592,,31.2611,0.114592,,,,7.85398e-5
1:1 (rep 3),1-Recover,44.733,1.955,0.86,0.002,,0.305506,25.4648,,30.5506,0.0254648,,,,7.85398e-5
1:1 (rep 3),1-Recover,45.1,1.976,0.839,-0.004,,0.298046,-50.9296,,29.8046,-0.0509296,,,,7.85398e-5
1:1 (rep 3),1-Recover,45.467,1.997,0.818,0.002,,0.290586,25.4648,,29.0586,0.0254648,,,,7.85398e-5
1:1 (rep 3),1-Recover,45.833,2.017,0.798,0.002,,0.283481,25.4648,,28.3481,0.0254648,,,,7.85398e-5
1:1 (rep 3),1-Recover,46.2,2.038,0.777,0.002,,0.276021,25.4648,,27.6021,0.0254648,,,,7.85398e-5
1:1 (rep 3),1-Recover,46.567,2.059,0.756,0.002,,0.268561,25.4648,,26.8561,0.0254648,,,,7.85398e-5
1:1 (rep 3),1-Recover,46.933,2.079,0.736,0.009,,0.261456,114.592,,26.1456,0.114592,,,,7.85398e-5
1:1 (rep 3),1-Recover,47.3,2.1,0.715,0.016,,0.253996,203.718,,25.3996,0.203718,,,,7.85398e-5
1:1 (rep 3),1-Recover,47.667,2.121,0.694,-0.004,,0.246536,-50.9296,,24.6536,-0.0509296,,,,7.85398e-5
1:1 (rep 3),1-Recover,48.033,2.141,0.674,0.002,,0.239432,25.4648,,23.9432,0.0254648,,,,7.85398e-5
1:1 (rep 3),1-Recover,48.4,2.162,0.653,0.002,,0.231972,25.4648,,23.1972,0.0254648,,,,7.85398e-5
1:1 (rep 3),1-Recover,48.767,2.183,0.632,-0.004,,0.224512,-50.9296,,22.4512,-0.0509296,,,,7.85398e-5
1:1 (rep 3),1-Recover,49.133,2.203,0.612,0.002,,0.217407,25.4648,,21.7407,0.0254648,,,,7.85398e-5
1:1 (rep 3),1-Recover,49.5,2.224,0.591,0.009,,0.209947,114.592,,20.9947,0.114592,,,,7.85398e-5
1:1 (rep 3),1-Recover,49.867,2.245,0.57,0.009,,0.202487,114.592,,20.2487,0.114592,,,,7.85398e-5
1:1 (rep 3),1-Recover,50.233,2.265,0.55,0.002,,0.195382,25.4648,,19.5382,0.0254648,,,,7.85398e-5
1:1 (rep 3),1-Recover,50.6,2.286,0.529,0.002,,0.187922,25.4648,,18.7922,0.0254648,,,,7.85398e-5
1:1 (rep 3),1-Recover,50.967,2.307,0.508,-0.004,,0.180462,-50.9296,,18.0462,-0.0509296,,,,7.85398e-5
1:1 (rep 3),1-Recover,51.333,2.327,0.488,-0.004,,0.173357,-50.9296,,17.3357,-0.0509296,,,,7.85398e-5
1:1 (rep 3),1-Recover,51.7,2.348,0.467,0.002,,0.165897,25.4648,,16.5897,0.0254648,,,,7.85398e-5
1:1 (rep 3),1-Recover,52.067,2.369,0.446,0.016,,0.158437,203.718,,15.8437,0.203718,,,,7.85398e-5
1:1 (rep 3),1-Recover,52.433,2.389,0.426,0.009,,0.151332,114.592,,15.1332,0.114592,,,,7.85398e-5
1:1 (rep 3),1-Recover,52.8,2.41,0.405,-0.004,,0.143872,-50.9296,,14.3872,-0.0509296,,,,7.85398e-5
1:1 (rep 3),1-Recover,53.167,2.431,0.384,0.002,,0.136412,25.4648,,13.6412,0.0254648,,,,7.85398e-5
1:1 (rep 3),1-Recover,53.533,2.451,0.364,-0.004,,0.129307,-50.9296,,12.9307,-0.0509296,,,,7.85398e-5
1:1 (rep 3),1-Recover,53.9,2.472,0.343,-0.004,,0.121847,-50.9296,,12.1847,-0.0509296,,,,7.85398e-5
1:1 (rep 3),1-Recover,54.267,2.493,0.322,0.002,,0.114387,25.4648,,11.4387,0.0254648,,,,7.85398e-5
1:1 (rep 3),1-Recover,54.633,2.513,0.302,0.009,,0.107282,114.592,,10.7282,0.114592,,,,7.85398e-5
1:1 (rep 3),1-Recover,55,2.534,0.281,0.002,,0.0998224,25.4648,,9.98224,0.0254648,,,,7.85398e-5
1:1 (rep 3),1-Recover,55.367,2.555,0.26,0.002,,0.0923623,25.4648,,9.23623,0.0254648,,,,7.85398e-5
1:1 (rep 3),1-Recover,55.733,2.575,0.24,-0.004,,0.0852575,-50.9296,,8.52575,-0.0509296,,,,7.85398e-5
1:1 (rep 3),1-Recover,56.1,2.596,0.219,-0.004,,0.0777975,-50.9296,,7.77975,-0.0509296,,,,7.85398e-5
1:1 (rep 3),1-Recover,56.467,2.617,0.198,0.002,,0.0703375,25.4648,,7.03375,0.0254648,,,,7.85398e-5
1:1 (rep 3),1-Recover,56.833,2.637,0.178,0.002,,0.0632327,25.4648,,6.32327,0.0254648,,,,7.85398e-5
1:1 (rep 3),1-Recover,57.2,2.658,0.157,0.009,,0.0557726,114.592,,5.57726,0.114592,,,,7.85398e-5
1:1 (rep 3),1-Recover,57.567,2.679,0.136,0.009,,0.0483126,114.592,,4.83126,0.114592,,,,7.85398e-5
1:1 (rep 3),1-Recover,57.933,2.699,0.116,-0.004,,0.0412078,-50.9296,,4.12078,-0.0509296,,,,7.85398e-5
1:1 (rep 3),1-Recover,58.3,2.72,0.095,-0.004,,0.0337478,-50.9296,,3.37478,-0.0509296,,,,7.85398e-5
1:1 (rep 3),1-Recover,58.667,2.741,0.074,0.002,,0.0262877,25.4648,,2.62877,0.0254648,,,,7.85398e-5
1:1 (rep 3),1-Recover,59.033,2.761,0.054,0.002,,0.0191829,25.4648,,1.91829,0.0254648,,,,7.85398e-5
1:1 (rep 3),1-Recover,59.4,2.782,0.033,0.002,,0.0117229,25.4648,,1.17229,0.0254648,,,,7.85398e-5
1:1 (rep 3),1-Recover,59.767,2.803,0.012,0.009,,0.00426288,114.592,,0.426288,0.114592,,,,7.85398e-5
1:1 (rep 3),2-Compress,60.117,2.811,0.004,0.009,,0.00142096,114.592,,0.142096,0.114592,,,,7.85398e-5
1:1 (rep 3),2-Compress,60.483,2.79,0.025,0.002,,0.00888099,25.4648,,0.888099,0.0254648,,,,7.85398e-5
1:1 (rep 3),2-Compress,60.85,2.77,0.045,0.002,,0.0159858,25.4648,,1.59858,0.0254648,,,,7.85398e-5
1:1 (rep 3),2-Compress,61.217,2.749,0.066,0.002,,0.0234458,25.4648,,2.34458,0.0254648,,,,7.85398e-5
1:1 (rep 3),2-Compress,61.583,2.728,0.087,0.002,,0.0309059,25.4648,,3.09059,0.0254648,,,,7.85398e-5
1:1 (rep 3),2-Compress,61.95,2.708,0.107,0.002,,0.0380107,25.4648,,3.80107,0.0254648,,,,7.85398e-5
1:1 (rep 3),2-Compress,62.317,2.687,0.128,0.009,,0.0454707,114.592,,4.54707,0.114592,,,,7.85398e-5
1:1 (rep 3),2-Compress,62.683,2.666,0.149,0.002,,0.0529307,25.4648,,5.29307,0.0254648,,,,7.85398e-5
1:1 (rep 3),2-Compress,63.05,2.646,0.169,0.002,,0.0600355,25.4648,,6.00355,0.0254648,,,,7.85398e-5
1:1 (rep 3),2-Compress,63.417,2.624,0.191,0.002,,0.0678508,25.4648,,6.78508,0.0254648,,,,7.85398e-5
1:1 (rep 3),2-Compress,63.783,2.604,0.211,-0.004,,0.0749556,-50.9296,,7.49556,-0.0509296,,,,7.85398e-5
1:1 (rep 3),2-Compress,64.15,2.584,0.231,0.002,,0.0820604,25.4648,,8.20604,0.0254648,,,,7.85398e-5
1:1 (rep 3),2-Compress,64.517,2.562,0.253,0.002,,0.0898757,25.4648,,8.98757,0.0254648,,,,7.85398e-5
1:1 (rep 3),2-Compress,64.883,2.542,0.273,0.009,,0.0969805,114.592,,9.69805,0.114592,,,,7.85398e-5
1:1 (rep 3),2-Compress,65.25,2.522,0.293,0.002,,0.104085,25.4648,,10.4085,0.0254648,,,,7.85398e-5
1:1 (rep 3),2-Compress,65.617,2.5,0.315,0.002,,0.111901,25.4648,,11.1901,0.0254648,,,,7.85398e-5
1:1 (rep 3),2-Compress,65.983,2.48,0.335,0.002,,0.119005,25.4648,,11.9005,0.0254648,,,,7.85398e-5
1:1 (rep 3),2-Compress,66.35,2.459,0.356,-0.004,,0.126465,-50.9296,,12.6465,-0.0509296,,,,7.85398e-5
1:1 (rep 3),2-Compress,66.717,2.438,0.377,0.002,,0.133925,25.4648,,13.3925,0.0254648,,,,7.85398e-5
1:1 (rep 3),2-Compress,67.083,2.418,0.397,0.002,,0.14103,25.4648,,14.103,0.0254648,,,,7.85398e-5
1:1 (rep 3),2-Compress,67.45,2.397,0.418,0.002,,0.14849,25.4648,,14.849,0.0254648,,,,7.85398e-5
1:1 (rep 3),2-Compress,67.817,2.376,0.439,0.002,,0.15595,25.4648,,15.595,0.0254648,,,,7.85398e-5
1:1 (rep 3),2-Compress,68.183,2.356,0.459,-0.004,,0.163055,-50.9296,,16.3055,-0.0509296,,,,7.85398e-5
1:1 (rep 3),2-Compress,68.55,2.335,0.48,0.009,,0.170515,114.592,,17.0515,0.114592,,,,7.85398e-5
1:1 (rep 3),2-Compress,68.917,2.314,0.501,0.002,,0.177975,25.4648,,17.7975,0.0254648,,,,7.85398e-5
1:1 (rep 3),2-Compress,69.283,2.294,0.521,0.002,,0.18508,25.4648,,18.508,0.0254648,,,,7.85398e-5
1:1 (rep 3),2-Compress,69.65,2.273,0.542,0.009,,0.19254,114.592,,19.254,0.114592,,,,7.85398e-5
1:1 (rep 3),2-Compress,70.017,2.252,0.563,0.002,,0.2,25.4648,,20,0.0254648,,,,7.85398e-5
1:1 (rep 3),2-Compress,70.383,2.232,0.583,0.002,,0.207105,25.4648,,20.7105,0.0254648,,,,7.85398e-5
1:1 (rep 3),2-Compress,70.75,2.211,0.604,0.002,,0.214565,25.4648,,21.4565,0.0254648,,,,7.85398e-5
1:1 (rep 3),2-Compress,71.117,2.19,0.625,0.002,,0.222025,25.4648,,22.2025,0.0254648,,,,7.85398e-5
1:1 (rep 3),2-Compress,71.483,2.17,0.645,0.002,,0.22913,25.4648,,22.913,0.0254648,,,,7.85398e-5
1:1 (rep 3),2-Compress,71.85,2.149,0.666,0.002,,0.23659,25.4648,,23.659,0.0254648,,,,7.85398e-5
1:1 (rep 3),2-Compress,72.217,2.128,0.687,0.009,,0.24405,114.592,,24.405,0.114592,,,,7.85398e-5
1:1 (rep 3),2-Compress,72.583,2.108,0.707,0.009,,0.251155,114.592,,25.1155,0.114592,,,,7.85398e-5
1:1 (rep 3),2-Compress,72.95,2.087,0.728,0.009,,0.258615,114.592,,25.8615,0.114592,,,,7.85398e-5
1:1 (rep 3),2-Compress,73.317,2.066,0.749,-0.004,,0.266075,-50.9296,,26.6075,-0.0509296,,,,7.85398e-5
1:1 (rep 3),2-Compress,73.683,2.046,0.769,0.002,,0.273179,25.4648,,27.3179,0.0254648,,,,7.85398e-5
1:1 (rep 3),2-Compress,74.05,2.025,0.79,0.002,,0.280639,25.4648,,28.0639,0.0254648,,,,7.85398e-5
1:1 (rep 3),2-Compress,74.417,2.004,0.811,0.002,,0.288099,25.4648,,28.8099,0.0254648,,,,7.85398e-5
1:1 (rep 3),2-Compress,74.783,1.984,0.831,0.009,,0.295204,114.592,,29.5204,0.114592,,,,7.85398e-5
1:1 (rep 3),2-Compress,75.15,1.963,0.852,0.009,,0.302664,114.592,,30.2664,0.114592,,,,7.85398e-5
1:1 (rep 3),2-Compress,75.517,1.942,0.873,0.023,,0.310124,292.845,,31.0124,0.292845,,,,7.85398e-5
1:1 (rep 3),2-Compress,75.883,1.922,0.893,-0.004,,0.317229,-50.9296,,31.7229,-0.0509296,,,,7.85398e-5
1:1 (rep 3),2-Compress,76.25,1.901,0.914,0.002,,0.324689,25.4648,,32.4689,0.0254648,,,,7.85398e-5
1:1 (rep 3),2-Compress,76.617,1.88,0.935,0.002,,0.332149,25.4648,,33.2149,0.0254648,,,,7.85398e-5
1:1 (rep 3),2-Compress,76.983,1.86,0.955,0.002,,0.339254,25.4648,,33.9254,0.0254648,,,,7.85398e-5
1:1 (rep 3),2-Compress,77.35,1.839,0.976,0.002,,0.346714,25.4648,,34.6714,0.0254648,,,,7.85398e-5
1:1 (rep 3),2-Compress,77.717,1.818,0.997,0.023,,0.354174,292.845,,35.4174,0.292845,,,,7.85398e-5
1:1 (rep 3),2-Compress,78.083,1.798,1.017,0.023,,0.361279,292.845,,36.1279,0.292845,,,,7.85398e-5
1:1 (rep 3),2-Compress,78.45,1.777,1.038,0.016,,0.368739,203.718,,36.8739,0.203718,,,,7.85398e-5
1:1 (rep 3),2-Compress,78.817,1.756,1.059,0.002,,0.376199,25.4648,,37.6199,0.0254648,,,,7.85398e-5
1:1 (rep 3),2-Compress,79.183,1.736,1.079,0.002,,0.383304,25.4648,,38.3304,0.0254648,,,,7.85398e-5
1:1 (rep 3),2-Compress,79.55,1.715,1.1,0.002,,0.390764,25.4648,,39.0764,0.0254648,,,,7.85398e-5
1:1 (rep 3),2-Compress,79.917,1.694,1.121,0.009,,0.398224,114.592,,39.8224,0.114592,,,,7.85398e-5
1:1 (rep 3),2-Compress,80.283,1.674,1.141,0.016,,0.405329,203.718,,40.5329,0.203718,,,,7.85398e-5
1:1 (rep 3),2-Compress,80.65,1.653,1.162,0.016,,0.412789,203.718,,41.2789,0.203718,,,,7.85398e-5
1:1 (rep 3),2-Compress,81.017,1.632,1.183,0.002,,0.420249,25.4648,,42.0249,0.0254648,,,,7.85398e-5
1:1 (rep 3),2-Compress,81.383,1.612,1.203,0.009,,0.427353,114.592,,42.7353,0.114592,,,,7.85398e-5
1:1 (rep 3),2-Compress,81.75,1.591,1.224,0.002,,0.434813,25.4648,,43.4813,0.0254648,,,,7.85398e-5
1:1 (rep 3),2-Compress,82.117,1.57,1.245,0.002,,0.442274,25.4648,,44.2274,0.0254648,,,,7.85398e-5
1:1 (rep 3),2-Compress,82.483,1.55,1.265,0.023,,0.449378,292.845,,44.9378,0.292845,,,,7.85398e-5
1:1 (rep 3),2-Compress,82.85,1.529,1.286,0.03,,0.456838,381.972,,45.6838,0.381972,,,,7.85398e-5
1:1 (rep 3),2-Compress,83.217,1.508,1.307,0.016,,0.464298,203.718,,46.4298,0.203718,,,,7.85398e-5
1:1 (rep 3),2-Compress,83.583,1.488,1.327,0.016,,0.471403,203.718,,47.1403,0.203718,,,,7.85398e-5
1:1 (rep 3),2-Compress,83.95,1.467,1.348,0.009,,0.478863,114.592,,47.8863,0.114592,,,,7.85398e-5
1:1 (rep 3),2-Compress,84.317,1.446,1.369,0.009,,0.486323,114.592,,48.6323,0.114592,,,,7.85398e-5
1:1 (rep 3),2-Compress,84.683,1.426,1.389,0.009,,0.493428,114.592,,49.3428,0.114592,,,,7.85398e-5
1:1 (rep 3),2-Compress,85.05,1.405,1.41,0.023,,0.500888,292.845,,50.0888,0.292845,,,,7.85398e-5
1:1 (rep 3),2-Compress,85.417,1.384,1.431,0.023,,0.508348,292.845,,50.8348,0.292845,,,,7.85398e-5
1:1 (rep 3),2-Compress,85.783,1.364,1.451,0.023,,0.515453,292.845,,51.5453,0.292845,,,,7.85398e-5
1:1 (rep 3),2-Compress,86.15,1.343,1.472,0.016,,0.522913,203.718,,52.2913,0.203718,,,,7.85398e-5
1:1 (rep 3),2-Compress,86.517,1.322,1.493,0.03,,0.530373,381.972,,53.0373,0.381972,,,,7.85398e-5
1:1 (rep 3),2-Compress,86.883,1.302,1.513,0.016,,0.537478,203.718,,53.7478,0.203718,,,,7.85398e-5
1:1 (rep 3),2-Compress,87.25,1.281,1.534,0.023,,0.544938,292.845,,54.4938,0.292845,,,,7.85398e-5
1:1 (rep 3),2-Compress,87.617,1.26,1.555,0.036,,0.552398,458.366,,55.2398,0.458366,,,,7.85398e-5
1:1 (rep 3),2-Compress,87.983,1.24,1.575,0.043,,0.559503,547.493,,55.9503,0.547493,,,,7.85398e-5
1:1 (rep 3),2-Compress,88.35,1.219,1.596,0.036,,0.566963,458.366,,56.6963,0.458366,,,,7.85398e-5
1:1 (rep 3),2-Compress,88.717,1.198,1.617,0.016,,0.574423,203.718,,57.4423,0.203718,,,,7.85398e-5
1:1 (rep 3),2-Compress,89.083,1.178,1.637,0.036,,0.581528,458.366,,58.1528,0.458366,,,,7.85398e-5
1:1 (rep 3),2-Compress,89.45,1.157,1.658,0.016,,0.588988,203.718,,58.8988,0.203718,,,,7.85398e-5
1:1 (rep 3),2-Compress,89.817,1.136,1.679,0.036,,0.596448,458.366,,59.6448,0.458366,,,,7.85398e-5
1:1 (rep 3),2-Recover,90.17,1.132,1.683,0.03,,0.597869,381.972,,59.7869,0.381972,,,,7.85398e-5
1:1 (rep 3),2-Recover,90.537,1.153,1.662,0.043,,0.590409,547.493,,59.0409,0.547493,,,,7.85398e-5
1:1 (rep 3),2-Recover,90.903,1.173,1.642,0.036,,0.583304,458.366,,58.3304,0.458366,,,,7.85398e-5
1:1 (rep 3),2-Recover,91.27,1.194,1.621,0.023,,0.575844,292.845,,57.5844,0.292845,,,,7.85398e-5
1:1 (rep 3),2-Recover,91.637,1.215,1.6,0.023,,0.568384,292.845,,56.8384,0.292845,,,,7.85398e-5
1:1 (rep 3),2-Recover,92.003,1.235,1.58,0.03,,0.561279,381.972,,56.1279,0.381972,,,,7.85398e-5
1:1 (rep 3),2-Recover,92.37,1.256,1.559,0.016,,0.553819,203.718,,55.3819,0.203718,,,,7.85398e-5
1:1 (rep 3),2-Recover,92.737,1.277,1.538,0.036,,0.546359,458.366,,54.6359,0.458366,,,,7.85398e-5
1:1 (rep 3),2-Recover,93.103,1.297,1.518,0.03,,0.539254,381.972,,53.9254,0.381972,,,,7.85398e-5
1:1 (rep 3),2-Recover,93.47,1.318,1.497,0.023,,0.531794,292.845,,53.1794,0.292845,,,,7.85398e-5
1:1 (rep 3),2-Recover,93.837,1.339,1.476,0.009,,0.524334,114.592,,52.4334,0.114592,,,,7.85398e-5
1:1 (rep 3),2-Recover,94.203,1.359,1.456,0.002,,0.517229,25.4648,,51.7229,0.0254648,,,,7.85398e-5
1:1 (rep 3),2-Recover,94.57,1.38,1.435,0.009,,0.509769,114.592,,50.9769,0.114592,,,,7.85398e-5
1:1 (rep 3),2-Recover,94.937,1.401,1.414,0.009,,0.502309,114.592,,50.2309,0.114592,,,,7.85398e-5
1:1 (rep 3),2-Recover,95.303,1.421,1.394,0.023,,0.495204,292.845,,49.5204,0.292845,,,,7.85398e-5
1:1 (rep 3),2-Recover,95.67,1.442,1.373,0.016,,0.487744,203.718,,48.7744,0.203718,,,,7.85398e-5
1:1 (rep 3),2-Recover,96.037,1.463,1.352,0.016,,0.480284,203.718,,48.0284,0.203718,,,,7.85398e-5
1:1 (rep 3),2-Recover,96.403,1.483,1.332,0.009,,0.473179,114.592,,47.3179,0.114592,,,,7.85398e-5
1:1 (rep 3),2-Recover,96.77,1.504,1.311,0.002,,0.465719,25.4648,,46.5719,0.0254648,,,,7.85398e-5
1:1 (rep 3),2-Recover,97.137,1.525,1.29,0.009,,0.458259,114.592,,45.8259,0.114592,,,,7.85398e-5
1:1 (rep 3),2-Recover,97.503,1.545,1.27,0.009,,0.451155,114.592,,45.1155,0.114592,,,,7.85398e-5
1:1 (rep 3),2-Recover,97.87,1.567,1.248,0.016,,0.443339,203.718,,44.3339,0.203718,,,,7.85398e-5
1:1 (rep 3),2-Recover,98.237,1.587,1.228,0.016,,0.436234,203.718,,43.6234,0.203718,,,,7.85398e-5
1:1 (rep 3),2-Recover,98.603,1.607,1.208,0.016,,0.42913,203.718,,42.913,0.203718,,,,7.85398e-5
1:1 (rep 3),2-Recover,98.97,1.629,1.186,0.009,,0.421314,114.592,,42.1314,0.114592,,,,7.85398e-5
1:1 (rep 3),2-Recover,99.337,1.649,1.166,0.002,,0.41421,25.4648,,41.421,0.0254648,,,,7.85398e-5
1:1 (rep 3),2-Recover,99.703,1.669,1.146,0.002,,0.407105,25.4648,,40.7105,0.0254648,,,,7.85398e-5
1:1 (rep 3),2-Recover,100.07,1.691,1.124,0.009,,0.39929,114.592,,39.929,0.114592,,,,7.85398e-5
1:1 (rep 3),2-Recover,100.437,1.711,1.104,0.002,,0.392185,25.4648,,39.2185,0.0254648,,,,7.85398e-5
1:1 (rep 3),2-Recover,100.803,1.732,1.083,0.016,,0.384725,203.718,,38.4725,0.203718,,,,7.85398e-5
1:1 (rep 3),2-Recover,101.17,1.752,1.063,0.002,,0.37762,25.4648,,37.762,0.0254648,,,,7.85398e-5
1:1 (rep 3),2-Recover,101.537,1.773,1.042,0.002,,0.37016,25.4648,,37.016,0.0254648,,,,7.85398e-5
1:1 (rep 3),2-Recover,101.903,1.794,1.021,0.002,,0.3627,25.4648,,36.27,0.0254648,,,,7.85398e-5
1:1 (rep 3),2-Recover,102.27,1.814,1.001,0.002,,0.355595,25.4648,,35.5595,0.0254648,,,,7.85398e-5
1:1 (rep 3),2-Recover,102.637,1.835,0.98,0.009,,0.348135,114.592,,34.8135,0.114592,,,,7.85398e-5
1:1 (rep 3),2-Recover,103.003,1.856,0.959,0.016,,0.340675,203.718,,34.0675,0.203718,,,,7.85398e-5
1:1 (rep 3),2-Recover,103.37,1.876,0.939,0.009,,0.33357,114.592,,33.357,0.114592,,,,7.85398e-5
1:1 (rep 3),2-Recover,103.737,1.897,0.918,0.002,,0.32611,25.4648,,32.611,0.0254648,,,,7.85398e-5
1:1 (rep 3),2-Recover,104.103,1.918,0.897,0.009,,0.31865,114.592,,31.865,0.114592,,,,7.85398e-5
1:1 (rep 3),2-Recover,104.47,1.938,0.877,0.002,,0.311545,25.4648,,31.1545,0.0254648,,,,7.85398e-5
1:1 (rep 3),2-Recover,104.837,1.959,0.856,0.002,,0.304085,25.4648,,30.4085,0.0254648,,,,7.85398e-5
1:1 (rep 3),2-Recover,105.203,1.98,0.835,0.016,,0.296625,203.718,,29.6625,0.203718,,,,7.85398e-5
1:1 (rep 3),2-Recover,105.57,2,0.815,0.002,,0.28952,25.4648,,28.952,0.0254648,,,,7.85398e-5
1:1 (rep 3),2-Recover,105.937,2.021,0.794,0.009,,0.28206,114.592,,28.206,0.114592,,,,7.85398e-5
1:1 (rep 3),2-Recover,106.303,2.042,0.773,0.009,,0.2746,114.592,,27.46,0.114592,,,,7.85398e-5
1:1 (rep 3),2-Recover,106.67,2.063,0.752,0.002,,0.26714,25.4648,,26.714,0.0254648,,,,7.85398e-5
1:1 (rep 3),2-Recover,107.037,2.083,0.732,0.002,,0.260036,25.4648,,26.0036,0.0254648,,,,7.85398e-5
1:1 (rep 3),2-Recover,107.403,2.104,0.711,0.002,,0.252575,25.4648,,25.2575,0.0254648,,,,7.85398e-5
1:1 (rep 3),2-Recover,107.77,2.125,0.69,0.009,,0.245115,114.592,,24.5115,0.114592,,,,7.85398e-5
1:1 (rep 3),2-Recover,108.137,2.145,0.67,0.009,,0.238011,114.592,,23.8011,0.114592,,,,7.85398e-5
1:1 (rep 3),2-Recover,108.503,2.166,0.649,0.009,,0.230551,114.592,,23.0551,0.114592,,,,7.85398e-5
1:1 (rep 3),2-Recover,108.87,2.187,0.628,0.002,,0.223091,25.4648,,22.3091,0.0254648,,,,7.85398e-5
1:1 (rep 3),2-Recover,109.237,2.207,0.608,0.002,,0.215986,25.4648,,21.5986,0.0254648,,,,7.85398e-5
1:1 (rep 3),2-Recover,109.603,2.228,0.587,0.002,,0.208526,25.4648,,20.8526,0.0254648,,,,7.85398e-5
1:1 (rep 3),2-Recover,109.97,2.249,0.566,0.009,,0.201066,114.592,,20.1066,0.114592,,,,7.85398e-5
1:1 (rep 3),2-Recover,110.337,2.269,0.546,0.009,,0.193961,114.592,,19.3961,0.114592,,,,7.85398e-5
1:1 (rep 3),2-Recover,110.703,2.29,0.525,0.016,,0.186501,203.718,,18.6501,0.203718,,,,7.85398e-5
1:1 (rep 3),2-Recover,111.07,2.311,0.504,0.002,,0.179041,25.4648,,17.9041,0.0254648,,,,7.85398e-5
1:1 (rep 3),2-Recover,111.437,2.331,0.484,0.002,,0.171936,25.4648,,17.1936,0.0254648,,,,7.85398e-5
1:1 (rep 3),2-Recover,111.803,2.352,0.463,0.002,,0.164476,25.4648,,16.4476,0.0254648,,,,7.85398e-5
1:1 (rep 3),2-Recover,112.17,2.372,0.443,0.002,,0.157371,25.4648,,15.7371,0.0254648,,,,7.85398e-5
1:1 (rep 3),2-Recover,112.537,2.393,0.422,0.009,,0.149911,114.592,,14.9911,0.114592,,,,7.85398e-5
1:1 (rep 3),2-Recover,112.903,2.414,0.401,0.009,,0.142451,114.592,,14.2451,0.114592,,,,7.85398e-5
1:1 (rep 3),2-Recover,113.27,2.434,0.381,0.002,,0.135346,25.4648,,13.5346,0.0254648,,,,7.85398e-5
1:1 (rep 3),2-Recover,113.637,2.456,0.359,0.002,,0.127531,25.4648,,12.7531,0.0254648,,,,7.85398e-5
1:1 (rep 3),2-Recover,114.003,2.476,0.339,0.002,,0.120426,25.4648,,12.0426,0.0254648,,,,7.85398e-5
1:1 (rep 3),2-Recover,114.37,2.496,0.319,0.002,,0.113321,25.4648,,11.3321,0.0254648,,,,7.85398e-5
1:1 (rep 3),2-Recover,114.737,2.518,0.297,0.002,,0.105506,25.4648,,10.5506,0.0254648,,,,7.85398e-5
1:1 (rep 3),2-Recover,115.103,2.538,0.277,0.009,,0.0984014,114.592,,9.84014,0.114592,,,,7.85398e-5
1:1 (rep 3),2-Recover,115.47,2.558,0.257,0.009,,0.0912966,114.592,,9.12966,0.114592,,,,7.85398e-5
1:1 (rep 3),2-Recover,115.837,2.58,0.235,0.002,,0.0834813,25.4648,,8.34813,0.0254648,,,,7.85398e-5
1:1 (rep 3),2-Recover,116.203,2.6,0.215,0.002,,0.0763766,25.4648,,7.63766,0.0254648,,,,7.85398e-5
1:1 (rep 3),2-Recover,116.57,2.621,0.194,-0.004,,0.0689165,-50.9296,,6.89165,-0.0509296,,,,7.85398e-5
1:1 (rep 3),2-Recover,116.937,2.642,0.173,0.002,,0.0614565,25.4648,,6.14565,0.0254648,,,,7.85398e-5
1:1 (rep 3),2-Recover,117.303,2.662,0.153,0.002,,0.0543517,25.4648,,5.43517,0.0254648,,,,7.85398e-5
1:1 (rep 3),2-Recover,117.67,2.683,0.132,0.009,,0.0468917,114.592,,4.68917,0.114592,,,,7.85398e-5
1:1 (rep 3),2-Recover,118.037,2.704,0.111,0.009,,0.0394316,114.592,,3.94316,0.114592,,,,7.85398e-5
1:1 (rep 3),2-Recover,118.403,2.724,0.091,-0.004,,0.0323268,-50.9296,,3.23268,-0.0509296,,,,7.85398e-5
1:1 (rep 3),2-Recover,118.77,2.745,0.07,-0.004,,0.0248668,-50.9296,,2.48668,-0.0509296,,,,7.85398e-5
1:1 (rep 3),2-Recover,119.137,2.766,0.049,0.002,,0.0174067,25.4648,,1.74067,0.0254648,,,,7.85398e-5
1:1 (rep 3),2-Recover,119.503,2.786,0.029,-0.004,,0.010302,-50.9296,,1.0302,-0.0509296,,,,7.85398e-5
1:1 (rep 3),2-Recover,119.87,2.807,0.008,0.002,,0.00284192,25.4648,,0.284192,0.0254648,,,,7.85398e-5
1:1 (rep 3),3-Compress,120.223,2.807,0.008,0.009,,0.00284192,114.592,,0.284192,0.114592,,,,7.85398e-5
1:1 (rep 3),3-Compress,120.59,2.786,0.029,0.016,,0.010302,203.718,,1.0302,0.203718,,,,7.85398e-5
1:1 (rep 3),3-Compress,120.957,2.765,0.05,-0.004,,0.017762,-50.9296,,1.7762,-0.0509296,,,,7.85398e-5
1:1 (rep 3),3-Compress,121.323,2.745,0.07,0.002,,0.0248668,25.4648,,2.48668,0.0254648,,,,7.85398e-5
1:1 (rep 3),3-Compress,121.69,2.724,0.091,0.002,,0.0323268,25.4648,,3.23268,0.0254648,,,,7.85398e-5
1:1 (rep 3),3-Compress,122.057,2.703,0.112,0.002,,0.0397869,25.4648,,3.97869,0.0254648,,,,7.85398e-5
1:1 (rep 3),3-Compress,122.423,2.683,0.132,0.002,,0.0468917,25.4648,,4.68917,0.0254648,,,,7.85398e-5
1:1 (rep 3),3-Compress,122.79,2.662,0.153,0.009,,0.0543517,114.592,,5.43517,0.114592,,,,7.85398e-5
1:1 (rep 3),3-Compress,123.157,2.641,0.174,0.016,,0.0618117,203.718,,6.18117,0.203718,,,,7.85398e-5
1:1 (rep 3),3-Compress,123.523,2.621,0.194,0.002,,0.0689165,25.4648,,6.89165,0.0254648,,,,7.85398e-5
1:1 (rep 3),3-Compress,123.89,2.6,0.215,0.009,,0.0763766,114.592,,7.63766,0.114592,,,,7.85398e-5
1:1 (rep 3),3-Compress,124.257,2.579,0.236,0.002,,0.0838366,25.4648,,8.38366,0.0254648,,,,7.85398e-5
1:1 (rep 3),3-Compress,124.623,2.559,0.256,-0.004,,0.0909414,-50.9296,,9.09414,-0.0509296,,,,7.85398e-5
1:1 (rep 3),3-Compress,124.99,2.538,0.277,0.002,,0.0984014,25.4648,,9.84014,0.0254648,,,,7.85398e-5
1:1 (rep 3),3-Compress,125.357,2.517,0.298,0.009,,0.105861,114.592,,10.5861,0.114592,,,,7.85398e-5
1:1 (rep 3),3-Compress,125.723,2.497,0.318,0.016,,0.112966,203.718,,11.2966,0.203718,,,,7.85398e-5
1:1 (rep 3),3-Compress,126.09,2.476,0.339,-0.004,,0.120426,-50.9296,,12.0426,-0.0509296,,,,7.85398e-5
1:1 (rep 3),3-Compress,126.457,2.456,0.359,-0.004,,0.127531,-50.9296,,12.7531,-0.0509296,,,,7.85398e-5
1:1 (rep 3),3-Compress,126.823,2.435,0.38,0.002,,0.134991,25.4648,,13.4991,0.0254648,,,,7.85398e-5
1:1 (rep 3),3-Compress,127.19,2.414,0.401,0.002,,0.142451,25.4648,,14.2451,0.0254648,,,,7.85398e-5
1:1 (rep 3),3-Compress,127.557,2.393,0.422,0.009,,0.149911,114.592,,14.9911,0.114592,,,,7.85398e-5
1:1 (rep 3),3-Compress,127.923,2.373,0.442,0.016,,0.157016,203.718,,15.7016,0.203718,,,,7.85398e-5
1:1 (rep 3),3-Compress,128.29,2.352,0.463,0.009,,0.164476,114.592,,16.4476,0.114592,,,,7.85398e-5
1:1 (rep 3),3-Compress,128.657,2.331,0.484,0.002,,0.171936,25.4648,,17.1936,0.0254648,,,,7.85398e-5
1:1 (rep 3),3-Compress,129.023,2.311,0.504,0.002,,0.179041,25.4648,,17.9041,0.0254648,,,,7.85398e-5
1:1 (rep 3),3-Compress,129.39,2.29,0.525,0.002,,0.186501,25.4648,,18.6501,0.0254648,,,,7.85398e-5
1:1 (rep 3),3-Compress,129.757,2.269,0.546,0.002,,0.193961,25.4648,,19.3961,0.0254648,,,,7.85398e-5
1:1 (rep 3),3-Compress,130.123,2.249,0.566,0.002,,0.201066,25.4648,,20.1066,0.0254648,,,,7.85398e-5
1:1 (rep 3),3-Compress,130.49,2.228,0.587,0.009,,0.208526,114.592,,20.8526,0.114592,,,,7.85398e-5
1:1 (rep 3),3-Compress,130.857,2.207,0.608,0.009,,0.215986,114.592,,21.5986,0.114592,,,,7.85398e-5
1:1 (rep 3),3-Compress,131.223,2.187,0.628,0.009,,0.223091,114.592,,22.3091,0.114592,,,,7.85398e-5
1:1 (rep 3),3-Compress,131.59,2.166,0.649,0.002,,0.230551,25.4648,,23.0551,0.0254648,,,,7.85398e-5
1:1 (rep 3),3-Compress,131.957,2.145,0.67,0.002,,0.238011,25.4648,,23.8011,0.0254648,,,,7.85398e-5
1:1 (rep 3),3-Compress,132.323,2.125,0.69,0.002,,0.245115,25.4648,,24.5115,0.0254648,,,,7.85398e-5
1:1 (rep 3),3-Compress,132.69,2.104,0.711,0.009,,0.252575,114.592,,25.2575,0.114592,,,,7.85398e-5
1:1 (rep 3),3-Compress,133.057,2.083,0.732,0.009,,0.260036,114.592,,26.0036,0.114592,,,,7.85398e-5
1:1 (rep 3),3-Compress,133.423,2.063,0.752,0.023,,0.26714,292.845,,26.714,0.292845,,,,7.85398e-5
1:1 (rep 3),3-Compress,133.79,2.042,0.773,-0.004,,0.2746,-50.9296,,27.46,-0.0509296,,,,7.85398e-5
1:1 (rep 3),3-Compress,134.157,2.021,0.794,0.009,,0.28206,114.592,,28.206,0.114592,,,,7.85398e-5
1:1 (rep 3),3-Compress,134.523,2.001,0.814,0.002,,0.289165,25.4648,,28.9165,0.0254648,,,,7.85398e-5
1:1 (rep 3),3-Compress,134.89,1.98,0.835,0.002,,0.296625,25.4648,,29.6625,0.0254648,,,,7.85398e-5
1:1 (rep 3),3-Compress,135.257,1.959,0.856,0.009,,0.304085,114.592,,30.4085,0.114592,,,,7.85398e-5
1:1 (rep 3),3-Compress,135.623,1.939,0.876,0.023,,0.31119,292.845,,31.119,0.292845,,,,7.85398e-5
1:1 (rep 3),3-Compress,135.99,1.918,0.897,0.009,,0.31865,114.592,,31.865,0.114592,,,,7.85398e-5
1:1 (rep 3),3-Compress,136.357,1.897,0.918,0.009,,0.32611,114.592,,32.611,0.114592,,,,7.85398e-5
1:1 (rep 3),3-Compress,136.723,1.877,0.938,0.009,,0.333215,114.592,,33.3215,0.114592,,,,7.85398e-5
1:1 (rep 3),3-Compress,137.09,1.856,0.959,0.002,,0.340675,25.4648,,34.0675,0.0254648,,,,7.85398e-5
1:1 (rep 3),3-Compress,137.457,1.835,0.98,0.002,,0.348135,25.4648,,34.8135,0.0254648,,,,7.85398e-5
1:1 (rep 3),3-Compress,137.823,1.815,1,0.009,,0.35524,114.592,,35.524,0.114592,,,,7.85398e-5
1:1 (rep 3),3-Compress,138.19,1.794,1.021,0.016,,0.3627,203.718,,36.27,0.203718,,,,7.85398e-5
1:1 (rep 3),3-Compress,138.557,1.773,1.042,0.023,,0.37016,292.845,,37.016,0.292845,,,,7.85398e-5
1:1 (rep 3),3-Compress,138.923,1.753,1.062,0.009,,0.377265,114.592,,37.7265,0.114592,,,,7.85398e-5
1:1 (rep 3),3-Compress,139.29,1.732,1.083,0.002,,0.384725,25.4648,,38.4725,0.0254648,,,,7.85398e-5
1:1 (rep 3),3-Compress,139.657,1.711,1.104,0.002,,0.392185,25.4648,,39.2185,0.0254648,,,,7.85398e-5
1:1 (rep 3),3-Compress,140.023,1.691,1.124,0.002,,0.39929,25.4648,,39.929,0.0254648,,,,7.85398e-5
1:1 (rep 3),3-Compress,140.39,1.669,1.146,0.009,,0.407105,114.592,,40.7105,0.114592,,,,7.85398e-5
1:1 (rep 3),3-Compress,140.757,1.649,1.166,0.03,,0.41421,381.972,,41.421,0.381972,,,,7.85398e-5
1:1 (rep 3),3-Compress,141.123,1.629,1.186,0.009,,0.421314,114.592,,42.1314,0.114592,,,,7.85398e-5
1:1 (rep 3),3-Compress,141.49,1.607,1.208,0.016,,0.42913,203.718,,42.913,0.203718,,,,7.85398e-5
1:1 (rep 3),3-Compress,141.857,1.587,1.228,0.002,,0.436234,25.4648,,43.6234,0.0254648,,,,7.85398e-5
1:1 (rep 3),3-Compress,142.223,1.567,1.248,0.002,,0.443339,25.4648,,44.3339,0.0254648,,,,7.85398e-5
1:1 (rep 3),3-Compress,142.59,1.545,1.27,0.009,,0.451155,114.592,,45.1155,0.114592,,,,7.85398e-5
1:1 (rep 3),3-Compress,142.957,1.525,1.29,0.023,,0.458259,292.845,,45.8259,0.292845,,,,7.85398e-5
1:1 (rep 3),3-Compress,143.323,1.504,1.311,0.023,,0.465719,292.845,,46.5719,0.292845,,,,7.85398e-5
1:1 (rep 3),3-Compress,143.69,1.483,1.332,0.023,,0.473179,292.845,,47.3179,0.292845,,,,7.85398e-5
1:1 (rep 3),3-Compress,144.057,1.463,1.352,0.016,,0.480284,203.718,,48.0284,0.203718,,,,7.85398e-5
1:1 (rep 3),3-Compress,144.423,1.442,1.373,0.016,,0.487744,203.718,,48.7744,0.203718,,,,7.85398e-5
1:1 (rep 3),3-Compress,144.79,1.421,1.394,0.002,,0.495204,25.4648,,49.5204,0.0254648,,,,7.85398e-5
1:1 (rep 3),3-Compress,145.157,1.401,1.414,0.009,,0.502309,114.592,,50.2309,0.114592,,,,7.85398e-5
1:1 (rep 3),3-Compress,145.523,1.38,1.435,0.023,,0.509769,292.845,,50.9769,0.292845,,,,7.85398e-5
1:1 (rep 3),3-Compress,145.89,1.359,1.456,0.023,,0.517229,292.845,,51.7229,0.292845,,,,7.85398e-5
1:1 (rep 3),3-Compress,146.257,1.339,1.476,0.023,,0.524334,292.845,,52.4334,0.292845,,,,7.85398e-5
1:1 (rep 3),3-Compress,146.623,1.318,1.497,0.03,,0.531794,381.972,,53.1794,0.381972,,,,7.85398e-5
1:1 (rep 3),3-Compress,146.99,1.297,1.518,0.023,,0.539254,292.845,,53.9254,0.292845,,,,7.85398e-5
1:1 (rep 3),3-Compress,147.357,1.277,1.538,0.016,,0.546359,203.718,,54.6359,0.203718,,,,7.85398e-5
1:1 (rep 3),3-Compress,147.723,1.256,1.559,0.03,,0.553819,381.972,,55.3819,0.381972,,,,7.85398e-5
1:1 (rep 3),3-Compress,148.09,1.235,1.58,0.036,,0.561279,458.366,,56.1279,0.458366,,,,7.85398e-5
1:1 (rep 3),3-Compress,148.457,1.215,1.6,0.03,,0.568384,381.972,,56.8384,0.381972,,,,7.85398e-5
1:1 (rep 3),3-Compress,148.823,1.194,1.621,0.03,,0.575844,381.972,,57.5844,0.381972,,,,7.85398e-5
1:1 (rep 3),3-Compress,149.19,1.173,1.642,0.03,,0.583304,381.972,,58.3304,0.381972,,,,7.85398e-5
1:1 (rep 3),3-Compress,149.557,1.153,1.662,0.016,,0.590409,203.718,,59.0409,0.203718,,,,7.85398e-5
1:1 (rep 3),3-Compress,149.923,1.132,1.683,0.009,,0.597869,114.592,,59.7869,0.114592,,,,7.85398e-5
1:1 (rep 3),3-Recover,150.267,1.136,1.679,0.043,,0.596448,547.493,,59.6448,0.547493,,,,7.85398e-5
1:1 (rep 3),3-Recover,150.633,1.156,1.659,0.036,,0.589343,458.366,,58.9343,0.458366,,,,7.85398e-5
1:1 (rep 3),3-Recover,151,1.176,1.639,0.03,,0.582238,381.972,,58.2238,0.381972,,,,7.85398e-5
1:1 (rep 3),3-Recover,151.367,1.198,1.617,0.03,,0.574423,381.972,,57.4423,0.381972,,,,7.85398e-5
1:1 (rep 3),3-Recover,151.733,1.218,1.597,0.03,,0.567318,381.972,,56.7318,0.381972,,,,7.85398e-5
1:1 (rep 3),3-Recover,152.1,1.238,1.577,0.009,,0.560213,114.592,,56.0213,0.114592,,,,7.85398e-5
1:1 (rep 3),3-Recover,152.467,1.26,1.555,0.002,,0.552398,25.4648,,55.2398,0.0254648,,,,7.85398e-5
1:1 (rep 3),3-Recover,152.833,1.28,1.535,0.023,,0.545293,292.845,,54.5293,0.292845,,,,7.85398e-5
1:1 (rep 3),3-Recover,153.2,1.301,1.514,0.016,,0.537833,203.718,,53.7833,0.203718,,,,7.85398e-5
1:1 (rep 3),3-Recover,153.567,1.322,1.493,0.03,,0.530373,381.972,,53.0373,0.381972,,,,7.85398e-5
1:1 (rep 3),3-Recover,153.933,1.342,1.473,0.023,,0.523268,292.845,,52.3268,0.292845,,,,7.85398e-5
1:1 (rep 3),3-Recover,154.3,1.363,1.452,0.023,,0.515808,292.845,,51.5808,0.292845,,,,7.85398e-5
1:1 (rep 3),3-Recover,154.667,1.384,1.431,0.009,,0.508348,114.592,,50.8348,0.114592,,,,7.85398e-5
1:1 (rep 3),3-Recover,155.033,1.404,1.411,0.002,,0.501243,25.4648,,50.1243,0.0254648,,,,7.85398e-5
1:1 (rep 3),3-Recover,155.4,1.425,1.39,0.002,,0.493783,25.4648,,49.3783,0.0254648,,,,7.85398e-5
1:1 (rep 3),3-Recover,155.767,1.446,1.369,0.023,,0.486323,292.845,,48.6323,0.292845,,,,7.85398e-5
1:1 (rep 3),3-Recover,156.133,1.466,1.349,0.03,,0.479218,381.972,,47.9218,0.381972,,,,7.85398e-5
1:1 (rep 3),3-Recover,156.5,1.487,1.328,0.016,,0.471758,203.718,,47.1758,0.203718,,,,7.85398e-5
1:1 (rep 3),3-Recover,156.867,1.508,1.307,0.009,,0.464298,114.592,,46.4298,0.114592,,,,7.85398e-5
1:1 (rep 3),3-Recover,157.233,1.528,1.287,0.002,,0.457194,25.4648,,45.7194,0.0254648,,,,7.85398e-5
1:1 (rep 3),3-Recover,157.6,1.549,1.266,0.002,,0.449734,25.4648,,44.9734,0.0254648,,,,7.85398e-5
1:1 (rep 3),3-Recover,157.967,1.57,1.245,0.009,,0.442274,114.592,,44.2274,0.114592,,,,7.85398e-5
1:1 (rep 3),3-Recover,158.333,1.59,1.225,0.009,,0.435169,114.592,,43.5169,0.114592,,,,7.85398e-5
1:1 (rep 3),3-Recover,158.7,1.611,1.204,0.023,,0.427709,292.845,,42.7709,0.292845,,,,7.85398e-5
1:1 (rep 3),3-Recover,159.067,1.632,1.183,0.009,,0.420249,114.592,,42.0249,0.114592,,,,7.85398e-5
1:1 (rep 3),3-Recover,159.433,1.652,1.163,0.002,,0.413144,25.4648,,41.3144,0.0254648,,,,7.85398e-5
1:1 (rep 3),3-Recover,159.8,1.673,1.142,0.002,,0.405684,25.4648,,40.5684,0.0254648,,,,7.85398e-5
1:1 (rep 3),3-Recover,160.167,1.694,1.121,0.002,,0.398224,25.4648,,39.8224,0.0254648,,,,7.85398e-5
1:1 (rep 3),3-Recover,160.533,1.714,1.101,0.009,,0.391119,114.592,,39.1119,0.114592,,,,7.85398e-5
1:1 (rep 3),3-Recover,160.9,1.735,1.08,0.009,,0.383659,114.592,,38.3659,0.114592,,,,7.85398e-5
1:1 (rep 3),3-Recover,161.267,1.756,1.059,0.002,,0.376199,25.4648,,37.6199,0.0254648,,,,7.85398e-5
1:1 (rep 3),3-Recover,161.633,1.776,1.039,0.002,,0.369094,25.4648,,36.9094,0.0254648,,,,7.85398e-5
1:1 (rep 3),3-Recover,162,1.797,1.018,0.002,,0.361634,25.4648,,36.1634,0.0254648,,,,7.85398e-5
1:1 (rep 3),3-Recover,162.367,1.818,0.997,0.002,,0.354174,25.4648,,35.4174,0.0254648,,,,7.85398e-5
1:1 (rep 3),3-Recover,162.733,1.838,0.977,0.002,,0.347069,25.4648,,34.7069,0.0254648,,,,7.85398e-5
1:1 (rep 3),3-Recover,163.1,1.859,0.956,0.009,,0.339609,114.592,,33.9609,0.114592,,,,7.85398e-5
1:1 (rep 3),3-Recover,163.467,1.88,0.935,0.009,,0.332149,114.592,,33.2149,0.114592,,,,7.85398e-5
1:1 (rep 3),3-Recover,163.833,1.9,0.915,0.002,,0.325044,25.4648,,32.5044,0.0254648,,,,7.85398e-5
1:1 (rep 3),3-Recover,164.2,1.921,0.894,0.009,,0.317584,114.592,,31.7584,0.114592,,,,7.85398e-5
1:1 (rep 3),3-Recover,164.567,1.942,0.873,0.002,,0.310124,25.4648,,31.0124,0.0254648,,,,7.85398e-5
1:1 (rep 3),3-Recover,164.933,1.962,0.853,0.002,,0.30302,25.4648,,30.302,0.0254648,,,,7.85398e-5
1:1 (rep 3),3-Recover,165.3,1.983,0.832,0.002,,0.29556,25.4648,,29.556,0.0254648,,,,7.85398e-5
1:1 (rep 3),3-Recover,165.667,2.004,0.811,0.009,,0.288099,114.592,,28.8099,0.114592,,,,7.85398e-5
1:1 (rep 3),3-Recover,166.033,2.024,0.791,0.016,,0.280995,203.718,,28.0995,0.203718,,,,7.85398e-5
1:1 (rep 3),3-Recover,166.4,2.045,0.77,0.002,,0.273535,25.4648,,27.3535,0.0254648,,,,7.85398e-5
1:1 (rep 3),3-Recover,166.767,2.066,0.749,-0.004,,0.266075,-50.9296,,26.6075,-0.0509296,,,,7.85398e-5
1:1 (rep 3),3-Recover,167.133,2.086,0.729,0.002,,0.25897,25.4648,,25.897,0.0254648,,,,7.85398e-5
1:1 (rep 3),3-Recover,167.5,2.107,0.708,0.002,,0.25151,25.4648,,25.151,0.0254648,,,,7.85398e-5
1:1 (rep 3),3-Recover,167.867,2.128,0.687,0.002,,0.24405,25.4648,,24.405,0.0254648,,,,7.85398e-5
1:1 (rep 3),3-Recover,168.233,2.148,0.667,0.009,,0.236945,114.592,,23.6945,0.114592,,,,7.85398e-5
1:1 (rep 3),3-Recover,168.6,2.169,0.646,0.016,,0.229485,203.718,,22.9485,0.203718,,,,7.85398e-5
1:1 (rep 3),3-Recover,168.967,2.19,0.625,-0.004,,0.222025,-50.9296,,22.2025,-0.0509296,,,,7.85398e-5
1:1 (rep 3),3-Recover,169.333,2.21,0.605,0.009,,0.21492,114.592,,21.492,0.114592,,,,7.85398e-5
1:1 (rep 3),3-Recover,169.7,2.231,0.584,0.002,,0.20746,25.4648,,20.746,0.0254648,,,,7.85398e-5
1:1 (rep 3),3-Recover,170.067,2.252,0.563,0.002,,0.2,25.4648,,20,0.0254648,,,,7.85398e-5
1:1 (rep 3),3-Recover,170.433,2.272,0.543,0.002,,0.192895,25.4648,,19.2895,0.0254648,,,,7.85398e-5
1:1 (rep 3),3-Recover,170.8,2.293,0.522,0.016,,0.185435,203.718,,18.5435,0.203718,,,,7.85398e-5
1:1 (rep 3),3-Recover,171.167,2.314,0.501,0.002,,0.177975,25.4648,,17.7975,0.0254648,,,,7.85398e-5
1:1 (rep 3),3-Recover,171.533,2.334,0.481,0.009,,0.17087,114.592,,17.087,0.114592,,,,7.85398e-5
1:1 (rep 3),3-Recover,171.9,2.355,0.46,0.002,,0.16341,25.4648,,16.341,0.0254648,,,,7.85398e-5
1:1 (rep 3),3-Recover,172.267,2.376,0.439,-0.004,,0.15595,-50.9296,,15.595,-0.0509296,,,,7.85398e-5
1:1 (rep 3),3-Recover,172.633,2.396,0.419,0.002,,0.148845,25.4648,,14.8845,0.0254648,,,,7.85398e-5
1:1 (rep 3),3-Recover,173,2.417,0.398,0.002,,0.141385,25.4648,,14.1385,0.0254648,,,,7.85398e-5
1:1 (rep 3),3-Recover,173.367,2.438,0.377,0.009,,0.133925,114.592,,13.3925,0.114592,,,,7.85398e-5
1:1 (rep 3),3-Recover,173.733,2.458,0.357,0.009,,0.126821,114.592,,12.6821,0.114592,,,,7.85398e-5
1:1 (rep 3),3-Recover,174.1,2.479,0.336,0.002,,0.119361,25.4648,,11.9361,0.0254648,,,,7.85398e-5
1:1 (rep 3),3-Recover,174.467,2.5,0.315,0.002,,0.111901,25.4648,,11.1901,0.0254648,,,,7.85398e-5
1:1 (rep 3),3-Recover,174.833,2.52,0.295,-0.004,,0.104796,-50.9296,,10.4796,-0.0509296,,,,7.85398e-5
1:1 (rep 3),3-Recover,175.2,2.541,0.274,0.002,,0.0973357,25.4648,,9.73357,0.0254648,,,,7.85398e-5
1:1 (rep 3),3-Recover,175.567,2.562,0.253,0.009,,0.0898757,114.592,,8.98757,0.114592,,,,7.85398e-5
1:1 (rep 3),3-Recover,175.933,2.582,0.233,0.009,,0.0827709,114.592,,8.27709,0.114592,,,,7.85398e-5
1:1 (rep 3),3-Recover,176.3,2.603,0.212,0.002,,0.0753108,25.4648,,7.53108,0.0254648,,,,7.85398e-5
1:1 (rep 3),3-Recover,176.667,2.624,0.191,0.002,,0.0678508,25.4648,,6.78508,0.0254648,,,,7.85398e-5
1:1 (rep 3),3-Recover,177.033,2.644,0.171,-0.004,,0.060746,-50.9296,,6.0746,-0.0509296,,,,7.85398e-5
1:1 (rep 3),3-Recover,177.4,2.665,0.15,-0.004,,0.053286,-50.9296,,5.3286,-0.0509296,,,,7.85398e-5
1:1 (rep 3),3-Recover,177.767,2.687,0.128,0.002,,0.0454707,25.4648,,4.54707,0.0254648,,,,7.85398e-5
1:1 (rep 3),3-Recover,178.133,2.706,0.109,0.009,,0.0387211,114.592,,3.87211,0.114592,,,,7.85398e-5
1:1 (rep 3),3-Recover,178.5,2.727,0.088,0.009,,0.0312611,114.592,,3.12611,0.114592,,,,7.85398e-5
1:1 (rep 3),3-Recover,178.867,2.749,0.066,0.002,,0.0234458,25.4648,,2.34458,0.0254648,,,,7.85398e-5
1:1 (rep 3),3-Recover,179.233,2.768,0.047,-0.004,,0.0166963,-50.9296,,1.66963,-0.0509296,,,,7.85398e-5
1:1 (rep 3),3-Recover,179.6,2.789,0.026,0.002,,0.00923623,25.4648,,0.923623,0.0254648,,,,7.85398e-5
1:1 (rep 3),3-Recover,179.967,2.811,0.004,-0.004,,0.00142096,-50.9296,,0.142096,-0.0509296,,,,7.85398e-5
1:1 (rep 3),3-Recover,180.1,2.815,0,0.009,,0,114.592,,0,0.114592,,,,7.85398e-5