File: data/beta_1-1-0.5_3.csv
SetName,Cycle,Time_S,Size_mm,Displacement_mm,Force_N,,Strain,Stress(Pascal),,%Strain,Stress(kPa),,,,Area(m^2)
1:0.5 (rep 3),1-Compress,0,3.528,0,0.011,,0,140.056,,0,0.140056,,,,7.85398e-5
1:0.5 (rep 3),1-Compress,0.367,3.503,0.025,0.011,,0.00708617,140.056,,0.708617,0.140056,,,,7.85398e-5
1:0.5 (rep 3),1-Compress,0.733,3.477,0.051,0.011,,0.0144558,140.056,,1.44558,0.140056,,,,7.85398e-5
1:0.5 (rep 3),1-Compress,1.1,3.451,0.077,0.018,,0.0218254,229.183,,2.18254,0.229183,,,,7.85398e-5
1:0.5 (rep 3),1-Compress,1.467,3.425,0.103,0.018,,0.029195,229.183,,2.9195,0.229183,,,,7.85398e-5
1:0.5 (rep 3),1-Compress,1.833,3.399,0.129,0.018,,0.0365646,229.183,,3.65646,0.229183,,,,7.85398e-5
1:0.5 (rep 3),1-Compress,2.2,3.373,0.155,0.025,,0.0439342,318.31,,4.39342,0.31831,,,,7.85398e-5
1:0.5 (rep 3),1-Compress,2.567,3.347,0.181,0.032,,0.0513039,407.437,,5.13039,0.407437,,,,7.85398e-5
1:0.5 (rep 3),1-Compress,2.933,3.321,0.207,0.038,,0.0586735,483.831,,5.86735,0.483831,,,,7.85398e-5
1:0.5 (rep 3),1-Compress,3.3,3.295,0.233,0.025,,0.0660431,318.31,,6.60431,0.31831,,,,7.85398e-5
1:0.5 (rep 3),1-Compress,3.667,3.269,0.259,0.018,,0.0734127,229.183,,7.34127,0.229183,,,,7.85398e-5
1:0.5 (rep 3),1-Compress,4.033,3.244,0.284,0.018,,0.0804989,229.183,,8.04989,0.229183,,,,7.85398e-5
1:0.5 (rep 3),1-Compress,4.4,3.218,0.31,0.018,,0.0878685,229.183,,8.78685,0.229183,,,,7.85398e-5
1:0.5 (rep 3),1-Compress,4.767,3.191,0.337,0.038,,0.0955215,483.831,,9.55215,0.483831,,,,7.85398e-5
1:0.5 (rep 3),1-Compress,5.133,3.166,0.362,0.059,,0.102608,751.211,,10.2608,0.751211,,,,7.85398e-5
1:0.5 (rep 3),1-Compress,5.5,3.14,0.388,0.059,,0.109977,751.211,,10.9977,0.751211,,,,7.85398e-5
1:0.5 (rep 3),1-Compress,5.867,3.114,0.414,0.059,,0.117347,751.211,,11.7347,0.751211,,,,7.85398e-5
1:0.5 (rep 3),1-Compress,6.233,3.088,0.44,0.059,,0.124717,751.211,,12.4717,0.751211,,,,7.85398e-5
1:0.5 (rep 3),1-Compress,6.6,3.062,0.466,0.052,,0.132086,662.085,,13.2086,0.662085,,,,7.85398e-5
1:0.5 (rep 3),1-Compress,6.967,3.036,0.492,0.059,,0.139456,751.211,,13.9456,0.751211,,,,7.85398e-5
1:0.5 (rep 3),1-Compress,7.333,3.01,0.518,0.066,,0.146825,840.338,,14.6825,0.840338,,,,7.85398e-5
1:0.5 (rep 3),1-Compress,7.7,2.985,0.543,0.066,,0.153912,840.338,,15.3912,0.840338,,,,7.85398e-5
1:0.5 (rep 3),1-Compress,8.067,2.958,0.57,0.066,,0.161565,840.338,,16.1565,0.840338,,,,7.85398e-5
1:0.5 (rep 3),1-Compress,8.433,2.933,0.595,0.066,,0.168651,840.338,,16.8651,0.840338,,,,7.85398e-5
1:0.5 (rep 3),1-Compress,8.8,2.907,0.621,0.066,,0.17602,840.338,,17.602,0.840338,,,,7.85398e-5
1:0.5 (rep 3),1-Compress,9.167,2.88,0.648,0.072,,0.183673,916.733,,18.3673,0.916733,,,,7.85398e-5
1:0.5 (rep 3),1-Compress,9.533,2.855,0.673,0.066,,0.19076,840.338,,19.076,0.840338,,,,7.85398e-5
1:0.5 (rep 3),1-Compress,9.9,2.829,0.699,0.072,,0.198129,916.733,,19.8129,0.916733,,,,7.85398e-5
1:0.5 (rep 3),1-Compress,10.267,2.803,0.725,0.066,,0.205499,840.338,,20.5499,0.840338,,,,7.85398e-5
1:0.5 (rep 3),1-Compress,10.633,2.777,0.751,0.066,,0.212868,840.338,,21.2868,0.840338,,,,7.85398e-5
1:0.5 (rep 3),1-Compress,11,2.751,0.777,0.066,,0.220238,840.338,,22.0238,0.840338,,,,7.85398e-5
1:0.5 (rep 3),1-Compress,11.367,2.725,0.803,0.072,,0.227608,916.733,,22.7608,0.916733,,,,7.85398e-5
1:0.5 (rep 3),1-Compress,11.733,2.699,0.829,0.066,,0.234977,840.338,,23.4977,0.840338,,,,7.85398e-5
1:0.5 (rep 3),1-Compress,12.1,2.674,0.854,0.072,,0.242063,916.733,,24.2063,0.916733,,,,7.85398e-5
1:0.5 (rep 3),1-Compress,12.467,2.647,0.881,0.079,,0.249717,1005.86,,24.9717,1.00586,,,,7.85398e-5
1:0.5 (rep 3),1-Compress,12.833,2.622,0.906,0.079,,0.256803,1005.86,,25.6803,1.00586,,,,7.85398e-5
1:0.5 (rep 3),1-Compress,13.2,2.596,0.932,0.093,,0.264172,1184.11,,26.4172,1.18411,,,,7.85398e-5
1:0.5 (rep 3),1-Compress,13.567,2.569,0.959,0.086,,0.271825,1094.99,,27.1825,1.09499,,,,7.85398e-5
1:0.5 (rep 3),1-Compress,13.933,2.544,0.984,0.093,,0.278912,1184.11,,27.8912,1.18411,,,,7.85398e-5
1:0.5 (rep 3),1-Compress,14.3,2.518,1.01,0.099,,0.286281,1260.51,,28.6281,1.26051,,,,7.85398e-5
1:0.5 (rep 3),1-Compress,14.667,2.492,1.036,0.086,,0.293651,1094.99,,29.3651,1.09499,,,,7.85398e-5
1:0.5 (rep 3),1-Compress,15.033,2.466,1.062,0.106,,0.30102,1349.63,,30.102,1.34963,,,,7.85398e-5
1:0.5 (rep 3),1-Compress,15.4,2.44,1.088,0.12,,0.30839,1527.89,,30.839,1.52789,,,,7.85398e-5
1:0.5 (rep 3),1-Compress,15.767,2.414,1.114,0.12,,0.31576,1527.89,,31.576,1.52789,,,,7.85398e-5
1:0.5 (rep 3),1-Compress,16.133,2.389,1.139,0.12,,0.322846,1527.89,,32.2846,1.52789,,,,7.85398e-5
1:0.5 (rep 3),1-Compress,16.5,2.362,1.166,0.12,,0.330499,1527.89,,33.0499,1.52789,,,,7.85398e-5
1:0.5 (rep 3),1-Compress,16.867,2.336,1.192,0.12,,0.337868,1527.89,,33.7868,1.52789,,,,7.85398e-5
1:0.5 (rep 3),1-Compress,17.233,2.311,1.217,0.12,,0.344955,1527.89,,34.4955,1.52789,,,,7.85398e-5
1:0.5 (rep 3),1-Compress,17.6,2.285,1.243,0.12,,0.352324,1527.89,,35.2324,1.52789,,,,7.85398e-5
1:0.5 (rep 3),1-Compress,17.967,2.259,1.269,0.127,,0.359694,1617.01,,35.9694,1.61701,,,,7.85398e-5
1:0.5 (rep 3),1-Compress,18.333,2.233,1.295,0.133,,0.367063,1693.41,,36.7063,1.69341,,,,7.85398e-5
1:0.5 (rep 3),1-Compress,18.7,2.207,1.321,0.127,,0.374433,1617.01,,37.4433,1.61701,,,,7.85398e-5
1:0.5 (rep 3),1-Compress,19.067,2.181,1.347,0.133,,0.381803,1693.41,,38.1803,1.69341,,,,7.85398e-5
1:0.5 (rep 3),1-Compress,19.433,2.156,1.372,0.127,,0.388889,1617.01,,38.8889,1.61701,,,,7.85398e-5
1:0.5 (rep 3),1-Compress,19.8,2.129,1.399,0.147,,0.396542,1871.66,,39.6542,1.87166,,,,7.85398e-5
1:0.5 (rep 3),1-Compress,20.167,2.103,1.425,0.161,,0.403912,2049.92,,40.3912,2.04992,,,,7.85398e-5
1:0.5 (rep 3),1-Compress,20.533,2.078,1.45,0.174,,0.410998,2215.44,,41.0998,2.21544,,,,7.85398e-5
1:0.5 (rep 3),1-Compress,20.9,2.051,1.477,0.174,,0.418651,2215.44,,41.8651,2.21544,,,,7.85398e-5
1:0.5 (rep 3),1-Compress,21.267,2.026,1.502,0.174,,0.425737,2215.44,,42.5737,2.21544,,,,7.85398e-5
1:0.5 (rep 3),1-Compress,21.633,2,1.528,0.174,,0.433107,2215.44,,43.3107,2.21544,,,,7.85398e-5
1:0.5 (rep 3),1-Compress,22,1.974,1.554,0.174,,0.440476,2215.44,,44.0476,2.21544,,,,7.85398e-5
1:0.5 (rep 3),1-Compress,22.367,1.948,1.58,0.174,,0.447846,2215.44,,44.7846,2.21544,,,,7.85398e-5
1:0.5 (rep 3),1-Compress,22.733,1.922,1.606,0.167,,0.455215,2126.31,,45.5215,2.12631,,,,7.85398e-5
1:0.5 (rep 3),1-Compress,23.1,1.896,1.632,0.181,,0.462585,2304.56,,46.2585,2.30456,,,,7.85398e-5
1:0.5 (rep 3),1-Compress,23.467,1.87,1.658,0.181,,0.469955,2304.56,,46.9955,2.30456,,,,7.85398e-5
1:0.5 (rep 3),1-Compress,23.833,1.844,1.684,0.188,,0.477324,2393.69,,47.7324,2.39369,,,,7.85398e-5
1:0.5 (rep 3),1-Compress,24.2,1.818,1.71,0.188,,0.484694,2393.69,,48.4694,2.39369,,,,7.85398e-5
1:0.5 (rep 3),1-Compress,24.567,1.792,1.736,0.229,,0.492063,2915.72,,49.2063,2.91572,,,,7.85398e-5
1:0.5 (rep 3),1-Compress,24.933,1.767,1.761,0.222,,0.49915,2826.59,,49.915,2.82659,,,,7.85398e-5
1:0.5 (rep 3),1-Compress,25.3,1.74,1.788,0.208,,0.506803,2648.34,,50.6803,2.64834,,,,7.85398e-5
1:0.5 (rep 3),1-Compress,25.667,1.714,1.814,0.208,,0.514172,2648.34,,51.4172,2.64834,,,,7.85398e-5
1:0.5 (rep 3),1-Compress,26.033,1.689,1.839,0.215,,0.521259,2737.47,,52.1259,2.73747,,,,7.85398e-5
1:0.5 (rep 3),1-Compress,26.4,1.663,1.865,0.229,,0.528628,2915.72,,52.8628,2.91572,,,,7.85398e-5
1:0.5 (rep 3),1-Compress,26.767,1.637,1.891,0.242,,0.535998,3081.24,,53.5998,3.08124,,,,7.85398e-5
1:0.5 (rep 3),1-Compress,27.133,1.611,1.917,0.256,,0.543367,3259.49,,54.3367,3.25949,,,,7.85398e-5
1:0.5 (rep 3),1-Compress,27.5,1.585,1.943,0.242,,0.550737,3081.24,,55.0737,3.08124,,,,7.85398e-5
1:0.5 (rep 3),1-Compress,27.867,1.559,1.969,0.235,,0.558107,2992.11,,55.8107,2.99211,,,,7.85398e-5
1:0.5 (rep 3),1-Compress,28.233,1.533,1.995,0.229,,0.565476,2915.72,,56.5476,2.91572,,,,7.85398e-5
1:0.5 (rep 3),1-Compress,28.6,1.507,2.021,0.229,,0.572846,2915.72,,57.2846,2.91572,,,,7.85398e-5
1:0.5 (rep 3),1-Compress,28.967,1.481,2.047,0.235,,0.580215,2992.11,,58.0215,2.99211,,,,7.85398e-5
1:0.5 (rep 3),1-Compress,29.333,1.456,2.072,0.235,,0.587302,2992.11,,58.7302,2.99211,,,,7.85398e-5
1:0.5 (rep 3),1-Compress,29.7,1.43,2.098,0.262,,0.594671,3335.89,,59.4671,3.33589,,,,7.85398e-5
1:0.5 (rep 3),1-Recover,30.067,1.414,2.114,0.283,,0.599206,3603.27,,59.9206,3.60327,,,,7.85398e-5
1:0.5 (rep 3),1-Recover,30.433,1.439,2.089,0.269,,0.59212,3425.02,,59.212,3.42502,,,,7.85398e-5
1:0.5 (rep 3),1-Recover,30.8,1.466,2.062,0.249,,0.584467,3170.37,,58.4467,3.17037,,,,7.85398e-5
1:0.5 (rep 3),1-Recover,31.167,1.492,2.036,0.229,,0.577098,2915.72,,57.7098,2.91572,,,,7.85398e-5
1:0.5 (rep 3),1-Recover,31.533,1.517,2.011,0.235,,0.570011,2992.11,,57.0011,2.99211,,,,7.85398e-5
1:0.5 (rep 3),1-Recover,31.9,1.543,1.985,0.235,,0.562642,2992.11,,56.2642,2.99211,,,,7.85398e-5
1:0.5 (rep 3),1-Recover,32.267,1.569,1.959,0.256,,0.555272,3259.49,,55.5272,3.25949,,,,7.85398e-5
1:0.5 (rep 3),1-Recover,32.633,1.595,1.933,0.229,,0.547902,2915.72,,54.7902,2.91572,,,,7.85398e-5
1:0.5 (rep 3),1-Recover,33,1.621,1.907,0.208,,0.540533,2648.34,,54.0533,2.64834,,,,7.85398e-5
1:0.5 (rep 3),1-Recover,33.367,1.647,1.881,0.208,,0.533163,2648.34,,53.3163,2.64834,,,,7.85398e-5
1:0.5 (rep 3),1-Recover,33.733,1.673,1.855,0.215,,0.525794,2737.47,,52.5794,2.73747,,,,7.85398e-5
1:0.5 (rep 3),1-Recover,34.1,1.699,1.829,0.222,,0.518424,2826.59,,51.8424,2.82659,,,,7.85398e-5
1:0.5 (rep 3),1-Recover,34.467,1.725,1.803,0.229,,0.511054,2915.72,,51.1054,2.91572,,,,7.85398e-5
1:0.5 (rep 3),1-Recover,34.833,1.751,1.777,0.188,,0.503685,2393.69,,50.3685,2.39369,,,,7.85398e-5
1:0.5 (rep 3),1-Recover,35.2,1.777,1.751,0.181,,0.496315,2304.56,,49.6315,2.30456,,,,7.85398e-5
1:0.5 (rep 3),1-Recover,35.567,1.803,1.725,0.161,,0.488946,2049.92,,48.8946,2.04992,,,,7.85398e-5
1:0.5 (rep 3),1-Recover,35.933,1.828,1.7,0.167,,0.481859,2126.31,,48.1859,2.12631,,,,7.85398e-5
1:0.5 (rep 3),1-Recover,36.3,1.854,1.674,0.174,,0.47449,2215.44,,47.449,2.21544,,,,7.85398e-5
1:0.5 (rep 3),1-Recover,36.667,1.881,1.647,0.174,,0.466837,2215.44,,46.6837,2.21544,,,,7.85398e-5
1:0.5 (rep 3),1-Recover,37.033,1.906,1.622,0.174,,0.459751,2215.44,,45.9751,2.21544,,,,7.85398e-5
1:0.5 (rep 3),1-Recover,37.4,1.932,1.596,0.167,,0.452381,2126.31,,45.2381,2.12631,,,,7.85398e-5
1:0.5 (rep 3),1-Recover,37.767,1.958,1.57,0.167,,0.445011,2126.31,,44.5011,2.12631,,,,7.85398e-5
1:0.5 (rep 3),1-Recover,38.133,1.984,1.544,0.167,,0.437642,2126.31,,43.7642,2.12631,,,,7.85398e-5
1:0.5 (rep 3),1-Recover,38.5,2.01,1.518,0.154,,0.430272,1960.79,,43.0272,1.96079,,,,7.85398e-5
1:0.5 (rep 3),1-Recover,38.867,2.036,1.492,0.14,,0.422902,1782.54,,42.2902,1.78254,,,,7.85398e-5
1:0.5 (rep 3),1-Recover,39.233,2.062,1.466,0.127,,0.415533,1617.01,,41.5533,1.61701,,,,7.85398e-5
1:0.5 (rep 3),1-Recover,39.6,2.088,1.44,0.12,,0.408163,1527.89,,40.8163,1.52789,,,,7.85398e-5
1:0.5 (rep 3),1-Recover,39.967,2.114,1.414,0.12,,0.400794,1527.89,,40.0794,1.52789,,,,7.85398e-5
1:0.5 (rep 3),1-Recover,40.333,2.139,1.389,0.12,,0.393707,1527.89,,39.3707,1.52789,,,,7.85398e-5
1:0.5 (rep 3),1-Recover,40.7,2.165,1.363,0.12,,0.386338,1527.89,,38.6338,1.52789,,,,7.85398e-5
1:0.5 (rep 3),1-Recover,41.067,2.192,1.336,0.12,,0.378685,1527.89,,37.8685,1.52789,,,,7.85398e-5
1:0.5 (rep 3),1-Recover,41.433,2.217,1.311,0.12,,0.371599,1527.89,,37.1599,1.52789,,,,7.85398e-5
1:0.5 (rep 3),1-Recover,41.8,2.243,1.285,0.12,,0.364229,1527.89,,36.4229,1.52789,,,,7.85398e-5
1:0.5 (rep 3),1-Recover,42.167,2.269,1.259,0.12,,0.356859,1527.89,,35.6859,1.52789,,,,7.85398e-5
1:0.5 (rep 3),1-Recover,42.533,2.294,1.234,0.12,,0.349773,1527.89,,34.9773,1.52789,,,,7.85398e-5
1:0.5 (rep 3),1-Recover,42.9,2.321,1.207,0.106,,0.34212,1349.63,,34.212,1.34963,,,,7.85398e-5
1:0.5 (rep 3),1-Recover,43.267,2.347,1.181,0.099,,0.334751,1260.51,,33.4751,1.26051,,,,7.85398e-5
1:0.5 (rep 3),1-Recover,43.633,2.372,1.156,0.106,,0.327664,1349.63,,32.7664,1.34963,,,,7.85398e-5
1:0.5 (rep 3),1-Recover,44,2.398,1.13,0.086,,0.320295,1094.99,,32.0295,1.09499,,,,7.85398e-5
1:0.5 (rep 3),1-Recover,44.367,2.425,1.103,0.072,,0.312642,916.733,,31.2642,0.916733,,,,7.85398e-5
1:0.5 (rep 3),1-Recover,44.733,2.45,1.078,0.066,,0.305556,840.338,,30.5556,0.840338,,,,7.85398e-5
1:0.5 (rep 3),1-Recover,45.1,2.476,1.052,0.079,,0.298186,1005.86,,29.8186,1.00586,,,,7.85398e-5
1:0.5 (rep 3),1-Recover,45.467,2.502,1.026,0.086,,0.290816,1094.99,,29.0816,1.09499,,,,7.85398e-5
1:0.5 (rep 3),1-Recover,45.833,2.528,1,0.072,,0.283447,916.733,,28.3447,0.916733,,,,7.85398e-5
1:0.5 (rep 3),1-Recover,46.2,2.554,0.974,0.072,,0.276077,916.733,,27.6077,0.916733,,,,7.85398e-5
1:0.5 (rep 3),1-Recover,46.567,2.58,0.948,0.066,,0.268707,840.338,,26.8707,0.840338,,,,7.85398e-5
1:0.5 (rep 3),1-Recover,46.933,2.606,0.922,0.066,,0.261338,840.338,,26.1338,0.840338,,,,7.85398e-5
1:0.5 (rep 3),1-Recover,47.3,2.632,0.896,0.072,,0.253968,916.733,,25.3968,0.916733,,,,7.85398e-5
1:0.5 (rep 3),1-Recover,47.667,2.658,0.87,0.072,,0.246599,916.733,,24.6599,0.916733,,,,7.85398e-5
1:0.5 (rep 3),1-Recover,48.033,2.683,0.845,0.066,,0.239512,840.338,,23.9512,0.840338,,,,7.85398e-5
1:0.5 (rep 3),1-Recover,48.4,2.71,0.818,0.066,,0.231859,840.338,,23.1859,0.840338,,,,7.85398e-5
1:0.5 (rep 3),1-Recover,48.767,2.736,0.792,0.066,,0.22449,840.338,,22.449,0.840338,,,,7.85398e-5
1:0.5 (rep 3),1-Recover,49.133,2.761,0.767,0.066,,0.217404,840.338,,21.7404,0.840338,,,,7.85398e-5
1:0.5 (rep 3),1-Recover,49.5,2.787,0.741,0.066,,0.210034,840.338,,21.0034,0.840338,,,,7.85398e-5
1:0.5 (rep 3),1-Recover,49.867,2.813,0.715,0.059,,0.202664,751.211,,20.2664,0.751211,,,,7.85398e-5
1:0.5 (rep 3),1-Recover,50.233,2.839,0.689,0.059,,0.195295,751.211,,19.5295,0.751211,,,,7.85398e-5
1:0.5 (rep 3),1-Recover,50.6,2.865,0.663,0.066,,0.187925,840.338,,18.7925,0.840338,,,,7.85398e-5
1:0.5 (rep 3),1-Recover,50.967,2.891,0.637,0.059,,0.180556,751.211,,18.0556,0.751211,,,,7.85398e-5
1:0.5 (rep 3),1-Recover,51.333,2.917,0.611,0.066,,0.173186,840.338,,17.3186,0.840338,,,,7.85398e-5
1:0.5 (rep 3),1-Recover,51.7,2.943,0.585,0.038,,0.165816,483.831,,16.5816,0.483831,,,,7.85398e-5
1:0.5 (rep 3),1-Recover,52.067,2.969,0.559,0.038,,0.158447,483.831,,15.8447,0.483831,,,,7.85398e-5
1:0.5 (rep 3),1-Recover,52.433,2.994,0.534,0.025,,0.151361,318.31,,15.1361,0.31831,,,,7.85398e-5
1:0.5 (rep 3),1-Recover,52.8,3.02,0.508,0.052,,0.143991,662.085,,14.3991,0.662085,,,,7.85398e-5
1:0.5 (rep 3),1-Recover,53.167,3.047,0.481,0.045,,0.136338,572.958,,13.6338,0.572958,,,,7.85398e-5
1:0.5 (rep 3),1-Recover,53.533,3.072,0.456,0.038,,0.129252,483.831,,12.9252,0.483831,,,,7.85398e-5
1:0.5 (rep 3),1-Recover,53.9,3.098,0.43,0.032,,0.121882,407.437,,12.1882,0.407437,,,,7.85398e-5
1:0.5 (rep 3),1-Recover,54.267,3.124,0.404,0.018,,0.114512,229.183,,11.4512,0.229183,,,,7.85398e-5
1:0.5 (rep 3),1-Recover,54.633,3.15,0.378,0.018,,0.107143,229.183,,10.7143,0.229183,,,,7.85398e-5
1:0.5 (rep 3),1-Recover,55,3.176,0.352,0.025,,0.0997732,318.31,,9.97732,0.31831,,,,7.85398e-5
1:0.5 (rep 3),1-Recover,55.367,3.202,0.326,0.025,,0.0924036,318.31,,9.24036,0.31831,,,,7.85398e-5
1:0.5 (rep 3),1-Recover,55.733,3.228,0.3,0.018,,0.085034,229.183,,8.5034,0.229183,,,,7.85398e-5
1:0.5 (rep 3),1-Recover,56.1,3.253,0.275,0.025,,0.0779478,318.31,,7.79478,0.31831,,,,7.85398e-5
1:0.5 (rep 3),1-Recover,56.467,3.28,0.248,0.018,,0.0702948,229.183,,7.02948,0.229183,,,,7.85398e-5
1:0.5 (rep 3),1-Recover,56.833,3.305,0.223,0.018,,0.0632086,229.183,,6.32086,0.229183,,,,7.85398e-5
1:0.5 (rep 3),1-Recover,57.2,3.331,0.197,0.018,,0.055839,229.183,,5.5839,0.229183,,,,7.85398e-5
1:0.5 (rep 3),1-Recover,57.567,3.358,0.17,0.025,,0.0481859,318.31,,4.81859,0.31831,,,,7.85398e-5
1:0.5 (rep 3),1-Recover,57.933,3.383,0.145,0.032,,0.0410998,407.437,,4.10998,0.407437,,,,7.85398e-5
1:0.5 (rep 3),1-Recover,58.3,3.409,0.119,0.011,,0.0337302,140.056,,3.37302,0.140056,,,,7.85398e-5
1:0.5 (rep 3),1-Recover,58.667,3.435,0.093,0.011,,0.0263605,140.056,,2.63605,0.140056,,,,7.85398e-5
1:0.5 (rep 3),1-Recover,59.033,3.461,0.067,0.011,,0.0189909,140.056,,1.89909,0.140056,,,,7.85398e-5
1:0.5 (rep 3),1-Recover,59.4,3.487,0.041,0.011,,0.0116213,140.056,,1.16213,0.140056,,,,7.85398e-5
1:0.5 (rep 3),1-Recover,59.767,3.513,0.015,0.018,,0.0042517,229.183,,0.42517,0.229183,,,,7.85398e-5
1:0.5 (rep 3),2-Compress,60.117,3.523,0.005,0.025,,0.00141723,318.31,,0.141723,0.31831,,,,7.85398e-5
1:0.5 (rep 3),2-Compress,60.483,3.497,0.031,0.025,,0.00878685,318.31,,0.878685,0.31831,,,,7.85398e-5
1:0.5 (rep 3),2-Compress,60.85,3.471,0.057,0.018,,0.0161565,229.183,,1.61565,0.229183,,,,7.85398e-5
1:0.5 (rep 3),2-Compress,61.217,3.445,0.083,0.018,,0.0235261,229.183,,2.35261,0.229183,,,,7.85398e-5
1:0.5 (rep 3),2-Compress,61.583,3.419,0.109,0.025,,0.0308957,318.31,,3.08957,0.31831,,,,7.85398e-5
1:0.5 (rep 3),2-Compress,61.95,3.393,0.135,0.018,,0.0382653,229.183,,3.82653,0.229183,,,,7.85398e-5
1:0.5 (rep 3),2-Compress,62.317,3.367,0.161,0.018,,0.0456349,229.183,,4.56349,0.229183,,,,7.85398e-5
1:0.5 (rep 3),2-Compress,62.683,3.342,0.186,0.032,,0.0527211,407.437,,5.27211,0.407437,,,,7.85398e-5
1:0.5 (rep 3),2-Compress,63.05,3.316,0.212,0.038,,0.0600907,483.831,,6.00907,0.483831,,,,7.85398e-5
1:0.5 (rep 3),2-Compress,63.417,3.289,0.239,0.032,,0.0677438,407.437,,6.77438,0.407437,,,,7.85398e-5
1:0.5 (rep 3),2-Compress,63.783,3.264,0.264,0.032,,0.0748299,407.437,,7.48299,0.407437,,,,7.85398e-5
1:0.5 (rep 3),2-Compress,64.15,3.238,0.29,0.025,,0.0821995,318.31,,8.21995,0.31831,,,,7.85398e-5
1:0.5 (rep 3),2-Compress,64.517,3.212,0.316,0.038,,0.0895692,483.831,,8.95692,0.483831,,,,7.85398e-5
1:0.5 (rep 3),2-Compress,64.883,3.186,0.342,0.018,,0.0969388,229.183,,9.69388,0.229183,,,,7.85398e-5
1:0.5 (rep 3),2-Compress,65.25,3.16,0.368,0.032,,0.104308,407.437,,10.4308,0.407437,,,,7.85398e-5
1:0.5 (rep 3),2-Compress,65.617,3.134,0.394,0.052,,0.111678,662.085,,11.1678,0.662085,,,,7.85398e-5
1:0.5 (rep 3),2-Compress,65.983,3.108,0.42,0.059,,0.119048,751.211,,11.9048,0.751211,,,,7.85398e-5
1:0.5 (rep 3),2-Compress,66.35,3.082,0.446,0.059,,0.126417,751.211,,12.6417,0.751211,,,,7.85398e-5
1:0.5 (rep 3),2-Compress,66.717,3.056,0.472,0.066,,0.133787,840.338,,13.3787,0.840338,,,,7.85398e-5
1:0.5 (rep 3),2-Compress,67.083,3.031,0.497,0.066,,0.140873,840.338,,14.0873,0.840338,,,,7.85398e-5
1:0.5 (rep 3),2-Compress,67.45,3.005,0.523,0.066,,0.148243,840.338,,14.8243,0.840338,,,,7.85398e-5
1:0.5 (rep 3),2-Compress,67.817,2.978,0.55,0.066,,0.155896,840.338,,15.5896,0.840338,,,,7.85398e-5
1:0.5 (rep 3),2-Compress,68.183,2.953,0.575,0.066,,0.162982,840.338,,16.2982,0.840338,,,,7.85398e-5
1:0.5 (rep 3),2-Compress,68.55,2.927,0.601,0.066,,0.170351,840.338,,17.0351,0.840338,,,,7.85398e-5
1:0.5 (rep 3),2-Compress,68.917,2.901,0.627,0.066,,0.177721,840.338,,17.7721,0.840338,,,,7.85398e-5
1:0.5 (rep 3),2-Compress,69.283,2.875,0.653,0.066,,0.185091,840.338,,18.5091,0.840338,,,,7.85398e-5
1:0.5 (rep 3),2-Compress,69.65,2.849,0.679,0.066,,0.19246,840.338,,19.246,0.840338,,,,7.85398e-5
1:0.5 (rep 3),2-Compress,70.017,2.823,0.705,0.066,,0.19983,840.338,,19.983,0.840338,,,,7.85398e-5
1:0.5 (rep 3),2-Compress,70.383,2.797,0.731,0.066,,0.2072,840.338,,20.72,0.840338,,,,7.85398e-5
1:0.5 (rep 3),2-Compress,70.75,2.771,0.757,0.066,,0.214569,840.338,,21.4569,0.840338,,,,7.85398e-5
1:0.5 (rep 3),2-Compress,71.117,2.745,0.783,0.066,,0.221939,840.338,,22.1939,0.840338,,,,7.85398e-5
1:0.5 (rep 3),2-Compress,71.483,2.72,0.808,0.072,,0.229025,916.733,,22.9025,0.916733,,,,7.85398e-5
1:0.5 (rep 3),2-Compress,71.85,2.694,0.834,0.066,,0.236395,840.338,,23.6395,0.840338,,,,7.85398e-5
1:0.5 (rep 3),2-Compress,72.217,2.667,0.861,0.072,,0.244048,916.733,,24.4048,0.916733,,,,7.85398e-5
1:0.5 (rep 3),2-Compress,72.583,2.642,0.886,0.066,,0.251134,840.338,,25.1134,0.840338,,,,7.85398e-5
1:0.5 (rep 3),2-Compress,72.95,2.616,0.912,0.086,,0.258503,1094.99,,25.8503,1.09499,,,,7.85398e-5
1:0.5 (rep 3),2-Compress,73.317,2.59,0.938,0.106,,0.265873,1349.63,,26.5873,1.34963,,,,7.85398e-5
1:0.5 (rep 3),2-Compress,73.683,2.564,0.964,0.086,,0.273243,1094.99,,27.3243,1.09499,,,,7.85398e-5
1:0.5 (rep 3),2-Compress,74.05,2.538,0.99,0.099,,0.280612,1260.51,,28.0612,1.26051,,,,7.85398e-5
1:0.5 (rep 3),2-Compress,74.417,2.512,1.016,0.106,,0.287982,1349.63,,28.7982,1.34963,,,,7.85398e-5
1:0.5 (rep 3),2-Compress,74.783,2.487,1.041,0.086,,0.295068,1094.99,,29.5068,1.09499,,,,7.85398e-5
1:0.5 (rep 3),2-Compress,75.15,2.46,1.068,0.099,,0.302721,1260.51,,30.2721,1.26051,,,,7.85398e-5
1:0.5 (rep 3),2-Compress,75.517,2.434,1.094,0.12,,0.310091,1527.89,,31.0091,1.52789,,,,7.85398e-5
1:0.5 (rep 3),2-Compress,75.883,2.409,1.119,0.12,,0.317177,1527.89,,31.7177,1.52789,,,,7.85398e-5
1:0.5 (rep 3),2-Compress,76.25,2.383,1.145,0.12,,0.324546,1527.89,,32.4546,1.52789,,,,7.85398e-5
1:0.5 (rep 3),2-Compress,76.617,2.357,1.171,0.12,,0.331916,1527.89,,33.1916,1.52789,,,,7.85398e-5
1:0.5 (rep 3),2-Compress,76.983,2.331,1.197,0.12,,0.339286,1527.89,,33.9286,1.52789,,,,7.85398e-5
1:0.5 (rep 3),2-Compress,77.35,2.305,1.223,0.12,,0.346655,1527.89,,34.6655,1.52789,,,,7.85398e-5
1:0.5 (rep 3),2-Compress,77.717,2.279,1.249,0.12,,0.354025,1527.89,,35.4025,1.52789,,,,7.85398e-5
1:0.5 (rep 3),2-Compress,78.083,2.253,1.275,0.127,,0.361395,1617.01,,36.1395,1.61701,,,,7.85398e-5
1:0.5 (rep 3),2-Compress,78.45,2.227,1.301,0.12,,0.368764,1527.89,,36.8764,1.52789,,,,7.85398e-5
1:0.5 (rep 3),2-Compress,78.817,2.201,1.327,0.133,,0.376134,1693.41,,37.6134,1.69341,,,,7.85398e-5
1:0.5 (rep 3),2-Compress,79.183,2.176,1.352,0.133,,0.38322,1693.41,,38.322,1.69341,,,,7.85398e-5
1:0.5 (rep 3),2-Compress,79.55,2.149,1.379,0.127,,0.390873,1617.01,,39.0873,1.61701,,,,7.85398e-5
1:0.5 (rep 3),2-Compress,79.917,2.123,1.405,0.127,,0.398243,1617.01,,39.8243,1.61701,,,,7.85398e-5
1:0.5 (rep 3),2-Compress,80.283,2.098,1.43,0.147,,0.405329,1871.66,,40.5329,1.87166,,,,7.85398e-5
1:0.5 (rep 3),2-Compress,80.65,2.072,1.456,0.161,,0.412698,2049.92,,41.2698,2.04992,,,,7.85398e-5
1:0.5 (rep 3),2-Compress,81.017,2.046,1.482,0.174,,0.420068,2215.44,,42.0068,2.21544,,,,7.85398e-5
1:0.5 (rep 3),2-Compress,81.383,2.02,1.508,0.174,,0.427438,2215.44,,42.7438,2.21544,,,,7.85398e-5
1:0.5 (rep 3),2-Compress,81.75,1.994,1.534,0.174,,0.434807,2215.44,,43.4807,2.21544,,,,7.85398e-5
1:0.5 (rep 3),2-Compress,82.117,1.968,1.56,0.174,,0.442177,2215.44,,44.2177,2.21544,,,,7.85398e-5
1:0.5 (rep 3),2-Compress,82.483,1.942,1.586,0.174,,0.449546,2215.44,,44.9546,2.21544,,,,7.85398e-5
1:0.5 (rep 3),2-Compress,82.85,1.916,1.612,0.174,,0.456916,2215.44,,45.6916,2.21544,,,,7.85398e-5
1:0.5 (rep 3),2-Compress,83.217,1.89,1.638,0.167,,0.464286,2126.31,,46.4286,2.12631,,,,7.85398e-5
1:0.5 (rep 3),2-Compress,83.583,1.865,1.663,0.174,,0.471372,2215.44,,47.1372,2.21544,,,,7.85398e-5
1:0.5 (rep 3),2-Compress,83.95,1.838,1.69,0.188,,0.479025,2393.69,,47.9025,2.39369,,,,7.85398e-5
1:0.5 (rep 3),2-Compress,84.317,1.812,1.716,0.201,,0.486395,2559.21,,48.6395,2.55921,,,,7.85398e-5
1:0.5 (rep 3),2-Compress,84.683,1.787,1.741,0.229,,0.493481,2915.72,,49.3481,2.91572,,,,7.85398e-5
1:0.5 (rep 3),2-Compress,85.05,1.761,1.767,0.229,,0.50085,2915.72,,50.085,2.91572,,,,7.85398e-5
1:0.5 (rep 3),2-Compress,85.417,1.734,1.794,0.222,,0.508503,2826.59,,50.8503,2.82659,,,,7.85398e-5
1:0.5 (rep 3),2-Compress,85.783,1.709,1.819,0.208,,0.51559,2648.34,,51.559,2.64834,,,,7.85398e-5
1:0.5 (rep 3),2-Compress,86.15,1.683,1.845,0.208,,0.522959,2648.34,,52.2959,2.64834,,,,7.85398e-5
1:0.5 (rep 3),2-Compress,86.517,1.657,1.871,0.222,,0.530329,2826.59,,53.0329,2.82659,,,,7.85398e-5
1:0.5 (rep 3),2-Compress,86.883,1.631,1.897,0.242,,0.537698,3081.24,,53.7698,3.08124,,,,7.85398e-5
1:0.5 (rep 3),2-Compress,87.25,1.605,1.923,0.256,,0.545068,3259.49,,54.5068,3.25949,,,,7.85398e-5
1:0.5 (rep 3),2-Compress,87.617,1.579,1.949,0.269,,0.552438,3425.02,,55.2438,3.42502,,,,7.85398e-5
1:0.5 (rep 3),2-Compress,87.983,1.554,1.974,0.249,,0.559524,3170.37,,55.9524,3.17037,,,,7.85398e-5
1:0.5 (rep 3),2-Compress,88.35,1.528,2,0.235,,0.566893,2992.11,,56.6893,2.99211,,,,7.85398e-5
1:0.5 (rep 3),2-Compress,88.717,1.501,2.027,0.229,,0.574546,2915.72,,57.4546,2.91572,,,,7.85398e-5
1:0.5 (rep 3),2-Compress,89.083,1.476,2.052,0.242,,0.581633,3081.24,,58.1633,3.08124,,,,7.85398e-5
1:0.5 (rep 3),2-Compress,89.45,1.45,2.078,0.242,,0.589002,3081.24,,58.9002,3.08124,,,,7.85398e-5
1:0.5 (rep 3),2-Compress,89.817,1.424,2.104,0.269,,0.596372,3425.02,,59.6372,3.42502,,,,7.85398e-5
1:0.5 (rep 3),2-Recover,90.17,1.418,2.11,0.276,,0.598073,3514.14,,59.8073,3.51414,,,,7.85398e-5
1:0.5 (rep 3),2-Recover,90.537,1.444,2.084,0.269,,0.590703,3425.02,,59.0703,3.42502,,,,7.85398e-5
1:0.5 (rep 3),2-Recover,90.903,1.47,2.058,0.235,,0.583333,2992.11,,58.3333,2.99211,,,,7.85398e-5
1:0.5 (rep 3),2-Recover,91.27,1.496,2.032,0.229,,0.575964,2915.72,,57.5964,2.91572,,,,7.85398e-5
1:0.5 (rep 3),2-Recover,91.637,1.522,2.006,0.235,,0.568594,2992.11,,56.8594,2.99211,,,,7.85398e-5
1:0.5 (rep 3),2-Recover,92.003,1.548,1.98,0.242,,0.561224,3081.24,,56.1224,3.08124,,,,7.85398e-5
1:0.5 (rep 3),2-Recover,92.37,1.574,1.954,0.249,,0.553855,3170.37,,55.3855,3.17037,,,,7.85398e-5
1:0.5 (rep 3),2-Recover,92.737,1.6,1.928,0.229,,0.546485,2915.72,,54.6485,2.91572,,,,7.85398e-5
1:0.5 (rep 3),2-Recover,93.103,1.626,1.902,0.222,,0.539116,2826.59,,53.9116,2.82659,,,,7.85398e-5
1:0.5 (rep 3),2-Recover,93.47,1.652,1.876,0.208,,0.531746,2648.34,,53.1746,2.64834,,,,7.85398e-5
1:0.5 (rep 3),2-Recover,93.837,1.678,1.85,0.208,,0.524376,2648.34,,52.4376,2.64834,,,,7.85398e-5
1:0.5 (rep 3),2-Recover,94.203,1.703,1.825,0.215,,0.51729,2737.47,,51.729,2.73747,,,,7.85398e-5
1:0.5 (rep 3),2-Recover,94.57,1.73,1.798,0.215,,0.509637,2737.47,,50.9637,2.73747,,,,7.85398e-5
1:0.5 (rep 3),2-Recover,94.937,1.756,1.772,0.201,,0.502268,2559.21,,50.2268,2.55921,,,,7.85398e-5
1:0.5 (rep 3),2-Recover,95.303,1.781,1.747,0.174,,0.495181,2215.44,,49.5181,2.21544,,,,7.85398e-5
1:0.5 (rep 3),2-Recover,95.67,1.807,1.721,0.174,,0.487812,2215.44,,48.7812,2.21544,,,,7.85398e-5
1:0.5 (rep 3),2-Recover,96.037,1.833,1.695,0.167,,0.480442,2126.31,,48.0442,2.12631,,,,7.85398e-5
1:0.5 (rep 3),2-Recover,96.403,1.859,1.669,0.181,,0.473073,2304.56,,47.3073,2.30456,,,,7.85398e-5
1:0.5 (rep 3),2-Recover,96.77,1.885,1.643,0.174,,0.465703,2215.44,,46.5703,2.21544,,,,7.85398e-5
1:0.5 (rep 3),2-Recover,97.137,1.911,1.617,0.174,,0.458333,2215.44,,45.8333,2.21544,,,,7.85398e-5
1:0.5 (rep 3),2-Recover,97.503,1.936,1.592,0.174,,0.451247,2215.44,,45.1247,2.21544,,,,7.85398e-5
1:0.5 (rep 3),2-Recover,97.87,1.963,1.565,0.174,,0.443594,2215.44,,44.3594,2.21544,,,,7.85398e-5
1:0.5 (rep 3),2-Recover,98.237,1.989,1.539,0.154,,0.436224,1960.79,,43.6224,1.96079,,,,7.85398e-5
1:0.5 (rep 3),2-Recover,98.603,2.014,1.514,0.154,,0.429138,1960.79,,42.9138,1.96079,,,,7.85398e-5
1:0.5 (rep 3),2-Recover,98.97,2.04,1.488,0.147,,0.421769,1871.66,,42.1769,1.87166,,,,7.85398e-5
1:0.5 (rep 3),2-Recover,99.337,2.066,1.462,0.127,,0.414399,1617.01,,41.4399,1.61701,,,,7.85398e-5
1:0.5 (rep 3),2-Recover,99.703,2.092,1.436,0.127,,0.407029,1617.01,,40.7029,1.61701,,,,7.85398e-5
1:0.5 (rep 3),2-Recover,100.07,2.118,1.41,0.127,,0.39966,1617.01,,39.966,1.61701,,,,7.85398e-5
1:0.5 (rep 3),2-Recover,100.437,2.144,1.384,0.12,,0.39229,1527.89,,39.229,1.52789,,,,7.85398e-5
1:0.5 (rep 3),2-Recover,100.803,2.17,1.358,0.12,,0.384921,1527.89,,38.4921,1.52789,,,,7.85398e-5
1:0.5 (rep 3),2-Recover,101.17,2.196,1.332,0.12,,0.377551,1527.89,,37.7551,1.52789,,,,7.85398e-5
1:0.5 (rep 3),2-Recover,101.537,2.222,1.306,0.12,,0.370181,1527.89,,37.0181,1.52789,,,,7.85398e-5
1:0.5 (rep 3),2-Recover,101.903,2.248,1.28,0.12,,0.362812,1527.89,,36.2812,1.52789,,,,7.85398e-5
1:0.5 (rep 3),2-Recover,102.27,2.274,1.254,0.12,,0.355442,1527.89,,35.5442,1.52789,,,,7.85398e-5
1:0.5 (rep 3),2-Recover,102.637,2.3,1.228,0.106,,0.348073,1349.63,,34.8073,1.34963,,,,7.85398e-5
1:0.5 (rep 3),2-Recover,103.003,2.325,1.203,0.106,,0.340986,1349.63,,34.0986,1.34963,,,,7.85398e-5
1:0.5 (rep 3),2-Recover,103.37,2.351,1.177,0.113,,0.333617,1438.76,,33.3617,1.43876,,,,7.85398e-5
1:0.5 (rep 3),2-Recover,103.737,2.378,1.15,0.106,,0.325964,1349.63,,32.5964,1.34963,,,,7.85398e-5
1:0.5 (rep 3),2-Recover,104.103,2.403,1.125,0.093,,0.318878,1184.11,,31.8878,1.18411,,,,7.85398e-5
1:0.5 (rep 3),2-Recover,104.47,2.429,1.099,0.086,,0.311508,1094.99,,31.1508,1.09499,,,,7.85398e-5
1:0.5 (rep 3),2-Recover,104.837,2.455,1.073,0.072,,0.304138,916.733,,30.4138,0.916733,,,,7.85398e-5
1:0.5 (rep 3),2-Recover,105.203,2.481,1.047,0.066,,0.296769,840.338,,29.6769,0.840338,,,,7.85398e-5
1:0.5 (rep 3),2-Recover,105.57,2.507,1.021,0.072,,0.289399,916.733,,28.9399,0.916733,,,,7.85398e-5
1:0.5 (rep 3),2-Recover,105.937,2.533,0.995,0.072,,0.282029,916.733,,28.2029,0.916733,,,,7.85398e-5
1:0.5 (rep 3),2-Recover,106.303,2.558,0.97,0.066,,0.274943,840.338,,27.4943,0.840338,,,,7.85398e-5
1:0.5 (rep 3),2-Recover,106.67,2.585,0.943,0.066,,0.26729,840.338,,26.729,0.840338,,,,7.85398e-5
1:0.5 (rep 3),2-Recover,107.037,2.611,0.917,0.072,,0.259921,916.733,,25.9921,0.916733,,,,7.85398e-5
1:0.5 (rep 3),2-Recover,107.403,2.636,0.892,0.066,,0.252834,840.338,,25.2834,0.840338,,,,7.85398e-5
1:0.5 (rep 3),2-Recover,107.77,2.662,0.866,0.066,,0.245465,840.338,,24.5465,0.840338,,,,7.85398e-5
1:0.5 (rep 3),2-Recover,108.137,2.689,0.839,0.066,,0.237812,840.338,,23.7812,0.840338,,,,7.85398e-5
1:0.5 (rep 3),2-Recover,108.503,2.714,0.814,0.066,,0.230726,840.338,,23.0726,0.840338,,,,7.85398e-5
1:0.5 (rep 3),2-Recover,108.87,2.74,0.788,0.066,,0.223356,840.338,,22.3356,0.840338,,,,7.85398e-5
1:0.5 (rep 3),2-Recover,109.237,2.766,0.762,0.066,,0.215986,840.338,,21.5986,0.840338,,,,7.85398e-5
1:0.5 (rep 3),2-Recover,109.603,2.791,0.737,0.066,,0.2089,840.338,,20.89,0.840338,,,,7.85398e-5
1:0.5 (rep 3),2-Recover,109.97,2.818,0.71,0.059,,0.201247,751.211,,20.1247,0.751211,,,,7.85398e-5
1:0.5 (rep 3),2-Recover,110.337,2.844,0.684,0.066,,0.193878,840.338,,19.3878,0.840338,,,,7.85398e-5
1:0.5 (rep 3),2-Recover,110.703,2.869,0.659,0.059,,0.186791,751.211,,18.6791,0.751211,,,,7.85398e-5
1:0.5 (rep 3),2-Recover,111.07,2.895,0.633,0.059,,0.179422,751.211,,17.9422,0.751211,,,,7.85398e-5
1:0.5 (rep 3),2-Recover,111.437,2.921,0.607,0.066,,0.172052,840.338,,17.2052,0.840338,,,,7.85398e-5
1:0.5 (rep 3),2-Recover,111.803,2.947,0.581,0.052,,0.164683,662.085,,16.4683,0.662085,,,,7.85398e-5
1:0.5 (rep 3),2-Recover,112.17,2.973,0.555,0.052,,0.157313,662.085,,15.7313,0.662085,,,,7.85398e-5
1:0.5 (rep 3),2-Recover,112.537,2.999,0.529,0.032,,0.149943,407.437,,14.9943,0.407437,,,,7.85398e-5
1:0.5 (rep 3),2-Recover,112.903,3.025,0.503,0.025,,0.142574,318.31,,14.2574,0.31831,,,,7.85398e-5
1:0.5 (rep 3),2-Recover,113.27,3.051,0.477,0.038,,0.135204,483.831,,13.5204,0.483831,,,,7.85398e-5
1:0.5 (rep 3),2-Recover,113.637,3.077,0.451,0.045,,0.127834,572.958,,12.7834,0.572958,,,,7.85398e-5
1:0.5 (rep 3),2-Recover,114.003,3.103,0.425,0.032,,0.120465,407.437,,12.0465,0.407437,,,,7.85398e-5
1:0.5 (rep 3),2-Recover,114.37,3.129,0.399,0.018,,0.113095,229.183,,11.3095,0.229183,,,,7.85398e-5
1:0.5 (rep 3),2-Recover,114.737,3.155,0.373,0.018,,0.105726,229.183,,10.5726,0.229183,,,,7.85398e-5
1:0.5 (rep 3),2-Recover,115.103,3.18,0.348,0.018,,0.0986395,229.183,,9.86395,0.229183,,,,7.85398e-5
1:0.5 (rep 3),2-Recover,115.47,3.207,0.321,0.018,,0.0909864,229.183,,9.09864,0.229183,,,,7.85398e-5
1:0.5 (rep 3),2-Recover,115.837,3.233,0.295,0.025,,0.0836168,318.31,,8.36168,0.31831,,,,7.85398e-5
1:0.5 (rep 3),2-Recover,116.203,3.258,0.27,0.025,,0.0765306,318.31,,7.65306,0.31831,,,,7.85398e-5
1:0.5 (rep 3),2-Recover,116.57,3.284,0.244,0.018,,0.069161,229.183,,6.9161,0.229183,,,,7.85398e-5
1:0.5 (rep 3),2-Recover,116.937,3.31,0.218,0.018,,0.0617914,229.183,,6.17914,0.229183,,,,7.85398e-5
1:0.5 (rep 3),2-Recover,117.303,3.336,0.192,0.011,,0.0544218,140.056,,5.44218,0.140056,,,,7.85398e-5
1:0.5 (rep 3),2-Recover,117.67,3.362,0.166,0.018,,0.0470522,229.183,,4.70522,0.229183,,,,7.85398e-5
1:0.5 (rep 3),2-Recover,118.037,3.388,0.14,0.025,,0.0396825,318.31,,3.96825,0.31831,,,,7.85398e-5
1:0.5 (rep 3),2-Recover,118.403,3.414,0.114,0.018,,0.0323129,229.183,,3.23129,0.229183,,,,7.85398e-5
1:0.5 (rep 3),2-Recover,118.77,3.44,0.088,0.018,,0.0249433,229.183,,2.49433,0.229183,,,,7.85398e-5
1:0.5 (rep 3),2-Recover,119.137,3.466,0.062,0.011,,0.0175737,140.056,,1.75737,0.140056,,,,7.85398e-5
1:0.5 (rep 3),2-Recover,119.503,3.491,0.037,0.011,,0.0104875,140.056,,1.04875,0.140056,,,,7.85398e-5
1:0.5 (rep 3),2-Recover,119.87,3.517,0.011,0.018,,0.00311791,229.183,,0.311791,0.229183,,,,7.85398e-5
1:0.5 (rep 3),3-Compress,120.223,3.518,0.01,0.018,,0.00283447,229.183,,0.283447,0.229183,,,,7.85398e-5
1:0.5 (rep 3),3-Compress,120.59,3.492,0.036,0.018,,0.0102041,229.183,,1.02041,0.229183,,,,7.85398e-5
1:0.5 (rep 3),3-Compress,120.957,3.466,0.062,0.025,,0.0175737,318.31,,1.75737,0.31831,,,,7.85398e-5
1:0.5 (rep 3),3-Compress,121.323,3.441,0.087,0.018,,0.0246599,229.183,,2.46599,0.229183,,,,7.85398e-5
1:0.5 (rep 3),3-Compress,121.69,3.415,0.113,0.018,,0.0320295,229.183,,3.20295,0.229183,,,,7.85398e-5
1:0.5 (rep 3),3-Compress,122.057,3.388,0.14,0.025,,0.0396825,318.31,,3.96825,0.31831,,,,7.85398e-5
1:0.5 (rep 3),3-Compress,122.423,3.363,0.165,0.011,,0.0467687,140.056,,4.67687,0.140056,,,,7.85398e-5
1:0.5 (rep 3),3-Compress,122.79,3.337,0.191,0.018,,0.0541383,229.183,,5.41383,0.229183,,,,7.85398e-5
1:0.5 (rep 3),3-Compress,123.157,3.311,0.217,0.025,,0.0615079,318.31,,6.15079,0.31831,,,,7.85398e-5
1:0.5 (rep 3),3-Compress,123.523,3.285,0.243,0.038,,0.0688776,483.831,,6.88776,0.483831,,,,7.85398e-5
1:0.5 (rep 3),3-Compress,123.89,3.259,0.269,0.038,,0.0762472,483.831,,7.62472,0.483831,,,,7.85398e-5
1:0.5 (rep 3),3-Compress,124.257,3.233,0.295,0.038,,0.0836168,483.831,,8.36168,0.483831,,,,7.85398e-5
1:0.5 (rep 3),3-Compress,124.623,3.207,0.321,0.025,,0.0909864,318.31,,9.09864,0.31831,,,,7.85398e-5
1:0.5 (rep 3),3-Compress,124.99,3.181,0.347,0.045,,0.098356,572.958,,9.8356,0.572958,,,,7.85398e-5
1:0.5 (rep 3),3-Compress,125.357,3.155,0.373,0.038,,0.105726,483.831,,10.5726,0.483831,,,,7.85398e-5
1:0.5 (rep 3),3-Compress,125.723,3.129,0.399,0.045,,0.113095,572.958,,11.3095,0.572958,,,,7.85398e-5
1:0.5 (rep 3),3-Compress,126.09,3.103,0.425,0.066,,0.120465,840.338,,12.0465,0.840338,,,,7.85398e-5
1:0.5 (rep 3),3-Compress,126.457,3.077,0.451,0.052,,0.127834,662.085,,12.7834,0.662085,,,,7.85398e-5
1:0.5 (rep 3),3-Compress,126.823,3.052,0.476,0.066,,0.134921,840.338,,13.4921,0.840338,,,,7.85398e-5
1:0.5 (rep 3),3-Compress,127.19,3.026,0.502,0.066,,0.14229,840.338,,14.229,0.840338,,,,7.85398e-5
1:0.5 (rep 3),3-Compress,127.557,2.999,0.529,0.066,,0.149943,840.338,,14.9943,0.840338,,,,7.85398e-5
1:0.5 (rep 3),3-Compress,127.923,2.974,0.554,0.066,,0.157029,840.338,,15.7029,0.840338,,,,7.85398e-5
1:0.5 (rep 3),3-Compress,128.29,2.948,0.58,0.059,,0.164399,751.211,,16.4399,0.751211,,,,7.85398e-5
1:0.5 (rep 3),3-Compress,128.657,2.922,0.606,0.066,,0.171769,840.338,,17.1769,0.840338,,,,7.85398e-5
1:0.5 (rep 3),3-Compress,129.023,2.896,0.632,0.066,,0.179138,840.338,,17.9138,0.840338,,,,7.85398e-5
1:0.5 (rep 3),3-Compress,129.39,2.87,0.658,0.066,,0.186508,840.338,,18.6508,0.840338,,,,7.85398e-5
1:0.5 (rep 3),3-Compress,129.757,2.844,0.684,0.066,,0.193878,840.338,,19.3878,0.840338,,,,7.85398e-5
1:0.5 (rep 3),3-Compress,130.123,2.819,0.709,0.066,,0.200964,840.338,,20.0964,0.840338,,,,7.85398e-5
1:0.5 (rep 3),3-Compress,130.49,2.792,0.736,0.066,,0.208617,840.338,,20.8617,0.840338,,,,7.85398e-5
1:0.5 (rep 3),3-Compress,130.857,2.766,0.762,0.072,,0.215986,916.733,,21.5986,0.916733,,,,7.85398e-5
1:0.5 (rep 3),3-Compress,131.223,2.741,0.787,0.072,,0.223073,916.733,,22.3073,0.916733,,,,7.85398e-5
1:0.5 (rep 3),3-Compress,131.59,2.715,0.813,0.066,,0.230442,840.338,,23.0442,0.840338,,,,7.85398e-5
1:0.5 (rep 3),3-Compress,131.957,2.689,0.839,0.079,,0.237812,1005.86,,23.7812,1.00586,,,,7.85398e-5
1:0.5 (rep 3),3-Compress,132.323,2.663,0.865,0.072,,0.245181,916.733,,24.5181,0.916733,,,,7.85398e-5
1:0.5 (rep 3),3-Compress,132.69,2.637,0.891,0.072,,0.252551,916.733,,25.2551,0.916733,,,,7.85398e-5
1:0.5 (rep 3),3-Compress,133.057,2.611,0.917,0.072,,0.259921,916.733,,25.9921,0.916733,,,,7.85398e-5
1:0.5 (rep 3),3-Compress,133.423,2.585,0.943,0.079,,0.26729,1005.86,,26.729,1.00586,,,,7.85398e-5
1:0.5 (rep 3),3-Compress,133.79,2.559,0.969,0.093,,0.27466,1184.11,,27.466,1.18411,,,,7.85398e-5
1:0.5 (rep 3),3-Compress,134.157,2.533,0.995,0.093,,0.282029,1184.11,,28.2029,1.18411,,,,7.85398e-5
1:0.5 (rep 3),3-Compress,134.523,2.508,1.02,0.106,,0.289116,1349.63,,28.9116,1.34963,,,,7.85398e-5
1:0.5 (rep 3),3-Compress,134.89,2.481,1.047,0.079,,0.296769,1005.86,,29.6769,1.00586,,,,7.85398e-5
1:0.5 (rep 3),3-Compress,135.257,2.455,1.073,0.106,,0.304138,1349.63,,30.4138,1.34963,,,,7.85398e-5
1:0.5 (rep 3),3-Compress,135.623,2.43,1.098,0.113,,0.311224,1438.76,,31.1224,1.43876,,,,7.85398e-5
1:0.5 (rep 3),3-Compress,135.99,2.404,1.124,0.12,,0.318594,1527.89,,31.8594,1.52789,,,,7.85398e-5
1:0.5 (rep 3),3-Compress,136.357,2.378,1.15,0.12,,0.325964,1527.89,,32.5964,1.52789,,,,7.85398e-5
1:0.5 (rep 3),3-Compress,136.723,2.352,1.176,0.12,,0.333333,1527.89,,33.3333,1.52789,,,,7.85398e-5
1:0.5 (rep 3),3-Compress,137.09,2.326,1.202,0.12,,0.340703,1527.89,,34.0703,1.52789,,,,7.85398e-5
1:0.5 (rep 3),3-Compress,137.457,2.3,1.228,0.12,,0.348073,1527.89,,34.8073,1.52789,,,,7.85398e-5
1:0.5 (rep 3),3-Compress,137.823,2.274,1.254,0.12,,0.355442,1527.89,,35.5442,1.52789,,,,7.85398e-5
1:0.5 (rep 3),3-Compress,138.19,2.248,1.28,0.12,,0.362812,1527.89,,36.2812,1.52789,,,,7.85398e-5
1:0.5 (rep 3),3-Compress,138.557,2.222,1.306,0.12,,0.370181,1527.89,,37.0181,1.52789,,,,7.85398e-5
1:0.5 (rep 3),3-Compress,138.923,2.197,1.331,0.14,,0.377268,1782.54,,37.7268,1.78254,,,,7.85398e-5
1:0.5 (rep 3),3-Compress,139.29,2.17,1.358,0.133,,0.384921,1693.41,,38.4921,1.69341,,,,7.85398e-5
1:0.5 (rep 3),3-Compress,139.657,2.144,1.384,0.14,,0.39229,1782.54,,39.229,1.78254,,,,7.85398e-5
1:0.5 (rep 3),3-Compress,140.023,2.119,1.409,0.133,,0.399376,1693.41,,39.9376,1.69341,,,,7.85398e-5
1:0.5 (rep 3),3-Compress,140.39,2.093,1.435,0.161,,0.406746,2049.92,,40.6746,2.04992,,,,7.85398e-5
1:0.5 (rep 3),3-Compress,140.757,2.066,1.462,0.161,,0.414399,2049.92,,41.4399,2.04992,,,,7.85398e-5
1:0.5 (rep 3),3-Compress,141.123,2.041,1.487,0.174,,0.421485,2215.44,,42.1485,2.21544,,,,7.85398e-5
1:0.5 (rep 3),3-Compress,141.49,2.015,1.513,0.174,,0.428855,2215.44,,42.8855,2.21544,,,,7.85398e-5
1:0.5 (rep 3),3-Compress,141.857,1.989,1.539,0.174,,0.436224,2215.44,,43.6224,2.21544,,,,7.85398e-5
1:0.5 (rep 3),3-Compress,142.223,1.964,1.564,0.174,,0.443311,2215.44,,44.3311,2.21544,,,,7.85398e-5
1:0.5 (rep 3),3-Compress,142.59,1.937,1.591,0.174,,0.450964,2215.44,,45.0964,2.21544,,,,7.85398e-5
1:0.5 (rep 3),3-Compress,142.957,1.911,1.617,0.181,,0.458333,2304.56,,45.8333,2.30456,,,,7.85398e-5
1:0.5 (rep 3),3-Compress,143.323,1.886,1.642,0.174,,0.46542,2215.44,,46.542,2.21544,,,,7.85398e-5
1:0.5 (rep 3),3-Compress,143.69,1.86,1.668,0.181,,0.472789,2304.56,,47.2789,2.30456,,,,7.85398e-5
1:0.5 (rep 3),3-Compress,144.057,1.833,1.695,0.195,,0.480442,2482.82,,48.0442,2.48282,,,,7.85398e-5
1:0.5 (rep 3),3-Compress,144.423,1.808,1.72,0.208,,0.487528,2648.34,,48.7528,2.64834,,,,7.85398e-5
1:0.5 (rep 3),3-Compress,144.79,1.782,1.746,0.222,,0.494898,2826.59,,49.4898,2.82659,,,,7.85398e-5
1:0.5 (rep 3),3-Compress,145.157,1.756,1.772,0.229,,0.502268,2915.72,,50.2268,2.91572,,,,7.85398e-5
1:0.5 (rep 3),3-Compress,145.523,1.73,1.798,0.229,,0.509637,2915.72,,50.9637,2.91572,,,,7.85398e-5
1:0.5 (rep 3),3-Compress,145.89,1.704,1.824,0.215,,0.517007,2737.47,,51.7007,2.73747,,,,7.85398e-5
1:0.5 (rep 3),3-Compress,146.257,1.678,1.85,0.215,,0.524376,2737.47,,52.4376,2.73747,,,,7.85398e-5
1:0.5 (rep 3),3-Compress,146.623,1.652,1.876,0.222,,0.531746,2826.59,,53.1746,2.82659,,,,7.85398e-5
1:0.5 (rep 3),3-Compress,146.99,1.626,1.902,0.242,,0.539116,3081.24,,53.9116,3.08124,,,,7.85398e-5
1:0.5 (rep 3),3-Compress,147.357,1.6,1.928,0.249,,0.546485,3170.37,,54.6485,3.17037,,,,7.85398e-5
1:0.5 (rep 3),3-Compress,147.723,1.575,1.953,0.256,,0.553571,3259.49,,55.3571,3.25949,,,,7.85398e-5
1:0.5 (rep 3),3-Compress,148.09,1.549,1.979,0.242,,0.560941,3081.24,,56.0941,3.08124,,,,7.85398e-5
1:0.5 (rep 3),3-Compress,148.457,1.522,2.006,0.242,,0.568594,3081.24,,56.8594,3.08124,,,,7.85398e-5
1:0.5 (rep 3),3-Compress,148.823,1.497,2.031,0.235,,0.57568,2992.11,,57.568,2.99211,,,,7.85398e-5
1:0.5 (rep 3),3-Compress,149.19,1.471,2.057,0.249,,0.58305,3170.37,,58.305,3.17037,,,,7.85398e-5
1:0.5 (rep 3),3-Compress,149.557,1.445,2.083,0.256,,0.59042,3259.49,,59.042,3.25949,,,,7.85398e-5
1:0.5 (rep 3),3-Compress,149.923,1.419,2.109,0.276,,0.597789,3514.14,,59.7789,3.51414,,,,7.85398e-5
1:0.5 (rep 3),3-Recover,150.267,1.423,2.105,0.283,,0.596655,3603.27,,59.6655,3.60327,,,,7.85398e-5
1:0.5 (rep 3),3-Recover,150.633,1.448,2.08,0.242,,0.589569,3081.24,,58.9569,3.08124,,,,7.85398e-5
1:0.5 (rep 3),3-Recover,151,1.474,2.054,0.242,,0.5822,3081.24,,58.22,3.08124,,,,7.85398e-5
1:0.5 (rep 3),3-Recover,151.367,1.501,2.027,0.249,,0.574546,3170.37,,57.4546,3.17037,,,,7.85398e-5
1:0.5 (rep 3),3-Recover,151.733,1.526,2.002,0.235,,0.56746,2992.11,,56.746,2.99211,,,,7.85398e-5
1:0.5 (rep 3),3-Recover,152.1,1.552,1.976,0.256,,0.560091,3259.49,,56.0091,3.25949,,,,7.85398e-5
1:0.5 (rep 3),3-Recover,152.467,1.578,1.95,0.249,,0.552721,3170.37,,55.2721,3.17037,,,,7.85398e-5
1:0.5 (rep 3),3-Recover,152.833,1.603,1.925,0.229,,0.545635,2915.72,,54.5635,2.91572,,,,7.85398e-5
1:0.5 (rep 3),3-Recover,153.2,1.63,1.898,0.229,,0.537982,2915.72,,53.7982,2.91572,,,,7.85398e-5
1:0.5 (rep 3),3-Recover,153.567,1.656,1.872,0.222,,0.530612,2826.59,,53.0612,2.82659,,,,7.85398e-5
1:0.5 (rep 3),3-Recover,153.933,1.681,1.847,0.215,,0.523526,2737.47,,52.3526,2.73747,,,,7.85398e-5
1:0.5 (rep 3),3-Recover,154.3,1.707,1.821,0.201,,0.516156,2559.21,,51.6156,2.55921,,,,7.85398e-5
1:0.5 (rep 3),3-Recover,154.667,1.734,1.794,0.208,,0.508503,2648.34,,50.8503,2.64834,,,,7.85398e-5
1:0.5 (rep 3),3-Recover,155.033,1.759,1.769,0.201,,0.501417,2559.21,,50.1417,2.55921,,,,7.85398e-5
1:0.5 (rep 3),3-Recover,155.4,1.785,1.743,0.181,,0.494048,2304.56,,49.4048,2.30456,,,,7.85398e-5
1:0.5 (rep 3),3-Recover,155.767,1.811,1.717,0.174,,0.486678,2215.44,,48.6678,2.21544,,,,7.85398e-5
1:0.5 (rep 3),3-Recover,156.133,1.837,1.691,0.174,,0.479308,2215.44,,47.9308,2.21544,,,,7.85398e-5
1:0.5 (rep 3),3-Recover,156.5,1.863,1.665,0.174,,0.471939,2215.44,,47.1939,2.21544,,,,7.85398e-5
1:0.5 (rep 3),3-Recover,156.867,1.889,1.639,0.174,,0.464569,2215.44,,46.4569,2.21544,,,,7.85398e-5
1:0.5 (rep 3),3-Recover,157.233,1.915,1.613,0.174,,0.4572,2215.44,,45.72,2.21544,,,,7.85398e-5
1:0.5 (rep 3),3-Recover,157.6,1.941,1.587,0.174,,0.44983,2215.44,,44.983,2.21544,,,,7.85398e-5
1:0.5 (rep 3),3-Recover,157.967,1.967,1.561,0.154,,0.44246,1960.79,,44.246,1.96079,,,,7.85398e-5
1:0.5 (rep 3),3-Recover,158.333,1.992,1.536,0.147,,0.435374,1871.66,,43.5374,1.87166,,,,7.85398e-5
1:0.5 (rep 3),3-Recover,158.7,2.019,1.509,0.147,,0.427721,1871.66,,42.7721,1.87166,,,,7.85398e-5
1:0.5 (rep 3),3-Recover,159.067,2.045,1.483,0.147,,0.420351,1871.66,,42.0351,1.87166,,,,7.85398e-5
1:0.5 (rep 3),3-Recover,159.433,2.07,1.458,0.147,,0.413265,1871.66,,41.3265,1.87166,,,,7.85398e-5
1:0.5 (rep 3),3-Recover,159.8,2.096,1.432,0.127,,0.405896,1617.01,,40.5896,1.61701,,,,7.85398e-5
1:0.5 (rep 3),3-Recover,160.167,2.122,1.406,0.127,,0.398526,1617.01,,39.8526,1.61701,,,,7.85398e-5
1:0.5 (rep 3),3-Recover,160.533,2.148,1.38,0.127,,0.391156,1617.01,,39.1156,1.61701,,,,7.85398e-5
1:0.5 (rep 3),3-Recover,160.9,2.174,1.354,0.12,,0.383787,1527.89,,38.3787,1.52789,,,,7.85398e-5
1:0.5 (rep 3),3-Recover,161.267,2.2,1.328,0.12,,0.376417,1527.89,,37.6417,1.52789,,,,7.85398e-5
1:0.5 (rep 3),3-Recover,161.633,2.226,1.302,0.12,,0.369048,1527.89,,36.9048,1.52789,,,,7.85398e-5
1:0.5 (rep 3),3-Recover,162,2.252,1.276,0.12,,0.361678,1527.89,,36.1678,1.52789,,,,7.85398e-5
1:0.5 (rep 3),3-Recover,162.367,2.278,1.25,0.12,,0.354308,1527.89,,35.4308,1.52789,,,,7.85398e-5
1:0.5 (rep 3),3-Recover,162.733,2.303,1.225,0.12,,0.347222,1527.89,,34.7222,1.52789,,,,7.85398e-5
1:0.5 (rep 3),3-Recover,163.1,2.329,1.199,0.106,,0.339853,1349.63,,33.9853,1.34963,,,,7.85398e-5
1:0.5 (rep 3),3-Recover,163.467,2.356,1.172,0.106,,0.3322,1349.63,,33.22,1.34963,,,,7.85398e-5
1:0.5 (rep 3),3-Recover,163.833,2.381,1.147,0.099,,0.325113,1260.51,,32.5113,1.26051,,,,7.85398e-5
1:0.5 (rep 3),3-Recover,164.2,2.407,1.121,0.106,,0.317744,1349.63,,31.7744,1.34963,,,,7.85398e-5
1:0.5 (rep 3),3-Recover,164.567,2.433,1.095,0.086,,0.310374,1094.99,,31.0374,1.09499,,,,7.85398e-5
1:0.5 (rep 3),3-Recover,164.933,2.459,1.069,0.086,,0.303005,1094.99,,30.3005,1.09499,,,,7.85398e-5
1:0.5 (rep 3),3-Recover,165.3,2.485,1.043,0.072,,0.295635,916.733,,29.5635,0.916733,,,,7.85398e-5
1:0.5 (rep 3),3-Recover,165.667,2.511,1.017,0.066,,0.288265,840.338,,28.8265,0.840338,,,,7.85398e-5
1:0.5 (rep 3),3-Recover,166.033,2.537,0.991,0.066,,0.280896,840.338,,28.0896,0.840338,,,,7.85398e-5
1:0.5 (rep 3),3-Recover,166.4,2.563,0.965,0.066,,0.273526,840.338,,27.3526,0.840338,,,,7.85398e-5
1:0.5 (rep 3),3-Recover,166.767,2.589,0.939,0.066,,0.266156,840.338,,26.6156,0.840338,,,,7.85398e-5
1:0.5 (rep 3),3-Recover,167.133,2.614,0.914,0.066,,0.25907,840.338,,25.907,0.840338,,,,7.85398e-5
1:0.5 (rep 3),3-Recover,167.5,2.64,0.888,0.066,,0.251701,840.338,,25.1701,0.840338,,,,7.85398e-5
1:0.5 (rep 3),3-Recover,167.867,2.667,0.861,0.066,,0.244048,840.338,,24.4048,0.840338,,,,7.85398e-5
1:0.5 (rep 3),3-Recover,168.233,2.692,0.836,0.066,,0.236961,840.338,,23.6961,0.840338,,,,7.85398e-5
1:0.5 (rep 3),3-Recover,168.6,2.718,0.81,0.066,,0.229592,840.338,,22.9592,0.840338,,,,7.85398e-5
1:0.5 (rep 3),3-Recover,168.967,2.744,0.784,0.066,,0.222222,840.338,,22.2222,0.840338,,,,7.85398e-5
1:0.5 (rep 3),3-Recover,169.333,2.77,0.758,0.066,,0.214853,840.338,,21.4853,0.840338,,,,7.85398e-5
1:0.5 (rep 3),3-Recover,169.7,2.796,0.732,0.066,,0.207483,840.338,,20.7483,0.840338,,,,7.85398e-5
1:0.5 (rep 3),3-Recover,170.067,2.822,0.706,0.066,,0.200113,840.338,,20.0113,0.840338,,,,7.85398e-5
1:0.5 (rep 3),3-Recover,170.433,2.848,0.68,0.059,,0.192744,751.211,,19.2744,0.751211,,,,7.85398e-5
1:0.5 (rep 3),3-Recover,170.8,2.874,0.654,0.066,,0.185374,840.338,,18.5374,0.840338,,,,7.85398e-5
1:0.5 (rep 3),3-Recover,171.167,2.9,0.628,0.066,,0.178005,840.338,,17.8005,0.840338,,,,7.85398e-5
1:0.5 (rep 3),3-Recover,171.533,2.925,0.603,0.059,,0.170918,751.211,,17.0918,0.751211,,,,7.85398e-5
1:0.5 (rep 3),3-Recover,171.9,2.952,0.576,0.066,,0.163265,840.338,,16.3265,0.840338,,,,7.85398e-5
1:0.5 (rep 3),3-Recover,172.267,2.978,0.55,0.038,,0.155896,483.831,,15.5896,0.483831,,,,7.85398e-5
1:0.5 (rep 3),3-Recover,172.633,3.003,0.525,0.038,,0.14881,483.831,,14.881,0.483831,,,,7.85398e-5
1:0.5 (rep 3),3-Recover,173,3.029,0.499,0.038,,0.14144,483.831,,14.144,0.483831,,,,7.85398e-5
1:0.5 (rep 3),3-Recover,173.367,3.055,0.473,0.032,,0.13407,407.437,,13.407,0.407437,,,,7.85398e-5
1:0.5 (rep 3),3-Recover,173.733,3.081,0.447,0.032,,0.126701,407.437,,12.6701,0.407437,,,,7.85398e-5
1:0.5 (rep 3),3-Recover,174.1,3.107,0.421,0.032,,0.119331,407.437,,11.9331,0.407437,,,,7.85398e-5
1:0.5 (rep 3),3-Recover,174.467,3.133,0.395,0.032,,0.111961,407.437,,11.1961,0.407437,,,,7.85398e-5
1:0.5 (rep 3),3-Recover,174.833,3.158,0.37,0.032,,0.104875,407.437,,10.4875,0.407437,,,,7.85398e-5
1:0.5 (rep 3),3-Recover,175.2,3.185,0.343,0.018,,0.0972222,229.183,,9.72222,0.229183,,,,7.85398e-5
1:0.5 (rep 3),3-Recover,175.567,3.211,0.317,0.018,,0.0898526,229.183,,8.98526,0.229183,,,,7.85398e-5
1:0.5 (rep 3),3-Recover,175.933,3.236,0.292,0.018,,0.0827664,229.183,,8.27664,0.229183,,,,7.85398e-5
1:0.5 (rep 3),3-Recover,176.3,3.262,0.266,0.025,,0.0753968,318.31,,7.53968,0.31831,,,,7.85398e-5
1:0.5 (rep 3),3-Recover,176.667,3.288,0.24,0.032,,0.0680272,407.437,,6.80272,0.407437,,,,7.85398e-5
1:0.5 (rep 3),3-Recover,177.033,3.314,0.214,0.011,,0.0606576,140.056,,6.06576,0.140056,,,,7.85398e-5
1:0.5 (rep 3),3-Recover,177.4,3.34,0.188,0.018,,0.053288,229.183,,5.3288,0.229183,,,,7.85398e-5
1:0.5 (rep 3),3-Recover,177.767,3.366,0.162,0.018,,0.0459184,229.183,,4.59184,0.229183,,,,7.85398e-5
1:0.5 (rep 3),3-Recover,178.133,3.392,0.136,0.018,,0.0385488,229.183,,3.85488,0.229183,,,,7.85398e-5
1:0.5 (rep 3),3-Recover,178.5,3.418,0.11,0.018,,0.0311791,229.183,,3.11791,0.229183,,,,7.85398e-5
1:0.5 (rep 3),3-Recover,178.867,3.444,0.084,0.025,,0.0238095,318.31,,2.38095,0.31831,,,,7.85398e-5
1:0.5 (rep 3),3-Recover,179.233,3.469,0.059,0.018,,0.0167234,229.183,,1.67234,0.229183,,,,7.85398e-5
1:0.5 (rep 3),3-Recover,179.6,3.496,0.032,0.011,,0.00907029,140.056,,0.907029,0.140056,,,,7.85398e-5
1:0.5 (rep 3),3-Recover,179.967,3.522,0.006,0.011,,0.00170068,140.056,,0.170068,0.140056,,,,7.85398e-5
1:0.5 (rep 3),3-Recover,180.1,3.528,0,0.018,,0,229.183,,0,0.229183,,,,7.85398e-5