File: data/beta_1-0_3.csv
SetName,Cycle,Time_S,Size_mm,Displacement_mm,Force_N,,Strain,Stress(Pascal),,%Strain,Stress(kPa),,,,Area(m^2)
1:0 (rep 3),1-Compress,0,2.789,0,0.011,,0,140.056,,0,0.140056,,,,7.85398e-5
1:0 (rep 3),1-Compress,0.367,2.768,0.021,0.025,,0.00752958,318.31,,0.752958,0.31831,,,,7.85398e-5
1:0 (rep 3),1-Compress,0.733,2.749,0.04,0.011,,0.0143421,140.056,,1.43421,0.140056,,,,7.85398e-5
1:0 (rep 3),1-Compress,1.1,2.728,0.061,0.018,,0.0218716,229.183,,2.18716,0.229183,,,,7.85398e-5
1:0 (rep 3),1-Compress,1.467,2.707,0.082,0.018,,0.0294012,229.183,,2.94012,0.229183,,,,7.85398e-5
1:0 (rep 3),1-Compress,1.833,2.687,0.102,0.018,,0.0365722,229.183,,3.65722,0.229183,,,,7.85398e-5
1:0 (rep 3),1-Compress,2.2,2.667,0.122,0.032,,0.0437433,407.437,,4.37433,0.407437,,,,7.85398e-5
1:0 (rep 3),1-Compress,2.567,2.646,0.143,0.032,,0.0512729,407.437,,5.12729,0.407437,,,,7.85398e-5
1:0 (rep 3),1-Compress,2.933,2.626,0.163,0.032,,0.0584439,407.437,,5.84439,0.407437,,,,7.85398e-5
1:0 (rep 3),1-Compress,3.3,2.605,0.184,0.025,,0.0659735,318.31,,6.59735,0.31831,,,,7.85398e-5
1:0 (rep 3),1-Compress,3.667,2.584,0.205,0.018,,0.073503,229.183,,7.3503,0.229183,,,,7.85398e-5
1:0 (rep 3),1-Compress,4.033,2.564,0.225,0.018,,0.0806741,229.183,,8.06741,0.229183,,,,7.85398e-5
1:0 (rep 3),1-Compress,4.4,2.544,0.245,0.032,,0.0878451,407.437,,8.78451,0.407437,,,,7.85398e-5
1:0 (rep 3),1-Compress,4.767,2.523,0.266,0.038,,0.0953747,483.831,,9.53747,0.483831,,,,7.85398e-5
1:0 (rep 3),1-Compress,5.133,2.503,0.286,0.066,,0.102546,840.338,,10.2546,0.840338,,,,7.85398e-5
1:0 (rep 3),1-Compress,5.5,2.482,0.307,0.038,,0.110075,483.831,,11.0075,0.483831,,,,7.85398e-5
1:0 (rep 3),1-Compress,5.867,2.461,0.328,0.038,,0.117605,483.831,,11.7605,0.483831,,,,7.85398e-5
1:0 (rep 3),1-Compress,6.233,2.442,0.347,0.038,,0.124417,483.831,,12.4417,0.483831,,,,7.85398e-5
1:0 (rep 3),1-Compress,6.6,2.421,0.368,0.025,,0.131947,318.31,,13.1947,0.31831,,,,7.85398e-5
1:0 (rep 3),1-Compress,6.967,2.4,0.389,0.038,,0.139477,483.831,,13.9477,0.483831,,,,7.85398e-5
1:0 (rep 3),1-Compress,7.333,2.38,0.409,0.066,,0.146648,840.338,,14.6648,0.840338,,,,7.85398e-5
1:0 (rep 3),1-Compress,7.7,2.359,0.43,0.066,,0.154177,840.338,,15.4177,0.840338,,,,7.85398e-5
1:0 (rep 3),1-Compress,8.067,2.339,0.45,0.066,,0.161348,840.338,,16.1348,0.840338,,,,7.85398e-5
1:0 (rep 3),1-Compress,8.433,2.319,0.47,0.066,,0.168519,840.338,,16.8519,0.840338,,,,7.85398e-5
1:0 (rep 3),1-Compress,8.8,2.298,0.491,0.066,,0.176049,840.338,,17.6049,0.840338,,,,7.85398e-5
1:0 (rep 3),1-Compress,9.167,2.277,0.512,0.066,,0.183578,840.338,,18.3578,0.840338,,,,7.85398e-5
1:0 (rep 3),1-Compress,9.533,2.257,0.532,0.072,,0.190749,916.733,,19.0749,0.916733,,,,7.85398e-5
1:0 (rep 3),1-Compress,9.9,2.236,0.553,0.059,,0.198279,751.211,,19.8279,0.751211,,,,7.85398e-5
1:0 (rep 3),1-Compress,10.267,2.216,0.573,0.066,,0.20545,840.338,,20.545,0.840338,,,,7.85398e-5
1:0 (rep 3),1-Compress,10.633,2.195,0.594,0.066,,0.21298,840.338,,21.298,0.840338,,,,7.85398e-5
1:0 (rep 3),1-Compress,11,2.175,0.614,0.066,,0.220151,840.338,,22.0151,0.840338,,,,7.85398e-5
1:0 (rep 3),1-Compress,11.367,2.155,0.634,0.066,,0.227322,840.338,,22.7322,0.840338,,,,7.85398e-5
1:0 (rep 3),1-Compress,11.733,2.134,0.655,0.066,,0.234851,840.338,,23.4851,0.840338,,,,7.85398e-5
1:0 (rep 3),1-Compress,12.1,2.114,0.675,0.066,,0.242022,840.338,,24.2022,0.840338,,,,7.85398e-5
1:0 (rep 3),1-Compress,12.467,2.093,0.696,0.066,,0.249552,840.338,,24.9552,0.840338,,,,7.85398e-5
1:0 (rep 3),1-Compress,12.833,2.073,0.716,0.072,,0.256723,916.733,,25.6723,0.916733,,,,7.85398e-5
1:0 (rep 3),1-Compress,13.2,2.052,0.737,0.072,,0.264252,916.733,,26.4252,0.916733,,,,7.85398e-5
1:0 (rep 3),1-Compress,13.567,2.032,0.757,0.072,,0.271423,916.733,,27.1423,0.916733,,,,7.85398e-5
1:0 (rep 3),1-Compress,13.933,2.011,0.778,0.072,,0.278953,916.733,,27.8953,0.916733,,,,7.85398e-5
1:0 (rep 3),1-Compress,14.3,1.991,0.798,0.066,,0.286124,840.338,,28.6124,0.840338,,,,7.85398e-5
1:0 (rep 3),1-Compress,14.667,1.97,0.819,0.079,,0.293654,1005.86,,29.3654,1.00586,,,,7.85398e-5
1:0 (rep 3),1-Compress,15.033,1.95,0.839,0.086,,0.300825,1094.99,,30.0825,1.09499,,,,7.85398e-5
1:0 (rep 3),1-Compress,15.4,1.93,0.859,0.106,,0.307996,1349.63,,30.7996,1.34963,,,,7.85398e-5
1:0 (rep 3),1-Compress,15.767,1.909,0.88,0.099,,0.315525,1260.51,,31.5525,1.26051,,,,7.85398e-5
1:0 (rep 3),1-Compress,16.133,1.889,0.9,0.093,,0.322696,1184.11,,32.2696,1.18411,,,,7.85398e-5
1:0 (rep 3),1-Compress,16.5,1.868,0.921,0.099,,0.330226,1260.51,,33.0226,1.26051,,,,7.85398e-5
1:0 (rep 3),1-Compress,16.867,1.847,0.942,0.113,,0.337755,1438.76,,33.7755,1.43876,,,,7.85398e-5
1:0 (rep 3),1-Compress,17.233,1.827,0.962,0.106,,0.344926,1349.63,,34.4926,1.34963,,,,7.85398e-5
1:0 (rep 3),1-Compress,17.6,1.807,0.982,0.12,,0.352098,1527.89,,35.2098,1.52789,,,,7.85398e-5
1:0 (rep 3),1-Compress,17.967,1.786,1.003,0.12,,0.359627,1527.89,,35.9627,1.52789,,,,7.85398e-5
1:0 (rep 3),1-Compress,18.333,1.766,1.023,0.12,,0.366798,1527.89,,36.6798,1.52789,,,,7.85398e-5
1:0 (rep 3),1-Compress,18.7,1.745,1.044,0.12,,0.374328,1527.89,,37.4328,1.52789,,,,7.85398e-5
1:0 (rep 3),1-Compress,19.067,1.724,1.065,0.12,,0.381857,1527.89,,38.1857,1.52789,,,,7.85398e-5
1:0 (rep 3),1-Compress,19.433,1.704,1.085,0.12,,0.389028,1527.89,,38.9028,1.52789,,,,7.85398e-5
1:0 (rep 3),1-Compress,19.8,1.684,1.105,0.12,,0.396199,1527.89,,39.6199,1.52789,,,,7.85398e-5
1:0 (rep 3),1-Compress,20.167,1.663,1.126,0.12,,0.403729,1527.89,,40.3729,1.52789,,,,7.85398e-5
1:0 (rep 3),1-Compress,20.533,1.643,1.146,0.127,,0.4109,1617.01,,41.09,1.61701,,,,7.85398e-5
1:0 (rep 3),1-Compress,20.9,1.622,1.167,0.12,,0.41843,1527.89,,41.843,1.52789,,,,7.85398e-5
1:0 (rep 3),1-Compress,21.267,1.601,1.188,0.127,,0.425959,1617.01,,42.5959,1.61701,,,,7.85398e-5
1:0 (rep 3),1-Compress,21.633,1.582,1.207,0.133,,0.432772,1693.41,,43.2772,1.69341,,,,7.85398e-5
1:0 (rep 3),1-Compress,22,1.561,1.228,0.14,,0.440301,1782.54,,44.0301,1.78254,,,,7.85398e-5
1:0 (rep 3),1-Compress,22.367,1.54,1.249,0.154,,0.447831,1960.79,,44.7831,1.96079,,,,7.85398e-5
1:0 (rep 3),1-Compress,22.733,1.52,1.269,0.154,,0.455002,1960.79,,45.5002,1.96079,,,,7.85398e-5
1:0 (rep 3),1-Compress,23.1,1.499,1.29,0.161,,0.462531,2049.92,,46.2531,2.04992,,,,7.85398e-5
1:0 (rep 3),1-Compress,23.467,1.479,1.31,0.174,,0.469702,2215.44,,46.9702,2.21544,,,,7.85398e-5
1:0 (rep 3),1-Compress,23.833,1.459,1.33,0.174,,0.476873,2215.44,,47.6873,2.21544,,,,7.85398e-5
1:0 (rep 3),1-Compress,24.2,1.438,1.351,0.174,,0.484403,2215.44,,48.4403,2.21544,,,,7.85398e-5
1:0 (rep 3),1-Compress,24.567,1.417,1.372,0.174,,0.491933,2215.44,,49.1933,2.21544,,,,7.85398e-5
1:0 (rep 3),1-Compress,24.933,1.397,1.392,0.174,,0.499104,2215.44,,49.9104,2.21544,,,,7.85398e-5
1:0 (rep 3),1-Compress,25.3,1.376,1.413,0.174,,0.506633,2215.44,,50.6633,2.21544,,,,7.85398e-5
1:0 (rep 3),1-Compress,25.667,1.356,1.433,0.174,,0.513804,2215.44,,51.3804,2.21544,,,,7.85398e-5
1:0 (rep 3),1-Compress,26.033,1.336,1.453,0.174,,0.520975,2215.44,,52.0975,2.21544,,,,7.85398e-5
1:0 (rep 3),1-Compress,26.4,1.315,1.474,0.174,,0.528505,2215.44,,52.8505,2.21544,,,,7.85398e-5
1:0 (rep 3),1-Compress,26.767,1.295,1.494,0.167,,0.535676,2126.31,,53.5676,2.12631,,,,7.85398e-5
1:0 (rep 3),1-Compress,27.133,1.274,1.515,0.181,,0.543205,2304.56,,54.3205,2.30456,,,,7.85398e-5
1:0 (rep 3),1-Compress,27.5,1.254,1.535,0.174,,0.550376,2215.44,,55.0376,2.21544,,,,7.85398e-5
1:0 (rep 3),1-Compress,27.867,1.233,1.556,0.188,,0.557906,2393.69,,55.7906,2.39369,,,,7.85398e-5
1:0 (rep 3),1-Compress,28.233,1.213,1.576,0.195,,0.565077,2482.82,,56.5077,2.48282,,,,7.85398e-5
1:0 (rep 3),1-Compress,28.6,1.192,1.597,0.215,,0.572607,2737.47,,57.2607,2.73747,,,,7.85398e-5
1:0 (rep 3),1-Compress,28.967,1.172,1.617,0.229,,0.579778,2915.72,,57.9778,2.91572,,,,7.85398e-5
1:0 (rep 3),1-Compress,29.333,1.151,1.638,0.229,,0.587307,2915.72,,58.7307,2.91572,,,,7.85398e-5
1:0 (rep 3),1-Compress,29.7,1.131,1.658,0.229,,0.594478,2915.72,,59.4478,2.91572,,,,7.85398e-5
1:0 (rep 3),1-Recover,30.067,1.119,1.67,0.208,,0.598781,2648.34,,59.8781,2.64834,,,,7.85398e-5
1:0 (rep 3),1-Recover,30.433,1.139,1.65,0.201,,0.59161,2559.21,,59.161,2.55921,,,,7.85398e-5
1:0 (rep 3),1-Recover,30.8,1.16,1.629,0.208,,0.58408,2648.34,,58.408,2.64834,,,,7.85398e-5
1:0 (rep 3),1-Recover,31.167,1.18,1.609,0.222,,0.576909,2826.59,,57.6909,2.82659,,,,7.85398e-5
1:0 (rep 3),1-Recover,31.533,1.201,1.588,0.174,,0.56938,2215.44,,56.938,2.21544,,,,7.85398e-5
1:0 (rep 3),1-Recover,31.9,1.221,1.568,0.181,,0.562209,2304.56,,56.2209,2.30456,,,,7.85398e-5
1:0 (rep 3),1-Recover,32.267,1.242,1.547,0.174,,0.554679,2215.44,,55.4679,2.21544,,,,7.85398e-5
1:0 (rep 3),1-Recover,32.633,1.262,1.527,0.161,,0.547508,2049.92,,54.7508,2.04992,,,,7.85398e-5
1:0 (rep 3),1-Recover,33,1.282,1.507,0.167,,0.540337,2126.31,,54.0337,2.12631,,,,7.85398e-5
1:0 (rep 3),1-Recover,33.367,1.304,1.485,0.174,,0.532449,2215.44,,53.2449,2.21544,,,,7.85398e-5
1:0 (rep 3),1-Recover,33.733,1.323,1.466,0.174,,0.525636,2215.44,,52.5636,2.21544,,,,7.85398e-5
1:0 (rep 3),1-Recover,34.1,1.344,1.445,0.174,,0.518107,2215.44,,51.8107,2.21544,,,,7.85398e-5
1:0 (rep 3),1-Recover,34.467,1.365,1.424,0.174,,0.510577,2215.44,,51.0577,2.21544,,,,7.85398e-5
1:0 (rep 3),1-Recover,34.833,1.385,1.404,0.167,,0.503406,2126.31,,50.3406,2.12631,,,,7.85398e-5
1:0 (rep 3),1-Recover,35.2,1.405,1.384,0.167,,0.496235,2126.31,,49.6235,2.12631,,,,7.85398e-5
1:0 (rep 3),1-Recover,35.567,1.426,1.363,0.167,,0.488706,2126.31,,48.8706,2.12631,,,,7.85398e-5
1:0 (rep 3),1-Recover,35.933,1.446,1.343,0.147,,0.481535,1871.66,,48.1535,1.87166,,,,7.85398e-5
1:0 (rep 3),1-Recover,36.3,1.467,1.322,0.133,,0.474005,1693.41,,47.4005,1.69341,,,,7.85398e-5
1:0 (rep 3),1-Recover,36.667,1.488,1.301,0.133,,0.466475,1693.41,,46.6475,1.69341,,,,7.85398e-5
1:0 (rep 3),1-Recover,37.033,1.507,1.282,0.12,,0.459663,1527.89,,45.9663,1.52789,,,,7.85398e-5
1:0 (rep 3),1-Recover,37.4,1.529,1.26,0.127,,0.451775,1617.01,,45.1775,1.61701,,,,7.85398e-5
1:0 (rep 3),1-Recover,37.767,1.549,1.24,0.12,,0.444604,1527.89,,44.4604,1.52789,,,,7.85398e-5
1:0 (rep 3),1-Recover,38.133,1.569,1.22,0.12,,0.437433,1527.89,,43.7433,1.52789,,,,7.85398e-5
1:0 (rep 3),1-Recover,38.5,1.59,1.199,0.12,,0.429903,1527.89,,42.9903,1.52789,,,,7.85398e-5
1:0 (rep 3),1-Recover,38.867,1.61,1.179,0.12,,0.422732,1527.89,,42.2732,1.52789,,,,7.85398e-5
1:0 (rep 3),1-Recover,39.233,1.63,1.159,0.12,,0.415561,1527.89,,41.5561,1.52789,,,,7.85398e-5
1:0 (rep 3),1-Recover,39.6,1.651,1.138,0.12,,0.408032,1527.89,,40.8032,1.52789,,,,7.85398e-5
1:0 (rep 3),1-Recover,39.967,1.672,1.117,0.12,,0.400502,1527.89,,40.0502,1.52789,,,,7.85398e-5
1:0 (rep 3),1-Recover,40.333,1.692,1.097,0.12,,0.393331,1527.89,,39.3331,1.52789,,,,7.85398e-5
1:0 (rep 3),1-Recover,40.7,1.713,1.076,0.12,,0.385801,1527.89,,38.5801,1.52789,,,,7.85398e-5
1:0 (rep 3),1-Recover,41.067,1.733,1.056,0.12,,0.37863,1527.89,,37.863,1.52789,,,,7.85398e-5
1:0 (rep 3),1-Recover,41.433,1.754,1.035,0.113,,0.371101,1438.76,,37.1101,1.43876,,,,7.85398e-5
1:0 (rep 3),1-Recover,41.8,1.774,1.015,0.079,,0.36393,1005.86,,36.393,1.00586,,,,7.85398e-5
1:0 (rep 3),1-Recover,42.167,1.795,0.994,0.086,,0.3564,1094.99,,35.64,1.09499,,,,7.85398e-5
1:0 (rep 3),1-Recover,42.533,1.815,0.974,0.099,,0.349229,1260.51,,34.9229,1.26051,,,,7.85398e-5
1:0 (rep 3),1-Recover,42.9,1.835,0.954,0.099,,0.342058,1260.51,,34.2058,1.26051,,,,7.85398e-5
1:0 (rep 3),1-Recover,43.267,1.856,0.933,0.079,,0.334529,1005.86,,33.4529,1.00586,,,,7.85398e-5
1:0 (rep 3),1-Recover,43.633,1.876,0.913,0.079,,0.327357,1005.86,,32.7357,1.00586,,,,7.85398e-5
1:0 (rep 3),1-Recover,44,1.897,0.892,0.072,,0.319828,916.733,,31.9828,0.916733,,,,7.85398e-5
1:0 (rep 3),1-Recover,44.367,1.917,0.872,0.072,,0.312657,916.733,,31.2657,0.916733,,,,7.85398e-5
1:0 (rep 3),1-Recover,44.733,1.938,0.851,0.066,,0.305127,840.338,,30.5127,0.840338,,,,7.85398e-5
1:0 (rep 3),1-Recover,45.1,1.958,0.831,0.072,,0.297956,916.733,,29.7956,0.916733,,,,7.85398e-5
1:0 (rep 3),1-Recover,45.467,1.979,0.81,0.066,,0.290427,840.338,,29.0427,0.840338,,,,7.85398e-5
1:0 (rep 3),1-Recover,45.833,1.999,0.79,0.066,,0.283256,840.338,,28.3256,0.840338,,,,7.85398e-5
1:0 (rep 3),1-Recover,46.2,2.02,0.769,0.066,,0.275726,840.338,,27.5726,0.840338,,,,7.85398e-5
1:0 (rep 3),1-Recover,46.567,2.04,0.749,0.066,,0.268555,840.338,,26.8555,0.840338,,,,7.85398e-5
1:0 (rep 3),1-Recover,46.933,2.061,0.728,0.066,,0.261025,840.338,,26.1025,0.840338,,,,7.85398e-5
1:0 (rep 3),1-Recover,47.3,2.081,0.708,0.066,,0.253854,840.338,,25.3854,0.840338,,,,7.85398e-5
1:0 (rep 3),1-Recover,47.667,2.102,0.687,0.066,,0.246325,840.338,,24.6325,0.840338,,,,7.85398e-5
1:0 (rep 3),1-Recover,48.033,2.122,0.667,0.066,,0.239154,840.338,,23.9154,0.840338,,,,7.85398e-5
1:0 (rep 3),1-Recover,48.4,2.142,0.647,0.066,,0.231983,840.338,,23.1983,0.840338,,,,7.85398e-5
1:0 (rep 3),1-Recover,48.767,2.163,0.626,0.066,,0.224453,840.338,,22.4453,0.840338,,,,7.85398e-5
1:0 (rep 3),1-Recover,49.133,2.183,0.606,0.066,,0.217282,840.338,,21.7282,0.840338,,,,7.85398e-5
1:0 (rep 3),1-Recover,49.5,2.204,0.585,0.052,,0.209753,662.085,,20.9753,0.662085,,,,7.85398e-5
1:0 (rep 3),1-Recover,49.867,2.225,0.564,0.059,,0.202223,751.211,,20.2223,0.751211,,,,7.85398e-5
1:0 (rep 3),1-Recover,50.233,2.245,0.544,0.059,,0.195052,751.211,,19.5052,0.751211,,,,7.85398e-5
1:0 (rep 3),1-Recover,50.6,2.265,0.524,0.059,,0.187881,751.211,,18.7881,0.751211,,,,7.85398e-5
1:0 (rep 3),1-Recover,50.967,2.286,0.503,0.038,,0.180351,483.831,,18.0351,0.483831,,,,7.85398e-5
1:0 (rep 3),1-Recover,51.333,2.306,0.483,0.052,,0.17318,662.085,,17.318,0.662085,,,,7.85398e-5
1:0 (rep 3),1-Recover,51.7,2.327,0.462,0.045,,0.165651,572.958,,16.5651,0.572958,,,,7.85398e-5
1:0 (rep 3),1-Recover,52.067,2.348,0.441,0.038,,0.158121,483.831,,15.8121,0.483831,,,,7.85398e-5
1:0 (rep 3),1-Recover,52.433,2.367,0.422,0.032,,0.151309,407.437,,15.1309,0.407437,,,,7.85398e-5
1:0 (rep 3),1-Recover,52.8,2.389,0.4,0.045,,0.143421,572.958,,14.3421,0.572958,,,,7.85398e-5
1:0 (rep 3),1-Recover,53.167,2.409,0.38,0.032,,0.13625,407.437,,13.625,0.407437,,,,7.85398e-5
1:0 (rep 3),1-Recover,53.533,2.429,0.36,0.032,,0.129079,407.437,,12.9079,0.407437,,,,7.85398e-5
1:0 (rep 3),1-Recover,53.9,2.45,0.339,0.025,,0.121549,318.31,,12.1549,0.31831,,,,7.85398e-5
1:0 (rep 3),1-Recover,54.267,2.47,0.319,0.018,,0.114378,229.183,,11.4378,0.229183,,,,7.85398e-5
1:0 (rep 3),1-Recover,54.633,2.49,0.299,0.018,,0.107207,229.183,,10.7207,0.229183,,,,7.85398e-5
1:0 (rep 3),1-Recover,55,2.511,0.278,0.025,,0.0996773,318.31,,9.96773,0.31831,,,,7.85398e-5
1:0 (rep 3),1-Recover,55.367,2.532,0.257,0.025,,0.0921477,318.31,,9.21477,0.31831,,,,7.85398e-5
1:0 (rep 3),1-Recover,55.733,2.552,0.237,0.018,,0.0849767,229.183,,8.49767,0.229183,,,,7.85398e-5
1:0 (rep 3),1-Recover,56.1,2.573,0.216,0.018,,0.0774471,229.183,,7.74471,0.229183,,,,7.85398e-5
1:0 (rep 3),1-Recover,56.467,2.593,0.196,0.011,,0.0702761,140.056,,7.02761,0.140056,,,,7.85398e-5
1:0 (rep 3),1-Recover,56.833,2.614,0.175,0.018,,0.0627465,229.183,,6.27465,0.229183,,,,7.85398e-5
1:0 (rep 3),1-Recover,57.2,2.634,0.155,0.018,,0.0555755,229.183,,5.55755,0.229183,,,,7.85398e-5
1:0 (rep 3),1-Recover,57.567,2.655,0.134,0.025,,0.0480459,318.31,,4.80459,0.31831,,,,7.85398e-5
1:0 (rep 3),1-Recover,57.933,2.675,0.114,0.018,,0.0408749,229.183,,4.08749,0.229183,,,,7.85398e-5
1:0 (rep 3),1-Recover,58.3,2.695,0.094,0.011,,0.0337038,140.056,,3.37038,0.140056,,,,7.85398e-5
1:0 (rep 3),1-Recover,58.667,2.716,0.073,0.018,,0.0261743,229.183,,2.61743,0.229183,,,,7.85398e-5
1:0 (rep 3),1-Recover,59.033,2.736,0.053,0.011,,0.0190032,140.056,,1.90032,0.140056,,,,7.85398e-5
1:0 (rep 3),1-Recover,59.4,2.757,0.032,0.018,,0.0114736,229.183,,1.14736,0.229183,,,,7.85398e-5
1:0 (rep 3),1-Recover,59.767,2.777,0.012,0.025,,0.00430262,318.31,,0.430262,0.31831,,,,7.85398e-5
1:0 (rep 3),2-Compress,60.117,2.785,0.004,0.018,,0.00143421,229.183,,0.143421,0.229183,,,,7.85398e-5
1:0 (rep 3),2-Compress,60.483,2.765,0.024,0.018,,0.00860523,229.183,,0.860523,0.229183,,,,7.85398e-5
1:0 (rep 3),2-Compress,60.85,2.744,0.045,0.011,,0.0161348,140.056,,1.61348,0.140056,,,,7.85398e-5
1:0 (rep 3),2-Compress,61.217,2.723,0.066,0.011,,0.0236644,140.056,,2.36644,0.140056,,,,7.85398e-5
1:0 (rep 3),2-Compress,61.583,2.703,0.086,0.018,,0.0308354,229.183,,3.08354,0.229183,,,,7.85398e-5
1:0 (rep 3),2-Compress,61.95,2.682,0.107,0.018,,0.038365,229.183,,3.8365,0.229183,,,,7.85398e-5
1:0 (rep 3),2-Compress,62.317,2.662,0.127,0.025,,0.045536,318.31,,4.5536,0.31831,,,,7.85398e-5
1:0 (rep 3),2-Compress,62.683,2.642,0.147,0.032,,0.0527071,407.437,,5.27071,0.407437,,,,7.85398e-5
1:0 (rep 3),2-Compress,63.05,2.621,0.168,0.011,,0.0602366,140.056,,6.02366,0.140056,,,,7.85398e-5
1:0 (rep 3),2-Compress,63.417,2.6,0.189,0.018,,0.0677662,229.183,,6.77662,0.229183,,,,7.85398e-5
1:0 (rep 3),2-Compress,63.783,2.58,0.209,0.025,,0.0749373,318.31,,7.49373,0.31831,,,,7.85398e-5
1:0 (rep 3),2-Compress,64.15,2.559,0.23,0.018,,0.0824668,229.183,,8.24668,0.229183,,,,7.85398e-5
1:0 (rep 3),2-Compress,64.517,2.539,0.25,0.018,,0.0896379,229.183,,8.96379,0.229183,,,,7.85398e-5
1:0 (rep 3),2-Compress,64.883,2.519,0.27,0.018,,0.0968089,229.183,,9.68089,0.229183,,,,7.85398e-5
1:0 (rep 3),2-Compress,65.25,2.498,0.291,0.032,,0.104338,407.437,,10.4338,0.407437,,,,7.85398e-5
1:0 (rep 3),2-Compress,65.617,2.478,0.311,0.045,,0.11151,572.958,,11.151,0.572958,,,,7.85398e-5
1:0 (rep 3),2-Compress,65.983,2.457,0.332,0.052,,0.119039,662.085,,11.9039,0.662085,,,,7.85398e-5
1:0 (rep 3),2-Compress,66.35,2.437,0.352,0.038,,0.12621,483.831,,12.621,0.483831,,,,7.85398e-5
1:0 (rep 3),2-Compress,66.717,2.416,0.373,0.018,,0.13374,229.183,,13.374,0.229183,,,,7.85398e-5
1:0 (rep 3),2-Compress,67.083,2.396,0.393,0.018,,0.140911,229.183,,14.0911,0.229183,,,,7.85398e-5
1:0 (rep 3),2-Compress,67.45,2.375,0.414,0.032,,0.14844,407.437,,14.844,0.407437,,,,7.85398e-5
1:0 (rep 3),2-Compress,67.817,2.355,0.434,0.059,,0.155611,751.211,,15.5611,0.751211,,,,7.85398e-5
1:0 (rep 3),2-Compress,68.183,2.334,0.455,0.059,,0.163141,751.211,,16.3141,0.751211,,,,7.85398e-5
1:0 (rep 3),2-Compress,68.55,2.314,0.475,0.052,,0.170312,662.085,,17.0312,0.662085,,,,7.85398e-5
1:0 (rep 3),2-Compress,68.917,2.294,0.495,0.066,,0.177483,840.338,,17.7483,0.840338,,,,7.85398e-5
1:0 (rep 3),2-Compress,69.283,2.273,0.516,0.066,,0.185013,840.338,,18.5013,0.840338,,,,7.85398e-5
1:0 (rep 3),2-Compress,69.65,2.253,0.536,0.066,,0.192184,840.338,,19.2184,0.840338,,,,7.85398e-5
1:0 (rep 3),2-Compress,70.017,2.232,0.557,0.066,,0.199713,840.338,,19.9713,0.840338,,,,7.85398e-5
1:0 (rep 3),2-Compress,70.383,2.212,0.577,0.059,,0.206884,751.211,,20.6884,0.751211,,,,7.85398e-5
1:0 (rep 3),2-Compress,70.75,2.191,0.598,0.066,,0.214414,840.338,,21.4414,0.840338,,,,7.85398e-5
1:0 (rep 3),2-Compress,71.117,2.17,0.619,0.066,,0.221943,840.338,,22.1943,0.840338,,,,7.85398e-5
1:0 (rep 3),2-Compress,71.483,2.15,0.639,0.066,,0.229114,840.338,,22.9114,0.840338,,,,7.85398e-5
1:0 (rep 3),2-Compress,71.85,2.13,0.659,0.066,,0.236285,840.338,,23.6285,0.840338,,,,7.85398e-5
1:0 (rep 3),2-Compress,72.217,2.109,0.68,0.066,,0.243815,840.338,,24.3815,0.840338,,,,7.85398e-5
1:0 (rep 3),2-Compress,72.583,2.089,0.7,0.066,,0.250986,840.338,,25.0986,0.840338,,,,7.85398e-5
1:0 (rep 3),2-Compress,72.95,2.068,0.721,0.066,,0.258516,840.338,,25.8516,0.840338,,,,7.85398e-5
1:0 (rep 3),2-Compress,73.317,2.047,0.742,0.066,,0.266045,840.338,,26.6045,0.840338,,,,7.85398e-5
1:0 (rep 3),2-Compress,73.683,2.028,0.761,0.072,,0.272858,916.733,,27.2858,0.916733,,,,7.85398e-5
1:0 (rep 3),2-Compress,74.05,2.007,0.782,0.066,,0.280387,840.338,,28.0387,0.840338,,,,7.85398e-5
1:0 (rep 3),2-Compress,74.417,1.986,0.803,0.072,,0.287917,916.733,,28.7917,0.916733,,,,7.85398e-5
1:0 (rep 3),2-Compress,74.783,1.966,0.823,0.066,,0.295088,840.338,,29.5088,0.840338,,,,7.85398e-5
1:0 (rep 3),2-Compress,75.15,1.945,0.844,0.079,,0.302617,1005.86,,30.2617,1.00586,,,,7.85398e-5
1:0 (rep 3),2-Compress,75.517,1.925,0.864,0.079,,0.309788,1005.86,,30.9788,1.00586,,,,7.85398e-5
1:0 (rep 3),2-Compress,75.883,1.905,0.884,0.093,,0.316959,1184.11,,31.6959,1.18411,,,,7.85398e-5
1:0 (rep 3),2-Compress,76.25,1.884,0.905,0.086,,0.324489,1094.99,,32.4489,1.09499,,,,7.85398e-5
1:0 (rep 3),2-Compress,76.617,1.863,0.926,0.099,,0.332019,1260.51,,33.2019,1.26051,,,,7.85398e-5
1:0 (rep 3),2-Compress,76.983,1.843,0.946,0.079,,0.33919,1005.86,,33.919,1.00586,,,,7.85398e-5
1:0 (rep 3),2-Compress,77.35,1.822,0.967,0.106,,0.346719,1349.63,,34.6719,1.34963,,,,7.85398e-5
1:0 (rep 3),2-Compress,77.717,1.802,0.987,0.093,,0.35389,1184.11,,35.389,1.18411,,,,7.85398e-5
1:0 (rep 3),2-Compress,78.083,1.782,1.007,0.12,,0.361061,1527.89,,36.1061,1.52789,,,,7.85398e-5
1:0 (rep 3),2-Compress,78.45,1.761,1.028,0.12,,0.368591,1527.89,,36.8591,1.52789,,,,7.85398e-5
1:0 (rep 3),2-Compress,78.817,1.74,1.049,0.12,,0.37612,1527.89,,37.612,1.52789,,,,7.85398e-5
1:0 (rep 3),2-Compress,79.183,1.72,1.069,0.12,,0.383292,1527.89,,38.3292,1.52789,,,,7.85398e-5
1:0 (rep 3),2-Compress,79.55,1.7,1.089,0.12,,0.390463,1527.89,,39.0463,1.52789,,,,7.85398e-5
1:0 (rep 3),2-Compress,79.917,1.679,1.11,0.12,,0.397992,1527.89,,39.7992,1.52789,,,,7.85398e-5
1:0 (rep 3),2-Compress,80.283,1.659,1.13,0.12,,0.405163,1527.89,,40.5163,1.52789,,,,7.85398e-5
1:0 (rep 3),2-Compress,80.65,1.638,1.151,0.12,,0.412693,1527.89,,41.2693,1.52789,,,,7.85398e-5
1:0 (rep 3),2-Compress,81.017,1.618,1.171,0.127,,0.419864,1617.01,,41.9864,1.61701,,,,7.85398e-5
1:0 (rep 3),2-Compress,81.383,1.597,1.192,0.127,,0.427393,1617.01,,42.7393,1.61701,,,,7.85398e-5
1:0 (rep 3),2-Compress,81.75,1.577,1.212,0.127,,0.434564,1617.01,,43.4564,1.61701,,,,7.85398e-5
1:0 (rep 3),2-Compress,82.117,1.556,1.233,0.12,,0.442094,1527.89,,44.2094,1.52789,,,,7.85398e-5
1:0 (rep 3),2-Compress,82.483,1.536,1.253,0.12,,0.449265,1527.89,,44.9265,1.52789,,,,7.85398e-5
1:0 (rep 3),2-Compress,82.85,1.515,1.274,0.154,,0.456795,1960.79,,45.6795,1.96079,,,,7.85398e-5
1:0 (rep 3),2-Compress,83.217,1.495,1.294,0.161,,0.463966,2049.92,,46.3966,2.04992,,,,7.85398e-5
1:0 (rep 3),2-Compress,83.583,1.474,1.315,0.154,,0.471495,1960.79,,47.1495,1.96079,,,,7.85398e-5
1:0 (rep 3),2-Compress,83.95,1.454,1.335,0.167,,0.478666,2126.31,,47.8666,2.12631,,,,7.85398e-5
1:0 (rep 3),2-Compress,84.317,1.434,1.355,0.167,,0.485837,2126.31,,48.5837,2.12631,,,,7.85398e-5
1:0 (rep 3),2-Compress,84.683,1.413,1.376,0.174,,0.493367,2215.44,,49.3367,2.21544,,,,7.85398e-5
1:0 (rep 3),2-Compress,85.05,1.393,1.396,0.167,,0.500538,2126.31,,50.0538,2.12631,,,,7.85398e-5
1:0 (rep 3),2-Compress,85.417,1.372,1.417,0.167,,0.508067,2126.31,,50.8067,2.12631,,,,7.85398e-5
1:0 (rep 3),2-Compress,85.783,1.352,1.437,0.174,,0.515238,2215.44,,51.5238,2.21544,,,,7.85398e-5
1:0 (rep 3),2-Compress,86.15,1.331,1.458,0.174,,0.522768,2215.44,,52.2768,2.21544,,,,7.85398e-5
1:0 (rep 3),2-Compress,86.517,1.31,1.479,0.174,,0.530298,2215.44,,53.0298,2.21544,,,,7.85398e-5
1:0 (rep 3),2-Compress,86.883,1.29,1.499,0.174,,0.537469,2215.44,,53.7469,2.21544,,,,7.85398e-5
1:0 (rep 3),2-Compress,87.25,1.27,1.519,0.174,,0.54464,2215.44,,54.464,2.21544,,,,7.85398e-5
1:0 (rep 3),2-Compress,87.617,1.249,1.54,0.174,,0.552169,2215.44,,55.2169,2.21544,,,,7.85398e-5
1:0 (rep 3),2-Compress,87.983,1.229,1.56,0.181,,0.55934,2304.56,,55.934,2.30456,,,,7.85398e-5
1:0 (rep 3),2-Compress,88.35,1.208,1.581,0.174,,0.56687,2215.44,,56.687,2.21544,,,,7.85398e-5
1:0 (rep 3),2-Compress,88.717,1.187,1.602,0.181,,0.574399,2304.56,,57.4399,2.30456,,,,7.85398e-5
1:0 (rep 3),2-Compress,89.083,1.168,1.621,0.208,,0.581212,2648.34,,58.1212,2.64834,,,,7.85398e-5
1:0 (rep 3),2-Compress,89.45,1.147,1.642,0.229,,0.588741,2915.72,,58.8741,2.91572,,,,7.85398e-5
1:0 (rep 3),2-Compress,89.817,1.126,1.663,0.229,,0.596271,2915.72,,59.6271,2.91572,,,,7.85398e-5
1:0 (rep 3),2-Recover,90.17,1.123,1.666,0.229,,0.597347,2915.72,,59.7347,2.91572,,,,7.85398e-5
1:0 (rep 3),2-Recover,90.537,1.143,1.646,0.208,,0.590176,2648.34,,59.0176,2.64834,,,,7.85398e-5
1:0 (rep 3),2-Recover,90.903,1.163,1.626,0.201,,0.583005,2559.21,,58.3005,2.55921,,,,7.85398e-5
1:0 (rep 3),2-Recover,91.27,1.184,1.605,0.181,,0.575475,2304.56,,57.5475,2.30456,,,,7.85398e-5
1:0 (rep 3),2-Recover,91.637,1.205,1.584,0.174,,0.567946,2215.44,,56.7946,2.21544,,,,7.85398e-5
1:0 (rep 3),2-Recover,92.003,1.225,1.564,0.174,,0.560774,2215.44,,56.0774,2.21544,,,,7.85398e-5
1:0 (rep 3),2-Recover,92.37,1.245,1.544,0.174,,0.553603,2215.44,,55.3603,2.21544,,,,7.85398e-5
1:0 (rep 3),2-Recover,92.737,1.266,1.523,0.174,,0.546074,2215.44,,54.6074,2.21544,,,,7.85398e-5
1:0 (rep 3),2-Recover,93.103,1.286,1.503,0.174,,0.538903,2215.44,,53.8903,2.21544,,,,7.85398e-5
1:0 (rep 3),2-Recover,93.47,1.307,1.482,0.174,,0.531373,2215.44,,53.1373,2.21544,,,,7.85398e-5
1:0 (rep 3),2-Recover,93.837,1.327,1.462,0.174,,0.524202,2215.44,,52.4202,2.21544,,,,7.85398e-5
1:0 (rep 3),2-Recover,94.203,1.348,1.441,0.174,,0.516673,2215.44,,51.6673,2.21544,,,,7.85398e-5
1:0 (rep 3),2-Recover,94.57,1.368,1.421,0.161,,0.509502,2049.92,,50.9502,2.04992,,,,7.85398e-5
1:0 (rep 3),2-Recover,94.937,1.389,1.4,0.161,,0.501972,2049.92,,50.1972,2.04992,,,,7.85398e-5
1:0 (rep 3),2-Recover,95.303,1.409,1.38,0.14,,0.494801,1782.54,,49.4801,1.78254,,,,7.85398e-5
1:0 (rep 3),2-Recover,95.67,1.43,1.359,0.14,,0.487271,1782.54,,48.7271,1.78254,,,,7.85398e-5
1:0 (rep 3),2-Recover,96.037,1.45,1.339,0.147,,0.4801,1871.66,,48.01,1.87166,,,,7.85398e-5
1:0 (rep 3),2-Recover,96.403,1.47,1.319,0.133,,0.472929,1693.41,,47.2929,1.69341,,,,7.85398e-5
1:0 (rep 3),2-Recover,96.77,1.491,1.298,0.127,,0.4654,1617.01,,46.54,1.61701,,,,7.85398e-5
1:0 (rep 3),2-Recover,97.137,1.511,1.278,0.127,,0.458229,1617.01,,45.8229,1.61701,,,,7.85398e-5
1:0 (rep 3),2-Recover,97.503,1.532,1.257,0.12,,0.450699,1527.89,,45.0699,1.52789,,,,7.85398e-5
1:0 (rep 3),2-Recover,97.87,1.552,1.237,0.127,,0.443528,1617.01,,44.3528,1.61701,,,,7.85398e-5
1:0 (rep 3),2-Recover,98.237,1.573,1.216,0.12,,0.435999,1527.89,,43.5999,1.52789,,,,7.85398e-5
1:0 (rep 3),2-Recover,98.603,1.593,1.196,0.12,,0.428828,1527.89,,42.8828,1.52789,,,,7.85398e-5
1:0 (rep 3),2-Recover,98.97,1.614,1.175,0.12,,0.421298,1527.89,,42.1298,1.52789,,,,7.85398e-5
1:0 (rep 3),2-Recover,99.337,1.634,1.155,0.12,,0.414127,1527.89,,41.4127,1.52789,,,,7.85398e-5
1:0 (rep 3),2-Recover,99.703,1.655,1.134,0.12,,0.406597,1527.89,,40.6597,1.52789,,,,7.85398e-5
1:0 (rep 3),2-Recover,100.07,1.675,1.114,0.113,,0.399426,1438.76,,39.9426,1.43876,,,,7.85398e-5
1:0 (rep 3),2-Recover,100.437,1.696,1.093,0.113,,0.391897,1438.76,,39.1897,1.43876,,,,7.85398e-5
1:0 (rep 3),2-Recover,100.803,1.716,1.073,0.106,,0.384726,1349.63,,38.4726,1.34963,,,,7.85398e-5
1:0 (rep 3),2-Recover,101.17,1.736,1.053,0.106,,0.377555,1349.63,,37.7555,1.34963,,,,7.85398e-5
1:0 (rep 3),2-Recover,101.537,1.758,1.031,0.106,,0.369667,1349.63,,36.9667,1.34963,,,,7.85398e-5
1:0 (rep 3),2-Recover,101.903,1.777,1.012,0.086,,0.362854,1094.99,,36.2854,1.09499,,,,7.85398e-5
1:0 (rep 3),2-Recover,102.27,1.798,0.991,0.072,,0.355324,916.733,,35.5324,0.916733,,,,7.85398e-5
1:0 (rep 3),2-Recover,102.637,1.819,0.97,0.072,,0.347795,916.733,,34.7795,0.916733,,,,7.85398e-5
1:0 (rep 3),2-Recover,103.003,1.839,0.95,0.079,,0.340624,1005.86,,34.0624,1.00586,,,,7.85398e-5
1:0 (rep 3),2-Recover,103.37,1.86,0.929,0.079,,0.333094,1005.86,,33.3094,1.00586,,,,7.85398e-5
1:0 (rep 3),2-Recover,103.737,1.88,0.909,0.086,,0.325923,1094.99,,32.5923,1.09499,,,,7.85398e-5
1:0 (rep 3),2-Recover,104.103,1.9,0.889,0.072,,0.318752,916.733,,31.8752,0.916733,,,,7.85398e-5
1:0 (rep 3),2-Recover,104.47,1.921,0.868,0.066,,0.311223,840.338,,31.1223,0.840338,,,,7.85398e-5
1:0 (rep 3),2-Recover,104.837,1.942,0.847,0.066,,0.303693,840.338,,30.3693,0.840338,,,,7.85398e-5
1:0 (rep 3),2-Recover,105.203,1.962,0.827,0.066,,0.296522,840.338,,29.6522,0.840338,,,,7.85398e-5
1:0 (rep 3),2-Recover,105.57,1.983,0.806,0.066,,0.288992,840.338,,28.8992,0.840338,,,,7.85398e-5
1:0 (rep 3),2-Recover,105.937,2.003,0.786,0.066,,0.281821,840.338,,28.1821,0.840338,,,,7.85398e-5
1:0 (rep 3),2-Recover,106.303,2.023,0.766,0.066,,0.27465,840.338,,27.465,0.840338,,,,7.85398e-5
1:0 (rep 3),2-Recover,106.67,2.044,0.745,0.066,,0.267121,840.338,,26.7121,0.840338,,,,7.85398e-5
1:0 (rep 3),2-Recover,107.037,2.064,0.725,0.066,,0.25995,840.338,,25.995,0.840338,,,,7.85398e-5
1:0 (rep 3),2-Recover,107.403,2.085,0.704,0.072,,0.25242,916.733,,25.242,0.916733,,,,7.85398e-5
1:0 (rep 3),2-Recover,107.77,2.105,0.684,0.066,,0.245249,840.338,,24.5249,0.840338,,,,7.85398e-5
1:0 (rep 3),2-Recover,108.137,2.126,0.663,0.066,,0.23772,840.338,,23.772,0.840338,,,,7.85398e-5
1:0 (rep 3),2-Recover,108.503,2.146,0.643,0.066,,0.230549,840.338,,23.0549,0.840338,,,,7.85398e-5
1:0 (rep 3),2-Recover,108.87,2.167,0.622,0.066,,0.223019,840.338,,22.3019,0.840338,,,,7.85398e-5
1:0 (rep 3),2-Recover,109.237,2.187,0.602,0.052,,0.215848,662.085,,21.5848,0.662085,,,,7.85398e-5
1:0 (rep 3),2-Recover,109.603,2.208,0.581,0.059,,0.208318,751.211,,20.8318,0.751211,,,,7.85398e-5
1:0 (rep 3),2-Recover,109.97,2.228,0.561,0.032,,0.201147,407.437,,20.1147,0.407437,,,,7.85398e-5
1:0 (rep 3),2-Recover,110.337,2.249,0.54,0.059,,0.193618,751.211,,19.3618,0.751211,,,,7.85398e-5
1:0 (rep 3),2-Recover,110.703,2.269,0.52,0.052,,0.186447,662.085,,18.6447,0.662085,,,,7.85398e-5
1:0 (rep 3),2-Recover,111.07,2.29,0.499,0.045,,0.178917,572.958,,17.8917,0.572958,,,,7.85398e-5
1:0 (rep 3),2-Recover,111.437,2.31,0.479,0.045,,0.171746,572.958,,17.1746,0.572958,,,,7.85398e-5
1:0 (rep 3),2-Recover,111.803,2.33,0.459,0.032,,0.164575,407.437,,16.4575,0.407437,,,,7.85398e-5
1:0 (rep 3),2-Recover,112.17,2.351,0.438,0.018,,0.157046,229.183,,15.7046,0.229183,,,,7.85398e-5
1:0 (rep 3),2-Recover,112.537,2.371,0.418,0.032,,0.149875,407.437,,14.9875,0.407437,,,,7.85398e-5
1:0 (rep 3),2-Recover,112.903,2.392,0.397,0.032,,0.142345,407.437,,14.2345,0.407437,,,,7.85398e-5
1:0 (rep 3),2-Recover,113.27,2.412,0.377,0.038,,0.135174,483.831,,13.5174,0.483831,,,,7.85398e-5
1:0 (rep 3),2-Recover,113.637,2.433,0.356,0.032,,0.127644,407.437,,12.7644,0.407437,,,,7.85398e-5
1:0 (rep 3),2-Recover,114.003,2.453,0.336,0.025,,0.120473,318.31,,12.0473,0.31831,,,,7.85398e-5
1:0 (rep 3),2-Recover,114.37,2.474,0.315,0.018,,0.112944,229.183,,11.2944,0.229183,,,,7.85398e-5
1:0 (rep 3),2-Recover,114.737,2.494,0.295,0.018,,0.105773,229.183,,10.5773,0.229183,,,,7.85398e-5
1:0 (rep 3),2-Recover,115.103,2.515,0.274,0.018,,0.0982431,229.183,,9.82431,0.229183,,,,7.85398e-5
1:0 (rep 3),2-Recover,115.47,2.535,0.254,0.025,,0.0910721,318.31,,9.10721,0.31831,,,,7.85398e-5
1:0 (rep 3),2-Recover,115.837,2.556,0.233,0.032,,0.0835425,407.437,,8.35425,0.407437,,,,7.85398e-5
1:0 (rep 3),2-Recover,116.203,2.576,0.213,0.018,,0.0763715,229.183,,7.63715,0.229183,,,,7.85398e-5
1:0 (rep 3),2-Recover,116.57,2.596,0.193,0.025,,0.0692004,318.31,,6.92004,0.31831,,,,7.85398e-5
1:0 (rep 3),2-Recover,116.937,2.618,0.171,0.011,,0.0613123,140.056,,6.13123,0.140056,,,,7.85398e-5
1:0 (rep 3),2-Recover,117.303,2.637,0.152,0.011,,0.0544998,140.056,,5.44998,0.140056,,,,7.85398e-5
1:0 (rep 3),2-Recover,117.67,2.658,0.131,0.018,,0.0469702,229.183,,4.69702,0.229183,,,,7.85398e-5
1:0 (rep 3),2-Recover,118.037,2.679,0.11,0.025,,0.0394407,318.31,,3.94407,0.31831,,,,7.85398e-5
1:0 (rep 3),2-Recover,118.403,2.699,0.09,0.018,,0.0322696,229.183,,3.22696,0.229183,,,,7.85398e-5
1:0 (rep 3),2-Recover,118.77,2.72,0.069,0.011,,0.0247401,140.056,,2.47401,0.140056,,,,7.85398e-5
1:0 (rep 3),2-Recover,119.137,2.74,0.049,0.011,,0.017569,140.056,,1.7569,0.140056,,,,7.85398e-5
1:0 (rep 3),2-Recover,119.503,2.76,0.029,0.011,,0.010398,140.056,,1.0398,0.140056,,,,7.85398e-5
1:0 (rep 3),2-Recover,119.87,2.781,0.008,0.018,,0.00286841,229.183,,0.286841,0.229183,,,,7.85398e-5
1:0 (rep 3),3-Compress,120.223,2.781,0.008,0.018,,0.00286841,229.183,,0.286841,0.229183,,,,7.85398e-5
1:0 (rep 3),3-Compress,120.59,2.76,0.029,0.025,,0.010398,318.31,,1.0398,0.31831,,,,7.85398e-5
1:0 (rep 3),3-Compress,120.957,2.74,0.049,0.018,,0.017569,229.183,,1.7569,0.229183,,,,7.85398e-5
1:0 (rep 3),3-Compress,121.323,2.72,0.069,0.018,,0.0247401,229.183,,2.47401,0.229183,,,,7.85398e-5
1:0 (rep 3),3-Compress,121.69,2.699,0.09,0.011,,0.0322696,140.056,,3.22696,0.140056,,,,7.85398e-5
1:0 (rep 3),3-Compress,122.057,2.678,0.111,0.011,,0.0397992,140.056,,3.97992,0.140056,,,,7.85398e-5
1:0 (rep 3),3-Compress,122.423,2.658,0.131,0.011,,0.0469702,140.056,,4.69702,0.140056,,,,7.85398e-5
1:0 (rep 3),3-Compress,122.79,2.637,0.152,0.018,,0.0544998,229.183,,5.44998,0.229183,,,,7.85398e-5
1:0 (rep 3),3-Compress,123.157,2.617,0.172,0.025,,0.0616708,318.31,,6.16708,0.31831,,,,7.85398e-5
1:0 (rep 3),3-Compress,123.523,2.597,0.192,0.032,,0.0688419,407.437,,6.88419,0.407437,,,,7.85398e-5
1:0 (rep 3),3-Compress,123.89,2.576,0.213,0.038,,0.0763715,483.831,,7.63715,0.483831,,,,7.85398e-5
1:0 (rep 3),3-Compress,124.257,2.556,0.233,0.018,,0.0835425,229.183,,8.35425,0.229183,,,,7.85398e-5
1:0 (rep 3),3-Compress,124.623,2.535,0.254,0.018,,0.0910721,229.183,,9.10721,0.229183,,,,7.85398e-5
1:0 (rep 3),3-Compress,124.99,2.515,0.274,0.018,,0.0982431,229.183,,9.82431,0.229183,,,,7.85398e-5
1:0 (rep 3),3-Compress,125.357,2.494,0.295,0.018,,0.105773,229.183,,10.5773,0.229183,,,,7.85398e-5
1:0 (rep 3),3-Compress,125.723,2.474,0.315,0.025,,0.112944,318.31,,11.2944,0.31831,,,,7.85398e-5
1:0 (rep 3),3-Compress,126.09,2.453,0.336,0.052,,0.120473,662.085,,12.0473,0.662085,,,,7.85398e-5
1:0 (rep 3),3-Compress,126.457,2.433,0.356,0.045,,0.127644,572.958,,12.7644,0.572958,,,,7.85398e-5
1:0 (rep 3),3-Compress,126.823,2.412,0.377,0.045,,0.135174,572.958,,13.5174,0.572958,,,,7.85398e-5
1:0 (rep 3),3-Compress,127.19,2.392,0.397,0.052,,0.142345,662.085,,14.2345,0.662085,,,,7.85398e-5
1:0 (rep 3),3-Compress,127.557,2.371,0.418,0.038,,0.149875,483.831,,14.9875,0.483831,,,,7.85398e-5
1:0 (rep 3),3-Compress,127.923,2.351,0.438,0.045,,0.157046,572.958,,15.7046,0.572958,,,,7.85398e-5
1:0 (rep 3),3-Compress,128.29,2.33,0.459,0.052,,0.164575,662.085,,16.4575,0.662085,,,,7.85398e-5
1:0 (rep 3),3-Compress,128.657,2.31,0.479,0.059,,0.171746,751.211,,17.1746,0.751211,,,,7.85398e-5
1:0 (rep 3),3-Compress,129.023,2.29,0.499,0.066,,0.178917,840.338,,17.8917,0.840338,,,,7.85398e-5
1:0 (rep 3),3-Compress,129.39,2.269,0.52,0.066,,0.186447,840.338,,18.6447,0.840338,,,,7.85398e-5
1:0 (rep 3),3-Compress,129.757,2.249,0.54,0.066,,0.193618,840.338,,19.3618,0.840338,,,,7.85398e-5
1:0 (rep 3),3-Compress,130.123,2.228,0.561,0.072,,0.201147,916.733,,20.1147,0.916733,,,,7.85398e-5
1:0 (rep 3),3-Compress,130.49,2.208,0.581,0.066,,0.208318,840.338,,20.8318,0.840338,,,,7.85398e-5
1:0 (rep 3),3-Compress,130.857,2.187,0.602,0.066,,0.215848,840.338,,21.5848,0.840338,,,,7.85398e-5
1:0 (rep 3),3-Compress,131.223,2.167,0.622,0.066,,0.223019,840.338,,22.3019,0.840338,,,,7.85398e-5
1:0 (rep 3),3-Compress,131.59,2.146,0.643,0.066,,0.230549,840.338,,23.0549,0.840338,,,,7.85398e-5
1:0 (rep 3),3-Compress,131.957,2.126,0.663,0.066,,0.23772,840.338,,23.772,0.840338,,,,7.85398e-5
1:0 (rep 3),3-Compress,132.323,2.105,0.684,0.066,,0.245249,840.338,,24.5249,0.840338,,,,7.85398e-5
1:0 (rep 3),3-Compress,132.69,2.085,0.704,0.066,,0.25242,840.338,,25.242,0.840338,,,,7.85398e-5
1:0 (rep 3),3-Compress,133.057,2.064,0.725,0.066,,0.25995,840.338,,25.995,0.840338,,,,7.85398e-5
1:0 (rep 3),3-Compress,133.423,2.044,0.745,0.072,,0.267121,916.733,,26.7121,0.916733,,,,7.85398e-5
1:0 (rep 3),3-Compress,133.79,2.024,0.765,0.066,,0.274292,840.338,,27.4292,0.840338,,,,7.85398e-5
1:0 (rep 3),3-Compress,134.157,2.002,0.787,0.072,,0.28218,916.733,,28.218,0.916733,,,,7.85398e-5
1:0 (rep 3),3-Compress,134.523,1.983,0.806,0.066,,0.288992,840.338,,28.8992,0.840338,,,,7.85398e-5
1:0 (rep 3),3-Compress,134.89,1.962,0.827,0.072,,0.296522,916.733,,29.6522,0.916733,,,,7.85398e-5
1:0 (rep 3),3-Compress,135.257,1.941,0.848,0.066,,0.304052,840.338,,30.4052,0.840338,,,,7.85398e-5
1:0 (rep 3),3-Compress,135.623,1.921,0.868,0.072,,0.311223,916.733,,31.1223,0.916733,,,,7.85398e-5
1:0 (rep 3),3-Compress,135.99,1.9,0.889,0.093,,0.318752,1184.11,,31.8752,1.18411,,,,7.85398e-5
1:0 (rep 3),3-Compress,136.357,1.88,0.909,0.093,,0.325923,1184.11,,32.5923,1.18411,,,,7.85398e-5
1:0 (rep 3),3-Compress,136.723,1.86,0.929,0.113,,0.333094,1438.76,,33.3094,1.43876,,,,7.85398e-5
1:0 (rep 3),3-Compress,137.09,1.839,0.95,0.086,,0.340624,1094.99,,34.0624,1.09499,,,,7.85398e-5
1:0 (rep 3),3-Compress,137.457,1.818,0.971,0.093,,0.348153,1184.11,,34.8153,1.18411,,,,7.85398e-5
1:0 (rep 3),3-Compress,137.823,1.799,0.99,0.12,,0.354966,1527.89,,35.4966,1.52789,,,,7.85398e-5
1:0 (rep 3),3-Compress,138.19,1.777,1.012,0.106,,0.362854,1349.63,,36.2854,1.34963,,,,7.85398e-5
1:0 (rep 3),3-Compress,138.557,1.757,1.032,0.12,,0.370025,1527.89,,37.0025,1.52789,,,,7.85398e-5
1:0 (rep 3),3-Compress,138.923,1.737,1.052,0.12,,0.377196,1527.89,,37.7196,1.52789,,,,7.85398e-5
1:0 (rep 3),3-Compress,139.29,1.716,1.073,0.12,,0.384726,1527.89,,38.4726,1.52789,,,,7.85398e-5
1:0 (rep 3),3-Compress,139.657,1.696,1.093,0.12,,0.391897,1527.89,,39.1897,1.52789,,,,7.85398e-5
1:0 (rep 3),3-Compress,140.023,1.676,1.113,0.12,,0.399068,1527.89,,39.9068,1.52789,,,,7.85398e-5
1:0 (rep 3),3-Compress,140.39,1.655,1.134,0.12,,0.406597,1527.89,,40.6597,1.52789,,,,7.85398e-5
1:0 (rep 3),3-Compress,140.757,1.634,1.155,0.12,,0.414127,1527.89,,41.4127,1.52789,,,,7.85398e-5
1:0 (rep 3),3-Compress,141.123,1.614,1.175,0.12,,0.421298,1527.89,,42.1298,1.52789,,,,7.85398e-5
1:0 (rep 3),3-Compress,141.49,1.593,1.196,0.127,,0.428828,1617.01,,42.8828,1.61701,,,,7.85398e-5
1:0 (rep 3),3-Compress,141.857,1.573,1.216,0.127,,0.435999,1617.01,,43.5999,1.61701,,,,7.85398e-5
1:0 (rep 3),3-Compress,142.223,1.552,1.237,0.127,,0.443528,1617.01,,44.3528,1.61701,,,,7.85398e-5
1:0 (rep 3),3-Compress,142.59,1.532,1.257,0.12,,0.450699,1527.89,,45.0699,1.52789,,,,7.85398e-5
1:0 (rep 3),3-Compress,142.957,1.511,1.278,0.12,,0.458229,1527.89,,45.8229,1.52789,,,,7.85398e-5
1:0 (rep 3),3-Compress,143.323,1.491,1.298,0.154,,0.4654,1960.79,,46.54,1.96079,,,,7.85398e-5
1:0 (rep 3),3-Compress,143.69,1.47,1.319,0.161,,0.472929,2049.92,,47.2929,2.04992,,,,7.85398e-5
1:0 (rep 3),3-Compress,144.057,1.45,1.339,0.154,,0.4801,1960.79,,48.01,1.96079,,,,7.85398e-5
1:0 (rep 3),3-Compress,144.423,1.43,1.359,0.174,,0.487271,2215.44,,48.7271,2.21544,,,,7.85398e-5
1:0 (rep 3),3-Compress,144.79,1.409,1.38,0.167,,0.494801,2126.31,,49.4801,2.12631,,,,7.85398e-5
1:0 (rep 3),3-Compress,145.157,1.389,1.4,0.174,,0.501972,2215.44,,50.1972,2.21544,,,,7.85398e-5
1:0 (rep 3),3-Compress,145.523,1.368,1.421,0.174,,0.509502,2215.44,,50.9502,2.21544,,,,7.85398e-5
1:0 (rep 3),3-Compress,145.89,1.348,1.441,0.167,,0.516673,2126.31,,51.6673,2.12631,,,,7.85398e-5
1:0 (rep 3),3-Compress,146.257,1.327,1.462,0.167,,0.524202,2126.31,,52.4202,2.12631,,,,7.85398e-5
1:0 (rep 3),3-Compress,146.623,1.307,1.482,0.174,,0.531373,2215.44,,53.1373,2.21544,,,,7.85398e-5
1:0 (rep 3),3-Compress,146.99,1.286,1.503,0.174,,0.538903,2215.44,,53.8903,2.21544,,,,7.85398e-5
1:0 (rep 3),3-Compress,147.357,1.266,1.523,0.174,,0.546074,2215.44,,54.6074,2.21544,,,,7.85398e-5
1:0 (rep 3),3-Compress,147.723,1.245,1.544,0.174,,0.553603,2215.44,,55.3603,2.21544,,,,7.85398e-5
1:0 (rep 3),3-Compress,148.09,1.225,1.564,0.188,,0.560774,2393.69,,56.0774,2.39369,,,,7.85398e-5
1:0 (rep 3),3-Compress,148.457,1.204,1.585,0.181,,0.568304,2304.56,,56.8304,2.30456,,,,7.85398e-5
1:0 (rep 3),3-Compress,148.823,1.184,1.605,0.181,,0.575475,2304.56,,57.5475,2.30456,,,,7.85398e-5
1:0 (rep 3),3-Compress,149.19,1.164,1.625,0.188,,0.582646,2393.69,,58.2646,2.39369,,,,7.85398e-5
1:0 (rep 3),3-Compress,149.557,1.142,1.647,0.208,,0.590534,2648.34,,59.0534,2.64834,,,,7.85398e-5
1:0 (rep 3),3-Compress,149.923,1.123,1.666,0.222,,0.597347,2826.59,,59.7347,2.82659,,,,7.85398e-5
1:0 (rep 3),3-Recover,150.277,1.126,1.663,0.229,,0.596271,2915.72,,59.6271,2.91572,,,,7.85398e-5
1:0 (rep 3),3-Recover,150.643,1.146,1.643,0.208,,0.5891,2648.34,,58.91,2.64834,,,,7.85398e-5
1:0 (rep 3),3-Recover,151.01,1.167,1.622,0.188,,0.58157,2393.69,,58.157,2.39369,,,,7.85398e-5
1:0 (rep 3),3-Recover,151.377,1.188,1.601,0.174,,0.574041,2215.44,,57.4041,2.21544,,,,7.85398e-5
1:0 (rep 3),3-Recover,151.743,1.208,1.581,0.167,,0.56687,2126.31,,56.687,2.12631,,,,7.85398e-5
1:0 (rep 3),3-Recover,152.11,1.228,1.561,0.174,,0.559699,2215.44,,55.9699,2.21544,,,,7.85398e-5
1:0 (rep 3),3-Recover,152.477,1.249,1.54,0.174,,0.552169,2215.44,,55.2169,2.21544,,,,7.85398e-5
1:0 (rep 3),3-Recover,152.843,1.269,1.52,0.174,,0.544998,2215.44,,54.4998,2.21544,,,,7.85398e-5
1:0 (rep 3),3-Recover,153.21,1.29,1.499,0.174,,0.537469,2215.44,,53.7469,2.21544,,,,7.85398e-5
1:0 (rep 3),3-Recover,153.577,1.311,1.478,0.174,,0.529939,2215.44,,52.9939,2.21544,,,,7.85398e-5
1:0 (rep 3),3-Recover,153.943,1.331,1.458,0.174,,0.522768,2215.44,,52.2768,2.21544,,,,7.85398e-5
1:0 (rep 3),3-Recover,154.31,1.351,1.438,0.174,,0.515597,2215.44,,51.5597,2.21544,,,,7.85398e-5
1:0 (rep 3),3-Recover,154.677,1.372,1.417,0.161,,0.508067,2049.92,,50.8067,2.04992,,,,7.85398e-5
1:0 (rep 3),3-Recover,155.043,1.392,1.397,0.154,,0.500896,1960.79,,50.0896,1.96079,,,,7.85398e-5
1:0 (rep 3),3-Recover,155.41,1.412,1.377,0.14,,0.493725,1782.54,,49.3725,1.78254,,,,7.85398e-5
1:0 (rep 3),3-Recover,155.777,1.434,1.355,0.12,,0.485837,1527.89,,48.5837,1.52789,,,,7.85398e-5
1:0 (rep 3),3-Recover,156.143,1.453,1.336,0.147,,0.479025,1871.66,,47.9025,1.87166,,,,7.85398e-5
1:0 (rep 3),3-Recover,156.51,1.474,1.315,0.133,,0.471495,1693.41,,47.1495,1.69341,,,,7.85398e-5
1:0 (rep 3),3-Recover,156.877,1.495,1.294,0.127,,0.463966,1617.01,,46.3966,1.61701,,,,7.85398e-5
1:0 (rep 3),3-Recover,157.243,1.515,1.274,0.127,,0.456795,1617.01,,45.6795,1.61701,,,,7.85398e-5
1:0 (rep 3),3-Recover,157.61,1.536,1.253,0.12,,0.449265,1527.89,,44.9265,1.52789,,,,7.85398e-5
1:0 (rep 3),3-Recover,157.977,1.556,1.233,0.12,,0.442094,1527.89,,44.2094,1.52789,,,,7.85398e-5
1:0 (rep 3),3-Recover,158.343,1.576,1.213,0.12,,0.434923,1527.89,,43.4923,1.52789,,,,7.85398e-5
1:0 (rep 3),3-Recover,158.71,1.597,1.192,0.12,,0.427393,1527.89,,42.7393,1.52789,,,,7.85398e-5
1:0 (rep 3),3-Recover,159.077,1.618,1.171,0.12,,0.419864,1527.89,,41.9864,1.52789,,,,7.85398e-5
1:0 (rep 3),3-Recover,159.443,1.637,1.152,0.12,,0.413051,1527.89,,41.3051,1.52789,,,,7.85398e-5
1:0 (rep 3),3-Recover,159.81,1.659,1.13,0.12,,0.405163,1527.89,,40.5163,1.52789,,,,7.85398e-5
1:0 (rep 3),3-Recover,160.177,1.679,1.11,0.113,,0.397992,1438.76,,39.7992,1.43876,,,,7.85398e-5
1:0 (rep 3),3-Recover,160.543,1.699,1.09,0.113,,0.390821,1438.76,,39.0821,1.43876,,,,7.85398e-5
1:0 (rep 3),3-Recover,160.91,1.72,1.069,0.106,,0.383292,1349.63,,38.3292,1.34963,,,,7.85398e-5
1:0 (rep 3),3-Recover,161.277,1.74,1.049,0.093,,0.37612,1184.11,,37.612,1.18411,,,,7.85398e-5
1:0 (rep 3),3-Recover,161.643,1.761,1.028,0.099,,0.368591,1260.51,,36.8591,1.26051,,,,7.85398e-5
1:0 (rep 3),3-Recover,162.01,1.781,1.008,0.079,,0.36142,1005.86,,36.142,1.00586,,,,7.85398e-5
1:0 (rep 3),3-Recover,162.377,1.802,0.987,0.072,,0.35389,916.733,,35.389,0.916733,,,,7.85398e-5
1:0 (rep 3),3-Recover,162.743,1.822,0.967,0.066,,0.346719,840.338,,34.6719,0.840338,,,,7.85398e-5
1:0 (rep 3),3-Recover,163.11,1.843,0.946,0.066,,0.33919,840.338,,33.919,0.840338,,,,7.85398e-5
1:0 (rep 3),3-Recover,163.477,1.863,0.926,0.072,,0.332019,916.733,,33.2019,0.916733,,,,7.85398e-5
1:0 (rep 3),3-Recover,163.843,1.884,0.905,0.072,,0.324489,916.733,,32.4489,0.916733,,,,7.85398e-5
1:0 (rep 3),3-Recover,164.21,1.904,0.885,0.072,,0.317318,916.733,,31.7318,0.916733,,,,7.85398e-5
1:0 (rep 3),3-Recover,164.577,1.925,0.864,0.066,,0.309788,840.338,,30.9788,0.840338,,,,7.85398e-5
1:0 (rep 3),3-Recover,164.943,1.945,0.844,0.066,,0.302617,840.338,,30.2617,0.840338,,,,7.85398e-5
1:0 (rep 3),3-Recover,165.31,1.965,0.824,0.066,,0.295446,840.338,,29.5446,0.840338,,,,7.85398e-5
1:0 (rep 3),3-Recover,165.677,1.986,0.803,0.066,,0.287917,840.338,,28.7917,0.840338,,,,7.85398e-5
1:0 (rep 3),3-Recover,166.043,2.006,0.783,0.072,,0.280746,916.733,,28.0746,0.916733,,,,7.85398e-5
1:0 (rep 3),3-Recover,166.41,2.027,0.762,0.072,,0.273216,916.733,,27.3216,0.916733,,,,7.85398e-5
1:0 (rep 3),3-Recover,166.777,2.047,0.742,0.066,,0.266045,840.338,,26.6045,0.840338,,,,7.85398e-5
1:0 (rep 3),3-Recover,167.143,2.068,0.721,0.066,,0.258516,840.338,,25.8516,0.840338,,,,7.85398e-5
1:0 (rep 3),3-Recover,167.51,2.088,0.701,0.066,,0.251345,840.338,,25.1345,0.840338,,,,7.85398e-5
1:0 (rep 3),3-Recover,167.877,2.109,0.68,0.066,,0.243815,840.338,,24.3815,0.840338,,,,7.85398e-5
1:0 (rep 3),3-Recover,168.243,2.129,0.66,0.059,,0.236644,751.211,,23.6644,0.751211,,,,7.85398e-5
1:0 (rep 3),3-Recover,168.61,2.15,0.639,0.066,,0.229114,840.338,,22.9114,0.840338,,,,7.85398e-5
1:0 (rep 3),3-Recover,168.977,2.171,0.618,0.066,,0.221585,840.338,,22.1585,0.840338,,,,7.85398e-5
1:0 (rep 3),3-Recover,169.343,2.191,0.598,0.066,,0.214414,840.338,,21.4414,0.840338,,,,7.85398e-5
1:0 (rep 3),3-Recover,169.71,2.211,0.578,0.059,,0.207243,751.211,,20.7243,0.751211,,,,7.85398e-5
1:0 (rep 3),3-Recover,170.077,2.232,0.557,0.025,,0.199713,318.31,,19.9713,0.31831,,,,7.85398e-5
1:0 (rep 3),3-Recover,170.443,2.252,0.537,0.038,,0.192542,483.831,,19.2542,0.483831,,,,7.85398e-5
1:0 (rep 3),3-Recover,170.81,2.272,0.517,0.045,,0.185371,572.958,,18.5371,0.572958,,,,7.85398e-5
1:0 (rep 3),3-Recover,171.177,2.294,0.495,0.045,,0.177483,572.958,,17.7483,0.572958,,,,7.85398e-5
1:0 (rep 3),3-Recover,171.543,2.313,0.476,0.052,,0.17067,662.085,,17.067,0.662085,,,,7.85398e-5
1:0 (rep 3),3-Recover,171.91,2.334,0.455,0.038,,0.163141,483.831,,16.3141,0.483831,,,,7.85398e-5
1:0 (rep 3),3-Recover,172.277,2.355,0.434,0.025,,0.155611,318.31,,15.5611,0.31831,,,,7.85398e-5
1:0 (rep 3),3-Recover,172.643,2.375,0.414,0.018,,0.14844,229.183,,14.844,0.229183,,,,7.85398e-5
1:0 (rep 3),3-Recover,173.01,2.396,0.393,0.018,,0.140911,229.183,,14.0911,0.229183,,,,7.85398e-5
1:0 (rep 3),3-Recover,173.377,2.416,0.373,0.025,,0.13374,318.31,,13.374,0.31831,,,,7.85398e-5
1:0 (rep 3),3-Recover,173.743,2.436,0.353,0.025,,0.126569,318.31,,12.6569,0.31831,,,,7.85398e-5
1:0 (rep 3),3-Recover,174.11,2.457,0.332,0.018,,0.119039,229.183,,11.9039,0.229183,,,,7.85398e-5
1:0 (rep 3),3-Recover,174.477,2.478,0.311,0.018,,0.11151,229.183,,11.151,0.229183,,,,7.85398e-5
1:0 (rep 3),3-Recover,174.843,2.497,0.292,0.011,,0.104697,140.056,,10.4697,0.140056,,,,7.85398e-5
1:0 (rep 3),3-Recover,175.21,2.519,0.27,0.018,,0.0968089,229.183,,9.68089,0.229183,,,,7.85398e-5
1:0 (rep 3),3-Recover,175.577,2.539,0.25,0.018,,0.0896379,229.183,,8.96379,0.229183,,,,7.85398e-5
1:0 (rep 3),3-Recover,175.943,2.559,0.23,0.025,,0.0824668,318.31,,8.24668,0.31831,,,,7.85398e-5
1:0 (rep 3),3-Recover,176.31,2.58,0.209,0.025,,0.0749373,318.31,,7.49373,0.31831,,,,7.85398e-5
1:0 (rep 3),3-Recover,176.677,2.6,0.189,0.011,,0.0677662,140.056,,6.77662,0.140056,,,,7.85398e-5
1:0 (rep 3),3-Recover,177.043,2.621,0.168,0.011,,0.0602366,140.056,,6.02366,0.140056,,,,7.85398e-5
1:0 (rep 3),3-Recover,177.41,2.641,0.148,0.011,,0.0530656,140.056,,5.30656,0.140056,,,,7.85398e-5
1:0 (rep 3),3-Recover,177.777,2.662,0.127,0.011,,0.045536,140.056,,4.5536,0.140056,,,,7.85398e-5
1:0 (rep 3),3-Recover,178.143,2.682,0.107,0.018,,0.038365,229.183,,3.8365,0.229183,,,,7.85398e-5
1:0 (rep 3),3-Recover,178.51,2.703,0.086,0.025,,0.0308354,318.31,,3.08354,0.31831,,,,7.85398e-5
1:0 (rep 3),3-Recover,178.877,2.723,0.066,0.018,,0.0236644,229.183,,2.36644,0.229183,,,,7.85398e-5
1:0 (rep 3),3-Recover,179.243,2.744,0.045,0.011,,0.0161348,140.056,,1.61348,0.140056,,,,7.85398e-5
1:0 (rep 3),3-Recover,179.61,2.764,0.025,0.011,,0.00896379,140.056,,0.896379,0.140056,,,,7.85398e-5
1:0 (rep 3),3-Recover,179.977,2.785,0.004,0.011,,0.00143421,140.056,,0.143421,0.140056,,,,7.85398e-5
1:0 (rep 3),3-Recover,180.11,2.789,0,0.025,,0,318.31,,0,0.31831,,,,7.85398e-5