File: data/beta_1-3-1_3.csv
SetName,Cycle,Time_S,Size_mm,Displacement_mm,Force_N,,Strain,Stress(Pascal),,%Strain,Stress(kPa),,,,Area(m^2)
Test1,1-Compress,0.000,6.482,-0,-0.004,,0,-50.9296,,0,-0.0509296,,,,7.85398e-5
Test1,1-Compress,0.367,6.436,0.046,-0.004,,0.00709658,-50.9296,,0.709658,-0.0509296,,,,7.85398e-5
Test1,1-Compress,0.733,6.389,0.093,-0.004,,0.0143474,-50.9296,,1.43474,-0.0509296,,,,7.85398e-5
Test1,1-Compress,1.100,6.341,0.141,-0.004,,0.0217525,-50.9296,,2.17525,-0.0509296,,,,7.85398e-5
Test1,1-Compress,1.467,6.293,0.189,0.003,,0.0291577,38.1972,,2.91577,0.0381972,,,,7.85398e-5
Test1,1-Compress,1.833,6.247,0.235,-0.004,,0.0362542,-50.9296,,3.62542,-0.0509296,,,,7.85398e-5
Test1,1-Compress,2.200,6.199,0.283,0.003,,0.0436594,38.1972,,4.36594,0.0381972,,,,7.85398e-5
Test1,1-Compress,2.567,6.151,0.331,-0.004,,0.0510645,-50.9296,,5.10645,-0.0509296,,,,7.85398e-5
Test1,1-Compress,2.933,6.104,0.378,-0.004,,0.0583153,-50.9296,,5.83153,-0.0509296,,,,7.85398e-5
Test1,1-Compress,3.300,6.056,0.426,-0.004,,0.0657205,-50.9296,,6.57205,-0.0509296,,,,7.85398e-5
Test1,1-Compress,3.667,6.008,0.474,-0.004,,0.0731256,-50.9296,,7.31256,-0.0509296,,,,7.85398e-5
Test1,1-Compress,4.033,5.961,0.521,0.003,,0.0803764,38.1972,,8.03764,0.0381972,,,,7.85398e-5
Test1,1-Compress,4.400,5.913,0.569,0.003,,0.0877815,38.1972,,8.77815,0.0381972,,,,7.85398e-5
Test1,1-Compress,4.767,5.865,0.617,-0.004,,0.0951867,-50.9296,,9.51867,-0.0509296,,,,7.85398e-5
Test1,1-Compress,5.133,5.818,0.664,-0.004,,0.102438,-50.9296,,10.2438,-0.0509296,,,,7.85398e-5
Test1,1-Compress,5.500,5.77,0.712,-0.004,,0.109843,-50.9296,,10.9843,-0.0509296,,,,7.85398e-5
Test1,1-Compress,5.867,5.722,0.76,-0.004,,0.117248,-50.9296,,11.7248,-0.0509296,,,,7.85398e-5
Test1,1-Compress,6.233,5.675,0.807,-0.004,,0.124499,-50.9296,,12.4499,-0.0509296,,,,7.85398e-5
Test1,1-Compress,6.600,5.627,0.855,-0.004,,0.131904,-50.9296,,13.1904,-0.0509296,,,,7.85398e-5
Test1,1-Compress,6.967,5.579,0.903,0.003,,0.139309,38.1972,,13.9309,0.0381972,,,,7.85398e-5
Test1,1-Compress,7.333,5.532,0.95,0.010,,0.14656,127.324,,14.656,0.127324,,,,7.85398e-5
Test1,1-Compress,7.700,5.485,0.997,-0.004,,0.153811,-50.9296,,15.3811,-0.0509296,,,,7.85398e-5
Test1,1-Compress,8.067,5.436,1.046,-0.004,,0.16137,-50.9296,,16.137,-0.0509296,,,,7.85398e-5
Test1,1-Compress,8.433,5.39,1.092,-0.004,,0.168467,-50.9296,,16.8467,-0.0509296,,,,7.85398e-5
Test1,1-Compress,8.800,5.342,1.14,-0.004,,0.175872,-50.9296,,17.5872,-0.0509296,,,,7.85398e-5
Test1,1-Compress,9.167,5.294,1.188,0.003,,0.183277,38.1972,,18.3277,0.0381972,,,,7.85398e-5
Test1,1-Compress,9.533,5.247,1.235,0.010,,0.190528,127.324,,19.0528,0.127324,,,,7.85398e-5
Test1,1-Compress,9.900,5.199,1.283,0.003,,0.197933,38.1972,,19.7933,0.0381972,,,,7.85398e-5
Test1,1-Compress,10.267,5.151,1.331,-0.004,,0.205338,-50.9296,,20.5338,-0.0509296,,,,7.85398e-5
Test1,1-Compress,10.633,5.104,1.378,-0.004,,0.212589,-50.9296,,21.2589,-0.0509296,,,,7.85398e-5
Test1,1-Compress,11.000,5.056,1.426,-0.004,,0.219994,-50.9296,,21.9994,-0.0509296,,,,7.85398e-5
Test1,1-Compress,11.367,5.008,1.474,-0.004,,0.227399,-50.9296,,22.7399,-0.0509296,,,,7.85398e-5
Test1,1-Compress,11.733,4.961,1.521,0.003,,0.23465,38.1972,,23.465,0.0381972,,,,7.85398e-5
Test1,1-Compress,12.100,4.913,1.569,0.010,,0.242055,127.324,,24.2055,0.127324,,,,7.85398e-5
Test1,1-Compress,12.467,4.865,1.617,0.003,,0.24946,38.1972,,24.946,0.0381972,,,,7.85398e-5
Test1,1-Compress,12.833,4.818,1.664,-0.004,,0.256711,-50.9296,,25.6711,-0.0509296,,,,7.85398e-5
Test1,1-Compress,13.200,4.77,1.712,-0.004,,0.264116,-50.9296,,26.4116,-0.0509296,,,,7.85398e-5
Test1,1-Compress,13.567,4.722,1.76,-0.004,,0.271521,-50.9296,,27.1521,-0.0509296,,,,7.85398e-5
Test1,1-Compress,13.933,4.675,1.807,-0.004,,0.278772,-50.9296,,27.8772,-0.0509296,,,,7.85398e-5
Test1,1-Compress,14.300,4.628,1.854,0.003,,0.286023,38.1972,,28.6023,0.0381972,,,,7.85398e-5
Test1,1-Compress,14.667,4.579,1.903,0.010,,0.293582,127.324,,29.3582,0.127324,,,,7.85398e-5
Test1,1-Compress,15.033,4.533,1.949,0.003,,0.300679,38.1972,,30.0679,0.0381972,,,,7.85398e-5
Test1,1-Compress,15.400,4.485,1.997,-0.004,,0.308084,-50.9296,,30.8084,-0.0509296,,,,7.85398e-5
Test1,1-Compress,15.767,4.437,2.045,-0.004,,0.315489,-50.9296,,31.5489,-0.0509296,,,,7.85398e-5
Test1,1-Compress,16.133,4.39,2.092,-0.004,,0.32274,-50.9296,,32.274,-0.0509296,,,,7.85398e-5
Test1,1-Compress,16.500,4.342,2.14,0.003,,0.330145,38.1972,,33.0145,0.0381972,,,,7.85398e-5
Test1,1-Compress,16.867,4.294,2.188,0.003,,0.33755,38.1972,,33.755,0.0381972,,,,7.85398e-5
Test1,1-Compress,17.233,4.247,2.235,0.003,,0.344801,38.1972,,34.4801,0.0381972,,,,7.85398e-5
Test1,1-Compress,17.600,4.199,2.283,0.003,,0.352206,38.1972,,35.2206,0.0381972,,,,7.85398e-5
Test1,1-Compress,17.967,4.151,2.331,-0.004,,0.359611,-50.9296,,35.9611,-0.0509296,,,,7.85398e-5
Test1,1-Compress,18.333,4.104,2.378,-0.004,,0.366862,-50.9296,,36.6862,-0.0509296,,,,7.85398e-5
Test1,1-Compress,18.700,4.056,2.426,-0.004,,0.374267,-50.9296,,37.4267,-0.0509296,,,,7.85398e-5
Test1,1-Compress,19.067,4.008,2.474,0.003,,0.381672,38.1972,,38.1672,0.0381972,,,,7.85398e-5
Test1,1-Compress,19.433,3.961,2.521,0.003,,0.388923,38.1972,,38.8923,0.0381972,,,,7.85398e-5
Test1,1-Compress,19.800,3.913,2.569,0.017,,0.396328,216.451,,39.6328,0.216451,,,,7.85398e-5
Test1,1-Compress,20.167,3.865,2.617,0.003,,0.403733,38.1972,,40.3733,0.0381972,,,,7.85398e-5
Test1,1-Compress,20.533,3.819,2.663,-0.004,,0.41083,-50.9296,,41.083,-0.0509296,,,,7.85398e-5
Test1,1-Compress,20.900,3.771,2.711,-0.004,,0.418235,-50.9296,,41.8235,-0.0509296,,,,7.85398e-5
Test1,1-Compress,21.267,3.722,2.76,0.003,,0.425795,38.1972,,42.5795,0.0381972,,,,7.85398e-5
Test1,1-Compress,21.633,3.676,2.806,0.003,,0.432891,38.1972,,43.2891,0.0381972,,,,7.85398e-5
Test1,1-Compress,22.000,3.628,2.854,0.003,,0.440296,38.1972,,44.0296,0.0381972,,,,7.85398e-5
Test1,1-Compress,22.367,3.58,2.902,0.017,,0.447701,216.451,,44.7701,0.216451,,,,7.85398e-5
Test1,1-Compress,22.733,3.533,2.949,0.017,,0.454952,216.451,,45.4952,0.216451,,,,7.85398e-5
Test1,1-Compress,23.100,3.485,2.997,0.003,,0.462357,38.1972,,46.2357,0.0381972,,,,7.85398e-5
Test1,1-Compress,23.467,3.437,3.045,0.003,,0.469762,38.1972,,46.9762,0.0381972,,,,7.85398e-5
Test1,1-Compress,23.833,3.39,3.092,0.003,,0.477013,38.1972,,47.7013,0.0381972,,,,7.85398e-5
Test1,1-Compress,24.200,3.342,3.14,0.003,,0.484418,38.1972,,48.4418,0.0381972,,,,7.85398e-5
Test1,1-Compress,24.567,3.294,3.188,0.003,,0.491824,38.1972,,49.1824,0.0381972,,,,7.85398e-5
Test1,1-Compress,24.933,3.247,3.235,0.017,,0.499074,216.451,,49.9074,0.216451,,,,7.85398e-5
Test1,1-Compress,25.300,3.199,3.283,0.030,,0.506479,381.972,,50.6479,0.381972,,,,7.85398e-5
Test1,1-Compress,25.667,3.151,3.331,0.023,,0.513885,292.845,,51.3885,0.292845,,,,7.85398e-5
Test1,1-Compress,26.033,3.105,3.377,0.037,,0.520981,471.099,,52.0981,0.471099,,,,7.85398e-5
Test1,1-Compress,26.400,3.056,3.426,0.037,,0.528541,471.099,,52.8541,0.471099,,,,7.85398e-5
Test1,1-Compress,26.767,3.008,3.474,0.030,,0.535946,381.972,,53.5946,0.381972,,,,7.85398e-5
Test1,1-Compress,27.133,2.961,3.521,0.044,,0.543197,560.226,,54.3197,0.560226,,,,7.85398e-5
Test1,1-Compress,27.500,2.914,3.568,0.044,,0.550447,560.226,,55.0447,0.560226,,,,7.85398e-5
Test1,1-Compress,27.867,2.866,3.616,0.051,,0.557853,649.352,,55.7853,0.649352,,,,7.85398e-5
Test1,1-Compress,28.233,2.819,3.663,0.044,,0.565103,560.226,,56.5103,0.560226,,,,7.85398e-5
Test1,1-Compress,28.600,2.771,3.711,0.051,,0.572508,649.352,,57.2508,0.649352,,,,7.85398e-5
Test1,1-Compress,28.967,2.723,3.759,0.051,,0.579914,649.352,,57.9914,0.649352,,,,7.85398e-5
Test1,1-Compress,29.333,2.676,3.806,0.057,,0.587164,725.747,,58.7164,0.725747,,,,7.85398e-5
Test1,1-Compress,29.700,2.628,3.854,0.051,,0.59457,649.352,,59.457,0.649352,,,,7.85398e-5
Test1,1-Recover,30.067,2.598,3.884,0.051,,0.599198,649.352,,59.9198,0.649352,,,,7.85398e-5
Test1,1-Recover,30.433,2.645,3.837,0.051,,0.591947,649.352,,59.1947,0.649352,,,,7.85398e-5
Test1,1-Recover,30.800,2.692,3.79,0.051,,0.584696,649.352,,58.4696,0.649352,,,,7.85398e-5
Test1,1-Recover,31.167,2.741,3.741,0.051,,0.577137,649.352,,57.7137,0.649352,,,,7.85398e-5
Test1,1-Recover,31.533,2.787,3.695,0.017,,0.57004,216.451,,57.004,0.216451,,,,7.85398e-5
Test1,1-Recover,31.900,2.835,3.647,0.023,,0.562635,292.845,,56.2635,0.292845,,,,7.85398e-5
Test1,1-Recover,32.267,2.884,3.598,0.023,,0.555076,292.845,,55.5076,0.292845,,,,7.85398e-5
Test1,1-Recover,32.633,2.93,3.552,0.044,,0.547979,560.226,,54.7979,0.560226,,,,7.85398e-5
Test1,1-Recover,33.000,2.978,3.504,0.023,,0.540574,292.845,,54.0574,0.292845,,,,7.85398e-5
Test1,1-Recover,33.367,3.026,3.456,0.017,,0.533169,216.451,,53.3169,0.216451,,,,7.85398e-5
Test1,1-Recover,33.733,3.073,3.409,0.010,,0.525918,127.324,,52.5918,0.127324,,,,7.85398e-5
Test1,1-Recover,34.100,3.121,3.361,0.003,,0.518513,38.1972,,51.8513,0.0381972,,,,7.85398e-5
Test1,1-Recover,34.467,3.169,3.313,0.003,,0.511108,38.1972,,51.1108,0.0381972,,,,7.85398e-5
Test1,1-Recover,34.833,3.216,3.266,0.010,,0.503857,127.324,,50.3857,0.127324,,,,7.85398e-5
Test1,1-Recover,35.200,3.264,3.218,0.023,,0.496452,292.845,,49.6452,0.292845,,,,7.85398e-5
Test1,1-Recover,35.567,3.312,3.17,0.017,,0.489047,216.451,,48.9047,0.216451,,,,7.85398e-5
Test1,1-Recover,35.933,3.359,3.123,0.010,,0.481796,127.324,,48.1796,0.127324,,,,7.85398e-5
Test1,1-Recover,36.300,3.407,3.075,0.003,,0.474391,38.1972,,47.4391,0.0381972,,,,7.85398e-5
Test1,1-Recover,36.667,3.455,3.027,0.003,,0.466985,38.1972,,46.6985,0.0381972,,,,7.85398e-5
Test1,1-Recover,37.033,3.502,2.98,0.003,,0.459735,38.1972,,45.9735,0.0381972,,,,7.85398e-5
Test1,1-Recover,37.400,3.549,2.933,0.010,,0.452484,127.324,,45.2484,0.127324,,,,7.85398e-5
Test1,1-Recover,37.767,3.598,2.884,0.010,,0.444924,127.324,,44.4924,0.127324,,,,7.85398e-5
Test1,1-Recover,38.133,3.644,2.838,-0.004,,0.437828,-50.9296,,43.7828,-0.0509296,,,,7.85398e-5
Test1,1-Recover,38.500,3.692,2.79,-0.004,,0.430423,-50.9296,,43.0423,-0.0509296,,,,7.85398e-5
Test1,1-Recover,38.867,3.741,2.741,-0.004,,0.422863,-50.9296,,42.2863,-0.0509296,,,,7.85398e-5
Test1,1-Recover,39.233,3.787,2.695,0.003,,0.415767,38.1972,,41.5767,0.0381972,,,,7.85398e-5
Test1,1-Recover,39.600,3.835,2.647,0.010,,0.408362,127.324,,40.8362,0.127324,,,,7.85398e-5
Test1,1-Recover,39.967,3.883,2.599,0.003,,0.400956,38.1972,,40.0956,0.0381972,,,,7.85398e-5
Test1,1-Recover,40.333,3.93,2.552,-0.004,,0.393706,-50.9296,,39.3706,-0.0509296,,,,7.85398e-5
Test1,1-Recover,40.700,3.978,2.504,-0.004,,0.386301,-50.9296,,38.6301,-0.0509296,,,,7.85398e-5
Test1,1-Recover,41.067,4.026,2.456,-0.004,,0.378895,-50.9296,,37.8895,-0.0509296,,,,7.85398e-5
Test1,1-Recover,41.433,4.073,2.409,-0.004,,0.371645,-50.9296,,37.1645,-0.0509296,,,,7.85398e-5
Test1,1-Recover,41.800,4.121,2.361,0.003,,0.364239,38.1972,,36.4239,0.0381972,,,,7.85398e-5
Test1,1-Recover,42.167,4.169,2.313,0.010,,0.356834,127.324,,35.6834,0.127324,,,,7.85398e-5
Test1,1-Recover,42.533,4.216,2.266,0.003,,0.349583,38.1972,,34.9583,0.0381972,,,,7.85398e-5
Test1,1-Recover,42.900,4.264,2.218,-0.004,,0.342178,-50.9296,,34.2178,-0.0509296,,,,7.85398e-5
Test1,1-Recover,43.267,4.312,2.17,-0.004,,0.334773,-50.9296,,33.4773,-0.0509296,,,,7.85398e-5
Test1,1-Recover,43.633,4.359,2.123,-0.004,,0.327522,-50.9296,,32.7522,-0.0509296,,,,7.85398e-5
Test1,1-Recover,44.000,4.406,2.076,-0.004,,0.320272,-50.9296,,32.0272,-0.0509296,,,,7.85398e-5
Test1,1-Recover,44.367,4.455,2.027,0.003,,0.312712,38.1972,,31.2712,0.0381972,,,,7.85398e-5
Test1,1-Recover,44.733,4.501,1.981,0.010,,0.305616,127.324,,30.5616,0.127324,,,,7.85398e-5
Test1,1-Recover,45.100,4.549,1.933,0.003,,0.29821,38.1972,,29.821,0.0381972,,,,7.85398e-5
Test1,1-Recover,45.467,4.598,1.884,-0.004,,0.290651,-50.9296,,29.0651,-0.0509296,,,,7.85398e-5
Test1,1-Recover,45.833,4.644,1.838,-0.004,,0.283554,-50.9296,,28.3554,-0.0509296,,,,7.85398e-5
Test1,1-Recover,46.200,4.692,1.79,-0.004,,0.276149,-50.9296,,27.6149,-0.0509296,,,,7.85398e-5
Test1,1-Recover,46.567,4.74,1.742,-0.004,,0.268744,-50.9296,,26.8744,-0.0509296,,,,7.85398e-5
Test1,1-Recover,46.933,4.787,1.695,0.003,,0.261493,38.1972,,26.1493,0.0381972,,,,7.85398e-5
Test1,1-Recover,47.300,4.835,1.647,0.010,,0.254088,127.324,,25.4088,0.127324,,,,7.85398e-5
Test1,1-Recover,47.667,4.883,1.599,0.003,,0.246683,38.1972,,24.6683,0.0381972,,,,7.85398e-5
Test1,1-Recover,48.033,4.93,1.552,-0.004,,0.239432,-50.9296,,23.9432,-0.0509296,,,,7.85398e-5
Test1,1-Recover,48.400,4.978,1.504,-0.004,,0.232027,-50.9296,,23.2027,-0.0509296,,,,7.85398e-5
Test1,1-Recover,48.767,5.026,1.456,-0.004,,0.224622,-50.9296,,22.4622,-0.0509296,,,,7.85398e-5
Test1,1-Recover,49.133,5.073,1.409,-0.004,,0.217371,-50.9296,,21.7371,-0.0509296,,,,7.85398e-5
Test1,1-Recover,49.500,5.121,1.361,0.003,,0.209966,38.1972,,20.9966,0.0381972,,,,7.85398e-5
Test1,1-Recover,49.867,5.169,1.313,0.003,,0.202561,38.1972,,20.2561,0.0381972,,,,7.85398e-5
Test1,1-Recover,50.233,5.215,1.267,0.003,,0.195464,38.1972,,19.5464,0.0381972,,,,7.85398e-5
Test1,1-Recover,50.600,5.264,1.218,-0.004,,0.187905,-50.9296,,18.7905,-0.0509296,,,,7.85398e-5
Test1,1-Recover,50.967,5.312,1.17,-0.004,,0.1805,-50.9296,,18.05,-0.0509296,,,,7.85398e-5
Test1,1-Recover,51.333,5.358,1.124,-0.004,,0.173403,-50.9296,,17.3403,-0.0509296,,,,7.85398e-5
Test1,1-Recover,51.700,5.406,1.076,0.003,,0.165998,38.1972,,16.5998,0.0381972,,,,7.85398e-5
Test1,1-Recover,52.067,5.454,1.028,0.003,,0.158593,38.1972,,15.8593,0.0381972,,,,7.85398e-5
Test1,1-Recover,52.433,5.501,0.981,-0.004,,0.151342,-50.9296,,15.1342,-0.0509296,,,,7.85398e-5
Test1,1-Recover,52.800,5.549,0.933,0.003,,0.143937,38.1972,,14.3937,0.0381972,,,,7.85398e-5
Test1,1-Recover,53.167,5.597,0.885,-0.004,,0.136532,-50.9296,,13.6532,-0.0509296,,,,7.85398e-5
Test1,1-Recover,53.533,5.644,0.838,-0.004,,0.129281,-50.9296,,12.9281,-0.0509296,,,,7.85398e-5
Test1,1-Recover,53.900,5.692,0.79,-0.004,,0.121876,-50.9296,,12.1876,-0.0509296,,,,7.85398e-5
Test1,1-Recover,54.267,5.74,0.742,0.003,,0.114471,38.1972,,11.4471,0.0381972,,,,7.85398e-5
Test1,1-Recover,54.633,5.787,0.695,0.003,,0.10722,38.1972,,10.722,0.0381972,,,,7.85398e-5
Test1,1-Recover,55.000,5.835,0.647,0.003,,0.0998149,38.1972,,9.98149,0.0381972,,,,7.85398e-5
Test1,1-Recover,55.367,5.883,0.599,-0.004,,0.0924098,-50.9296,,9.24098,-0.0509296,,,,7.85398e-5
Test1,1-Recover,55.733,5.929,0.553,-0.004,,0.0853132,-50.9296,,8.53132,-0.0509296,,,,7.85398e-5
Test1,1-Recover,56.100,5.978,0.504,-0.004,,0.0777538,-50.9296,,7.77538,-0.0509296,,,,7.85398e-5
Test1,1-Recover,56.467,6.026,0.456,-0.004,,0.0703487,-50.9296,,7.03487,-0.0509296,,,,7.85398e-5
Test1,1-Recover,56.833,6.072,0.41,0.003,,0.0632521,38.1972,,6.32521,0.0381972,,,,7.85398e-5
Test1,1-Recover,57.200,6.121,0.361,0.003,,0.0556927,38.1972,,5.56927,0.0381972,,,,7.85398e-5
Test1,1-Recover,57.567,6.168,0.314,0.010,,0.0484418,127.324,,4.84418,0.127324,,,,7.85398e-5
Test1,1-Recover,57.933,6.215,0.267,-0.004,,0.041191,-50.9296,,4.1191,-0.0509296,,,,7.85398e-5
Test1,1-Recover,58.300,6.263,0.219,-0.004,,0.0337859,-50.9296,,3.37859,-0.0509296,,,,7.85398e-5
Test1,1-Recover,58.667,6.311,0.171,-0.004,,0.0263807,-50.9296,,2.63807,-0.0509296,,,,7.85398e-5
Test1,1-Recover,59.033,6.358,0.124,-0.004,,0.0191299,-50.9296,,1.91299,-0.0509296,,,,7.85398e-5
Test1,1-Recover,59.400,6.406,0.076,-0.004,,0.0117248,-50.9296,,1.17248,-0.0509296,,,,7.85398e-5
Test1,1-Recover,59.767,6.454,0.028,0.003,,0.00431965,38.1972,,0.431965,0.0381972,,,,7.85398e-5
Test1,2-Compress,60.117,6.473,0.009,-0.004,,0.00138846,-50.9296,,0.138846,-0.0509296,,,,7.85398e-5
Test1,2-Compress,60.483,6.426,0.056,0.003,,0.00863931,38.1972,,0.863931,0.0381972,,,,7.85398e-5
Test1,2-Compress,60.850,6.378,0.104,-0.004,,0.0160444,-50.9296,,1.60444,-0.0509296,,,,7.85398e-5
Test1,2-Compress,61.217,6.33,0.152,-0.004,,0.0234496,-50.9296,,2.34496,-0.0509296,,,,7.85398e-5
Test1,2-Compress,61.583,6.284,0.198,-0.004,,0.0305461,-50.9296,,3.05461,-0.0509296,,,,7.85398e-5
Test1,2-Compress,61.950,6.235,0.247,0.003,,0.0381055,38.1972,,3.81055,0.0381972,,,,7.85398e-5
Test1,2-Compress,62.317,6.188,0.294,0.003,,0.0453564,38.1972,,4.53564,0.0381972,,,,7.85398e-5
Test1,2-Compress,62.683,6.141,0.341,0.003,,0.0526072,38.1972,,5.26072,0.0381972,,,,7.85398e-5
Test1,2-Compress,63.050,6.093,0.389,0.003,,0.0600123,38.1972,,6.00123,0.0381972,,,,7.85398e-5
Test1,2-Compress,63.417,6.045,0.437,-0.004,,0.0674175,-50.9296,,6.74175,-0.0509296,,,,7.85398e-5
Test1,2-Compress,63.783,5.998,0.484,-0.004,,0.0746683,-50.9296,,7.46683,-0.0509296,,,,7.85398e-5
Test1,2-Compress,64.150,5.95,0.532,-0.004,,0.0820734,-50.9296,,8.20734,-0.0509296,,,,7.85398e-5
Test1,2-Compress,64.517,5.902,0.58,0.003,,0.0894786,38.1972,,8.94786,0.0381972,,,,7.85398e-5
Test1,2-Compress,64.883,5.855,0.627,0.003,,0.0967294,38.1972,,9.67294,0.0381972,,,,7.85398e-5
Test1,2-Compress,65.250,5.807,0.675,0.010,,0.104135,127.324,,10.4135,0.127324,,,,7.85398e-5
Test1,2-Compress,65.617,5.759,0.723,-0.004,,0.11154,-50.9296,,11.154,-0.0509296,,,,7.85398e-5
Test1,2-Compress,65.983,5.712,0.77,-0.004,,0.11879,-50.9296,,11.879,-0.0509296,,,,7.85398e-5
Test1,2-Compress,66.350,5.664,0.818,-0.004,,0.126196,-50.9296,,12.6196,-0.0509296,,,,7.85398e-5
Test1,2-Compress,66.717,5.616,0.866,-0.004,,0.133601,-50.9296,,13.3601,-0.0509296,,,,7.85398e-5
Test1,2-Compress,67.083,5.569,0.913,0.003,,0.140852,38.1972,,14.0852,0.0381972,,,,7.85398e-5
Test1,2-Compress,67.450,5.521,0.961,0.003,,0.148257,38.1972,,14.8257,0.0381972,,,,7.85398e-5
Test1,2-Compress,67.817,5.473,1.009,-0.004,,0.155662,-50.9296,,15.5662,-0.0509296,,,,7.85398e-5
Test1,2-Compress,68.183,5.427,1.055,-0.004,,0.162758,-50.9296,,16.2758,-0.0509296,,,,7.85398e-5
Test1,2-Compress,68.550,5.379,1.103,-0.004,,0.170164,-50.9296,,17.0164,-0.0509296,,,,7.85398e-5
Test1,2-Compress,68.917,5.33,1.152,-0.004,,0.177723,-50.9296,,17.7723,-0.0509296,,,,7.85398e-5
Test1,2-Compress,69.283,5.284,1.198,-0.004,,0.18482,-50.9296,,18.482,-0.0509296,,,,7.85398e-5
Test1,2-Compress,69.650,5.236,1.246,0.003,,0.192225,38.1972,,19.2225,0.0381972,,,,7.85398e-5
Test1,2-Compress,70.017,5.188,1.294,0.010,,0.19963,127.324,,19.963,0.127324,,,,7.85398e-5
Test1,2-Compress,70.383,5.141,1.341,0.003,,0.206881,38.1972,,20.6881,0.0381972,,,,7.85398e-5
Test1,2-Compress,70.750,5.093,1.389,-0.004,,0.214286,-50.9296,,21.4286,-0.0509296,,,,7.85398e-5
Test1,2-Compress,71.117,5.045,1.437,-0.004,,0.221691,-50.9296,,22.1691,-0.0509296,,,,7.85398e-5
Test1,2-Compress,71.483,4.998,1.484,-0.004,,0.228942,-50.9296,,22.8942,-0.0509296,,,,7.85398e-5
Test1,2-Compress,71.850,4.95,1.532,-0.004,,0.236347,-50.9296,,23.6347,-0.0509296,,,,7.85398e-5
Test1,2-Compress,72.217,4.902,1.58,0.003,,0.243752,38.1972,,24.3752,0.0381972,,,,7.85398e-5
Test1,2-Compress,72.583,4.855,1.627,0.010,,0.251003,127.324,,25.1003,0.127324,,,,7.85398e-5
Test1,2-Compress,72.950,4.807,1.675,0.010,,0.258408,127.324,,25.8408,0.127324,,,,7.85398e-5
Test1,2-Compress,73.317,4.759,1.723,-0.004,,0.265813,-50.9296,,26.5813,-0.0509296,,,,7.85398e-5
Test1,2-Compress,73.683,4.712,1.77,-0.004,,0.273064,-50.9296,,27.3064,-0.0509296,,,,7.85398e-5
Test1,2-Compress,74.050,4.665,1.817,-0.004,,0.280315,-50.9296,,28.0315,-0.0509296,,,,7.85398e-5
Test1,2-Compress,74.417,4.616,1.866,0.003,,0.287874,38.1972,,28.7874,0.0381972,,,,7.85398e-5
Test1,2-Compress,74.783,4.57,1.912,0.003,,0.294971,38.1972,,29.4971,0.0381972,,,,7.85398e-5
Test1,2-Compress,75.150,4.522,1.96,0.010,,0.302376,127.324,,30.2376,0.127324,,,,7.85398e-5
Test1,2-Compress,75.517,4.473,2.009,0.003,,0.309935,38.1972,,30.9935,0.0381972,,,,7.85398e-5
Test1,2-Compress,75.883,4.427,2.055,-0.004,,0.317032,-50.9296,,31.7032,-0.0509296,,,,7.85398e-5
Test1,2-Compress,76.250,4.379,2.103,-0.004,,0.324437,-50.9296,,32.4437,-0.0509296,,,,7.85398e-5
Test1,2-Compress,76.617,4.331,2.151,-0.004,,0.331842,-50.9296,,33.1842,-0.0509296,,,,7.85398e-5
Test1,2-Compress,76.983,4.284,2.198,0.003,,0.339093,38.1972,,33.9093,0.0381972,,,,7.85398e-5
Test1,2-Compress,77.350,4.236,2.246,0.003,,0.346498,38.1972,,34.6498,0.0381972,,,,7.85398e-5
Test1,2-Compress,77.717,4.188,2.294,0.010,,0.353903,127.324,,35.3903,0.127324,,,,7.85398e-5
Test1,2-Compress,78.083,4.141,2.341,0.010,,0.361154,127.324,,36.1154,0.127324,,,,7.85398e-5
Test1,2-Compress,78.450,4.093,2.389,-0.004,,0.368559,-50.9296,,36.8559,-0.0509296,,,,7.85398e-5
Test1,2-Compress,78.817,4.045,2.437,0.003,,0.375964,38.1972,,37.5964,0.0381972,,,,7.85398e-5
Test1,2-Compress,79.183,3.998,2.484,0.003,,0.383215,38.1972,,38.3215,0.0381972,,,,7.85398e-5
Test1,2-Compress,79.550,3.95,2.532,0.003,,0.39062,38.1972,,39.062,0.0381972,,,,7.85398e-5
Test1,2-Compress,79.917,3.902,2.58,0.003,,0.398025,38.1972,,39.8025,0.0381972,,,,7.85398e-5
Test1,2-Compress,80.283,3.855,2.627,0.017,,0.405276,216.451,,40.5276,0.216451,,,,7.85398e-5
Test1,2-Compress,80.650,3.808,2.674,0.010,,0.412527,127.324,,41.2527,0.127324,,,,7.85398e-5
Test1,2-Compress,81.017,3.759,2.723,0.003,,0.420086,38.1972,,42.0086,0.0381972,,,,7.85398e-5
Test1,2-Compress,81.383,3.713,2.769,0.003,,0.427183,38.1972,,42.7183,0.0381972,,,,7.85398e-5
Test1,2-Compress,81.750,3.665,2.817,-0.004,,0.434588,-50.9296,,43.4588,-0.0509296,,,,7.85398e-5
Test1,2-Compress,82.117,3.616,2.866,0.003,,0.442147,38.1972,,44.2147,0.0381972,,,,7.85398e-5
Test1,2-Compress,82.483,3.57,2.912,0.003,,0.449244,38.1972,,44.9244,0.0381972,,,,7.85398e-5
Test1,2-Compress,82.850,3.522,2.96,0.017,,0.456649,216.451,,45.6649,0.216451,,,,7.85398e-5
Test1,2-Compress,83.217,3.474,3.008,0.010,,0.464054,127.324,,46.4054,0.127324,,,,7.85398e-5
Test1,2-Compress,83.583,3.427,3.055,0.003,,0.471305,38.1972,,47.1305,0.0381972,,,,7.85398e-5
Test1,2-Compress,83.950,3.379,3.103,0.010,,0.47871,127.324,,47.871,0.127324,,,,7.85398e-5
Test1,2-Compress,84.317,3.331,3.151,0.003,,0.486115,38.1972,,48.6115,0.0381972,,,,7.85398e-5
Test1,2-Compress,84.683,3.284,3.198,0.003,,0.493366,38.1972,,49.3366,0.0381972,,,,7.85398e-5
Test1,2-Compress,85.050,3.236,3.246,0.003,,0.500771,38.1972,,50.0771,0.0381972,,,,7.85398e-5
Test1,2-Compress,85.417,3.188,3.294,0.030,,0.508176,381.972,,50.8176,0.381972,,,,7.85398e-5
Test1,2-Compress,85.783,3.141,3.341,0.037,,0.515427,471.099,,51.5427,0.471099,,,,7.85398e-5
Test1,2-Compress,86.150,3.093,3.389,0.030,,0.522832,381.972,,52.2832,0.381972,,,,7.85398e-5
Test1,2-Compress,86.517,3.045,3.437,0.037,,0.530238,471.099,,53.0238,0.471099,,,,7.85398e-5
Test1,2-Compress,86.883,2.998,3.484,0.023,,0.537488,292.845,,53.7488,0.292845,,,,7.85398e-5
Test1,2-Compress,87.250,2.951,3.531,0.051,,0.544739,649.352,,54.4739,0.649352,,,,7.85398e-5
Test1,2-Compress,87.617,2.902,3.58,0.051,,0.552299,649.352,,55.2299,0.649352,,,,7.85398e-5
Test1,2-Compress,87.983,2.856,3.626,0.051,,0.559395,649.352,,55.9395,0.649352,,,,7.85398e-5
Test1,2-Compress,88.350,2.808,3.674,0.051,,0.5668,649.352,,56.68,0.649352,,,,7.85398e-5
Test1,2-Compress,88.717,2.76,3.722,0.051,,0.574205,649.352,,57.4205,0.649352,,,,7.85398e-5
Test1,2-Compress,89.083,2.713,3.769,0.051,,0.581456,649.352,,58.1456,0.649352,,,,7.85398e-5
Test1,2-Compress,89.450,2.665,3.817,0.051,,0.588861,649.352,,58.8861,0.649352,,,,7.85398e-5
Test1,2-Compress,89.817,2.617,3.865,0.051,,0.596267,649.352,,59.6267,0.649352,,,,7.85398e-5
Test1,2-Recover,90.170,2.606,3.876,0.051,,0.597964,649.352,,59.7964,0.649352,,,,7.85398e-5
Test1,2-Recover,90.537,2.654,3.828,0.051,,0.590558,649.352,,59.0558,0.649352,,,,7.85398e-5
Test1,2-Recover,90.903,2.701,3.781,0.051,,0.583308,649.352,,58.3308,0.649352,,,,7.85398e-5
Test1,2-Recover,91.270,2.749,3.733,0.051,,0.575902,649.352,,57.5902,0.649352,,,,7.85398e-5
Test1,2-Recover,91.637,2.797,3.685,0.051,,0.568497,649.352,,56.8497,0.649352,,,,7.85398e-5
Test1,2-Recover,92.003,2.844,3.638,0.037,,0.561247,471.099,,56.1247,0.471099,,,,7.85398e-5
Test1,2-Recover,92.370,2.891,3.591,0.023,,0.553996,292.845,,55.3996,0.292845,,,,7.85398e-5
Test1,2-Recover,92.737,2.94,3.542,0.030,,0.546436,381.972,,54.6436,0.381972,,,,7.85398e-5
Test1,2-Recover,93.103,2.986,3.496,0.030,,0.53934,381.972,,53.934,0.381972,,,,7.85398e-5
Test1,2-Recover,93.470,3.034,3.448,0.030,,0.531935,381.972,,53.1935,0.381972,,,,7.85398e-5
Test1,2-Recover,93.837,3.083,3.399,0.017,,0.524375,216.451,,52.4375,0.216451,,,,7.85398e-5
Test1,2-Recover,94.203,3.129,3.353,0.010,,0.517279,127.324,,51.7279,0.127324,,,,7.85398e-5
Test1,2-Recover,94.570,3.177,3.305,0.003,,0.509873,38.1972,,50.9873,0.0381972,,,,7.85398e-5
Test1,2-Recover,94.937,3.225,3.257,0.003,,0.502468,38.1972,,50.2468,0.0381972,,,,7.85398e-5
Test1,2-Recover,95.303,3.272,3.21,0.010,,0.495218,127.324,,49.5218,0.127324,,,,7.85398e-5
Test1,2-Recover,95.670,3.32,3.162,0.023,,0.487812,292.845,,48.7812,0.292845,,,,7.85398e-5
Test1,2-Recover,96.037,3.368,3.114,0.003,,0.480407,38.1972,,48.0407,0.0381972,,,,7.85398e-5
Test1,2-Recover,96.403,3.415,3.067,0.010,,0.473156,127.324,,47.3156,0.127324,,,,7.85398e-5
Test1,2-Recover,96.770,3.463,3.019,0.003,,0.465751,38.1972,,46.5751,0.0381972,,,,7.85398e-5
Test1,2-Recover,97.137,3.511,2.971,0.003,,0.458346,38.1972,,45.8346,0.0381972,,,,7.85398e-5
Test1,2-Recover,97.503,3.558,2.924,0.003,,0.451095,38.1972,,45.1095,0.0381972,,,,7.85398e-5
Test1,2-Recover,97.870,3.606,2.876,0.010,,0.44369,127.324,,44.369,0.127324,,,,7.85398e-5
Test1,2-Recover,98.237,3.654,2.828,0.003,,0.436285,38.1972,,43.6285,0.0381972,,,,7.85398e-5
Test1,2-Recover,98.603,3.7,2.782,0.003,,0.429189,38.1972,,42.9189,0.0381972,,,,7.85398e-5
Test1,2-Recover,98.970,3.748,2.734,-0.004,,0.421783,-50.9296,,42.1783,-0.0509296,,,,7.85398e-5
Test1,2-Recover,99.337,3.797,2.685,0.003,,0.414224,38.1972,,41.4224,0.0381972,,,,7.85398e-5
Test1,2-Recover,99.703,3.843,2.639,0.003,,0.407127,38.1972,,40.7127,0.0381972,,,,7.85398e-5
Test1,2-Recover,100.070,3.891,2.591,0.010,,0.399722,127.324,,39.9722,0.127324,,,,7.85398e-5
Test1,2-Recover,100.437,3.939,2.543,0.010,,0.392317,127.324,,39.2317,0.127324,,,,7.85398e-5
Test1,2-Recover,100.803,3.986,2.496,0.003,,0.385066,38.1972,,38.5066,0.0381972,,,,7.85398e-5
Test1,2-Recover,101.170,4.034,2.448,-0.004,,0.377661,-50.9296,,37.7661,-0.0509296,,,,7.85398e-5
Test1,2-Recover,101.537,4.082,2.4,-0.004,,0.370256,-50.9296,,37.0256,-0.0509296,,,,7.85398e-5
Test1,2-Recover,101.903,4.129,2.353,-0.004,,0.363005,-50.9296,,36.3005,-0.0509296,,,,7.85398e-5
Test1,2-Recover,102.270,4.177,2.305,0.003,,0.3556,38.1972,,35.56,0.0381972,,,,7.85398e-5
Test1,2-Recover,102.637,4.225,2.257,0.003,,0.348195,38.1972,,34.8195,0.0381972,,,,7.85398e-5
Test1,2-Recover,103.003,4.272,2.21,0.010,,0.340944,127.324,,34.0944,0.127324,,,,7.85398e-5
Test1,2-Recover,103.370,4.32,2.162,0.003,,0.333539,38.1972,,33.3539,0.0381972,,,,7.85398e-5
Test1,2-Recover,103.737,4.368,2.114,-0.004,,0.326134,-50.9296,,32.6134,-0.0509296,,,,7.85398e-5
Test1,2-Recover,104.103,4.415,2.067,-0.004,,0.318883,-50.9296,,31.8883,-0.0509296,,,,7.85398e-5
Test1,2-Recover,104.470,4.463,2.019,-0.004,,0.311478,-50.9296,,31.1478,-0.0509296,,,,7.85398e-5
Test1,2-Recover,104.837,4.511,1.971,0.003,,0.304073,38.1972,,30.4073,0.0381972,,,,7.85398e-5
Test1,2-Recover,105.203,4.557,1.925,0.003,,0.296976,38.1972,,29.6976,0.0381972,,,,7.85398e-5
Test1,2-Recover,105.570,4.605,1.877,0.003,,0.289571,38.1972,,28.9571,0.0381972,,,,7.85398e-5
Test1,2-Recover,105.937,4.653,1.829,-0.004,,0.282166,-50.9296,,28.2166,-0.0509296,,,,7.85398e-5
Test1,2-Recover,106.303,4.7,1.782,-0.004,,0.274915,-50.9296,,27.4915,-0.0509296,,,,7.85398e-5
Test1,2-Recover,106.670,4.748,1.734,-0.004,,0.26751,-50.9296,,26.751,-0.0509296,,,,7.85398e-5
Test1,2-Recover,107.037,4.796,1.686,-0.004,,0.260105,-50.9296,,26.0105,-0.0509296,,,,7.85398e-5
Test1,2-Recover,107.403,4.843,1.639,0.003,,0.252854,38.1972,,25.2854,0.0381972,,,,7.85398e-5
Test1,2-Recover,107.770,4.891,1.591,0.010,,0.245449,127.324,,24.5449,0.127324,,,,7.85398e-5
Test1,2-Recover,108.137,4.939,1.543,0.003,,0.238044,38.1972,,23.8044,0.0381972,,,,7.85398e-5
Test1,2-Recover,108.503,4.986,1.496,-0.004,,0.230793,-50.9296,,23.0793,-0.0509296,,,,7.85398e-5
Test1,2-Recover,108.870,5.034,1.448,-0.004,,0.223388,-50.9296,,22.3388,-0.0509296,,,,7.85398e-5
Test1,2-Recover,109.237,5.082,1.4,-0.004,,0.215983,-50.9296,,21.5983,-0.0509296,,,,7.85398e-5
Test1,2-Recover,109.603,5.129,1.353,-0.004,,0.208732,-50.9296,,20.8732,-0.0509296,,,,7.85398e-5
Test1,2-Recover,109.970,5.177,1.305,0.003,,0.201327,38.1972,,20.1327,0.0381972,,,,7.85398e-5
Test1,2-Recover,110.337,5.225,1.257,0.003,,0.193922,38.1972,,19.3922,0.0381972,,,,7.85398e-5
Test1,2-Recover,110.703,5.271,1.211,0.003,,0.186825,38.1972,,18.6825,0.0381972,,,,7.85398e-5
Test1,2-Recover,111.070,5.32,1.162,-0.004,,0.179266,-50.9296,,17.9266,-0.0509296,,,,7.85398e-5
Test1,2-Recover,111.437,5.368,1.114,-0.004,,0.171861,-50.9296,,17.1861,-0.0509296,,,,7.85398e-5
Test1,2-Recover,111.803,5.414,1.068,-0.004,,0.164764,-50.9296,,16.4764,-0.0509296,,,,7.85398e-5
Test1,2-Recover,112.170,5.462,1.02,-0.004,,0.157359,-50.9296,,15.7359,-0.0509296,,,,7.85398e-5
Test1,2-Recover,112.537,5.51,0.972,0.003,,0.149954,38.1972,,14.9954,0.0381972,,,,7.85398e-5
Test1,2-Recover,112.903,5.557,0.925,0.010,,0.142703,127.324,,14.2703,0.127324,,,,7.85398e-5
Test1,2-Recover,113.270,5.605,0.877,0.003,,0.135298,38.1972,,13.5298,0.0381972,,,,7.85398e-5
Test1,2-Recover,113.637,5.653,0.829,-0.004,,0.127893,-50.9296,,12.7893,-0.0509296,,,,7.85398e-5
Test1,2-Recover,114.003,5.7,0.782,-0.004,,0.120642,-50.9296,,12.0642,-0.0509296,,,,7.85398e-5
Test1,2-Recover,114.370,5.748,0.734,-0.004,,0.113237,-50.9296,,11.3237,-0.0509296,,,,7.85398e-5
Test1,2-Recover,114.737,5.796,0.686,-0.004,,0.105832,-50.9296,,10.5832,-0.0509296,,,,7.85398e-5
Test1,2-Recover,115.103,5.843,0.639,0.003,,0.0985807,38.1972,,9.85807,0.0381972,,,,7.85398e-5
Test1,2-Recover,115.470,5.891,0.591,0.003,,0.0911756,38.1972,,9.11756,0.0381972,,,,7.85398e-5
Test1,2-Recover,115.837,5.939,0.543,-0.004,,0.0837704,-50.9296,,8.37704,-0.0509296,,,,7.85398e-5
Test1,2-Recover,116.203,5.986,0.496,-0.004,,0.0765196,-50.9296,,7.65196,-0.0509296,,,,7.85398e-5
Test1,2-Recover,116.570,6.034,0.448,-0.004,,0.0691145,-50.9296,,6.91145,-0.0509296,,,,7.85398e-5
Test1,2-Recover,116.937,6.082,0.4,-0.004,,0.0617093,-50.9296,,6.17093,-0.0509296,,,,7.85398e-5
Test1,2-Recover,117.303,6.128,0.354,0.003,,0.0546128,38.1972,,5.46128,0.0381972,,,,7.85398e-5
Test1,2-Recover,117.670,6.177,0.305,0.003,,0.0470534,38.1972,,4.70534,0.0381972,,,,7.85398e-5
Test1,2-Recover,118.037,6.225,0.257,0.003,,0.0396483,38.1972,,3.96483,0.0381972,,,,7.85398e-5
Test1,2-Recover,118.403,6.271,0.211,-0.004,,0.0325517,-50.9296,,3.25517,-0.0509296,,,,7.85398e-5
Test1,2-Recover,118.770,6.32,0.162,-0.004,,0.0249923,-50.9296,,2.49923,-0.0509296,,,,7.85398e-5
Test1,2-Recover,119.137,6.367,0.115,-0.004,,0.0177414,-50.9296,,1.77414,-0.0509296,,,,7.85398e-5
Test1,2-Recover,119.503,6.414,0.068,-0.004,,0.0104906,-50.9296,,1.04906,-0.0509296,,,,7.85398e-5
Test1,2-Recover,119.870,6.462,0.02,-0.004,,0.00308547,-50.9296,,0.308547,-0.0509296,,,,7.85398e-5
Test1,3-Compress,120.213,6.466,0.016,0.003,,0.00246837,38.1972,,0.246837,0.0381972,,,,7.85398e-5
Test1,3-Compress,120.580,6.419,0.063,0.003,,0.00971922,38.1972,,0.971922,0.0381972,,,,7.85398e-5
Test1,3-Compress,120.947,6.37,0.112,0.003,,0.0172786,38.1972,,1.72786,0.0381972,,,,7.85398e-5
Test1,3-Compress,121.313,6.324,0.158,-0.004,,0.0243752,-50.9296,,2.43752,-0.0509296,,,,7.85398e-5
Test1,3-Compress,121.680,6.276,0.206,-0.004,,0.0317803,-50.9296,,3.17803,-0.0509296,,,,7.85398e-5
Test1,3-Compress,122.047,6.228,0.254,-0.004,,0.0391854,-50.9296,,3.91854,-0.0509296,,,,7.85398e-5
Test1,3-Compress,122.413,6.181,0.301,-0.004,,0.0464363,-50.9296,,4.64363,-0.0509296,,,,7.85398e-5
Test1,3-Compress,122.780,6.133,0.349,-0.004,,0.0538414,-50.9296,,5.38414,-0.0509296,,,,7.85398e-5
Test1,3-Compress,123.147,6.085,0.397,0.010,,0.0612465,127.324,,6.12465,0.127324,,,,7.85398e-5
Test1,3-Compress,123.513,6.038,0.444,0.010,,0.0684974,127.324,,6.84974,0.127324,,,,7.85398e-5
Test1,3-Compress,123.880,5.99,0.492,-0.004,,0.0759025,-50.9296,,7.59025,-0.0509296,,,,7.85398e-5
Test1,3-Compress,124.247,5.942,0.54,-0.004,,0.0833076,-50.9296,,8.33076,-0.0509296,,,,7.85398e-5
Test1,3-Compress,124.613,5.895,0.587,-0.004,,0.0905585,-50.9296,,9.05585,-0.0509296,,,,7.85398e-5
Test1,3-Compress,124.980,5.847,0.635,-0.004,,0.0979636,-50.9296,,9.79636,-0.0509296,,,,7.85398e-5
Test1,3-Compress,125.347,5.799,0.683,0.003,,0.105369,38.1972,,10.5369,0.0381972,,,,7.85398e-5
Test1,3-Compress,125.713,5.752,0.73,0.003,,0.11262,38.1972,,11.262,0.0381972,,,,7.85398e-5
Test1,3-Compress,126.080,5.704,0.778,0.003,,0.120025,38.1972,,12.0025,0.0381972,,,,7.85398e-5
Test1,3-Compress,126.447,5.656,0.826,-0.004,,0.12743,-50.9296,,12.743,-0.0509296,,,,7.85398e-5
Test1,3-Compress,126.813,5.61,0.872,-0.004,,0.134526,-50.9296,,13.4526,-0.0509296,,,,7.85398e-5
Test1,3-Compress,127.180,5.561,0.921,-0.004,,0.142086,-50.9296,,14.2086,-0.0509296,,,,7.85398e-5
Test1,3-Compress,127.547,5.513,0.969,0.003,,0.149491,38.1972,,14.9491,0.0381972,,,,7.85398e-5
Test1,3-Compress,127.913,5.467,1.015,0.003,,0.156587,38.1972,,15.6587,0.0381972,,,,7.85398e-5
Test1,3-Compress,128.280,5.419,1.063,0.003,,0.163993,38.1972,,16.3993,0.0381972,,,,7.85398e-5
Test1,3-Compress,128.647,5.371,1.111,-0.004,,0.171398,-50.9296,,17.1398,-0.0509296,,,,7.85398e-5
Test1,3-Compress,129.013,5.324,1.158,-0.004,,0.178649,-50.9296,,17.8649,-0.0509296,,,,7.85398e-5
Test1,3-Compress,129.380,5.276,1.206,-0.004,,0.186054,-50.9296,,18.6054,-0.0509296,,,,7.85398e-5
Test1,3-Compress,129.747,5.228,1.254,-0.004,,0.193459,-50.9296,,19.3459,-0.0509296,,,,7.85398e-5
Test1,3-Compress,130.113,5.181,1.301,0.003,,0.20071,38.1972,,20.071,0.0381972,,,,7.85398e-5
Test1,3-Compress,130.480,5.133,1.349,0.010,,0.208115,127.324,,20.8115,0.127324,,,,7.85398e-5
Test1,3-Compress,130.847,5.085,1.397,0.010,,0.21552,127.324,,21.552,0.127324,,,,7.85398e-5
Test1,3-Compress,131.213,5.038,1.444,0.003,,0.222771,38.1972,,22.2771,0.0381972,,,,7.85398e-5
Test1,3-Compress,131.580,4.99,1.492,-0.004,,0.230176,-50.9296,,23.0176,-0.0509296,,,,7.85398e-5
Test1,3-Compress,131.947,4.942,1.54,-0.004,,0.237581,-50.9296,,23.7581,-0.0509296,,,,7.85398e-5
Test1,3-Compress,132.313,4.896,1.586,-0.004,,0.244678,-50.9296,,24.4678,-0.0509296,,,,7.85398e-5
Test1,3-Compress,132.680,4.847,1.635,0.003,,0.252237,38.1972,,25.2237,0.0381972,,,,7.85398e-5
Test1,3-Compress,133.047,4.799,1.683,0.010,,0.259642,127.324,,25.9642,0.127324,,,,7.85398e-5
Test1,3-Compress,133.413,4.753,1.729,0.003,,0.266739,38.1972,,26.6739,0.0381972,,,,7.85398e-5
Test1,3-Compress,133.780,4.704,1.778,-0.004,,0.274298,-50.9296,,27.4298,-0.0509296,,,,7.85398e-5
Test1,3-Compress,134.147,4.657,1.825,-0.004,,0.281549,-50.9296,,28.1549,-0.0509296,,,,7.85398e-5
Test1,3-Compress,134.513,4.61,1.872,-0.004,,0.2888,-50.9296,,28.88,-0.0509296,,,,7.85398e-5
Test1,3-Compress,134.880,4.562,1.92,-0.004,,0.296205,-50.9296,,29.6205,-0.0509296,,,,7.85398e-5
Test1,3-Compress,135.247,4.514,1.968,0.003,,0.30361,38.1972,,30.361,0.0381972,,,,7.85398e-5
Test1,3-Compress,135.613,4.467,2.015,0.010,,0.310861,127.324,,31.0861,0.127324,,,,7.85398e-5
Test1,3-Compress,135.980,4.419,2.063,0.003,,0.318266,38.1972,,31.8266,0.0381972,,,,7.85398e-5
Test1,3-Compress,136.347,4.371,2.111,-0.004,,0.325671,-50.9296,,32.5671,-0.0509296,,,,7.85398e-5
Test1,3-Compress,136.713,4.324,2.158,-0.004,,0.332922,-50.9296,,33.2922,-0.0509296,,,,7.85398e-5
Test1,3-Compress,137.080,4.276,2.206,-0.004,,0.340327,-50.9296,,34.0327,-0.0509296,,,,7.85398e-5
Test1,3-Compress,137.447,4.228,2.254,-0.004,,0.347732,-50.9296,,34.7732,-0.0509296,,,,7.85398e-5
Test1,3-Compress,137.813,4.181,2.301,0.003,,0.354983,38.1972,,35.4983,0.0381972,,,,7.85398e-5
Test1,3-Compress,138.180,4.133,2.349,0.010,,0.362388,127.324,,36.2388,0.127324,,,,7.85398e-5
Test1,3-Compress,138.547,4.085,2.397,0.010,,0.369793,127.324,,36.9793,0.127324,,,,7.85398e-5
Test1,3-Compress,138.913,4.039,2.443,-0.004,,0.37689,-50.9296,,37.689,-0.0509296,,,,7.85398e-5
Test1,3-Compress,139.280,3.99,2.492,-0.004,,0.384449,-50.9296,,38.4449,-0.0509296,,,,7.85398e-5
Test1,3-Compress,139.647,3.943,2.539,0.003,,0.3917,38.1972,,39.17,0.0381972,,,,7.85398e-5
Test1,3-Compress,140.013,3.896,2.586,-0.004,,0.398951,-50.9296,,39.8951,-0.0509296,,,,7.85398e-5
Test1,3-Compress,140.380,3.847,2.635,0.003,,0.40651,38.1972,,40.651,0.0381972,,,,7.85398e-5
Test1,3-Compress,140.747,3.8,2.682,0.010,,0.413761,127.324,,41.3761,0.127324,,,,7.85398e-5
Test1,3-Compress,141.113,3.753,2.729,0.017,,0.421012,216.451,,42.1012,0.216451,,,,7.85398e-5
Test1,3-Compress,141.480,3.705,2.777,0.003,,0.428417,38.1972,,42.8417,0.0381972,,,,7.85398e-5
Test1,3-Compress,141.847,3.657,2.825,0.003,,0.435822,38.1972,,43.5822,0.0381972,,,,7.85398e-5
Test1,3-Compress,142.213,3.61,2.872,0.003,,0.443073,38.1972,,44.3073,0.0381972,,,,7.85398e-5
Test1,3-Compress,142.580,3.562,2.92,0.003,,0.450478,38.1972,,45.0478,0.0381972,,,,7.85398e-5
Test1,3-Compress,142.947,3.514,2.968,0.003,,0.457883,38.1972,,45.7883,0.0381972,,,,7.85398e-5
Test1,3-Compress,143.313,3.467,3.015,0.010,,0.465134,127.324,,46.5134,0.127324,,,,7.85398e-5
Test1,3-Compress,143.680,3.419,3.063,0.017,,0.472539,216.451,,47.2539,0.216451,,,,7.85398e-5
Test1,3-Compress,144.047,3.371,3.111,0.017,,0.479944,216.451,,47.9944,0.216451,,,,7.85398e-5
Test1,3-Compress,144.413,3.324,3.158,0.010,,0.487195,127.324,,48.7195,0.127324,,,,7.85398e-5
Test1,3-Compress,144.780,3.276,3.206,0.003,,0.4946,38.1972,,49.46,0.0381972,,,,7.85398e-5
Test1,3-Compress,145.147,3.228,3.254,0.003,,0.502006,38.1972,,50.2006,0.0381972,,,,7.85398e-5
Test1,3-Compress,145.513,3.182,3.3,0.023,,0.509102,292.845,,50.9102,0.292845,,,,7.85398e-5
Test1,3-Compress,145.880,3.133,3.349,0.030,,0.516662,381.972,,51.6662,0.381972,,,,7.85398e-5
Test1,3-Compress,146.247,3.086,3.396,0.030,,0.523912,381.972,,52.3912,0.381972,,,,7.85398e-5
Test1,3-Compress,146.613,3.039,3.443,0.037,,0.531163,471.099,,53.1163,0.471099,,,,7.85398e-5
Test1,3-Compress,146.980,2.991,3.491,0.044,,0.538568,560.226,,53.8568,0.560226,,,,7.85398e-5
Test1,3-Compress,147.347,2.943,3.539,0.044,,0.545973,560.226,,54.5973,0.560226,,,,7.85398e-5
Test1,3-Compress,147.713,2.896,3.586,0.051,,0.553224,649.352,,55.3224,0.649352,,,,7.85398e-5
Test1,3-Compress,148.080,2.848,3.634,0.051,,0.560629,649.352,,56.0629,0.649352,,,,7.85398e-5
Test1,3-Compress,148.447,2.8,3.682,0.051,,0.568035,649.352,,56.8035,0.649352,,,,7.85398e-5
Test1,3-Compress,148.813,2.753,3.729,0.051,,0.575285,649.352,,57.5285,0.649352,,,,7.85398e-5
Test1,3-Compress,149.180,2.705,3.777,0.051,,0.582691,649.352,,58.2691,0.649352,,,,7.85398e-5
Test1,3-Compress,149.547,2.657,3.825,0.051,,0.590096,649.352,,59.0096,0.649352,,,,7.85398e-5
Test1,3-Compress,149.913,2.61,3.872,0.051,,0.597346,649.352,,59.7346,0.649352,,,,7.85398e-5
Test1,3-Recover,150.267,2.614,3.868,0.051,,0.596729,649.352,,59.6729,0.649352,,,,7.85398e-5
Test1,3-Recover,150.633,2.66,3.822,0.051,,0.589633,649.352,,58.9633,0.649352,,,,7.85398e-5
Test1,3-Recover,151.000,2.708,3.774,0.051,,0.582228,649.352,,58.2228,0.649352,,,,7.85398e-5
Test1,3-Recover,151.367,2.756,3.726,0.051,,0.574823,649.352,,57.4823,0.649352,,,,7.85398e-5
Test1,3-Recover,151.733,2.803,3.679,0.044,,0.567572,560.226,,56.7572,0.560226,,,,7.85398e-5
Test1,3-Recover,152.100,2.852,3.63,0.037,,0.560012,471.099,,56.0012,0.471099,,,,7.85398e-5
Test1,3-Recover,152.467,2.899,3.583,0.030,,0.552761,381.972,,55.2761,0.381972,,,,7.85398e-5
Test1,3-Recover,152.833,2.946,3.536,0.023,,0.545511,292.845,,54.5511,0.292845,,,,7.85398e-5
Test1,3-Recover,153.200,2.994,3.488,0.003,,0.538106,38.1972,,53.8106,0.0381972,,,,7.85398e-5
Test1,3-Recover,153.567,3.042,3.44,0.023,,0.5307,292.845,,53.07,0.292845,,,,7.85398e-5
Test1,3-Recover,153.933,3.089,3.393,0.030,,0.52345,381.972,,52.345,0.381972,,,,7.85398e-5
Test1,3-Recover,154.300,3.137,3.345,0.023,,0.516044,292.845,,51.6044,0.292845,,,,7.85398e-5
Test1,3-Recover,154.667,3.185,3.297,0.010,,0.508639,127.324,,50.8639,0.127324,,,,7.85398e-5
Test1,3-Recover,155.033,3.232,3.25,0.003,,0.501388,38.1972,,50.1388,0.0381972,,,,7.85398e-5
Test1,3-Recover,155.400,3.28,3.202,0.003,,0.493983,38.1972,,49.3983,0.0381972,,,,7.85398e-5
Test1,3-Recover,155.767,3.328,3.154,0.010,,0.486578,127.324,,48.6578,0.127324,,,,7.85398e-5
Test1,3-Recover,156.133,3.375,3.107,0.023,,0.479327,292.845,,47.9327,0.292845,,,,7.85398e-5
Test1,3-Recover,156.500,3.423,3.059,0.003,,0.471922,38.1972,,47.1922,0.0381972,,,,7.85398e-5
Test1,3-Recover,156.867,3.471,3.011,0.010,,0.464517,127.324,,46.4517,0.127324,,,,7.85398e-5
Test1,3-Recover,157.233,3.517,2.965,0.003,,0.457421,38.1972,,45.7421,0.0381972,,,,7.85398e-5
Test1,3-Recover,157.600,3.566,2.916,0.003,,0.449861,38.1972,,44.9861,0.0381972,,,,7.85398e-5
Test1,3-Recover,157.967,3.614,2.868,0.003,,0.442456,38.1972,,44.2456,0.0381972,,,,7.85398e-5
Test1,3-Recover,158.333,3.66,2.822,0.010,,0.435359,127.324,,43.5359,0.127324,,,,7.85398e-5
Test1,3-Recover,158.700,3.708,2.774,0.010,,0.427954,127.324,,42.7954,0.127324,,,,7.85398e-5
Test1,3-Recover,159.067,3.756,2.726,-0.004,,0.420549,-50.9296,,42.0549,-0.0509296,,,,7.85398e-5
Test1,3-Recover,159.433,3.803,2.679,-0.004,,0.413298,-50.9296,,41.3298,-0.0509296,,,,7.85398e-5
Test1,3-Recover,159.800,3.851,2.631,-0.004,,0.405893,-50.9296,,40.5893,-0.0509296,,,,7.85398e-5
Test1,3-Recover,160.167,3.899,2.583,-0.004,,0.398488,-50.9296,,39.8488,-0.0509296,,,,7.85398e-5
Test1,3-Recover,160.533,3.946,2.536,0.003,,0.391237,38.1972,,39.1237,0.0381972,,,,7.85398e-5
Test1,3-Recover,160.900,3.994,2.488,0.010,,0.383832,127.324,,38.3832,0.127324,,,,7.85398e-5
Test1,3-Recover,161.267,4.042,2.44,0.003,,0.376427,38.1972,,37.6427,0.0381972,,,,7.85398e-5
Test1,3-Recover,161.633,4.089,2.393,-0.004,,0.369176,-50.9296,,36.9176,-0.0509296,,,,7.85398e-5
Test1,3-Recover,162.000,4.137,2.345,-0.004,,0.361771,-50.9296,,36.1771,-0.0509296,,,,7.85398e-5
Test1,3-Recover,162.367,4.185,2.297,-0.004,,0.354366,-50.9296,,35.4366,-0.0509296,,,,7.85398e-5
Test1,3-Recover,162.733,4.232,2.25,-0.004,,0.347115,-50.9296,,34.7115,-0.0509296,,,,7.85398e-5
Test1,3-Recover,163.100,4.28,2.202,0.003,,0.33971,38.1972,,33.971,0.0381972,,,,7.85398e-5
Test1,3-Recover,163.467,4.328,2.154,0.010,,0.332305,127.324,,33.2305,0.127324,,,,7.85398e-5
Test1,3-Recover,163.833,4.374,2.108,0.010,,0.325208,127.324,,32.5208,0.127324,,,,7.85398e-5
Test1,3-Recover,164.200,4.422,2.06,-0.004,,0.317803,-50.9296,,31.7803,-0.0509296,,,,7.85398e-5
Test1,3-Recover,164.567,4.471,2.011,-0.004,,0.310244,-50.9296,,31.0244,-0.0509296,,,,7.85398e-5
Test1,3-Recover,164.933,4.517,1.965,-0.004,,0.303147,-50.9296,,30.3147,-0.0509296,,,,7.85398e-5
Test1,3-Recover,165.300,4.565,1.917,0.003,,0.295742,38.1972,,29.5742,0.0381972,,,,7.85398e-5
Test1,3-Recover,165.667,4.613,1.869,0.010,,0.288337,127.324,,28.8337,0.127324,,,,7.85398e-5
Test1,3-Recover,166.033,4.66,1.822,0.017,,0.281086,216.451,,28.1086,0.216451,,,,7.85398e-5
Test1,3-Recover,166.400,4.708,1.774,0.003,,0.273681,38.1972,,27.3681,0.0381972,,,,7.85398e-5
Test1,3-Recover,166.767,4.756,1.726,-0.004,,0.266276,-50.9296,,26.6276,-0.0509296,,,,7.85398e-5
Test1,3-Recover,167.133,4.803,1.679,-0.004,,0.259025,-50.9296,,25.9025,-0.0509296,,,,7.85398e-5
Test1,3-Recover,167.500,4.851,1.631,-0.004,,0.25162,-50.9296,,25.162,-0.0509296,,,,7.85398e-5
Test1,3-Recover,167.867,4.899,1.583,0.003,,0.244215,38.1972,,24.4215,0.0381972,,,,7.85398e-5
Test1,3-Recover,168.233,4.946,1.536,0.003,,0.236964,38.1972,,23.6964,0.0381972,,,,7.85398e-5
Test1,3-Recover,168.600,4.994,1.488,0.010,,0.229559,127.324,,22.9559,0.127324,,,,7.85398e-5
Test1,3-Recover,168.967,5.042,1.44,-0.004,,0.222154,-50.9296,,22.2154,-0.0509296,,,,7.85398e-5
Test1,3-Recover,169.333,5.089,1.393,-0.004,,0.214903,-50.9296,,21.4903,-0.0509296,,,,7.85398e-5
Test1,3-Recover,169.700,5.136,1.346,-0.004,,0.207652,-50.9296,,20.7652,-0.0509296,,,,7.85398e-5
Test1,3-Recover,170.067,5.185,1.297,-0.004,,0.200093,-50.9296,,20.0093,-0.0509296,,,,7.85398e-5
Test1,3-Recover,170.433,5.231,1.251,-0.004,,0.192996,-50.9296,,19.2996,-0.0509296,,,,7.85398e-5
Test1,3-Recover,170.800,5.279,1.203,0.003,,0.185591,38.1972,,18.5591,0.0381972,,,,7.85398e-5
Test1,3-Recover,171.167,5.328,1.154,-0.004,,0.178031,-50.9296,,17.8031,-0.0509296,,,,7.85398e-5
Test1,3-Recover,171.533,5.374,1.108,0.003,,0.170935,38.1972,,17.0935,0.0381972,,,,7.85398e-5
Test1,3-Recover,171.900,5.422,1.06,-0.004,,0.16353,-50.9296,,16.353,-0.0509296,,,,7.85398e-5
Test1,3-Recover,172.267,5.47,1.012,-0.004,,0.156125,-50.9296,,15.6125,-0.0509296,,,,7.85398e-5
Test1,3-Recover,172.633,5.517,0.965,-0.004,,0.148874,-50.9296,,14.8874,-0.0509296,,,,7.85398e-5
Test1,3-Recover,173.000,5.565,0.917,0.003,,0.141469,38.1972,,14.1469,0.0381972,,,,7.85398e-5
Test1,3-Recover,173.367,5.613,0.869,0.003,,0.134064,38.1972,,13.4064,0.0381972,,,,7.85398e-5
Test1,3-Recover,173.733,5.66,0.822,-0.004,,0.126813,-50.9296,,12.6813,-0.0509296,,,,7.85398e-5
Test1,3-Recover,174.100,5.708,0.774,-0.004,,0.119408,-50.9296,,11.9408,-0.0509296,,,,7.85398e-5
Test1,3-Recover,174.467,5.756,0.726,-0.004,,0.112002,-50.9296,,11.2002,-0.0509296,,,,7.85398e-5
Test1,3-Recover,174.833,5.803,0.679,-0.004,,0.104752,-50.9296,,10.4752,-0.0509296,,,,7.85398e-5
Test1,3-Recover,175.200,5.851,0.631,-0.004,,0.0973465,-50.9296,,9.73465,-0.0509296,,,,7.85398e-5
Test1,3-Recover,175.567,5.899,0.583,0.003,,0.0899414,38.1972,,8.99414,0.0381972,,,,7.85398e-5
Test1,3-Recover,175.933,5.946,0.536,0.003,,0.0826905,38.1972,,8.26905,0.0381972,,,,7.85398e-5
Test1,3-Recover,176.300,5.993,0.489,0.003,,0.0754397,38.1972,,7.54397,0.0381972,,,,7.85398e-5
Test1,3-Recover,176.667,6.042,0.44,-0.004,,0.0678803,-50.9296,,6.78803,-0.0509296,,,,7.85398e-5
Test1,3-Recover,177.033,6.088,0.394,-0.004,,0.0607837,-50.9296,,6.07837,-0.0509296,,,,7.85398e-5
Test1,3-Recover,177.400,6.136,0.346,-0.004,,0.0533786,-50.9296,,5.33786,-0.0509296,,,,7.85398e-5
Test1,3-Recover,177.767,6.185,0.297,-0.004,,0.0458192,-50.9296,,4.58192,-0.0509296,,,,7.85398e-5
Test1,3-Recover,178.133,6.231,0.251,0.003,,0.0387226,38.1972,,3.87226,0.0381972,,,,7.85398e-5
Test1,3-Recover,178.500,6.279,0.203,0.003,,0.0313175,38.1972,,3.13175,0.0381972,,,,7.85398e-5
Test1,3-Recover,178.867,6.327,0.155,0.003,,0.0239124,38.1972,,2.39124,0.0381972,,,,7.85398e-5
Test1,3-Recover,179.233,6.374,0.108,-0.004,,0.0166615,-50.9296,,1.66615,-0.0509296,,,,7.85398e-5
Test1,3-Recover,179.600,6.422,0.06,-0.004,,0.0092564,-50.9296,,0.92564,-0.0509296,,,,7.85398e-5
Test1,3-Recover,179.967,6.47,0.012,-0.004,,0.00185128,-50.9296,,0.185128,-0.0509296,,,,7.85398e-5
Test1,3-Recover,180.100,6.482,-0,-0.004,,0,-50.9296,,0,-0.0509296,,,,7.85398e-5