File: data/beta_1-1_2.csv
SetName,Cycle,Time_S,Size_mm,Displacement_mm,Force_N,,Strain,Stress(Pascal),,%Strain,Stress(kPa),,,,Area(m^2)
1:1 (rep 2),1-Compress,0,1.985,0,0.011,,0,140.056,,0,0.140056,,,,7.85398e-5
1:1 (rep 2),1-Compress,0.367,1.97,0.015,0.011,,0.00755668,140.056,,0.755668,0.140056,,,,7.85398e-5
1:1 (rep 2),1-Compress,0.733,1.956,0.029,0.011,,0.0146096,140.056,,1.46096,0.140056,,,,7.85398e-5
1:1 (rep 2),1-Compress,1.1,1.941,0.044,0.011,,0.0221662,140.056,,2.21662,0.140056,,,,7.85398e-5
1:1 (rep 2),1-Compress,1.467,1.927,0.058,0.018,,0.0292191,229.183,,2.92191,0.229183,,,,7.85398e-5
1:1 (rep 2),1-Compress,1.833,1.912,0.073,0.018,,0.0367758,229.183,,3.67758,0.229183,,,,7.85398e-5
1:1 (rep 2),1-Compress,2.2,1.898,0.087,0.025,,0.0438287,318.31,,4.38287,0.31831,,,,7.85398e-5
1:1 (rep 2),1-Compress,2.567,1.883,0.102,0.011,,0.0513854,140.056,,5.13854,0.140056,,,,7.85398e-5
1:1 (rep 2),1-Compress,2.933,1.869,0.116,0.011,,0.0584383,140.056,,5.84383,0.140056,,,,7.85398e-5
1:1 (rep 2),1-Compress,3.3,1.854,0.131,0.011,,0.065995,140.056,,6.5995,0.140056,,,,7.85398e-5
1:1 (rep 2),1-Compress,3.667,1.839,0.146,0.011,,0.0735516,140.056,,7.35516,0.140056,,,,7.85398e-5
1:1 (rep 2),1-Compress,4.033,1.825,0.16,0.018,,0.0806045,229.183,,8.06045,0.229183,,,,7.85398e-5
1:1 (rep 2),1-Compress,4.4,1.81,0.175,0.025,,0.0881612,318.31,,8.81612,0.31831,,,,7.85398e-5
1:1 (rep 2),1-Compress,4.767,1.796,0.189,0.025,,0.0952141,318.31,,9.52141,0.31831,,,,7.85398e-5
1:1 (rep 2),1-Compress,5.133,1.781,0.204,0.018,,0.102771,229.183,,10.2771,0.229183,,,,7.85398e-5
1:1 (rep 2),1-Compress,5.5,1.766,0.219,0.011,,0.110327,140.056,,11.0327,0.140056,,,,7.85398e-5
1:1 (rep 2),1-Compress,5.867,1.752,0.233,0.011,,0.11738,140.056,,11.738,0.140056,,,,7.85398e-5
1:1 (rep 2),1-Compress,6.233,1.737,0.248,0.011,,0.124937,140.056,,12.4937,0.140056,,,,7.85398e-5
1:1 (rep 2),1-Compress,6.6,1.723,0.262,0.018,,0.13199,229.183,,13.199,0.229183,,,,7.85398e-5
1:1 (rep 2),1-Compress,6.967,1.708,0.277,0.025,,0.139547,318.31,,13.9547,0.31831,,,,7.85398e-5
1:1 (rep 2),1-Compress,7.333,1.694,0.291,0.025,,0.146599,318.31,,14.6599,0.31831,,,,7.85398e-5
1:1 (rep 2),1-Compress,7.7,1.679,0.306,0.011,,0.154156,140.056,,15.4156,0.140056,,,,7.85398e-5
1:1 (rep 2),1-Compress,8.067,1.664,0.321,0.011,,0.161713,140.056,,16.1713,0.140056,,,,7.85398e-5
1:1 (rep 2),1-Compress,8.433,1.65,0.335,0.011,,0.168766,140.056,,16.8766,0.140056,,,,7.85398e-5
1:1 (rep 2),1-Compress,8.8,1.635,0.35,0.011,,0.176322,140.056,,17.6322,0.140056,,,,7.85398e-5
1:1 (rep 2),1-Compress,9.167,1.621,0.364,0.018,,0.183375,229.183,,18.3375,0.229183,,,,7.85398e-5
1:1 (rep 2),1-Compress,9.533,1.606,0.379,0.025,,0.190932,318.31,,19.0932,0.31831,,,,7.85398e-5
1:1 (rep 2),1-Compress,9.9,1.592,0.393,0.018,,0.197985,229.183,,19.7985,0.229183,,,,7.85398e-5
1:1 (rep 2),1-Compress,10.267,1.577,0.408,0.011,,0.205542,140.056,,20.5542,0.140056,,,,7.85398e-5
1:1 (rep 2),1-Compress,10.633,1.563,0.422,0.011,,0.212594,140.056,,21.2594,0.140056,,,,7.85398e-5
1:1 (rep 2),1-Compress,11,1.548,0.437,0.011,,0.220151,140.056,,22.0151,0.140056,,,,7.85398e-5
1:1 (rep 2),1-Compress,11.367,1.533,0.452,0.011,,0.227708,140.056,,22.7708,0.140056,,,,7.85398e-5
1:1 (rep 2),1-Compress,11.733,1.519,0.466,0.018,,0.234761,229.183,,23.4761,0.229183,,,,7.85398e-5
1:1 (rep 2),1-Compress,12.1,1.504,0.481,0.025,,0.242317,318.31,,24.2317,0.31831,,,,7.85398e-5
1:1 (rep 2),1-Compress,12.467,1.489,0.496,0.018,,0.249874,229.183,,24.9874,0.229183,,,,7.85398e-5
1:1 (rep 2),1-Compress,12.833,1.475,0.51,0.011,,0.256927,140.056,,25.6927,0.140056,,,,7.85398e-5
1:1 (rep 2),1-Compress,13.2,1.46,0.525,0.018,,0.264484,229.183,,26.4484,0.229183,,,,7.85398e-5
1:1 (rep 2),1-Compress,13.567,1.446,0.539,0.011,,0.271537,140.056,,27.1537,0.140056,,,,7.85398e-5
1:1 (rep 2),1-Compress,13.933,1.431,0.554,0.011,,0.279093,140.056,,27.9093,0.140056,,,,7.85398e-5
1:1 (rep 2),1-Compress,14.3,1.417,0.568,0.018,,0.286146,229.183,,28.6146,0.229183,,,,7.85398e-5
1:1 (rep 2),1-Compress,14.667,1.402,0.583,0.018,,0.293703,229.183,,29.3703,0.229183,,,,7.85398e-5
1:1 (rep 2),1-Compress,15.033,1.388,0.597,0.018,,0.300756,229.183,,30.0756,0.229183,,,,7.85398e-5
1:1 (rep 2),1-Compress,15.4,1.373,0.612,0.011,,0.308312,140.056,,30.8312,0.140056,,,,7.85398e-5
1:1 (rep 2),1-Compress,15.767,1.358,0.627,0.011,,0.315869,140.056,,31.5869,0.140056,,,,7.85398e-5
1:1 (rep 2),1-Compress,16.133,1.344,0.641,0.011,,0.322922,140.056,,32.2922,0.140056,,,,7.85398e-5
1:1 (rep 2),1-Compress,16.5,1.329,0.656,0.018,,0.330479,229.183,,33.0479,0.229183,,,,7.85398e-5
1:1 (rep 2),1-Compress,16.867,1.314,0.671,0.018,,0.338035,229.183,,33.8035,0.229183,,,,7.85398e-5
1:1 (rep 2),1-Compress,17.233,1.3,0.685,0.032,,0.345088,407.437,,34.5088,0.407437,,,,7.85398e-5
1:1 (rep 2),1-Compress,17.6,1.285,0.7,0.032,,0.352645,407.437,,35.2645,0.407437,,,,7.85398e-5
1:1 (rep 2),1-Compress,17.967,1.271,0.714,0.018,,0.359698,229.183,,35.9698,0.229183,,,,7.85398e-5
1:1 (rep 2),1-Compress,18.333,1.256,0.729,0.018,,0.367254,229.183,,36.7254,0.229183,,,,7.85398e-5
1:1 (rep 2),1-Compress,18.7,1.242,0.743,0.011,,0.374307,140.056,,37.4307,0.140056,,,,7.85398e-5
1:1 (rep 2),1-Compress,19.067,1.227,0.758,0.018,,0.381864,229.183,,38.1864,0.229183,,,,7.85398e-5
1:1 (rep 2),1-Compress,19.433,1.213,0.772,0.018,,0.388917,229.183,,38.8917,0.229183,,,,7.85398e-5
1:1 (rep 2),1-Compress,19.8,1.198,0.787,0.025,,0.396474,318.31,,39.6474,0.31831,,,,7.85398e-5
1:1 (rep 2),1-Compress,20.167,1.183,0.802,0.025,,0.40403,318.31,,40.403,0.31831,,,,7.85398e-5
1:1 (rep 2),1-Compress,20.533,1.169,0.816,0.018,,0.411083,229.183,,41.1083,0.229183,,,,7.85398e-5
1:1 (rep 2),1-Compress,20.9,1.154,0.831,0.018,,0.41864,229.183,,41.864,0.229183,,,,7.85398e-5
1:1 (rep 2),1-Compress,21.267,1.139,0.846,0.018,,0.426196,229.183,,42.6196,0.229183,,,,7.85398e-5
1:1 (rep 2),1-Compress,21.633,1.125,0.86,0.018,,0.433249,229.183,,43.3249,0.229183,,,,7.85398e-5
1:1 (rep 2),1-Compress,22,1.11,0.875,0.025,,0.440806,318.31,,44.0806,0.31831,,,,7.85398e-5
1:1 (rep 2),1-Compress,22.367,1.096,0.889,0.032,,0.447859,407.437,,44.7859,0.407437,,,,7.85398e-5
1:1 (rep 2),1-Compress,22.733,1.081,0.904,0.025,,0.455416,318.31,,45.5416,0.31831,,,,7.85398e-5
1:1 (rep 2),1-Compress,23.1,1.067,0.918,0.032,,0.462469,407.437,,46.2469,0.407437,,,,7.85398e-5
1:1 (rep 2),1-Compress,23.467,1.052,0.933,0.025,,0.470025,318.31,,47.0025,0.31831,,,,7.85398e-5
1:1 (rep 2),1-Compress,23.833,1.038,0.947,0.018,,0.477078,229.183,,47.7078,0.229183,,,,7.85398e-5
1:1 (rep 2),1-Compress,24.2,1.023,0.962,0.018,,0.484635,229.183,,48.4635,0.229183,,,,7.85398e-5
1:1 (rep 2),1-Compress,24.567,1.008,0.977,0.025,,0.492191,318.31,,49.2191,0.31831,,,,7.85398e-5
1:1 (rep 2),1-Compress,24.933,0.994,0.991,0.025,,0.499244,318.31,,49.9244,0.31831,,,,7.85398e-5
1:1 (rep 2),1-Compress,25.3,0.979,1.006,0.025,,0.506801,318.31,,50.6801,0.31831,,,,7.85398e-5
1:1 (rep 2),1-Compress,25.667,0.965,1.02,0.025,,0.513854,318.31,,51.3854,0.31831,,,,7.85398e-5
1:1 (rep 2),1-Compress,26.033,0.95,1.035,0.025,,0.521411,318.31,,52.1411,0.31831,,,,7.85398e-5
1:1 (rep 2),1-Compress,26.4,0.936,1.049,0.018,,0.528463,229.183,,52.8463,0.229183,,,,7.85398e-5
1:1 (rep 2),1-Compress,26.767,0.921,1.064,0.018,,0.53602,229.183,,53.602,0.229183,,,,7.85398e-5
1:1 (rep 2),1-Compress,27.133,0.907,1.078,0.025,,0.543073,318.31,,54.3073,0.31831,,,,7.85398e-5
1:1 (rep 2),1-Compress,27.5,0.892,1.093,0.038,,0.55063,483.831,,55.063,0.483831,,,,7.85398e-5
1:1 (rep 2),1-Compress,27.867,0.877,1.108,0.038,,0.558186,483.831,,55.8186,0.483831,,,,7.85398e-5
1:1 (rep 2),1-Compress,28.233,0.863,1.122,0.032,,0.565239,407.437,,56.5239,0.407437,,,,7.85398e-5
1:1 (rep 2),1-Compress,28.6,0.848,1.137,0.025,,0.572796,318.31,,57.2796,0.31831,,,,7.85398e-5
1:1 (rep 2),1-Compress,28.967,0.833,1.152,0.018,,0.580353,229.183,,58.0353,0.229183,,,,7.85398e-5
1:1 (rep 2),1-Compress,29.333,0.819,1.166,0.025,,0.587406,318.31,,58.7406,0.31831,,,,7.85398e-5
1:1 (rep 2),1-Compress,29.7,0.804,1.181,0.038,,0.594962,483.831,,59.4962,0.483831,,,,7.85398e-5
1:1 (rep 2),1-Recover,30.067,0.797,1.188,0.045,,0.598489,572.958,,59.8489,0.572958,,,,7.85398e-5
1:1 (rep 2),1-Recover,30.433,0.811,1.174,0.045,,0.591436,572.958,,59.1436,0.572958,,,,7.85398e-5
1:1 (rep 2),1-Recover,30.8,0.826,1.159,0.025,,0.583879,318.31,,58.3879,0.31831,,,,7.85398e-5
1:1 (rep 2),1-Recover,31.167,0.84,1.145,0.025,,0.576826,318.31,,57.6826,0.31831,,,,7.85398e-5
1:1 (rep 2),1-Recover,31.533,0.855,1.13,0.018,,0.56927,229.183,,56.927,0.229183,,,,7.85398e-5
1:1 (rep 2),1-Recover,31.9,0.869,1.116,0.018,,0.562217,229.183,,56.2217,0.229183,,,,7.85398e-5
1:1 (rep 2),1-Recover,32.267,0.884,1.101,0.032,,0.55466,407.437,,55.466,0.407437,,,,7.85398e-5
1:1 (rep 2),1-Recover,32.633,0.898,1.087,0.032,,0.547607,407.437,,54.7607,0.407437,,,,7.85398e-5
1:1 (rep 2),1-Recover,33,0.913,1.072,0.025,,0.54005,318.31,,54.005,0.31831,,,,7.85398e-5
1:1 (rep 2),1-Recover,33.367,0.928,1.057,0.032,,0.532494,407.437,,53.2494,0.407437,,,,7.85398e-5
1:1 (rep 2),1-Recover,33.733,0.942,1.043,0.018,,0.525441,229.183,,52.5441,0.229183,,,,7.85398e-5
1:1 (rep 2),1-Recover,34.1,0.957,1.028,0.018,,0.517884,229.183,,51.7884,0.229183,,,,7.85398e-5
1:1 (rep 2),1-Recover,34.467,0.972,1.013,0.018,,0.510327,229.183,,51.0327,0.229183,,,,7.85398e-5
1:1 (rep 2),1-Recover,34.833,0.986,0.999,0.032,,0.503275,407.437,,50.3275,0.407437,,,,7.85398e-5
1:1 (rep 2),1-Recover,35.2,1.001,0.984,0.025,,0.495718,318.31,,49.5718,0.31831,,,,7.85398e-5
1:1 (rep 2),1-Recover,35.567,1.015,0.97,0.025,,0.488665,318.31,,48.8665,0.31831,,,,7.85398e-5
1:1 (rep 2),1-Recover,35.933,1.03,0.955,0.018,,0.481108,229.183,,48.1108,0.229183,,,,7.85398e-5
1:1 (rep 2),1-Recover,36.3,1.044,0.941,0.018,,0.474055,229.183,,47.4055,0.229183,,,,7.85398e-5
1:1 (rep 2),1-Recover,36.667,1.059,0.926,0.018,,0.466499,229.183,,46.6499,0.229183,,,,7.85398e-5
1:1 (rep 2),1-Recover,37.033,1.073,0.912,0.018,,0.459446,229.183,,45.9446,0.229183,,,,7.85398e-5
1:1 (rep 2),1-Recover,37.4,1.088,0.897,0.025,,0.451889,318.31,,45.1889,0.31831,,,,7.85398e-5
1:1 (rep 2),1-Recover,37.767,1.103,0.882,0.025,,0.444332,318.31,,44.4332,0.31831,,,,7.85398e-5
1:1 (rep 2),1-Recover,38.133,1.117,0.868,0.018,,0.43728,229.183,,43.728,0.229183,,,,7.85398e-5
1:1 (rep 2),1-Recover,38.5,1.132,0.853,0.018,,0.429723,229.183,,42.9723,0.229183,,,,7.85398e-5
1:1 (rep 2),1-Recover,38.867,1.146,0.839,0.011,,0.42267,140.056,,42.267,0.140056,,,,7.85398e-5
1:1 (rep 2),1-Recover,39.233,1.161,0.824,0.018,,0.415113,229.183,,41.5113,0.229183,,,,7.85398e-5
1:1 (rep 2),1-Recover,39.6,1.175,0.81,0.025,,0.40806,318.31,,40.806,0.31831,,,,7.85398e-5
1:1 (rep 2),1-Recover,39.967,1.19,0.795,0.025,,0.400504,318.31,,40.0504,0.31831,,,,7.85398e-5
1:1 (rep 2),1-Recover,40.333,1.205,0.78,0.025,,0.392947,318.31,,39.2947,0.31831,,,,7.85398e-5
1:1 (rep 2),1-Recover,40.7,1.219,0.766,0.018,,0.385894,229.183,,38.5894,0.229183,,,,7.85398e-5
1:1 (rep 2),1-Recover,41.067,1.234,0.751,0.018,,0.378338,229.183,,37.8338,0.229183,,,,7.85398e-5
1:1 (rep 2),1-Recover,41.433,1.248,0.737,0.011,,0.371285,140.056,,37.1285,0.140056,,,,7.85398e-5
1:1 (rep 2),1-Recover,41.8,1.263,0.722,0.018,,0.363728,229.183,,36.3728,0.229183,,,,7.85398e-5
1:1 (rep 2),1-Recover,42.167,1.277,0.708,0.025,,0.356675,318.31,,35.6675,0.31831,,,,7.85398e-5
1:1 (rep 2),1-Recover,42.533,1.292,0.693,0.025,,0.349118,318.31,,34.9118,0.31831,,,,7.85398e-5
1:1 (rep 2),1-Recover,42.9,1.306,0.679,0.011,,0.342065,140.056,,34.2065,0.140056,,,,7.85398e-5
1:1 (rep 2),1-Recover,43.267,1.321,0.664,0.011,,0.334509,140.056,,33.4509,0.140056,,,,7.85398e-5
1:1 (rep 2),1-Recover,43.633,1.336,0.649,0.011,,0.326952,140.056,,32.6952,0.140056,,,,7.85398e-5
1:1 (rep 2),1-Recover,44,1.35,0.635,0.011,,0.319899,140.056,,31.9899,0.140056,,,,7.85398e-5
1:1 (rep 2),1-Recover,44.367,1.365,0.62,0.018,,0.312343,229.183,,31.2343,0.229183,,,,7.85398e-5
1:1 (rep 2),1-Recover,44.733,1.379,0.606,0.025,,0.30529,318.31,,30.529,0.31831,,,,7.85398e-5
1:1 (rep 2),1-Recover,45.1,1.394,0.591,0.025,,0.297733,318.31,,29.7733,0.31831,,,,7.85398e-5
1:1 (rep 2),1-Recover,45.467,1.408,0.577,0.011,,0.29068,140.056,,29.068,0.140056,,,,7.85398e-5
1:1 (rep 2),1-Recover,45.833,1.423,0.562,0.011,,0.283123,140.056,,28.3123,0.140056,,,,7.85398e-5
1:1 (rep 2),1-Recover,46.2,1.437,0.548,0.011,,0.276071,140.056,,27.6071,0.140056,,,,7.85398e-5
1:1 (rep 2),1-Recover,46.567,1.452,0.533,0.011,,0.268514,140.056,,26.8514,0.140056,,,,7.85398e-5
1:1 (rep 2),1-Recover,46.933,1.467,0.518,0.018,,0.260957,229.183,,26.0957,0.229183,,,,7.85398e-5
1:1 (rep 2),1-Recover,47.3,1.481,0.504,0.025,,0.253904,318.31,,25.3904,0.31831,,,,7.85398e-5
1:1 (rep 2),1-Recover,47.667,1.496,0.489,0.018,,0.246348,229.183,,24.6348,0.229183,,,,7.85398e-5
1:1 (rep 2),1-Recover,48.033,1.51,0.475,0.011,,0.239295,140.056,,23.9295,0.140056,,,,7.85398e-5
1:1 (rep 2),1-Recover,48.4,1.525,0.46,0.011,,0.231738,140.056,,23.1738,0.140056,,,,7.85398e-5
1:1 (rep 2),1-Recover,48.767,1.54,0.445,0.011,,0.224181,140.056,,22.4181,0.140056,,,,7.85398e-5
1:1 (rep 2),1-Recover,49.133,1.554,0.431,0.011,,0.217128,140.056,,21.7128,0.140056,,,,7.85398e-5
1:1 (rep 2),1-Recover,49.5,1.569,0.416,0.018,,0.209572,229.183,,20.9572,0.229183,,,,7.85398e-5
1:1 (rep 2),1-Recover,49.867,1.583,0.402,0.025,,0.202519,318.31,,20.2519,0.31831,,,,7.85398e-5
1:1 (rep 2),1-Recover,50.233,1.598,0.387,0.018,,0.194962,229.183,,19.4962,0.229183,,,,7.85398e-5
1:1 (rep 2),1-Recover,50.6,1.612,0.373,0.011,,0.187909,140.056,,18.7909,0.140056,,,,7.85398e-5
1:1 (rep 2),1-Recover,50.967,1.627,0.358,0.011,,0.180353,140.056,,18.0353,0.140056,,,,7.85398e-5
1:1 (rep 2),1-Recover,51.333,1.641,0.344,0.011,,0.1733,140.056,,17.33,0.140056,,,,7.85398e-5
1:1 (rep 2),1-Recover,51.7,1.656,0.329,0.018,,0.165743,229.183,,16.5743,0.229183,,,,7.85398e-5
1:1 (rep 2),1-Recover,52.067,1.671,0.314,0.018,,0.158186,229.183,,15.8186,0.229183,,,,7.85398e-5
1:1 (rep 2),1-Recover,52.433,1.685,0.3,0.018,,0.151134,229.183,,15.1134,0.229183,,,,7.85398e-5
1:1 (rep 2),1-Recover,52.8,1.7,0.285,0.011,,0.143577,140.056,,14.3577,0.140056,,,,7.85398e-5
1:1 (rep 2),1-Recover,53.167,1.715,0.27,0.011,,0.13602,140.056,,13.602,0.140056,,,,7.85398e-5
1:1 (rep 2),1-Recover,53.533,1.729,0.256,0.011,,0.128967,140.056,,12.8967,0.140056,,,,7.85398e-5
1:1 (rep 2),1-Recover,53.9,1.744,0.241,0.011,,0.121411,140.056,,12.1411,0.140056,,,,7.85398e-5
1:1 (rep 2),1-Recover,54.267,1.759,0.226,0.011,,0.113854,140.056,,11.3854,0.140056,,,,7.85398e-5
1:1 (rep 2),1-Recover,54.633,1.773,0.212,0.018,,0.106801,229.183,,10.6801,0.229183,,,,7.85398e-5
1:1 (rep 2),1-Recover,55,1.787,0.198,0.011,,0.0997481,140.056,,9.97481,0.140056,,,,7.85398e-5
1:1 (rep 2),1-Recover,55.367,1.802,0.183,0.011,,0.0921914,140.056,,9.21914,0.140056,,,,7.85398e-5
1:1 (rep 2),1-Recover,55.733,1.816,0.169,0.011,,0.0851385,140.056,,8.51385,0.140056,,,,7.85398e-5
1:1 (rep 2),1-Recover,56.1,1.831,0.154,0.011,,0.0775819,140.056,,7.75819,0.140056,,,,7.85398e-5
1:1 (rep 2),1-Recover,56.467,1.846,0.139,0.011,,0.0700252,140.056,,7.00252,0.140056,,,,7.85398e-5
1:1 (rep 2),1-Recover,56.833,1.86,0.125,0.011,,0.0629723,140.056,,6.29723,0.140056,,,,7.85398e-5
1:1 (rep 2),1-Recover,57.2,1.875,0.11,0.018,,0.0554156,229.183,,5.54156,0.229183,,,,7.85398e-5
1:1 (rep 2),1-Recover,57.567,1.89,0.095,0.025,,0.0478589,318.31,,4.78589,0.31831,,,,7.85398e-5
1:1 (rep 2),1-Recover,57.933,1.904,0.081,0.018,,0.040806,229.183,,4.0806,0.229183,,,,7.85398e-5
1:1 (rep 2),1-Recover,58.3,1.919,0.066,0.011,,0.0332494,140.056,,3.32494,0.140056,,,,7.85398e-5
1:1 (rep 2),1-Recover,58.667,1.933,0.052,0.011,,0.0261965,140.056,,2.61965,0.140056,,,,7.85398e-5
1:1 (rep 2),1-Recover,59.033,1.948,0.037,0.011,,0.0186398,140.056,,1.86398,0.140056,,,,7.85398e-5
1:1 (rep 2),1-Recover,59.4,1.963,0.022,0.018,,0.0110831,229.183,,1.10831,0.229183,,,,7.85398e-5
1:1 (rep 2),1-Recover,59.767,1.977,0.008,0.018,,0.00403023,229.183,,0.403023,0.229183,,,,7.85398e-5
1:1 (rep 2),2-Compress,60.117,1.982,0.003,0.018,,0.00151134,229.183,,0.151134,0.229183,,,,7.85398e-5
1:1 (rep 2),2-Compress,60.483,1.967,0.018,0.011,,0.00906801,140.056,,0.906801,0.140056,,,,7.85398e-5
1:1 (rep 2),2-Compress,60.85,1.953,0.032,0.011,,0.0161209,140.056,,1.61209,0.140056,,,,7.85398e-5
1:1 (rep 2),2-Compress,61.217,1.938,0.047,0.011,,0.0236776,140.056,,2.36776,0.140056,,,,7.85398e-5
1:1 (rep 2),2-Compress,61.583,1.924,0.061,0.011,,0.0307305,140.056,,3.07305,0.140056,,,,7.85398e-5
1:1 (rep 2),2-Compress,61.95,1.909,0.076,0.018,,0.0382872,229.183,,3.82872,0.229183,,,,7.85398e-5
1:1 (rep 2),2-Compress,62.317,1.894,0.091,0.018,,0.0458438,229.183,,4.58438,0.229183,,,,7.85398e-5
1:1 (rep 2),2-Compress,62.683,1.88,0.105,0.025,,0.0528967,318.31,,5.28967,0.31831,,,,7.85398e-5
1:1 (rep 2),2-Compress,63.05,1.865,0.12,0.018,,0.0604534,229.183,,6.04534,0.229183,,,,7.85398e-5
1:1 (rep 2),2-Compress,63.417,1.851,0.134,0.011,,0.0675063,140.056,,6.75063,0.140056,,,,7.85398e-5
1:1 (rep 2),2-Compress,63.783,1.836,0.149,0.011,,0.075063,140.056,,7.5063,0.140056,,,,7.85398e-5
1:1 (rep 2),2-Compress,64.15,1.822,0.163,0.011,,0.0821159,140.056,,8.21159,0.140056,,,,7.85398e-5
1:1 (rep 2),2-Compress,64.517,1.807,0.178,0.018,,0.0896725,229.183,,8.96725,0.229183,,,,7.85398e-5
1:1 (rep 2),2-Compress,64.883,1.793,0.192,0.018,,0.0967254,229.183,,9.67254,0.229183,,,,7.85398e-5
1:1 (rep 2),2-Compress,65.25,1.778,0.207,0.018,,0.104282,229.183,,10.4282,0.229183,,,,7.85398e-5
1:1 (rep 2),2-Compress,65.617,1.763,0.222,0.011,,0.111839,140.056,,11.1839,0.140056,,,,7.85398e-5
1:1 (rep 2),2-Compress,65.983,1.749,0.236,0.011,,0.118892,140.056,,11.8892,0.140056,,,,7.85398e-5
1:1 (rep 2),2-Compress,66.35,1.734,0.251,0.011,,0.126448,140.056,,12.6448,0.140056,,,,7.85398e-5
1:1 (rep 2),2-Compress,66.717,1.719,0.266,0.011,,0.134005,140.056,,13.4005,0.140056,,,,7.85398e-5
1:1 (rep 2),2-Compress,67.083,1.705,0.28,0.018,,0.141058,229.183,,14.1058,0.229183,,,,7.85398e-5
1:1 (rep 2),2-Compress,67.45,1.69,0.295,0.018,,0.148615,229.183,,14.8615,0.229183,,,,7.85398e-5
1:1 (rep 2),2-Compress,67.817,1.676,0.309,0.018,,0.155668,229.183,,15.5668,0.229183,,,,7.85398e-5
1:1 (rep 2),2-Compress,68.183,1.661,0.324,0.011,,0.163224,140.056,,16.3224,0.140056,,,,7.85398e-5
1:1 (rep 2),2-Compress,68.55,1.647,0.338,0.011,,0.170277,140.056,,17.0277,0.140056,,,,7.85398e-5
1:1 (rep 2),2-Compress,68.917,1.632,0.353,0.011,,0.177834,140.056,,17.7834,0.140056,,,,7.85398e-5
1:1 (rep 2),2-Compress,69.283,1.618,0.367,0.011,,0.184887,140.056,,18.4887,0.140056,,,,7.85398e-5
1:1 (rep 2),2-Compress,69.65,1.603,0.382,0.018,,0.192443,229.183,,19.2443,0.229183,,,,7.85398e-5
1:1 (rep 2),2-Compress,70.017,1.588,0.397,0.032,,0.2,407.437,,20,0.407437,,,,7.85398e-5
1:1 (rep 2),2-Compress,70.383,1.574,0.411,0.018,,0.207053,229.183,,20.7053,0.229183,,,,7.85398e-5
1:1 (rep 2),2-Compress,70.75,1.559,0.426,0.011,,0.21461,140.056,,21.461,0.140056,,,,7.85398e-5
1:1 (rep 2),2-Compress,71.117,1.544,0.441,0.011,,0.222166,140.056,,22.2166,0.140056,,,,7.85398e-5
1:1 (rep 2),2-Compress,71.483,1.53,0.455,0.011,,0.229219,140.056,,22.9219,0.140056,,,,7.85398e-5
1:1 (rep 2),2-Compress,71.85,1.515,0.47,0.011,,0.236776,140.056,,23.6776,0.140056,,,,7.85398e-5
1:1 (rep 2),2-Compress,72.217,1.501,0.484,0.018,,0.243829,229.183,,24.3829,0.229183,,,,7.85398e-5
1:1 (rep 2),2-Compress,72.583,1.486,0.499,0.025,,0.251385,318.31,,25.1385,0.31831,,,,7.85398e-5
1:1 (rep 2),2-Compress,72.95,1.472,0.513,0.018,,0.258438,229.183,,25.8438,0.229183,,,,7.85398e-5
1:1 (rep 2),2-Compress,73.317,1.457,0.528,0.011,,0.265995,140.056,,26.5995,0.140056,,,,7.85398e-5
1:1 (rep 2),2-Compress,73.683,1.443,0.542,0.011,,0.273048,140.056,,27.3048,0.140056,,,,7.85398e-5
1:1 (rep 2),2-Compress,74.05,1.428,0.557,0.011,,0.280605,140.056,,28.0605,0.140056,,,,7.85398e-5
1:1 (rep 2),2-Compress,74.417,1.413,0.572,0.018,,0.288161,229.183,,28.8161,0.229183,,,,7.85398e-5
1:1 (rep 2),2-Compress,74.783,1.399,0.586,0.018,,0.295214,229.183,,29.5214,0.229183,,,,7.85398e-5
1:1 (rep 2),2-Compress,75.15,1.384,0.601,0.025,,0.302771,318.31,,30.2771,0.31831,,,,7.85398e-5
1:1 (rep 2),2-Compress,75.517,1.37,0.615,0.018,,0.309824,229.183,,30.9824,0.229183,,,,7.85398e-5
1:1 (rep 2),2-Compress,75.883,1.355,0.63,0.011,,0.31738,140.056,,31.738,0.140056,,,,7.85398e-5
1:1 (rep 2),2-Compress,76.25,1.34,0.645,0.011,,0.324937,140.056,,32.4937,0.140056,,,,7.85398e-5
1:1 (rep 2),2-Compress,76.617,1.326,0.659,0.011,,0.33199,140.056,,33.199,0.140056,,,,7.85398e-5
1:1 (rep 2),2-Compress,76.983,1.311,0.674,0.018,,0.339547,229.183,,33.9547,0.229183,,,,7.85398e-5
1:1 (rep 2),2-Compress,77.35,1.297,0.688,0.018,,0.346599,229.183,,34.6599,0.229183,,,,7.85398e-5
1:1 (rep 2),2-Compress,77.717,1.282,0.703,0.025,,0.354156,318.31,,35.4156,0.31831,,,,7.85398e-5
1:1 (rep 2),2-Compress,78.083,1.268,0.717,0.018,,0.361209,229.183,,36.1209,0.229183,,,,7.85398e-5
1:1 (rep 2),2-Compress,78.45,1.253,0.732,0.018,,0.368766,229.183,,36.8766,0.229183,,,,7.85398e-5
1:1 (rep 2),2-Compress,78.817,1.238,0.747,0.018,,0.376322,229.183,,37.6322,0.229183,,,,7.85398e-5
1:1 (rep 2),2-Compress,79.183,1.224,0.761,0.018,,0.383375,229.183,,38.3375,0.229183,,,,7.85398e-5
1:1 (rep 2),2-Compress,79.55,1.209,0.776,0.018,,0.390932,229.183,,39.0932,0.229183,,,,7.85398e-5
1:1 (rep 2),2-Compress,79.917,1.195,0.79,0.025,,0.397985,318.31,,39.7985,0.31831,,,,7.85398e-5
1:1 (rep 2),2-Compress,80.283,1.18,0.805,0.025,,0.405542,318.31,,40.5542,0.31831,,,,7.85398e-5
1:1 (rep 2),2-Compress,80.65,1.166,0.819,0.025,,0.412594,318.31,,41.2594,0.31831,,,,7.85398e-5
1:1 (rep 2),2-Compress,81.017,1.151,0.834,0.018,,0.420151,229.183,,42.0151,0.229183,,,,7.85398e-5
1:1 (rep 2),2-Compress,81.383,1.137,0.848,0.018,,0.427204,229.183,,42.7204,0.229183,,,,7.85398e-5
1:1 (rep 2),2-Compress,81.75,1.122,0.863,0.018,,0.434761,229.183,,43.4761,0.229183,,,,7.85398e-5
1:1 (rep 2),2-Compress,82.117,1.107,0.878,0.018,,0.442317,229.183,,44.2317,0.229183,,,,7.85398e-5
1:1 (rep 2),2-Compress,82.483,1.093,0.892,0.025,,0.44937,318.31,,44.937,0.31831,,,,7.85398e-5
1:1 (rep 2),2-Compress,82.85,1.078,0.907,0.032,,0.456927,407.437,,45.6927,0.407437,,,,7.85398e-5
1:1 (rep 2),2-Compress,83.217,1.063,0.922,0.018,,0.464484,229.183,,46.4484,0.229183,,,,7.85398e-5
1:1 (rep 2),2-Compress,83.583,1.049,0.936,0.018,,0.471537,229.183,,47.1537,0.229183,,,,7.85398e-5
1:1 (rep 2),2-Compress,83.95,1.034,0.951,0.025,,0.479093,318.31,,47.9093,0.31831,,,,7.85398e-5
1:1 (rep 2),2-Compress,84.317,1.02,0.965,0.018,,0.486146,229.183,,48.6146,0.229183,,,,7.85398e-5
1:1 (rep 2),2-Compress,84.683,1.005,0.98,0.018,,0.493703,229.183,,49.3703,0.229183,,,,7.85398e-5
1:1 (rep 2),2-Compress,85.05,0.991,0.994,0.025,,0.500756,318.31,,50.0756,0.31831,,,,7.85398e-5
1:1 (rep 2),2-Compress,85.417,0.976,1.009,0.025,,0.508312,318.31,,50.8312,0.31831,,,,7.85398e-5
1:1 (rep 2),2-Compress,85.783,0.962,1.023,0.038,,0.515365,483.831,,51.5365,0.483831,,,,7.85398e-5
1:1 (rep 2),2-Compress,86.15,0.947,1.038,0.018,,0.522922,229.183,,52.2922,0.229183,,,,7.85398e-5
1:1 (rep 2),2-Compress,86.517,0.932,1.053,0.018,,0.530479,229.183,,53.0479,0.229183,,,,7.85398e-5
1:1 (rep 2),2-Compress,86.883,0.918,1.067,0.018,,0.537531,229.183,,53.7531,0.229183,,,,7.85398e-5
1:1 (rep 2),2-Compress,87.25,0.903,1.082,0.018,,0.545088,229.183,,54.5088,0.229183,,,,7.85398e-5
1:1 (rep 2),2-Compress,87.617,0.888,1.097,0.025,,0.552645,318.31,,55.2645,0.31831,,,,7.85398e-5
1:1 (rep 2),2-Compress,87.983,0.874,1.111,0.038,,0.559698,483.831,,55.9698,0.483831,,,,7.85398e-5
1:1 (rep 2),2-Compress,88.35,0.859,1.126,0.038,,0.567254,483.831,,56.7254,0.483831,,,,7.85398e-5
1:1 (rep 2),2-Compress,88.717,0.845,1.14,0.032,,0.574307,407.437,,57.4307,0.407437,,,,7.85398e-5
1:1 (rep 2),2-Compress,89.083,0.83,1.155,0.025,,0.581864,318.31,,58.1864,0.31831,,,,7.85398e-5
1:1 (rep 2),2-Compress,89.45,0.816,1.169,0.018,,0.588917,229.183,,58.8917,0.229183,,,,7.85398e-5
1:1 (rep 2),2-Compress,89.817,0.801,1.184,0.018,,0.596474,229.183,,59.6474,0.229183,,,,7.85398e-5
1:1 (rep 2),2-Recover,90.17,0.799,1.186,0.025,,0.597481,318.31,,59.7481,0.31831,,,,7.85398e-5
1:1 (rep 2),2-Recover,90.537,0.814,1.171,0.045,,0.589924,572.958,,58.9924,0.572958,,,,7.85398e-5
1:1 (rep 2),2-Recover,90.903,0.828,1.157,0.045,,0.582872,572.958,,58.2872,0.572958,,,,7.85398e-5
1:1 (rep 2),2-Recover,91.27,0.843,1.142,0.032,,0.575315,407.437,,57.5315,0.407437,,,,7.85398e-5
1:1 (rep 2),2-Recover,91.637,0.857,1.128,0.025,,0.568262,318.31,,56.8262,0.31831,,,,7.85398e-5
1:1 (rep 2),2-Recover,92.003,0.872,1.113,0.018,,0.560705,229.183,,56.0705,0.229183,,,,7.85398e-5
1:1 (rep 2),2-Recover,92.37,0.886,1.099,0.018,,0.553652,229.183,,55.3652,0.229183,,,,7.85398e-5
1:1 (rep 2),2-Recover,92.737,0.901,1.084,0.025,,0.546096,318.31,,54.6096,0.31831,,,,7.85398e-5
1:1 (rep 2),2-Recover,93.103,0.915,1.07,0.032,,0.539043,407.437,,53.9043,0.407437,,,,7.85398e-5
1:1 (rep 2),2-Recover,93.47,0.93,1.055,0.032,,0.531486,407.437,,53.1486,0.407437,,,,7.85398e-5
1:1 (rep 2),2-Recover,93.837,0.945,1.04,0.025,,0.523929,318.31,,52.3929,0.31831,,,,7.85398e-5
1:1 (rep 2),2-Recover,94.203,0.959,1.026,0.025,,0.516877,318.31,,51.6877,0.31831,,,,7.85398e-5
1:1 (rep 2),2-Recover,94.57,0.974,1.011,0.018,,0.50932,229.183,,50.932,0.229183,,,,7.85398e-5
1:1 (rep 2),2-Recover,94.937,0.989,0.996,0.018,,0.501763,229.183,,50.1763,0.229183,,,,7.85398e-5
1:1 (rep 2),2-Recover,95.303,1.003,0.982,0.025,,0.49471,318.31,,49.471,0.31831,,,,7.85398e-5
1:1 (rep 2),2-Recover,95.67,1.018,0.967,0.032,,0.487154,407.437,,48.7154,0.407437,,,,7.85398e-5
1:1 (rep 2),2-Recover,96.037,1.032,0.953,0.025,,0.480101,318.31,,48.0101,0.31831,,,,7.85398e-5
1:1 (rep 2),2-Recover,96.403,1.047,0.938,0.018,,0.472544,229.183,,47.2544,0.229183,,,,7.85398e-5
1:1 (rep 2),2-Recover,96.77,1.061,0.924,0.018,,0.465491,229.183,,46.5491,0.229183,,,,7.85398e-5
1:1 (rep 2),2-Recover,97.137,1.076,0.909,0.018,,0.457935,229.183,,45.7935,0.229183,,,,7.85398e-5
1:1 (rep 2),2-Recover,97.503,1.09,0.895,0.018,,0.450882,229.183,,45.0882,0.229183,,,,7.85398e-5
1:1 (rep 2),2-Recover,97.87,1.105,0.88,0.025,,0.443325,318.31,,44.3325,0.31831,,,,7.85398e-5
1:1 (rep 2),2-Recover,98.237,1.12,0.865,0.018,,0.435768,229.183,,43.5768,0.229183,,,,7.85398e-5
1:1 (rep 2),2-Recover,98.603,1.134,0.851,0.011,,0.428715,140.056,,42.8715,0.140056,,,,7.85398e-5
1:1 (rep 2),2-Recover,98.97,1.149,0.836,0.018,,0.421159,229.183,,42.1159,0.229183,,,,7.85398e-5
1:1 (rep 2),2-Recover,99.337,1.164,0.821,0.011,,0.413602,140.056,,41.3602,0.140056,,,,7.85398e-5
1:1 (rep 2),2-Recover,99.703,1.178,0.807,0.018,,0.406549,229.183,,40.6549,0.229183,,,,7.85398e-5
1:1 (rep 2),2-Recover,100.07,1.193,0.792,0.018,,0.398992,229.183,,39.8992,0.229183,,,,7.85398e-5
1:1 (rep 2),2-Recover,100.437,1.207,0.778,0.025,,0.39194,318.31,,39.194,0.31831,,,,7.85398e-5
1:1 (rep 2),2-Recover,100.803,1.222,0.763,0.018,,0.384383,229.183,,38.4383,0.229183,,,,7.85398e-5
1:1 (rep 2),2-Recover,101.17,1.236,0.749,0.011,,0.37733,140.056,,37.733,0.140056,,,,7.85398e-5
1:1 (rep 2),2-Recover,101.537,1.251,0.734,0.011,,0.369773,140.056,,36.9773,0.140056,,,,7.85398e-5
1:1 (rep 2),2-Recover,101.903,1.265,0.72,0.011,,0.36272,140.056,,36.272,0.140056,,,,7.85398e-5
1:1 (rep 2),2-Recover,102.27,1.28,0.705,0.018,,0.355164,229.183,,35.5164,0.229183,,,,7.85398e-5
1:1 (rep 2),2-Recover,102.637,1.295,0.69,0.025,,0.347607,318.31,,34.7607,0.31831,,,,7.85398e-5
1:1 (rep 2),2-Recover,103.003,1.309,0.676,0.025,,0.340554,318.31,,34.0554,0.31831,,,,7.85398e-5
1:1 (rep 2),2-Recover,103.37,1.324,0.661,0.011,,0.332997,140.056,,33.2997,0.140056,,,,7.85398e-5
1:1 (rep 2),2-Recover,103.737,1.338,0.647,0.011,,0.325945,140.056,,32.5945,0.140056,,,,7.85398e-5
1:1 (rep 2),2-Recover,104.103,1.353,0.632,0.011,,0.318388,140.056,,31.8388,0.140056,,,,7.85398e-5
1:1 (rep 2),2-Recover,104.47,1.368,0.617,0.011,,0.310831,140.056,,31.0831,0.140056,,,,7.85398e-5
1:1 (rep 2),2-Recover,104.837,1.382,0.603,0.018,,0.303778,229.183,,30.3778,0.229183,,,,7.85398e-5
1:1 (rep 2),2-Recover,105.203,1.397,0.588,0.018,,0.296222,229.183,,29.6222,0.229183,,,,7.85398e-5
1:1 (rep 2),2-Recover,105.57,1.411,0.574,0.025,,0.289169,318.31,,28.9169,0.31831,,,,7.85398e-5
1:1 (rep 2),2-Recover,105.937,1.426,0.559,0.011,,0.281612,140.056,,28.1612,0.140056,,,,7.85398e-5
1:1 (rep 2),2-Recover,106.303,1.44,0.545,0.011,,0.274559,140.056,,27.4559,0.140056,,,,7.85398e-5
1:1 (rep 2),2-Recover,106.67,1.455,0.53,0.011,,0.267003,140.056,,26.7003,0.140056,,,,7.85398e-5
1:1 (rep 2),2-Recover,107.037,1.469,0.516,0.011,,0.25995,140.056,,25.995,0.140056,,,,7.85398e-5
1:1 (rep 2),2-Recover,107.403,1.484,0.501,0.018,,0.252393,229.183,,25.2393,0.229183,,,,7.85398e-5
1:1 (rep 2),2-Recover,107.77,1.499,0.486,0.025,,0.244836,318.31,,24.4836,0.31831,,,,7.85398e-5
1:1 (rep 2),2-Recover,108.137,1.513,0.472,0.018,,0.237783,229.183,,23.7783,0.229183,,,,7.85398e-5
1:1 (rep 2),2-Recover,108.503,1.528,0.457,0.011,,0.230227,140.056,,23.0227,0.140056,,,,7.85398e-5
1:1 (rep 2),2-Recover,108.87,1.542,0.443,0.011,,0.223174,140.056,,22.3174,0.140056,,,,7.85398e-5
1:1 (rep 2),2-Recover,109.237,1.557,0.428,0.011,,0.215617,140.056,,21.5617,0.140056,,,,7.85398e-5
1:1 (rep 2),2-Recover,109.603,1.571,0.414,0.011,,0.208564,140.056,,20.8564,0.140056,,,,7.85398e-5
1:1 (rep 2),2-Recover,109.97,1.586,0.399,0.018,,0.201008,229.183,,20.1008,0.229183,,,,7.85398e-5
1:1 (rep 2),2-Recover,110.337,1.601,0.384,0.025,,0.193451,318.31,,19.3451,0.31831,,,,7.85398e-5
1:1 (rep 2),2-Recover,110.703,1.615,0.37,0.018,,0.186398,229.183,,18.6398,0.229183,,,,7.85398e-5
1:1 (rep 2),2-Recover,111.07,1.63,0.355,0.011,,0.178841,140.056,,17.8841,0.140056,,,,7.85398e-5
1:1 (rep 2),2-Recover,111.437,1.645,0.34,0.011,,0.171285,140.056,,17.1285,0.140056,,,,7.85398e-5
1:1 (rep 2),2-Recover,111.803,1.659,0.326,0.011,,0.164232,140.056,,16.4232,0.140056,,,,7.85398e-5
1:1 (rep 2),2-Recover,112.17,1.673,0.312,0.011,,0.157179,140.056,,15.7179,0.140056,,,,7.85398e-5
1:1 (rep 2),2-Recover,112.537,1.688,0.297,0.018,,0.149622,229.183,,14.9622,0.229183,,,,7.85398e-5
1:1 (rep 2),2-Recover,112.903,1.702,0.283,0.025,,0.142569,318.31,,14.2569,0.31831,,,,7.85398e-5
1:1 (rep 2),2-Recover,113.27,1.717,0.268,0.018,,0.135013,229.183,,13.5013,0.229183,,,,7.85398e-5
1:1 (rep 2),2-Recover,113.637,1.732,0.253,0.011,,0.127456,140.056,,12.7456,0.140056,,,,7.85398e-5
1:1 (rep 2),2-Recover,114.003,1.746,0.239,0.011,,0.120403,140.056,,12.0403,0.140056,,,,7.85398e-5
1:1 (rep 2),2-Recover,114.37,1.761,0.224,0.011,,0.112846,140.056,,11.2846,0.140056,,,,7.85398e-5
1:1 (rep 2),2-Recover,114.737,1.776,0.209,0.018,,0.10529,229.183,,10.529,0.229183,,,,7.85398e-5
1:1 (rep 2),2-Recover,115.103,1.79,0.195,0.018,,0.0982368,229.183,,9.82368,0.229183,,,,7.85398e-5
1:1 (rep 2),2-Recover,115.47,1.804,0.181,0.018,,0.0911839,229.183,,9.11839,0.229183,,,,7.85398e-5
1:1 (rep 2),2-Recover,115.837,1.82,0.165,0.011,,0.0831234,140.056,,8.31234,0.140056,,,,7.85398e-5
1:1 (rep 2),2-Recover,116.203,1.833,0.152,0.011,,0.0765743,140.056,,7.65743,0.140056,,,,7.85398e-5
1:1 (rep 2),2-Recover,116.57,1.849,0.136,0.011,,0.0685139,140.056,,6.85139,0.140056,,,,7.85398e-5
1:1 (rep 2),2-Recover,116.937,1.863,0.122,0.011,,0.061461,140.056,,6.1461,0.140056,,,,7.85398e-5
1:1 (rep 2),2-Recover,117.303,1.877,0.108,0.011,,0.0544081,140.056,,5.44081,0.140056,,,,7.85398e-5
1:1 (rep 2),2-Recover,117.67,1.892,0.093,0.025,,0.0468514,318.31,,4.68514,0.31831,,,,7.85398e-5
1:1 (rep 2),2-Recover,118.037,1.907,0.078,0.018,,0.0392947,229.183,,3.92947,0.229183,,,,7.85398e-5
1:1 (rep 2),2-Recover,118.403,1.921,0.064,0.018,,0.0322418,229.183,,3.22418,0.229183,,,,7.85398e-5
1:1 (rep 2),2-Recover,118.77,1.936,0.049,0.011,,0.0246851,140.056,,2.46851,0.140056,,,,7.85398e-5
1:1 (rep 2),2-Recover,119.137,1.951,0.034,0.011,,0.0171285,140.056,,1.71285,0.140056,,,,7.85398e-5
1:1 (rep 2),2-Recover,119.503,1.965,0.02,0.011,,0.0100756,140.056,,1.00756,0.140056,,,,7.85398e-5
1:1 (rep 2),2-Recover,119.87,1.98,0.005,0.018,,0.00251889,229.183,,0.251889,0.229183,,,,7.85398e-5
1:1 (rep 2),3-Compress,120.213,1.979,0.006,0.018,,0.00302267,229.183,,0.302267,0.229183,,,,7.85398e-5
1:1 (rep 2),3-Compress,120.58,1.965,0.02,0.018,,0.0100756,229.183,,1.00756,0.229183,,,,7.85398e-5
1:1 (rep 2),3-Compress,120.947,1.95,0.035,0.018,,0.0176322,229.183,,1.76322,0.229183,,,,7.85398e-5
1:1 (rep 2),3-Compress,121.313,1.936,0.049,0.011,,0.0246851,140.056,,2.46851,0.140056,,,,7.85398e-5
1:1 (rep 2),3-Compress,121.68,1.921,0.064,0.011,,0.0322418,140.056,,3.22418,0.140056,,,,7.85398e-5
1:1 (rep 2),3-Compress,122.047,1.906,0.079,0.011,,0.0397985,140.056,,3.97985,0.140056,,,,7.85398e-5
1:1 (rep 2),3-Compress,122.413,1.892,0.093,0.011,,0.0468514,140.056,,4.68514,0.140056,,,,7.85398e-5
1:1 (rep 2),3-Compress,122.78,1.877,0.108,0.018,,0.0544081,229.183,,5.44081,0.229183,,,,7.85398e-5
1:1 (rep 2),3-Compress,123.147,1.863,0.122,0.018,,0.061461,229.183,,6.1461,0.229183,,,,7.85398e-5
1:1 (rep 2),3-Compress,123.513,1.848,0.137,0.018,,0.0690176,229.183,,6.90176,0.229183,,,,7.85398e-5
1:1 (rep 2),3-Compress,123.88,1.833,0.152,0.011,,0.0765743,140.056,,7.65743,0.140056,,,,7.85398e-5
1:1 (rep 2),3-Compress,124.247,1.819,0.166,0.011,,0.0836272,140.056,,8.36272,0.140056,,,,7.85398e-5
1:1 (rep 2),3-Compress,124.613,1.804,0.181,0.011,,0.0911839,140.056,,9.11839,0.140056,,,,7.85398e-5
1:1 (rep 2),3-Compress,124.98,1.79,0.195,0.018,,0.0982368,229.183,,9.82368,0.229183,,,,7.85398e-5
1:1 (rep 2),3-Compress,125.347,1.775,0.21,0.018,,0.105793,229.183,,10.5793,0.229183,,,,7.85398e-5
1:1 (rep 2),3-Compress,125.713,1.761,0.224,0.018,,0.112846,229.183,,11.2846,0.229183,,,,7.85398e-5
1:1 (rep 2),3-Compress,126.08,1.746,0.239,0.018,,0.120403,229.183,,12.0403,0.229183,,,,7.85398e-5
1:1 (rep 2),3-Compress,126.447,1.732,0.253,0.011,,0.127456,140.056,,12.7456,0.140056,,,,7.85398e-5
1:1 (rep 2),3-Compress,126.813,1.717,0.268,0.011,,0.135013,140.056,,13.5013,0.140056,,,,7.85398e-5
1:1 (rep 2),3-Compress,127.18,1.702,0.283,0.011,,0.142569,140.056,,14.2569,0.140056,,,,7.85398e-5
1:1 (rep 2),3-Compress,127.547,1.688,0.297,0.018,,0.149622,229.183,,14.9622,0.229183,,,,7.85398e-5
1:1 (rep 2),3-Compress,127.913,1.673,0.312,0.018,,0.157179,229.183,,15.7179,0.229183,,,,7.85398e-5
1:1 (rep 2),3-Compress,128.28,1.659,0.326,0.018,,0.164232,229.183,,16.4232,0.229183,,,,7.85398e-5
1:1 (rep 2),3-Compress,128.647,1.644,0.341,0.018,,0.171788,229.183,,17.1788,0.229183,,,,7.85398e-5
1:1 (rep 2),3-Compress,129.013,1.63,0.355,0.011,,0.178841,140.056,,17.8841,0.140056,,,,7.85398e-5
1:1 (rep 2),3-Compress,129.38,1.615,0.37,0.011,,0.186398,140.056,,18.6398,0.140056,,,,7.85398e-5
1:1 (rep 2),3-Compress,129.747,1.601,0.384,0.011,,0.193451,140.056,,19.3451,0.140056,,,,7.85398e-5
1:1 (rep 2),3-Compress,130.113,1.586,0.399,0.018,,0.201008,229.183,,20.1008,0.229183,,,,7.85398e-5
1:1 (rep 2),3-Compress,130.48,1.571,0.414,0.025,,0.208564,318.31,,20.8564,0.31831,,,,7.85398e-5
1:1 (rep 2),3-Compress,130.847,1.557,0.428,0.025,,0.215617,318.31,,21.5617,0.31831,,,,7.85398e-5
1:1 (rep 2),3-Compress,131.213,1.542,0.443,0.018,,0.223174,229.183,,22.3174,0.229183,,,,7.85398e-5
1:1 (rep 2),3-Compress,131.58,1.528,0.457,0.011,,0.230227,140.056,,23.0227,0.140056,,,,7.85398e-5
1:1 (rep 2),3-Compress,131.947,1.513,0.472,0.011,,0.237783,140.056,,23.7783,0.140056,,,,7.85398e-5
1:1 (rep 2),3-Compress,132.313,1.499,0.486,0.011,,0.244836,140.056,,24.4836,0.140056,,,,7.85398e-5
1:1 (rep 2),3-Compress,132.68,1.484,0.501,0.018,,0.252393,229.183,,25.2393,0.229183,,,,7.85398e-5
1:1 (rep 2),3-Compress,133.047,1.469,0.516,0.025,,0.25995,318.31,,25.995,0.31831,,,,7.85398e-5
1:1 (rep 2),3-Compress,133.413,1.455,0.53,0.025,,0.267003,318.31,,26.7003,0.31831,,,,7.85398e-5
1:1 (rep 2),3-Compress,133.78,1.44,0.545,0.011,,0.274559,140.056,,27.4559,0.140056,,,,7.85398e-5
1:1 (rep 2),3-Compress,134.147,1.426,0.559,0.011,,0.281612,140.056,,28.1612,0.140056,,,,7.85398e-5
1:1 (rep 2),3-Compress,134.513,1.411,0.574,0.011,,0.289169,140.056,,28.9169,0.140056,,,,7.85398e-5
1:1 (rep 2),3-Compress,134.88,1.397,0.588,0.018,,0.296222,229.183,,29.6222,0.229183,,,,7.85398e-5
1:1 (rep 2),3-Compress,135.247,1.382,0.603,0.018,,0.303778,229.183,,30.3778,0.229183,,,,7.85398e-5
1:1 (rep 2),3-Compress,135.613,1.368,0.617,0.025,,0.310831,318.31,,31.0831,0.31831,,,,7.85398e-5
1:1 (rep 2),3-Compress,135.98,1.353,0.632,0.018,,0.318388,229.183,,31.8388,0.229183,,,,7.85398e-5
1:1 (rep 2),3-Compress,136.347,1.338,0.647,0.011,,0.325945,140.056,,32.5945,0.140056,,,,7.85398e-5
1:1 (rep 2),3-Compress,136.713,1.324,0.661,0.018,,0.332997,229.183,,33.2997,0.229183,,,,7.85398e-5
1:1 (rep 2),3-Compress,137.08,1.309,0.676,0.011,,0.340554,140.056,,34.0554,0.140056,,,,7.85398e-5
1:1 (rep 2),3-Compress,137.447,1.294,0.691,0.018,,0.348111,229.183,,34.8111,0.229183,,,,7.85398e-5
1:1 (rep 2),3-Compress,137.813,1.28,0.705,0.018,,0.355164,229.183,,35.5164,0.229183,,,,7.85398e-5
1:1 (rep 2),3-Compress,138.18,1.265,0.72,0.018,,0.36272,229.183,,36.272,0.229183,,,,7.85398e-5
1:1 (rep 2),3-Compress,138.547,1.251,0.734,0.025,,0.369773,318.31,,36.9773,0.31831,,,,7.85398e-5
1:1 (rep 2),3-Compress,138.913,1.236,0.749,0.011,,0.37733,140.056,,37.733,0.140056,,,,7.85398e-5
1:1 (rep 2),3-Compress,139.28,1.222,0.763,0.018,,0.384383,229.183,,38.4383,0.229183,,,,7.85398e-5
1:1 (rep 2),3-Compress,139.647,1.206,0.779,0.018,,0.392443,229.183,,39.2443,0.229183,,,,7.85398e-5
1:1 (rep 2),3-Compress,140.013,1.193,0.792,0.018,,0.398992,229.183,,39.8992,0.229183,,,,7.85398e-5
1:1 (rep 2),3-Compress,140.38,1.178,0.807,0.018,,0.406549,229.183,,40.6549,0.229183,,,,7.85398e-5
1:1 (rep 2),3-Compress,140.747,1.163,0.822,0.018,,0.414106,229.183,,41.4106,0.229183,,,,7.85398e-5
1:1 (rep 2),3-Compress,141.113,1.149,0.836,0.018,,0.421159,229.183,,42.1159,0.229183,,,,7.85398e-5
1:1 (rep 2),3-Compress,141.48,1.134,0.851,0.018,,0.428715,229.183,,42.8715,0.229183,,,,7.85398e-5
1:1 (rep 2),3-Compress,141.847,1.119,0.866,0.011,,0.436272,140.056,,43.6272,0.140056,,,,7.85398e-5
1:1 (rep 2),3-Compress,142.213,1.105,0.88,0.018,,0.443325,229.183,,44.3325,0.229183,,,,7.85398e-5
1:1 (rep 2),3-Compress,142.58,1.09,0.895,0.018,,0.450882,229.183,,45.0882,0.229183,,,,7.85398e-5
1:1 (rep 2),3-Compress,142.947,1.076,0.909,0.018,,0.457935,229.183,,45.7935,0.229183,,,,7.85398e-5
1:1 (rep 2),3-Compress,143.313,1.061,0.924,0.018,,0.465491,229.183,,46.5491,0.229183,,,,7.85398e-5
1:1 (rep 2),3-Compress,143.68,1.047,0.938,0.038,,0.472544,483.831,,47.2544,0.483831,,,,7.85398e-5
1:1 (rep 2),3-Compress,144.047,1.032,0.953,0.018,,0.480101,229.183,,48.0101,0.229183,,,,7.85398e-5
1:1 (rep 2),3-Compress,144.413,1.018,0.967,0.025,,0.487154,318.31,,48.7154,0.31831,,,,7.85398e-5
1:1 (rep 2),3-Compress,144.78,1.003,0.982,0.018,,0.49471,229.183,,49.471,0.229183,,,,7.85398e-5
1:1 (rep 2),3-Compress,145.147,0.988,0.997,0.018,,0.502267,229.183,,50.2267,0.229183,,,,7.85398e-5
1:1 (rep 2),3-Compress,145.513,0.974,1.011,0.018,,0.50932,229.183,,50.932,0.229183,,,,7.85398e-5
1:1 (rep 2),3-Compress,145.88,0.959,1.026,0.025,,0.516877,318.31,,51.6877,0.31831,,,,7.85398e-5
1:1 (rep 2),3-Compress,146.247,0.944,1.041,0.025,,0.524433,318.31,,52.4433,0.31831,,,,7.85398e-5
1:1 (rep 2),3-Compress,146.613,0.93,1.055,0.025,,0.531486,318.31,,53.1486,0.31831,,,,7.85398e-5
1:1 (rep 2),3-Compress,146.98,0.915,1.07,0.025,,0.539043,318.31,,53.9043,0.31831,,,,7.85398e-5
1:1 (rep 2),3-Compress,147.347,0.901,1.084,0.018,,0.546096,229.183,,54.6096,0.229183,,,,7.85398e-5
1:1 (rep 2),3-Compress,147.713,0.886,1.099,0.018,,0.553652,229.183,,55.3652,0.229183,,,,7.85398e-5
1:1 (rep 2),3-Compress,148.08,0.872,1.113,0.018,,0.560705,229.183,,56.0705,0.229183,,,,7.85398e-5
1:1 (rep 2),3-Compress,148.447,0.857,1.128,0.032,,0.568262,407.437,,56.8262,0.407437,,,,7.85398e-5
1:1 (rep 2),3-Compress,148.813,0.843,1.142,0.032,,0.575315,407.437,,57.5315,0.407437,,,,7.85398e-5
1:1 (rep 2),3-Compress,149.18,0.828,1.157,0.032,,0.582872,407.437,,58.2872,0.407437,,,,7.85398e-5
1:1 (rep 2),3-Compress,149.547,0.813,1.172,0.025,,0.590428,318.31,,59.0428,0.31831,,,,7.85398e-5
1:1 (rep 2),3-Compress,149.913,0.799,1.186,0.018,,0.597481,229.183,,59.7481,0.229183,,,,7.85398e-5
1:1 (rep 2),3-Recover,150.267,0.801,1.184,0.018,,0.596474,229.183,,59.6474,0.229183,,,,7.85398e-5
1:1 (rep 2),3-Recover,150.633,0.816,1.169,0.018,,0.588917,229.183,,58.8917,0.229183,,,,7.85398e-5
1:1 (rep 2),3-Recover,151,0.83,1.155,0.038,,0.581864,483.831,,58.1864,0.483831,,,,7.85398e-5
1:1 (rep 2),3-Recover,151.367,0.845,1.14,0.032,,0.574307,407.437,,57.4307,0.407437,,,,7.85398e-5
1:1 (rep 2),3-Recover,151.733,0.859,1.126,0.025,,0.567254,318.31,,56.7254,0.31831,,,,7.85398e-5
1:1 (rep 2),3-Recover,152.1,0.874,1.111,0.032,,0.559698,407.437,,55.9698,0.407437,,,,7.85398e-5
1:1 (rep 2),3-Recover,152.467,0.889,1.096,0.018,,0.552141,229.183,,55.2141,0.229183,,,,7.85398e-5
1:1 (rep 2),3-Recover,152.833,0.903,1.082,0.018,,0.545088,229.183,,54.5088,0.229183,,,,7.85398e-5
1:1 (rep 2),3-Recover,153.2,0.918,1.067,0.025,,0.537531,318.31,,53.7531,0.31831,,,,7.85398e-5
1:1 (rep 2),3-Recover,153.567,0.933,1.052,0.032,,0.529975,407.437,,52.9975,0.407437,,,,7.85398e-5
1:1 (rep 2),3-Recover,153.933,0.947,1.038,0.038,,0.522922,483.831,,52.2922,0.483831,,,,7.85398e-5
1:1 (rep 2),3-Recover,154.3,0.962,1.023,0.025,,0.515365,318.31,,51.5365,0.31831,,,,7.85398e-5
1:1 (rep 2),3-Recover,154.667,0.976,1.009,0.025,,0.508312,318.31,,50.8312,0.31831,,,,7.85398e-5
1:1 (rep 2),3-Recover,155.033,0.991,0.994,0.018,,0.500756,229.183,,50.0756,0.229183,,,,7.85398e-5
1:1 (rep 2),3-Recover,155.4,1.005,0.98,0.018,,0.493703,229.183,,49.3703,0.229183,,,,7.85398e-5
1:1 (rep 2),3-Recover,155.767,1.02,0.965,0.018,,0.486146,229.183,,48.6146,0.229183,,,,7.85398e-5
1:1 (rep 2),3-Recover,156.133,1.034,0.951,0.025,,0.479093,318.31,,47.9093,0.31831,,,,7.85398e-5
1:1 (rep 2),3-Recover,156.5,1.049,0.936,0.018,,0.471537,229.183,,47.1537,0.229183,,,,7.85398e-5
1:1 (rep 2),3-Recover,156.867,1.064,0.921,0.011,,0.46398,140.056,,46.398,0.140056,,,,7.85398e-5
1:1 (rep 2),3-Recover,157.233,1.078,0.907,0.018,,0.456927,229.183,,45.6927,0.229183,,,,7.85398e-5
1:1 (rep 2),3-Recover,157.6,1.093,0.892,0.011,,0.44937,140.056,,44.937,0.140056,,,,7.85398e-5
1:1 (rep 2),3-Recover,157.967,1.107,0.878,0.018,,0.442317,229.183,,44.2317,0.229183,,,,7.85398e-5
1:1 (rep 2),3-Recover,158.333,1.122,0.863,0.025,,0.434761,318.31,,43.4761,0.31831,,,,7.85398e-5
1:1 (rep 2),3-Recover,158.7,1.137,0.848,0.025,,0.427204,318.31,,42.7204,0.31831,,,,7.85398e-5
1:1 (rep 2),3-Recover,159.067,1.151,0.834,0.025,,0.420151,318.31,,42.0151,0.31831,,,,7.85398e-5
1:1 (rep 2),3-Recover,159.433,1.166,0.819,0.011,,0.412594,140.056,,41.2594,0.140056,,,,7.85398e-5
1:1 (rep 2),3-Recover,159.8,1.18,0.805,0.011,,0.405542,140.056,,40.5542,0.140056,,,,7.85398e-5
1:1 (rep 2),3-Recover,160.167,1.195,0.79,0.011,,0.397985,140.056,,39.7985,0.140056,,,,7.85398e-5
1:1 (rep 2),3-Recover,160.533,1.209,0.776,0.018,,0.390932,229.183,,39.0932,0.229183,,,,7.85398e-5
1:1 (rep 2),3-Recover,160.9,1.224,0.761,0.032,,0.383375,407.437,,38.3375,0.407437,,,,7.85398e-5
1:1 (rep 2),3-Recover,161.267,1.239,0.746,0.018,,0.375819,229.183,,37.5819,0.229183,,,,7.85398e-5
1:1 (rep 2),3-Recover,161.633,1.253,0.732,0.018,,0.368766,229.183,,36.8766,0.229183,,,,7.85398e-5
1:1 (rep 2),3-Recover,162,1.268,0.717,0.011,,0.361209,140.056,,36.1209,0.140056,,,,7.85398e-5
1:1 (rep 2),3-Recover,162.367,1.282,0.703,0.011,,0.354156,140.056,,35.4156,0.140056,,,,7.85398e-5
1:1 (rep 2),3-Recover,162.733,1.297,0.688,0.011,,0.346599,140.056,,34.6599,0.140056,,,,7.85398e-5
1:1 (rep 2),3-Recover,163.1,1.311,0.674,0.025,,0.339547,318.31,,33.9547,0.31831,,,,7.85398e-5
1:1 (rep 2),3-Recover,163.467,1.326,0.659,0.025,,0.33199,318.31,,33.199,0.31831,,,,7.85398e-5
1:1 (rep 2),3-Recover,163.833,1.34,0.645,0.018,,0.324937,229.183,,32.4937,0.229183,,,,7.85398e-5
1:1 (rep 2),3-Recover,164.2,1.355,0.63,0.011,,0.31738,140.056,,31.738,0.140056,,,,7.85398e-5
1:1 (rep 2),3-Recover,164.567,1.37,0.615,0.011,,0.309824,140.056,,30.9824,0.140056,,,,7.85398e-5
1:1 (rep 2),3-Recover,164.933,1.384,0.601,0.011,,0.302771,140.056,,30.2771,0.140056,,,,7.85398e-5
1:1 (rep 2),3-Recover,165.3,1.399,0.586,0.018,,0.295214,229.183,,29.5214,0.229183,,,,7.85398e-5
1:1 (rep 2),3-Recover,165.667,1.414,0.571,0.018,,0.287657,229.183,,28.7657,0.229183,,,,7.85398e-5
1:1 (rep 2),3-Recover,166.033,1.428,0.557,0.025,,0.280605,318.31,,28.0605,0.31831,,,,7.85398e-5
1:1 (rep 2),3-Recover,166.4,1.443,0.542,0.018,,0.273048,229.183,,27.3048,0.229183,,,,7.85398e-5
1:1 (rep 2),3-Recover,166.767,1.457,0.528,0.011,,0.265995,140.056,,26.5995,0.140056,,,,7.85398e-5
1:1 (rep 2),3-Recover,167.133,1.472,0.513,0.011,,0.258438,140.056,,25.8438,0.140056,,,,7.85398e-5
1:1 (rep 2),3-Recover,167.5,1.486,0.499,0.011,,0.251385,140.056,,25.1385,0.140056,,,,7.85398e-5
1:1 (rep 2),3-Recover,167.867,1.501,0.484,0.018,,0.243829,229.183,,24.3829,0.229183,,,,7.85398e-5
1:1 (rep 2),3-Recover,168.233,1.515,0.47,0.018,,0.236776,229.183,,23.6776,0.229183,,,,7.85398e-5
1:1 (rep 2),3-Recover,168.6,1.53,0.455,0.018,,0.229219,229.183,,22.9219,0.229183,,,,7.85398e-5
1:1 (rep 2),3-Recover,168.967,1.545,0.44,0.018,,0.221662,229.183,,22.1662,0.229183,,,,7.85398e-5
1:1 (rep 2),3-Recover,169.333,1.559,0.426,0.011,,0.21461,140.056,,21.461,0.140056,,,,7.85398e-5
1:1 (rep 2),3-Recover,169.7,1.574,0.411,0.011,,0.207053,140.056,,20.7053,0.140056,,,,7.85398e-5
1:1 (rep 2),3-Recover,170.067,1.589,0.396,0.011,,0.199496,140.056,,19.9496,0.140056,,,,7.85398e-5
1:1 (rep 2),3-Recover,170.433,1.603,0.382,0.018,,0.192443,229.183,,19.2443,0.229183,,,,7.85398e-5
1:1 (rep 2),3-Recover,170.8,1.618,0.367,0.018,,0.184887,229.183,,18.4887,0.229183,,,,7.85398e-5
1:1 (rep 2),3-Recover,171.167,1.632,0.353,0.025,,0.177834,318.31,,17.7834,0.31831,,,,7.85398e-5
1:1 (rep 2),3-Recover,171.533,1.647,0.338,0.011,,0.170277,140.056,,17.0277,0.140056,,,,7.85398e-5
1:1 (rep 2),3-Recover,171.9,1.661,0.324,0.011,,0.163224,140.056,,16.3224,0.140056,,,,7.85398e-5
1:1 (rep 2),3-Recover,172.267,1.676,0.309,0.011,,0.155668,140.056,,15.5668,0.140056,,,,7.85398e-5
1:1 (rep 2),3-Recover,172.633,1.69,0.295,0.011,,0.148615,140.056,,14.8615,0.140056,,,,7.85398e-5
1:1 (rep 2),3-Recover,173,1.705,0.28,0.018,,0.141058,229.183,,14.1058,0.229183,,,,7.85398e-5
1:1 (rep 2),3-Recover,173.367,1.72,0.265,0.025,,0.133501,318.31,,13.3501,0.31831,,,,7.85398e-5
1:1 (rep 2),3-Recover,173.733,1.734,0.251,0.025,,0.126448,318.31,,12.6448,0.31831,,,,7.85398e-5
1:1 (rep 2),3-Recover,174.1,1.749,0.236,0.011,,0.118892,140.056,,11.8892,0.140056,,,,7.85398e-5
1:1 (rep 2),3-Recover,174.467,1.764,0.221,0.011,,0.111335,140.056,,11.1335,0.140056,,,,7.85398e-5
1:1 (rep 2),3-Recover,174.833,1.778,0.207,0.011,,0.104282,140.056,,10.4282,0.140056,,,,7.85398e-5
1:1 (rep 2),3-Recover,175.2,1.793,0.192,0.011,,0.0967254,140.056,,9.67254,0.140056,,,,7.85398e-5
1:1 (rep 2),3-Recover,175.567,1.807,0.178,0.018,,0.0896725,229.183,,8.96725,0.229183,,,,7.85398e-5
1:1 (rep 2),3-Recover,175.933,1.822,0.163,0.025,,0.0821159,318.31,,8.21159,0.31831,,,,7.85398e-5
1:1 (rep 2),3-Recover,176.3,1.836,0.149,0.018,,0.075063,229.183,,7.5063,0.229183,,,,7.85398e-5
1:1 (rep 2),3-Recover,176.667,1.851,0.134,0.011,,0.0675063,140.056,,6.75063,0.140056,,,,7.85398e-5
1:1 (rep 2),3-Recover,177.033,1.865,0.12,0.011,,0.0604534,140.056,,6.04534,0.140056,,,,7.85398e-5
1:1 (rep 2),3-Recover,177.4,1.88,0.105,0.011,,0.0528967,140.056,,5.28967,0.140056,,,,7.85398e-5
1:1 (rep 2),3-Recover,177.767,1.895,0.09,0.011,,0.0453401,140.056,,4.53401,0.140056,,,,7.85398e-5
1:1 (rep 2),3-Recover,178.133,1.909,0.076,0.018,,0.0382872,229.183,,3.82872,0.229183,,,,7.85398e-5
1:1 (rep 2),3-Recover,178.5,1.924,0.061,0.018,,0.0307305,229.183,,3.07305,0.229183,,,,7.85398e-5
1:1 (rep 2),3-Recover,178.867,1.938,0.047,0.025,,0.0236776,318.31,,2.36776,0.31831,,,,7.85398e-5
1:1 (rep 2),3-Recover,179.233,1.953,0.032,0.011,,0.0161209,140.056,,1.61209,0.140056,,,,7.85398e-5
1:1 (rep 2),3-Recover,179.6,1.967,0.018,0.011,,0.00906801,140.056,,0.906801,0.140056,,,,7.85398e-5
1:1 (rep 2),3-Recover,179.967,1.982,0.003,0.011,,0.00151134,140.056,,0.151134,0.140056,,,,7.85398e-5
1:1 (rep 2),3-Recover,180.1,1.985,0,0.025,,0,318.31,,0,0.31831,,,,7.85398e-5