File: data/beta_1-1-1_11.csv
SetName,Cycle,Time_S,Size_mm,Displacement_mm,Force_N,,Strain,Stress(Pascal),,%Strain,Stress(kPa),,,,Area(m^2)
1:1 (rep 1),1-Compress,0,2.698,0,-0.004,,0,-50.9296,,0,-0.0509296,,,,7.85398e-5
1:1 (rep 1),1-Compress,0.367,2.678,0.02,0.009,,0.0074129,114.592,,0.74129,0.114592,,,,7.85398e-5
1:1 (rep 1),1-Compress,0.733,2.659,0.039,0.002,,0.0144552,25.4648,,1.44552,0.0254648,,,,7.85398e-5
1:1 (rep 1),1-Compress,1.1,2.639,0.059,0.03,,0.0218681,381.972,,2.18681,0.381972,,,,7.85398e-5
1:1 (rep 1),1-Compress,1.467,2.619,0.079,0.036,,0.0292809,458.366,,2.92809,0.458366,,,,7.85398e-5
1:1 (rep 1),1-Compress,1.833,2.599,0.099,0.036,,0.0366938,458.366,,3.66938,0.458366,,,,7.85398e-5
1:1 (rep 1),1-Compress,2.2,2.579,0.119,0.036,,0.0441067,458.366,,4.41067,0.458366,,,,7.85398e-5
1:1 (rep 1),1-Compress,2.567,2.559,0.139,0.043,,0.0515196,547.493,,5.15196,0.547493,,,,7.85398e-5
1:1 (rep 1),1-Compress,2.933,2.54,0.158,0.036,,0.0585619,458.366,,5.85619,0.458366,,,,7.85398e-5
1:1 (rep 1),1-Compress,3.3,2.52,0.178,0.023,,0.0659748,292.845,,6.59748,0.292845,,,,7.85398e-5
1:1 (rep 1),1-Compress,3.667,2.5,0.198,0.016,,0.0733877,203.718,,7.33877,0.203718,,,,7.85398e-5
1:1 (rep 1),1-Compress,4.033,2.481,0.217,0.03,,0.0804299,381.972,,8.04299,0.381972,,,,7.85398e-5
1:1 (rep 1),1-Compress,4.4,2.46,0.238,0.036,,0.0882135,458.366,,8.82135,0.458366,,,,7.85398e-5
1:1 (rep 1),1-Compress,4.767,2.44,0.258,0.036,,0.0956264,458.366,,9.56264,0.458366,,,,7.85398e-5
1:1 (rep 1),1-Compress,5.133,2.421,0.277,0.036,,0.102669,458.366,,10.2669,0.458366,,,,7.85398e-5
1:1 (rep 1),1-Compress,5.5,2.401,0.297,0.043,,0.110082,547.493,,11.0082,0.547493,,,,7.85398e-5
1:1 (rep 1),1-Compress,5.867,2.381,0.317,0.03,,0.117494,381.972,,11.7494,0.381972,,,,7.85398e-5
1:1 (rep 1),1-Compress,6.233,2.361,0.337,0.043,,0.124907,547.493,,12.4907,0.547493,,,,7.85398e-5
1:1 (rep 1),1-Compress,6.6,2.341,0.357,0.036,,0.13232,458.366,,13.232,0.458366,,,,7.85398e-5
1:1 (rep 1),1-Compress,6.967,2.322,0.376,0.043,,0.139362,547.493,,13.9362,0.547493,,,,7.85398e-5
1:1 (rep 1),1-Compress,7.333,2.302,0.396,0.05,,0.146775,636.62,,14.6775,0.63662,,,,7.85398e-5
1:1 (rep 1),1-Compress,7.7,2.282,0.416,0.043,,0.154188,547.493,,15.4188,0.547493,,,,7.85398e-5
1:1 (rep 1),1-Compress,8.067,2.262,0.436,0.05,,0.161601,636.62,,16.1601,0.63662,,,,7.85398e-5
1:1 (rep 1),1-Compress,8.433,2.242,0.456,0.05,,0.169014,636.62,,16.9014,0.63662,,,,7.85398e-5
1:1 (rep 1),1-Compress,8.8,2.223,0.475,0.043,,0.176056,547.493,,17.6056,0.547493,,,,7.85398e-5
1:1 (rep 1),1-Compress,9.167,2.203,0.495,0.05,,0.183469,636.62,,18.3469,0.63662,,,,7.85398e-5
1:1 (rep 1),1-Compress,9.533,2.183,0.515,0.05,,0.190882,636.62,,19.0882,0.63662,,,,7.85398e-5
1:1 (rep 1),1-Compress,9.9,2.163,0.535,0.05,,0.198295,636.62,,19.8295,0.63662,,,,7.85398e-5
1:1 (rep 1),1-Compress,10.267,2.143,0.555,0.043,,0.205708,547.493,,20.5708,0.547493,,,,7.85398e-5
1:1 (rep 1),1-Compress,10.633,2.124,0.574,0.05,,0.21275,636.62,,21.275,0.63662,,,,7.85398e-5
1:1 (rep 1),1-Compress,11,2.104,0.594,0.043,,0.220163,547.493,,22.0163,0.547493,,,,7.85398e-5
1:1 (rep 1),1-Compress,11.367,2.083,0.615,0.05,,0.227947,636.62,,22.7947,0.63662,,,,7.85398e-5
1:1 (rep 1),1-Compress,11.733,2.064,0.634,0.05,,0.234989,636.62,,23.4989,0.63662,,,,7.85398e-5
1:1 (rep 1),1-Compress,12.1,2.044,0.654,0.05,,0.242402,636.62,,24.2402,0.63662,,,,7.85398e-5
1:1 (rep 1),1-Compress,12.467,2.024,0.674,0.05,,0.249815,636.62,,24.9815,0.63662,,,,7.85398e-5
1:1 (rep 1),1-Compress,12.833,2.005,0.693,0.05,,0.256857,636.62,,25.6857,0.63662,,,,7.85398e-5
1:1 (rep 1),1-Compress,13.2,1.985,0.713,0.05,,0.26427,636.62,,26.427,0.63662,,,,7.85398e-5
1:1 (rep 1),1-Compress,13.567,1.964,0.734,0.05,,0.272053,636.62,,27.2053,0.63662,,,,7.85398e-5
1:1 (rep 1),1-Compress,13.933,1.945,0.753,0.05,,0.279096,636.62,,27.9096,0.63662,,,,7.85398e-5
1:1 (rep 1),1-Compress,14.3,1.925,0.773,0.05,,0.286509,636.62,,28.6509,0.63662,,,,7.85398e-5
1:1 (rep 1),1-Compress,14.667,1.905,0.793,0.05,,0.293921,636.62,,29.3921,0.63662,,,,7.85398e-5
1:1 (rep 1),1-Compress,15.033,1.886,0.812,0.05,,0.300964,636.62,,30.0964,0.63662,,,,7.85398e-5
1:1 (rep 1),1-Compress,15.4,1.865,0.833,0.05,,0.308747,636.62,,30.8747,0.63662,,,,7.85398e-5
1:1 (rep 1),1-Compress,15.767,1.846,0.852,0.05,,0.315789,636.62,,31.5789,0.63662,,,,7.85398e-5
1:1 (rep 1),1-Compress,16.133,1.826,0.872,0.057,,0.323202,725.747,,32.3202,0.725747,,,,7.85398e-5
1:1 (rep 1),1-Compress,16.5,1.806,0.892,0.05,,0.330615,636.62,,33.0615,0.63662,,,,7.85398e-5
1:1 (rep 1),1-Compress,16.867,1.786,0.912,0.05,,0.338028,636.62,,33.8028,0.63662,,,,7.85398e-5
1:1 (rep 1),1-Compress,17.233,1.766,0.932,0.05,,0.345441,636.62,,34.5441,0.63662,,,,7.85398e-5
1:1 (rep 1),1-Compress,17.6,1.747,0.951,0.05,,0.352483,636.62,,35.2483,0.63662,,,,7.85398e-5
1:1 (rep 1),1-Compress,17.967,1.727,0.971,0.05,,0.359896,636.62,,35.9896,0.63662,,,,7.85398e-5
1:1 (rep 1),1-Compress,18.333,1.707,0.991,0.05,,0.367309,636.62,,36.7309,0.63662,,,,7.85398e-5
1:1 (rep 1),1-Compress,18.7,1.687,1.011,0.057,,0.374722,725.747,,37.4722,0.725747,,,,7.85398e-5
1:1 (rep 1),1-Compress,19.067,1.667,1.031,0.05,,0.382135,636.62,,38.2135,0.63662,,,,7.85398e-5
1:1 (rep 1),1-Compress,19.433,1.648,1.05,0.05,,0.389177,636.62,,38.9177,0.63662,,,,7.85398e-5
1:1 (rep 1),1-Compress,19.8,1.628,1.07,0.05,,0.39659,636.62,,39.659,0.63662,,,,7.85398e-5
1:1 (rep 1),1-Compress,20.167,1.608,1.09,0.05,,0.404003,636.62,,40.4003,0.63662,,,,7.85398e-5
1:1 (rep 1),1-Compress,20.533,1.588,1.11,0.05,,0.411416,636.62,,41.1416,0.63662,,,,7.85398e-5
1:1 (rep 1),1-Compress,20.9,1.568,1.13,0.05,,0.418829,636.62,,41.8829,0.63662,,,,7.85398e-5
1:1 (rep 1),1-Compress,21.267,1.548,1.15,0.05,,0.426242,636.62,,42.6242,0.63662,,,,7.85398e-5
1:1 (rep 1),1-Compress,21.633,1.529,1.169,0.057,,0.433284,725.747,,43.3284,0.725747,,,,7.85398e-5
1:1 (rep 1),1-Compress,22,1.509,1.189,0.05,,0.440697,636.62,,44.0697,0.63662,,,,7.85398e-5
1:1 (rep 1),1-Compress,22.367,1.489,1.209,0.057,,0.44811,725.747,,44.811,0.725747,,,,7.85398e-5
1:1 (rep 1),1-Compress,22.733,1.469,1.229,0.05,,0.455523,636.62,,45.5523,0.63662,,,,7.85398e-5
1:1 (rep 1),1-Compress,23.1,1.45,1.248,0.05,,0.462565,636.62,,46.2565,0.63662,,,,7.85398e-5
1:1 (rep 1),1-Compress,23.467,1.429,1.269,0.05,,0.470348,636.62,,47.0348,0.63662,,,,7.85398e-5
1:1 (rep 1),1-Compress,23.833,1.41,1.288,0.057,,0.477391,725.747,,47.7391,0.725747,,,,7.85398e-5
1:1 (rep 1),1-Compress,24.2,1.39,1.308,0.064,,0.484804,814.873,,48.4804,0.814873,,,,7.85398e-5
1:1 (rep 1),1-Compress,24.567,1.37,1.328,0.07,,0.492216,891.268,,49.2216,0.891268,,,,7.85398e-5
1:1 (rep 1),1-Compress,24.933,1.351,1.347,0.064,,0.499259,814.873,,49.9259,0.814873,,,,7.85398e-5
1:1 (rep 1),1-Compress,25.3,1.331,1.367,0.057,,0.506672,725.747,,50.6672,0.725747,,,,7.85398e-5
1:1 (rep 1),1-Compress,25.667,1.31,1.388,0.05,,0.514455,636.62,,51.4455,0.63662,,,,7.85398e-5
1:1 (rep 1),1-Compress,26.033,1.291,1.407,0.05,,0.521497,636.62,,52.1497,0.63662,,,,7.85398e-5
1:1 (rep 1),1-Compress,26.4,1.271,1.427,0.077,,0.52891,980.395,,52.891,0.980395,,,,7.85398e-5
1:1 (rep 1),1-Compress,26.767,1.251,1.447,0.07,,0.536323,891.268,,53.6323,0.891268,,,,7.85398e-5
1:1 (rep 1),1-Compress,27.133,1.232,1.466,0.07,,0.543365,891.268,,54.3365,0.891268,,,,7.85398e-5
1:1 (rep 1),1-Compress,27.5,1.211,1.487,0.064,,0.551149,814.873,,55.1149,0.814873,,,,7.85398e-5
1:1 (rep 1),1-Compress,27.867,1.192,1.506,0.057,,0.558191,725.747,,55.8191,0.725747,,,,7.85398e-5
1:1 (rep 1),1-Compress,28.233,1.172,1.526,0.057,,0.565604,725.747,,56.5604,0.725747,,,,7.85398e-5
1:1 (rep 1),1-Compress,28.6,1.152,1.546,0.07,,0.573017,891.268,,57.3017,0.891268,,,,7.85398e-5
1:1 (rep 1),1-Compress,28.967,1.132,1.566,0.084,,0.58043,1069.52,,58.043,1.06952,,,,7.85398e-5
1:1 (rep 1),1-Compress,29.333,1.112,1.586,0.077,,0.587843,980.395,,58.7843,0.980395,,,,7.85398e-5
1:1 (rep 1),1-Compress,29.7,1.093,1.605,0.091,,0.594885,1158.65,,59.4885,1.15865,,,,7.85398e-5
1:1 (rep 1),1-Recover,30.067,1.081,1.617,0.077,,0.599333,980.395,,59.9333,0.980395,,,,7.85398e-5
1:1 (rep 1),1-Recover,30.433,1.101,1.597,0.064,,0.59192,814.873,,59.192,0.814873,,,,7.85398e-5
1:1 (rep 1),1-Recover,30.8,1.121,1.577,0.057,,0.584507,725.747,,58.4507,0.725747,,,,7.85398e-5
1:1 (rep 1),1-Recover,31.167,1.14,1.558,0.07,,0.577465,891.268,,57.7465,0.891268,,,,7.85398e-5
1:1 (rep 1),1-Recover,31.533,1.16,1.538,0.07,,0.570052,891.268,,57.0052,0.891268,,,,7.85398e-5
1:1 (rep 1),1-Recover,31.9,1.18,1.518,0.064,,0.562639,814.873,,56.2639,0.814873,,,,7.85398e-5
1:1 (rep 1),1-Recover,32.267,1.2,1.498,0.064,,0.555226,814.873,,55.5226,0.814873,,,,7.85398e-5
1:1 (rep 1),1-Recover,32.633,1.22,1.478,0.057,,0.547813,725.747,,54.7813,0.725747,,,,7.85398e-5
1:1 (rep 1),1-Recover,33,1.239,1.459,0.057,,0.540771,725.747,,54.0771,0.725747,,,,7.85398e-5
1:1 (rep 1),1-Recover,33.367,1.26,1.438,0.05,,0.532987,636.62,,53.2987,0.63662,,,,7.85398e-5
1:1 (rep 1),1-Recover,33.733,1.279,1.419,0.057,,0.525945,725.747,,52.5945,0.725747,,,,7.85398e-5
1:1 (rep 1),1-Recover,34.1,1.299,1.399,0.05,,0.518532,636.62,,51.8532,0.63662,,,,7.85398e-5
1:1 (rep 1),1-Recover,34.467,1.319,1.379,0.05,,0.511119,636.62,,51.1119,0.63662,,,,7.85398e-5
1:1 (rep 1),1-Recover,34.833,1.338,1.36,0.057,,0.504077,725.747,,50.4077,0.725747,,,,7.85398e-5
1:1 (rep 1),1-Recover,35.2,1.358,1.34,0.05,,0.496664,636.62,,49.6664,0.63662,,,,7.85398e-5
1:1 (rep 1),1-Recover,35.567,1.379,1.319,0.05,,0.488881,636.62,,48.8881,0.63662,,,,7.85398e-5
1:1 (rep 1),1-Recover,35.933,1.398,1.3,0.05,,0.481838,636.62,,48.1838,0.63662,,,,7.85398e-5
1:1 (rep 1),1-Recover,36.3,1.418,1.28,0.05,,0.474426,636.62,,47.4426,0.63662,,,,7.85398e-5
1:1 (rep 1),1-Recover,36.667,1.438,1.26,0.05,,0.467013,636.62,,46.7013,0.63662,,,,7.85398e-5
1:1 (rep 1),1-Recover,37.033,1.457,1.241,0.05,,0.45997,636.62,,45.997,0.63662,,,,7.85398e-5
1:1 (rep 1),1-Recover,37.4,1.478,1.22,0.05,,0.452187,636.62,,45.2187,0.63662,,,,7.85398e-5
1:1 (rep 1),1-Recover,37.767,1.498,1.2,0.05,,0.444774,636.62,,44.4774,0.63662,,,,7.85398e-5
1:1 (rep 1),1-Recover,38.133,1.517,1.181,0.05,,0.437732,636.62,,43.7732,0.63662,,,,7.85398e-5
1:1 (rep 1),1-Recover,38.5,1.537,1.161,0.05,,0.430319,636.62,,43.0319,0.63662,,,,7.85398e-5
1:1 (rep 1),1-Recover,38.867,1.557,1.141,0.05,,0.422906,636.62,,42.2906,0.63662,,,,7.85398e-5
1:1 (rep 1),1-Recover,39.233,1.577,1.121,0.05,,0.415493,636.62,,41.5493,0.63662,,,,7.85398e-5
1:1 (rep 1),1-Recover,39.6,1.597,1.101,0.05,,0.40808,636.62,,40.808,0.63662,,,,7.85398e-5
1:1 (rep 1),1-Recover,39.967,1.616,1.082,0.05,,0.401038,636.62,,40.1038,0.63662,,,,7.85398e-5
1:1 (rep 1),1-Recover,40.333,1.636,1.062,0.05,,0.393625,636.62,,39.3625,0.63662,,,,7.85398e-5
1:1 (rep 1),1-Recover,40.7,1.656,1.042,0.05,,0.386212,636.62,,38.6212,0.63662,,,,7.85398e-5
1:1 (rep 1),1-Recover,41.067,1.676,1.022,0.05,,0.378799,636.62,,37.8799,0.63662,,,,7.85398e-5
1:1 (rep 1),1-Recover,41.433,1.696,1.002,0.05,,0.371386,636.62,,37.1386,0.63662,,,,7.85398e-5
1:1 (rep 1),1-Recover,41.8,1.715,0.983,0.05,,0.364344,636.62,,36.4344,0.63662,,,,7.85398e-5
1:1 (rep 1),1-Recover,42.167,1.735,0.963,0.05,,0.356931,636.62,,35.6931,0.63662,,,,7.85398e-5
1:1 (rep 1),1-Recover,42.533,1.755,0.943,0.05,,0.349518,636.62,,34.9518,0.63662,,,,7.85398e-5
1:1 (rep 1),1-Recover,42.9,1.775,0.923,0.05,,0.342105,636.62,,34.2105,0.63662,,,,7.85398e-5
1:1 (rep 1),1-Recover,43.267,1.795,0.903,0.05,,0.334692,636.62,,33.4692,0.63662,,,,7.85398e-5
1:1 (rep 1),1-Recover,43.633,1.814,0.884,0.05,,0.32765,636.62,,32.765,0.63662,,,,7.85398e-5
1:1 (rep 1),1-Recover,44,1.834,0.864,0.05,,0.320237,636.62,,32.0237,0.63662,,,,7.85398e-5
1:1 (rep 1),1-Recover,44.367,1.855,0.843,0.05,,0.312454,636.62,,31.2454,0.63662,,,,7.85398e-5
1:1 (rep 1),1-Recover,44.733,1.874,0.824,0.043,,0.305411,547.493,,30.5411,0.547493,,,,7.85398e-5
1:1 (rep 1),1-Recover,45.1,1.894,0.804,0.043,,0.297999,547.493,,29.7999,0.547493,,,,7.85398e-5
1:1 (rep 1),1-Recover,45.467,1.914,0.784,0.036,,0.290586,458.366,,29.0586,0.458366,,,,7.85398e-5
1:1 (rep 1),1-Recover,45.833,1.933,0.765,0.05,,0.283543,636.62,,28.3543,0.63662,,,,7.85398e-5
1:1 (rep 1),1-Recover,46.2,1.953,0.745,0.043,,0.27613,547.493,,27.613,0.547493,,,,7.85398e-5
1:1 (rep 1),1-Recover,46.567,1.973,0.725,0.043,,0.268718,547.493,,26.8718,0.547493,,,,7.85398e-5
1:1 (rep 1),1-Recover,46.933,1.993,0.705,0.043,,0.261305,547.493,,26.1305,0.547493,,,,7.85398e-5
1:1 (rep 1),1-Recover,47.3,2.013,0.685,0.036,,0.253892,458.366,,25.3892,0.458366,,,,7.85398e-5
1:1 (rep 1),1-Recover,47.667,2.033,0.665,0.023,,0.246479,292.845,,24.6479,0.292845,,,,7.85398e-5
1:1 (rep 1),1-Recover,48.033,2.052,0.646,0.036,,0.239437,458.366,,23.9437,0.458366,,,,7.85398e-5
1:1 (rep 1),1-Recover,48.4,2.072,0.626,0.009,,0.232024,114.592,,23.2024,0.114592,,,,7.85398e-5
1:1 (rep 1),1-Recover,48.767,2.092,0.606,0.043,,0.224611,547.493,,22.4611,0.547493,,,,7.85398e-5
1:1 (rep 1),1-Recover,49.133,2.111,0.587,0.03,,0.217569,381.972,,21.7569,0.381972,,,,7.85398e-5
1:1 (rep 1),1-Recover,49.5,2.132,0.566,0.03,,0.209785,381.972,,20.9785,0.381972,,,,7.85398e-5
1:1 (rep 1),1-Recover,49.867,2.152,0.546,0.023,,0.202372,292.845,,20.2372,0.292845,,,,7.85398e-5
1:1 (rep 1),1-Recover,50.233,2.171,0.527,0.023,,0.19533,292.845,,19.533,0.292845,,,,7.85398e-5
1:1 (rep 1),1-Recover,50.6,2.191,0.507,0.002,,0.187917,25.4648,,18.7917,0.0254648,,,,7.85398e-5
1:1 (rep 1),1-Recover,50.967,2.211,0.487,0.023,,0.180504,292.845,,18.0504,0.292845,,,,7.85398e-5
1:1 (rep 1),1-Recover,51.333,2.231,0.467,0.03,,0.173091,381.972,,17.3091,0.381972,,,,7.85398e-5
1:1 (rep 1),1-Recover,51.7,2.251,0.447,0.03,,0.165678,381.972,,16.5678,0.381972,,,,7.85398e-5
1:1 (rep 1),1-Recover,52.067,2.27,0.428,0.03,,0.158636,381.972,,15.8636,0.381972,,,,7.85398e-5
1:1 (rep 1),1-Recover,52.433,2.29,0.408,0.016,,0.151223,203.718,,15.1223,0.203718,,,,7.85398e-5
1:1 (rep 1),1-Recover,52.8,2.31,0.388,0.002,,0.14381,25.4648,,14.381,0.0254648,,,,7.85398e-5
1:1 (rep 1),1-Recover,53.167,2.33,0.368,0.009,,0.136397,114.592,,13.6397,0.114592,,,,7.85398e-5
1:1 (rep 1),1-Recover,53.533,2.35,0.348,0.009,,0.128984,114.592,,12.8984,0.114592,,,,7.85398e-5
1:1 (rep 1),1-Recover,53.9,2.369,0.329,0.023,,0.121942,292.845,,12.1942,0.292845,,,,7.85398e-5
1:1 (rep 1),1-Recover,54.267,2.389,0.309,0.023,,0.114529,292.845,,11.4529,0.292845,,,,7.85398e-5
1:1 (rep 1),1-Recover,54.633,2.409,0.289,0.023,,0.107116,292.845,,10.7116,0.292845,,,,7.85398e-5
1:1 (rep 1),1-Recover,55,2.429,0.269,0.009,,0.0997035,114.592,,9.97035,0.114592,,,,7.85398e-5
1:1 (rep 1),1-Recover,55.367,2.449,0.249,0.002,,0.0922906,25.4648,,9.22906,0.0254648,,,,7.85398e-5
1:1 (rep 1),1-Recover,55.733,2.468,0.23,0.002,,0.0852483,25.4648,,8.52483,0.0254648,,,,7.85398e-5
1:1 (rep 1),1-Recover,56.1,2.488,0.21,0.009,,0.0778354,114.592,,7.78354,0.114592,,,,7.85398e-5
1:1 (rep 1),1-Recover,56.467,2.509,0.189,0.016,,0.0700519,203.718,,7.00519,0.203718,,,,7.85398e-5
1:1 (rep 1),1-Recover,56.833,2.528,0.17,0.023,,0.0630096,292.845,,6.30096,0.292845,,,,7.85398e-5
1:1 (rep 1),1-Recover,57.2,2.548,0.15,0.009,,0.0555967,114.592,,5.55967,0.114592,,,,7.85398e-5
1:1 (rep 1),1-Recover,57.567,2.568,0.13,0.009,,0.0481838,114.592,,4.81838,0.114592,,,,7.85398e-5
1:1 (rep 1),1-Recover,57.933,2.587,0.111,0.002,,0.0411416,25.4648,,4.11416,0.0254648,,,,7.85398e-5
1:1 (rep 1),1-Recover,58.3,2.607,0.091,0.002,,0.0337287,25.4648,,3.37287,0.0254648,,,,7.85398e-5
1:1 (rep 1),1-Recover,58.667,2.627,0.071,0.009,,0.0263158,114.592,,2.63158,0.114592,,,,7.85398e-5
1:1 (rep 1),1-Recover,59.033,2.647,0.051,0.016,,0.0189029,203.718,,1.89029,0.203718,,,,7.85398e-5
1:1 (rep 1),1-Recover,59.4,2.667,0.031,0.016,,0.01149,203.718,,1.149,0.203718,,,,7.85398e-5
1:1 (rep 1),1-Recover,59.767,2.687,0.011,0.002,,0.00407709,25.4648,,0.407709,0.0254648,,,,7.85398e-5
1:1 (rep 1),2-Compress,60.117,2.693,0.005,0.009,,0.00185322,114.592,,0.185322,0.114592,,,,7.85398e-5
1:1 (rep 1),2-Compress,60.483,2.674,0.024,0.002,,0.00889548,25.4648,,0.889548,0.0254648,,,,7.85398e-5
1:1 (rep 1),2-Compress,60.85,2.654,0.044,0.002,,0.0163084,25.4648,,1.63084,0.0254648,,,,7.85398e-5
1:1 (rep 1),2-Compress,61.217,2.634,0.064,0.009,,0.0237213,114.592,,2.37213,0.114592,,,,7.85398e-5
1:1 (rep 1),2-Compress,61.583,2.615,0.083,0.009,,0.0307635,114.592,,3.07635,0.114592,,,,7.85398e-5
1:1 (rep 1),2-Compress,61.95,2.594,0.104,0.03,,0.0385471,381.972,,3.85471,0.381972,,,,7.85398e-5
1:1 (rep 1),2-Compress,62.317,2.575,0.123,0.009,,0.0455893,114.592,,4.55893,0.114592,,,,7.85398e-5
1:1 (rep 1),2-Compress,62.683,2.555,0.143,0.016,,0.0530022,203.718,,5.30022,0.203718,,,,7.85398e-5
1:1 (rep 1),2-Compress,63.05,2.535,0.163,0.002,,0.0604151,25.4648,,6.04151,0.0254648,,,,7.85398e-5
1:1 (rep 1),2-Compress,63.417,2.515,0.183,0.002,,0.067828,25.4648,,6.7828,0.0254648,,,,7.85398e-5
1:1 (rep 1),2-Compress,63.783,2.495,0.203,0.009,,0.0752409,114.592,,7.52409,0.114592,,,,7.85398e-5
1:1 (rep 1),2-Compress,64.15,2.476,0.222,0.023,,0.0822832,292.845,,8.22832,0.292845,,,,7.85398e-5
1:1 (rep 1),2-Compress,64.517,2.456,0.242,0.03,,0.0896961,381.972,,8.96961,0.381972,,,,7.85398e-5
1:1 (rep 1),2-Compress,64.883,2.436,0.262,0.023,,0.097109,292.845,,9.7109,0.292845,,,,7.85398e-5
1:1 (rep 1),2-Compress,65.25,2.416,0.282,0.009,,0.104522,114.592,,10.4522,0.114592,,,,7.85398e-5
1:1 (rep 1),2-Compress,65.617,2.396,0.302,0.016,,0.111935,203.718,,11.1935,0.203718,,,,7.85398e-5
1:1 (rep 1),2-Compress,65.983,2.377,0.321,0.002,,0.118977,25.4648,,11.8977,0.0254648,,,,7.85398e-5
1:1 (rep 1),2-Compress,66.35,2.357,0.341,0.03,,0.12639,381.972,,12.639,0.381972,,,,7.85398e-5
1:1 (rep 1),2-Compress,66.717,2.337,0.361,0.03,,0.133803,381.972,,13.3803,0.381972,,,,7.85398e-5
1:1 (rep 1),2-Compress,67.083,2.317,0.381,0.03,,0.141216,381.972,,14.1216,0.381972,,,,7.85398e-5
1:1 (rep 1),2-Compress,67.45,2.297,0.401,0.03,,0.148629,381.972,,14.8629,0.381972,,,,7.85398e-5
1:1 (rep 1),2-Compress,67.817,2.277,0.421,0.023,,0.156042,292.845,,15.6042,0.292845,,,,7.85398e-5
1:1 (rep 1),2-Compress,68.183,2.258,0.44,0.023,,0.163084,292.845,,16.3084,0.292845,,,,7.85398e-5
1:1 (rep 1),2-Compress,68.55,2.238,0.46,0.016,,0.170497,203.718,,17.0497,0.203718,,,,7.85398e-5
1:1 (rep 1),2-Compress,68.917,2.218,0.48,0.023,,0.17791,292.845,,17.791,0.292845,,,,7.85398e-5
1:1 (rep 1),2-Compress,69.283,2.198,0.5,0.03,,0.185322,381.972,,18.5322,0.381972,,,,7.85398e-5
1:1 (rep 1),2-Compress,69.65,2.179,0.519,0.036,,0.192365,458.366,,19.2365,0.458366,,,,7.85398e-5
1:1 (rep 1),2-Compress,70.017,2.158,0.54,0.05,,0.200148,636.62,,20.0148,0.63662,,,,7.85398e-5
1:1 (rep 1),2-Compress,70.383,2.139,0.559,0.036,,0.207191,458.366,,20.7191,0.458366,,,,7.85398e-5
1:1 (rep 1),2-Compress,70.75,2.119,0.579,0.023,,0.214603,292.845,,21.4603,0.292845,,,,7.85398e-5
1:1 (rep 1),2-Compress,71.117,2.099,0.599,0.036,,0.222016,458.366,,22.2016,0.458366,,,,7.85398e-5
1:1 (rep 1),2-Compress,71.483,2.08,0.618,0.036,,0.229059,458.366,,22.9059,0.458366,,,,7.85398e-5
1:1 (rep 1),2-Compress,71.85,2.059,0.639,0.05,,0.236842,636.62,,23.6842,0.63662,,,,7.85398e-5
1:1 (rep 1),2-Compress,72.217,2.039,0.659,0.05,,0.244255,636.62,,24.4255,0.63662,,,,7.85398e-5
1:1 (rep 1),2-Compress,72.583,2.02,0.678,0.05,,0.251297,636.62,,25.1297,0.63662,,,,7.85398e-5
1:1 (rep 1),2-Compress,72.95,2,0.698,0.05,,0.25871,636.62,,25.871,0.63662,,,,7.85398e-5
1:1 (rep 1),2-Compress,73.317,1.98,0.718,0.043,,0.266123,547.493,,26.6123,0.547493,,,,7.85398e-5
1:1 (rep 1),2-Compress,73.683,1.961,0.737,0.05,,0.273165,636.62,,27.3165,0.63662,,,,7.85398e-5
1:1 (rep 1),2-Compress,74.05,1.94,0.758,0.05,,0.280949,636.62,,28.0949,0.63662,,,,7.85398e-5
1:1 (rep 1),2-Compress,74.417,1.921,0.777,0.05,,0.287991,636.62,,28.7991,0.63662,,,,7.85398e-5
1:1 (rep 1),2-Compress,74.783,1.901,0.797,0.05,,0.295404,636.62,,29.5404,0.63662,,,,7.85398e-5
1:1 (rep 1),2-Compress,75.15,1.881,0.817,0.05,,0.302817,636.62,,30.2817,0.63662,,,,7.85398e-5
1:1 (rep 1),2-Compress,75.517,1.861,0.837,0.05,,0.31023,636.62,,31.023,0.63662,,,,7.85398e-5
1:1 (rep 1),2-Compress,75.883,1.841,0.857,0.05,,0.317643,636.62,,31.7643,0.63662,,,,7.85398e-5
1:1 (rep 1),2-Compress,76.25,1.822,0.876,0.05,,0.324685,636.62,,32.4685,0.63662,,,,7.85398e-5
1:1 (rep 1),2-Compress,76.617,1.802,0.896,0.05,,0.332098,636.62,,33.2098,0.63662,,,,7.85398e-5
1:1 (rep 1),2-Compress,76.983,1.782,0.916,0.05,,0.339511,636.62,,33.9511,0.63662,,,,7.85398e-5
1:1 (rep 1),2-Compress,77.35,1.762,0.936,0.05,,0.346924,636.62,,34.6924,0.63662,,,,7.85398e-5
1:1 (rep 1),2-Compress,77.717,1.742,0.956,0.05,,0.354337,636.62,,35.4337,0.63662,,,,7.85398e-5
1:1 (rep 1),2-Compress,78.083,1.723,0.975,0.05,,0.361379,636.62,,36.1379,0.63662,,,,7.85398e-5
1:1 (rep 1),2-Compress,78.45,1.703,0.995,0.05,,0.368792,636.62,,36.8792,0.63662,,,,7.85398e-5
1:1 (rep 1),2-Compress,78.817,1.683,1.015,0.05,,0.376205,636.62,,37.6205,0.63662,,,,7.85398e-5
1:1 (rep 1),2-Compress,79.183,1.663,1.035,0.05,,0.383617,636.62,,38.3617,0.63662,,,,7.85398e-5
1:1 (rep 1),2-Compress,79.55,1.643,1.055,0.05,,0.39103,636.62,,39.103,0.63662,,,,7.85398e-5
1:1 (rep 1),2-Compress,79.917,1.623,1.075,0.05,,0.398443,636.62,,39.8443,0.63662,,,,7.85398e-5
1:1 (rep 1),2-Compress,80.283,1.604,1.094,0.05,,0.405486,636.62,,40.5486,0.63662,,,,7.85398e-5
1:1 (rep 1),2-Compress,80.65,1.584,1.114,0.05,,0.412898,636.62,,41.2898,0.63662,,,,7.85398e-5
1:1 (rep 1),2-Compress,81.017,1.564,1.134,0.05,,0.420311,636.62,,42.0311,0.63662,,,,7.85398e-5
1:1 (rep 1),2-Compress,81.383,1.544,1.154,0.05,,0.427724,636.62,,42.7724,0.63662,,,,7.85398e-5
1:1 (rep 1),2-Compress,81.75,1.524,1.174,0.057,,0.435137,725.747,,43.5137,0.725747,,,,7.85398e-5
1:1 (rep 1),2-Compress,82.117,1.504,1.194,0.05,,0.44255,636.62,,44.255,0.63662,,,,7.85398e-5
1:1 (rep 1),2-Compress,82.483,1.485,1.213,0.05,,0.449592,636.62,,44.9592,0.63662,,,,7.85398e-5
1:1 (rep 1),2-Compress,82.85,1.465,1.233,0.05,,0.457005,636.62,,45.7005,0.63662,,,,7.85398e-5
1:1 (rep 1),2-Compress,83.217,1.445,1.253,0.05,,0.464418,636.62,,46.4418,0.63662,,,,7.85398e-5
1:1 (rep 1),2-Compress,83.583,1.426,1.272,0.05,,0.47146,636.62,,47.146,0.63662,,,,7.85398e-5
1:1 (rep 1),2-Compress,83.95,1.405,1.293,0.05,,0.479244,636.62,,47.9244,0.63662,,,,7.85398e-5
1:1 (rep 1),2-Compress,84.317,1.385,1.313,0.057,,0.486657,725.747,,48.6657,0.725747,,,,7.85398e-5
1:1 (rep 1),2-Compress,84.683,1.366,1.332,0.064,,0.493699,814.873,,49.3699,0.814873,,,,7.85398e-5
1:1 (rep 1),2-Compress,85.05,1.346,1.352,0.057,,0.501112,725.747,,50.1112,0.725747,,,,7.85398e-5
1:1 (rep 1),2-Compress,85.417,1.326,1.372,0.05,,0.508525,636.62,,50.8525,0.63662,,,,7.85398e-5
1:1 (rep 1),2-Compress,85.783,1.306,1.392,0.057,,0.515938,725.747,,51.5938,0.725747,,,,7.85398e-5
1:1 (rep 1),2-Compress,86.15,1.286,1.412,0.05,,0.523351,636.62,,52.3351,0.63662,,,,7.85398e-5
1:1 (rep 1),2-Compress,86.517,1.267,1.431,0.05,,0.530393,636.62,,53.0393,0.63662,,,,7.85398e-5
1:1 (rep 1),2-Compress,86.883,1.247,1.451,0.07,,0.537806,891.268,,53.7806,0.891268,,,,7.85398e-5
1:1 (rep 1),2-Compress,87.25,1.227,1.471,0.064,,0.545219,814.873,,54.5219,0.814873,,,,7.85398e-5
1:1 (rep 1),2-Compress,87.617,1.207,1.491,0.064,,0.552632,814.873,,55.2632,0.814873,,,,7.85398e-5
1:1 (rep 1),2-Compress,87.983,1.187,1.511,0.057,,0.560044,725.747,,56.0044,0.725747,,,,7.85398e-5
1:1 (rep 1),2-Compress,88.35,1.168,1.53,0.057,,0.567087,725.747,,56.7087,0.725747,,,,7.85398e-5
1:1 (rep 1),2-Compress,88.717,1.148,1.55,0.05,,0.5745,636.62,,57.45,0.63662,,,,7.85398e-5
1:1 (rep 1),2-Compress,89.083,1.128,1.57,0.057,,0.581913,725.747,,58.1913,0.725747,,,,7.85398e-5
1:1 (rep 1),2-Compress,89.45,1.108,1.59,0.077,,0.589325,980.395,,58.9325,0.980395,,,,7.85398e-5
1:1 (rep 1),2-Compress,89.817,1.088,1.61,0.091,,0.596738,1158.65,,59.6738,1.15865,,,,7.85398e-5
1:1 (rep 1),2-Recover,90.17,1.084,1.614,0.077,,0.598221,980.395,,59.8221,0.980395,,,,7.85398e-5
1:1 (rep 1),2-Recover,90.537,1.105,1.593,0.064,,0.590437,814.873,,59.0437,0.814873,,,,7.85398e-5
1:1 (rep 1),2-Recover,90.903,1.124,1.574,0.057,,0.583395,725.747,,58.3395,0.725747,,,,7.85398e-5
1:1 (rep 1),2-Recover,91.27,1.144,1.554,0.05,,0.575982,636.62,,57.5982,0.63662,,,,7.85398e-5
1:1 (rep 1),2-Recover,91.637,1.164,1.534,0.05,,0.568569,636.62,,56.8569,0.63662,,,,7.85398e-5
1:1 (rep 1),2-Recover,92.003,1.183,1.515,0.064,,0.561527,814.873,,56.1527,0.814873,,,,7.85398e-5
1:1 (rep 1),2-Recover,92.37,1.204,1.494,0.064,,0.553744,814.873,,55.3744,0.814873,,,,7.85398e-5
1:1 (rep 1),2-Recover,92.737,1.224,1.474,0.057,,0.546331,725.747,,54.6331,0.725747,,,,7.85398e-5
1:1 (rep 1),2-Recover,93.103,1.243,1.455,0.057,,0.539288,725.747,,53.9288,0.725747,,,,7.85398e-5
1:1 (rep 1),2-Recover,93.47,1.263,1.435,0.05,,0.531875,636.62,,53.1875,0.63662,,,,7.85398e-5
1:1 (rep 1),2-Recover,93.837,1.283,1.415,0.05,,0.524463,636.62,,52.4463,0.63662,,,,7.85398e-5
1:1 (rep 1),2-Recover,94.203,1.303,1.395,0.057,,0.51705,725.747,,51.705,0.725747,,,,7.85398e-5
1:1 (rep 1),2-Recover,94.57,1.323,1.375,0.05,,0.509637,636.62,,50.9637,0.63662,,,,7.85398e-5
1:1 (rep 1),2-Recover,94.937,1.342,1.356,0.05,,0.502595,636.62,,50.2595,0.63662,,,,7.85398e-5
1:1 (rep 1),2-Recover,95.303,1.362,1.336,0.05,,0.495182,636.62,,49.5182,0.63662,,,,7.85398e-5
1:1 (rep 1),2-Recover,95.67,1.382,1.316,0.05,,0.487769,636.62,,48.7769,0.63662,,,,7.85398e-5
1:1 (rep 1),2-Recover,96.037,1.402,1.296,0.043,,0.480356,547.493,,48.0356,0.547493,,,,7.85398e-5
1:1 (rep 1),2-Recover,96.403,1.422,1.276,0.043,,0.472943,547.493,,47.2943,0.547493,,,,7.85398e-5
1:1 (rep 1),2-Recover,96.77,1.441,1.257,0.043,,0.465901,547.493,,46.5901,0.547493,,,,7.85398e-5
1:1 (rep 1),2-Recover,97.137,1.461,1.237,0.036,,0.458488,458.366,,45.8488,0.458366,,,,7.85398e-5
1:1 (rep 1),2-Recover,97.503,1.481,1.217,0.043,,0.451075,547.493,,45.1075,0.547493,,,,7.85398e-5
1:1 (rep 1),2-Recover,97.87,1.501,1.197,0.03,,0.443662,381.972,,44.3662,0.381972,,,,7.85398e-5
1:1 (rep 1),2-Recover,98.237,1.521,1.177,0.023,,0.436249,292.845,,43.6249,0.292845,,,,7.85398e-5
1:1 (rep 1),2-Recover,98.603,1.54,1.158,0.023,,0.429207,292.845,,42.9207,0.292845,,,,7.85398e-5
1:1 (rep 1),2-Recover,98.97,1.56,1.138,0.036,,0.421794,458.366,,42.1794,0.458366,,,,7.85398e-5
1:1 (rep 1),2-Recover,99.337,1.58,1.118,0.043,,0.414381,547.493,,41.4381,0.547493,,,,7.85398e-5
1:1 (rep 1),2-Recover,99.703,1.6,1.098,0.043,,0.406968,547.493,,40.6968,0.547493,,,,7.85398e-5
1:1 (rep 1),2-Recover,100.07,1.62,1.078,0.03,,0.399555,381.972,,39.9555,0.381972,,,,7.85398e-5
1:1 (rep 1),2-Recover,100.437,1.64,1.058,0.05,,0.392142,636.62,,39.2142,0.63662,,,,7.85398e-5
1:1 (rep 1),2-Recover,100.803,1.659,1.039,0.05,,0.3851,636.62,,38.51,0.63662,,,,7.85398e-5
1:1 (rep 1),2-Recover,101.17,1.679,1.019,0.05,,0.377687,636.62,,37.7687,0.63662,,,,7.85398e-5
1:1 (rep 1),2-Recover,101.537,1.7,0.998,0.05,,0.369904,636.62,,36.9904,0.63662,,,,7.85398e-5
1:1 (rep 1),2-Recover,101.903,1.719,0.979,0.05,,0.362861,636.62,,36.2861,0.63662,,,,7.85398e-5
1:1 (rep 1),2-Recover,102.27,1.738,0.96,0.05,,0.355819,636.62,,35.5819,0.63662,,,,7.85398e-5
1:1 (rep 1),2-Recover,102.637,1.759,0.939,0.05,,0.348036,636.62,,34.8036,0.63662,,,,7.85398e-5
1:1 (rep 1),2-Recover,103.003,1.778,0.92,0.05,,0.340993,636.62,,34.0993,0.63662,,,,7.85398e-5
1:1 (rep 1),2-Recover,103.37,1.799,0.899,0.036,,0.33321,458.366,,33.321,0.458366,,,,7.85398e-5
1:1 (rep 1),2-Recover,103.737,1.818,0.88,0.043,,0.326168,547.493,,32.6168,0.547493,,,,7.85398e-5
1:1 (rep 1),2-Recover,104.103,1.837,0.861,0.043,,0.319125,547.493,,31.9125,0.547493,,,,7.85398e-5
1:1 (rep 1),2-Recover,104.47,1.858,0.84,0.05,,0.311342,636.62,,31.1342,0.63662,,,,7.85398e-5
1:1 (rep 1),2-Recover,104.837,1.878,0.82,0.05,,0.303929,636.62,,30.3929,0.63662,,,,7.85398e-5
1:1 (rep 1),2-Recover,105.203,1.897,0.801,0.043,,0.296887,547.493,,29.6887,0.547493,,,,7.85398e-5
1:1 (rep 1),2-Recover,105.57,1.917,0.781,0.043,,0.289474,547.493,,28.9474,0.547493,,,,7.85398e-5
1:1 (rep 1),2-Recover,105.937,1.937,0.761,0.036,,0.282061,458.366,,28.2061,0.458366,,,,7.85398e-5
1:1 (rep 1),2-Recover,106.303,1.957,0.741,0.016,,0.274648,203.718,,27.4648,0.203718,,,,7.85398e-5
1:1 (rep 1),2-Recover,106.67,1.977,0.721,0.03,,0.267235,381.972,,26.7235,0.381972,,,,7.85398e-5
1:1 (rep 1),2-Recover,107.037,1.997,0.701,0.036,,0.259822,458.366,,25.9822,0.458366,,,,7.85398e-5
1:1 (rep 1),2-Recover,107.403,2.016,0.682,0.023,,0.25278,292.845,,25.278,0.292845,,,,7.85398e-5
1:1 (rep 1),2-Recover,107.77,2.036,0.662,0.016,,0.245367,203.718,,24.5367,0.203718,,,,7.85398e-5
1:1 (rep 1),2-Recover,108.137,2.056,0.642,0.002,,0.237954,25.4648,,23.7954,0.0254648,,,,7.85398e-5
1:1 (rep 1),2-Recover,108.503,2.076,0.622,0.002,,0.230541,25.4648,,23.0541,0.0254648,,,,7.85398e-5
1:1 (rep 1),2-Recover,108.87,2.096,0.602,0.002,,0.223128,25.4648,,22.3128,0.0254648,,,,7.85398e-5
1:1 (rep 1),2-Recover,109.237,2.115,0.583,0.016,,0.216086,203.718,,21.6086,0.203718,,,,7.85398e-5
1:1 (rep 1),2-Recover,109.603,2.135,0.563,0.016,,0.208673,203.718,,20.8673,0.203718,,,,7.85398e-5
1:1 (rep 1),2-Recover,109.97,2.155,0.543,0.016,,0.20126,203.718,,20.126,0.203718,,,,7.85398e-5
1:1 (rep 1),2-Recover,110.337,2.175,0.523,0.009,,0.193847,114.592,,19.3847,0.114592,,,,7.85398e-5
1:1 (rep 1),2-Recover,110.703,2.195,0.503,0.009,,0.186434,114.592,,18.6434,0.114592,,,,7.85398e-5
1:1 (rep 1),2-Recover,111.07,2.214,0.484,0.002,,0.179392,25.4648,,17.9392,0.0254648,,,,7.85398e-5
1:1 (rep 1),2-Recover,111.437,2.235,0.463,0.002,,0.171609,25.4648,,17.1609,0.0254648,,,,7.85398e-5
1:1 (rep 1),2-Recover,111.803,2.254,0.444,0.009,,0.164566,114.592,,16.4566,0.114592,,,,7.85398e-5
1:1 (rep 1),2-Recover,112.17,2.274,0.424,0.009,,0.157153,114.592,,15.7153,0.114592,,,,7.85398e-5
1:1 (rep 1),2-Recover,112.537,2.294,0.404,0.009,,0.149741,114.592,,14.9741,0.114592,,,,7.85398e-5
1:1 (rep 1),2-Recover,112.903,2.313,0.385,0.002,,0.142698,25.4648,,14.2698,0.0254648,,,,7.85398e-5
1:1 (rep 1),2-Recover,113.27,2.333,0.365,0.002,,0.135285,25.4648,,13.5285,0.0254648,,,,7.85398e-5
1:1 (rep 1),2-Recover,113.637,2.354,0.344,0.002,,0.127502,25.4648,,12.7502,0.0254648,,,,7.85398e-5
1:1 (rep 1),2-Recover,114.003,2.373,0.325,0.002,,0.12046,25.4648,,12.046,0.0254648,,,,7.85398e-5
1:1 (rep 1),2-Recover,114.37,2.393,0.305,0.009,,0.113047,114.592,,11.3047,0.114592,,,,7.85398e-5
1:1 (rep 1),2-Recover,114.737,2.413,0.285,0.009,,0.105634,114.592,,10.5634,0.114592,,,,7.85398e-5
1:1 (rep 1),2-Recover,115.103,2.432,0.266,-0.004,,0.0985915,-50.9296,,9.85915,-0.0509296,,,,7.85398e-5
1:1 (rep 1),2-Recover,115.47,2.453,0.245,0.009,,0.090808,114.592,,9.0808,0.114592,,,,7.85398e-5
1:1 (rep 1),2-Recover,115.837,2.472,0.226,0.002,,0.0837658,25.4648,,8.37658,0.0254648,,,,7.85398e-5
1:1 (rep 1),2-Recover,116.203,2.492,0.206,0.002,,0.0763529,25.4648,,7.63529,0.0254648,,,,7.85398e-5
1:1 (rep 1),2-Recover,116.57,2.512,0.186,0.009,,0.06894,114.592,,6.894,0.114592,,,,7.85398e-5
1:1 (rep 1),2-Recover,116.937,2.532,0.166,0.009,,0.0615271,114.592,,6.15271,0.114592,,,,7.85398e-5
1:1 (rep 1),2-Recover,117.303,2.551,0.147,0.03,,0.0544848,381.972,,5.44848,0.381972,,,,7.85398e-5
1:1 (rep 1),2-Recover,117.67,2.571,0.127,0.009,,0.0470719,114.592,,4.70719,0.114592,,,,7.85398e-5
1:1 (rep 1),2-Recover,118.037,2.591,0.107,-0.004,,0.039659,-50.9296,,3.9659,-0.0509296,,,,7.85398e-5
1:1 (rep 1),2-Recover,118.403,2.611,0.087,0.009,,0.0322461,114.592,,3.22461,0.114592,,,,7.85398e-5
1:1 (rep 1),2-Recover,118.77,2.631,0.067,0.002,,0.0248332,25.4648,,2.48332,0.0254648,,,,7.85398e-5
1:1 (rep 1),2-Recover,119.137,2.651,0.047,0.009,,0.0174203,114.592,,1.74203,0.114592,,,,7.85398e-5
1:1 (rep 1),2-Recover,119.503,2.67,0.028,0.009,,0.0103781,114.592,,1.03781,0.114592,,,,7.85398e-5
1:1 (rep 1),2-Recover,119.87,2.69,0.008,0.016,,0.00296516,203.718,,0.296516,0.203718,,,,7.85398e-5
1:1 (rep 1),3-Compress,120.213,2.691,0.007,0.009,,0.00259451,114.592,,0.259451,0.114592,,,,7.85398e-5
1:1 (rep 1),3-Compress,120.58,2.671,0.027,0.002,,0.0100074,25.4648,,1.00074,0.0254648,,,,7.85398e-5
1:1 (rep 1),3-Compress,120.947,2.651,0.047,0.002,,0.0174203,25.4648,,1.74203,0.0254648,,,,7.85398e-5
1:1 (rep 1),3-Compress,121.313,2.631,0.067,0.002,,0.0248332,25.4648,,2.48332,0.0254648,,,,7.85398e-5
1:1 (rep 1),3-Compress,121.68,2.612,0.086,0.002,,0.0318755,25.4648,,3.18755,0.0254648,,,,7.85398e-5
1:1 (rep 1),3-Compress,122.047,2.591,0.107,0.016,,0.039659,203.718,,3.9659,0.203718,,,,7.85398e-5
1:1 (rep 1),3-Compress,122.413,2.572,0.126,0.009,,0.0467013,114.592,,4.67013,0.114592,,,,7.85398e-5
1:1 (rep 1),3-Compress,122.78,2.552,0.146,0.002,,0.0541142,25.4648,,5.41142,0.0254648,,,,7.85398e-5
1:1 (rep 1),3-Compress,123.147,2.532,0.166,0.016,,0.0615271,203.718,,6.15271,0.203718,,,,7.85398e-5
1:1 (rep 1),3-Compress,123.513,2.513,0.185,0.009,,0.0685693,114.592,,6.85693,0.114592,,,,7.85398e-5
1:1 (rep 1),3-Compress,123.88,2.492,0.206,0.002,,0.0763529,25.4648,,7.63529,0.0254648,,,,7.85398e-5
1:1 (rep 1),3-Compress,124.247,2.472,0.226,0.002,,0.0837658,25.4648,,8.37658,0.0254648,,,,7.85398e-5
1:1 (rep 1),3-Compress,124.613,2.453,0.245,0.023,,0.090808,292.845,,9.0808,0.292845,,,,7.85398e-5
1:1 (rep 1),3-Compress,124.98,2.433,0.265,0.023,,0.0982209,292.845,,9.82209,0.292845,,,,7.85398e-5
1:1 (rep 1),3-Compress,125.347,2.413,0.285,0.016,,0.105634,203.718,,10.5634,0.203718,,,,7.85398e-5
1:1 (rep 1),3-Compress,125.713,2.393,0.305,0.016,,0.113047,203.718,,11.3047,0.203718,,,,7.85398e-5
1:1 (rep 1),3-Compress,126.08,2.373,0.325,0.002,,0.12046,25.4648,,12.046,0.0254648,,,,7.85398e-5
1:1 (rep 1),3-Compress,126.447,2.354,0.344,0.009,,0.127502,114.592,,12.7502,0.114592,,,,7.85398e-5
1:1 (rep 1),3-Compress,126.813,2.334,0.364,0.002,,0.134915,25.4648,,13.4915,0.0254648,,,,7.85398e-5
1:1 (rep 1),3-Compress,127.18,2.314,0.384,0.023,,0.142328,292.845,,14.2328,0.292845,,,,7.85398e-5
1:1 (rep 1),3-Compress,127.547,2.294,0.404,0.03,,0.149741,381.972,,14.9741,0.381972,,,,7.85398e-5
1:1 (rep 1),3-Compress,127.913,2.274,0.424,0.023,,0.157153,292.845,,15.7153,0.292845,,,,7.85398e-5
1:1 (rep 1),3-Compress,128.28,2.255,0.443,0.023,,0.164196,292.845,,16.4196,0.292845,,,,7.85398e-5
1:1 (rep 1),3-Compress,128.647,2.235,0.463,0.009,,0.171609,114.592,,17.1609,0.114592,,,,7.85398e-5
1:1 (rep 1),3-Compress,129.013,2.215,0.483,0.002,,0.179021,25.4648,,17.9021,0.0254648,,,,7.85398e-5
1:1 (rep 1),3-Compress,129.38,2.195,0.503,0.016,,0.186434,203.718,,18.6434,0.203718,,,,7.85398e-5
1:1 (rep 1),3-Compress,129.747,2.175,0.523,0.016,,0.193847,203.718,,19.3847,0.203718,,,,7.85398e-5
1:1 (rep 1),3-Compress,130.113,2.156,0.542,0.03,,0.20089,381.972,,20.089,0.381972,,,,7.85398e-5
1:1 (rep 1),3-Compress,130.48,2.136,0.562,0.036,,0.208302,458.366,,20.8302,0.458366,,,,7.85398e-5
1:1 (rep 1),3-Compress,130.847,2.116,0.582,0.03,,0.215715,381.972,,21.5715,0.381972,,,,7.85398e-5
1:1 (rep 1),3-Compress,131.213,2.096,0.602,0.05,,0.223128,636.62,,22.3128,0.63662,,,,7.85398e-5
1:1 (rep 1),3-Compress,131.58,2.076,0.622,0.023,,0.230541,292.845,,23.0541,0.292845,,,,7.85398e-5
1:1 (rep 1),3-Compress,131.947,2.056,0.642,0.036,,0.237954,458.366,,23.7954,0.458366,,,,7.85398e-5
1:1 (rep 1),3-Compress,132.313,2.037,0.661,0.036,,0.244996,458.366,,24.4996,0.458366,,,,7.85398e-5
1:1 (rep 1),3-Compress,132.68,2.017,0.681,0.036,,0.252409,458.366,,25.2409,0.458366,,,,7.85398e-5
1:1 (rep 1),3-Compress,133.047,1.997,0.701,0.036,,0.259822,458.366,,25.9822,0.458366,,,,7.85398e-5
1:1 (rep 1),3-Compress,133.413,1.977,0.721,0.05,,0.267235,636.62,,26.7235,0.63662,,,,7.85398e-5
1:1 (rep 1),3-Compress,133.78,1.957,0.741,0.03,,0.274648,381.972,,27.4648,0.381972,,,,7.85398e-5
1:1 (rep 1),3-Compress,134.147,1.937,0.761,0.043,,0.282061,547.493,,28.2061,0.547493,,,,7.85398e-5
1:1 (rep 1),3-Compress,134.513,1.918,0.78,0.036,,0.289103,458.366,,28.9103,0.458366,,,,7.85398e-5
1:1 (rep 1),3-Compress,134.88,1.898,0.8,0.05,,0.296516,636.62,,29.6516,0.63662,,,,7.85398e-5
1:1 (rep 1),3-Compress,135.247,1.878,0.82,0.05,,0.303929,636.62,,30.3929,0.63662,,,,7.85398e-5
1:1 (rep 1),3-Compress,135.613,1.859,0.839,0.05,,0.310971,636.62,,31.0971,0.63662,,,,7.85398e-5
1:1 (rep 1),3-Compress,135.98,1.838,0.86,0.05,,0.318755,636.62,,31.8755,0.63662,,,,7.85398e-5
1:1 (rep 1),3-Compress,136.347,1.818,0.88,0.05,,0.326168,636.62,,32.6168,0.63662,,,,7.85398e-5
1:1 (rep 1),3-Compress,136.713,1.799,0.899,0.05,,0.33321,636.62,,33.321,0.63662,,,,7.85398e-5
1:1 (rep 1),3-Compress,137.08,1.779,0.919,0.05,,0.340623,636.62,,34.0623,0.63662,,,,7.85398e-5
1:1 (rep 1),3-Compress,137.447,1.759,0.939,0.057,,0.348036,725.747,,34.8036,0.725747,,,,7.85398e-5
1:1 (rep 1),3-Compress,137.813,1.739,0.959,0.05,,0.355448,636.62,,35.5448,0.63662,,,,7.85398e-5
1:1 (rep 1),3-Compress,138.18,1.719,0.979,0.05,,0.362861,636.62,,36.2861,0.63662,,,,7.85398e-5
1:1 (rep 1),3-Compress,138.547,1.7,0.998,0.05,,0.369904,636.62,,36.9904,0.63662,,,,7.85398e-5
1:1 (rep 1),3-Compress,138.913,1.68,1.018,0.05,,0.377317,636.62,,37.7317,0.63662,,,,7.85398e-5
1:1 (rep 1),3-Compress,139.28,1.66,1.038,0.05,,0.384729,636.62,,38.4729,0.63662,,,,7.85398e-5
1:1 (rep 1),3-Compress,139.647,1.64,1.058,0.057,,0.392142,725.747,,39.2142,0.725747,,,,7.85398e-5
1:1 (rep 1),3-Compress,140.013,1.62,1.078,0.05,,0.399555,636.62,,39.9555,0.63662,,,,7.85398e-5
1:1 (rep 1),3-Compress,140.38,1.601,1.097,0.05,,0.406597,636.62,,40.6597,0.63662,,,,7.85398e-5
1:1 (rep 1),3-Compress,140.747,1.581,1.117,0.05,,0.41401,636.62,,41.401,0.63662,,,,7.85398e-5
1:1 (rep 1),3-Compress,141.113,1.561,1.137,0.05,,0.421423,636.62,,42.1423,0.63662,,,,7.85398e-5
1:1 (rep 1),3-Compress,141.48,1.541,1.157,0.05,,0.428836,636.62,,42.8836,0.63662,,,,7.85398e-5
1:1 (rep 1),3-Compress,141.847,1.521,1.177,0.05,,0.436249,636.62,,43.6249,0.63662,,,,7.85398e-5
1:1 (rep 1),3-Compress,142.213,1.502,1.196,0.05,,0.443291,636.62,,44.3291,0.63662,,,,7.85398e-5
1:1 (rep 1),3-Compress,142.58,1.482,1.216,0.05,,0.450704,636.62,,45.0704,0.63662,,,,7.85398e-5
1:1 (rep 1),3-Compress,142.947,1.461,1.237,0.05,,0.458488,636.62,,45.8488,0.63662,,,,7.85398e-5
1:1 (rep 1),3-Compress,143.313,1.442,1.256,0.05,,0.46553,636.62,,46.553,0.63662,,,,7.85398e-5
1:1 (rep 1),3-Compress,143.68,1.422,1.276,0.05,,0.472943,636.62,,47.2943,0.63662,,,,7.85398e-5
1:1 (rep 1),3-Compress,144.047,1.402,1.296,0.05,,0.480356,636.62,,48.0356,0.63662,,,,7.85398e-5
1:1 (rep 1),3-Compress,144.413,1.383,1.315,0.05,,0.487398,636.62,,48.7398,0.63662,,,,7.85398e-5
1:1 (rep 1),3-Compress,144.78,1.363,1.335,0.057,,0.494811,725.747,,49.4811,0.725747,,,,7.85398e-5
1:1 (rep 1),3-Compress,145.147,1.342,1.356,0.05,,0.502595,636.62,,50.2595,0.63662,,,,7.85398e-5
1:1 (rep 1),3-Compress,145.513,1.323,1.375,0.057,,0.509637,725.747,,50.9637,0.725747,,,,7.85398e-5
1:1 (rep 1),3-Compress,145.88,1.303,1.395,0.057,,0.51705,725.747,,51.705,0.725747,,,,7.85398e-5
1:1 (rep 1),3-Compress,146.247,1.283,1.415,0.057,,0.524463,725.747,,52.4463,0.725747,,,,7.85398e-5
1:1 (rep 1),3-Compress,146.613,1.264,1.434,0.057,,0.531505,725.747,,53.1505,0.725747,,,,7.85398e-5
1:1 (rep 1),3-Compress,146.98,1.243,1.455,0.05,,0.539288,636.62,,53.9288,0.63662,,,,7.85398e-5
1:1 (rep 1),3-Compress,147.347,1.224,1.474,0.057,,0.546331,725.747,,54.6331,0.725747,,,,7.85398e-5
1:1 (rep 1),3-Compress,147.713,1.205,1.493,0.07,,0.553373,891.268,,55.3373,0.891268,,,,7.85398e-5
1:1 (rep 1),3-Compress,148.08,1.184,1.514,0.057,,0.561156,725.747,,56.1156,0.725747,,,,7.85398e-5
1:1 (rep 1),3-Compress,148.447,1.164,1.534,0.064,,0.568569,814.873,,56.8569,0.814873,,,,7.85398e-5
1:1 (rep 1),3-Compress,148.813,1.144,1.554,0.057,,0.575982,725.747,,57.5982,0.725747,,,,7.85398e-5
1:1 (rep 1),3-Compress,149.18,1.125,1.573,0.057,,0.583024,725.747,,58.3024,0.725747,,,,7.85398e-5
1:1 (rep 1),3-Compress,149.547,1.105,1.593,0.064,,0.590437,814.873,,59.0437,0.814873,,,,7.85398e-5
1:1 (rep 1),3-Compress,149.913,1.085,1.613,0.07,,0.59785,891.268,,59.785,0.891268,,,,7.85398e-5
1:1 (rep 1),3-Recover,150.267,1.088,1.61,0.084,,0.596738,1069.52,,59.6738,1.06952,,,,7.85398e-5
1:1 (rep 1),3-Recover,150.633,1.107,1.591,0.077,,0.589696,980.395,,58.9696,0.980395,,,,7.85398e-5
1:1 (rep 1),3-Recover,151,1.127,1.571,0.064,,0.582283,814.873,,58.2283,0.814873,,,,7.85398e-5
1:1 (rep 1),3-Recover,151.367,1.147,1.551,0.05,,0.57487,636.62,,57.487,0.63662,,,,7.85398e-5
1:1 (rep 1),3-Recover,151.733,1.167,1.531,0.057,,0.567457,725.747,,56.7457,0.725747,,,,7.85398e-5
1:1 (rep 1),3-Recover,152.1,1.187,1.511,0.05,,0.560044,636.62,,56.0044,0.63662,,,,7.85398e-5
1:1 (rep 1),3-Recover,152.467,1.207,1.491,0.05,,0.552632,636.62,,55.2632,0.63662,,,,7.85398e-5
1:1 (rep 1),3-Recover,152.833,1.226,1.472,0.05,,0.545589,636.62,,54.5589,0.63662,,,,7.85398e-5
1:1 (rep 1),3-Recover,153.2,1.246,1.452,0.05,,0.538176,636.62,,53.8176,0.63662,,,,7.85398e-5
1:1 (rep 1),3-Recover,153.567,1.267,1.431,0.05,,0.530393,636.62,,53.0393,0.63662,,,,7.85398e-5
1:1 (rep 1),3-Recover,153.933,1.286,1.412,0.05,,0.523351,636.62,,52.3351,0.63662,,,,7.85398e-5
1:1 (rep 1),3-Recover,154.3,1.305,1.393,0.05,,0.516308,636.62,,51.6308,0.63662,,,,7.85398e-5
1:1 (rep 1),3-Recover,154.667,1.326,1.372,0.05,,0.508525,636.62,,50.8525,0.63662,,,,7.85398e-5
1:1 (rep 1),3-Recover,155.033,1.345,1.353,0.05,,0.501483,636.62,,50.1483,0.63662,,,,7.85398e-5
1:1 (rep 1),3-Recover,155.4,1.365,1.333,0.05,,0.49407,636.62,,49.407,0.63662,,,,7.85398e-5
1:1 (rep 1),3-Recover,155.767,1.385,1.313,0.05,,0.486657,636.62,,48.6657,0.63662,,,,7.85398e-5
1:1 (rep 1),3-Recover,156.133,1.404,1.294,0.05,,0.479615,636.62,,47.9615,0.63662,,,,7.85398e-5
1:1 (rep 1),3-Recover,156.5,1.425,1.273,0.05,,0.471831,636.62,,47.1831,0.63662,,,,7.85398e-5
1:1 (rep 1),3-Recover,156.867,1.445,1.253,0.057,,0.464418,725.747,,46.4418,0.725747,,,,7.85398e-5
1:1 (rep 1),3-Recover,157.233,1.464,1.234,0.05,,0.457376,636.62,,45.7376,0.63662,,,,7.85398e-5
1:1 (rep 1),3-Recover,157.6,1.484,1.214,0.05,,0.449963,636.62,,44.9963,0.63662,,,,7.85398e-5
1:1 (rep 1),3-Recover,157.967,1.504,1.194,0.05,,0.44255,636.62,,44.255,0.63662,,,,7.85398e-5
1:1 (rep 1),3-Recover,158.333,1.524,1.174,0.05,,0.435137,636.62,,43.5137,0.63662,,,,7.85398e-5
1:1 (rep 1),3-Recover,158.7,1.544,1.154,0.05,,0.427724,636.62,,42.7724,0.63662,,,,7.85398e-5
1:1 (rep 1),3-Recover,159.067,1.564,1.134,0.05,,0.420311,636.62,,42.0311,0.63662,,,,7.85398e-5
1:1 (rep 1),3-Recover,159.433,1.583,1.115,0.05,,0.413269,636.62,,41.3269,0.63662,,,,7.85398e-5
1:1 (rep 1),3-Recover,159.8,1.603,1.095,0.043,,0.405856,547.493,,40.5856,0.547493,,,,7.85398e-5
1:1 (rep 1),3-Recover,160.167,1.623,1.075,0.05,,0.398443,636.62,,39.8443,0.63662,,,,7.85398e-5
1:1 (rep 1),3-Recover,160.533,1.643,1.055,0.05,,0.39103,636.62,,39.103,0.63662,,,,7.85398e-5
1:1 (rep 1),3-Recover,160.9,1.663,1.035,0.05,,0.383617,636.62,,38.3617,0.63662,,,,7.85398e-5
1:1 (rep 1),3-Recover,161.267,1.682,1.016,0.05,,0.376575,636.62,,37.6575,0.63662,,,,7.85398e-5
1:1 (rep 1),3-Recover,161.633,1.702,0.996,0.05,,0.369162,636.62,,36.9162,0.63662,,,,7.85398e-5
1:1 (rep 1),3-Recover,162,1.722,0.976,0.043,,0.361749,547.493,,36.1749,0.547493,,,,7.85398e-5
1:1 (rep 1),3-Recover,162.367,1.742,0.956,0.036,,0.354337,458.366,,35.4337,0.458366,,,,7.85398e-5
1:1 (rep 1),3-Recover,162.733,1.762,0.936,0.05,,0.346924,636.62,,34.6924,0.63662,,,,7.85398e-5
1:1 (rep 1),3-Recover,163.1,1.781,0.917,0.05,,0.339881,636.62,,33.9881,0.63662,,,,7.85398e-5
1:1 (rep 1),3-Recover,163.467,1.801,0.897,0.043,,0.332468,547.493,,33.2468,0.547493,,,,7.85398e-5
1:1 (rep 1),3-Recover,163.833,1.821,0.877,0.05,,0.325056,636.62,,32.5056,0.63662,,,,7.85398e-5
1:1 (rep 1),3-Recover,164.2,1.841,0.857,0.036,,0.317643,458.366,,31.7643,0.458366,,,,7.85398e-5
1:1 (rep 1),3-Recover,164.567,1.861,0.837,0.009,,0.31023,114.592,,31.023,0.114592,,,,7.85398e-5
1:1 (rep 1),3-Recover,164.933,1.88,0.818,0.043,,0.303188,547.493,,30.3188,0.547493,,,,7.85398e-5
1:1 (rep 1),3-Recover,165.3,1.9,0.798,0.036,,0.295775,458.366,,29.5775,0.458366,,,,7.85398e-5
1:1 (rep 1),3-Recover,165.667,1.921,0.777,0.043,,0.287991,547.493,,28.7991,0.547493,,,,7.85398e-5
1:1 (rep 1),3-Recover,166.033,1.94,0.758,0.03,,0.280949,381.972,,28.0949,0.381972,,,,7.85398e-5
1:1 (rep 1),3-Recover,166.4,1.96,0.738,0.023,,0.273536,292.845,,27.3536,0.292845,,,,7.85398e-5
1:1 (rep 1),3-Recover,166.767,1.98,0.718,0.016,,0.266123,203.718,,26.6123,0.203718,,,,7.85398e-5
1:1 (rep 1),3-Recover,167.133,1.999,0.699,0.016,,0.259081,203.718,,25.9081,0.203718,,,,7.85398e-5
1:1 (rep 1),3-Recover,167.5,2.02,0.678,0.03,,0.251297,381.972,,25.1297,0.381972,,,,7.85398e-5
1:1 (rep 1),3-Recover,167.867,2.039,0.659,0.03,,0.244255,381.972,,24.4255,0.381972,,,,7.85398e-5
1:1 (rep 1),3-Recover,168.233,2.059,0.639,0.023,,0.236842,292.845,,23.6842,0.292845,,,,7.85398e-5
1:1 (rep 1),3-Recover,168.6,2.079,0.619,0.016,,0.229429,203.718,,22.9429,0.203718,,,,7.85398e-5
1:1 (rep 1),3-Recover,168.967,2.099,0.599,0.009,,0.222016,114.592,,22.2016,0.114592,,,,7.85398e-5
1:1 (rep 1),3-Recover,169.333,2.118,0.58,0.002,,0.214974,25.4648,,21.4974,0.0254648,,,,7.85398e-5
1:1 (rep 1),3-Recover,169.7,2.138,0.56,0.016,,0.207561,203.718,,20.7561,0.203718,,,,7.85398e-5
1:1 (rep 1),3-Recover,170.067,2.158,0.54,0.023,,0.200148,292.845,,20.0148,0.292845,,,,7.85398e-5
1:1 (rep 1),3-Recover,170.433,2.178,0.52,0.016,,0.192735,203.718,,19.2735,0.203718,,,,7.85398e-5
1:1 (rep 1),3-Recover,170.8,2.198,0.5,0.016,,0.185322,203.718,,18.5322,0.203718,,,,7.85398e-5
1:1 (rep 1),3-Recover,171.167,2.218,0.48,0.002,,0.17791,25.4648,,17.791,0.0254648,,,,7.85398e-5
1:1 (rep 1),3-Recover,171.533,2.237,0.461,0.002,,0.170867,25.4648,,17.0867,0.0254648,,,,7.85398e-5
1:1 (rep 1),3-Recover,171.9,2.257,0.441,0.002,,0.163454,25.4648,,16.3454,0.0254648,,,,7.85398e-5
1:1 (rep 1),3-Recover,172.267,2.277,0.421,0.016,,0.156042,203.718,,15.6042,0.203718,,,,7.85398e-5
1:1 (rep 1),3-Recover,172.633,2.297,0.401,0.03,,0.148629,381.972,,14.8629,0.381972,,,,7.85398e-5
1:1 (rep 1),3-Recover,173,2.317,0.381,0.03,,0.141216,381.972,,14.1216,0.381972,,,,7.85398e-5
1:1 (rep 1),3-Recover,173.367,2.336,0.362,0.016,,0.134173,203.718,,13.4173,0.203718,,,,7.85398e-5
1:1 (rep 1),3-Recover,173.733,2.356,0.342,0.009,,0.126761,114.592,,12.6761,0.114592,,,,7.85398e-5
1:1 (rep 1),3-Recover,174.1,2.376,0.322,0.009,,0.119348,114.592,,11.9348,0.114592,,,,7.85398e-5
1:1 (rep 1),3-Recover,174.467,2.396,0.302,0.002,,0.111935,25.4648,,11.1935,0.0254648,,,,7.85398e-5
1:1 (rep 1),3-Recover,174.833,2.416,0.282,0.009,,0.104522,114.592,,10.4522,0.114592,,,,7.85398e-5
1:1 (rep 1),3-Recover,175.2,2.435,0.263,0.03,,0.0974796,381.972,,9.74796,0.381972,,,,7.85398e-5
1:1 (rep 1),3-Recover,175.567,2.456,0.242,0.009,,0.0896961,114.592,,8.96961,0.114592,,,,7.85398e-5
1:1 (rep 1),3-Recover,175.933,2.475,0.223,0.016,,0.0826538,203.718,,8.26538,0.203718,,,,7.85398e-5
1:1 (rep 1),3-Recover,176.3,2.495,0.203,0.002,,0.0752409,25.4648,,7.52409,0.0254648,,,,7.85398e-5
1:1 (rep 1),3-Recover,176.667,2.515,0.183,0.002,,0.067828,25.4648,,6.7828,0.0254648,,,,7.85398e-5
1:1 (rep 1),3-Recover,177.033,2.534,0.164,0.002,,0.0607858,25.4648,,6.07858,0.0254648,,,,7.85398e-5
1:1 (rep 1),3-Recover,177.4,2.554,0.144,0.009,,0.0533729,114.592,,5.33729,0.114592,,,,7.85398e-5
1:1 (rep 1),3-Recover,177.767,2.575,0.123,0.023,,0.0455893,292.845,,4.55893,0.292845,,,,7.85398e-5
1:1 (rep 1),3-Recover,178.133,2.594,0.104,0.009,,0.0385471,114.592,,3.85471,0.114592,,,,7.85398e-5
1:1 (rep 1),3-Recover,178.5,2.614,0.084,0.002,,0.0311342,25.4648,,3.11342,0.0254648,,,,7.85398e-5
1:1 (rep 1),3-Recover,178.867,2.634,0.064,0.002,,0.0237213,25.4648,,2.37213,0.0254648,,,,7.85398e-5
1:1 (rep 1),3-Recover,179.233,2.653,0.045,0.002,,0.016679,25.4648,,1.6679,0.0254648,,,,7.85398e-5
1:1 (rep 1),3-Recover,179.6,2.674,0.024,0.002,,0.00889548,25.4648,,0.889548,0.0254648,,,,7.85398e-5
1:1 (rep 1),3-Recover,179.967,2.693,0.005,0.009,,0.00185322,114.592,,0.185322,0.114592,,,,7.85398e-5
1:1 (rep 1),3-Recover,180.1,2.698,0,0.009,,0,114.592,,0,0.114592,,,,7.85398e-5