File: data/beta_1-0.5_2.csv
SetName,Cycle,Time_S,Size_mm,Displacement_mm,Force_N,,Strain,Stress(Pascal),,%Strain,Stress(kPa),,,,Area(m^2)
Test7,1-Compress,0.000,4.819,-0,0.013,,0,165.521,,0,0.165521,,,,7.85398e-5
Test7,1-Compress,0.333,4.789,0.03,0.013,,0.00622536,165.521,,0.622536,0.165521,,,,7.85398e-5
Test7,1-Compress,0.667,4.756,0.063,0.013,,0.0130733,165.521,,1.30733,0.165521,,,,7.85398e-5
Test7,1-Compress,1.000,4.724,0.095,0.013,,0.0197136,165.521,,1.97136,0.165521,,,,7.85398e-5
Test7,1-Compress,1.333,4.692,0.127,0.013,,0.026354,165.521,,2.6354,0.165521,,,,7.85398e-5
Test7,1-Compress,1.667,4.659,0.16,0.013,,0.0332019,165.521,,3.32019,0.165521,,,,7.85398e-5
Test7,1-Compress,2.000,4.628,0.191,0.013,,0.0396348,165.521,,3.96348,0.165521,,,,7.85398e-5
Test7,1-Compress,2.333,4.596,0.223,0.013,,0.0462752,165.521,,4.62752,0.165521,,,,7.85398e-5
Test7,1-Compress,2.667,4.563,0.256,0.013,,0.0531231,165.521,,5.31231,0.165521,,,,7.85398e-5
Test7,1-Compress,3.000,4.531,0.288,0.013,,0.0597634,165.521,,5.97634,0.165521,,,,7.85398e-5
Test7,1-Compress,3.333,4.499,0.32,0.013,,0.0664038,165.521,,6.64038,0.165521,,,,7.85398e-5
Test7,1-Compress,3.667,4.466,0.353,0.013,,0.0732517,165.521,,7.32517,0.165521,,,,7.85398e-5
Test7,1-Compress,4.000,4.434,0.385,0.013,,0.0798921,165.521,,7.98921,0.165521,,,,7.85398e-5
Test7,1-Compress,4.333,4.403,0.416,0.020,,0.086325,254.648,,8.6325,0.254648,,,,7.85398e-5
Test7,1-Compress,4.667,4.37,0.449,0.020,,0.0931729,254.648,,9.31729,0.254648,,,,7.85398e-5
Test7,1-Compress,5.000,4.338,0.481,0.020,,0.0998132,254.648,,9.98132,0.254648,,,,7.85398e-5
Test7,1-Compress,5.333,4.306,0.513,0.020,,0.106454,254.648,,10.6454,0.254648,,,,7.85398e-5
Test7,1-Compress,5.667,4.273,0.546,0.027,,0.113302,343.775,,11.3302,0.343775,,,,7.85398e-5
Test7,1-Compress,6.000,4.241,0.578,0.027,,0.119942,343.775,,11.9942,0.343775,,,,7.85398e-5
Test7,1-Compress,6.333,4.209,0.61,0.034,,0.126582,432.902,,12.6582,0.432902,,,,7.85398e-5
Test7,1-Compress,6.667,4.177,0.642,0.027,,0.133223,343.775,,13.3223,0.343775,,,,7.85398e-5
Test7,1-Compress,7.000,4.145,0.674,0.027,,0.139863,343.775,,13.9863,0.343775,,,,7.85398e-5
Test7,1-Compress,7.333,4.113,0.706,0.034,,0.146503,432.902,,14.6503,0.432902,,,,7.85398e-5
Test7,1-Compress,7.667,4.08,0.739,0.034,,0.153351,432.902,,15.3351,0.432902,,,,7.85398e-5
Test7,1-Compress,8.000,4.048,0.771,0.047,,0.159992,598.423,,15.9992,0.598423,,,,7.85398e-5
Test7,1-Compress,8.333,4.016,0.803,0.040,,0.166632,509.296,,16.6632,0.509296,,,,7.85398e-5
Test7,1-Compress,8.667,3.983,0.836,0.034,,0.17348,432.902,,17.348,0.432902,,,,7.85398e-5
Test7,1-Compress,9.000,3.952,0.867,0.047,,0.179913,598.423,,17.9913,0.598423,,,,7.85398e-5
Test7,1-Compress,9.333,3.92,0.899,0.047,,0.186553,598.423,,18.6553,0.598423,,,,7.85398e-5
Test7,1-Compress,9.667,3.887,0.932,0.068,,0.193401,865.803,,19.3401,0.865803,,,,7.85398e-5
Test7,1-Compress,10.000,3.855,0.964,0.047,,0.200042,598.423,,20.0042,0.598423,,,,7.85398e-5
Test7,1-Compress,10.333,3.823,0.996,0.061,,0.206682,776.676,,20.6682,0.776676,,,,7.85398e-5
Test7,1-Compress,10.667,3.791,1.028,0.061,,0.213322,776.676,,21.3322,0.776676,,,,7.85398e-5
Test7,1-Compress,11.000,3.759,1.06,0.068,,0.219963,865.803,,21.9963,0.865803,,,,7.85398e-5
Test7,1-Compress,11.333,3.727,1.092,0.068,,0.226603,865.803,,22.6603,0.865803,,,,7.85398e-5
Test7,1-Compress,11.667,3.694,1.125,0.068,,0.233451,865.803,,23.3451,0.865803,,,,7.85398e-5
Test7,1-Compress,12.000,3.662,1.157,0.068,,0.240091,865.803,,24.0091,0.865803,,,,7.85398e-5
Test7,1-Compress,12.333,3.63,1.189,0.068,,0.246732,865.803,,24.6732,0.865803,,,,7.85398e-5
Test7,1-Compress,12.667,3.597,1.222,0.068,,0.25358,865.803,,25.358,0.865803,,,,7.85398e-5
Test7,1-Compress,13.000,3.566,1.253,0.068,,0.260012,865.803,,26.0012,0.865803,,,,7.85398e-5
Test7,1-Compress,13.333,3.534,1.285,0.068,,0.266653,865.803,,26.6653,0.865803,,,,7.85398e-5
Test7,1-Compress,13.667,3.501,1.318,0.068,,0.273501,865.803,,27.3501,0.865803,,,,7.85398e-5
Test7,1-Compress,14.000,3.469,1.35,0.068,,0.280141,865.803,,28.0141,0.865803,,,,7.85398e-5
Test7,1-Compress,14.333,3.437,1.382,0.068,,0.286781,865.803,,28.6781,0.865803,,,,7.85398e-5
Test7,1-Compress,14.667,3.405,1.414,0.088,,0.293422,1120.45,,29.3422,1.12045,,,,7.85398e-5
Test7,1-Compress,15.000,3.373,1.446,0.088,,0.300062,1120.45,,30.0062,1.12045,,,,7.85398e-5
Test7,1-Compress,15.333,3.341,1.478,0.095,,0.306703,1209.58,,30.6703,1.20958,,,,7.85398e-5
Test7,1-Compress,15.667,3.308,1.511,0.101,,0.313551,1285.97,,31.3551,1.28597,,,,7.85398e-5
Test7,1-Compress,16.000,3.276,1.543,0.108,,0.320191,1375.1,,32.0191,1.3751,,,,7.85398e-5
Test7,1-Compress,16.333,3.244,1.575,0.108,,0.326831,1375.1,,32.6831,1.3751,,,,7.85398e-5
Test7,1-Compress,16.667,3.212,1.607,0.122,,0.333472,1553.35,,33.3472,1.55335,,,,7.85398e-5
Test7,1-Compress,17.000,3.18,1.639,0.122,,0.340112,1553.35,,34.0112,1.55335,,,,7.85398e-5
Test7,1-Compress,17.333,3.148,1.671,0.122,,0.346752,1553.35,,34.6752,1.55335,,,,7.85398e-5
Test7,1-Compress,17.667,3.115,1.704,0.122,,0.3536,1553.35,,35.36,1.55335,,,,7.85398e-5
Test7,1-Compress,18.000,3.083,1.736,0.122,,0.360241,1553.35,,36.0241,1.55335,,,,7.85398e-5
Test7,1-Compress,18.333,3.052,1.767,0.122,,0.366674,1553.35,,36.6674,1.55335,,,,7.85398e-5
Test7,1-Compress,18.667,3.019,1.8,0.122,,0.373521,1553.35,,37.3521,1.55335,,,,7.85398e-5
Test7,1-Compress,19.000,2.987,1.832,0.122,,0.380162,1553.35,,38.0162,1.55335,,,,7.85398e-5
Test7,1-Compress,19.333,2.954,1.865,0.129,,0.38701,1642.48,,38.701,1.64248,,,,7.85398e-5
Test7,1-Compress,19.667,2.922,1.897,0.129,,0.39365,1642.48,,39.365,1.64248,,,,7.85398e-5
Test7,1-Compress,20.000,2.89,1.929,0.135,,0.400291,1718.87,,40.0291,1.71887,,,,7.85398e-5
Test7,1-Compress,20.333,2.858,1.961,0.142,,0.406931,1808,,40.6931,1.808,,,,7.85398e-5
Test7,1-Compress,20.667,2.825,1.994,0.156,,0.413779,1986.25,,41.3779,1.98625,,,,7.85398e-5
Test7,1-Compress,21.000,2.793,2.026,0.149,,0.420419,1897.13,,42.0419,1.89713,,,,7.85398e-5
Test7,1-Compress,21.333,2.762,2.057,0.156,,0.426852,1986.25,,42.6852,1.98625,,,,7.85398e-5
Test7,1-Compress,21.667,2.729,2.09,0.176,,0.4337,2240.9,,43.37,2.2409,,,,7.85398e-5
Test7,1-Compress,22.000,2.697,2.122,0.176,,0.44034,2240.9,,44.034,2.2409,,,,7.85398e-5
Test7,1-Compress,22.333,2.665,2.154,0.176,,0.446981,2240.9,,44.6981,2.2409,,,,7.85398e-5
Test7,1-Compress,22.667,2.632,2.187,0.176,,0.453829,2240.9,,45.3829,2.2409,,,,7.85398e-5
Test7,1-Compress,23.000,2.601,2.218,0.169,,0.460261,2151.78,,46.0261,2.15178,,,,7.85398e-5
Test7,1-Compress,23.333,2.569,2.25,0.169,,0.466902,2151.78,,46.6902,2.15178,,,,7.85398e-5
Test7,1-Compress,23.667,2.536,2.283,0.169,,0.47375,2151.78,,47.375,2.15178,,,,7.85398e-5
Test7,1-Compress,24.000,2.504,2.315,0.176,,0.48039,2240.9,,48.039,2.2409,,,,7.85398e-5
Test7,1-Compress,24.333,2.472,2.347,0.183,,0.487031,2330.03,,48.7031,2.33003,,,,7.85398e-5
Test7,1-Compress,24.667,2.439,2.38,0.210,,0.493878,2673.8,,49.3878,2.6738,,,,7.85398e-5
Test7,1-Compress,25.000,2.407,2.412,0.210,,0.500519,2673.8,,50.0519,2.6738,,,,7.85398e-5
Test7,1-Compress,25.333,2.376,2.443,0.210,,0.506952,2673.8,,50.6952,2.6738,,,,7.85398e-5
Test7,1-Compress,25.667,2.343,2.476,0.217,,0.5138,2762.93,,51.38,2.76293,,,,7.85398e-5
Test7,1-Compress,26.000,2.311,2.508,0.217,,0.52044,2762.93,,52.044,2.76293,,,,7.85398e-5
Test7,1-Compress,26.333,2.279,2.54,0.237,,0.52708,3017.58,,52.708,3.01758,,,,7.85398e-5
Test7,1-Compress,26.667,2.246,2.573,0.251,,0.533928,3195.83,,53.3928,3.19583,,,,7.85398e-5
Test7,1-Compress,27.000,2.215,2.604,0.264,,0.540361,3361.35,,54.0361,3.36135,,,,7.85398e-5
Test7,1-Compress,27.333,2.183,2.636,0.258,,0.547001,3284.96,,54.7001,3.28496,,,,7.85398e-5
Test7,1-Compress,27.667,2.15,2.669,0.231,,0.553849,2941.18,,55.3849,2.94118,,,,7.85398e-5
Test7,1-Compress,28.000,2.118,2.701,0.231,,0.56049,2941.18,,56.049,2.94118,,,,7.85398e-5
Test7,1-Compress,28.333,2.086,2.733,0.237,,0.56713,3017.58,,56.713,3.01758,,,,7.85398e-5
Test7,1-Compress,28.667,2.053,2.766,0.244,,0.573978,3106.71,,57.3978,3.10671,,,,7.85398e-5
Test7,1-Compress,29.000,2.021,2.798,0.264,,0.580618,3361.35,,58.0618,3.36135,,,,7.85398e-5
Test7,1-Compress,29.333,1.99,2.829,0.278,,0.587051,3539.61,,58.7051,3.53961,,,,7.85398e-5
Test7,1-Compress,29.667,1.957,2.862,0.292,,0.593899,3717.86,,59.3899,3.71786,,,,7.85398e-5
Test7,1-Compress,30.000,1.928,2.891,0.298,,0.599917,3794.25,,59.9917,3.79425,,,,7.85398e-5
Test7,1-Recover,30.333,1.957,2.862,0.298,,0.593899,3794.25,,59.3899,3.79425,,,,7.85398e-5
Test7,1-Recover,30.667,1.99,2.829,0.292,,0.587051,3717.86,,58.7051,3.71786,,,,7.85398e-5
Test7,1-Recover,31.000,2.022,2.797,0.271,,0.580411,3450.48,,58.0411,3.45048,,,,7.85398e-5
Test7,1-Recover,31.333,2.054,2.765,0.251,,0.57377,3195.83,,57.377,3.19583,,,,7.85398e-5
Test7,1-Recover,31.667,2.087,2.732,0.237,,0.566923,3017.58,,56.6923,3.01758,,,,7.85398e-5
Test7,1-Recover,32.000,2.118,2.701,0.237,,0.56049,3017.58,,56.049,3.01758,,,,7.85398e-5
Test7,1-Recover,32.333,2.15,2.669,0.237,,0.553849,3017.58,,55.3849,3.01758,,,,7.85398e-5
Test7,1-Recover,32.667,2.183,2.636,0.251,,0.547001,3195.83,,54.7001,3.19583,,,,7.85398e-5
Test7,1-Recover,33.000,2.215,2.604,0.231,,0.540361,2941.18,,54.0361,2.94118,,,,7.85398e-5
Test7,1-Recover,33.333,2.246,2.573,0.224,,0.533928,2852.06,,53.3928,2.85206,,,,7.85398e-5
Test7,1-Recover,33.667,2.279,2.54,0.217,,0.52708,2762.93,,52.708,2.76293,,,,7.85398e-5
Test7,1-Recover,34.000,2.311,2.508,0.217,,0.52044,2762.93,,52.044,2.76293,,,,7.85398e-5
Test7,1-Recover,34.333,2.343,2.476,0.217,,0.5138,2762.93,,51.38,2.76293,,,,7.85398e-5
Test7,1-Recover,34.667,2.376,2.443,0.217,,0.506952,2762.93,,50.6952,2.76293,,,,7.85398e-5
Test7,1-Recover,35.000,2.408,2.411,0.183,,0.500311,2330.03,,50.0311,2.33003,,,,7.85398e-5
Test7,1-Recover,35.333,2.44,2.379,0.176,,0.493671,2240.9,,49.3671,2.2409,,,,7.85398e-5
Test7,1-Recover,35.667,2.472,2.347,0.183,,0.487031,2330.03,,48.7031,2.33003,,,,7.85398e-5
Test7,1-Recover,36.000,2.504,2.315,0.176,,0.48039,2240.9,,48.039,2.2409,,,,7.85398e-5
Test7,1-Recover,36.333,2.536,2.283,0.176,,0.47375,2240.9,,47.375,2.2409,,,,7.85398e-5
Test7,1-Recover,36.667,2.569,2.25,0.176,,0.466902,2240.9,,46.6902,2.2409,,,,7.85398e-5
Test7,1-Recover,37.000,2.601,2.218,0.176,,0.460261,2240.9,,46.0261,2.2409,,,,7.85398e-5
Test7,1-Recover,37.333,2.632,2.187,0.176,,0.453829,2240.9,,45.3829,2.2409,,,,7.85398e-5
Test7,1-Recover,37.667,2.665,2.154,0.169,,0.446981,2151.78,,44.6981,2.15178,,,,7.85398e-5
Test7,1-Recover,38.000,2.697,2.122,0.169,,0.44034,2151.78,,44.034,2.15178,,,,7.85398e-5
Test7,1-Recover,38.333,2.729,2.09,0.135,,0.4337,1718.87,,43.37,1.71887,,,,7.85398e-5
Test7,1-Recover,38.667,2.762,2.057,0.156,,0.426852,1986.25,,42.6852,1.98625,,,,7.85398e-5
Test7,1-Recover,39.000,2.794,2.025,0.142,,0.420212,1808,,42.0212,1.808,,,,7.85398e-5
Test7,1-Recover,39.333,2.826,1.993,0.135,,0.413571,1718.87,,41.3571,1.71887,,,,7.85398e-5
Test7,1-Recover,39.667,2.858,1.961,0.142,,0.406931,1808,,40.6931,1.808,,,,7.85398e-5
Test7,1-Recover,40.000,2.89,1.929,0.122,,0.400291,1553.35,,40.0291,1.55335,,,,7.85398e-5
Test7,1-Recover,40.333,2.922,1.897,0.122,,0.39365,1553.35,,39.365,1.55335,,,,7.85398e-5
Test7,1-Recover,40.667,2.955,1.864,0.122,,0.386802,1553.35,,38.6802,1.55335,,,,7.85398e-5
Test7,1-Recover,41.000,2.987,1.832,0.122,,0.380162,1553.35,,38.0162,1.55335,,,,7.85398e-5
Test7,1-Recover,41.333,3.019,1.8,0.122,,0.373521,1553.35,,37.3521,1.55335,,,,7.85398e-5
Test7,1-Recover,41.667,3.052,1.767,0.122,,0.366674,1553.35,,36.6674,1.55335,,,,7.85398e-5
Test7,1-Recover,42.000,3.083,1.736,0.122,,0.360241,1553.35,,36.0241,1.55335,,,,7.85398e-5
Test7,1-Recover,42.333,3.115,1.704,0.108,,0.3536,1375.1,,35.36,1.3751,,,,7.85398e-5
Test7,1-Recover,42.667,3.148,1.671,0.101,,0.346752,1285.97,,34.6752,1.28597,,,,7.85398e-5
Test7,1-Recover,43.000,3.18,1.639,0.101,,0.340112,1285.97,,34.0112,1.28597,,,,7.85398e-5
Test7,1-Recover,43.333,3.212,1.607,0.081,,0.333472,1031.32,,33.3472,1.03132,,,,7.85398e-5
Test7,1-Recover,43.667,3.245,1.574,0.074,,0.326624,942.197,,32.6624,0.942197,,,,7.85398e-5
Test7,1-Recover,44.000,3.277,1.542,0.068,,0.319983,865.803,,31.9983,0.865803,,,,7.85398e-5
Test7,1-Recover,44.333,3.308,1.511,0.074,,0.313551,942.197,,31.3551,0.942197,,,,7.85398e-5
Test7,1-Recover,44.667,3.341,1.478,0.074,,0.306703,942.197,,30.6703,0.942197,,,,7.85398e-5
Test7,1-Recover,45.000,3.373,1.446,0.068,,0.300062,865.803,,30.0062,0.865803,,,,7.85398e-5
Test7,1-Recover,45.333,3.405,1.414,0.068,,0.293422,865.803,,29.3422,0.865803,,,,7.85398e-5
Test7,1-Recover,45.667,3.438,1.381,0.068,,0.286574,865.803,,28.6574,0.865803,,,,7.85398e-5
Test7,1-Recover,46.000,3.469,1.35,0.068,,0.280141,865.803,,28.0141,0.865803,,,,7.85398e-5
Test7,1-Recover,46.333,3.501,1.318,0.068,,0.273501,865.803,,27.3501,0.865803,,,,7.85398e-5
Test7,1-Recover,46.667,3.534,1.285,0.068,,0.266653,865.803,,26.6653,0.865803,,,,7.85398e-5
Test7,1-Recover,47.000,3.566,1.253,0.068,,0.260012,865.803,,26.0012,0.865803,,,,7.85398e-5
Test7,1-Recover,47.333,3.598,1.221,0.061,,0.253372,776.676,,25.3372,0.776676,,,,7.85398e-5
Test7,1-Recover,47.667,3.631,1.188,0.068,,0.246524,865.803,,24.6524,0.865803,,,,7.85398e-5
Test7,1-Recover,48.000,3.663,1.156,0.068,,0.239884,865.803,,23.9884,0.865803,,,,7.85398e-5
Test7,1-Recover,48.333,3.694,1.125,0.061,,0.233451,776.676,,23.3451,0.776676,,,,7.85398e-5
Test7,1-Recover,48.667,3.727,1.092,0.061,,0.226603,776.676,,22.6603,0.776676,,,,7.85398e-5
Test7,1-Recover,49.000,3.759,1.06,0.061,,0.219963,776.676,,21.9963,0.776676,,,,7.85398e-5
Test7,1-Recover,49.333,3.791,1.028,0.061,,0.213322,776.676,,21.3322,0.776676,,,,7.85398e-5
Test7,1-Recover,49.667,3.824,0.995,0.054,,0.206474,687.549,,20.6474,0.687549,,,,7.85398e-5
Test7,1-Recover,50.000,3.855,0.964,0.034,,0.200042,432.902,,20.0042,0.432902,,,,7.85398e-5
Test7,1-Recover,50.333,3.887,0.932,0.034,,0.193401,432.902,,19.3401,0.432902,,,,7.85398e-5
Test7,1-Recover,50.667,3.92,0.899,0.020,,0.186553,254.648,,18.6553,0.254648,,,,7.85398e-5
Test7,1-Recover,51.000,3.952,0.867,0.027,,0.179913,343.775,,17.9913,0.343775,,,,7.85398e-5
Test7,1-Recover,51.333,3.984,0.835,0.020,,0.173272,254.648,,17.3272,0.254648,,,,7.85398e-5
Test7,1-Recover,51.667,4.017,0.802,0.013,,0.166425,165.521,,16.6425,0.165521,,,,7.85398e-5
Test7,1-Recover,52.000,4.049,0.77,0.013,,0.159784,165.521,,15.9784,0.165521,,,,7.85398e-5
Test7,1-Recover,52.333,4.08,0.739,0.020,,0.153351,254.648,,15.3351,0.254648,,,,7.85398e-5
Test7,1-Recover,52.667,4.113,0.706,0.020,,0.146503,254.648,,14.6503,0.254648,,,,7.85398e-5
Test7,1-Recover,53.000,4.145,0.674,0.020,,0.139863,254.648,,13.9863,0.254648,,,,7.85398e-5
Test7,1-Recover,53.333,4.177,0.642,0.020,,0.133223,254.648,,13.3223,0.254648,,,,7.85398e-5
Test7,1-Recover,53.667,4.21,0.609,0.020,,0.126375,254.648,,12.6375,0.254648,,,,7.85398e-5
Test7,1-Recover,54.000,4.241,0.578,0.027,,0.119942,343.775,,11.9942,0.343775,,,,7.85398e-5
Test7,1-Recover,54.333,4.274,0.545,0.027,,0.113094,343.775,,11.3094,0.343775,,,,7.85398e-5
Test7,1-Recover,54.667,4.306,0.513,0.020,,0.106454,254.648,,10.6454,0.254648,,,,7.85398e-5
Test7,1-Recover,55.000,4.338,0.481,0.027,,0.0998132,343.775,,9.98132,0.343775,,,,7.85398e-5
Test7,1-Recover,55.333,4.37,0.449,0.020,,0.0931729,254.648,,9.31729,0.254648,,,,7.85398e-5
Test7,1-Recover,55.667,4.403,0.416,0.020,,0.086325,254.648,,8.6325,0.254648,,,,7.85398e-5
Test7,1-Recover,56.000,4.435,0.384,0.020,,0.0796846,254.648,,7.96846,0.254648,,,,7.85398e-5
Test7,1-Recover,56.333,4.467,0.352,0.013,,0.0730442,165.521,,7.30442,0.165521,,,,7.85398e-5
Test7,1-Recover,56.667,4.5,0.319,0.013,,0.0661963,165.521,,6.61963,0.165521,,,,7.85398e-5
Test7,1-Recover,57.000,4.531,0.288,0.013,,0.0597634,165.521,,5.97634,0.165521,,,,7.85398e-5
Test7,1-Recover,57.333,4.563,0.256,0.013,,0.0531231,165.521,,5.31231,0.165521,,,,7.85398e-5
Test7,1-Recover,57.667,4.596,0.223,0.013,,0.0462752,165.521,,4.62752,0.165521,,,,7.85398e-5
Test7,1-Recover,58.000,4.628,0.191,0.013,,0.0396348,165.521,,3.96348,0.165521,,,,7.85398e-5
Test7,1-Recover,58.333,4.66,0.159,0.013,,0.0329944,165.521,,3.29944,0.165521,,,,7.85398e-5
Test7,1-Recover,58.667,4.692,0.127,0.013,,0.026354,165.521,,2.6354,0.165521,,,,7.85398e-5
Test7,1-Recover,59.000,4.724,0.095,0.013,,0.0197136,165.521,,1.97136,0.165521,,,,7.85398e-5
Test7,1-Recover,59.333,4.756,0.063,0.006,,0.0130733,76.3944,,1.30733,0.0763944,,,,7.85398e-5
Test7,1-Recover,59.667,4.789,0.03,0.006,,0.00622536,76.3944,,0.622536,0.0763944,,,,7.85398e-5
Test7,1-Recover,60.000,4.819,-0,-0.007,,0,-89.1268,,0,-0.0891268,,,,7.85398e-5
Test7,2-Compress,60.317,4.793,0.026,-0.007,,0.00539531,-89.1268,,0.539531,-0.0891268,,,,7.85398e-5
Test7,2-Compress,60.650,4.761,0.058,0.006,,0.0120357,76.3944,,1.20357,0.0763944,,,,7.85398e-5
Test7,2-Compress,60.983,4.729,0.09,0.013,,0.0186761,165.521,,1.86761,0.165521,,,,7.85398e-5
Test7,2-Compress,61.317,4.697,0.122,0.013,,0.0253165,165.521,,2.53165,0.165521,,,,7.85398e-5
Test7,2-Compress,61.650,4.665,0.154,0.020,,0.0319568,254.648,,3.19568,0.254648,,,,7.85398e-5
Test7,2-Compress,61.983,4.633,0.186,0.020,,0.0385972,254.648,,3.85972,0.254648,,,,7.85398e-5
Test7,2-Compress,62.317,4.6,0.219,0.020,,0.0454451,254.648,,4.54451,0.254648,,,,7.85398e-5
Test7,2-Compress,62.650,4.568,0.251,0.027,,0.0520855,343.775,,5.20855,0.343775,,,,7.85398e-5
Test7,2-Compress,62.983,4.537,0.282,0.020,,0.0585184,254.648,,5.85184,0.254648,,,,7.85398e-5
Test7,2-Compress,63.317,4.504,0.315,0.013,,0.0653663,165.521,,6.53663,0.165521,,,,7.85398e-5
Test7,2-Compress,63.650,4.472,0.347,0.020,,0.0720066,254.648,,7.20066,0.254648,,,,7.85398e-5
Test7,2-Compress,63.983,4.44,0.379,0.020,,0.078647,254.648,,7.8647,0.254648,,,,7.85398e-5
Test7,2-Compress,64.317,4.407,0.412,0.020,,0.0854949,254.648,,8.54949,0.254648,,,,7.85398e-5
Test7,2-Compress,64.650,4.375,0.444,0.013,,0.0921353,165.521,,9.21353,0.165521,,,,7.85398e-5
Test7,2-Compress,64.983,4.343,0.476,0.013,,0.0987757,165.521,,9.87757,0.165521,,,,7.85398e-5
Test7,2-Compress,65.317,4.31,0.509,0.013,,0.105624,165.521,,10.5624,0.165521,,,,7.85398e-5
Test7,2-Compress,65.650,4.278,0.541,0.020,,0.112264,254.648,,11.2264,0.254648,,,,7.85398e-5
Test7,2-Compress,65.983,4.247,0.572,0.013,,0.118697,165.521,,11.8697,0.165521,,,,7.85398e-5
Test7,2-Compress,66.317,4.214,0.605,0.020,,0.125545,254.648,,12.5545,0.254648,,,,7.85398e-5
Test7,2-Compress,66.650,4.182,0.637,0.027,,0.132185,343.775,,13.2185,0.343775,,,,7.85398e-5
Test7,2-Compress,66.983,4.15,0.669,0.020,,0.138825,254.648,,13.8825,0.254648,,,,7.85398e-5
Test7,2-Compress,67.317,4.117,0.702,0.020,,0.145673,254.648,,14.5673,0.254648,,,,7.85398e-5
Test7,2-Compress,67.650,4.086,0.733,0.020,,0.152106,254.648,,15.2106,0.254648,,,,7.85398e-5
Test7,2-Compress,67.983,4.054,0.765,0.020,,0.158747,254.648,,15.8747,0.254648,,,,7.85398e-5
Test7,2-Compress,68.317,4.021,0.798,0.027,,0.165595,343.775,,16.5595,0.343775,,,,7.85398e-5
Test7,2-Compress,68.650,3.989,0.83,0.034,,0.172235,432.902,,17.2235,0.432902,,,,7.85398e-5
Test7,2-Compress,68.983,3.957,0.862,0.047,,0.178875,598.423,,17.8875,0.598423,,,,7.85398e-5
Test7,2-Compress,69.317,3.924,0.895,0.054,,0.185723,687.549,,18.5723,0.687549,,,,7.85398e-5
Test7,2-Compress,69.650,3.892,0.927,0.054,,0.192364,687.549,,19.2364,0.687549,,,,7.85398e-5
Test7,2-Compress,69.983,3.861,0.958,0.040,,0.198796,509.296,,19.8796,0.509296,,,,7.85398e-5
Test7,2-Compress,70.317,3.828,0.991,0.061,,0.205644,776.676,,20.5644,0.776676,,,,7.85398e-5
Test7,2-Compress,70.650,3.796,1.023,0.068,,0.212285,865.803,,21.2285,0.865803,,,,7.85398e-5
Test7,2-Compress,70.983,3.764,1.055,0.068,,0.218925,865.803,,21.8925,0.865803,,,,7.85398e-5
Test7,2-Compress,71.317,3.731,1.088,0.068,,0.225773,865.803,,22.5773,0.865803,,,,7.85398e-5
Test7,2-Compress,71.650,3.7,1.119,0.068,,0.232206,865.803,,23.2206,0.865803,,,,7.85398e-5
Test7,2-Compress,71.983,3.668,1.151,0.074,,0.238846,942.197,,23.8846,0.942197,,,,7.85398e-5
Test7,2-Compress,72.317,3.635,1.184,0.068,,0.245694,865.803,,24.5694,0.865803,,,,7.85398e-5
Test7,2-Compress,72.650,3.603,1.216,0.068,,0.252335,865.803,,25.2335,0.865803,,,,7.85398e-5
Test7,2-Compress,72.983,3.571,1.248,0.068,,0.258975,865.803,,25.8975,0.865803,,,,7.85398e-5
Test7,2-Compress,73.317,3.538,1.281,0.068,,0.265823,865.803,,26.5823,0.865803,,,,7.85398e-5
Test7,2-Compress,73.650,3.506,1.313,0.074,,0.272463,942.197,,27.2463,0.942197,,,,7.85398e-5
Test7,2-Compress,73.983,3.475,1.344,0.081,,0.278896,1031.32,,27.8896,1.03132,,,,7.85398e-5
Test7,2-Compress,74.317,3.442,1.377,0.074,,0.285744,942.197,,28.5744,0.942197,,,,7.85398e-5
Test7,2-Compress,74.650,3.41,1.409,0.074,,0.292384,942.197,,29.2384,0.942197,,,,7.85398e-5
Test7,2-Compress,74.983,3.378,1.441,0.081,,0.299025,1031.32,,29.9025,1.03132,,,,7.85398e-5
Test7,2-Compress,75.317,3.345,1.474,0.074,,0.305873,942.197,,30.5873,0.942197,,,,7.85398e-5
Test7,2-Compress,75.650,3.314,1.505,0.088,,0.312305,1120.45,,31.2305,1.12045,,,,7.85398e-5
Test7,2-Compress,75.983,3.282,1.537,0.088,,0.318946,1120.45,,31.8946,1.12045,,,,7.85398e-5
Test7,2-Compress,76.317,3.249,1.57,0.122,,0.325794,1553.35,,32.5794,1.55335,,,,7.85398e-5
Test7,2-Compress,76.650,3.217,1.602,0.122,,0.332434,1553.35,,33.2434,1.55335,,,,7.85398e-5
Test7,2-Compress,76.983,3.185,1.634,0.122,,0.339074,1553.35,,33.9074,1.55335,,,,7.85398e-5
Test7,2-Compress,77.317,3.152,1.667,0.122,,0.345922,1553.35,,34.5922,1.55335,,,,7.85398e-5
Test7,2-Compress,77.650,3.12,1.699,0.122,,0.352563,1553.35,,35.2563,1.55335,,,,7.85398e-5
Test7,2-Compress,77.983,3.088,1.731,0.129,,0.359203,1642.48,,35.9203,1.64248,,,,7.85398e-5
Test7,2-Compress,78.317,3.055,1.764,0.122,,0.366051,1553.35,,36.6051,1.55335,,,,7.85398e-5
Test7,2-Compress,78.650,3.024,1.795,0.122,,0.372484,1553.35,,37.2484,1.55335,,,,7.85398e-5
Test7,2-Compress,78.983,2.992,1.827,0.135,,0.379124,1718.87,,37.9124,1.71887,,,,7.85398e-5
Test7,2-Compress,79.317,2.959,1.86,0.135,,0.385972,1718.87,,38.5972,1.71887,,,,7.85398e-5
Test7,2-Compress,79.650,2.927,1.892,0.142,,0.392613,1808,,39.2613,1.808,,,,7.85398e-5
Test7,2-Compress,79.983,2.895,1.924,0.156,,0.399253,1986.25,,39.9253,1.98625,,,,7.85398e-5
Test7,2-Compress,80.317,2.863,1.956,0.163,,0.405893,2075.38,,40.5893,2.07538,,,,7.85398e-5
Test7,2-Compress,80.650,2.831,1.988,0.163,,0.412534,2075.38,,41.2534,2.07538,,,,7.85398e-5
Test7,2-Compress,80.983,2.799,2.02,0.176,,0.419174,2240.9,,41.9174,2.2409,,,,7.85398e-5
Test7,2-Compress,81.317,2.766,2.053,0.176,,0.426022,2240.9,,42.6022,2.2409,,,,7.85398e-5
Test7,2-Compress,81.650,2.734,2.085,0.176,,0.432662,2240.9,,43.2662,2.2409,,,,7.85398e-5
Test7,2-Compress,81.983,2.702,2.117,0.176,,0.439303,2240.9,,43.9303,2.2409,,,,7.85398e-5
Test7,2-Compress,82.317,2.669,2.15,0.176,,0.446151,2240.9,,44.6151,2.2409,,,,7.85398e-5
Test7,2-Compress,82.650,2.638,2.181,0.176,,0.452584,2240.9,,45.2584,2.2409,,,,7.85398e-5
Test7,2-Compress,82.983,2.606,2.213,0.176,,0.459224,2240.9,,45.9224,2.2409,,,,7.85398e-5
Test7,2-Compress,83.317,2.573,2.246,0.176,,0.466072,2240.9,,46.6072,2.2409,,,,7.85398e-5
Test7,2-Compress,83.650,2.541,2.278,0.176,,0.472712,2240.9,,47.2712,2.2409,,,,7.85398e-5
Test7,2-Compress,83.983,2.509,2.31,0.183,,0.479353,2330.03,,47.9353,2.33003,,,,7.85398e-5
Test7,2-Compress,84.317,2.477,2.342,0.217,,0.485993,2762.93,,48.5993,2.76293,,,,7.85398e-5
Test7,2-Compress,84.650,2.445,2.374,0.231,,0.492633,2941.18,,49.2633,2.94118,,,,7.85398e-5
Test7,2-Compress,84.983,2.413,2.406,0.231,,0.499274,2941.18,,49.9274,2.94118,,,,7.85398e-5
Test7,2-Compress,85.317,2.38,2.439,0.231,,0.506122,2941.18,,50.6122,2.94118,,,,7.85398e-5
Test7,2-Compress,85.650,2.348,2.471,0.231,,0.512762,2941.18,,51.2762,2.94118,,,,7.85398e-5
Test7,2-Compress,85.983,2.316,2.503,0.231,,0.519402,2941.18,,51.9402,2.94118,,,,7.85398e-5
Test7,2-Compress,86.317,2.283,2.536,0.237,,0.52625,3017.58,,52.625,3.01758,,,,7.85398e-5
Test7,2-Compress,86.650,2.252,2.567,0.251,,0.532683,3195.83,,53.2683,3.19583,,,,7.85398e-5
Test7,2-Compress,86.983,2.22,2.599,0.244,,0.539324,3106.71,,53.9324,3.10671,,,,7.85398e-5
Test7,2-Compress,87.317,2.187,2.632,0.251,,0.546171,3195.83,,54.6171,3.19583,,,,7.85398e-5
Test7,2-Compress,87.650,2.155,2.664,0.237,,0.552812,3017.58,,55.2812,3.01758,,,,7.85398e-5
Test7,2-Compress,87.983,2.123,2.696,0.237,,0.559452,3017.58,,55.9452,3.01758,,,,7.85398e-5
Test7,2-Compress,88.317,2.091,2.728,0.258,,0.566093,3284.96,,56.6093,3.28496,,,,7.85398e-5
Test7,2-Compress,88.650,2.059,2.76,0.264,,0.572733,3361.35,,57.2733,3.36135,,,,7.85398e-5
Test7,2-Compress,88.983,2.027,2.792,0.271,,0.579373,3450.48,,57.9373,3.45048,,,,7.85398e-5
Test7,2-Compress,89.317,1.994,2.825,0.285,,0.586221,3628.73,,58.6221,3.62873,,,,7.85398e-5
Test7,2-Compress,89.650,1.962,2.857,0.285,,0.592862,3628.73,,59.2862,3.62873,,,,7.85398e-5
Test7,2-Compress,89.983,1.93,2.889,0.285,,0.599502,3628.73,,59.9502,3.62873,,,,7.85398e-5
Test7,2-Recover,90.303,1.951,2.868,0.285,,0.595144,3628.73,,59.5144,3.62873,,,,7.85398e-5
Test7,2-Recover,90.637,1.983,2.836,0.285,,0.588504,3628.73,,58.8504,3.62873,,,,7.85398e-5
Test7,2-Recover,90.970,2.015,2.804,0.278,,0.581863,3539.61,,58.1863,3.53961,,,,7.85398e-5
Test7,2-Recover,91.303,2.047,2.772,0.251,,0.575223,3195.83,,57.5223,3.19583,,,,7.85398e-5
Test7,2-Recover,91.637,2.08,2.739,0.237,,0.568375,3017.58,,56.8375,3.01758,,,,7.85398e-5
Test7,2-Recover,91.970,2.112,2.707,0.231,,0.561735,2941.18,,56.1735,2.94118,,,,7.85398e-5
Test7,2-Recover,92.303,2.143,2.676,0.231,,0.555302,2941.18,,55.5302,2.94118,,,,7.85398e-5
Test7,2-Recover,92.637,2.176,2.643,0.258,,0.548454,3284.96,,54.8454,3.28496,,,,7.85398e-5
Test7,2-Recover,92.970,2.208,2.611,0.244,,0.541814,3106.71,,54.1814,3.10671,,,,7.85398e-5
Test7,2-Recover,93.303,2.24,2.579,0.231,,0.535173,2941.18,,53.5173,2.94118,,,,7.85398e-5
Test7,2-Recover,93.637,2.273,2.546,0.231,,0.528325,2941.18,,52.8325,2.94118,,,,7.85398e-5
Test7,2-Recover,93.970,2.304,2.515,0.231,,0.521893,2941.18,,52.1893,2.94118,,,,7.85398e-5
Test7,2-Recover,94.303,2.337,2.482,0.231,,0.515045,2941.18,,51.5045,2.94118,,,,7.85398e-5
Test7,2-Recover,94.637,2.369,2.45,0.217,,0.508404,2762.93,,50.8404,2.76293,,,,7.85398e-5
Test7,2-Recover,94.970,2.401,2.418,0.203,,0.501764,2584.68,,50.1764,2.58468,,,,7.85398e-5
Test7,2-Recover,95.303,2.433,2.386,0.183,,0.495123,2330.03,,49.5123,2.33003,,,,7.85398e-5
Test7,2-Recover,95.637,2.466,2.353,0.190,,0.488276,2419.16,,48.8276,2.41916,,,,7.85398e-5
Test7,2-Recover,95.970,2.498,2.321,0.176,,0.481635,2240.9,,48.1635,2.2409,,,,7.85398e-5
Test7,2-Recover,96.303,2.529,2.29,0.176,,0.475202,2240.9,,47.5202,2.2409,,,,7.85398e-5
Test7,2-Recover,96.637,2.562,2.257,0.176,,0.468354,2240.9,,46.8354,2.2409,,,,7.85398e-5
Test7,2-Recover,96.970,2.594,2.225,0.176,,0.461714,2240.9,,46.1714,2.2409,,,,7.85398e-5
Test7,2-Recover,97.303,2.626,2.193,0.176,,0.455074,2240.9,,45.5074,2.2409,,,,7.85398e-5
Test7,2-Recover,97.637,2.659,2.16,0.176,,0.448226,2240.9,,44.8226,2.2409,,,,7.85398e-5
Test7,2-Recover,97.970,2.69,2.129,0.176,,0.441793,2240.9,,44.1793,2.2409,,,,7.85398e-5
Test7,2-Recover,98.303,2.723,2.096,0.176,,0.434945,2240.9,,43.4945,2.2409,,,,7.85398e-5
Test7,2-Recover,98.637,2.755,2.064,0.149,,0.428305,1897.13,,42.8305,1.89713,,,,7.85398e-5
Test7,2-Recover,98.970,2.787,2.032,0.142,,0.421664,1808,,42.1664,1.808,,,,7.85398e-5
Test7,2-Recover,99.303,2.819,2,0.135,,0.415024,1718.87,,41.5024,1.71887,,,,7.85398e-5
Test7,2-Recover,99.637,2.852,1.967,0.129,,0.408176,1642.48,,40.8176,1.64248,,,,7.85398e-5
Test7,2-Recover,99.970,2.884,1.935,0.122,,0.401536,1553.35,,40.1536,1.55335,,,,7.85398e-5
Test7,2-Recover,100.303,2.916,1.903,0.122,,0.394895,1553.35,,39.4895,1.55335,,,,7.85398e-5
Test7,2-Recover,100.637,2.949,1.87,0.122,,0.388047,1553.35,,38.8047,1.55335,,,,7.85398e-5
Test7,2-Recover,100.970,2.98,1.839,0.122,,0.381614,1553.35,,38.1614,1.55335,,,,7.85398e-5
Test7,2-Recover,101.303,3.012,1.807,0.122,,0.374974,1553.35,,37.4974,1.55335,,,,7.85398e-5
Test7,2-Recover,101.637,3.045,1.774,0.122,,0.368126,1553.35,,36.8126,1.55335,,,,7.85398e-5
Test7,2-Recover,101.970,3.077,1.742,0.122,,0.361486,1553.35,,36.1486,1.55335,,,,7.85398e-5
Test7,2-Recover,102.303,3.109,1.71,0.122,,0.354845,1553.35,,35.4845,1.55335,,,,7.85398e-5
Test7,2-Recover,102.637,3.141,1.678,0.115,,0.348205,1464.23,,34.8205,1.46423,,,,7.85398e-5
Test7,2-Recover,102.970,3.173,1.646,0.081,,0.341565,1031.32,,34.1565,1.03132,,,,7.85398e-5
Test7,2-Recover,103.303,3.205,1.614,0.095,,0.334924,1209.58,,33.4924,1.20958,,,,7.85398e-5
Test7,2-Recover,103.637,3.238,1.581,0.095,,0.328076,1209.58,,32.8076,1.20958,,,,7.85398e-5
Test7,2-Recover,103.970,3.27,1.549,0.081,,0.321436,1031.32,,32.1436,1.03132,,,,7.85398e-5
Test7,2-Recover,104.303,3.302,1.517,0.095,,0.314796,1209.58,,31.4796,1.20958,,,,7.85398e-5
Test7,2-Recover,104.637,3.335,1.484,0.081,,0.307948,1031.32,,30.7948,1.03132,,,,7.85398e-5
Test7,2-Recover,104.970,3.366,1.453,0.074,,0.301515,942.197,,30.1515,0.942197,,,,7.85398e-5
Test7,2-Recover,105.303,3.398,1.421,0.068,,0.294874,865.803,,29.4874,0.865803,,,,7.85398e-5
Test7,2-Recover,105.637,3.431,1.388,0.068,,0.288027,865.803,,28.8027,0.865803,,,,7.85398e-5
Test7,2-Recover,105.970,3.463,1.356,0.068,,0.281386,865.803,,28.1386,0.865803,,,,7.85398e-5
Test7,2-Recover,106.303,3.495,1.324,0.068,,0.274746,865.803,,27.4746,0.865803,,,,7.85398e-5
Test7,2-Recover,106.637,3.527,1.292,0.068,,0.268105,865.803,,26.8105,0.865803,,,,7.85398e-5
Test7,2-Recover,106.970,3.559,1.26,0.068,,0.261465,865.803,,26.1465,0.865803,,,,7.85398e-5
Test7,2-Recover,107.303,3.591,1.228,0.068,,0.254825,865.803,,25.4825,0.865803,,,,7.85398e-5
Test7,2-Recover,107.637,3.624,1.195,0.068,,0.247977,865.803,,24.7977,0.865803,,,,7.85398e-5
Test7,2-Recover,107.970,3.656,1.163,0.068,,0.241336,865.803,,24.1336,0.865803,,,,7.85398e-5
Test7,2-Recover,108.303,3.688,1.131,0.068,,0.234696,865.803,,23.4696,0.865803,,,,7.85398e-5
Test7,2-Recover,108.637,3.721,1.098,0.040,,0.227848,509.296,,22.7848,0.509296,,,,7.85398e-5
Test7,2-Recover,108.970,3.752,1.067,0.068,,0.221415,865.803,,22.1415,0.865803,,,,7.85398e-5
Test7,2-Recover,109.303,3.784,1.035,0.068,,0.214775,865.803,,21.4775,0.865803,,,,7.85398e-5
Test7,2-Recover,109.637,3.817,1.002,0.047,,0.207927,598.423,,20.7927,0.598423,,,,7.85398e-5
Test7,2-Recover,109.970,3.849,0.97,0.034,,0.201287,432.902,,20.1287,0.432902,,,,7.85398e-5
Test7,2-Recover,110.303,3.881,0.938,0.034,,0.194646,432.902,,19.4646,0.432902,,,,7.85398e-5
Test7,2-Recover,110.637,3.913,0.906,0.040,,0.188006,509.296,,18.8006,0.509296,,,,7.85398e-5
Test7,2-Recover,110.970,3.945,0.874,0.027,,0.181365,343.775,,18.1365,0.343775,,,,7.85398e-5
Test7,2-Recover,111.303,3.977,0.842,0.034,,0.174725,432.902,,17.4725,0.432902,,,,7.85398e-5
Test7,2-Recover,111.637,4.01,0.809,0.027,,0.167877,343.775,,16.7877,0.343775,,,,7.85398e-5
Test7,2-Recover,111.970,4.042,0.777,0.027,,0.161237,343.775,,16.1237,0.343775,,,,7.85398e-5
Test7,2-Recover,112.303,4.074,0.745,0.034,,0.154596,432.902,,15.4596,0.432902,,,,7.85398e-5
Test7,2-Recover,112.637,4.107,0.712,0.027,,0.147748,343.775,,14.7748,0.343775,,,,7.85398e-5
Test7,2-Recover,112.970,4.139,0.68,0.020,,0.141108,254.648,,14.1108,0.254648,,,,7.85398e-5
Test7,2-Recover,113.303,4.17,0.649,0.013,,0.134675,165.521,,13.4675,0.165521,,,,7.85398e-5
Test7,2-Recover,113.637,4.203,0.616,0.013,,0.127827,165.521,,12.7827,0.165521,,,,7.85398e-5
Test7,2-Recover,113.970,4.235,0.584,0.013,,0.121187,165.521,,12.1187,0.165521,,,,7.85398e-5
Test7,2-Recover,114.303,4.267,0.552,0.013,,0.114547,165.521,,11.4547,0.165521,,,,7.85398e-5
Test7,2-Recover,114.637,4.3,0.519,0.013,,0.107699,165.521,,10.7699,0.165521,,,,7.85398e-5
Test7,2-Recover,114.970,4.332,0.487,0.013,,0.101058,165.521,,10.1058,0.165521,,,,7.85398e-5
Test7,2-Recover,115.303,4.364,0.455,0.013,,0.0944179,165.521,,9.44179,0.165521,,,,7.85398e-5
Test7,2-Recover,115.637,4.396,0.423,0.013,,0.0877775,165.521,,8.77775,0.165521,,,,7.85398e-5
Test7,2-Recover,115.970,4.428,0.391,0.013,,0.0811372,165.521,,8.11372,0.165521,,,,7.85398e-5
Test7,2-Recover,116.303,4.46,0.359,0.013,,0.0744968,165.521,,7.44968,0.165521,,,,7.85398e-5
Test7,2-Recover,116.637,4.493,0.326,0.013,,0.0676489,165.521,,6.76489,0.165521,,,,7.85398e-5
Test7,2-Recover,116.970,4.525,0.294,0.013,,0.0610085,165.521,,6.10085,0.165521,,,,7.85398e-5
Test7,2-Recover,117.303,4.556,0.263,0.020,,0.0545756,254.648,,5.45756,0.254648,,,,7.85398e-5
Test7,2-Recover,117.637,4.589,0.23,0.013,,0.0477277,165.521,,4.77277,0.165521,,,,7.85398e-5
Test7,2-Recover,117.970,4.621,0.198,0.020,,0.0410874,254.648,,4.10874,0.254648,,,,7.85398e-5
Test7,2-Recover,118.303,4.653,0.166,0.013,,0.034447,165.521,,3.4447,0.165521,,,,7.85398e-5
Test7,2-Recover,118.637,4.686,0.133,0.020,,0.0275991,254.648,,2.75991,0.254648,,,,7.85398e-5
Test7,2-Recover,118.970,4.718,0.101,0.020,,0.0209587,254.648,,2.09587,0.254648,,,,7.85398e-5
Test7,2-Recover,119.303,4.75,0.069,0.013,,0.0143183,165.521,,1.43183,0.165521,,,,7.85398e-5
Test7,2-Recover,119.637,4.782,0.037,0.013,,0.00767794,165.521,,0.767794,0.165521,,,,7.85398e-5
Test7,2-Recover,119.970,4.814,0.005,-0.000,,0.00103756,0,,0.103756,0,,,,7.85398e-5
Test7,3-Compress,120.290,4.8,0.019,0.013,,0.00394273,165.521,,0.394273,0.165521,,,,7.85398e-5
Test7,3-Compress,120.623,4.768,0.051,0.020,,0.0105831,254.648,,1.05831,0.254648,,,,7.85398e-5
Test7,3-Compress,120.957,4.735,0.084,0.013,,0.017431,165.521,,1.7431,0.165521,,,,7.85398e-5
Test7,3-Compress,121.290,4.703,0.116,0.013,,0.0240714,165.521,,2.40714,0.165521,,,,7.85398e-5
Test7,3-Compress,121.623,4.671,0.148,0.013,,0.0307118,165.521,,3.07118,0.165521,,,,7.85398e-5
Test7,3-Compress,121.957,4.638,0.181,0.013,,0.0375597,165.521,,3.75597,0.165521,,,,7.85398e-5
Test7,3-Compress,122.290,4.606,0.213,0.013,,0.0442,165.521,,4.42,0.165521,,,,7.85398e-5
Test7,3-Compress,122.623,4.575,0.244,0.013,,0.0506329,165.521,,5.06329,0.165521,,,,7.85398e-5
Test7,3-Compress,122.957,4.542,0.277,0.013,,0.0574808,165.521,,5.74808,0.165521,,,,7.85398e-5
Test7,3-Compress,123.290,4.51,0.309,0.013,,0.0641212,165.521,,6.41212,0.165521,,,,7.85398e-5
Test7,3-Compress,123.623,4.478,0.341,0.013,,0.0707616,165.521,,7.07616,0.165521,,,,7.85398e-5
Test7,3-Compress,123.957,4.445,0.374,0.013,,0.0776095,165.521,,7.76095,0.165521,,,,7.85398e-5
Test7,3-Compress,124.290,4.414,0.405,0.013,,0.0840423,165.521,,8.40423,0.165521,,,,7.85398e-5
Test7,3-Compress,124.623,4.382,0.437,0.013,,0.0906827,165.521,,9.06827,0.165521,,,,7.85398e-5
Test7,3-Compress,124.957,4.349,0.47,0.013,,0.0975306,165.521,,9.75306,0.165521,,,,7.85398e-5
Test7,3-Compress,125.290,4.317,0.502,0.020,,0.104171,254.648,,10.4171,0.254648,,,,7.85398e-5
Test7,3-Compress,125.623,4.285,0.534,0.020,,0.110811,254.648,,11.0811,0.254648,,,,7.85398e-5
Test7,3-Compress,125.957,4.253,0.566,0.020,,0.117452,254.648,,11.7452,0.254648,,,,7.85398e-5
Test7,3-Compress,126.290,4.22,0.599,0.020,,0.1243,254.648,,12.43,0.254648,,,,7.85398e-5
Test7,3-Compress,126.623,4.189,0.63,0.020,,0.130733,254.648,,13.0733,0.254648,,,,7.85398e-5
Test7,3-Compress,126.957,4.156,0.663,0.027,,0.13758,343.775,,13.758,0.343775,,,,7.85398e-5
Test7,3-Compress,127.290,4.124,0.695,0.027,,0.144221,343.775,,14.4221,0.343775,,,,7.85398e-5
Test7,3-Compress,127.623,4.092,0.727,0.034,,0.150861,432.902,,15.0861,0.432902,,,,7.85398e-5
Test7,3-Compress,127.957,4.059,0.76,0.034,,0.157709,432.902,,15.7709,0.432902,,,,7.85398e-5
Test7,3-Compress,128.290,4.028,0.791,0.047,,0.164142,598.423,,16.4142,0.598423,,,,7.85398e-5
Test7,3-Compress,128.623,3.996,0.823,0.054,,0.170782,687.549,,17.0782,0.687549,,,,7.85398e-5
Test7,3-Compress,128.957,3.963,0.856,0.054,,0.17763,687.549,,17.763,0.687549,,,,7.85398e-5
Test7,3-Compress,129.290,3.931,0.888,0.061,,0.184271,776.676,,18.4271,0.776676,,,,7.85398e-5
Test7,3-Compress,129.623,3.899,0.92,0.054,,0.190911,687.549,,19.0911,0.687549,,,,7.85398e-5
Test7,3-Compress,129.957,3.867,0.952,0.061,,0.197551,776.676,,19.7551,0.776676,,,,7.85398e-5
Test7,3-Compress,130.290,3.834,0.985,0.068,,0.204399,865.803,,20.4399,0.865803,,,,7.85398e-5
Test7,3-Compress,130.623,3.803,1.016,0.068,,0.210832,865.803,,21.0832,0.865803,,,,7.85398e-5
Test7,3-Compress,130.957,3.77,1.049,0.068,,0.21768,865.803,,21.768,0.865803,,,,7.85398e-5
Test7,3-Compress,131.290,3.738,1.081,0.068,,0.22432,865.803,,22.432,0.865803,,,,7.85398e-5
Test7,3-Compress,131.623,3.706,1.113,0.068,,0.230961,865.803,,23.0961,0.865803,,,,7.85398e-5
Test7,3-Compress,131.957,3.673,1.146,0.068,,0.237809,865.803,,23.7809,0.865803,,,,7.85398e-5
Test7,3-Compress,132.290,3.642,1.177,0.068,,0.244242,865.803,,24.4242,0.865803,,,,7.85398e-5
Test7,3-Compress,132.623,3.61,1.209,0.068,,0.250882,865.803,,25.0882,0.865803,,,,7.85398e-5
Test7,3-Compress,132.957,3.577,1.242,0.068,,0.25773,865.803,,25.773,0.865803,,,,7.85398e-5
Test7,3-Compress,133.290,3.545,1.274,0.074,,0.26437,942.197,,26.437,0.942197,,,,7.85398e-5
Test7,3-Compress,133.623,3.513,1.306,0.068,,0.271011,865.803,,27.1011,0.865803,,,,7.85398e-5
Test7,3-Compress,133.957,3.481,1.338,0.068,,0.277651,865.803,,27.7651,0.865803,,,,7.85398e-5
Test7,3-Compress,134.290,3.448,1.371,0.068,,0.284499,865.803,,28.4499,0.865803,,,,7.85398e-5
Test7,3-Compress,134.623,3.416,1.403,0.068,,0.291139,865.803,,29.1139,0.865803,,,,7.85398e-5
Test7,3-Compress,134.957,3.383,1.436,0.068,,0.297987,865.803,,29.7987,0.865803,,,,7.85398e-5
Test7,3-Compress,135.290,3.352,1.467,0.088,,0.30442,1120.45,,30.442,1.12045,,,,7.85398e-5
Test7,3-Compress,135.623,3.32,1.499,0.108,,0.31106,1375.1,,31.106,1.3751,,,,7.85398e-5
Test7,3-Compress,135.957,3.287,1.532,0.122,,0.317908,1553.35,,31.7908,1.55335,,,,7.85398e-5
Test7,3-Compress,136.290,3.255,1.564,0.108,,0.324549,1375.1,,32.4549,1.3751,,,,7.85398e-5
Test7,3-Compress,136.623,3.224,1.595,0.122,,0.330982,1553.35,,33.0982,1.55335,,,,7.85398e-5
Test7,3-Compress,136.957,3.191,1.628,0.122,,0.337829,1553.35,,33.7829,1.55335,,,,7.85398e-5
Test7,3-Compress,137.290,3.159,1.66,0.122,,0.34447,1553.35,,34.447,1.55335,,,,7.85398e-5
Test7,3-Compress,137.623,3.127,1.692,0.122,,0.35111,1553.35,,35.111,1.55335,,,,7.85398e-5
Test7,3-Compress,137.957,3.094,1.725,0.122,,0.357958,1553.35,,35.7958,1.55335,,,,7.85398e-5
Test7,3-Compress,138.290,3.062,1.757,0.122,,0.364598,1553.35,,36.4598,1.55335,,,,7.85398e-5
Test7,3-Compress,138.623,3.03,1.789,0.122,,0.371239,1553.35,,37.1239,1.55335,,,,7.85398e-5
Test7,3-Compress,138.957,2.997,1.822,0.122,,0.378087,1553.35,,37.8087,1.55335,,,,7.85398e-5
Test7,3-Compress,139.290,2.966,1.853,0.129,,0.38452,1642.48,,38.452,1.64248,,,,7.85398e-5
Test7,3-Compress,139.623,2.934,1.885,0.135,,0.39116,1718.87,,39.116,1.71887,,,,7.85398e-5
Test7,3-Compress,139.957,2.901,1.918,0.142,,0.398008,1808,,39.8008,1.808,,,,7.85398e-5
Test7,3-Compress,140.290,2.869,1.95,0.149,,0.404648,1897.13,,40.4648,1.89713,,,,7.85398e-5
Test7,3-Compress,140.623,2.838,1.981,0.163,,0.411081,2075.38,,41.1081,2.07538,,,,7.85398e-5
Test7,3-Compress,140.957,2.805,2.014,0.169,,0.417929,2151.78,,41.7929,2.15178,,,,7.85398e-5
Test7,3-Compress,141.290,2.773,2.046,0.176,,0.424569,2240.9,,42.4569,2.2409,,,,7.85398e-5
Test7,3-Compress,141.623,2.741,2.078,0.176,,0.43121,2240.9,,43.121,2.2409,,,,7.85398e-5
Test7,3-Compress,141.957,2.708,2.111,0.176,,0.438058,2240.9,,43.8058,2.2409,,,,7.85398e-5
Test7,3-Compress,142.290,2.676,2.143,0.176,,0.444698,2240.9,,44.4698,2.2409,,,,7.85398e-5
Test7,3-Compress,142.623,2.644,2.175,0.176,,0.451338,2240.9,,45.1338,2.2409,,,,7.85398e-5
Test7,3-Compress,142.957,2.611,2.208,0.176,,0.458186,2240.9,,45.8186,2.2409,,,,7.85398e-5
Test7,3-Compress,143.290,2.58,2.239,0.183,,0.464619,2330.03,,46.4619,2.33003,,,,7.85398e-5
Test7,3-Compress,143.623,2.548,2.271,0.190,,0.47126,2419.16,,47.126,2.41916,,,,7.85398e-5
Test7,3-Compress,143.957,2.515,2.304,0.190,,0.478107,2419.16,,47.8107,2.41916,,,,7.85398e-5
Test7,3-Compress,144.290,2.483,2.336,0.190,,0.484748,2419.16,,48.4748,2.41916,,,,7.85398e-5
Test7,3-Compress,144.623,2.452,2.367,0.203,,0.491181,2584.68,,49.1181,2.58468,,,,7.85398e-5
Test7,3-Compress,144.957,2.419,2.4,0.210,,0.498029,2673.8,,49.8029,2.6738,,,,7.85398e-5
Test7,3-Compress,145.290,2.387,2.432,0.203,,0.504669,2584.68,,50.4669,2.58468,,,,7.85398e-5
Test7,3-Compress,145.623,2.355,2.464,0.203,,0.511309,2584.68,,51.1309,2.58468,,,,7.85398e-5
Test7,3-Compress,145.957,2.322,2.497,0.217,,0.518157,2762.93,,51.8157,2.76293,,,,7.85398e-5
Test7,3-Compress,146.290,2.29,2.529,0.224,,0.524798,2852.06,,52.4798,2.85206,,,,7.85398e-5
Test7,3-Compress,146.623,2.258,2.561,0.244,,0.531438,3106.71,,53.1438,3.10671,,,,7.85398e-5
Test7,3-Compress,146.957,2.225,2.594,0.258,,0.538286,3284.96,,53.8286,3.28496,,,,7.85398e-5
Test7,3-Compress,147.290,2.194,2.625,0.244,,0.544719,3106.71,,54.4719,3.10671,,,,7.85398e-5
Test7,3-Compress,147.623,2.162,2.657,0.231,,0.551359,2941.18,,55.1359,2.94118,,,,7.85398e-5
Test7,3-Compress,147.957,2.129,2.69,0.231,,0.558207,2941.18,,55.8207,2.94118,,,,7.85398e-5
Test7,3-Compress,148.290,2.097,2.722,0.237,,0.564847,3017.58,,56.4847,3.01758,,,,7.85398e-5
Test7,3-Compress,148.623,2.065,2.754,0.244,,0.571488,3106.71,,57.1488,3.10671,,,,7.85398e-5
Test7,3-Compress,148.957,2.032,2.787,0.278,,0.578336,3539.61,,57.8336,3.53961,,,,7.85398e-5
Test7,3-Compress,149.290,2.001,2.818,0.285,,0.584769,3628.73,,58.4769,3.62873,,,,7.85398e-5
Test7,3-Compress,149.623,1.968,2.851,0.292,,0.591617,3717.86,,59.1617,3.71786,,,,7.85398e-5
Test7,3-Compress,149.957,1.936,2.883,0.292,,0.598257,3717.86,,59.8257,3.71786,,,,7.85398e-5
Test7,3-Recover,150.277,1.944,2.875,0.292,,0.596597,3717.86,,59.6597,3.71786,,,,7.85398e-5
Test7,3-Recover,150.610,1.976,2.843,0.292,,0.589956,3717.86,,58.9956,3.71786,,,,7.85398e-5
Test7,3-Recover,150.943,2.008,2.811,0.285,,0.583316,3628.73,,58.3316,3.62873,,,,7.85398e-5
Test7,3-Recover,151.277,2.041,2.778,0.258,,0.576468,3284.96,,57.6468,3.28496,,,,7.85398e-5
Test7,3-Recover,151.610,2.073,2.746,0.244,,0.569828,3106.71,,56.9828,3.10671,,,,7.85398e-5
Test7,3-Recover,151.943,2.104,2.715,0.244,,0.563395,3106.71,,56.3395,3.10671,,,,7.85398e-5
Test7,3-Recover,152.277,2.137,2.682,0.244,,0.556547,3106.71,,55.6547,3.10671,,,,7.85398e-5
Test7,3-Recover,152.610,2.169,2.65,0.237,,0.549907,3017.58,,54.9907,3.01758,,,,7.85398e-5
Test7,3-Recover,152.943,2.201,2.618,0.244,,0.543266,3106.71,,54.3266,3.10671,,,,7.85398e-5
Test7,3-Recover,153.277,2.234,2.585,0.237,,0.536418,3017.58,,53.6418,3.01758,,,,7.85398e-5
Test7,3-Recover,153.610,2.265,2.554,0.217,,0.529985,2762.93,,52.9985,2.76293,,,,7.85398e-5
Test7,3-Recover,153.943,2.297,2.522,0.203,,0.523345,2584.68,,52.3345,2.58468,,,,7.85398e-5
Test7,3-Recover,154.277,2.33,2.489,0.210,,0.516497,2673.8,,51.6497,2.6738,,,,7.85398e-5
Test7,3-Recover,154.610,2.362,2.457,0.210,,0.509857,2673.8,,50.9857,2.6738,,,,7.85398e-5
Test7,3-Recover,154.943,2.394,2.425,0.210,,0.503216,2673.8,,50.3216,2.6738,,,,7.85398e-5
Test7,3-Recover,155.277,2.427,2.392,0.190,,0.496369,2419.16,,49.6369,2.41916,,,,7.85398e-5
Test7,3-Recover,155.610,2.459,2.36,0.183,,0.489728,2330.03,,48.9728,2.33003,,,,7.85398e-5
Test7,3-Recover,155.943,2.491,2.328,0.183,,0.483088,2330.03,,48.3088,2.33003,,,,7.85398e-5
Test7,3-Recover,156.277,2.524,2.295,0.176,,0.47624,2240.9,,47.624,2.2409,,,,7.85398e-5
Test7,3-Recover,156.610,2.555,2.264,0.176,,0.469807,2240.9,,46.9807,2.2409,,,,7.85398e-5
Test7,3-Recover,156.943,2.587,2.232,0.176,,0.463167,2240.9,,46.3167,2.2409,,,,7.85398e-5
Test7,3-Recover,157.277,2.62,2.199,0.176,,0.456319,2240.9,,45.6319,2.2409,,,,7.85398e-5
Test7,3-Recover,157.610,2.652,2.167,0.176,,0.449678,2240.9,,44.9678,2.2409,,,,7.85398e-5
Test7,3-Recover,157.943,2.684,2.135,0.176,,0.443038,2240.9,,44.3038,2.2409,,,,7.85398e-5
Test7,3-Recover,158.277,2.716,2.103,0.163,,0.436398,2075.38,,43.6398,2.07538,,,,7.85398e-5
Test7,3-Recover,158.610,2.748,2.071,0.135,,0.429757,1718.87,,42.9757,1.71887,,,,7.85398e-5
Test7,3-Recover,158.943,2.78,2.039,0.142,,0.423117,1808,,42.3117,1.808,,,,7.85398e-5
Test7,3-Recover,159.277,2.813,2.006,0.129,,0.416269,1642.48,,41.6269,1.64248,,,,7.85398e-5
Test7,3-Recover,159.610,2.845,1.974,0.129,,0.409629,1642.48,,40.9629,1.64248,,,,7.85398e-5
Test7,3-Recover,159.943,2.877,1.942,0.135,,0.402988,1718.87,,40.2988,1.71887,,,,7.85398e-5
Test7,3-Recover,160.277,2.91,1.909,0.129,,0.39614,1642.48,,39.614,1.64248,,,,7.85398e-5
Test7,3-Recover,160.610,2.941,1.878,0.122,,0.389707,1553.35,,38.9707,1.55335,,,,7.85398e-5
Test7,3-Recover,160.943,2.973,1.846,0.122,,0.383067,1553.35,,38.3067,1.55335,,,,7.85398e-5
Test7,3-Recover,161.277,3.006,1.813,0.122,,0.376219,1553.35,,37.6219,1.55335,,,,7.85398e-5
Test7,3-Recover,161.610,3.038,1.781,0.122,,0.369579,1553.35,,36.9579,1.55335,,,,7.85398e-5
Test7,3-Recover,161.943,3.07,1.749,0.122,,0.362938,1553.35,,36.2938,1.55335,,,,7.85398e-5
Test7,3-Recover,162.277,3.102,1.717,0.122,,0.356298,1553.35,,35.6298,1.55335,,,,7.85398e-5
Test7,3-Recover,162.610,3.134,1.685,0.101,,0.349658,1285.97,,34.9658,1.28597,,,,7.85398e-5
Test7,3-Recover,162.943,3.166,1.653,0.115,,0.343017,1464.23,,34.3017,1.46423,,,,7.85398e-5
Test7,3-Recover,163.277,3.199,1.62,0.101,,0.336169,1285.97,,33.6169,1.28597,,,,7.85398e-5
Test7,3-Recover,163.610,3.231,1.588,0.088,,0.329529,1120.45,,32.9529,1.12045,,,,7.85398e-5
Test7,3-Recover,163.943,3.263,1.556,0.081,,0.322889,1031.32,,32.2889,1.03132,,,,7.85398e-5
Test7,3-Recover,164.277,3.296,1.523,0.074,,0.316041,942.197,,31.6041,0.942197,,,,7.85398e-5
Test7,3-Recover,164.610,3.327,1.492,0.074,,0.309608,942.197,,30.9608,0.942197,,,,7.85398e-5
Test7,3-Recover,164.943,3.359,1.46,0.068,,0.302967,865.803,,30.2967,0.865803,,,,7.85398e-5
Test7,3-Recover,165.277,3.392,1.427,0.074,,0.29612,942.197,,29.612,0.942197,,,,7.85398e-5
Test7,3-Recover,165.610,3.424,1.395,0.068,,0.289479,865.803,,28.9479,0.865803,,,,7.85398e-5
Test7,3-Recover,165.943,3.456,1.363,0.068,,0.282839,865.803,,28.2839,0.865803,,,,7.85398e-5
Test7,3-Recover,166.277,3.488,1.331,0.068,,0.276198,865.803,,27.6198,0.865803,,,,7.85398e-5
Test7,3-Recover,166.610,3.52,1.299,0.068,,0.269558,865.803,,26.9558,0.865803,,,,7.85398e-5
Test7,3-Recover,166.943,3.552,1.267,0.068,,0.262918,865.803,,26.2918,0.865803,,,,7.85398e-5
Test7,3-Recover,167.277,3.585,1.234,0.068,,0.25607,865.803,,25.607,0.865803,,,,7.85398e-5
Test7,3-Recover,167.610,3.617,1.202,0.068,,0.249429,865.803,,24.9429,0.865803,,,,7.85398e-5
Test7,3-Recover,167.943,3.649,1.17,0.068,,0.242789,865.803,,24.2789,0.865803,,,,7.85398e-5
Test7,3-Recover,168.277,3.682,1.137,0.068,,0.235941,865.803,,23.5941,0.865803,,,,7.85398e-5
Test7,3-Recover,168.610,3.713,1.106,0.054,,0.229508,687.549,,22.9508,0.687549,,,,7.85398e-5
Test7,3-Recover,168.943,3.745,1.074,0.061,,0.222868,776.676,,22.2868,0.776676,,,,7.85398e-5
Test7,3-Recover,169.277,3.778,1.041,0.054,,0.21602,687.549,,21.602,0.687549,,,,7.85398e-5
Test7,3-Recover,169.610,3.81,1.009,0.054,,0.20938,687.549,,20.938,0.687549,,,,7.85398e-5
Test7,3-Recover,169.943,3.842,0.977,0.054,,0.202739,687.549,,20.2739,0.687549,,,,7.85398e-5
Test7,3-Recover,170.277,3.875,0.944,0.040,,0.195891,509.296,,19.5891,0.509296,,,,7.85398e-5
Test7,3-Recover,170.610,3.907,0.912,0.027,,0.189251,343.775,,18.9251,0.343775,,,,7.85398e-5
Test7,3-Recover,170.943,3.939,0.88,0.034,,0.182611,432.902,,18.2611,0.432902,,,,7.85398e-5
Test7,3-Recover,171.277,3.971,0.848,0.027,,0.17597,343.775,,17.597,0.343775,,,,7.85398e-5
Test7,3-Recover,171.610,4.003,0.816,0.020,,0.16933,254.648,,16.933,0.254648,,,,7.85398e-5
Test7,3-Recover,171.943,4.035,0.784,0.020,,0.162689,254.648,,16.2689,0.254648,,,,7.85398e-5
Test7,3-Recover,172.277,4.068,0.751,0.013,,0.155841,165.521,,15.5841,0.165521,,,,7.85398e-5
Test7,3-Recover,172.610,4.1,0.719,0.013,,0.149201,165.521,,14.9201,0.165521,,,,7.85398e-5
Test7,3-Recover,172.943,4.131,0.688,0.013,,0.142768,165.521,,14.2768,0.165521,,,,7.85398e-5
Test7,3-Recover,173.277,4.164,0.655,0.013,,0.13592,165.521,,13.592,0.165521,,,,7.85398e-5
Test7,3-Recover,173.610,4.196,0.623,0.020,,0.12928,254.648,,12.928,0.254648,,,,7.85398e-5
Test7,3-Recover,173.943,4.228,0.591,0.020,,0.12264,254.648,,12.264,0.254648,,,,7.85398e-5
Test7,3-Recover,174.277,4.261,0.558,0.020,,0.115792,254.648,,11.5792,0.254648,,,,7.85398e-5
Test7,3-Recover,174.610,4.293,0.526,0.020,,0.109151,254.648,,10.9151,0.254648,,,,7.85398e-5
Test7,3-Recover,174.943,4.325,0.494,0.020,,0.102511,254.648,,10.2511,0.254648,,,,7.85398e-5
Test7,3-Recover,175.277,4.357,0.462,0.020,,0.0958705,254.648,,9.58705,0.254648,,,,7.85398e-5
Test7,3-Recover,175.610,4.389,0.43,0.027,,0.0892301,343.775,,8.92301,0.343775,,,,7.85398e-5
Test7,3-Recover,175.943,4.421,0.398,0.020,,0.0825897,254.648,,8.25897,0.254648,,,,7.85398e-5
Test7,3-Recover,176.277,4.454,0.365,0.020,,0.0757419,254.648,,7.57419,0.254648,,,,7.85398e-5
Test7,3-Recover,176.610,4.486,0.333,0.013,,0.0691015,165.521,,6.91015,0.165521,,,,7.85398e-5
Test7,3-Recover,176.943,4.517,0.302,0.013,,0.0626686,165.521,,6.26686,0.165521,,,,7.85398e-5
Test7,3-Recover,177.277,4.55,0.269,0.013,,0.0558207,165.521,,5.58207,0.165521,,,,7.85398e-5
Test7,3-Recover,177.610,4.582,0.237,0.013,,0.0491803,165.521,,4.91803,0.165521,,,,7.85398e-5
Test7,3-Recover,177.943,4.614,0.205,0.013,,0.0425399,165.521,,4.25399,0.165521,,,,7.85398e-5
Test7,3-Recover,178.277,4.647,0.172,0.013,,0.0356921,165.521,,3.56921,0.165521,,,,7.85398e-5
Test7,3-Recover,178.610,4.679,0.14,0.013,,0.0290517,165.521,,2.90517,0.165521,,,,7.85398e-5
Test7,3-Recover,178.943,4.711,0.108,0.013,,0.0224113,165.521,,2.24113,0.165521,,,,7.85398e-5
Test7,3-Recover,179.277,4.743,0.076,0.006,,0.0157709,76.3944,,1.57709,0.0763944,,,,7.85398e-5
Test7,3-Recover,179.610,4.775,0.044,0.013,,0.00913053,165.521,,0.913053,0.165521,,,,7.85398e-5
Test7,3-Recover,179.943,4.807,0.012,-0.000,,0.00249014,0,,0.249014,0,,,,7.85398e-5
Test7,3-Recover,180.110,4.819,-0,-0.000,,0,0,,0,0,,,,7.85398e-5