File: data/beta_1-0.5_1.csv
SetName,Cycle,Time_S,Size_mm,Displacement_mm,Force_N,,Strain,Stress(Pascal),,%Strain,Stress(kPa),,,,Area(m^2)
1:0.5 (rep 1),1-Compress,0,3.215,0,0.05,,0,636.62,,0,0.63662,,,,7.85398e-5
1:0.5 (rep 1),1-Compress,0.367,3.192,0.023,0.05,,0.00715397,636.62,,0.715397,0.63662,,,,7.85398e-5
1:0.5 (rep 1),1-Compress,0.733,3.169,0.046,0.05,,0.0143079,636.62,,1.43079,0.63662,,,,7.85398e-5
1:0.5 (rep 1),1-Compress,1.1,3.145,0.07,0.05,,0.0217729,636.62,,2.17729,0.63662,,,,7.85398e-5
1:0.5 (rep 1),1-Compress,1.467,3.121,0.094,0.057,,0.0292379,725.747,,2.92379,0.725747,,,,7.85398e-5
1:0.5 (rep 1),1-Compress,1.833,3.098,0.117,0.064,,0.0363919,814.873,,3.63919,0.814873,,,,7.85398e-5
1:0.5 (rep 1),1-Compress,2.2,3.074,0.141,0.07,,0.0438569,891.268,,4.38569,0.891268,,,,7.85398e-5
1:0.5 (rep 1),1-Compress,2.567,3.05,0.165,0.064,,0.0513219,814.873,,5.13219,0.814873,,,,7.85398e-5
1:0.5 (rep 1),1-Compress,2.933,3.027,0.188,0.064,,0.0584759,814.873,,5.84759,0.814873,,,,7.85398e-5
1:0.5 (rep 1),1-Compress,3.3,3.003,0.212,0.057,,0.0659409,725.747,,6.59409,0.725747,,,,7.85398e-5
1:0.5 (rep 1),1-Compress,3.667,2.979,0.236,0.084,,0.0734059,1069.52,,7.34059,1.06952,,,,7.85398e-5
1:0.5 (rep 1),1-Compress,4.033,2.956,0.259,0.057,,0.0805599,725.747,,8.05599,0.725747,,,,7.85398e-5
1:0.5 (rep 1),1-Compress,4.4,2.932,0.283,0.091,,0.0880249,1158.65,,8.80249,1.15865,,,,7.85398e-5
1:0.5 (rep 1),1-Compress,4.767,2.909,0.306,0.098,,0.0951788,1247.78,,9.51788,1.24778,,,,7.85398e-5
1:0.5 (rep 1),1-Compress,5.133,2.885,0.33,0.098,,0.102644,1247.78,,10.2644,1.24778,,,,7.85398e-5
1:0.5 (rep 1),1-Compress,5.5,2.861,0.354,0.104,,0.110109,1324.17,,11.0109,1.32417,,,,7.85398e-5
1:0.5 (rep 1),1-Compress,5.867,2.837,0.378,0.104,,0.117574,1324.17,,11.7574,1.32417,,,,7.85398e-5
1:0.5 (rep 1),1-Compress,6.233,2.814,0.401,0.104,,0.124728,1324.17,,12.4728,1.32417,,,,7.85398e-5
1:0.5 (rep 1),1-Compress,6.6,2.79,0.425,0.104,,0.132193,1324.17,,13.2193,1.32417,,,,7.85398e-5
1:0.5 (rep 1),1-Compress,6.967,2.767,0.448,0.104,,0.139347,1324.17,,13.9347,1.32417,,,,7.85398e-5
1:0.5 (rep 1),1-Compress,7.333,2.744,0.471,0.104,,0.146501,1324.17,,14.6501,1.32417,,,,7.85398e-5
1:0.5 (rep 1),1-Compress,7.7,2.72,0.495,0.104,,0.153966,1324.17,,15.3966,1.32417,,,,7.85398e-5
1:0.5 (rep 1),1-Compress,8.067,2.696,0.519,0.104,,0.161431,1324.17,,16.1431,1.32417,,,,7.85398e-5
1:0.5 (rep 1),1-Compress,8.433,2.673,0.542,0.104,,0.168585,1324.17,,16.8585,1.32417,,,,7.85398e-5
1:0.5 (rep 1),1-Compress,8.8,2.649,0.566,0.104,,0.17605,1324.17,,17.605,1.32417,,,,7.85398e-5
1:0.5 (rep 1),1-Compress,9.167,2.625,0.59,0.118,,0.183515,1502.42,,18.3515,1.50242,,,,7.85398e-5
1:0.5 (rep 1),1-Compress,9.533,2.602,0.613,0.125,,0.190669,1591.55,,19.0669,1.59155,,,,7.85398e-5
1:0.5 (rep 1),1-Compress,9.9,2.578,0.637,0.125,,0.198134,1591.55,,19.8134,1.59155,,,,7.85398e-5
1:0.5 (rep 1),1-Compress,10.267,2.554,0.661,0.131,,0.205599,1667.94,,20.5599,1.66794,,,,7.85398e-5
1:0.5 (rep 1),1-Compress,10.633,2.531,0.684,0.125,,0.212753,1591.55,,21.2753,1.59155,,,,7.85398e-5
1:0.5 (rep 1),1-Compress,11,2.507,0.708,0.145,,0.220218,1846.2,,22.0218,1.8462,,,,7.85398e-5
1:0.5 (rep 1),1-Compress,11.367,2.484,0.731,0.138,,0.227372,1757.07,,22.7372,1.75707,,,,7.85398e-5
1:0.5 (rep 1),1-Compress,11.733,2.46,0.755,0.145,,0.234837,1846.2,,23.4837,1.8462,,,,7.85398e-5
1:0.5 (rep 1),1-Compress,12.1,2.436,0.779,0.159,,0.242302,2024.45,,24.2302,2.02445,,,,7.85398e-5
1:0.5 (rep 1),1-Compress,12.467,2.413,0.802,0.159,,0.249456,2024.45,,24.9456,2.02445,,,,7.85398e-5
1:0.5 (rep 1),1-Compress,12.833,2.389,0.826,0.159,,0.256921,2024.45,,25.6921,2.02445,,,,7.85398e-5
1:0.5 (rep 1),1-Compress,13.2,2.365,0.85,0.159,,0.264386,2024.45,,26.4386,2.02445,,,,7.85398e-5
1:0.5 (rep 1),1-Compress,13.567,2.342,0.873,0.159,,0.27154,2024.45,,27.154,2.02445,,,,7.85398e-5
1:0.5 (rep 1),1-Compress,13.933,2.319,0.896,0.159,,0.278694,2024.45,,27.8694,2.02445,,,,7.85398e-5
1:0.5 (rep 1),1-Compress,14.3,2.295,0.92,0.165,,0.286159,2100.85,,28.6159,2.10085,,,,7.85398e-5
1:0.5 (rep 1),1-Compress,14.667,2.271,0.944,0.152,,0.293624,1935.32,,29.3624,1.93532,,,,7.85398e-5
1:0.5 (rep 1),1-Compress,15.033,2.248,0.967,0.159,,0.300778,2024.45,,30.0778,2.02445,,,,7.85398e-5
1:0.5 (rep 1),1-Compress,15.4,2.224,0.991,0.165,,0.308243,2100.85,,30.8243,2.10085,,,,7.85398e-5
1:0.5 (rep 1),1-Compress,15.767,2.2,1.015,0.193,,0.315708,2457.35,,31.5708,2.45735,,,,7.85398e-5
1:0.5 (rep 1),1-Compress,16.133,2.177,1.038,0.199,,0.322862,2533.75,,32.2862,2.53375,,,,7.85398e-5
1:0.5 (rep 1),1-Compress,16.5,2.153,1.062,0.206,,0.330327,2622.87,,33.0327,2.62287,,,,7.85398e-5
1:0.5 (rep 1),1-Compress,16.867,2.129,1.086,0.193,,0.337792,2457.35,,33.7792,2.45735,,,,7.85398e-5
1:0.5 (rep 1),1-Compress,17.233,2.106,1.109,0.193,,0.344946,2457.35,,34.4946,2.45735,,,,7.85398e-5
1:0.5 (rep 1),1-Compress,17.6,2.082,1.133,0.193,,0.352411,2457.35,,35.2411,2.45735,,,,7.85398e-5
1:0.5 (rep 1),1-Compress,17.967,2.059,1.156,0.206,,0.359565,2622.87,,35.9565,2.62287,,,,7.85398e-5
1:0.5 (rep 1),1-Compress,18.333,2.035,1.18,0.213,,0.36703,2712,,36.703,2.712,,,,7.85398e-5
1:0.5 (rep 1),1-Compress,18.7,2.012,1.203,0.213,,0.374184,2712,,37.4184,2.712,,,,7.85398e-5
1:0.5 (rep 1),1-Compress,19.067,1.988,1.227,0.22,,0.381649,2801.13,,38.1649,2.80113,,,,7.85398e-5
1:0.5 (rep 1),1-Compress,19.433,1.964,1.251,0.227,,0.389114,2890.25,,38.9114,2.89025,,,,7.85398e-5
1:0.5 (rep 1),1-Compress,19.8,1.94,1.275,0.213,,0.396579,2712,,39.6579,2.712,,,,7.85398e-5
1:0.5 (rep 1),1-Compress,20.167,1.917,1.298,0.233,,0.403733,2966.65,,40.3733,2.96665,,,,7.85398e-5
1:0.5 (rep 1),1-Compress,20.533,1.894,1.321,0.227,,0.410886,2890.25,,41.0886,2.89025,,,,7.85398e-5
1:0.5 (rep 1),1-Compress,20.9,1.87,1.345,0.213,,0.418351,2712,,41.8351,2.712,,,,7.85398e-5
1:0.5 (rep 1),1-Compress,21.267,1.846,1.369,0.22,,0.425816,2801.13,,42.5816,2.80113,,,,7.85398e-5
1:0.5 (rep 1),1-Compress,21.633,1.823,1.392,0.227,,0.43297,2890.25,,43.297,2.89025,,,,7.85398e-5
1:0.5 (rep 1),1-Compress,22,1.799,1.416,0.24,,0.440435,3055.78,,44.0435,3.05578,,,,7.85398e-5
1:0.5 (rep 1),1-Compress,22.367,1.775,1.44,0.247,,0.4479,3144.9,,44.79,3.1449,,,,7.85398e-5
1:0.5 (rep 1),1-Compress,22.733,1.752,1.463,0.261,,0.455054,3323.16,,45.5054,3.32316,,,,7.85398e-5
1:0.5 (rep 1),1-Compress,23.1,1.728,1.487,0.267,,0.462519,3399.55,,46.2519,3.39955,,,,7.85398e-5
1:0.5 (rep 1),1-Compress,23.467,1.704,1.511,0.267,,0.469984,3399.55,,46.9984,3.39955,,,,7.85398e-5
1:0.5 (rep 1),1-Compress,23.833,1.681,1.534,0.274,,0.477138,3488.68,,47.7138,3.48868,,,,7.85398e-5
1:0.5 (rep 1),1-Compress,24.2,1.657,1.558,0.281,,0.484603,3577.8,,48.4603,3.5778,,,,7.85398e-5
1:0.5 (rep 1),1-Compress,24.567,1.634,1.581,0.281,,0.491757,3577.8,,49.1757,3.5778,,,,7.85398e-5
1:0.5 (rep 1),1-Compress,24.933,1.61,1.605,0.294,,0.499222,3743.33,,49.9222,3.74333,,,,7.85398e-5
1:0.5 (rep 1),1-Compress,25.3,1.587,1.628,0.308,,0.506376,3921.58,,50.6376,3.92158,,,,7.85398e-5
1:0.5 (rep 1),1-Compress,25.667,1.563,1.652,0.322,,0.513841,4099.83,,51.3841,4.09983,,,,7.85398e-5
1:0.5 (rep 1),1-Compress,26.033,1.539,1.676,0.322,,0.521306,4099.83,,52.1306,4.09983,,,,7.85398e-5
1:0.5 (rep 1),1-Compress,26.4,1.515,1.7,0.322,,0.528771,4099.83,,52.8771,4.09983,,,,7.85398e-5
1:0.5 (rep 1),1-Compress,26.767,1.492,1.723,0.335,,0.535925,4265.35,,53.5925,4.26535,,,,7.85398e-5
1:0.5 (rep 1),1-Compress,27.133,1.469,1.746,0.362,,0.543079,4609.13,,54.3079,4.60913,,,,7.85398e-5
1:0.5 (rep 1),1-Compress,27.5,1.445,1.77,0.376,,0.550544,4787.38,,55.0544,4.78738,,,,7.85398e-5
1:0.5 (rep 1),1-Compress,27.867,1.421,1.794,0.376,,0.558009,4787.38,,55.8009,4.78738,,,,7.85398e-5
1:0.5 (rep 1),1-Compress,28.233,1.398,1.817,0.376,,0.565163,4787.38,,56.5163,4.78738,,,,7.85398e-5
1:0.5 (rep 1),1-Compress,28.6,1.374,1.841,0.383,,0.572628,4876.51,,57.2628,4.87651,,,,7.85398e-5
1:0.5 (rep 1),1-Compress,28.967,1.35,1.865,0.383,,0.580093,4876.51,,58.0093,4.87651,,,,7.85398e-5
1:0.5 (rep 1),1-Compress,29.333,1.327,1.888,0.417,,0.587247,5309.41,,58.7247,5.30941,,,,7.85398e-5
1:0.5 (rep 1),1-Compress,29.7,1.303,1.912,0.41,,0.594712,5220.28,,59.4712,5.22028,,,,7.85398e-5
1:0.5 (rep 1),1-Recover,30.067,1.289,1.926,0.41,,0.599067,5220.28,,59.9067,5.22028,,,,7.85398e-5
1:0.5 (rep 1),1-Recover,30.433,1.312,1.903,0.342,,0.591913,4354.48,,59.1913,4.35448,,,,7.85398e-5
1:0.5 (rep 1),1-Recover,30.8,1.336,1.879,0.322,,0.584448,4099.83,,58.4448,4.09983,,,,7.85398e-5
1:0.5 (rep 1),1-Recover,31.167,1.36,1.855,0.322,,0.576983,4099.83,,57.6983,4.09983,,,,7.85398e-5
1:0.5 (rep 1),1-Recover,31.533,1.383,1.832,0.294,,0.569829,3743.33,,56.9829,3.74333,,,,7.85398e-5
1:0.5 (rep 1),1-Recover,31.9,1.407,1.808,0.274,,0.562364,3488.68,,56.2364,3.48868,,,,7.85398e-5
1:0.5 (rep 1),1-Recover,32.267,1.431,1.784,0.274,,0.554899,3488.68,,55.4899,3.48868,,,,7.85398e-5
1:0.5 (rep 1),1-Recover,32.633,1.454,1.761,0.267,,0.547745,3399.55,,54.7745,3.39955,,,,7.85398e-5
1:0.5 (rep 1),1-Recover,33,1.478,1.737,0.267,,0.54028,3399.55,,54.028,3.39955,,,,7.85398e-5
1:0.5 (rep 1),1-Recover,33.367,1.502,1.713,0.24,,0.532815,3055.78,,53.2815,3.05578,,,,7.85398e-5
1:0.5 (rep 1),1-Recover,33.733,1.525,1.69,0.22,,0.525661,2801.13,,52.5661,2.80113,,,,7.85398e-5
1:0.5 (rep 1),1-Recover,34.1,1.549,1.666,0.22,,0.518196,2801.13,,51.8196,2.80113,,,,7.85398e-5
1:0.5 (rep 1),1-Recover,34.467,1.572,1.643,0.22,,0.511042,2801.13,,51.1042,2.80113,,,,7.85398e-5
1:0.5 (rep 1),1-Recover,34.833,1.596,1.619,0.213,,0.503577,2712,,50.3577,2.712,,,,7.85398e-5
1:0.5 (rep 1),1-Recover,35.2,1.619,1.596,0.227,,0.496423,2890.25,,49.6423,2.89025,,,,7.85398e-5
1:0.5 (rep 1),1-Recover,35.567,1.643,1.572,0.22,,0.488958,2801.13,,48.8958,2.80113,,,,7.85398e-5
1:0.5 (rep 1),1-Recover,35.933,1.667,1.548,0.22,,0.481493,2801.13,,48.1493,2.80113,,,,7.85398e-5
1:0.5 (rep 1),1-Recover,36.3,1.69,1.525,0.213,,0.474339,2712,,47.4339,2.712,,,,7.85398e-5
1:0.5 (rep 1),1-Recover,36.667,1.714,1.501,0.213,,0.466874,2712,,46.6874,2.712,,,,7.85398e-5
1:0.5 (rep 1),1-Recover,37.033,1.737,1.478,0.186,,0.45972,2368.23,,45.972,2.36823,,,,7.85398e-5
1:0.5 (rep 1),1-Recover,37.4,1.761,1.454,0.186,,0.452255,2368.23,,45.2255,2.36823,,,,7.85398e-5
1:0.5 (rep 1),1-Recover,37.767,1.785,1.43,0.193,,0.44479,2457.35,,44.479,2.45735,,,,7.85398e-5
1:0.5 (rep 1),1-Recover,38.133,1.808,1.407,0.186,,0.437636,2368.23,,43.7636,2.36823,,,,7.85398e-5
1:0.5 (rep 1),1-Recover,38.5,1.832,1.383,0.165,,0.430171,2100.85,,43.0171,2.10085,,,,7.85398e-5
1:0.5 (rep 1),1-Recover,38.867,1.856,1.359,0.165,,0.422706,2100.85,,42.2706,2.10085,,,,7.85398e-5
1:0.5 (rep 1),1-Recover,39.233,1.879,1.336,0.159,,0.415552,2024.45,,41.5552,2.02445,,,,7.85398e-5
1:0.5 (rep 1),1-Recover,39.6,1.903,1.312,0.152,,0.408087,1935.32,,40.8087,1.93532,,,,7.85398e-5
1:0.5 (rep 1),1-Recover,39.967,1.927,1.288,0.152,,0.400622,1935.32,,40.0622,1.93532,,,,7.85398e-5
1:0.5 (rep 1),1-Recover,40.333,1.95,1.265,0.159,,0.393468,2024.45,,39.3468,2.02445,,,,7.85398e-5
1:0.5 (rep 1),1-Recover,40.7,1.974,1.241,0.159,,0.386003,2024.45,,38.6003,2.02445,,,,7.85398e-5
1:0.5 (rep 1),1-Recover,41.067,1.997,1.218,0.159,,0.378849,2024.45,,37.8849,2.02445,,,,7.85398e-5
1:0.5 (rep 1),1-Recover,41.433,2.021,1.194,0.159,,0.371384,2024.45,,37.1384,2.02445,,,,7.85398e-5
1:0.5 (rep 1),1-Recover,41.8,2.044,1.171,0.152,,0.36423,1935.32,,36.423,1.93532,,,,7.85398e-5
1:0.5 (rep 1),1-Recover,42.167,2.068,1.147,0.152,,0.356765,1935.32,,35.6765,1.93532,,,,7.85398e-5
1:0.5 (rep 1),1-Recover,42.533,2.092,1.123,0.159,,0.3493,2024.45,,34.93,2.02445,,,,7.85398e-5
1:0.5 (rep 1),1-Recover,42.9,2.115,1.1,0.125,,0.342146,1591.55,,34.2146,1.59155,,,,7.85398e-5
1:0.5 (rep 1),1-Recover,43.267,2.139,1.076,0.125,,0.334681,1591.55,,33.4681,1.59155,,,,7.85398e-5
1:0.5 (rep 1),1-Recover,43.633,2.162,1.053,0.111,,0.327527,1413.3,,32.7527,1.4133,,,,7.85398e-5
1:0.5 (rep 1),1-Recover,44,2.186,1.029,0.104,,0.320062,1324.17,,32.0062,1.32417,,,,7.85398e-5
1:0.5 (rep 1),1-Recover,44.367,2.21,1.005,0.104,,0.312597,1324.17,,31.2597,1.32417,,,,7.85398e-5
1:0.5 (rep 1),1-Recover,44.733,2.233,0.982,0.104,,0.305443,1324.17,,30.5443,1.32417,,,,7.85398e-5
1:0.5 (rep 1),1-Recover,45.1,2.257,0.958,0.104,,0.297978,1324.17,,29.7978,1.32417,,,,7.85398e-5
1:0.5 (rep 1),1-Recover,45.467,2.281,0.934,0.104,,0.290513,1324.17,,29.0513,1.32417,,,,7.85398e-5
1:0.5 (rep 1),1-Recover,45.833,2.304,0.911,0.104,,0.283359,1324.17,,28.3359,1.32417,,,,7.85398e-5
1:0.5 (rep 1),1-Recover,46.2,2.328,0.887,0.104,,0.275894,1324.17,,27.5894,1.32417,,,,7.85398e-5
1:0.5 (rep 1),1-Recover,46.567,2.352,0.863,0.104,,0.268429,1324.17,,26.8429,1.32417,,,,7.85398e-5
1:0.5 (rep 1),1-Recover,46.933,2.375,0.84,0.104,,0.261275,1324.17,,26.1275,1.32417,,,,7.85398e-5
1:0.5 (rep 1),1-Recover,47.3,2.399,0.816,0.104,,0.25381,1324.17,,25.381,1.32417,,,,7.85398e-5
1:0.5 (rep 1),1-Recover,47.667,2.423,0.792,0.104,,0.246345,1324.17,,24.6345,1.32417,,,,7.85398e-5
1:0.5 (rep 1),1-Recover,48.033,2.446,0.769,0.091,,0.239191,1158.65,,23.9191,1.15865,,,,7.85398e-5
1:0.5 (rep 1),1-Recover,48.4,2.469,0.746,0.091,,0.232037,1158.65,,23.2037,1.15865,,,,7.85398e-5
1:0.5 (rep 1),1-Recover,48.767,2.493,0.722,0.084,,0.224572,1069.52,,22.4572,1.06952,,,,7.85398e-5
1:0.5 (rep 1),1-Recover,49.133,2.516,0.699,0.057,,0.217418,725.747,,21.7418,0.725747,,,,7.85398e-5
1:0.5 (rep 1),1-Recover,49.5,2.54,0.675,0.07,,0.209953,891.268,,20.9953,0.891268,,,,7.85398e-5
1:0.5 (rep 1),1-Recover,49.867,2.564,0.651,0.084,,0.202488,1069.52,,20.2488,1.06952,,,,7.85398e-5
1:0.5 (rep 1),1-Recover,50.233,2.588,0.627,0.07,,0.195023,891.268,,19.5023,0.891268,,,,7.85398e-5
1:0.5 (rep 1),1-Recover,50.6,2.611,0.604,0.057,,0.187869,725.747,,18.7869,0.725747,,,,7.85398e-5
1:0.5 (rep 1),1-Recover,50.967,2.635,0.58,0.057,,0.180404,725.747,,18.0404,0.725747,,,,7.85398e-5
1:0.5 (rep 1),1-Recover,51.333,2.658,0.557,0.05,,0.17325,636.62,,17.325,0.63662,,,,7.85398e-5
1:0.5 (rep 1),1-Recover,51.7,2.682,0.533,0.05,,0.165785,636.62,,16.5785,0.63662,,,,7.85398e-5
1:0.5 (rep 1),1-Recover,52.067,2.706,0.509,0.064,,0.15832,814.873,,15.832,0.814873,,,,7.85398e-5
1:0.5 (rep 1),1-Recover,52.433,2.729,0.486,0.05,,0.151166,636.62,,15.1166,0.63662,,,,7.85398e-5
1:0.5 (rep 1),1-Recover,52.8,2.753,0.462,0.05,,0.143701,636.62,,14.3701,0.63662,,,,7.85398e-5
1:0.5 (rep 1),1-Recover,53.167,2.777,0.438,0.05,,0.136236,636.62,,13.6236,0.63662,,,,7.85398e-5
1:0.5 (rep 1),1-Recover,53.533,2.8,0.415,0.05,,0.129082,636.62,,12.9082,0.63662,,,,7.85398e-5
1:0.5 (rep 1),1-Recover,53.9,2.824,0.391,0.057,,0.121617,725.747,,12.1617,0.725747,,,,7.85398e-5
1:0.5 (rep 1),1-Recover,54.267,2.848,0.367,0.05,,0.114152,636.62,,11.4152,0.63662,,,,7.85398e-5
1:0.5 (rep 1),1-Recover,54.633,2.871,0.344,0.05,,0.106998,636.62,,10.6998,0.63662,,,,7.85398e-5
1:0.5 (rep 1),1-Recover,55,2.894,0.321,0.05,,0.0998445,636.62,,9.98445,0.63662,,,,7.85398e-5
1:0.5 (rep 1),1-Recover,55.367,2.918,0.297,0.05,,0.0923795,636.62,,9.23795,0.63662,,,,7.85398e-5
1:0.5 (rep 1),1-Recover,55.733,2.941,0.274,0.05,,0.0852255,636.62,,8.52255,0.63662,,,,7.85398e-5
1:0.5 (rep 1),1-Recover,56.1,2.965,0.25,0.05,,0.0777605,636.62,,7.77605,0.63662,,,,7.85398e-5
1:0.5 (rep 1),1-Recover,56.467,2.989,0.226,0.057,,0.0702955,725.747,,7.02955,0.725747,,,,7.85398e-5
1:0.5 (rep 1),1-Recover,56.833,3.012,0.203,0.043,,0.0631415,547.493,,6.31415,0.547493,,,,7.85398e-5
1:0.5 (rep 1),1-Recover,57.2,3.036,0.179,0.05,,0.0556765,636.62,,5.56765,0.63662,,,,7.85398e-5
1:0.5 (rep 1),1-Recover,57.567,3.06,0.155,0.05,,0.0482115,636.62,,4.82115,0.63662,,,,7.85398e-5
1:0.5 (rep 1),1-Recover,57.933,3.083,0.132,0.043,,0.0410575,547.493,,4.10575,0.547493,,,,7.85398e-5
1:0.5 (rep 1),1-Recover,58.3,3.107,0.108,0.043,,0.0335925,547.493,,3.35925,0.547493,,,,7.85398e-5
1:0.5 (rep 1),1-Recover,58.667,3.131,0.084,0.03,,0.0261275,381.972,,2.61275,0.381972,,,,7.85398e-5
1:0.5 (rep 1),1-Recover,59.033,3.154,0.061,0.05,,0.0189736,636.62,,1.89736,0.63662,,,,7.85398e-5
1:0.5 (rep 1),1-Recover,59.4,3.178,0.037,0.03,,0.0115086,381.972,,1.15086,0.381972,,,,7.85398e-5
1:0.5 (rep 1),1-Recover,59.767,3.202,0.013,0.036,,0.00404355,458.366,,0.404355,0.458366,,,,7.85398e-5
1:0.5 (rep 1),2-Compress,60.117,3.21,0.005,0.036,,0.00155521,458.366,,0.155521,0.458366,,,,7.85398e-5
1:0.5 (rep 1),2-Compress,60.483,3.187,0.028,0.05,,0.00870918,636.62,,0.870918,0.63662,,,,7.85398e-5
1:0.5 (rep 1),2-Compress,60.85,3.163,0.052,0.05,,0.0161742,636.62,,1.61742,0.63662,,,,7.85398e-5
1:0.5 (rep 1),2-Compress,61.217,3.139,0.076,0.05,,0.0236392,636.62,,2.36392,0.63662,,,,7.85398e-5
1:0.5 (rep 1),2-Compress,61.583,3.116,0.099,0.043,,0.0307932,547.493,,3.07932,0.547493,,,,7.85398e-5
1:0.5 (rep 1),2-Compress,61.95,3.092,0.123,0.05,,0.0382582,636.62,,3.82582,0.63662,,,,7.85398e-5
1:0.5 (rep 1),2-Compress,62.317,3.068,0.147,0.05,,0.0457232,636.62,,4.57232,0.63662,,,,7.85398e-5
1:0.5 (rep 1),2-Compress,62.683,3.045,0.17,0.05,,0.0528771,636.62,,5.28771,0.63662,,,,7.85398e-5
1:0.5 (rep 1),2-Compress,63.05,3.021,0.194,0.05,,0.0603421,636.62,,6.03421,0.63662,,,,7.85398e-5
1:0.5 (rep 1),2-Compress,63.417,2.997,0.218,0.05,,0.0678072,636.62,,6.78072,0.63662,,,,7.85398e-5
1:0.5 (rep 1),2-Compress,63.783,2.974,0.241,0.05,,0.0749611,636.62,,7.49611,0.63662,,,,7.85398e-5
1:0.5 (rep 1),2-Compress,64.15,2.951,0.264,0.05,,0.0821151,636.62,,8.21151,0.63662,,,,7.85398e-5
1:0.5 (rep 1),2-Compress,64.517,2.927,0.288,0.05,,0.0895801,636.62,,8.95801,0.63662,,,,7.85398e-5
1:0.5 (rep 1),2-Compress,64.883,2.904,0.311,0.05,,0.0967341,636.62,,9.67341,0.63662,,,,7.85398e-5
1:0.5 (rep 1),2-Compress,65.25,2.88,0.335,0.05,,0.104199,636.62,,10.4199,0.63662,,,,7.85398e-5
1:0.5 (rep 1),2-Compress,65.617,2.856,0.359,0.05,,0.111664,636.62,,11.1664,0.63662,,,,7.85398e-5
1:0.5 (rep 1),2-Compress,65.983,2.833,0.382,0.05,,0.118818,636.62,,11.8818,0.63662,,,,7.85398e-5
1:0.5 (rep 1),2-Compress,66.35,2.809,0.406,0.057,,0.126283,725.747,,12.6283,0.725747,,,,7.85398e-5
1:0.5 (rep 1),2-Compress,66.717,2.785,0.43,0.05,,0.133748,636.62,,13.3748,0.63662,,,,7.85398e-5
1:0.5 (rep 1),2-Compress,67.083,2.762,0.453,0.057,,0.140902,725.747,,14.0902,0.725747,,,,7.85398e-5
1:0.5 (rep 1),2-Compress,67.45,2.738,0.477,0.05,,0.148367,636.62,,14.8367,0.63662,,,,7.85398e-5
1:0.5 (rep 1),2-Compress,67.817,2.714,0.501,0.077,,0.155832,980.395,,15.5832,0.980395,,,,7.85398e-5
1:0.5 (rep 1),2-Compress,68.183,2.691,0.524,0.07,,0.162986,891.268,,16.2986,0.891268,,,,7.85398e-5
1:0.5 (rep 1),2-Compress,68.55,2.667,0.548,0.064,,0.170451,814.873,,17.0451,0.814873,,,,7.85398e-5
1:0.5 (rep 1),2-Compress,68.917,2.643,0.572,0.077,,0.177916,980.395,,17.7916,0.980395,,,,7.85398e-5
1:0.5 (rep 1),2-Compress,69.283,2.62,0.595,0.091,,0.18507,1158.65,,18.507,1.15865,,,,7.85398e-5
1:0.5 (rep 1),2-Compress,69.65,2.596,0.619,0.077,,0.192535,980.395,,19.2535,0.980395,,,,7.85398e-5
1:0.5 (rep 1),2-Compress,70.017,2.572,0.643,0.098,,0.2,1247.78,,20,1.24778,,,,7.85398e-5
1:0.5 (rep 1),2-Compress,70.383,2.549,0.666,0.104,,0.207154,1324.17,,20.7154,1.32417,,,,7.85398e-5
1:0.5 (rep 1),2-Compress,70.75,2.525,0.69,0.104,,0.214619,1324.17,,21.4619,1.32417,,,,7.85398e-5
1:0.5 (rep 1),2-Compress,71.117,2.502,0.713,0.104,,0.221773,1324.17,,22.1773,1.32417,,,,7.85398e-5
1:0.5 (rep 1),2-Compress,71.483,2.479,0.736,0.104,,0.228927,1324.17,,22.8927,1.32417,,,,7.85398e-5
1:0.5 (rep 1),2-Compress,71.85,2.455,0.76,0.104,,0.236392,1324.17,,23.6392,1.32417,,,,7.85398e-5
1:0.5 (rep 1),2-Compress,72.217,2.431,0.784,0.104,,0.243857,1324.17,,24.3857,1.32417,,,,7.85398e-5
1:0.5 (rep 1),2-Compress,72.583,2.408,0.807,0.104,,0.251011,1324.17,,25.1011,1.32417,,,,7.85398e-5
1:0.5 (rep 1),2-Compress,72.95,2.384,0.831,0.104,,0.258476,1324.17,,25.8476,1.32417,,,,7.85398e-5
1:0.5 (rep 1),2-Compress,73.317,2.36,0.855,0.104,,0.265941,1324.17,,26.5941,1.32417,,,,7.85398e-5
1:0.5 (rep 1),2-Compress,73.683,2.337,0.878,0.111,,0.273095,1413.3,,27.3095,1.4133,,,,7.85398e-5
1:0.5 (rep 1),2-Compress,74.05,2.313,0.902,0.111,,0.28056,1413.3,,28.056,1.4133,,,,7.85398e-5
1:0.5 (rep 1),2-Compress,74.417,2.289,0.926,0.118,,0.288025,1502.42,,28.8025,1.50242,,,,7.85398e-5
1:0.5 (rep 1),2-Compress,74.783,2.266,0.949,0.118,,0.295179,1502.42,,29.5179,1.50242,,,,7.85398e-5
1:0.5 (rep 1),2-Compress,75.15,2.242,0.973,0.138,,0.302644,1757.07,,30.2644,1.75707,,,,7.85398e-5
1:0.5 (rep 1),2-Compress,75.517,2.219,0.996,0.131,,0.309798,1667.94,,30.9798,1.66794,,,,7.85398e-5
1:0.5 (rep 1),2-Compress,75.883,2.195,1.02,0.152,,0.317263,1935.32,,31.7263,1.93532,,,,7.85398e-5
1:0.5 (rep 1),2-Compress,76.25,2.171,1.044,0.159,,0.324728,2024.45,,32.4728,2.02445,,,,7.85398e-5
1:0.5 (rep 1),2-Compress,76.617,2.147,1.068,0.152,,0.332193,1935.32,,33.2193,1.93532,,,,7.85398e-5
1:0.5 (rep 1),2-Compress,76.983,2.124,1.091,0.152,,0.339347,1935.32,,33.9347,1.93532,,,,7.85398e-5
1:0.5 (rep 1),2-Compress,77.35,2.1,1.115,0.159,,0.346812,2024.45,,34.6812,2.02445,,,,7.85398e-5
1:0.5 (rep 1),2-Compress,77.717,2.077,1.138,0.159,,0.353966,2024.45,,35.3966,2.02445,,,,7.85398e-5
1:0.5 (rep 1),2-Compress,78.083,2.054,1.161,0.159,,0.36112,2024.45,,36.112,2.02445,,,,7.85398e-5
1:0.5 (rep 1),2-Compress,78.45,2.03,1.185,0.159,,0.368585,2024.45,,36.8585,2.02445,,,,7.85398e-5
1:0.5 (rep 1),2-Compress,78.817,2.006,1.209,0.159,,0.37605,2024.45,,37.605,2.02445,,,,7.85398e-5
1:0.5 (rep 1),2-Compress,79.183,1.983,1.232,0.159,,0.383204,2024.45,,38.3204,2.02445,,,,7.85398e-5
1:0.5 (rep 1),2-Compress,79.55,1.959,1.256,0.159,,0.390669,2024.45,,39.0669,2.02445,,,,7.85398e-5
1:0.5 (rep 1),2-Compress,79.917,1.935,1.28,0.165,,0.398134,2100.85,,39.8134,2.10085,,,,7.85398e-5
1:0.5 (rep 1),2-Compress,80.283,1.912,1.303,0.165,,0.405288,2100.85,,40.5288,2.10085,,,,7.85398e-5
1:0.5 (rep 1),2-Compress,80.65,1.888,1.327,0.179,,0.412753,2279.1,,41.2753,2.2791,,,,7.85398e-5
1:0.5 (rep 1),2-Compress,81.017,1.864,1.351,0.186,,0.420218,2368.23,,42.0218,2.36823,,,,7.85398e-5
1:0.5 (rep 1),2-Compress,81.383,1.841,1.374,0.213,,0.427372,2712,,42.7372,2.712,,,,7.85398e-5
1:0.5 (rep 1),2-Compress,81.75,1.817,1.398,0.213,,0.434837,2712,,43.4837,2.712,,,,7.85398e-5
1:0.5 (rep 1),2-Compress,82.117,1.794,1.421,0.213,,0.441991,2712,,44.1991,2.712,,,,7.85398e-5
1:0.5 (rep 1),2-Compress,82.483,1.77,1.445,0.206,,0.449456,2622.87,,44.9456,2.62287,,,,7.85398e-5
1:0.5 (rep 1),2-Compress,82.85,1.746,1.469,0.199,,0.456921,2533.75,,45.6921,2.53375,,,,7.85398e-5
1:0.5 (rep 1),2-Compress,83.217,1.723,1.492,0.206,,0.464075,2622.87,,46.4075,2.62287,,,,7.85398e-5
1:0.5 (rep 1),2-Compress,83.583,1.699,1.516,0.227,,0.47154,2890.25,,47.154,2.89025,,,,7.85398e-5
1:0.5 (rep 1),2-Compress,83.95,1.675,1.54,0.233,,0.479005,2966.65,,47.9005,2.96665,,,,7.85398e-5
1:0.5 (rep 1),2-Compress,84.317,1.652,1.563,0.233,,0.486159,2966.65,,48.6159,2.96665,,,,7.85398e-5
1:0.5 (rep 1),2-Compress,84.683,1.629,1.586,0.213,,0.493313,2712,,49.3313,2.712,,,,7.85398e-5
1:0.5 (rep 1),2-Compress,85.05,1.605,1.61,0.213,,0.500778,2712,,50.0778,2.712,,,,7.85398e-5
1:0.5 (rep 1),2-Compress,85.417,1.581,1.634,0.213,,0.508243,2712,,50.8243,2.712,,,,7.85398e-5
1:0.5 (rep 1),2-Compress,85.783,1.558,1.657,0.213,,0.515397,2712,,51.5397,2.712,,,,7.85398e-5
1:0.5 (rep 1),2-Compress,86.15,1.534,1.681,0.22,,0.522862,2801.13,,52.2862,2.80113,,,,7.85398e-5
1:0.5 (rep 1),2-Compress,86.517,1.51,1.705,0.22,,0.530327,2801.13,,53.0327,2.80113,,,,7.85398e-5
1:0.5 (rep 1),2-Compress,86.883,1.487,1.728,0.233,,0.537481,2966.65,,53.7481,2.96665,,,,7.85398e-5
1:0.5 (rep 1),2-Compress,87.25,1.463,1.752,0.254,,0.544946,3234.03,,54.4946,3.23403,,,,7.85398e-5
1:0.5 (rep 1),2-Compress,87.617,1.439,1.776,0.267,,0.552411,3399.55,,55.2411,3.39955,,,,7.85398e-5
1:0.5 (rep 1),2-Compress,87.983,1.416,1.799,0.267,,0.559565,3399.55,,55.9565,3.39955,,,,7.85398e-5
1:0.5 (rep 1),2-Compress,88.35,1.392,1.823,0.267,,0.56703,3399.55,,56.703,3.39955,,,,7.85398e-5
1:0.5 (rep 1),2-Compress,88.717,1.369,1.846,0.267,,0.574184,3399.55,,57.4184,3.39955,,,,7.85398e-5
1:0.5 (rep 1),2-Compress,89.083,1.345,1.87,0.274,,0.581649,3488.68,,58.1649,3.48868,,,,7.85398e-5
1:0.5 (rep 1),2-Compress,89.45,1.321,1.894,0.274,,0.589114,3488.68,,58.9114,3.48868,,,,7.85398e-5
1:0.5 (rep 1),2-Compress,89.817,1.298,1.917,0.274,,0.596267,3488.68,,59.6267,3.48868,,,,7.85398e-5
1:0.5 (rep 1),2-Recover,90.17,1.293,1.922,0.274,,0.597823,3488.68,,59.7823,3.48868,,,,7.85398e-5
1:0.5 (rep 1),2-Recover,90.537,1.317,1.898,0.254,,0.590358,3234.03,,59.0358,3.23403,,,,7.85398e-5
1:0.5 (rep 1),2-Recover,90.903,1.34,1.875,0.227,,0.583204,2890.25,,58.3204,2.89025,,,,7.85398e-5
1:0.5 (rep 1),2-Recover,91.27,1.364,1.851,0.22,,0.575739,2801.13,,57.5739,2.80113,,,,7.85398e-5
1:0.5 (rep 1),2-Recover,91.637,1.388,1.827,0.233,,0.568274,2966.65,,56.8274,2.96665,,,,7.85398e-5
1:0.5 (rep 1),2-Recover,92.003,1.411,1.804,0.24,,0.56112,3055.78,,56.112,3.05578,,,,7.85398e-5
1:0.5 (rep 1),2-Recover,92.37,1.435,1.78,0.227,,0.553655,2890.25,,55.3655,2.89025,,,,7.85398e-5
1:0.5 (rep 1),2-Recover,92.737,1.459,1.756,0.206,,0.54619,2622.87,,54.619,2.62287,,,,7.85398e-5
1:0.5 (rep 1),2-Recover,93.103,1.482,1.733,0.199,,0.539036,2533.75,,53.9036,2.53375,,,,7.85398e-5
1:0.5 (rep 1),2-Recover,93.47,1.506,1.709,0.199,,0.531571,2533.75,,53.1571,2.53375,,,,7.85398e-5
1:0.5 (rep 1),2-Recover,93.837,1.53,1.685,0.206,,0.524106,2622.87,,52.4106,2.62287,,,,7.85398e-5
1:0.5 (rep 1),2-Recover,94.203,1.553,1.662,0.213,,0.516952,2712,,51.6952,2.712,,,,7.85398e-5
1:0.5 (rep 1),2-Recover,94.57,1.576,1.639,0.199,,0.509798,2533.75,,50.9798,2.53375,,,,7.85398e-5
1:0.5 (rep 1),2-Recover,94.937,1.6,1.615,0.172,,0.502333,2189.97,,50.2333,2.18997,,,,7.85398e-5
1:0.5 (rep 1),2-Recover,95.303,1.623,1.592,0.165,,0.495179,2100.85,,49.5179,2.10085,,,,7.85398e-5
1:0.5 (rep 1),2-Recover,95.67,1.647,1.568,0.159,,0.487714,2024.45,,48.7714,2.02445,,,,7.85398e-5
1:0.5 (rep 1),2-Recover,96.037,1.671,1.544,0.152,,0.480249,1935.32,,48.0249,1.93532,,,,7.85398e-5
1:0.5 (rep 1),2-Recover,96.403,1.695,1.52,0.159,,0.472784,2024.45,,47.2784,2.02445,,,,7.85398e-5
1:0.5 (rep 1),2-Recover,96.77,1.718,1.497,0.159,,0.46563,2024.45,,46.563,2.02445,,,,7.85398e-5
1:0.5 (rep 1),2-Recover,97.137,1.742,1.473,0.159,,0.458165,2024.45,,45.8165,2.02445,,,,7.85398e-5
1:0.5 (rep 1),2-Recover,97.503,1.765,1.45,0.152,,0.451011,1935.32,,45.1011,1.93532,,,,7.85398e-5
1:0.5 (rep 1),2-Recover,97.87,1.789,1.426,0.159,,0.443546,2024.45,,44.3546,2.02445,,,,7.85398e-5
1:0.5 (rep 1),2-Recover,98.237,1.813,1.402,0.159,,0.436081,2024.45,,43.6081,2.02445,,,,7.85398e-5
1:0.5 (rep 1),2-Recover,98.603,1.836,1.379,0.145,,0.428927,1846.2,,42.8927,1.8462,,,,7.85398e-5
1:0.5 (rep 1),2-Recover,98.97,1.86,1.355,0.118,,0.421462,1502.42,,42.1462,1.50242,,,,7.85398e-5
1:0.5 (rep 1),2-Recover,99.337,1.884,1.331,0.118,,0.413997,1502.42,,41.3997,1.50242,,,,7.85398e-5
1:0.5 (rep 1),2-Recover,99.703,1.907,1.308,0.104,,0.406843,1324.17,,40.6843,1.32417,,,,7.85398e-5
1:0.5 (rep 1),2-Recover,100.07,1.931,1.284,0.125,,0.399378,1591.55,,39.9378,1.59155,,,,7.85398e-5
1:0.5 (rep 1),2-Recover,100.437,1.955,1.26,0.118,,0.391913,1502.42,,39.1913,1.50242,,,,7.85398e-5
1:0.5 (rep 1),2-Recover,100.803,1.978,1.237,0.111,,0.384759,1413.3,,38.4759,1.4133,,,,7.85398e-5
1:0.5 (rep 1),2-Recover,101.17,2.001,1.214,0.104,,0.377605,1324.17,,37.7605,1.32417,,,,7.85398e-5
1:0.5 (rep 1),2-Recover,101.537,2.025,1.19,0.104,,0.37014,1324.17,,37.014,1.32417,,,,7.85398e-5
1:0.5 (rep 1),2-Recover,101.903,2.048,1.167,0.104,,0.362986,1324.17,,36.2986,1.32417,,,,7.85398e-5
1:0.5 (rep 1),2-Recover,102.27,2.072,1.143,0.098,,0.355521,1247.78,,35.5521,1.24778,,,,7.85398e-5
1:0.5 (rep 1),2-Recover,102.637,2.096,1.119,0.104,,0.348056,1324.17,,34.8056,1.32417,,,,7.85398e-5
1:0.5 (rep 1),2-Recover,103.003,2.119,1.096,0.104,,0.340902,1324.17,,34.0902,1.32417,,,,7.85398e-5
1:0.5 (rep 1),2-Recover,103.37,2.143,1.072,0.104,,0.333437,1324.17,,33.3437,1.32417,,,,7.85398e-5
1:0.5 (rep 1),2-Recover,103.737,2.167,1.048,0.104,,0.325972,1324.17,,32.5972,1.32417,,,,7.85398e-5
1:0.5 (rep 1),2-Recover,104.103,2.19,1.025,0.098,,0.318818,1247.78,,31.8818,1.24778,,,,7.85398e-5
1:0.5 (rep 1),2-Recover,104.47,2.214,1.001,0.07,,0.311353,891.268,,31.1353,0.891268,,,,7.85398e-5
1:0.5 (rep 1),2-Recover,104.837,2.238,0.977,0.084,,0.303888,1069.52,,30.3888,1.06952,,,,7.85398e-5
1:0.5 (rep 1),2-Recover,105.203,2.261,0.954,0.077,,0.296734,980.395,,29.6734,0.980395,,,,7.85398e-5
1:0.5 (rep 1),2-Recover,105.57,2.285,0.93,0.077,,0.289269,980.395,,28.9269,0.980395,,,,7.85398e-5
1:0.5 (rep 1),2-Recover,105.937,2.309,0.906,0.07,,0.281804,891.268,,28.1804,0.891268,,,,7.85398e-5
1:0.5 (rep 1),2-Recover,106.303,2.332,0.883,0.064,,0.27465,814.873,,27.465,0.814873,,,,7.85398e-5
1:0.5 (rep 1),2-Recover,106.67,2.356,0.859,0.057,,0.267185,725.747,,26.7185,0.725747,,,,7.85398e-5
1:0.5 (rep 1),2-Recover,107.037,2.38,0.835,0.05,,0.25972,636.62,,25.972,0.63662,,,,7.85398e-5
1:0.5 (rep 1),2-Recover,107.403,2.403,0.812,0.057,,0.252566,725.747,,25.2566,0.725747,,,,7.85398e-5
1:0.5 (rep 1),2-Recover,107.77,2.426,0.789,0.064,,0.245412,814.873,,24.5412,0.814873,,,,7.85398e-5
1:0.5 (rep 1),2-Recover,108.137,2.45,0.765,0.05,,0.237947,636.62,,23.7947,0.63662,,,,7.85398e-5
1:0.5 (rep 1),2-Recover,108.503,2.473,0.742,0.057,,0.230793,725.747,,23.0793,0.725747,,,,7.85398e-5
1:0.5 (rep 1),2-Recover,108.87,2.497,0.718,0.05,,0.223328,636.62,,22.3328,0.63662,,,,7.85398e-5
1:0.5 (rep 1),2-Recover,109.237,2.521,0.694,0.05,,0.215863,636.62,,21.5863,0.63662,,,,7.85398e-5
1:0.5 (rep 1),2-Recover,109.603,2.544,0.671,0.05,,0.208709,636.62,,20.8709,0.63662,,,,7.85398e-5
1:0.5 (rep 1),2-Recover,109.97,2.568,0.647,0.05,,0.201244,636.62,,20.1244,0.63662,,,,7.85398e-5
1:0.5 (rep 1),2-Recover,110.337,2.592,0.623,0.05,,0.193779,636.62,,19.3779,0.63662,,,,7.85398e-5
1:0.5 (rep 1),2-Recover,110.703,2.615,0.6,0.05,,0.186625,636.62,,18.6625,0.63662,,,,7.85398e-5
1:0.5 (rep 1),2-Recover,111.07,2.639,0.576,0.05,,0.17916,636.62,,17.916,0.63662,,,,7.85398e-5
1:0.5 (rep 1),2-Recover,111.437,2.663,0.552,0.05,,0.171695,636.62,,17.1695,0.63662,,,,7.85398e-5
1:0.5 (rep 1),2-Recover,111.803,2.686,0.529,0.05,,0.164541,636.62,,16.4541,0.63662,,,,7.85398e-5
1:0.5 (rep 1),2-Recover,112.17,2.71,0.505,0.05,,0.157076,636.62,,15.7076,0.63662,,,,7.85398e-5
1:0.5 (rep 1),2-Recover,112.537,2.733,0.482,0.05,,0.149922,636.62,,14.9922,0.63662,,,,7.85398e-5
1:0.5 (rep 1),2-Recover,112.903,2.757,0.458,0.05,,0.142457,636.62,,14.2457,0.63662,,,,7.85398e-5
1:0.5 (rep 1),2-Recover,113.27,2.781,0.434,0.05,,0.134992,636.62,,13.4992,0.63662,,,,7.85398e-5
1:0.5 (rep 1),2-Recover,113.637,2.805,0.41,0.05,,0.127527,636.62,,12.7527,0.63662,,,,7.85398e-5
1:0.5 (rep 1),2-Recover,114.003,2.828,0.387,0.05,,0.120373,636.62,,12.0373,0.63662,,,,7.85398e-5
1:0.5 (rep 1),2-Recover,114.37,2.852,0.363,0.03,,0.112908,381.972,,11.2908,0.381972,,,,7.85398e-5
1:0.5 (rep 1),2-Recover,114.737,2.875,0.34,0.043,,0.105754,547.493,,10.5754,0.547493,,,,7.85398e-5
1:0.5 (rep 1),2-Recover,115.103,2.898,0.317,0.05,,0.0986003,636.62,,9.86003,0.63662,,,,7.85398e-5
1:0.5 (rep 1),2-Recover,115.47,2.922,0.293,0.043,,0.0911353,547.493,,9.11353,0.547493,,,,7.85398e-5
1:0.5 (rep 1),2-Recover,115.837,2.946,0.269,0.043,,0.0836703,547.493,,8.36703,0.547493,,,,7.85398e-5
1:0.5 (rep 1),2-Recover,116.203,2.969,0.246,0.023,,0.0765163,292.845,,7.65163,0.292845,,,,7.85398e-5
1:0.5 (rep 1),2-Recover,116.57,2.993,0.222,0.009,,0.0690513,114.592,,6.90513,0.114592,,,,7.85398e-5
1:0.5 (rep 1),2-Recover,116.937,3.017,0.198,0.03,,0.0615863,381.972,,6.15863,0.381972,,,,7.85398e-5
1:0.5 (rep 1),2-Recover,117.303,3.04,0.175,0.009,,0.0544323,114.592,,5.44323,0.114592,,,,7.85398e-5
1:0.5 (rep 1),2-Recover,117.67,3.064,0.151,0.03,,0.0469673,381.972,,4.69673,0.381972,,,,7.85398e-5
1:0.5 (rep 1),2-Recover,118.037,3.088,0.127,0.03,,0.0395023,381.972,,3.95023,0.381972,,,,7.85398e-5
1:0.5 (rep 1),2-Recover,118.403,3.111,0.104,0.023,,0.0323484,292.845,,3.23484,0.292845,,,,7.85398e-5
1:0.5 (rep 1),2-Recover,118.77,3.135,0.08,0.009,,0.0248834,114.592,,2.48834,0.114592,,,,7.85398e-5
1:0.5 (rep 1),2-Recover,119.137,3.158,0.057,0.002,,0.0177294,25.4648,,1.77294,0.0254648,,,,7.85398e-5
1:0.5 (rep 1),2-Recover,119.503,3.182,0.033,0.002,,0.0102644,25.4648,,1.02644,0.0254648,,,,7.85398e-5
1:0.5 (rep 1),2-Recover,119.87,3.206,0.009,0.009,,0.00279938,114.592,,0.279938,0.114592,,,,7.85398e-5
1:0.5 (rep 1),3-Compress,120.223,3.206,0.009,0.009,,0.00279938,114.592,,0.279938,0.114592,,,,7.85398e-5
1:0.5 (rep 1),3-Compress,120.59,3.182,0.033,0.03,,0.0102644,381.972,,1.02644,0.381972,,,,7.85398e-5
1:0.5 (rep 1),3-Compress,120.957,3.158,0.057,0.03,,0.0177294,381.972,,1.77294,0.381972,,,,7.85398e-5
1:0.5 (rep 1),3-Compress,121.323,3.135,0.08,0.03,,0.0248834,381.972,,2.48834,0.381972,,,,7.85398e-5
1:0.5 (rep 1),3-Compress,121.69,3.112,0.103,0.043,,0.0320373,547.493,,3.20373,0.547493,,,,7.85398e-5
1:0.5 (rep 1),3-Compress,122.057,3.088,0.127,0.002,,0.0395023,25.4648,,3.95023,0.0254648,,,,7.85398e-5
1:0.5 (rep 1),3-Compress,122.423,3.065,0.15,0.036,,0.0466563,458.366,,4.66563,0.458366,,,,7.85398e-5
1:0.5 (rep 1),3-Compress,122.79,3.041,0.174,0.03,,0.0541213,381.972,,5.41213,0.381972,,,,7.85398e-5
1:0.5 (rep 1),3-Compress,123.157,3.017,0.198,0.036,,0.0615863,458.366,,6.15863,0.458366,,,,7.85398e-5
1:0.5 (rep 1),3-Compress,123.523,2.994,0.221,0.036,,0.0687403,458.366,,6.87403,0.458366,,,,7.85398e-5
1:0.5 (rep 1),3-Compress,123.89,2.97,0.245,0.05,,0.0762053,636.62,,7.62053,0.63662,,,,7.85398e-5
1:0.5 (rep 1),3-Compress,124.257,2.946,0.269,0.043,,0.0836703,547.493,,8.36703,0.547493,,,,7.85398e-5
1:0.5 (rep 1),3-Compress,124.623,2.923,0.292,0.05,,0.0908243,636.62,,9.08243,0.63662,,,,7.85398e-5
1:0.5 (rep 1),3-Compress,124.99,2.899,0.316,0.05,,0.0982893,636.62,,9.82893,0.63662,,,,7.85398e-5
1:0.5 (rep 1),3-Compress,125.357,2.875,0.34,0.05,,0.105754,636.62,,10.5754,0.63662,,,,7.85398e-5
1:0.5 (rep 1),3-Compress,125.723,2.852,0.363,0.05,,0.112908,636.62,,11.2908,0.63662,,,,7.85398e-5
1:0.5 (rep 1),3-Compress,126.09,2.828,0.387,0.05,,0.120373,636.62,,12.0373,0.63662,,,,7.85398e-5
1:0.5 (rep 1),3-Compress,126.457,2.804,0.411,0.05,,0.127838,636.62,,12.7838,0.63662,,,,7.85398e-5
1:0.5 (rep 1),3-Compress,126.823,2.781,0.434,0.05,,0.134992,636.62,,13.4992,0.63662,,,,7.85398e-5
1:0.5 (rep 1),3-Compress,127.19,2.757,0.458,0.05,,0.142457,636.62,,14.2457,0.63662,,,,7.85398e-5
1:0.5 (rep 1),3-Compress,127.557,2.733,0.482,0.057,,0.149922,725.747,,14.9922,0.725747,,,,7.85398e-5
1:0.5 (rep 1),3-Compress,127.923,2.71,0.505,0.05,,0.157076,636.62,,15.7076,0.63662,,,,7.85398e-5
1:0.5 (rep 1),3-Compress,128.29,2.687,0.528,0.05,,0.16423,636.62,,16.423,0.63662,,,,7.85398e-5
1:0.5 (rep 1),3-Compress,128.657,2.663,0.552,0.05,,0.171695,636.62,,17.1695,0.63662,,,,7.85398e-5
1:0.5 (rep 1),3-Compress,129.023,2.64,0.575,0.05,,0.178849,636.62,,17.8849,0.63662,,,,7.85398e-5
1:0.5 (rep 1),3-Compress,129.39,2.616,0.599,0.05,,0.186314,636.62,,18.6314,0.63662,,,,7.85398e-5
1:0.5 (rep 1),3-Compress,129.757,2.592,0.623,0.05,,0.193779,636.62,,19.3779,0.63662,,,,7.85398e-5
1:0.5 (rep 1),3-Compress,130.123,2.569,0.646,0.057,,0.200933,725.747,,20.0933,0.725747,,,,7.85398e-5
1:0.5 (rep 1),3-Compress,130.49,2.545,0.67,0.077,,0.208398,980.395,,20.8398,0.980395,,,,7.85398e-5
1:0.5 (rep 1),3-Compress,130.857,2.521,0.694,0.064,,0.215863,814.873,,21.5863,0.814873,,,,7.85398e-5
1:0.5 (rep 1),3-Compress,131.223,2.498,0.717,0.064,,0.223017,814.873,,22.3017,0.814873,,,,7.85398e-5
1:0.5 (rep 1),3-Compress,131.59,2.474,0.741,0.057,,0.230482,725.747,,23.0482,0.725747,,,,7.85398e-5
1:0.5 (rep 1),3-Compress,131.957,2.45,0.765,0.064,,0.237947,814.873,,23.7947,0.814873,,,,7.85398e-5
1:0.5 (rep 1),3-Compress,132.323,2.427,0.788,0.064,,0.245101,814.873,,24.5101,0.814873,,,,7.85398e-5
1:0.5 (rep 1),3-Compress,132.69,2.403,0.812,0.064,,0.252566,814.873,,25.2566,0.814873,,,,7.85398e-5
1:0.5 (rep 1),3-Compress,133.057,2.379,0.836,0.084,,0.260031,1069.52,,26.0031,1.06952,,,,7.85398e-5
1:0.5 (rep 1),3-Compress,133.423,2.356,0.859,0.098,,0.267185,1247.78,,26.7185,1.24778,,,,7.85398e-5
1:0.5 (rep 1),3-Compress,133.79,2.332,0.883,0.098,,0.27465,1247.78,,27.465,1.24778,,,,7.85398e-5
1:0.5 (rep 1),3-Compress,134.157,2.308,0.907,0.104,,0.282115,1324.17,,28.2115,1.32417,,,,7.85398e-5
1:0.5 (rep 1),3-Compress,134.523,2.285,0.93,0.104,,0.289269,1324.17,,28.9269,1.32417,,,,7.85398e-5
1:0.5 (rep 1),3-Compress,134.89,2.261,0.954,0.098,,0.296734,1247.78,,29.6734,1.24778,,,,7.85398e-5
1:0.5 (rep 1),3-Compress,135.257,2.238,0.977,0.104,,0.303888,1324.17,,30.3888,1.32417,,,,7.85398e-5
1:0.5 (rep 1),3-Compress,135.623,2.215,1,0.104,,0.311042,1324.17,,31.1042,1.32417,,,,7.85398e-5
1:0.5 (rep 1),3-Compress,135.99,2.191,1.024,0.104,,0.318507,1324.17,,31.8507,1.32417,,,,7.85398e-5
1:0.5 (rep 1),3-Compress,136.357,2.167,1.048,0.104,,0.325972,1324.17,,32.5972,1.32417,,,,7.85398e-5
1:0.5 (rep 1),3-Compress,136.723,2.144,1.071,0.104,,0.333126,1324.17,,33.3126,1.32417,,,,7.85398e-5
1:0.5 (rep 1),3-Compress,137.09,2.12,1.095,0.104,,0.340591,1324.17,,34.0591,1.32417,,,,7.85398e-5
1:0.5 (rep 1),3-Compress,137.457,2.096,1.119,0.111,,0.348056,1413.3,,34.8056,1.4133,,,,7.85398e-5
1:0.5 (rep 1),3-Compress,137.823,2.073,1.142,0.118,,0.35521,1502.42,,35.521,1.50242,,,,7.85398e-5
1:0.5 (rep 1),3-Compress,138.19,2.049,1.166,0.118,,0.362675,1502.42,,36.2675,1.50242,,,,7.85398e-5
1:0.5 (rep 1),3-Compress,138.557,2.025,1.19,0.125,,0.37014,1591.55,,37.014,1.59155,,,,7.85398e-5
1:0.5 (rep 1),3-Compress,138.923,2.002,1.213,0.125,,0.377294,1591.55,,37.7294,1.59155,,,,7.85398e-5
1:0.5 (rep 1),3-Compress,139.29,1.978,1.237,0.118,,0.384759,1502.42,,38.4759,1.50242,,,,7.85398e-5
1:0.5 (rep 1),3-Compress,139.657,1.955,1.26,0.111,,0.391913,1413.3,,39.1913,1.4133,,,,7.85398e-5
1:0.5 (rep 1),3-Compress,140.023,1.931,1.284,0.145,,0.399378,1846.2,,39.9378,1.8462,,,,7.85398e-5
1:0.5 (rep 1),3-Compress,140.39,1.907,1.308,0.152,,0.406843,1935.32,,40.6843,1.93532,,,,7.85398e-5
1:0.5 (rep 1),3-Compress,140.757,1.883,1.332,0.159,,0.414308,2024.45,,41.4308,2.02445,,,,7.85398e-5
1:0.5 (rep 1),3-Compress,141.123,1.86,1.355,0.159,,0.421462,2024.45,,42.1462,2.02445,,,,7.85398e-5
1:0.5 (rep 1),3-Compress,141.49,1.836,1.379,0.159,,0.428927,2024.45,,42.8927,2.02445,,,,7.85398e-5
1:0.5 (rep 1),3-Compress,141.857,1.813,1.402,0.159,,0.436081,2024.45,,43.6081,2.02445,,,,7.85398e-5
1:0.5 (rep 1),3-Compress,142.223,1.79,1.425,0.159,,0.443235,2024.45,,44.3235,2.02445,,,,7.85398e-5
1:0.5 (rep 1),3-Compress,142.59,1.766,1.449,0.159,,0.4507,2024.45,,45.07,2.02445,,,,7.85398e-5
1:0.5 (rep 1),3-Compress,142.957,1.742,1.473,0.152,,0.458165,1935.32,,45.8165,1.93532,,,,7.85398e-5
1:0.5 (rep 1),3-Compress,143.323,1.719,1.496,0.152,,0.465319,1935.32,,46.5319,1.93532,,,,7.85398e-5
1:0.5 (rep 1),3-Compress,143.69,1.695,1.52,0.159,,0.472784,2024.45,,47.2784,2.02445,,,,7.85398e-5
1:0.5 (rep 1),3-Compress,144.057,1.671,1.544,0.172,,0.480249,2189.97,,48.0249,2.18997,,,,7.85398e-5
1:0.5 (rep 1),3-Compress,144.423,1.648,1.567,0.172,,0.487403,2189.97,,48.7403,2.18997,,,,7.85398e-5
1:0.5 (rep 1),3-Compress,144.79,1.624,1.591,0.165,,0.494868,2100.85,,49.4868,2.10085,,,,7.85398e-5
1:0.5 (rep 1),3-Compress,145.157,1.6,1.615,0.186,,0.502333,2368.23,,50.2333,2.36823,,,,7.85398e-5
1:0.5 (rep 1),3-Compress,145.523,1.577,1.638,0.193,,0.509487,2457.35,,50.9487,2.45735,,,,7.85398e-5
1:0.5 (rep 1),3-Compress,145.89,1.553,1.662,0.186,,0.516952,2368.23,,51.6952,2.36823,,,,7.85398e-5
1:0.5 (rep 1),3-Compress,146.257,1.53,1.685,0.199,,0.524106,2533.75,,52.4106,2.53375,,,,7.85398e-5
1:0.5 (rep 1),3-Compress,146.623,1.506,1.709,0.206,,0.531571,2622.87,,53.1571,2.62287,,,,7.85398e-5
1:0.5 (rep 1),3-Compress,146.99,1.482,1.733,0.213,,0.539036,2712,,53.9036,2.712,,,,7.85398e-5
1:0.5 (rep 1),3-Compress,147.357,1.459,1.756,0.213,,0.54619,2712,,54.619,2.712,,,,7.85398e-5
1:0.5 (rep 1),3-Compress,147.723,1.435,1.78,0.213,,0.553655,2712,,55.3655,2.712,,,,7.85398e-5
1:0.5 (rep 1),3-Compress,148.09,1.411,1.804,0.206,,0.56112,2622.87,,56.112,2.62287,,,,7.85398e-5
1:0.5 (rep 1),3-Compress,148.457,1.388,1.827,0.206,,0.568274,2622.87,,56.8274,2.62287,,,,7.85398e-5
1:0.5 (rep 1),3-Compress,148.823,1.365,1.85,0.22,,0.575428,2801.13,,57.5428,2.80113,,,,7.85398e-5
1:0.5 (rep 1),3-Compress,149.19,1.341,1.874,0.24,,0.582893,3055.78,,58.2893,3.05578,,,,7.85398e-5
1:0.5 (rep 1),3-Compress,149.557,1.317,1.898,0.213,,0.590358,2712,,59.0358,2.712,,,,7.85398e-5
1:0.5 (rep 1),3-Compress,149.923,1.294,1.921,0.254,,0.597512,3234.03,,59.7512,3.23403,,,,7.85398e-5
1:0.5 (rep 1),3-Recover,150.267,1.297,1.918,0.227,,0.596579,2890.25,,59.6579,2.89025,,,,7.85398e-5
1:0.5 (rep 1),3-Recover,150.633,1.32,1.895,0.22,,0.589425,2801.13,,58.9425,2.80113,,,,7.85398e-5
1:0.5 (rep 1),3-Recover,151,1.344,1.871,0.213,,0.58196,2712,,58.196,2.712,,,,7.85398e-5
1:0.5 (rep 1),3-Recover,151.367,1.368,1.847,0.199,,0.574495,2533.75,,57.4495,2.53375,,,,7.85398e-5
1:0.5 (rep 1),3-Recover,151.733,1.391,1.824,0.199,,0.567341,2533.75,,56.7341,2.53375,,,,7.85398e-5
1:0.5 (rep 1),3-Recover,152.1,1.415,1.8,0.213,,0.559876,2712,,55.9876,2.712,,,,7.85398e-5
1:0.5 (rep 1),3-Recover,152.467,1.439,1.776,0.213,,0.552411,2712,,55.2411,2.712,,,,7.85398e-5
1:0.5 (rep 1),3-Recover,152.833,1.462,1.753,0.199,,0.545257,2533.75,,54.5257,2.53375,,,,7.85398e-5
1:0.5 (rep 1),3-Recover,153.2,1.486,1.729,0.172,,0.537792,2189.97,,53.7792,2.18997,,,,7.85398e-5
1:0.5 (rep 1),3-Recover,153.567,1.51,1.705,0.159,,0.530327,2024.45,,53.0327,2.02445,,,,7.85398e-5
1:0.5 (rep 1),3-Recover,153.933,1.533,1.682,0.159,,0.523173,2024.45,,52.3173,2.02445,,,,7.85398e-5
1:0.5 (rep 1),3-Recover,154.3,1.557,1.658,0.159,,0.515708,2024.45,,51.5708,2.02445,,,,7.85398e-5
1:0.5 (rep 1),3-Recover,154.667,1.58,1.635,0.159,,0.508554,2024.45,,50.8554,2.02445,,,,7.85398e-5
1:0.5 (rep 1),3-Recover,155.033,1.603,1.612,0.159,,0.5014,2024.45,,50.14,2.02445,,,,7.85398e-5
1:0.5 (rep 1),3-Recover,155.4,1.627,1.588,0.159,,0.493935,2024.45,,49.3935,2.02445,,,,7.85398e-5
1:0.5 (rep 1),3-Recover,155.767,1.651,1.564,0.159,,0.48647,2024.45,,48.647,2.02445,,,,7.85398e-5
1:0.5 (rep 1),3-Recover,156.133,1.674,1.541,0.159,,0.479316,2024.45,,47.9316,2.02445,,,,7.85398e-5
1:0.5 (rep 1),3-Recover,156.5,1.698,1.517,0.159,,0.471851,2024.45,,47.1851,2.02445,,,,7.85398e-5
1:0.5 (rep 1),3-Recover,156.867,1.722,1.493,0.159,,0.464386,2024.45,,46.4386,2.02445,,,,7.85398e-5
1:0.5 (rep 1),3-Recover,157.233,1.745,1.47,0.125,,0.457232,1591.55,,45.7232,1.59155,,,,7.85398e-5
1:0.5 (rep 1),3-Recover,157.6,1.769,1.446,0.104,,0.449767,1324.17,,44.9767,1.32417,,,,7.85398e-5
1:0.5 (rep 1),3-Recover,157.967,1.793,1.422,0.118,,0.442302,1502.42,,44.2302,1.50242,,,,7.85398e-5
1:0.5 (rep 1),3-Recover,158.333,1.816,1.399,0.118,,0.435148,1502.42,,43.5148,1.50242,,,,7.85398e-5
1:0.5 (rep 1),3-Recover,158.7,1.84,1.375,0.104,,0.427683,1324.17,,42.7683,1.32417,,,,7.85398e-5
1:0.5 (rep 1),3-Recover,159.067,1.864,1.351,0.104,,0.420218,1324.17,,42.0218,1.32417,,,,7.85398e-5
1:0.5 (rep 1),3-Recover,159.433,1.887,1.328,0.104,,0.413064,1324.17,,41.3064,1.32417,,,,7.85398e-5
1:0.5 (rep 1),3-Recover,159.8,1.911,1.304,0.104,,0.405599,1324.17,,40.5599,1.32417,,,,7.85398e-5
1:0.5 (rep 1),3-Recover,160.167,1.934,1.281,0.104,,0.398445,1324.17,,39.8445,1.32417,,,,7.85398e-5
1:0.5 (rep 1),3-Recover,160.533,1.958,1.257,0.104,,0.39098,1324.17,,39.098,1.32417,,,,7.85398e-5
1:0.5 (rep 1),3-Recover,160.9,1.982,1.233,0.104,,0.383515,1324.17,,38.3515,1.32417,,,,7.85398e-5
1:0.5 (rep 1),3-Recover,161.267,2.005,1.21,0.104,,0.376361,1324.17,,37.6361,1.32417,,,,7.85398e-5
1:0.5 (rep 1),3-Recover,161.633,2.029,1.186,0.091,,0.368896,1158.65,,36.8896,1.15865,,,,7.85398e-5
1:0.5 (rep 1),3-Recover,162,2.052,1.163,0.104,,0.361742,1324.17,,36.1742,1.32417,,,,7.85398e-5
1:0.5 (rep 1),3-Recover,162.367,2.076,1.139,0.064,,0.354277,814.873,,35.4277,0.814873,,,,7.85398e-5
1:0.5 (rep 1),3-Recover,162.733,2.099,1.116,0.077,,0.347123,980.395,,34.7123,0.980395,,,,7.85398e-5
1:0.5 (rep 1),3-Recover,163.1,2.123,1.092,0.091,,0.339658,1158.65,,33.9658,1.15865,,,,7.85398e-5
1:0.5 (rep 1),3-Recover,163.467,2.147,1.068,0.091,,0.332193,1158.65,,33.2193,1.15865,,,,7.85398e-5
1:0.5 (rep 1),3-Recover,163.833,2.17,1.045,0.077,,0.325039,980.395,,32.5039,0.980395,,,,7.85398e-5
1:0.5 (rep 1),3-Recover,164.2,2.194,1.021,0.064,,0.317574,814.873,,31.7574,0.814873,,,,7.85398e-5
1:0.5 (rep 1),3-Recover,164.567,2.218,0.997,0.057,,0.310109,725.747,,31.0109,0.725747,,,,7.85398e-5
1:0.5 (rep 1),3-Recover,164.933,2.241,0.974,0.05,,0.302955,636.62,,30.2955,0.63662,,,,7.85398e-5
1:0.5 (rep 1),3-Recover,165.3,2.265,0.95,0.05,,0.29549,636.62,,29.549,0.63662,,,,7.85398e-5
1:0.5 (rep 1),3-Recover,165.667,2.289,0.926,0.057,,0.288025,725.747,,28.8025,0.725747,,,,7.85398e-5
1:0.5 (rep 1),3-Recover,166.033,2.312,0.903,0.05,,0.280871,636.62,,28.0871,0.63662,,,,7.85398e-5
1:0.5 (rep 1),3-Recover,166.4,2.336,0.879,0.05,,0.273406,636.62,,27.3406,0.63662,,,,7.85398e-5
1:0.5 (rep 1),3-Recover,166.767,2.36,0.855,0.05,,0.265941,636.62,,26.5941,0.63662,,,,7.85398e-5
1:0.5 (rep 1),3-Recover,167.133,2.383,0.832,0.05,,0.258787,636.62,,25.8787,0.63662,,,,7.85398e-5
1:0.5 (rep 1),3-Recover,167.5,2.407,0.808,0.05,,0.251322,636.62,,25.1322,0.63662,,,,7.85398e-5
1:0.5 (rep 1),3-Recover,167.867,2.43,0.785,0.05,,0.244168,636.62,,24.4168,0.63662,,,,7.85398e-5
1:0.5 (rep 1),3-Recover,168.233,2.454,0.761,0.05,,0.236703,636.62,,23.6703,0.63662,,,,7.85398e-5
1:0.5 (rep 1),3-Recover,168.6,2.477,0.738,0.05,,0.229549,636.62,,22.9549,0.63662,,,,7.85398e-5
1:0.5 (rep 1),3-Recover,168.967,2.501,0.714,0.05,,0.222084,636.62,,22.2084,0.63662,,,,7.85398e-5
1:0.5 (rep 1),3-Recover,169.333,2.524,0.691,0.05,,0.21493,636.62,,21.493,0.63662,,,,7.85398e-5
1:0.5 (rep 1),3-Recover,169.7,2.548,0.667,0.05,,0.207465,636.62,,20.7465,0.63662,,,,7.85398e-5
1:0.5 (rep 1),3-Recover,170.067,2.572,0.643,0.05,,0.2,636.62,,20,0.63662,,,,7.85398e-5
1:0.5 (rep 1),3-Recover,170.433,2.595,0.62,0.05,,0.192846,636.62,,19.2846,0.63662,,,,7.85398e-5
1:0.5 (rep 1),3-Recover,170.8,2.619,0.596,0.05,,0.185381,636.62,,18.5381,0.63662,,,,7.85398e-5
1:0.5 (rep 1),3-Recover,171.167,2.643,0.572,0.05,,0.177916,636.62,,17.7916,0.63662,,,,7.85398e-5
1:0.5 (rep 1),3-Recover,171.533,2.666,0.549,0.05,,0.170762,636.62,,17.0762,0.63662,,,,7.85398e-5
1:0.5 (rep 1),3-Recover,171.9,2.69,0.525,0.05,,0.163297,636.62,,16.3297,0.63662,,,,7.85398e-5
1:0.5 (rep 1),3-Recover,172.267,2.714,0.501,0.03,,0.155832,381.972,,15.5832,0.381972,,,,7.85398e-5
1:0.5 (rep 1),3-Recover,172.633,2.737,0.478,0.016,,0.148678,203.718,,14.8678,0.203718,,,,7.85398e-5
1:0.5 (rep 1),3-Recover,173,2.761,0.454,0.043,,0.141213,547.493,,14.1213,0.547493,,,,7.85398e-5
1:0.5 (rep 1),3-Recover,173.367,2.785,0.43,0.043,,0.133748,547.493,,13.3748,0.547493,,,,7.85398e-5
1:0.5 (rep 1),3-Recover,173.733,2.808,0.407,0.036,,0.126594,458.366,,12.6594,0.458366,,,,7.85398e-5
1:0.5 (rep 1),3-Recover,174.1,2.832,0.383,0.03,,0.119129,381.972,,11.9129,0.381972,,,,7.85398e-5
1:0.5 (rep 1),3-Recover,174.467,2.855,0.36,0.023,,0.111975,292.845,,11.1975,0.292845,,,,7.85398e-5
1:0.5 (rep 1),3-Recover,174.833,2.879,0.336,0.016,,0.10451,203.718,,10.451,0.203718,,,,7.85398e-5
1:0.5 (rep 1),3-Recover,175.2,2.902,0.313,0.016,,0.0973561,203.718,,9.73561,0.203718,,,,7.85398e-5
1:0.5 (rep 1),3-Recover,175.567,2.926,0.289,0.023,,0.0898911,292.845,,8.98911,0.292845,,,,7.85398e-5
1:0.5 (rep 1),3-Recover,175.933,2.949,0.266,0.03,,0.0827372,381.972,,8.27372,0.381972,,,,7.85398e-5
1:0.5 (rep 1),3-Recover,176.3,2.973,0.242,0.023,,0.0752722,292.845,,7.52722,0.292845,,,,7.85398e-5
1:0.5 (rep 1),3-Recover,176.667,2.997,0.218,0.009,,0.0678072,114.592,,6.78072,0.114592,,,,7.85398e-5
1:0.5 (rep 1),3-Recover,177.033,3.02,0.195,0.009,,0.0606532,114.592,,6.06532,0.114592,,,,7.85398e-5
1:0.5 (rep 1),3-Recover,177.4,3.044,0.171,0.009,,0.0531882,114.592,,5.31882,0.114592,,,,7.85398e-5
1:0.5 (rep 1),3-Recover,177.767,3.068,0.147,0.002,,0.0457232,25.4648,,4.57232,0.0254648,,,,7.85398e-5
1:0.5 (rep 1),3-Recover,178.133,3.091,0.124,0.016,,0.0385692,203.718,,3.85692,0.203718,,,,7.85398e-5
1:0.5 (rep 1),3-Recover,178.5,3.115,0.1,0.009,,0.0311042,114.592,,3.11042,0.114592,,,,7.85398e-5
1:0.5 (rep 1),3-Recover,178.867,3.139,0.076,0.023,,0.0236392,292.845,,2.36392,0.292845,,,,7.85398e-5
1:0.5 (rep 1),3-Recover,179.233,3.162,0.053,0.009,,0.0164852,114.592,,1.64852,0.114592,,,,7.85398e-5
1:0.5 (rep 1),3-Recover,179.6,3.185,0.03,0.002,,0.00933126,25.4648,,0.933126,0.0254648,,,,7.85398e-5
1:0.5 (rep 1),3-Recover,179.967,3.21,0.005,0.002,,0.00155521,25.4648,,0.155521,0.0254648,,,,7.85398e-5
1:0.5 (rep 1),3-Recover,180.1,3.215,0,0.016,,0,203.718,,0,0.203718,,,,7.85398e-5