File: data/beta_1-1-0_1.csv
SetName,Cycle,Time_S,Size_mm,Displacement_mm,Force_N,,Strain,Stress(Pascal),,%Strain,Stress(kPa),,,,Area(m^2)
Test1,1-Compress,0.000,2.208,-0,0.031,,0,394.704,,0,0.394704,,,,7.85398e-5
Test1,1-Compress,0.333,2.193,0.015,0.031,,0.00679348,394.704,,0.679348,0.394704,,,,7.85398e-5
Test1,1-Compress,0.667,2.178,0.03,0.031,,0.013587,394.704,,1.3587,0.394704,,,,7.85398e-5
Test1,1-Compress,1.000,2.163,0.045,0.031,,0.0203804,394.704,,2.03804,0.394704,,,,7.85398e-5
Test1,1-Compress,1.333,2.149,0.059,0.031,,0.026721,394.704,,2.6721,0.394704,,,,7.85398e-5
Test1,1-Compress,1.667,2.134,0.074,0.031,,0.0335145,394.704,,3.35145,0.394704,,,,7.85398e-5
Test1,1-Compress,2.000,2.119,0.089,0.031,,0.040308,394.704,,4.0308,0.394704,,,,7.85398e-5
Test1,1-Compress,2.333,2.105,0.103,0.031,,0.0466486,394.704,,4.66486,0.394704,,,,7.85398e-5
Test1,1-Compress,2.667,2.09,0.118,0.031,,0.053442,394.704,,5.3442,0.394704,,,,7.85398e-5
Test1,1-Compress,3.000,2.075,0.133,0.031,,0.0602355,394.704,,6.02355,0.394704,,,,7.85398e-5
Test1,1-Compress,3.333,2.061,0.147,0.031,,0.0665761,394.704,,6.65761,0.394704,,,,7.85398e-5
Test1,1-Compress,3.667,2.045,0.163,0.031,,0.0738225,394.704,,7.38225,0.394704,,,,7.85398e-5
Test1,1-Compress,4.000,2.031,0.177,0.031,,0.080163,394.704,,8.0163,0.394704,,,,7.85398e-5
Test1,1-Compress,4.333,2.016,0.192,0.031,,0.0869565,394.704,,8.69565,0.394704,,,,7.85398e-5
Test1,1-Compress,4.667,2.001,0.207,0.038,,0.09375,483.831,,9.375,0.483831,,,,7.85398e-5
Test1,1-Compress,5.000,1.987,0.221,0.038,,0.100091,483.831,,10.0091,0.483831,,,,7.85398e-5
Test1,1-Compress,5.333,1.972,0.236,0.038,,0.106884,483.831,,10.6884,0.483831,,,,7.85398e-5
Test1,1-Compress,5.667,1.957,0.251,0.044,,0.113678,560.226,,11.3678,0.560226,,,,7.85398e-5
Test1,1-Compress,6.000,1.942,0.266,0.038,,0.120471,483.831,,12.0471,0.483831,,,,7.85398e-5
Test1,1-Compress,6.333,1.928,0.28,0.044,,0.126812,560.226,,12.6812,0.560226,,,,7.85398e-5
Test1,1-Compress,6.667,1.913,0.295,0.044,,0.133605,560.226,,13.3605,0.560226,,,,7.85398e-5
Test1,1-Compress,7.000,1.898,0.31,0.044,,0.140399,560.226,,14.0399,0.560226,,,,7.85398e-5
Test1,1-Compress,7.333,1.884,0.324,0.038,,0.146739,483.831,,14.6739,0.483831,,,,7.85398e-5
Test1,1-Compress,7.667,1.868,0.34,0.038,,0.153986,483.831,,15.3986,0.483831,,,,7.85398e-5
Test1,1-Compress,8.000,1.854,0.354,0.044,,0.160326,560.226,,16.0326,0.560226,,,,7.85398e-5
Test1,1-Compress,8.333,1.839,0.369,0.044,,0.16712,560.226,,16.712,0.560226,,,,7.85398e-5
Test1,1-Compress,8.667,1.824,0.384,0.038,,0.173913,483.831,,17.3913,0.483831,,,,7.85398e-5
Test1,1-Compress,9.000,1.81,0.398,0.038,,0.180254,483.831,,18.0254,0.483831,,,,7.85398e-5
Test1,1-Compress,9.333,1.795,0.413,0.044,,0.187047,560.226,,18.7047,0.560226,,,,7.85398e-5
Test1,1-Compress,9.667,1.78,0.428,0.044,,0.193841,560.226,,19.3841,0.560226,,,,7.85398e-5
Test1,1-Compress,10.000,1.766,0.442,0.051,,0.200181,649.352,,20.0181,0.649352,,,,7.85398e-5
Test1,1-Compress,10.333,1.751,0.457,0.038,,0.206975,483.831,,20.6975,0.483831,,,,7.85398e-5
Test1,1-Compress,10.667,1.736,0.472,0.038,,0.213768,483.831,,21.3768,0.483831,,,,7.85398e-5
Test1,1-Compress,11.000,1.721,0.487,0.044,,0.220562,560.226,,22.0562,0.560226,,,,7.85398e-5
Test1,1-Compress,11.333,1.707,0.501,0.038,,0.226902,483.831,,22.6902,0.483831,,,,7.85398e-5
Test1,1-Compress,11.667,1.692,0.516,0.038,,0.233696,483.831,,23.3696,0.483831,,,,7.85398e-5
Test1,1-Compress,12.000,1.677,0.531,0.038,,0.240489,483.831,,24.0489,0.483831,,,,7.85398e-5
Test1,1-Compress,12.333,1.663,0.545,0.038,,0.24683,483.831,,24.683,0.483831,,,,7.85398e-5
Test1,1-Compress,12.667,1.647,0.561,0.038,,0.254076,483.831,,25.4076,0.483831,,,,7.85398e-5
Test1,1-Compress,13.000,1.633,0.575,0.038,,0.260417,483.831,,26.0417,0.483831,,,,7.85398e-5
Test1,1-Compress,13.333,1.618,0.59,0.058,,0.26721,738.479,,26.721,0.738479,,,,7.85398e-5
Test1,1-Compress,13.667,1.603,0.605,0.051,,0.274004,649.352,,27.4004,0.649352,,,,7.85398e-5
Test1,1-Compress,14.000,1.589,0.619,0.065,,0.280344,827.606,,28.0344,0.827606,,,,7.85398e-5
Test1,1-Compress,14.333,1.574,0.634,0.051,,0.287138,649.352,,28.7138,0.649352,,,,7.85398e-5
Test1,1-Compress,14.667,1.559,0.649,0.065,,0.293931,827.606,,29.3931,0.827606,,,,7.85398e-5
Test1,1-Compress,15.000,1.544,0.664,0.072,,0.300725,916.733,,30.0725,0.916733,,,,7.85398e-5
Test1,1-Compress,15.333,1.53,0.678,0.065,,0.307065,827.606,,30.7065,0.827606,,,,7.85398e-5
Test1,1-Compress,15.667,1.515,0.693,0.072,,0.313859,916.733,,31.3859,0.916733,,,,7.85398e-5
Test1,1-Compress,16.000,1.5,0.708,0.085,,0.320652,1082.25,,32.0652,1.08225,,,,7.85398e-5
Test1,1-Compress,16.333,1.486,0.722,0.078,,0.326993,993.127,,32.6993,0.993127,,,,7.85398e-5
Test1,1-Compress,16.667,1.47,0.738,0.078,,0.334239,993.127,,33.4239,0.993127,,,,7.85398e-5
Test1,1-Compress,17.000,1.456,0.752,0.085,,0.34058,1082.25,,34.058,1.08225,,,,7.85398e-5
Test1,1-Compress,17.333,1.441,0.767,0.085,,0.347373,1082.25,,34.7373,1.08225,,,,7.85398e-5
Test1,1-Compress,17.667,1.426,0.782,0.085,,0.354167,1082.25,,35.4167,1.08225,,,,7.85398e-5
Test1,1-Compress,18.000,1.412,0.796,0.078,,0.360507,993.127,,36.0507,0.993127,,,,7.85398e-5
Test1,1-Compress,18.333,1.397,0.811,0.072,,0.367301,916.733,,36.7301,0.916733,,,,7.85398e-5
Test1,1-Compress,18.667,1.382,0.826,0.058,,0.374094,738.479,,37.4094,0.738479,,,,7.85398e-5
Test1,1-Compress,19.000,1.368,0.84,0.085,,0.380435,1082.25,,38.0435,1.08225,,,,7.85398e-5
Test1,1-Compress,19.333,1.353,0.855,0.058,,0.387228,738.479,,38.7228,0.738479,,,,7.85398e-5
Test1,1-Compress,19.667,1.338,0.87,0.085,,0.394022,1082.25,,39.4022,1.08225,,,,7.85398e-5
Test1,1-Compress,20.000,1.323,0.885,0.078,,0.400815,993.127,,40.0815,0.993127,,,,7.85398e-5
Test1,1-Compress,20.333,1.309,0.899,0.085,,0.407156,1082.25,,40.7156,1.08225,,,,7.85398e-5
Test1,1-Compress,20.667,1.294,0.914,0.085,,0.413949,1082.25,,41.3949,1.08225,,,,7.85398e-5
Test1,1-Compress,21.000,1.279,0.929,0.078,,0.420743,993.127,,42.0743,0.993127,,,,7.85398e-5
Test1,1-Compress,21.333,1.265,0.943,0.085,,0.427083,1082.25,,42.7083,1.08225,,,,7.85398e-5
Test1,1-Compress,21.667,1.249,0.959,0.085,,0.43433,1082.25,,43.433,1.08225,,,,7.85398e-5
Test1,1-Compress,22.000,1.235,0.973,0.092,,0.44067,1171.38,,44.067,1.17138,,,,7.85398e-5
Test1,1-Compress,22.333,1.22,0.988,0.085,,0.447464,1082.25,,44.7464,1.08225,,,,7.85398e-5
Test1,1-Compress,22.667,1.205,1.003,0.085,,0.454257,1082.25,,45.4257,1.08225,,,,7.85398e-5
Test1,1-Compress,23.000,1.191,1.017,0.085,,0.460598,1082.25,,46.0598,1.08225,,,,7.85398e-5
Test1,1-Compress,23.333,1.176,1.032,0.085,,0.467391,1082.25,,46.7391,1.08225,,,,7.85398e-5
Test1,1-Compress,23.667,1.161,1.047,0.092,,0.474185,1171.38,,47.4185,1.17138,,,,7.85398e-5
Test1,1-Compress,24.000,1.146,1.062,0.085,,0.480978,1082.25,,48.0978,1.08225,,,,7.85398e-5
Test1,1-Compress,24.333,1.132,1.076,0.085,,0.487319,1082.25,,48.7319,1.08225,,,,7.85398e-5
Test1,1-Compress,24.667,1.117,1.091,0.085,,0.494112,1082.25,,49.4112,1.08225,,,,7.85398e-5
Test1,1-Compress,25.000,1.102,1.106,0.085,,0.500906,1082.25,,50.0906,1.08225,,,,7.85398e-5
Test1,1-Compress,25.333,1.088,1.12,0.085,,0.507246,1082.25,,50.7246,1.08225,,,,7.85398e-5
Test1,1-Compress,25.667,1.073,1.135,0.085,,0.51404,1082.25,,51.404,1.08225,,,,7.85398e-5
Test1,1-Compress,26.000,1.058,1.15,0.085,,0.520833,1082.25,,52.0833,1.08225,,,,7.85398e-5
Test1,1-Compress,26.333,1.043,1.165,0.085,,0.527627,1082.25,,52.7627,1.08225,,,,7.85398e-5
Test1,1-Compress,26.667,1.028,1.18,0.085,,0.53442,1082.25,,53.442,1.08225,,,,7.85398e-5
Test1,1-Compress,27.000,1.014,1.194,0.085,,0.540761,1082.25,,54.0761,1.08225,,,,7.85398e-5
Test1,1-Compress,27.333,0.999,1.209,0.085,,0.547554,1082.25,,54.7554,1.08225,,,,7.85398e-5
Test1,1-Compress,27.667,0.984,1.224,0.092,,0.554348,1171.38,,55.4348,1.17138,,,,7.85398e-5
Test1,1-Compress,28.000,0.97,1.238,0.092,,0.560688,1171.38,,56.0688,1.17138,,,,7.85398e-5
Test1,1-Compress,28.333,0.955,1.253,0.092,,0.567482,1171.38,,56.7482,1.17138,,,,7.85398e-5
Test1,1-Compress,28.667,0.94,1.268,0.092,,0.574275,1171.38,,57.4275,1.17138,,,,7.85398e-5
Test1,1-Compress,29.000,0.925,1.283,0.085,,0.581069,1082.25,,58.1069,1.08225,,,,7.85398e-5
Test1,1-Compress,29.333,0.911,1.297,0.085,,0.587409,1082.25,,58.7409,1.08225,,,,7.85398e-5
Test1,1-Compress,29.667,0.896,1.312,0.099,,0.594203,1260.51,,59.4203,1.26051,,,,7.85398e-5
Test1,1-Compress,30.000,0.883,1.325,0.092,,0.600091,1171.38,,60.0091,1.17138,,,,7.85398e-5
Test1,1-Recover,30.333,0.897,1.311,0.092,,0.59375,1171.38,,59.375,1.17138,,,,7.85398e-5
Test1,1-Recover,30.667,0.912,1.296,0.099,,0.586957,1260.51,,58.6957,1.26051,,,,7.85398e-5
Test1,1-Recover,31.000,0.926,1.282,0.092,,0.580616,1171.38,,58.0616,1.17138,,,,7.85398e-5
Test1,1-Recover,31.333,0.941,1.267,0.099,,0.573822,1260.51,,57.3822,1.26051,,,,7.85398e-5
Test1,1-Recover,31.667,0.956,1.252,0.092,,0.567029,1171.38,,56.7029,1.17138,,,,7.85398e-5
Test1,1-Recover,32.000,0.971,1.237,0.099,,0.560236,1260.51,,56.0236,1.26051,,,,7.85398e-5
Test1,1-Recover,32.333,0.985,1.223,0.092,,0.553895,1171.38,,55.3895,1.17138,,,,7.85398e-5
Test1,1-Recover,32.667,1,1.208,0.085,,0.547101,1082.25,,54.7101,1.08225,,,,7.85398e-5
Test1,1-Recover,33.000,1.015,1.193,0.085,,0.540308,1082.25,,54.0308,1.08225,,,,7.85398e-5
Test1,1-Recover,33.333,1.029,1.179,0.085,,0.533967,1082.25,,53.3967,1.08225,,,,7.85398e-5
Test1,1-Recover,33.667,1.044,1.164,0.085,,0.527174,1082.25,,52.7174,1.08225,,,,7.85398e-5
Test1,1-Recover,34.000,1.059,1.149,0.085,,0.52038,1082.25,,52.038,1.08225,,,,7.85398e-5
Test1,1-Recover,34.333,1.073,1.135,0.085,,0.51404,1082.25,,51.404,1.08225,,,,7.85398e-5
Test1,1-Recover,34.667,1.089,1.119,0.085,,0.506793,1082.25,,50.6793,1.08225,,,,7.85398e-5
Test1,1-Recover,35.000,1.103,1.105,0.085,,0.500453,1082.25,,50.0453,1.08225,,,,7.85398e-5
Test1,1-Recover,35.333,1.118,1.09,0.085,,0.493659,1082.25,,49.3659,1.08225,,,,7.85398e-5
Test1,1-Recover,35.667,1.133,1.075,0.085,,0.486866,1082.25,,48.6866,1.08225,,,,7.85398e-5
Test1,1-Recover,36.000,1.147,1.061,0.085,,0.480525,1082.25,,48.0525,1.08225,,,,7.85398e-5
Test1,1-Recover,36.333,1.162,1.046,0.085,,0.473732,1082.25,,47.3732,1.08225,,,,7.85398e-5
Test1,1-Recover,36.667,1.177,1.031,0.085,,0.466938,1082.25,,46.6938,1.08225,,,,7.85398e-5
Test1,1-Recover,37.000,1.192,1.016,0.085,,0.460145,1082.25,,46.0145,1.08225,,,,7.85398e-5
Test1,1-Recover,37.333,1.206,1.002,0.058,,0.453804,738.479,,45.3804,0.738479,,,,7.85398e-5
Test1,1-Recover,37.667,1.221,0.987,0.085,,0.447011,1082.25,,44.7011,1.08225,,,,7.85398e-5
Test1,1-Recover,38.000,1.236,0.972,0.065,,0.440217,827.606,,44.0217,0.827606,,,,7.85398e-5
Test1,1-Recover,38.333,1.25,0.958,0.078,,0.433877,993.127,,43.3877,0.993127,,,,7.85398e-5
Test1,1-Recover,38.667,1.266,0.942,0.078,,0.42663,993.127,,42.663,0.993127,,,,7.85398e-5
Test1,1-Recover,39.000,1.28,0.928,0.065,,0.42029,827.606,,42.029,0.827606,,,,7.85398e-5
Test1,1-Recover,39.333,1.295,0.913,0.072,,0.413496,916.733,,41.3496,0.916733,,,,7.85398e-5
Test1,1-Recover,39.667,1.31,0.898,0.072,,0.406703,916.733,,40.6703,0.916733,,,,7.85398e-5
Test1,1-Recover,40.000,1.324,0.884,0.072,,0.400362,916.733,,40.0362,0.916733,,,,7.85398e-5
Test1,1-Recover,40.333,1.339,0.869,0.078,,0.393569,993.127,,39.3569,0.993127,,,,7.85398e-5
Test1,1-Recover,40.667,1.354,0.854,0.058,,0.386775,738.479,,38.6775,0.738479,,,,7.85398e-5
Test1,1-Recover,41.000,1.369,0.839,0.058,,0.379982,738.479,,37.9982,0.738479,,,,7.85398e-5
Test1,1-Recover,41.333,1.383,0.825,0.051,,0.373641,649.352,,37.3641,0.649352,,,,7.85398e-5
Test1,1-Recover,41.667,1.398,0.81,0.044,,0.366848,560.226,,36.6848,0.560226,,,,7.85398e-5
Test1,1-Recover,42.000,1.413,0.795,0.044,,0.360054,560.226,,36.0054,0.560226,,,,7.85398e-5
Test1,1-Recover,42.333,1.428,0.78,0.044,,0.353261,560.226,,35.3261,0.560226,,,,7.85398e-5
Test1,1-Recover,42.667,1.442,0.766,0.038,,0.34692,483.831,,34.692,0.483831,,,,7.85398e-5
Test1,1-Recover,43.000,1.457,0.751,0.038,,0.340127,483.831,,34.0127,0.483831,,,,7.85398e-5
Test1,1-Recover,43.333,1.472,0.736,0.038,,0.333333,483.831,,33.3333,0.483831,,,,7.85398e-5
Test1,1-Recover,43.667,1.487,0.721,0.038,,0.32654,483.831,,32.654,0.483831,,,,7.85398e-5
Test1,1-Recover,44.000,1.501,0.707,0.031,,0.320199,394.704,,32.0199,0.394704,,,,7.85398e-5
Test1,1-Recover,44.333,1.516,0.692,0.038,,0.313406,483.831,,31.3406,0.483831,,,,7.85398e-5
Test1,1-Recover,44.667,1.531,0.677,0.038,,0.306612,483.831,,30.6612,0.483831,,,,7.85398e-5
Test1,1-Recover,45.000,1.545,0.663,0.038,,0.300272,483.831,,30.0272,0.483831,,,,7.85398e-5
Test1,1-Recover,45.333,1.56,0.648,0.038,,0.293478,483.831,,29.3478,0.483831,,,,7.85398e-5
Test1,1-Recover,45.667,1.575,0.633,0.038,,0.286685,483.831,,28.6685,0.483831,,,,7.85398e-5
Test1,1-Recover,46.000,1.59,0.618,0.044,,0.279891,560.226,,27.9891,0.560226,,,,7.85398e-5
Test1,1-Recover,46.333,1.604,0.604,0.044,,0.273551,560.226,,27.3551,0.560226,,,,7.85398e-5
Test1,1-Recover,46.667,1.619,0.589,0.044,,0.266757,560.226,,26.6757,0.560226,,,,7.85398e-5
Test1,1-Recover,47.000,1.634,0.574,0.038,,0.259964,483.831,,25.9964,0.483831,,,,7.85398e-5
Test1,1-Recover,47.333,1.649,0.559,0.044,,0.25317,560.226,,25.317,0.560226,,,,7.85398e-5
Test1,1-Recover,47.667,1.664,0.544,0.038,,0.246377,483.831,,24.6377,0.483831,,,,7.85398e-5
Test1,1-Recover,48.000,1.678,0.53,0.038,,0.240036,483.831,,24.0036,0.483831,,,,7.85398e-5
Test1,1-Recover,48.333,1.693,0.515,0.031,,0.233243,394.704,,23.3243,0.394704,,,,7.85398e-5
Test1,1-Recover,48.667,1.708,0.5,0.031,,0.226449,394.704,,22.6449,0.394704,,,,7.85398e-5
Test1,1-Recover,49.000,1.723,0.485,0.031,,0.219656,394.704,,21.9656,0.394704,,,,7.85398e-5
Test1,1-Recover,49.333,1.737,0.471,0.031,,0.213315,394.704,,21.3315,0.394704,,,,7.85398e-5
Test1,1-Recover,49.667,1.752,0.456,0.031,,0.206522,394.704,,20.6522,0.394704,,,,7.85398e-5
Test1,1-Recover,50.000,1.767,0.441,0.031,,0.199728,394.704,,19.9728,0.394704,,,,7.85398e-5
Test1,1-Recover,50.333,1.781,0.427,0.031,,0.193388,394.704,,19.3388,0.394704,,,,7.85398e-5
Test1,1-Recover,50.667,1.796,0.412,0.031,,0.186594,394.704,,18.6594,0.394704,,,,7.85398e-5
Test1,1-Recover,51.000,1.811,0.397,0.031,,0.179801,394.704,,17.9801,0.394704,,,,7.85398e-5
Test1,1-Recover,51.333,1.826,0.382,0.031,,0.173007,394.704,,17.3007,0.394704,,,,7.85398e-5
Test1,1-Recover,51.667,1.84,0.368,0.031,,0.166667,394.704,,16.6667,0.394704,,,,7.85398e-5
Test1,1-Recover,52.000,1.855,0.353,0.031,,0.159873,394.704,,15.9873,0.394704,,,,7.85398e-5
Test1,1-Recover,52.333,1.87,0.338,0.031,,0.15308,394.704,,15.308,0.394704,,,,7.85398e-5
Test1,1-Recover,52.667,1.885,0.323,0.024,,0.146286,305.578,,14.6286,0.305578,,,,7.85398e-5
Test1,1-Recover,53.000,1.899,0.309,0.024,,0.139946,305.578,,13.9946,0.305578,,,,7.85398e-5
Test1,1-Recover,53.333,1.914,0.294,0.024,,0.133152,305.578,,13.3152,0.305578,,,,7.85398e-5
Test1,1-Recover,53.667,1.929,0.279,0.004,,0.126359,50.9296,,12.6359,0.0509296,,,,7.85398e-5
Test1,1-Recover,54.000,1.944,0.264,0.024,,0.119565,305.578,,11.9565,0.305578,,,,7.85398e-5
Test1,1-Recover,54.333,1.959,0.249,0.024,,0.112772,305.578,,11.2772,0.305578,,,,7.85398e-5
Test1,1-Recover,54.667,1.973,0.235,0.011,,0.106431,140.056,,10.6431,0.140056,,,,7.85398e-5
Test1,1-Recover,55.000,1.988,0.22,0.011,,0.0996377,140.056,,9.96377,0.140056,,,,7.85398e-5
Test1,1-Recover,55.333,2.003,0.205,0.017,,0.0928442,216.451,,9.28442,0.216451,,,,7.85398e-5
Test1,1-Recover,55.667,2.018,0.19,0.017,,0.0860507,216.451,,8.60507,0.216451,,,,7.85398e-5
Test1,1-Recover,56.000,2.032,0.176,0.011,,0.0797101,140.056,,7.97101,0.140056,,,,7.85398e-5
Test1,1-Recover,56.333,2.047,0.161,0.017,,0.0729167,216.451,,7.29167,0.216451,,,,7.85398e-5
Test1,1-Recover,56.667,2.062,0.146,0.004,,0.0661232,50.9296,,6.61232,0.0509296,,,,7.85398e-5
Test1,1-Recover,57.000,2.076,0.132,0.024,,0.0597826,305.578,,5.97826,0.305578,,,,7.85398e-5
Test1,1-Recover,57.333,2.091,0.117,0.004,,0.0529891,50.9296,,5.29891,0.0509296,,,,7.85398e-5
Test1,1-Recover,57.667,2.106,0.102,-0.003,,0.0461957,-38.1972,,4.61957,-0.0381972,,,,7.85398e-5
Test1,1-Recover,58.000,2.121,0.087,0.004,,0.0394022,50.9296,,3.94022,0.0509296,,,,7.85398e-5
Test1,1-Recover,58.333,2.135,0.073,-0.010,,0.0330616,-127.324,,3.30616,-0.127324,,,,7.85398e-5
Test1,1-Recover,58.667,2.15,0.058,-0.017,,0.0262681,-216.451,,2.62681,-0.216451,,,,7.85398e-5
Test1,1-Recover,59.000,2.165,0.043,-0.003,,0.0194746,-38.1972,,1.94746,-0.0381972,,,,7.85398e-5
Test1,1-Recover,59.333,2.18,0.028,-0.010,,0.0126812,-127.324,,1.26812,-0.127324,,,,7.85398e-5
Test1,1-Recover,59.667,2.195,0.013,-0.017,,0.00588768,-216.451,,0.588768,-0.216451,,,,7.85398e-5
Test1,1-Recover,60.000,2.208,-0,-0.003,,0,-38.1972,,0,-0.0381972,,,,7.85398e-5
Test1,2-Compress,60.317,2.195,0.013,-0.010,,0.00588768,-127.324,,0.588768,-0.127324,,,,7.85398e-5
Test1,2-Compress,60.650,2.181,0.027,-0.010,,0.0122283,-127.324,,1.22283,-0.127324,,,,7.85398e-5
Test1,2-Compress,60.983,2.166,0.042,-0.017,,0.0190217,-216.451,,1.90217,-0.216451,,,,7.85398e-5
Test1,2-Compress,61.317,2.151,0.057,-0.017,,0.0258152,-216.451,,2.58152,-0.216451,,,,7.85398e-5
Test1,2-Compress,61.650,2.137,0.071,-0.010,,0.0321558,-127.324,,3.21558,-0.127324,,,,7.85398e-5
Test1,2-Compress,61.983,2.122,0.086,0.004,,0.0389493,50.9296,,3.89493,0.0509296,,,,7.85398e-5
Test1,2-Compress,62.317,2.107,0.101,0.011,,0.0457428,140.056,,4.57428,0.140056,,,,7.85398e-5
Test1,2-Compress,62.650,2.092,0.116,0.011,,0.0525362,140.056,,5.25362,0.140056,,,,7.85398e-5
Test1,2-Compress,62.983,2.078,0.13,0.017,,0.0588768,216.451,,5.88768,0.216451,,,,7.85398e-5
Test1,2-Compress,63.317,2.063,0.145,0.031,,0.0656703,394.704,,6.56703,0.394704,,,,7.85398e-5
Test1,2-Compress,63.650,2.048,0.16,0.024,,0.0724638,305.578,,7.24638,0.305578,,,,7.85398e-5
Test1,2-Compress,63.983,2.033,0.175,0.031,,0.0792572,394.704,,7.92572,0.394704,,,,7.85398e-5
Test1,2-Compress,64.317,2.019,0.189,0.024,,0.0855978,305.578,,8.55978,0.305578,,,,7.85398e-5
Test1,2-Compress,64.650,2.004,0.204,0.031,,0.0923913,394.704,,9.23913,0.394704,,,,7.85398e-5
Test1,2-Compress,64.983,1.989,0.219,0.031,,0.0991848,394.704,,9.91848,0.394704,,,,7.85398e-5
Test1,2-Compress,65.317,1.974,0.234,0.031,,0.105978,394.704,,10.5978,0.394704,,,,7.85398e-5
Test1,2-Compress,65.650,1.96,0.248,0.031,,0.112319,394.704,,11.2319,0.394704,,,,7.85398e-5
Test1,2-Compress,65.983,1.945,0.263,0.031,,0.119112,394.704,,11.9112,0.394704,,,,7.85398e-5
Test1,2-Compress,66.317,1.93,0.278,0.031,,0.125906,394.704,,12.5906,0.394704,,,,7.85398e-5
Test1,2-Compress,66.650,1.915,0.293,0.031,,0.132699,394.704,,13.2699,0.394704,,,,7.85398e-5
Test1,2-Compress,66.983,1.9,0.308,0.031,,0.139493,394.704,,13.9493,0.394704,,,,7.85398e-5
Test1,2-Compress,67.317,1.886,0.322,0.031,,0.145833,394.704,,14.5833,0.394704,,,,7.85398e-5
Test1,2-Compress,67.650,1.871,0.337,0.031,,0.152627,394.704,,15.2627,0.394704,,,,7.85398e-5
Test1,2-Compress,67.983,1.856,0.352,0.031,,0.15942,394.704,,15.942,0.394704,,,,7.85398e-5
Test1,2-Compress,68.317,1.842,0.366,0.031,,0.165761,394.704,,16.5761,0.394704,,,,7.85398e-5
Test1,2-Compress,68.650,1.827,0.381,0.031,,0.172554,394.704,,17.2554,0.394704,,,,7.85398e-5
Test1,2-Compress,68.983,1.812,0.396,0.031,,0.179348,394.704,,17.9348,0.394704,,,,7.85398e-5
Test1,2-Compress,69.317,1.798,0.41,0.038,,0.185688,483.831,,18.5688,0.483831,,,,7.85398e-5
Test1,2-Compress,69.650,1.783,0.425,0.038,,0.192482,483.831,,19.2482,0.483831,,,,7.85398e-5
Test1,2-Compress,69.983,1.768,0.44,0.038,,0.199275,483.831,,19.9275,0.483831,,,,7.85398e-5
Test1,2-Compress,70.317,1.753,0.455,0.038,,0.206069,483.831,,20.6069,0.483831,,,,7.85398e-5
Test1,2-Compress,70.650,1.738,0.47,0.044,,0.212862,560.226,,21.2862,0.560226,,,,7.85398e-5
Test1,2-Compress,70.983,1.724,0.484,0.044,,0.219203,560.226,,21.9203,0.560226,,,,7.85398e-5
Test1,2-Compress,71.317,1.709,0.499,0.044,,0.225996,560.226,,22.5996,0.560226,,,,7.85398e-5
Test1,2-Compress,71.650,1.694,0.514,0.044,,0.23279,560.226,,23.279,0.560226,,,,7.85398e-5
Test1,2-Compress,71.983,1.679,0.529,0.044,,0.239583,560.226,,23.9583,0.560226,,,,7.85398e-5
Test1,2-Compress,72.317,1.665,0.543,0.038,,0.245924,483.831,,24.5924,0.483831,,,,7.85398e-5
Test1,2-Compress,72.650,1.65,0.558,0.038,,0.252717,483.831,,25.2717,0.483831,,,,7.85398e-5
Test1,2-Compress,72.983,1.635,0.573,0.031,,0.259511,394.704,,25.9511,0.394704,,,,7.85398e-5
Test1,2-Compress,73.317,1.62,0.588,0.038,,0.266304,483.831,,26.6304,0.483831,,,,7.85398e-5
Test1,2-Compress,73.650,1.606,0.602,0.038,,0.272645,483.831,,27.2645,0.483831,,,,7.85398e-5
Test1,2-Compress,73.983,1.591,0.617,0.044,,0.279438,560.226,,27.9438,0.560226,,,,7.85398e-5
Test1,2-Compress,74.317,1.576,0.632,0.038,,0.286232,483.831,,28.6232,0.483831,,,,7.85398e-5
Test1,2-Compress,74.650,1.561,0.647,0.031,,0.293025,394.704,,29.3025,0.394704,,,,7.85398e-5
Test1,2-Compress,74.983,1.547,0.661,0.038,,0.299366,483.831,,29.9366,0.483831,,,,7.85398e-5
Test1,2-Compress,75.317,1.532,0.676,0.044,,0.306159,560.226,,30.6159,0.560226,,,,7.85398e-5
Test1,2-Compress,75.650,1.517,0.691,0.038,,0.312953,483.831,,31.2953,0.483831,,,,7.85398e-5
Test1,2-Compress,75.983,1.502,0.706,0.038,,0.319746,483.831,,31.9746,0.483831,,,,7.85398e-5
Test1,2-Compress,76.317,1.488,0.72,0.038,,0.326087,483.831,,32.6087,0.483831,,,,7.85398e-5
Test1,2-Compress,76.650,1.473,0.735,0.038,,0.33288,483.831,,33.288,0.483831,,,,7.85398e-5
Test1,2-Compress,76.983,1.458,0.75,0.038,,0.339674,483.831,,33.9674,0.483831,,,,7.85398e-5
Test1,2-Compress,77.317,1.443,0.765,0.038,,0.346467,483.831,,34.6467,0.483831,,,,7.85398e-5
Test1,2-Compress,77.650,1.429,0.779,0.038,,0.352808,483.831,,35.2808,0.483831,,,,7.85398e-5
Test1,2-Compress,77.983,1.414,0.794,0.038,,0.359601,483.831,,35.9601,0.483831,,,,7.85398e-5
Test1,2-Compress,78.317,1.399,0.809,0.065,,0.366395,827.606,,36.6395,0.827606,,,,7.85398e-5
Test1,2-Compress,78.650,1.384,0.824,0.051,,0.373188,649.352,,37.3188,0.649352,,,,7.85398e-5
Test1,2-Compress,78.983,1.37,0.838,0.051,,0.379529,649.352,,37.9529,0.649352,,,,7.85398e-5
Test1,2-Compress,79.317,1.355,0.853,0.065,,0.386322,827.606,,38.6322,0.827606,,,,7.85398e-5
Test1,2-Compress,79.650,1.34,0.868,0.065,,0.393116,827.606,,39.3116,0.827606,,,,7.85398e-5
Test1,2-Compress,79.983,1.326,0.882,0.065,,0.399457,827.606,,39.9457,0.827606,,,,7.85398e-5
Test1,2-Compress,80.317,1.311,0.897,0.072,,0.40625,916.733,,40.625,0.916733,,,,7.85398e-5
Test1,2-Compress,80.650,1.296,0.912,0.072,,0.413043,916.733,,41.3043,0.916733,,,,7.85398e-5
Test1,2-Compress,80.983,1.281,0.927,0.065,,0.419837,827.606,,41.9837,0.827606,,,,7.85398e-5
Test1,2-Compress,81.317,1.267,0.941,0.065,,0.426178,827.606,,42.6178,0.827606,,,,7.85398e-5
Test1,2-Compress,81.650,1.252,0.956,0.078,,0.432971,993.127,,43.2971,0.993127,,,,7.85398e-5
Test1,2-Compress,81.983,1.237,0.971,0.078,,0.439764,993.127,,43.9764,0.993127,,,,7.85398e-5
Test1,2-Compress,82.317,1.222,0.986,0.085,,0.446558,1082.25,,44.6558,1.08225,,,,7.85398e-5
Test1,2-Compress,82.650,1.207,1.001,0.085,,0.453351,1082.25,,45.3351,1.08225,,,,7.85398e-5
Test1,2-Compress,82.983,1.193,1.015,0.085,,0.459692,1082.25,,45.9692,1.08225,,,,7.85398e-5
Test1,2-Compress,83.317,1.178,1.03,0.085,,0.466486,1082.25,,46.6486,1.08225,,,,7.85398e-5
Test1,2-Compress,83.650,1.163,1.045,0.085,,0.473279,1082.25,,47.3279,1.08225,,,,7.85398e-5
Test1,2-Compress,83.983,1.149,1.059,0.085,,0.47962,1082.25,,47.962,1.08225,,,,7.85398e-5
Test1,2-Compress,84.317,1.134,1.074,0.085,,0.486413,1082.25,,48.6413,1.08225,,,,7.85398e-5
Test1,2-Compress,84.650,1.119,1.089,0.085,,0.493207,1082.25,,49.3207,1.08225,,,,7.85398e-5
Test1,2-Compress,84.983,1.105,1.103,0.085,,0.499547,1082.25,,49.9547,1.08225,,,,7.85398e-5
Test1,2-Compress,85.317,1.089,1.119,0.085,,0.506793,1082.25,,50.6793,1.08225,,,,7.85398e-5
Test1,2-Compress,85.650,1.075,1.133,0.085,,0.513134,1082.25,,51.3134,1.08225,,,,7.85398e-5
Test1,2-Compress,85.983,1.06,1.148,0.085,,0.519928,1082.25,,51.9928,1.08225,,,,7.85398e-5
Test1,2-Compress,86.317,1.045,1.163,0.085,,0.526721,1082.25,,52.6721,1.08225,,,,7.85398e-5
Test1,2-Compress,86.650,1.031,1.177,0.092,,0.533062,1171.38,,53.3062,1.17138,,,,7.85398e-5
Test1,2-Compress,86.983,1.016,1.192,0.085,,0.539855,1082.25,,53.9855,1.08225,,,,7.85398e-5
Test1,2-Compress,87.317,1.001,1.207,0.099,,0.546649,1260.51,,54.6649,1.26051,,,,7.85398e-5
Test1,2-Compress,87.650,0.986,1.222,0.085,,0.553442,1082.25,,55.3442,1.08225,,,,7.85398e-5
Test1,2-Compress,87.983,0.972,1.236,0.092,,0.559783,1171.38,,55.9783,1.17138,,,,7.85398e-5
Test1,2-Compress,88.317,0.957,1.251,0.106,,0.566576,1349.63,,56.6576,1.34963,,,,7.85398e-5
Test1,2-Compress,88.650,0.942,1.266,0.112,,0.57337,1426.03,,57.337,1.42603,,,,7.85398e-5
Test1,2-Compress,88.983,0.928,1.28,0.099,,0.57971,1260.51,,57.971,1.26051,,,,7.85398e-5
Test1,2-Compress,89.317,0.912,1.296,0.106,,0.586957,1349.63,,58.6957,1.34963,,,,7.85398e-5
Test1,2-Compress,89.650,0.898,1.31,0.112,,0.593297,1426.03,,59.3297,1.42603,,,,7.85398e-5
Test1,2-Compress,89.983,0.883,1.325,0.106,,0.600091,1349.63,,60.0091,1.34963,,,,7.85398e-5
Test1,2-Recover,90.303,0.894,1.314,0.112,,0.595109,1426.03,,59.5109,1.42603,,,,7.85398e-5
Test1,2-Recover,90.637,0.908,1.3,0.099,,0.588768,1260.51,,58.8768,1.26051,,,,7.85398e-5
Test1,2-Recover,90.970,0.923,1.285,0.099,,0.581975,1260.51,,58.1975,1.26051,,,,7.85398e-5
Test1,2-Recover,91.303,0.938,1.27,0.099,,0.575181,1260.51,,57.5181,1.26051,,,,7.85398e-5
Test1,2-Recover,91.637,0.953,1.255,0.092,,0.568388,1171.38,,56.8388,1.17138,,,,7.85398e-5
Test1,2-Recover,91.970,0.968,1.24,0.092,,0.561594,1171.38,,56.1594,1.17138,,,,7.85398e-5
Test1,2-Recover,92.303,0.982,1.226,0.092,,0.555254,1171.38,,55.5254,1.17138,,,,7.85398e-5
Test1,2-Recover,92.637,0.997,1.211,0.085,,0.54846,1082.25,,54.846,1.08225,,,,7.85398e-5
Test1,2-Recover,92.970,1.012,1.196,0.085,,0.541667,1082.25,,54.1667,1.08225,,,,7.85398e-5
Test1,2-Recover,93.303,1.027,1.181,0.085,,0.534873,1082.25,,53.4873,1.08225,,,,7.85398e-5
Test1,2-Recover,93.637,1.041,1.167,0.085,,0.528533,1082.25,,52.8533,1.08225,,,,7.85398e-5
Test1,2-Recover,93.970,1.056,1.152,0.085,,0.521739,1082.25,,52.1739,1.08225,,,,7.85398e-5
Test1,2-Recover,94.303,1.071,1.137,0.085,,0.514946,1082.25,,51.4946,1.08225,,,,7.85398e-5
Test1,2-Recover,94.637,1.085,1.123,0.085,,0.508605,1082.25,,50.8605,1.08225,,,,7.85398e-5
Test1,2-Recover,94.970,1.1,1.108,0.085,,0.501812,1082.25,,50.1812,1.08225,,,,7.85398e-5
Test1,2-Recover,95.303,1.115,1.093,0.078,,0.495018,993.127,,49.5018,0.993127,,,,7.85398e-5
Test1,2-Recover,95.637,1.13,1.078,0.085,,0.488225,1082.25,,48.8225,1.08225,,,,7.85398e-5
Test1,2-Recover,95.970,1.144,1.064,0.085,,0.481884,1082.25,,48.1884,1.08225,,,,7.85398e-5
Test1,2-Recover,96.303,1.159,1.049,0.085,,0.475091,1082.25,,47.5091,1.08225,,,,7.85398e-5
Test1,2-Recover,96.637,1.174,1.034,0.085,,0.468297,1082.25,,46.8297,1.08225,,,,7.85398e-5
Test1,2-Recover,96.970,1.189,1.019,0.085,,0.461504,1082.25,,46.1504,1.08225,,,,7.85398e-5
Test1,2-Recover,97.303,1.204,1.004,0.078,,0.45471,993.127,,45.471,0.993127,,,,7.85398e-5
Test1,2-Recover,97.637,1.218,0.99,0.065,,0.44837,827.606,,44.837,0.827606,,,,7.85398e-5
Test1,2-Recover,97.970,1.233,0.975,0.072,,0.441576,916.733,,44.1576,0.916733,,,,7.85398e-5
Test1,2-Recover,98.303,1.248,0.96,0.065,,0.434783,827.606,,43.4783,0.827606,,,,7.85398e-5
Test1,2-Recover,98.637,1.263,0.945,0.065,,0.427989,827.606,,42.7989,0.827606,,,,7.85398e-5
Test1,2-Recover,98.970,1.277,0.931,0.058,,0.421649,738.479,,42.1649,0.738479,,,,7.85398e-5
Test1,2-Recover,99.303,1.292,0.916,0.051,,0.414855,649.352,,41.4855,0.649352,,,,7.85398e-5
Test1,2-Recover,99.637,1.307,0.901,0.044,,0.408062,560.226,,40.8062,0.560226,,,,7.85398e-5
Test1,2-Recover,99.970,1.321,0.887,0.044,,0.401721,560.226,,40.1721,0.560226,,,,7.85398e-5
Test1,2-Recover,100.303,1.336,0.872,0.044,,0.394928,560.226,,39.4928,0.560226,,,,7.85398e-5
Test1,2-Recover,100.637,1.351,0.857,0.038,,0.388134,483.831,,38.8134,0.483831,,,,7.85398e-5
Test1,2-Recover,100.970,1.366,0.842,0.038,,0.381341,483.831,,38.1341,0.483831,,,,7.85398e-5
Test1,2-Recover,101.303,1.38,0.828,0.038,,0.375,483.831,,37.5,0.483831,,,,7.85398e-5
Test1,2-Recover,101.637,1.395,0.813,0.038,,0.368207,483.831,,36.8207,0.483831,,,,7.85398e-5
Test1,2-Recover,101.970,1.41,0.798,0.038,,0.361413,483.831,,36.1413,0.483831,,,,7.85398e-5
Test1,2-Recover,102.303,1.425,0.783,0.038,,0.35462,483.831,,35.462,0.483831,,,,7.85398e-5
Test1,2-Recover,102.637,1.439,0.769,0.044,,0.348279,560.226,,34.8279,0.560226,,,,7.85398e-5
Test1,2-Recover,102.970,1.454,0.754,0.051,,0.341486,649.352,,34.1486,0.649352,,,,7.85398e-5
Test1,2-Recover,103.303,1.469,0.739,0.044,,0.334692,560.226,,33.4692,0.560226,,,,7.85398e-5
Test1,2-Recover,103.637,1.484,0.724,0.044,,0.327899,560.226,,32.7899,0.560226,,,,7.85398e-5
Test1,2-Recover,103.970,1.499,0.709,0.038,,0.321105,483.831,,32.1105,0.483831,,,,7.85398e-5
Test1,2-Recover,104.303,1.513,0.695,0.044,,0.314764,560.226,,31.4764,0.560226,,,,7.85398e-5
Test1,2-Recover,104.637,1.528,0.68,0.038,,0.307971,483.831,,30.7971,0.483831,,,,7.85398e-5
Test1,2-Recover,104.970,1.543,0.665,0.038,,0.301178,483.831,,30.1178,0.483831,,,,7.85398e-5
Test1,2-Recover,105.303,1.557,0.651,0.031,,0.294837,394.704,,29.4837,0.394704,,,,7.85398e-5
Test1,2-Recover,105.637,1.572,0.636,0.031,,0.288043,394.704,,28.8043,0.394704,,,,7.85398e-5
Test1,2-Recover,105.970,1.587,0.621,0.031,,0.28125,394.704,,28.125,0.394704,,,,7.85398e-5
Test1,2-Recover,106.303,1.601,0.607,0.031,,0.274909,394.704,,27.4909,0.394704,,,,7.85398e-5
Test1,2-Recover,106.637,1.616,0.592,0.031,,0.268116,394.704,,26.8116,0.394704,,,,7.85398e-5
Test1,2-Recover,106.970,1.631,0.577,0.031,,0.261322,394.704,,26.1322,0.394704,,,,7.85398e-5
Test1,2-Recover,107.303,1.646,0.562,0.031,,0.254529,394.704,,25.4529,0.394704,,,,7.85398e-5
Test1,2-Recover,107.637,1.661,0.547,0.031,,0.247736,394.704,,24.7736,0.394704,,,,7.85398e-5
Test1,2-Recover,107.970,1.675,0.533,0.031,,0.241395,394.704,,24.1395,0.394704,,,,7.85398e-5
Test1,2-Recover,108.303,1.69,0.518,0.031,,0.234601,394.704,,23.4601,0.394704,,,,7.85398e-5
Test1,2-Recover,108.637,1.705,0.503,0.031,,0.227808,394.704,,22.7808,0.394704,,,,7.85398e-5
Test1,2-Recover,108.970,1.72,0.488,0.031,,0.221014,394.704,,22.1014,0.394704,,,,7.85398e-5
Test1,2-Recover,109.303,1.734,0.474,0.031,,0.214674,394.704,,21.4674,0.394704,,,,7.85398e-5
Test1,2-Recover,109.637,1.749,0.459,0.031,,0.20788,394.704,,20.788,0.394704,,,,7.85398e-5
Test1,2-Recover,109.970,1.764,0.444,0.031,,0.201087,394.704,,20.1087,0.394704,,,,7.85398e-5
Test1,2-Recover,110.303,1.778,0.43,0.038,,0.194746,483.831,,19.4746,0.483831,,,,7.85398e-5
Test1,2-Recover,110.637,1.794,0.414,0.031,,0.1875,394.704,,18.75,0.394704,,,,7.85398e-5
Test1,2-Recover,110.970,1.808,0.4,0.038,,0.181159,483.831,,18.1159,0.483831,,,,7.85398e-5
Test1,2-Recover,111.303,1.823,0.385,0.031,,0.174366,394.704,,17.4366,0.394704,,,,7.85398e-5
Test1,2-Recover,111.637,1.838,0.37,0.044,,0.167572,560.226,,16.7572,0.560226,,,,7.85398e-5
Test1,2-Recover,111.970,1.852,0.356,0.024,,0.161232,305.578,,16.1232,0.305578,,,,7.85398e-5
Test1,2-Recover,112.303,1.867,0.341,0.024,,0.154438,305.578,,15.4438,0.305578,,,,7.85398e-5
Test1,2-Recover,112.637,1.882,0.326,0.031,,0.147645,394.704,,14.7645,0.394704,,,,7.85398e-5
Test1,2-Recover,112.970,1.897,0.311,0.031,,0.140851,394.704,,14.0851,0.394704,,,,7.85398e-5
Test1,2-Recover,113.303,1.911,0.297,0.031,,0.134511,394.704,,13.4511,0.394704,,,,7.85398e-5
Test1,2-Recover,113.637,1.926,0.282,0.024,,0.127717,305.578,,12.7717,0.305578,,,,7.85398e-5
Test1,2-Recover,113.970,1.941,0.267,0.004,,0.120924,50.9296,,12.0924,0.0509296,,,,7.85398e-5
Test1,2-Recover,114.303,1.955,0.253,0.017,,0.114583,216.451,,11.4583,0.216451,,,,7.85398e-5
Test1,2-Recover,114.637,1.97,0.238,-0.003,,0.10779,-38.1972,,10.779,-0.0381972,,,,7.85398e-5
Test1,2-Recover,114.970,1.985,0.223,0.004,,0.100996,50.9296,,10.0996,0.0509296,,,,7.85398e-5
Test1,2-Recover,115.303,1.999,0.209,-0.003,,0.0946558,-38.1972,,9.46558,-0.0381972,,,,7.85398e-5
Test1,2-Recover,115.637,2.015,0.193,-0.010,,0.0874094,-127.324,,8.74094,-0.127324,,,,7.85398e-5
Test1,2-Recover,115.970,2.029,0.179,-0.003,,0.0810688,-38.1972,,8.10688,-0.0381972,,,,7.85398e-5
Test1,2-Recover,116.303,2.044,0.164,-0.017,,0.0742754,-216.451,,7.42754,-0.216451,,,,7.85398e-5
Test1,2-Recover,116.637,2.059,0.149,-0.003,,0.0674819,-38.1972,,6.74819,-0.0381972,,,,7.85398e-5
Test1,2-Recover,116.970,2.073,0.135,-0.017,,0.0611413,-216.451,,6.11413,-0.216451,,,,7.85398e-5
Test1,2-Recover,117.303,2.088,0.12,-0.017,,0.0543478,-216.451,,5.43478,-0.216451,,,,7.85398e-5
Test1,2-Recover,117.637,2.103,0.105,-0.017,,0.0475543,-216.451,,4.75543,-0.216451,,,,7.85398e-5
Test1,2-Recover,117.970,2.118,0.09,-0.017,,0.0407609,-216.451,,4.07609,-0.216451,,,,7.85398e-5
Test1,2-Recover,118.303,2.132,0.076,-0.017,,0.0344203,-216.451,,3.44203,-0.216451,,,,7.85398e-5
Test1,2-Recover,118.637,2.147,0.061,-0.003,,0.0276268,-38.1972,,2.76268,-0.0381972,,,,7.85398e-5
Test1,2-Recover,118.970,2.162,0.046,0.011,,0.0208333,140.056,,2.08333,0.140056,,,,7.85398e-5
Test1,2-Recover,119.303,2.176,0.032,0.004,,0.0144928,50.9296,,1.44928,0.0509296,,,,7.85398e-5
Test1,2-Recover,119.637,2.192,0.016,-0.010,,0.00724638,-127.324,,0.724638,-0.127324,,,,7.85398e-5
Test1,2-Recover,119.970,2.206,0.002,-0.003,,0.000905797,-38.1972,,0.0905797,-0.0381972,,,,7.85398e-5
Test1,3-Compress,120.290,2.198,0.01,0.004,,0.00452899,50.9296,,0.452899,0.0509296,,,,7.85398e-5
Test1,3-Compress,120.623,2.184,0.024,-0.003,,0.0108696,-38.1972,,1.08696,-0.0381972,,,,7.85398e-5
Test1,3-Compress,120.957,2.168,0.04,-0.010,,0.0181159,-127.324,,1.81159,-0.127324,,,,7.85398e-5
Test1,3-Compress,121.290,2.154,0.054,0.004,,0.0244565,50.9296,,2.44565,0.0509296,,,,7.85398e-5
Test1,3-Compress,121.623,2.139,0.069,0.004,,0.03125,50.9296,,3.125,0.0509296,,,,7.85398e-5
Test1,3-Compress,121.957,2.124,0.084,0.004,,0.0380435,50.9296,,3.80435,0.0509296,,,,7.85398e-5
Test1,3-Compress,122.290,2.11,0.098,0.004,,0.0443841,50.9296,,4.43841,0.0509296,,,,7.85398e-5
Test1,3-Compress,122.623,2.095,0.113,0.004,,0.0511775,50.9296,,5.11775,0.0509296,,,,7.85398e-5
Test1,3-Compress,122.957,2.08,0.128,-0.003,,0.057971,-38.1972,,5.7971,-0.0381972,,,,7.85398e-5
Test1,3-Compress,123.290,2.065,0.143,-0.003,,0.0647645,-38.1972,,6.47645,-0.0381972,,,,7.85398e-5
Test1,3-Compress,123.623,2.051,0.157,-0.003,,0.0711051,-38.1972,,7.11051,-0.0381972,,,,7.85398e-5
Test1,3-Compress,123.957,2.036,0.172,-0.003,,0.0778986,-38.1972,,7.78986,-0.0381972,,,,7.85398e-5
Test1,3-Compress,124.290,2.021,0.187,0.011,,0.084692,140.056,,8.4692,0.140056,,,,7.85398e-5
Test1,3-Compress,124.623,2.007,0.201,-0.010,,0.0910326,-127.324,,9.10326,-0.127324,,,,7.85398e-5
Test1,3-Compress,124.957,1.992,0.216,0.024,,0.0978261,305.578,,9.78261,0.305578,,,,7.85398e-5
Test1,3-Compress,125.290,1.977,0.231,0.024,,0.10462,305.578,,10.462,0.305578,,,,7.85398e-5
Test1,3-Compress,125.623,1.963,0.245,0.011,,0.11096,140.056,,11.096,0.140056,,,,7.85398e-5
Test1,3-Compress,125.957,1.947,0.261,0.011,,0.118207,140.056,,11.8207,0.140056,,,,7.85398e-5
Test1,3-Compress,126.290,1.933,0.275,0.031,,0.124547,394.704,,12.4547,0.394704,,,,7.85398e-5
Test1,3-Compress,126.623,1.918,0.29,0.031,,0.131341,394.704,,13.1341,0.394704,,,,7.85398e-5
Test1,3-Compress,126.957,1.903,0.305,0.031,,0.138134,394.704,,13.8134,0.394704,,,,7.85398e-5
Test1,3-Compress,127.290,1.889,0.319,0.024,,0.144475,305.578,,14.4475,0.305578,,,,7.85398e-5
Test1,3-Compress,127.623,1.874,0.334,0.031,,0.151268,394.704,,15.1268,0.394704,,,,7.85398e-5
Test1,3-Compress,127.957,1.859,0.349,0.038,,0.158062,483.831,,15.8062,0.483831,,,,7.85398e-5
Test1,3-Compress,128.290,1.844,0.364,0.031,,0.164855,394.704,,16.4855,0.394704,,,,7.85398e-5
Test1,3-Compress,128.623,1.83,0.378,0.044,,0.171196,560.226,,17.1196,0.560226,,,,7.85398e-5
Test1,3-Compress,128.957,1.815,0.393,0.031,,0.177989,394.704,,17.7989,0.394704,,,,7.85398e-5
Test1,3-Compress,129.290,1.8,0.408,0.038,,0.184783,483.831,,18.4783,0.483831,,,,7.85398e-5
Test1,3-Compress,129.623,1.786,0.422,0.031,,0.191123,394.704,,19.1123,0.394704,,,,7.85398e-5
Test1,3-Compress,129.957,1.77,0.438,0.031,,0.19837,394.704,,19.837,0.394704,,,,7.85398e-5
Test1,3-Compress,130.290,1.756,0.452,0.031,,0.20471,394.704,,20.471,0.394704,,,,7.85398e-5
Test1,3-Compress,130.623,1.741,0.467,0.031,,0.211504,394.704,,21.1504,0.394704,,,,7.85398e-5
Test1,3-Compress,130.957,1.726,0.482,0.031,,0.218297,394.704,,21.8297,0.394704,,,,7.85398e-5
Test1,3-Compress,131.290,1.712,0.496,0.031,,0.224638,394.704,,22.4638,0.394704,,,,7.85398e-5
Test1,3-Compress,131.623,1.697,0.511,0.031,,0.231431,394.704,,23.1431,0.394704,,,,7.85398e-5
Test1,3-Compress,131.957,1.682,0.526,0.031,,0.238225,394.704,,23.8225,0.394704,,,,7.85398e-5
Test1,3-Compress,132.290,1.667,0.541,0.031,,0.245018,394.704,,24.5018,0.394704,,,,7.85398e-5
Test1,3-Compress,132.623,1.653,0.555,0.031,,0.251359,394.704,,25.1359,0.394704,,,,7.85398e-5
Test1,3-Compress,132.957,1.638,0.57,0.031,,0.258152,394.704,,25.8152,0.394704,,,,7.85398e-5
Test1,3-Compress,133.290,1.623,0.585,0.031,,0.264946,394.704,,26.4946,0.394704,,,,7.85398e-5
Test1,3-Compress,133.623,1.609,0.599,0.038,,0.271286,483.831,,27.1286,0.483831,,,,7.85398e-5
Test1,3-Compress,133.957,1.594,0.614,0.038,,0.27808,483.831,,27.808,0.483831,,,,7.85398e-5
Test1,3-Compress,134.290,1.579,0.629,0.038,,0.284873,483.831,,28.4873,0.483831,,,,7.85398e-5
Test1,3-Compress,134.623,1.565,0.643,0.038,,0.291214,483.831,,29.1214,0.483831,,,,7.85398e-5
Test1,3-Compress,134.957,1.549,0.659,0.044,,0.29846,560.226,,29.846,0.560226,,,,7.85398e-5
Test1,3-Compress,135.290,1.535,0.673,0.044,,0.304801,560.226,,30.4801,0.560226,,,,7.85398e-5
Test1,3-Compress,135.623,1.52,0.688,0.051,,0.311594,649.352,,31.1594,0.649352,,,,7.85398e-5
Test1,3-Compress,135.957,1.505,0.703,0.044,,0.318388,560.226,,31.8388,0.560226,,,,7.85398e-5
Test1,3-Compress,136.290,1.491,0.717,0.044,,0.324728,560.226,,32.4728,0.560226,,,,7.85398e-5
Test1,3-Compress,136.623,1.476,0.732,0.051,,0.331522,649.352,,33.1522,0.649352,,,,7.85398e-5
Test1,3-Compress,136.957,1.461,0.747,0.038,,0.338315,483.831,,33.8315,0.483831,,,,7.85398e-5
Test1,3-Compress,137.290,1.446,0.762,0.058,,0.345109,738.479,,34.5109,0.738479,,,,7.85398e-5
Test1,3-Compress,137.623,1.432,0.776,0.051,,0.351449,649.352,,35.1449,0.649352,,,,7.85398e-5
Test1,3-Compress,137.957,1.417,0.791,0.051,,0.358243,649.352,,35.8243,0.649352,,,,7.85398e-5
Test1,3-Compress,138.290,1.402,0.806,0.058,,0.365036,738.479,,36.5036,0.738479,,,,7.85398e-5
Test1,3-Compress,138.623,1.388,0.82,0.058,,0.371377,738.479,,37.1377,0.738479,,,,7.85398e-5
Test1,3-Compress,138.957,1.372,0.836,0.078,,0.378623,993.127,,37.8623,0.993127,,,,7.85398e-5
Test1,3-Compress,139.290,1.358,0.85,0.051,,0.384964,649.352,,38.4964,0.649352,,,,7.85398e-5
Test1,3-Compress,139.623,1.343,0.865,0.051,,0.391757,649.352,,39.1757,0.649352,,,,7.85398e-5
Test1,3-Compress,139.957,1.328,0.88,0.058,,0.398551,738.479,,39.8551,0.738479,,,,7.85398e-5
Test1,3-Compress,140.290,1.314,0.894,0.058,,0.404891,738.479,,40.4891,0.738479,,,,7.85398e-5
Test1,3-Compress,140.623,1.299,0.909,0.058,,0.411685,738.479,,41.1685,0.738479,,,,7.85398e-5
Test1,3-Compress,140.957,1.284,0.924,0.085,,0.418478,1082.25,,41.8478,1.08225,,,,7.85398e-5
Test1,3-Compress,141.290,1.27,0.938,0.078,,0.424819,993.127,,42.4819,0.993127,,,,7.85398e-5
Test1,3-Compress,141.623,1.255,0.953,0.072,,0.431612,916.733,,43.1612,0.916733,,,,7.85398e-5
Test1,3-Compress,141.957,1.24,0.968,0.065,,0.438406,827.606,,43.8406,0.827606,,,,7.85398e-5
Test1,3-Compress,142.290,1.225,0.983,0.078,,0.445199,993.127,,44.5199,0.993127,,,,7.85398e-5
Test1,3-Compress,142.623,1.211,0.997,0.085,,0.45154,1082.25,,45.154,1.08225,,,,7.85398e-5
Test1,3-Compress,142.957,1.196,1.012,0.078,,0.458333,993.127,,45.8333,0.993127,,,,7.85398e-5
Test1,3-Compress,143.290,1.181,1.027,0.085,,0.465127,1082.25,,46.5127,1.08225,,,,7.85398e-5
Test1,3-Compress,143.623,1.167,1.041,0.078,,0.471467,993.127,,47.1467,0.993127,,,,7.85398e-5
Test1,3-Compress,143.957,1.151,1.057,0.085,,0.478714,1082.25,,47.8714,1.08225,,,,7.85398e-5
Test1,3-Compress,144.290,1.137,1.071,0.085,,0.485054,1082.25,,48.5054,1.08225,,,,7.85398e-5
Test1,3-Compress,144.623,1.122,1.086,0.085,,0.491848,1082.25,,49.1848,1.08225,,,,7.85398e-5
Test1,3-Compress,144.957,1.107,1.101,0.085,,0.498641,1082.25,,49.8641,1.08225,,,,7.85398e-5
Test1,3-Compress,145.290,1.093,1.115,0.085,,0.504982,1082.25,,50.4982,1.08225,,,,7.85398e-5
Test1,3-Compress,145.623,1.078,1.13,0.085,,0.511775,1082.25,,51.1775,1.08225,,,,7.85398e-5
Test1,3-Compress,145.957,1.063,1.145,0.085,,0.518569,1082.25,,51.8569,1.08225,,,,7.85398e-5
Test1,3-Compress,146.290,1.048,1.16,0.085,,0.525362,1082.25,,52.5362,1.08225,,,,7.85398e-5
Test1,3-Compress,146.623,1.034,1.174,0.085,,0.531703,1082.25,,53.1703,1.08225,,,,7.85398e-5
Test1,3-Compress,146.957,1.019,1.189,0.085,,0.538496,1082.25,,53.8496,1.08225,,,,7.85398e-5
Test1,3-Compress,147.290,1.004,1.204,0.085,,0.54529,1082.25,,54.529,1.08225,,,,7.85398e-5
Test1,3-Compress,147.623,0.99,1.218,0.085,,0.55163,1082.25,,55.163,1.08225,,,,7.85398e-5
Test1,3-Compress,147.957,0.974,1.234,0.085,,0.558877,1082.25,,55.8877,1.08225,,,,7.85398e-5
Test1,3-Compress,148.290,0.96,1.248,0.085,,0.565217,1082.25,,56.5217,1.08225,,,,7.85398e-5
Test1,3-Compress,148.623,0.945,1.263,0.092,,0.572011,1171.38,,57.2011,1.17138,,,,7.85398e-5
Test1,3-Compress,148.957,0.93,1.278,0.085,,0.578804,1082.25,,57.8804,1.08225,,,,7.85398e-5
Test1,3-Compress,149.290,0.916,1.292,0.092,,0.585145,1171.38,,58.5145,1.17138,,,,7.85398e-5
Test1,3-Compress,149.623,0.901,1.307,0.092,,0.591938,1171.38,,59.1938,1.17138,,,,7.85398e-5
Test1,3-Compress,149.957,0.886,1.322,0.092,,0.598732,1171.38,,59.8732,1.17138,,,,7.85398e-5
Test1,3-Recover,150.267,0.891,1.317,0.092,,0.596467,1171.38,,59.6467,1.17138,,,,7.85398e-5
Test1,3-Recover,150.600,0.905,1.303,0.085,,0.590127,1082.25,,59.0127,1.08225,,,,7.85398e-5
Test1,3-Recover,150.933,0.92,1.288,0.085,,0.583333,1082.25,,58.3333,1.08225,,,,7.85398e-5
Test1,3-Recover,151.267,0.935,1.273,0.085,,0.57654,1082.25,,57.654,1.08225,,,,7.85398e-5
Test1,3-Recover,151.600,0.949,1.259,0.085,,0.570199,1082.25,,57.0199,1.08225,,,,7.85398e-5
Test1,3-Recover,151.933,0.964,1.244,0.092,,0.563406,1171.38,,56.3406,1.17138,,,,7.85398e-5
Test1,3-Recover,152.267,0.979,1.229,0.085,,0.556612,1082.25,,55.6612,1.08225,,,,7.85398e-5
Test1,3-Recover,152.600,0.994,1.214,0.085,,0.549819,1082.25,,54.9819,1.08225,,,,7.85398e-5
Test1,3-Recover,152.933,1.008,1.2,0.085,,0.543478,1082.25,,54.3478,1.08225,,,,7.85398e-5
Test1,3-Recover,153.267,1.023,1.185,0.085,,0.536685,1082.25,,53.6685,1.08225,,,,7.85398e-5
Test1,3-Recover,153.600,1.038,1.17,0.085,,0.529891,1082.25,,52.9891,1.08225,,,,7.85398e-5
Test1,3-Recover,153.933,1.052,1.156,0.085,,0.523551,1082.25,,52.3551,1.08225,,,,7.85398e-5
Test1,3-Recover,154.267,1.068,1.14,0.085,,0.516304,1082.25,,51.6304,1.08225,,,,7.85398e-5
Test1,3-Recover,154.600,1.082,1.126,0.085,,0.509964,1082.25,,50.9964,1.08225,,,,7.85398e-5
Test1,3-Recover,154.933,1.097,1.111,0.085,,0.50317,1082.25,,50.317,1.08225,,,,7.85398e-5
Test1,3-Recover,155.267,1.112,1.096,0.085,,0.496377,1082.25,,49.6377,1.08225,,,,7.85398e-5
Test1,3-Recover,155.600,1.126,1.082,0.085,,0.490036,1082.25,,49.0036,1.08225,,,,7.85398e-5
Test1,3-Recover,155.933,1.141,1.067,0.085,,0.483243,1082.25,,48.3243,1.08225,,,,7.85398e-5
Test1,3-Recover,156.267,1.156,1.052,0.085,,0.476449,1082.25,,47.6449,1.08225,,,,7.85398e-5
Test1,3-Recover,156.600,1.171,1.037,0.078,,0.469656,993.127,,46.9656,0.993127,,,,7.85398e-5
Test1,3-Recover,156.933,1.185,1.023,0.058,,0.463315,738.479,,46.3315,0.738479,,,,7.85398e-5
Test1,3-Recover,157.267,1.2,1.008,0.051,,0.456522,649.352,,45.6522,0.649352,,,,7.85398e-5
Test1,3-Recover,157.600,1.215,0.993,0.065,,0.449728,827.606,,44.9728,0.827606,,,,7.85398e-5
Test1,3-Recover,157.933,1.229,0.979,0.051,,0.443388,649.352,,44.3388,0.649352,,,,7.85398e-5
Test1,3-Recover,158.267,1.244,0.964,0.072,,0.436594,916.733,,43.6594,0.916733,,,,7.85398e-5
Test1,3-Recover,158.600,1.259,0.949,0.038,,0.429801,483.831,,42.9801,0.483831,,,,7.85398e-5
Test1,3-Recover,158.933,1.274,0.934,0.058,,0.423007,738.479,,42.3007,0.738479,,,,7.85398e-5
Test1,3-Recover,159.267,1.289,0.919,0.044,,0.416214,560.226,,41.6214,0.560226,,,,7.85398e-5
Test1,3-Recover,159.600,1.303,0.905,0.044,,0.409873,560.226,,40.9873,0.560226,,,,7.85398e-5
Test1,3-Recover,159.933,1.318,0.89,0.044,,0.40308,560.226,,40.308,0.560226,,,,7.85398e-5
Test1,3-Recover,160.267,1.333,0.875,0.044,,0.396286,560.226,,39.6286,0.560226,,,,7.85398e-5
Test1,3-Recover,160.600,1.347,0.861,0.051,,0.389946,649.352,,38.9946,0.649352,,,,7.85398e-5
Test1,3-Recover,160.933,1.362,0.846,0.058,,0.383152,738.479,,38.3152,0.738479,,,,7.85398e-5
Test1,3-Recover,161.267,1.377,0.831,0.038,,0.376359,483.831,,37.6359,0.483831,,,,7.85398e-5
Test1,3-Recover,161.600,1.392,0.816,0.038,,0.369565,483.831,,36.9565,0.483831,,,,7.85398e-5
Test1,3-Recover,161.933,1.406,0.802,0.044,,0.363225,560.226,,36.3225,0.560226,,,,7.85398e-5
Test1,3-Recover,162.267,1.421,0.787,0.038,,0.356431,483.831,,35.6431,0.483831,,,,7.85398e-5
Test1,3-Recover,162.600,1.436,0.772,0.031,,0.349638,394.704,,34.9638,0.394704,,,,7.85398e-5
Test1,3-Recover,162.933,1.451,0.757,0.031,,0.342844,394.704,,34.2844,0.394704,,,,7.85398e-5
Test1,3-Recover,163.267,1.466,0.742,0.038,,0.336051,483.831,,33.6051,0.483831,,,,7.85398e-5
Test1,3-Recover,163.600,1.48,0.728,0.031,,0.32971,394.704,,32.971,0.394704,,,,7.85398e-5
Test1,3-Recover,163.933,1.495,0.713,0.031,,0.322917,394.704,,32.2917,0.394704,,,,7.85398e-5
Test1,3-Recover,164.267,1.51,0.698,0.031,,0.316123,394.704,,31.6123,0.394704,,,,7.85398e-5
Test1,3-Recover,164.600,1.524,0.684,0.031,,0.309783,394.704,,30.9783,0.394704,,,,7.85398e-5
Test1,3-Recover,164.933,1.539,0.669,0.031,,0.302989,394.704,,30.2989,0.394704,,,,7.85398e-5
Test1,3-Recover,165.267,1.554,0.654,0.031,,0.296196,394.704,,29.6196,0.394704,,,,7.85398e-5
Test1,3-Recover,165.600,1.568,0.64,0.031,,0.289855,394.704,,28.9855,0.394704,,,,7.85398e-5
Test1,3-Recover,165.933,1.583,0.625,0.031,,0.283062,394.704,,28.3062,0.394704,,,,7.85398e-5
Test1,3-Recover,166.267,1.598,0.61,0.038,,0.276268,483.831,,27.6268,0.483831,,,,7.85398e-5
Test1,3-Recover,166.600,1.613,0.595,0.038,,0.269475,483.831,,26.9475,0.483831,,,,7.85398e-5
Test1,3-Recover,166.933,1.628,0.58,0.031,,0.262681,394.704,,26.2681,0.394704,,,,7.85398e-5
Test1,3-Recover,167.267,1.642,0.566,0.038,,0.256341,483.831,,25.6341,0.483831,,,,7.85398e-5
Test1,3-Recover,167.600,1.657,0.551,0.038,,0.249547,483.831,,24.9547,0.483831,,,,7.85398e-5
Test1,3-Recover,167.933,1.672,0.536,0.038,,0.242754,483.831,,24.2754,0.483831,,,,7.85398e-5
Test1,3-Recover,168.267,1.687,0.521,0.038,,0.23596,483.831,,23.596,0.483831,,,,7.85398e-5
Test1,3-Recover,168.600,1.701,0.507,0.038,,0.22962,483.831,,22.962,0.483831,,,,7.85398e-5
Test1,3-Recover,168.933,1.716,0.492,0.044,,0.222826,560.226,,22.2826,0.560226,,,,7.85398e-5
Test1,3-Recover,169.267,1.731,0.477,0.031,,0.216033,394.704,,21.6033,0.394704,,,,7.85398e-5
Test1,3-Recover,169.600,1.746,0.462,0.038,,0.209239,483.831,,20.9239,0.483831,,,,7.85398e-5
Test1,3-Recover,169.933,1.761,0.447,0.038,,0.202446,483.831,,20.2446,0.483831,,,,7.85398e-5
Test1,3-Recover,170.267,1.775,0.433,0.031,,0.196105,394.704,,19.6105,0.394704,,,,7.85398e-5
Test1,3-Recover,170.600,1.79,0.418,0.031,,0.189312,394.704,,18.9312,0.394704,,,,7.85398e-5
Test1,3-Recover,170.933,1.805,0.403,0.024,,0.182518,305.578,,18.2518,0.305578,,,,7.85398e-5
Test1,3-Recover,171.267,1.819,0.389,0.017,,0.176178,216.451,,17.6178,0.216451,,,,7.85398e-5
Test1,3-Recover,171.600,1.834,0.374,0.031,,0.169384,394.704,,16.9384,0.394704,,,,7.85398e-5
Test1,3-Recover,171.933,1.849,0.359,0.017,,0.162591,216.451,,16.2591,0.216451,,,,7.85398e-5
Test1,3-Recover,172.267,1.864,0.344,0.017,,0.155797,216.451,,15.5797,0.216451,,,,7.85398e-5
Test1,3-Recover,172.600,1.878,0.33,0.031,,0.149457,394.704,,14.9457,0.394704,,,,7.85398e-5
Test1,3-Recover,172.933,1.893,0.315,-0.003,,0.142663,-38.1972,,14.2663,-0.0381972,,,,7.85398e-5
Test1,3-Recover,173.267,1.908,0.3,0.004,,0.13587,50.9296,,13.587,0.0509296,,,,7.85398e-5
Test1,3-Recover,173.600,1.923,0.285,0.004,,0.129076,50.9296,,12.9076,0.0509296,,,,7.85398e-5
Test1,3-Recover,173.933,1.937,0.271,-0.010,,0.122736,-127.324,,12.2736,-0.127324,,,,7.85398e-5
Test1,3-Recover,174.267,1.952,0.256,0.011,,0.115942,140.056,,11.5942,0.140056,,,,7.85398e-5
Test1,3-Recover,174.600,1.967,0.241,-0.017,,0.109149,-216.451,,10.9149,-0.216451,,,,7.85398e-5
Test1,3-Recover,174.933,1.982,0.226,-0.010,,0.102355,-127.324,,10.2355,-0.127324,,,,7.85398e-5
Test1,3-Recover,175.267,1.996,0.212,-0.003,,0.0960145,-38.1972,,9.60145,-0.0381972,,,,7.85398e-5
Test1,3-Recover,175.600,2.011,0.197,-0.003,,0.089221,-38.1972,,8.9221,-0.0381972,,,,7.85398e-5
Test1,3-Recover,175.933,2.026,0.182,-0.003,,0.0824275,-38.1972,,8.24275,-0.0381972,,,,7.85398e-5
Test1,3-Recover,176.267,2.041,0.167,-0.003,,0.0756341,-38.1972,,7.56341,-0.0381972,,,,7.85398e-5
Test1,3-Recover,176.600,2.056,0.152,0.004,,0.0688406,50.9296,,6.88406,0.0509296,,,,7.85398e-5
Test1,3-Recover,176.933,2.07,0.138,0.004,,0.0625,50.9296,,6.25,0.0509296,,,,7.85398e-5
Test1,3-Recover,177.267,2.085,0.123,0.004,,0.0557065,50.9296,,5.57065,0.0509296,,,,7.85398e-5
Test1,3-Recover,177.600,2.1,0.108,-0.003,,0.048913,-38.1972,,4.8913,-0.0381972,,,,7.85398e-5
Test1,3-Recover,177.933,2.114,0.094,0.004,,0.0425725,50.9296,,4.25725,0.0509296,,,,7.85398e-5
Test1,3-Recover,178.267,2.129,0.079,0.004,,0.035779,50.9296,,3.5779,0.0509296,,,,7.85398e-5
Test1,3-Recover,178.600,2.144,0.064,-0.010,,0.0289855,-127.324,,2.89855,-0.127324,,,,7.85398e-5
Test1,3-Recover,178.933,2.159,0.049,-0.003,,0.022192,-38.1972,,2.2192,-0.0381972,,,,7.85398e-5
Test1,3-Recover,179.267,2.173,0.035,0.011,,0.0158514,140.056,,1.58514,0.140056,,,,7.85398e-5
Test1,3-Recover,179.600,2.188,0.02,-0.017,,0.00905797,-216.451,,0.905797,-0.216451,,,,7.85398e-5
Test1,3-Recover,179.933,2.203,0.005,-0.003,,0.00226449,-38.1972,,0.226449,-0.0381972,,,,7.85398e-5
Test1,3-Recover,180.100,2.208,-0,-0.003,,0,-38.1972,,0,-0.0381972,,,,7.85398e-5