File: data/beta_1-1-0_0.csv
SetName,Cycle,Time_S,Size_mm,Displacement_mm,Force_N,,Strain,Stress(Pascal),,%Strain,Stress(kPa),,,,Area(m^2)
1:0 (rep 1),1-Compress,0,3.074,0,-0.004,,0,-50.9296,,0,-0.0509296,,,,7.85398e-5
1:0 (rep 1),1-Compress,0.367,3.052,0.022,0.009,,0.0071568,114.592,,0.71568,0.114592,,,,7.85398e-5
1:0 (rep 1),1-Compress,0.733,3.03,0.044,-0.004,,0.0143136,-50.9296,,1.43136,-0.0509296,,,,7.85398e-5
1:0 (rep 1),1-Compress,1.1,3.007,0.067,0.002,,0.0217957,25.4648,,2.17957,0.0254648,,,,7.85398e-5
1:0 (rep 1),1-Compress,1.467,2.984,0.09,0.002,,0.0292778,25.4648,,2.92778,0.0254648,,,,7.85398e-5
1:0 (rep 1),1-Compress,1.833,2.962,0.112,0.002,,0.0364346,25.4648,,3.64346,0.0254648,,,,7.85398e-5
1:0 (rep 1),1-Compress,2.2,2.939,0.135,0.009,,0.0439167,114.592,,4.39167,0.114592,,,,7.85398e-5
1:0 (rep 1),1-Compress,2.567,2.916,0.158,0.016,,0.0513988,203.718,,5.13988,0.203718,,,,7.85398e-5
1:0 (rep 1),1-Compress,2.933,2.894,0.18,0.002,,0.0585556,25.4648,,5.85556,0.0254648,,,,7.85398e-5
1:0 (rep 1),1-Compress,3.3,2.871,0.203,0.002,,0.0660377,25.4648,,6.60377,0.0254648,,,,7.85398e-5
1:0 (rep 1),1-Compress,3.667,2.849,0.225,0.002,,0.0731945,25.4648,,7.31945,0.0254648,,,,7.85398e-5
1:0 (rep 1),1-Compress,4.033,2.826,0.248,0.002,,0.0806766,25.4648,,8.06766,0.0254648,,,,7.85398e-5
1:0 (rep 1),1-Compress,4.4,2.804,0.27,0.002,,0.0878334,25.4648,,8.78334,0.0254648,,,,7.85398e-5
1:0 (rep 1),1-Compress,4.767,2.781,0.293,0.023,,0.0953155,292.845,,9.53155,0.292845,,,,7.85398e-5
1:0 (rep 1),1-Compress,5.133,2.759,0.315,0.023,,0.102472,292.845,,10.2472,0.292845,,,,7.85398e-5
1:0 (rep 1),1-Compress,5.5,2.736,0.338,0.043,,0.109954,547.493,,10.9954,0.547493,,,,7.85398e-5
1:0 (rep 1),1-Compress,5.867,2.713,0.361,0.036,,0.117437,458.366,,11.7437,0.458366,,,,7.85398e-5
1:0 (rep 1),1-Compress,6.233,2.691,0.383,0.05,,0.124593,636.62,,12.4593,0.63662,,,,7.85398e-5
1:0 (rep 1),1-Compress,6.6,2.668,0.406,0.036,,0.132075,458.366,,13.2075,0.458366,,,,7.85398e-5
1:0 (rep 1),1-Compress,6.967,2.646,0.428,0.023,,0.139232,292.845,,13.9232,0.292845,,,,7.85398e-5
1:0 (rep 1),1-Compress,7.333,2.623,0.451,0.043,,0.146714,547.493,,14.6714,0.547493,,,,7.85398e-5
1:0 (rep 1),1-Compress,7.7,2.601,0.473,0.05,,0.153871,636.62,,15.3871,0.63662,,,,7.85398e-5
1:0 (rep 1),1-Compress,8.067,2.578,0.496,0.05,,0.161353,636.62,,16.1353,0.63662,,,,7.85398e-5
1:0 (rep 1),1-Compress,8.433,2.556,0.518,0.05,,0.16851,636.62,,16.851,0.63662,,,,7.85398e-5
1:0 (rep 1),1-Compress,8.8,2.533,0.541,0.05,,0.175992,636.62,,17.5992,0.63662,,,,7.85398e-5
1:0 (rep 1),1-Compress,9.167,2.51,0.564,0.05,,0.183474,636.62,,18.3474,0.63662,,,,7.85398e-5
1:0 (rep 1),1-Compress,9.533,2.488,0.586,0.05,,0.190631,636.62,,19.0631,0.63662,,,,7.85398e-5
1:0 (rep 1),1-Compress,9.9,2.465,0.609,0.05,,0.198113,636.62,,19.8113,0.63662,,,,7.85398e-5
1:0 (rep 1),1-Compress,10.267,2.442,0.632,0.05,,0.205595,636.62,,20.5595,0.63662,,,,7.85398e-5
1:0 (rep 1),1-Compress,10.633,2.421,0.653,0.05,,0.212427,636.62,,21.2427,0.63662,,,,7.85398e-5
1:0 (rep 1),1-Compress,11,2.397,0.677,0.05,,0.220234,636.62,,22.0234,0.63662,,,,7.85398e-5
1:0 (rep 1),1-Compress,11.367,2.375,0.699,0.057,,0.227391,725.747,,22.7391,0.725747,,,,7.85398e-5
1:0 (rep 1),1-Compress,11.733,2.353,0.721,0.05,,0.234548,636.62,,23.4548,0.63662,,,,7.85398e-5
1:0 (rep 1),1-Compress,12.1,2.33,0.744,0.05,,0.24203,636.62,,24.203,0.63662,,,,7.85398e-5
1:0 (rep 1),1-Compress,12.467,2.307,0.767,0.064,,0.249512,814.873,,24.9512,0.814873,,,,7.85398e-5
1:0 (rep 1),1-Compress,12.833,2.285,0.789,0.07,,0.256669,891.268,,25.6669,0.891268,,,,7.85398e-5
1:0 (rep 1),1-Compress,13.2,2.262,0.812,0.077,,0.264151,980.395,,26.4151,0.980395,,,,7.85398e-5
1:0 (rep 1),1-Compress,13.567,2.239,0.835,0.084,,0.271633,1069.52,,27.1633,1.06952,,,,7.85398e-5
1:0 (rep 1),1-Compress,13.933,2.217,0.857,0.07,,0.27879,891.268,,27.879,0.891268,,,,7.85398e-5
1:0 (rep 1),1-Compress,14.3,2.194,0.88,0.084,,0.286272,1069.52,,28.6272,1.06952,,,,7.85398e-5
1:0 (rep 1),1-Compress,14.667,2.172,0.902,0.091,,0.293429,1158.65,,29.3429,1.15865,,,,7.85398e-5
1:0 (rep 1),1-Compress,15.033,2.149,0.925,0.091,,0.300911,1158.65,,30.0911,1.15865,,,,7.85398e-5
1:0 (rep 1),1-Compress,15.4,2.127,0.947,0.104,,0.308068,1324.17,,30.8068,1.32417,,,,7.85398e-5
1:0 (rep 1),1-Compress,15.767,2.104,0.97,0.104,,0.31555,1324.17,,31.555,1.32417,,,,7.85398e-5
1:0 (rep 1),1-Compress,16.133,2.082,0.992,0.104,,0.322707,1324.17,,32.2707,1.32417,,,,7.85398e-5
1:0 (rep 1),1-Compress,16.5,2.059,1.015,0.104,,0.330189,1324.17,,33.0189,1.32417,,,,7.85398e-5
1:0 (rep 1),1-Compress,16.867,2.036,1.038,0.104,,0.337671,1324.17,,33.7671,1.32417,,,,7.85398e-5
1:0 (rep 1),1-Compress,17.233,2.014,1.06,0.104,,0.344828,1324.17,,34.4828,1.32417,,,,7.85398e-5
1:0 (rep 1),1-Compress,17.6,1.992,1.082,0.104,,0.351984,1324.17,,35.1984,1.32417,,,,7.85398e-5
1:0 (rep 1),1-Compress,17.967,1.968,1.106,0.104,,0.359792,1324.17,,35.9792,1.32417,,,,7.85398e-5
1:0 (rep 1),1-Compress,18.333,1.946,1.128,0.104,,0.366949,1324.17,,36.6949,1.32417,,,,7.85398e-5
1:0 (rep 1),1-Compress,18.7,1.924,1.15,0.118,,0.374105,1502.42,,37.4105,1.50242,,,,7.85398e-5
1:0 (rep 1),1-Compress,19.067,1.901,1.173,0.111,,0.381588,1413.3,,38.1588,1.4133,,,,7.85398e-5
1:0 (rep 1),1-Compress,19.433,1.879,1.195,0.111,,0.388744,1413.3,,38.8744,1.4133,,,,7.85398e-5
1:0 (rep 1),1-Compress,19.8,1.856,1.218,0.118,,0.396226,1502.42,,39.6226,1.50242,,,,7.85398e-5
1:0 (rep 1),1-Compress,20.167,1.833,1.241,0.131,,0.403709,1667.94,,40.3709,1.66794,,,,7.85398e-5
1:0 (rep 1),1-Compress,20.533,1.811,1.263,0.159,,0.410865,2024.45,,41.0865,2.02445,,,,7.85398e-5
1:0 (rep 1),1-Compress,20.9,1.788,1.286,0.145,,0.418347,1846.2,,41.8347,1.8462,,,,7.85398e-5
1:0 (rep 1),1-Compress,21.267,1.765,1.309,0.159,,0.42583,2024.45,,42.583,2.02445,,,,7.85398e-5
1:0 (rep 1),1-Compress,21.633,1.743,1.331,0.159,,0.432986,2024.45,,43.2986,2.02445,,,,7.85398e-5
1:0 (rep 1),1-Compress,22,1.72,1.354,0.159,,0.440468,2024.45,,44.0468,2.02445,,,,7.85398e-5
1:0 (rep 1),1-Compress,22.367,1.698,1.376,0.159,,0.447625,2024.45,,44.7625,2.02445,,,,7.85398e-5
1:0 (rep 1),1-Compress,22.733,1.675,1.399,0.152,,0.455107,1935.32,,45.5107,1.93532,,,,7.85398e-5
1:0 (rep 1),1-Compress,23.1,1.653,1.421,0.145,,0.462264,1846.2,,46.2264,1.8462,,,,7.85398e-5
1:0 (rep 1),1-Compress,23.467,1.63,1.444,0.152,,0.469746,1935.32,,46.9746,1.93532,,,,7.85398e-5
1:0 (rep 1),1-Compress,23.833,1.608,1.466,0.152,,0.476903,1935.32,,47.6903,1.93532,,,,7.85398e-5
1:0 (rep 1),1-Compress,24.2,1.585,1.489,0.159,,0.484385,2024.45,,48.4385,2.02445,,,,7.85398e-5
1:0 (rep 1),1-Compress,24.567,1.563,1.511,0.159,,0.491542,2024.45,,49.1542,2.02445,,,,7.85398e-5
1:0 (rep 1),1-Compress,24.933,1.54,1.534,0.165,,0.499024,2100.85,,49.9024,2.10085,,,,7.85398e-5
1:0 (rep 1),1-Compress,25.3,1.517,1.557,0.186,,0.506506,2368.23,,50.6506,2.36823,,,,7.85398e-5
1:0 (rep 1),1-Compress,25.667,1.495,1.579,0.186,,0.513663,2368.23,,51.3663,2.36823,,,,7.85398e-5
1:0 (rep 1),1-Compress,26.033,1.472,1.602,0.193,,0.521145,2457.35,,52.1145,2.45735,,,,7.85398e-5
1:0 (rep 1),1-Compress,26.4,1.45,1.624,0.206,,0.528302,2622.87,,52.8302,2.62287,,,,7.85398e-5
1:0 (rep 1),1-Compress,26.767,1.427,1.647,0.213,,0.535784,2712,,53.5784,2.712,,,,7.85398e-5
1:0 (rep 1),1-Compress,27.133,1.405,1.669,0.213,,0.542941,2712,,54.2941,2.712,,,,7.85398e-5
1:0 (rep 1),1-Compress,27.5,1.382,1.692,0.213,,0.550423,2712,,55.0423,2.712,,,,7.85398e-5
1:0 (rep 1),1-Compress,27.867,1.359,1.715,0.206,,0.557905,2622.87,,55.7905,2.62287,,,,7.85398e-5
1:0 (rep 1),1-Compress,28.233,1.337,1.737,0.22,,0.565062,2801.13,,56.5062,2.80113,,,,7.85398e-5
1:0 (rep 1),1-Compress,28.6,1.314,1.76,0.227,,0.572544,2890.25,,57.2544,2.89025,,,,7.85398e-5
1:0 (rep 1),1-Compress,28.967,1.291,1.783,0.24,,0.580026,3055.78,,58.0026,3.05578,,,,7.85398e-5
1:0 (rep 1),1-Compress,29.333,1.27,1.804,0.227,,0.586858,2890.25,,58.6858,2.89025,,,,7.85398e-5
1:0 (rep 1),1-Compress,29.7,1.246,1.828,0.22,,0.594665,2801.13,,59.4665,2.80113,,,,7.85398e-5
1:0 (rep 1),1-Recover,30.067,1.234,1.84,0.233,,0.598569,2966.65,,59.8569,2.96665,,,,7.85398e-5
1:0 (rep 1),1-Recover,30.433,1.255,1.819,0.22,,0.591737,2801.13,,59.1737,2.80113,,,,7.85398e-5
1:0 (rep 1),1-Recover,30.8,1.278,1.796,0.233,,0.584255,2966.65,,58.4255,2.96665,,,,7.85398e-5
1:0 (rep 1),1-Recover,31.167,1.301,1.773,0.233,,0.576773,2966.65,,57.6773,2.96665,,,,7.85398e-5
1:0 (rep 1),1-Recover,31.533,1.323,1.751,0.213,,0.569616,2712,,56.9616,2.712,,,,7.85398e-5
1:0 (rep 1),1-Recover,31.9,1.346,1.728,0.213,,0.562134,2712,,56.2134,2.712,,,,7.85398e-5
1:0 (rep 1),1-Recover,32.267,1.369,1.705,0.213,,0.554652,2712,,55.4652,2.712,,,,7.85398e-5
1:0 (rep 1),1-Recover,32.633,1.391,1.683,0.199,,0.547495,2533.75,,54.7495,2.53375,,,,7.85398e-5
1:0 (rep 1),1-Recover,33,1.414,1.66,0.193,,0.540013,2457.35,,54.0013,2.45735,,,,7.85398e-5
1:0 (rep 1),1-Recover,33.367,1.436,1.638,0.193,,0.532856,2457.35,,53.2856,2.45735,,,,7.85398e-5
1:0 (rep 1),1-Recover,33.733,1.459,1.615,0.172,,0.525374,2189.97,,52.5374,2.18997,,,,7.85398e-5
1:0 (rep 1),1-Recover,34.1,1.481,1.593,0.179,,0.518217,2279.1,,51.8217,2.2791,,,,7.85398e-5
1:0 (rep 1),1-Recover,34.467,1.504,1.57,0.159,,0.510735,2024.45,,51.0735,2.02445,,,,7.85398e-5
1:0 (rep 1),1-Recover,34.833,1.526,1.548,0.159,,0.503578,2024.45,,50.3578,2.02445,,,,7.85398e-5
1:0 (rep 1),1-Recover,35.2,1.549,1.525,0.159,,0.496096,2024.45,,49.6096,2.02445,,,,7.85398e-5
1:0 (rep 1),1-Recover,35.567,1.572,1.502,0.152,,0.488614,1935.32,,48.8614,1.93532,,,,7.85398e-5
1:0 (rep 1),1-Recover,35.933,1.594,1.48,0.159,,0.481457,2024.45,,48.1457,2.02445,,,,7.85398e-5
1:0 (rep 1),1-Recover,36.3,1.617,1.457,0.159,,0.473975,2024.45,,47.3975,2.02445,,,,7.85398e-5
1:0 (rep 1),1-Recover,36.667,1.639,1.435,0.159,,0.466818,2024.45,,46.6818,2.02445,,,,7.85398e-5
1:0 (rep 1),1-Recover,37.033,1.662,1.412,0.159,,0.459336,2024.45,,45.9336,2.02445,,,,7.85398e-5
1:0 (rep 1),1-Recover,37.4,1.684,1.39,0.159,,0.45218,2024.45,,45.218,2.02445,,,,7.85398e-5
1:0 (rep 1),1-Recover,37.767,1.707,1.367,0.145,,0.444697,1846.2,,44.4697,1.8462,,,,7.85398e-5
1:0 (rep 1),1-Recover,38.133,1.729,1.345,0.145,,0.437541,1846.2,,43.7541,1.8462,,,,7.85398e-5
1:0 (rep 1),1-Recover,38.5,1.752,1.322,0.125,,0.430059,1591.55,,43.0059,1.59155,,,,7.85398e-5
1:0 (rep 1),1-Recover,38.867,1.775,1.299,0.118,,0.422576,1502.42,,42.2576,1.50242,,,,7.85398e-5
1:0 (rep 1),1-Recover,39.233,1.797,1.277,0.111,,0.41542,1413.3,,41.542,1.4133,,,,7.85398e-5
1:0 (rep 1),1-Recover,39.6,1.82,1.254,0.104,,0.407938,1324.17,,40.7938,1.32417,,,,7.85398e-5
1:0 (rep 1),1-Recover,39.967,1.843,1.231,0.104,,0.400455,1324.17,,40.0455,1.32417,,,,7.85398e-5
1:0 (rep 1),1-Recover,40.333,1.865,1.209,0.104,,0.393299,1324.17,,39.3299,1.32417,,,,7.85398e-5
1:0 (rep 1),1-Recover,40.7,1.888,1.186,0.104,,0.385817,1324.17,,38.5817,1.32417,,,,7.85398e-5
1:0 (rep 1),1-Recover,41.067,1.91,1.164,0.104,,0.37866,1324.17,,37.866,1.32417,,,,7.85398e-5
1:0 (rep 1),1-Recover,41.433,1.932,1.142,0.104,,0.371503,1324.17,,37.1503,1.32417,,,,7.85398e-5
1:0 (rep 1),1-Recover,41.8,1.955,1.119,0.104,,0.364021,1324.17,,36.4021,1.32417,,,,7.85398e-5
1:0 (rep 1),1-Recover,42.167,1.978,1.096,0.098,,0.356539,1247.78,,35.6539,1.24778,,,,7.85398e-5
1:0 (rep 1),1-Recover,42.533,2,1.074,0.104,,0.349382,1324.17,,34.9382,1.32417,,,,7.85398e-5
1:0 (rep 1),1-Recover,42.9,2.023,1.051,0.104,,0.3419,1324.17,,34.19,1.32417,,,,7.85398e-5
1:0 (rep 1),1-Recover,43.267,2.046,1.028,0.098,,0.334418,1247.78,,33.4418,1.24778,,,,7.85398e-5
1:0 (rep 1),1-Recover,43.633,2.068,1.006,0.098,,0.327261,1247.78,,32.7261,1.24778,,,,7.85398e-5
1:0 (rep 1),1-Recover,44,2.091,0.983,0.064,,0.319779,814.873,,31.9779,0.814873,,,,7.85398e-5
1:0 (rep 1),1-Recover,44.367,2.113,0.961,0.07,,0.312622,891.268,,31.2622,0.891268,,,,7.85398e-5
1:0 (rep 1),1-Recover,44.733,2.136,0.938,0.057,,0.30514,725.747,,30.514,0.725747,,,,7.85398e-5
1:0 (rep 1),1-Recover,45.1,2.158,0.916,0.057,,0.297983,725.747,,29.7983,0.725747,,,,7.85398e-5
1:0 (rep 1),1-Recover,45.467,2.181,0.893,0.07,,0.290501,891.268,,29.0501,0.891268,,,,7.85398e-5
1:0 (rep 1),1-Recover,45.833,2.203,0.871,0.05,,0.283344,636.62,,28.3344,0.63662,,,,7.85398e-5
1:0 (rep 1),1-Recover,46.2,2.226,0.848,0.064,,0.275862,814.873,,27.5862,0.814873,,,,7.85398e-5
1:0 (rep 1),1-Recover,46.567,2.249,0.825,0.057,,0.26838,725.747,,26.838,0.725747,,,,7.85398e-5
1:0 (rep 1),1-Recover,46.933,2.271,0.803,0.057,,0.261223,725.747,,26.1223,0.725747,,,,7.85398e-5
1:0 (rep 1),1-Recover,47.3,2.294,0.78,0.05,,0.253741,636.62,,25.3741,0.63662,,,,7.85398e-5
1:0 (rep 1),1-Recover,47.667,2.317,0.757,0.05,,0.246259,636.62,,24.6259,0.63662,,,,7.85398e-5
1:0 (rep 1),1-Recover,48.033,2.339,0.735,0.05,,0.239102,636.62,,23.9102,0.63662,,,,7.85398e-5
1:0 (rep 1),1-Recover,48.4,2.361,0.713,0.05,,0.231945,636.62,,23.1945,0.63662,,,,7.85398e-5
1:0 (rep 1),1-Recover,48.767,2.384,0.69,0.05,,0.224463,636.62,,22.4463,0.63662,,,,7.85398e-5
1:0 (rep 1),1-Recover,49.133,2.406,0.668,0.05,,0.217306,636.62,,21.7306,0.63662,,,,7.85398e-5
1:0 (rep 1),1-Recover,49.5,2.429,0.645,0.05,,0.209824,636.62,,20.9824,0.63662,,,,7.85398e-5
1:0 (rep 1),1-Recover,49.867,2.452,0.622,0.05,,0.202342,636.62,,20.2342,0.63662,,,,7.85398e-5
1:0 (rep 1),1-Recover,50.233,2.474,0.6,0.05,,0.195185,636.62,,19.5185,0.63662,,,,7.85398e-5
1:0 (rep 1),1-Recover,50.6,2.497,0.577,0.05,,0.187703,636.62,,18.7703,0.63662,,,,7.85398e-5
1:0 (rep 1),1-Recover,50.967,2.52,0.554,0.05,,0.180221,636.62,,18.0221,0.63662,,,,7.85398e-5
1:0 (rep 1),1-Recover,51.333,2.542,0.532,0.036,,0.173064,458.366,,17.3064,0.458366,,,,7.85398e-5
1:0 (rep 1),1-Recover,51.7,2.565,0.509,0.043,,0.165582,547.493,,16.5582,0.547493,,,,7.85398e-5
1:0 (rep 1),1-Recover,52.067,2.587,0.487,0.05,,0.158426,636.62,,15.8426,0.63662,,,,7.85398e-5
1:0 (rep 1),1-Recover,52.433,2.61,0.464,0.009,,0.150943,114.592,,15.0943,0.114592,,,,7.85398e-5
1:0 (rep 1),1-Recover,52.8,2.632,0.442,0.043,,0.143787,547.493,,14.3787,0.547493,,,,7.85398e-5
1:0 (rep 1),1-Recover,53.167,2.655,0.419,0.036,,0.136304,458.366,,13.6304,0.458366,,,,7.85398e-5
1:0 (rep 1),1-Recover,53.533,2.677,0.397,0.023,,0.129148,292.845,,12.9148,0.292845,,,,7.85398e-5
1:0 (rep 1),1-Recover,53.9,2.7,0.374,0.016,,0.121666,203.718,,12.1666,0.203718,,,,7.85398e-5
1:0 (rep 1),1-Recover,54.267,2.723,0.351,0.002,,0.114183,25.4648,,11.4183,0.0254648,,,,7.85398e-5
1:0 (rep 1),1-Recover,54.633,2.745,0.329,0.002,,0.107027,25.4648,,10.7027,0.0254648,,,,7.85398e-5
1:0 (rep 1),1-Recover,55,2.768,0.306,0.009,,0.0995446,114.592,,9.95446,0.114592,,,,7.85398e-5
1:0 (rep 1),1-Recover,55.367,2.79,0.284,0.009,,0.0923878,114.592,,9.23878,0.114592,,,,7.85398e-5
1:0 (rep 1),1-Recover,55.733,2.813,0.261,0.016,,0.0849057,203.718,,8.49057,0.203718,,,,7.85398e-5
1:0 (rep 1),1-Recover,56.1,2.835,0.239,0.002,,0.0777489,25.4648,,7.77489,0.0254648,,,,7.85398e-5
1:0 (rep 1),1-Recover,56.467,2.858,0.216,0.002,,0.0702668,25.4648,,7.02668,0.0254648,,,,7.85398e-5
1:0 (rep 1),1-Recover,56.833,2.88,0.194,0.002,,0.06311,25.4648,,6.311,0.0254648,,,,7.85398e-5
1:0 (rep 1),1-Recover,57.2,2.903,0.171,0.002,,0.0556278,25.4648,,5.56278,0.0254648,,,,7.85398e-5
1:0 (rep 1),1-Recover,57.567,2.926,0.148,0.009,,0.0481457,114.592,,4.81457,0.114592,,,,7.85398e-5
1:0 (rep 1),1-Recover,57.933,2.948,0.126,0.002,,0.0409889,25.4648,,4.09889,0.0254648,,,,7.85398e-5
1:0 (rep 1),1-Recover,58.3,2.971,0.103,0.002,,0.0335068,25.4648,,3.35068,0.0254648,,,,7.85398e-5
1:0 (rep 1),1-Recover,58.667,2.994,0.08,0.002,,0.0260247,25.4648,,2.60247,0.0254648,,,,7.85398e-5
1:0 (rep 1),1-Recover,59.033,3.016,0.058,-0.004,,0.0188679,-50.9296,,1.88679,-0.0509296,,,,7.85398e-5
1:0 (rep 1),1-Recover,59.4,3.039,0.035,-0.004,,0.0113858,-50.9296,,1.13858,-0.0509296,,,,7.85398e-5
1:0 (rep 1),1-Recover,59.767,3.061,0.013,0.002,,0.00422902,25.4648,,0.422902,0.0254648,,,,7.85398e-5
1:0 (rep 1),2-Compress,60.117,3.069,0.005,0.009,,0.00162655,114.592,,0.162655,0.114592,,,,7.85398e-5
1:0 (rep 1),2-Compress,60.483,3.047,0.027,0.009,,0.00878334,114.592,,0.878334,0.114592,,,,7.85398e-5
1:0 (rep 1),2-Compress,60.85,3.024,0.05,0.002,,0.0162655,25.4648,,1.62655,0.0254648,,,,7.85398e-5
1:0 (rep 1),2-Compress,61.217,3.002,0.072,0.002,,0.0234223,25.4648,,2.34223,0.0254648,,,,7.85398e-5
1:0 (rep 1),2-Compress,61.583,2.979,0.095,0.002,,0.0309044,25.4648,,3.09044,0.0254648,,,,7.85398e-5
1:0 (rep 1),2-Compress,61.95,2.957,0.117,0.002,,0.0380612,25.4648,,3.80612,0.0254648,,,,7.85398e-5
1:0 (rep 1),2-Compress,62.317,2.934,0.14,0.002,,0.0455433,25.4648,,4.55433,0.0254648,,,,7.85398e-5
1:0 (rep 1),2-Compress,62.683,2.912,0.162,0.002,,0.0527001,25.4648,,5.27001,0.0254648,,,,7.85398e-5
1:0 (rep 1),2-Compress,63.05,2.889,0.185,0.023,,0.0601822,292.845,,6.01822,0.292845,,,,7.85398e-5
1:0 (rep 1),2-Compress,63.417,2.866,0.208,0.002,,0.0676643,25.4648,,6.76643,0.0254648,,,,7.85398e-5
1:0 (rep 1),2-Compress,63.783,2.844,0.23,0.023,,0.0748211,292.845,,7.48211,0.292845,,,,7.85398e-5
1:0 (rep 1),2-Compress,64.15,2.821,0.253,0.009,,0.0823032,114.592,,8.23032,0.114592,,,,7.85398e-5
1:0 (rep 1),2-Compress,64.517,2.798,0.276,0.002,,0.0897853,25.4648,,8.97853,0.0254648,,,,7.85398e-5
1:0 (rep 1),2-Compress,64.883,2.776,0.298,0.009,,0.0969421,114.592,,9.69421,0.114592,,,,7.85398e-5
1:0 (rep 1),2-Compress,65.25,2.754,0.32,0.016,,0.104099,203.718,,10.4099,0.203718,,,,7.85398e-5
1:0 (rep 1),2-Compress,65.617,2.731,0.343,0.036,,0.111581,458.366,,11.1581,0.458366,,,,7.85398e-5
1:0 (rep 1),2-Compress,65.983,2.709,0.365,0.043,,0.118738,547.493,,11.8738,0.547493,,,,7.85398e-5
1:0 (rep 1),2-Compress,66.35,2.686,0.388,0.036,,0.12622,458.366,,12.622,0.458366,,,,7.85398e-5
1:0 (rep 1),2-Compress,66.717,2.663,0.411,0.043,,0.133702,547.493,,13.3702,0.547493,,,,7.85398e-5
1:0 (rep 1),2-Compress,67.083,2.641,0.433,0.03,,0.140859,381.972,,14.0859,0.381972,,,,7.85398e-5
1:0 (rep 1),2-Compress,67.45,2.618,0.456,0.043,,0.148341,547.493,,14.8341,0.547493,,,,7.85398e-5
1:0 (rep 1),2-Compress,67.817,2.595,0.479,0.043,,0.155823,547.493,,15.5823,0.547493,,,,7.85398e-5
1:0 (rep 1),2-Compress,68.183,2.573,0.501,0.05,,0.16298,636.62,,16.298,0.63662,,,,7.85398e-5
1:0 (rep 1),2-Compress,68.55,2.55,0.524,0.05,,0.170462,636.62,,17.0462,0.63662,,,,7.85398e-5
1:0 (rep 1),2-Compress,68.917,2.528,0.546,0.05,,0.177619,636.62,,17.7619,0.63662,,,,7.85398e-5
1:0 (rep 1),2-Compress,69.283,2.505,0.569,0.05,,0.185101,636.62,,18.5101,0.63662,,,,7.85398e-5
1:0 (rep 1),2-Compress,69.65,2.483,0.591,0.05,,0.192258,636.62,,19.2258,0.63662,,,,7.85398e-5
1:0 (rep 1),2-Compress,70.017,2.46,0.614,0.05,,0.19974,636.62,,19.974,0.63662,,,,7.85398e-5
1:0 (rep 1),2-Compress,70.383,2.438,0.636,0.05,,0.206897,636.62,,20.6897,0.63662,,,,7.85398e-5
1:0 (rep 1),2-Compress,70.75,2.415,0.659,0.05,,0.214379,636.62,,21.4379,0.63662,,,,7.85398e-5
1:0 (rep 1),2-Compress,71.117,2.392,0.682,0.05,,0.221861,636.62,,22.1861,0.63662,,,,7.85398e-5
1:0 (rep 1),2-Compress,71.483,2.37,0.704,0.05,,0.229018,636.62,,22.9018,0.63662,,,,7.85398e-5
1:0 (rep 1),2-Compress,71.85,2.347,0.727,0.05,,0.2365,636.62,,23.65,0.63662,,,,7.85398e-5
1:0 (rep 1),2-Compress,72.217,2.325,0.749,0.05,,0.243656,636.62,,24.3656,0.63662,,,,7.85398e-5
1:0 (rep 1),2-Compress,72.583,2.302,0.772,0.05,,0.251139,636.62,,25.1139,0.63662,,,,7.85398e-5
1:0 (rep 1),2-Compress,72.95,2.28,0.794,0.064,,0.258295,814.873,,25.8295,0.814873,,,,7.85398e-5
1:0 (rep 1),2-Compress,73.317,2.257,0.817,0.07,,0.265777,891.268,,26.5777,0.891268,,,,7.85398e-5
1:0 (rep 1),2-Compress,73.683,2.235,0.839,0.077,,0.272934,980.395,,27.2934,0.980395,,,,7.85398e-5
1:0 (rep 1),2-Compress,74.05,2.212,0.862,0.077,,0.280416,980.395,,28.0416,0.980395,,,,7.85398e-5
1:0 (rep 1),2-Compress,74.417,2.189,0.885,0.077,,0.287899,980.395,,28.7899,0.980395,,,,7.85398e-5
1:0 (rep 1),2-Compress,74.783,2.167,0.907,0.091,,0.295055,1158.65,,29.5055,1.15865,,,,7.85398e-5
1:0 (rep 1),2-Compress,75.15,2.144,0.93,0.084,,0.302537,1069.52,,30.2537,1.06952,,,,7.85398e-5
1:0 (rep 1),2-Compress,75.517,2.121,0.953,0.084,,0.31002,1069.52,,31.002,1.06952,,,,7.85398e-5
1:0 (rep 1),2-Compress,75.883,2.099,0.975,0.104,,0.317176,1324.17,,31.7176,1.32417,,,,7.85398e-5
1:0 (rep 1),2-Compress,76.25,2.076,0.998,0.104,,0.324658,1324.17,,32.4658,1.32417,,,,7.85398e-5
1:0 (rep 1),2-Compress,76.617,2.054,1.02,0.104,,0.331815,1324.17,,33.1815,1.32417,,,,7.85398e-5
1:0 (rep 1),2-Compress,76.983,2.031,1.043,0.104,,0.339297,1324.17,,33.9297,1.32417,,,,7.85398e-5
1:0 (rep 1),2-Compress,77.35,2.009,1.065,0.104,,0.346454,1324.17,,34.6454,1.32417,,,,7.85398e-5
1:0 (rep 1),2-Compress,77.717,1.986,1.088,0.104,,0.353936,1324.17,,35.3936,1.32417,,,,7.85398e-5
1:0 (rep 1),2-Compress,78.083,1.964,1.11,0.104,,0.361093,1324.17,,36.1093,1.32417,,,,7.85398e-5
1:0 (rep 1),2-Compress,78.45,1.941,1.133,0.104,,0.368575,1324.17,,36.8575,1.32417,,,,7.85398e-5
1:0 (rep 1),2-Compress,78.817,1.918,1.156,0.104,,0.376057,1324.17,,37.6057,1.32417,,,,7.85398e-5
1:0 (rep 1),2-Compress,79.183,1.896,1.178,0.118,,0.383214,1502.42,,38.3214,1.50242,,,,7.85398e-5
1:0 (rep 1),2-Compress,79.55,1.873,1.201,0.111,,0.390696,1413.3,,39.0696,1.4133,,,,7.85398e-5
1:0 (rep 1),2-Compress,79.917,1.851,1.223,0.118,,0.397853,1502.42,,39.7853,1.50242,,,,7.85398e-5
1:0 (rep 1),2-Compress,80.283,1.828,1.246,0.104,,0.405335,1324.17,,40.5335,1.32417,,,,7.85398e-5
1:0 (rep 1),2-Compress,80.65,1.806,1.268,0.138,,0.412492,1757.07,,41.2492,1.75707,,,,7.85398e-5
1:0 (rep 1),2-Compress,81.017,1.783,1.291,0.145,,0.419974,1846.2,,41.9974,1.8462,,,,7.85398e-5
1:0 (rep 1),2-Compress,81.383,1.761,1.313,0.159,,0.427131,2024.45,,42.7131,2.02445,,,,7.85398e-5
1:0 (rep 1),2-Compress,81.75,1.738,1.336,0.152,,0.434613,1935.32,,43.4613,1.93532,,,,7.85398e-5
1:0 (rep 1),2-Compress,82.117,1.715,1.359,0.159,,0.442095,2024.45,,44.2095,2.02445,,,,7.85398e-5
1:0 (rep 1),2-Compress,82.483,1.693,1.381,0.159,,0.449252,2024.45,,44.9252,2.02445,,,,7.85398e-5
1:0 (rep 1),2-Compress,82.85,1.67,1.404,0.159,,0.456734,2024.45,,45.6734,2.02445,,,,7.85398e-5
1:0 (rep 1),2-Compress,83.217,1.647,1.427,0.159,,0.464216,2024.45,,46.4216,2.02445,,,,7.85398e-5
1:0 (rep 1),2-Compress,83.583,1.625,1.449,0.152,,0.471373,1935.32,,47.1373,1.93532,,,,7.85398e-5
1:0 (rep 1),2-Compress,83.95,1.602,1.472,0.152,,0.478855,1935.32,,47.8855,1.93532,,,,7.85398e-5
1:0 (rep 1),2-Compress,84.317,1.58,1.494,0.152,,0.486012,1935.32,,48.6012,1.93532,,,,7.85398e-5
1:0 (rep 1),2-Compress,84.683,1.558,1.516,0.165,,0.493169,2100.85,,49.3169,2.10085,,,,7.85398e-5
1:0 (rep 1),2-Compress,85.05,1.535,1.539,0.165,,0.500651,2100.85,,50.0651,2.10085,,,,7.85398e-5
1:0 (rep 1),2-Compress,85.417,1.512,1.562,0.186,,0.508133,2368.23,,50.8133,2.36823,,,,7.85398e-5
1:0 (rep 1),2-Compress,85.783,1.49,1.584,0.193,,0.51529,2457.35,,51.529,2.45735,,,,7.85398e-5
1:0 (rep 1),2-Compress,86.15,1.467,1.607,0.186,,0.522772,2368.23,,52.2772,2.36823,,,,7.85398e-5
1:0 (rep 1),2-Compress,86.517,1.444,1.63,0.199,,0.530254,2533.75,,53.0254,2.53375,,,,7.85398e-5
1:0 (rep 1),2-Compress,86.883,1.422,1.652,0.206,,0.537411,2622.87,,53.7411,2.62287,,,,7.85398e-5
1:0 (rep 1),2-Compress,87.25,1.399,1.675,0.213,,0.544893,2712,,54.4893,2.712,,,,7.85398e-5
1:0 (rep 1),2-Compress,87.617,1.377,1.697,0.213,,0.552049,2712,,55.2049,2.712,,,,7.85398e-5
1:0 (rep 1),2-Compress,87.983,1.354,1.72,0.213,,0.559532,2712,,55.9532,2.712,,,,7.85398e-5
1:0 (rep 1),2-Compress,88.35,1.332,1.742,0.206,,0.566688,2622.87,,56.6688,2.62287,,,,7.85398e-5
1:0 (rep 1),2-Compress,88.717,1.309,1.765,0.227,,0.57417,2890.25,,57.417,2.89025,,,,7.85398e-5
1:0 (rep 1),2-Compress,89.083,1.287,1.787,0.233,,0.581327,2966.65,,58.1327,2.96665,,,,7.85398e-5
1:0 (rep 1),2-Compress,89.45,1.264,1.81,0.213,,0.588809,2712,,58.8809,2.712,,,,7.85398e-5
1:0 (rep 1),2-Compress,89.817,1.241,1.833,0.22,,0.596291,2801.13,,59.6291,2.80113,,,,7.85398e-5
1:0 (rep 1),2-Recover,90.17,1.237,1.837,0.22,,0.597593,2801.13,,59.7593,2.80113,,,,7.85398e-5
1:0 (rep 1),2-Recover,90.537,1.26,1.814,0.227,,0.590111,2890.25,,59.0111,2.89025,,,,7.85398e-5
1:0 (rep 1),2-Recover,90.903,1.282,1.792,0.227,,0.582954,2890.25,,58.2954,2.89025,,,,7.85398e-5
1:0 (rep 1),2-Recover,91.27,1.305,1.769,0.22,,0.575472,2801.13,,57.5472,2.80113,,,,7.85398e-5
1:0 (rep 1),2-Recover,91.637,1.327,1.747,0.206,,0.568315,2622.87,,56.8315,2.62287,,,,7.85398e-5
1:0 (rep 1),2-Recover,92.003,1.35,1.724,0.206,,0.560833,2622.87,,56.0833,2.62287,,,,7.85398e-5
1:0 (rep 1),2-Recover,92.37,1.372,1.702,0.213,,0.553676,2712,,55.3676,2.712,,,,7.85398e-5
1:0 (rep 1),2-Recover,92.737,1.395,1.679,0.213,,0.546194,2712,,54.6194,2.712,,,,7.85398e-5
1:0 (rep 1),2-Recover,93.103,1.417,1.657,0.199,,0.539037,2533.75,,53.9037,2.53375,,,,7.85398e-5
1:0 (rep 1),2-Recover,93.47,1.44,1.634,0.186,,0.531555,2368.23,,53.1555,2.36823,,,,7.85398e-5
1:0 (rep 1),2-Recover,93.837,1.463,1.611,0.172,,0.524073,2189.97,,52.4073,2.18997,,,,7.85398e-5
1:0 (rep 1),2-Recover,94.203,1.485,1.589,0.165,,0.516916,2100.85,,51.6916,2.10085,,,,7.85398e-5
1:0 (rep 1),2-Recover,94.57,1.508,1.566,0.159,,0.509434,2024.45,,50.9434,2.02445,,,,7.85398e-5
1:0 (rep 1),2-Recover,94.937,1.531,1.543,0.165,,0.501952,2100.85,,50.1952,2.10085,,,,7.85398e-5
1:0 (rep 1),2-Recover,95.303,1.553,1.521,0.159,,0.494795,2024.45,,49.4795,2.02445,,,,7.85398e-5
1:0 (rep 1),2-Recover,95.67,1.575,1.499,0.159,,0.487638,2024.45,,48.7638,2.02445,,,,7.85398e-5
1:0 (rep 1),2-Recover,96.037,1.599,1.475,0.159,,0.479831,2024.45,,47.9831,2.02445,,,,7.85398e-5
1:0 (rep 1),2-Recover,96.403,1.62,1.454,0.159,,0.472999,2024.45,,47.2999,2.02445,,,,7.85398e-5
1:0 (rep 1),2-Recover,96.77,1.643,1.431,0.159,,0.465517,2024.45,,46.5517,2.02445,,,,7.85398e-5
1:0 (rep 1),2-Recover,97.137,1.666,1.408,0.159,,0.458035,2024.45,,45.8035,2.02445,,,,7.85398e-5
1:0 (rep 1),2-Recover,97.503,1.688,1.386,0.152,,0.450878,1935.32,,45.0878,1.93532,,,,7.85398e-5
1:0 (rep 1),2-Recover,97.87,1.711,1.363,0.131,,0.443396,1667.94,,44.3396,1.66794,,,,7.85398e-5
1:0 (rep 1),2-Recover,98.237,1.734,1.34,0.131,,0.435914,1667.94,,43.5914,1.66794,,,,7.85398e-5
1:0 (rep 1),2-Recover,98.603,1.756,1.318,0.125,,0.428757,1591.55,,42.8757,1.59155,,,,7.85398e-5
1:0 (rep 1),2-Recover,98.97,1.779,1.295,0.118,,0.421275,1502.42,,42.1275,1.50242,,,,7.85398e-5
1:0 (rep 1),2-Recover,99.337,1.801,1.273,0.111,,0.414118,1413.3,,41.4118,1.4133,,,,7.85398e-5
1:0 (rep 1),2-Recover,99.703,1.824,1.25,0.104,,0.406636,1324.17,,40.6636,1.32417,,,,7.85398e-5
1:0 (rep 1),2-Recover,100.07,1.846,1.228,0.104,,0.39948,1324.17,,39.948,1.32417,,,,7.85398e-5
1:0 (rep 1),2-Recover,100.437,1.869,1.205,0.104,,0.391997,1324.17,,39.1997,1.32417,,,,7.85398e-5
1:0 (rep 1),2-Recover,100.803,1.891,1.183,0.104,,0.384841,1324.17,,38.4841,1.32417,,,,7.85398e-5
1:0 (rep 1),2-Recover,101.17,1.914,1.16,0.104,,0.377358,1324.17,,37.7358,1.32417,,,,7.85398e-5
1:0 (rep 1),2-Recover,101.537,1.937,1.137,0.104,,0.369876,1324.17,,36.9876,1.32417,,,,7.85398e-5
1:0 (rep 1),2-Recover,101.903,1.959,1.115,0.104,,0.36272,1324.17,,36.272,1.32417,,,,7.85398e-5
1:0 (rep 1),2-Recover,102.27,1.982,1.092,0.104,,0.355237,1324.17,,35.5237,1.32417,,,,7.85398e-5
1:0 (rep 1),2-Recover,102.637,2.004,1.07,0.098,,0.348081,1247.78,,34.8081,1.24778,,,,7.85398e-5
1:0 (rep 1),2-Recover,103.003,2.027,1.047,0.091,,0.340599,1158.65,,34.0599,1.15865,,,,7.85398e-5
1:0 (rep 1),2-Recover,103.37,2.049,1.025,0.091,,0.333442,1158.65,,33.3442,1.15865,,,,7.85398e-5
1:0 (rep 1),2-Recover,103.737,2.072,1.002,0.104,,0.32596,1324.17,,32.596,1.32417,,,,7.85398e-5
1:0 (rep 1),2-Recover,104.103,2.094,0.98,0.077,,0.318803,980.395,,31.8803,0.980395,,,,7.85398e-5
1:0 (rep 1),2-Recover,104.47,2.117,0.957,0.07,,0.311321,891.268,,31.1321,0.891268,,,,7.85398e-5
1:0 (rep 1),2-Recover,104.837,2.14,0.934,0.057,,0.303839,725.747,,30.3839,0.725747,,,,7.85398e-5
1:0 (rep 1),2-Recover,105.203,2.162,0.912,0.05,,0.296682,636.62,,29.6682,0.63662,,,,7.85398e-5
1:0 (rep 1),2-Recover,105.57,2.185,0.889,0.05,,0.2892,636.62,,28.92,0.63662,,,,7.85398e-5
1:0 (rep 1),2-Recover,105.937,2.208,0.866,0.05,,0.281718,636.62,,28.1718,0.63662,,,,7.85398e-5
1:0 (rep 1),2-Recover,106.303,2.23,0.844,0.057,,0.274561,725.747,,27.4561,0.725747,,,,7.85398e-5
1:0 (rep 1),2-Recover,106.67,2.253,0.821,0.05,,0.267079,636.62,,26.7079,0.63662,,,,7.85398e-5
1:0 (rep 1),2-Recover,107.037,2.275,0.799,0.05,,0.259922,636.62,,25.9922,0.63662,,,,7.85398e-5
1:0 (rep 1),2-Recover,107.403,2.297,0.777,0.05,,0.252765,636.62,,25.2765,0.63662,,,,7.85398e-5
1:0 (rep 1),2-Recover,107.77,2.32,0.754,0.05,,0.245283,636.62,,24.5283,0.63662,,,,7.85398e-5
1:0 (rep 1),2-Recover,108.137,2.343,0.731,0.05,,0.237801,636.62,,23.7801,0.63662,,,,7.85398e-5
1:0 (rep 1),2-Recover,108.503,2.365,0.709,0.05,,0.230644,636.62,,23.0644,0.63662,,,,7.85398e-5
1:0 (rep 1),2-Recover,108.87,2.388,0.686,0.05,,0.223162,636.62,,22.3162,0.63662,,,,7.85398e-5
1:0 (rep 1),2-Recover,109.237,2.411,0.663,0.05,,0.21568,636.62,,21.568,0.63662,,,,7.85398e-5
1:0 (rep 1),2-Recover,109.603,2.433,0.641,0.05,,0.208523,636.62,,20.8523,0.63662,,,,7.85398e-5
1:0 (rep 1),2-Recover,109.97,2.456,0.618,0.043,,0.201041,547.493,,20.1041,0.547493,,,,7.85398e-5
1:0 (rep 1),2-Recover,110.337,2.478,0.596,0.05,,0.193884,636.62,,19.3884,0.63662,,,,7.85398e-5
1:0 (rep 1),2-Recover,110.703,2.501,0.573,0.043,,0.186402,547.493,,18.6402,0.547493,,,,7.85398e-5
1:0 (rep 1),2-Recover,111.07,2.523,0.551,0.036,,0.179245,458.366,,17.9245,0.458366,,,,7.85398e-5
1:0 (rep 1),2-Recover,111.437,2.546,0.528,0.036,,0.171763,458.366,,17.1763,0.458366,,,,7.85398e-5
1:0 (rep 1),2-Recover,111.803,2.568,0.506,0.05,,0.164606,636.62,,16.4606,0.63662,,,,7.85398e-5
1:0 (rep 1),2-Recover,112.17,2.591,0.483,0.023,,0.157124,292.845,,15.7124,0.292845,,,,7.85398e-5
1:0 (rep 1),2-Recover,112.537,2.614,0.46,0.002,,0.149642,25.4648,,14.9642,0.0254648,,,,7.85398e-5
1:0 (rep 1),2-Recover,112.903,2.636,0.438,0.016,,0.142485,203.718,,14.2485,0.203718,,,,7.85398e-5
1:0 (rep 1),2-Recover,113.27,2.659,0.415,0.016,,0.135003,203.718,,13.5003,0.203718,,,,7.85398e-5
1:0 (rep 1),2-Recover,113.637,2.682,0.392,0.03,,0.127521,381.972,,12.7521,0.381972,,,,7.85398e-5
1:0 (rep 1),2-Recover,114.003,2.704,0.37,0.016,,0.120364,203.718,,12.0364,0.203718,,,,7.85398e-5
1:0 (rep 1),2-Recover,114.37,2.726,0.348,0.009,,0.113208,114.592,,11.3208,0.114592,,,,7.85398e-5
1:0 (rep 1),2-Recover,114.737,2.75,0.324,0.002,,0.1054,25.4648,,10.54,0.0254648,,,,7.85398e-5
1:0 (rep 1),2-Recover,115.103,2.771,0.303,0.002,,0.0985686,25.4648,,9.85686,0.0254648,,,,7.85398e-5
1:0 (rep 1),2-Recover,115.47,2.794,0.28,0.002,,0.0910865,25.4648,,9.10865,0.0254648,,,,7.85398e-5
1:0 (rep 1),2-Recover,115.837,2.817,0.257,0.016,,0.0836044,203.718,,8.36044,0.203718,,,,7.85398e-5
1:0 (rep 1),2-Recover,116.203,2.839,0.235,0.009,,0.0764476,114.592,,7.64476,0.114592,,,,7.85398e-5
1:0 (rep 1),2-Recover,116.57,2.862,0.212,-0.004,,0.0689655,-50.9296,,6.89655,-0.0509296,,,,7.85398e-5
1:0 (rep 1),2-Recover,116.937,2.885,0.189,-0.004,,0.0614834,-50.9296,,6.14834,-0.0509296,,,,7.85398e-5
1:0 (rep 1),2-Recover,117.303,2.907,0.167,-0.004,,0.0543266,-50.9296,,5.43266,-0.0509296,,,,7.85398e-5
1:0 (rep 1),2-Recover,117.67,2.93,0.144,0.002,,0.0468445,25.4648,,4.68445,0.0254648,,,,7.85398e-5
1:0 (rep 1),2-Recover,118.037,2.952,0.122,0.002,,0.0396877,25.4648,,3.96877,0.0254648,,,,7.85398e-5
1:0 (rep 1),2-Recover,118.403,2.975,0.099,0.002,,0.0322056,25.4648,,3.22056,0.0254648,,,,7.85398e-5
1:0 (rep 1),2-Recover,118.77,2.997,0.077,0.009,,0.0250488,114.592,,2.50488,0.114592,,,,7.85398e-5
1:0 (rep 1),2-Recover,119.137,3.02,0.054,0.002,,0.0175667,25.4648,,1.75667,0.0254648,,,,7.85398e-5
1:0 (rep 1),2-Recover,119.503,3.042,0.032,-0.004,,0.0104099,-50.9296,,1.04099,-0.0509296,,,,7.85398e-5
1:0 (rep 1),2-Recover,119.87,3.065,0.009,-0.004,,0.00292778,-50.9296,,0.292778,-0.0509296,,,,7.85398e-5
1:0 (rep 1),3-Compress,120.213,3.066,0.008,-0.004,,0.00260247,-50.9296,,0.260247,-0.0509296,,,,7.85398e-5
1:0 (rep 1),3-Compress,120.58,3.043,0.031,0.002,,0.0100846,25.4648,,1.00846,0.0254648,,,,7.85398e-5
1:0 (rep 1),3-Compress,120.947,3.021,0.053,0.002,,0.0172414,25.4648,,1.72414,0.0254648,,,,7.85398e-5
1:0 (rep 1),3-Compress,121.313,2.998,0.076,0.002,,0.0247235,25.4648,,2.47235,0.0254648,,,,7.85398e-5
1:0 (rep 1),3-Compress,121.68,2.976,0.098,0.002,,0.0318803,25.4648,,3.18803,0.0254648,,,,7.85398e-5
1:0 (rep 1),3-Compress,122.047,2.953,0.121,-0.004,,0.0393624,-50.9296,,3.93624,-0.0509296,,,,7.85398e-5
1:0 (rep 1),3-Compress,122.413,2.931,0.143,0.002,,0.0465192,25.4648,,4.65192,0.0254648,,,,7.85398e-5
1:0 (rep 1),3-Compress,122.78,2.908,0.166,0.002,,0.0540013,25.4648,,5.40013,0.0254648,,,,7.85398e-5
1:0 (rep 1),3-Compress,123.147,2.885,0.189,0.002,,0.0614834,25.4648,,6.14834,0.0254648,,,,7.85398e-5
1:0 (rep 1),3-Compress,123.513,2.863,0.211,0.016,,0.0686402,203.718,,6.86402,0.203718,,,,7.85398e-5
1:0 (rep 1),3-Compress,123.88,2.84,0.234,0.023,,0.0761223,292.845,,7.61223,0.292845,,,,7.85398e-5
1:0 (rep 1),3-Compress,124.247,2.818,0.256,0.002,,0.0832791,25.4648,,8.32791,0.0254648,,,,7.85398e-5
1:0 (rep 1),3-Compress,124.613,2.795,0.279,0.016,,0.0907612,203.718,,9.07612,0.203718,,,,7.85398e-5
1:0 (rep 1),3-Compress,124.98,2.773,0.301,0.009,,0.097918,114.592,,9.7918,0.114592,,,,7.85398e-5
1:0 (rep 1),3-Compress,125.347,2.75,0.324,0.002,,0.1054,25.4648,,10.54,0.0254648,,,,7.85398e-5
1:0 (rep 1),3-Compress,125.713,2.728,0.346,0.016,,0.112557,203.718,,11.2557,0.203718,,,,7.85398e-5
1:0 (rep 1),3-Compress,126.08,2.705,0.369,0.03,,0.120039,381.972,,12.0039,0.381972,,,,7.85398e-5
1:0 (rep 1),3-Compress,126.447,2.682,0.392,0.043,,0.127521,547.493,,12.7521,0.547493,,,,7.85398e-5
1:0 (rep 1),3-Compress,126.813,2.66,0.414,0.043,,0.134678,547.493,,13.4678,0.547493,,,,7.85398e-5
1:0 (rep 1),3-Compress,127.18,2.637,0.437,0.023,,0.14216,292.845,,14.216,0.292845,,,,7.85398e-5
1:0 (rep 1),3-Compress,127.547,2.614,0.46,0.036,,0.149642,458.366,,14.9642,0.458366,,,,7.85398e-5
1:0 (rep 1),3-Compress,127.913,2.592,0.482,0.05,,0.156799,636.62,,15.6799,0.63662,,,,7.85398e-5
1:0 (rep 1),3-Compress,128.28,2.569,0.505,0.043,,0.164281,547.493,,16.4281,0.547493,,,,7.85398e-5
1:0 (rep 1),3-Compress,128.647,2.547,0.527,0.057,,0.171438,725.747,,17.1438,0.725747,,,,7.85398e-5
1:0 (rep 1),3-Compress,129.013,2.525,0.549,0.05,,0.178595,636.62,,17.8595,0.63662,,,,7.85398e-5
1:0 (rep 1),3-Compress,129.38,2.502,0.572,0.05,,0.186077,636.62,,18.6077,0.63662,,,,7.85398e-5
1:0 (rep 1),3-Compress,129.747,2.479,0.595,0.05,,0.193559,636.62,,19.3559,0.63662,,,,7.85398e-5
1:0 (rep 1),3-Compress,130.113,2.457,0.617,0.05,,0.200716,636.62,,20.0716,0.63662,,,,7.85398e-5
1:0 (rep 1),3-Compress,130.48,2.434,0.64,0.05,,0.208198,636.62,,20.8198,0.63662,,,,7.85398e-5
1:0 (rep 1),3-Compress,130.847,2.411,0.663,0.05,,0.21568,636.62,,21.568,0.63662,,,,7.85398e-5
1:0 (rep 1),3-Compress,131.213,2.389,0.685,0.05,,0.222837,636.62,,22.2837,0.63662,,,,7.85398e-5
1:0 (rep 1),3-Compress,131.58,2.366,0.708,0.05,,0.230319,636.62,,23.0319,0.63662,,,,7.85398e-5
1:0 (rep 1),3-Compress,131.947,2.344,0.73,0.057,,0.237476,725.747,,23.7476,0.725747,,,,7.85398e-5
1:0 (rep 1),3-Compress,132.313,2.321,0.753,0.05,,0.244958,636.62,,24.4958,0.63662,,,,7.85398e-5
1:0 (rep 1),3-Compress,132.68,2.299,0.775,0.057,,0.252115,725.747,,25.2115,0.725747,,,,7.85398e-5
1:0 (rep 1),3-Compress,133.047,2.276,0.798,0.05,,0.259597,636.62,,25.9597,0.63662,,,,7.85398e-5
1:0 (rep 1),3-Compress,133.413,2.254,0.82,0.057,,0.266753,725.747,,26.6753,0.725747,,,,7.85398e-5
1:0 (rep 1),3-Compress,133.78,2.231,0.843,0.057,,0.274236,725.747,,27.4236,0.725747,,,,7.85398e-5
1:0 (rep 1),3-Compress,134.147,2.208,0.866,0.077,,0.281718,980.395,,28.1718,0.980395,,,,7.85398e-5
1:0 (rep 1),3-Compress,134.513,2.186,0.888,0.077,,0.288874,980.395,,28.8874,0.980395,,,,7.85398e-5
1:0 (rep 1),3-Compress,134.88,2.163,0.911,0.07,,0.296357,891.268,,29.6357,0.891268,,,,7.85398e-5
1:0 (rep 1),3-Compress,135.247,2.14,0.934,0.084,,0.303839,1069.52,,30.3839,1.06952,,,,7.85398e-5
1:0 (rep 1),3-Compress,135.613,2.118,0.956,0.091,,0.310995,1158.65,,31.0995,1.15865,,,,7.85398e-5
1:0 (rep 1),3-Compress,135.98,2.096,0.978,0.084,,0.318152,1069.52,,31.8152,1.06952,,,,7.85398e-5
1:0 (rep 1),3-Compress,136.347,2.073,1.001,0.104,,0.325634,1324.17,,32.5634,1.32417,,,,7.85398e-5
1:0 (rep 1),3-Compress,136.713,2.051,1.023,0.104,,0.332791,1324.17,,33.2791,1.32417,,,,7.85398e-5
1:0 (rep 1),3-Compress,137.08,2.028,1.046,0.104,,0.340273,1324.17,,34.0273,1.32417,,,,7.85398e-5
1:0 (rep 1),3-Compress,137.447,2.005,1.069,0.104,,0.347755,1324.17,,34.7755,1.32417,,,,7.85398e-5
1:0 (rep 1),3-Compress,137.813,1.983,1.091,0.104,,0.354912,1324.17,,35.4912,1.32417,,,,7.85398e-5
1:0 (rep 1),3-Compress,138.18,1.96,1.114,0.104,,0.362394,1324.17,,36.2394,1.32417,,,,7.85398e-5
1:0 (rep 1),3-Compress,138.547,1.937,1.137,0.104,,0.369876,1324.17,,36.9876,1.32417,,,,7.85398e-5
1:0 (rep 1),3-Compress,138.913,1.915,1.159,0.111,,0.377033,1413.3,,37.7033,1.4133,,,,7.85398e-5
1:0 (rep 1),3-Compress,139.28,1.892,1.182,0.118,,0.384515,1502.42,,38.4515,1.50242,,,,7.85398e-5
1:0 (rep 1),3-Compress,139.647,1.87,1.204,0.118,,0.391672,1502.42,,39.1672,1.50242,,,,7.85398e-5
1:0 (rep 1),3-Compress,140.013,1.847,1.227,0.118,,0.399154,1502.42,,39.9154,1.50242,,,,7.85398e-5
1:0 (rep 1),3-Compress,140.38,1.825,1.249,0.118,,0.406311,1502.42,,40.6311,1.50242,,,,7.85398e-5
1:0 (rep 1),3-Compress,140.747,1.802,1.272,0.111,,0.413793,1413.3,,41.3793,1.4133,,,,7.85398e-5
1:0 (rep 1),3-Compress,141.113,1.78,1.294,0.125,,0.42095,1591.55,,42.095,1.59155,,,,7.85398e-5
1:0 (rep 1),3-Compress,141.48,1.757,1.317,0.145,,0.428432,1846.2,,42.8432,1.8462,,,,7.85398e-5
1:0 (rep 1),3-Compress,141.847,1.734,1.34,0.159,,0.435914,2024.45,,43.5914,2.02445,,,,7.85398e-5
1:0 (rep 1),3-Compress,142.213,1.712,1.362,0.159,,0.443071,2024.45,,44.3071,2.02445,,,,7.85398e-5
1:0 (rep 1),3-Compress,142.58,1.689,1.385,0.159,,0.450553,2024.45,,45.0553,2.02445,,,,7.85398e-5
1:0 (rep 1),3-Compress,142.947,1.667,1.407,0.159,,0.45771,2024.45,,45.771,2.02445,,,,7.85398e-5
1:0 (rep 1),3-Compress,143.313,1.644,1.43,0.159,,0.465192,2024.45,,46.5192,2.02445,,,,7.85398e-5
1:0 (rep 1),3-Compress,143.68,1.622,1.452,0.159,,0.472349,2024.45,,47.2349,2.02445,,,,7.85398e-5
1:0 (rep 1),3-Compress,144.047,1.599,1.475,0.145,,0.479831,1846.2,,47.9831,1.8462,,,,7.85398e-5
1:0 (rep 1),3-Compress,144.413,1.577,1.497,0.152,,0.486988,1935.32,,48.6988,1.93532,,,,7.85398e-5
1:0 (rep 1),3-Compress,144.78,1.554,1.52,0.159,,0.49447,2024.45,,49.447,2.02445,,,,7.85398e-5
1:0 (rep 1),3-Compress,145.147,1.531,1.543,0.159,,0.501952,2024.45,,50.1952,2.02445,,,,7.85398e-5
1:0 (rep 1),3-Compress,145.513,1.509,1.565,0.165,,0.509109,2100.85,,50.9109,2.10085,,,,7.85398e-5
1:0 (rep 1),3-Compress,145.88,1.486,1.588,0.193,,0.516591,2457.35,,51.6591,2.45735,,,,7.85398e-5
1:0 (rep 1),3-Compress,146.247,1.463,1.611,0.193,,0.524073,2457.35,,52.4073,2.45735,,,,7.85398e-5
1:0 (rep 1),3-Compress,146.613,1.441,1.633,0.186,,0.53123,2368.23,,53.123,2.36823,,,,7.85398e-5
1:0 (rep 1),3-Compress,146.98,1.418,1.656,0.193,,0.538712,2457.35,,53.8712,2.45735,,,,7.85398e-5
1:0 (rep 1),3-Compress,147.347,1.396,1.678,0.199,,0.545869,2533.75,,54.5869,2.53375,,,,7.85398e-5
1:0 (rep 1),3-Compress,147.713,1.373,1.701,0.206,,0.553351,2622.87,,55.3351,2.62287,,,,7.85398e-5
1:0 (rep 1),3-Compress,148.08,1.351,1.723,0.213,,0.560507,2712,,56.0507,2.712,,,,7.85398e-5
1:0 (rep 1),3-Compress,148.447,1.328,1.746,0.213,,0.56799,2712,,56.799,2.712,,,,7.85398e-5
1:0 (rep 1),3-Compress,148.813,1.306,1.768,0.22,,0.575146,2801.13,,57.5146,2.80113,,,,7.85398e-5
1:0 (rep 1),3-Compress,149.18,1.283,1.791,0.233,,0.582628,2966.65,,58.2628,2.96665,,,,7.85398e-5
1:0 (rep 1),3-Compress,149.547,1.26,1.814,0.227,,0.590111,2890.25,,59.0111,2.89025,,,,7.85398e-5
1:0 (rep 1),3-Compress,149.913,1.238,1.836,0.227,,0.597267,2890.25,,59.7267,2.89025,,,,7.85398e-5
1:0 (rep 1),3-Recover,150.267,1.241,1.833,0.213,,0.596291,2712,,59.6291,2.712,,,,7.85398e-5
1:0 (rep 1),3-Recover,150.633,1.263,1.811,0.24,,0.589135,3055.78,,58.9135,3.05578,,,,7.85398e-5
1:0 (rep 1),3-Recover,151,1.286,1.788,0.227,,0.581653,2890.25,,58.1653,2.89025,,,,7.85398e-5
1:0 (rep 1),3-Recover,151.367,1.309,1.765,0.213,,0.57417,2712,,57.417,2.712,,,,7.85398e-5
1:0 (rep 1),3-Recover,151.733,1.331,1.743,0.193,,0.567014,2457.35,,56.7014,2.45735,,,,7.85398e-5
1:0 (rep 1),3-Recover,152.1,1.354,1.72,0.193,,0.559532,2457.35,,55.9532,2.45735,,,,7.85398e-5
1:0 (rep 1),3-Recover,152.467,1.376,1.698,0.199,,0.552375,2533.75,,55.2375,2.53375,,,,7.85398e-5
1:0 (rep 1),3-Recover,152.833,1.399,1.675,0.206,,0.544893,2622.87,,54.4893,2.62287,,,,7.85398e-5
1:0 (rep 1),3-Recover,153.2,1.421,1.653,0.199,,0.537736,2533.75,,53.7736,2.53375,,,,7.85398e-5
1:0 (rep 1),3-Recover,153.567,1.444,1.63,0.186,,0.530254,2368.23,,53.0254,2.36823,,,,7.85398e-5
1:0 (rep 1),3-Recover,153.933,1.466,1.608,0.165,,0.523097,2100.85,,52.3097,2.10085,,,,7.85398e-5
1:0 (rep 1),3-Recover,154.3,1.489,1.585,0.159,,0.515615,2024.45,,51.5615,2.02445,,,,7.85398e-5
1:0 (rep 1),3-Recover,154.667,1.512,1.562,0.152,,0.508133,1935.32,,50.8133,1.93532,,,,7.85398e-5
1:0 (rep 1),3-Recover,155.033,1.534,1.54,0.159,,0.500976,2024.45,,50.0976,2.02445,,,,7.85398e-5
1:0 (rep 1),3-Recover,155.4,1.557,1.517,0.159,,0.493494,2024.45,,49.3494,2.02445,,,,7.85398e-5
1:0 (rep 1),3-Recover,155.767,1.579,1.495,0.159,,0.486337,2024.45,,48.6337,2.02445,,,,7.85398e-5
1:0 (rep 1),3-Recover,156.133,1.601,1.473,0.159,,0.47918,2024.45,,47.918,2.02445,,,,7.85398e-5
1:0 (rep 1),3-Recover,156.5,1.624,1.45,0.152,,0.471698,1935.32,,47.1698,1.93532,,,,7.85398e-5
1:0 (rep 1),3-Recover,156.867,1.647,1.427,0.152,,0.464216,1935.32,,46.4216,1.93532,,,,7.85398e-5
1:0 (rep 1),3-Recover,157.233,1.669,1.405,0.159,,0.457059,2024.45,,45.7059,2.02445,,,,7.85398e-5
1:0 (rep 1),3-Recover,157.6,1.692,1.382,0.138,,0.449577,1757.07,,44.9577,1.75707,,,,7.85398e-5
1:0 (rep 1),3-Recover,157.967,1.715,1.359,0.118,,0.442095,1502.42,,44.2095,1.50242,,,,7.85398e-5
1:0 (rep 1),3-Recover,158.333,1.737,1.337,0.111,,0.434938,1413.3,,43.4938,1.4133,,,,7.85398e-5
1:0 (rep 1),3-Recover,158.7,1.76,1.314,0.111,,0.427456,1413.3,,42.7456,1.4133,,,,7.85398e-5
1:0 (rep 1),3-Recover,159.067,1.783,1.291,0.118,,0.419974,1502.42,,41.9974,1.50242,,,,7.85398e-5
1:0 (rep 1),3-Recover,159.433,1.804,1.27,0.111,,0.413142,1413.3,,41.3142,1.4133,,,,7.85398e-5
1:0 (rep 1),3-Recover,159.8,1.828,1.246,0.104,,0.405335,1324.17,,40.5335,1.32417,,,,7.85398e-5
1:0 (rep 1),3-Recover,160.167,1.85,1.224,0.104,,0.398178,1324.17,,39.8178,1.32417,,,,7.85398e-5
1:0 (rep 1),3-Recover,160.533,1.872,1.202,0.104,,0.391021,1324.17,,39.1021,1.32417,,,,7.85398e-5
1:0 (rep 1),3-Recover,160.9,1.895,1.179,0.104,,0.383539,1324.17,,38.3539,1.32417,,,,7.85398e-5
1:0 (rep 1),3-Recover,161.267,1.918,1.156,0.104,,0.376057,1324.17,,37.6057,1.32417,,,,7.85398e-5
1:0 (rep 1),3-Recover,161.633,1.94,1.134,0.104,,0.3689,1324.17,,36.89,1.32417,,,,7.85398e-5
1:0 (rep 1),3-Recover,162,1.963,1.111,0.104,,0.361418,1324.17,,36.1418,1.32417,,,,7.85398e-5
1:0 (rep 1),3-Recover,162.367,1.986,1.088,0.098,,0.353936,1247.78,,35.3936,1.24778,,,,7.85398e-5
1:0 (rep 1),3-Recover,162.733,2.008,1.066,0.091,,0.346779,1158.65,,34.6779,1.15865,,,,7.85398e-5
1:0 (rep 1),3-Recover,163.1,2.03,1.044,0.091,,0.339623,1158.65,,33.9623,1.15865,,,,7.85398e-5
1:0 (rep 1),3-Recover,163.467,2.053,1.021,0.064,,0.332141,814.873,,33.2141,0.814873,,,,7.85398e-5
1:0 (rep 1),3-Recover,163.833,2.076,0.998,0.07,,0.324658,891.268,,32.4658,0.891268,,,,7.85398e-5
1:0 (rep 1),3-Recover,164.2,2.098,0.976,0.077,,0.317502,980.395,,31.7502,0.980395,,,,7.85398e-5
1:0 (rep 1),3-Recover,164.567,2.121,0.953,0.057,,0.31002,725.747,,31.002,0.725747,,,,7.85398e-5
1:0 (rep 1),3-Recover,164.933,2.143,0.931,0.057,,0.302863,725.747,,30.2863,0.725747,,,,7.85398e-5
1:0 (rep 1),3-Recover,165.3,2.166,0.908,0.057,,0.295381,725.747,,29.5381,0.725747,,,,7.85398e-5
1:0 (rep 1),3-Recover,165.667,2.189,0.885,0.05,,0.287899,636.62,,28.7899,0.63662,,,,7.85398e-5
1:0 (rep 1),3-Recover,166.033,2.211,0.863,0.05,,0.280742,636.62,,28.0742,0.63662,,,,7.85398e-5
1:0 (rep 1),3-Recover,166.4,2.233,0.841,0.05,,0.273585,636.62,,27.3585,0.63662,,,,7.85398e-5
1:0 (rep 1),3-Recover,166.767,2.257,0.817,0.05,,0.265777,636.62,,26.5777,0.63662,,,,7.85398e-5
1:0 (rep 1),3-Recover,167.133,2.279,0.795,0.05,,0.258621,636.62,,25.8621,0.63662,,,,7.85398e-5
1:0 (rep 1),3-Recover,167.5,2.301,0.773,0.05,,0.251464,636.62,,25.1464,0.63662,,,,7.85398e-5
1:0 (rep 1),3-Recover,167.867,2.324,0.75,0.05,,0.243982,636.62,,24.3982,0.63662,,,,7.85398e-5
1:0 (rep 1),3-Recover,168.233,2.346,0.728,0.05,,0.236825,636.62,,23.6825,0.63662,,,,7.85398e-5
1:0 (rep 1),3-Recover,168.6,2.369,0.705,0.05,,0.229343,636.62,,22.9343,0.63662,,,,7.85398e-5
1:0 (rep 1),3-Recover,168.967,2.392,0.682,0.05,,0.221861,636.62,,22.1861,0.63662,,,,7.85398e-5
1:0 (rep 1),3-Recover,169.333,2.414,0.66,0.05,,0.214704,636.62,,21.4704,0.63662,,,,7.85398e-5
1:0 (rep 1),3-Recover,169.7,2.437,0.637,0.05,,0.207222,636.62,,20.7222,0.63662,,,,7.85398e-5
1:0 (rep 1),3-Recover,170.067,2.459,0.615,0.05,,0.200065,636.62,,20.0065,0.63662,,,,7.85398e-5
1:0 (rep 1),3-Recover,170.433,2.482,0.592,0.043,,0.192583,547.493,,19.2583,0.547493,,,,7.85398e-5
1:0 (rep 1),3-Recover,170.8,2.505,0.569,0.043,,0.185101,547.493,,18.5101,0.547493,,,,7.85398e-5
1:0 (rep 1),3-Recover,171.167,2.527,0.547,0.03,,0.177944,381.972,,17.7944,0.381972,,,,7.85398e-5
1:0 (rep 1),3-Recover,171.533,2.55,0.524,0.043,,0.170462,547.493,,17.0462,0.547493,,,,7.85398e-5
1:0 (rep 1),3-Recover,171.9,2.572,0.502,0.036,,0.163305,458.366,,16.3305,0.458366,,,,7.85398e-5
1:0 (rep 1),3-Recover,172.267,2.595,0.479,0.03,,0.155823,381.972,,15.5823,0.381972,,,,7.85398e-5
1:0 (rep 1),3-Recover,172.633,2.617,0.457,0.016,,0.148666,203.718,,14.8666,0.203718,,,,7.85398e-5
1:0 (rep 1),3-Recover,173,2.64,0.434,0.009,,0.141184,114.592,,14.1184,0.114592,,,,7.85398e-5
1:0 (rep 1),3-Recover,173.367,2.662,0.412,0.009,,0.134027,114.592,,13.4027,0.114592,,,,7.85398e-5
1:0 (rep 1),3-Recover,173.733,2.685,0.389,0.009,,0.126545,114.592,,12.6545,0.114592,,,,7.85398e-5
1:0 (rep 1),3-Recover,174.1,2.708,0.366,0.03,,0.119063,381.972,,11.9063,0.381972,,,,7.85398e-5
1:0 (rep 1),3-Recover,174.467,2.73,0.344,0.009,,0.111906,114.592,,11.1906,0.114592,,,,7.85398e-5
1:0 (rep 1),3-Recover,174.833,2.753,0.321,0.002,,0.104424,25.4648,,10.4424,0.0254648,,,,7.85398e-5
1:0 (rep 1),3-Recover,175.2,2.775,0.299,0.002,,0.0972674,25.4648,,9.72674,0.0254648,,,,7.85398e-5
1:0 (rep 1),3-Recover,175.567,2.798,0.276,-0.004,,0.0897853,-50.9296,,8.97853,-0.0509296,,,,7.85398e-5
1:0 (rep 1),3-Recover,175.933,2.82,0.254,0.002,,0.0826285,25.4648,,8.26285,0.0254648,,,,7.85398e-5
1:0 (rep 1),3-Recover,176.3,2.843,0.231,0.009,,0.0751464,114.592,,7.51464,0.114592,,,,7.85398e-5
1:0 (rep 1),3-Recover,176.667,2.866,0.208,0.002,,0.0676643,25.4648,,6.76643,0.0254648,,,,7.85398e-5
1:0 (rep 1),3-Recover,177.033,2.888,0.186,-0.004,,0.0605075,-50.9296,,6.05075,-0.0509296,,,,7.85398e-5
1:0 (rep 1),3-Recover,177.4,2.911,0.163,0.002,,0.0530254,25.4648,,5.30254,0.0254648,,,,7.85398e-5
1:0 (rep 1),3-Recover,177.767,2.934,0.14,0.002,,0.0455433,25.4648,,4.55433,0.0254648,,,,7.85398e-5
1:0 (rep 1),3-Recover,178.133,2.955,0.119,0.002,,0.0387118,25.4648,,3.87118,0.0254648,,,,7.85398e-5
1:0 (rep 1),3-Recover,178.5,2.979,0.095,0.002,,0.0309044,25.4648,,3.09044,0.0254648,,,,7.85398e-5
1:0 (rep 1),3-Recover,178.867,3.001,0.073,0.016,,0.0237476,203.718,,2.37476,0.203718,,,,7.85398e-5
1:0 (rep 1),3-Recover,179.233,3.023,0.051,0.002,,0.0165908,25.4648,,1.65908,0.0254648,,,,7.85398e-5
1:0 (rep 1),3-Recover,179.6,3.046,0.028,0.002,,0.00910865,25.4648,,0.910865,0.0254648,,,,7.85398e-5
1:0 (rep 1),3-Recover,179.967,3.069,0.005,-0.004,,0.00162655,-50.9296,,0.162655,-0.0509296,,,,7.85398e-5
1:0 (rep 1),3-Recover,180.1,3.074,0,0.002,,0,25.4648,,0,0.0254648,,,,7.85398e-5