File: data/beta_1-1-0.25_3.csv
SetName,Cycle,Time_S,Size_mm,Displacement_mm,Force_N,,Strain,Stress(Pascal),,%Strain,Stress(kPa),,,,Area(m^2)
1:0.25 (rep 3),1-Compress,0,3.626,0,0.038,,0,483.831,,0,0.483831,,,,7.85398e-5
1:0.25 (rep 3),1-Compress,0.367,3.6,0.026,0.025,,0.00717044,318.31,,0.717044,0.31831,,,,7.85398e-5
1:0.25 (rep 3),1-Compress,0.733,3.574,0.052,0.025,,0.0143409,318.31,,1.43409,0.31831,,,,7.85398e-5
1:0.25 (rep 3),1-Compress,1.1,3.547,0.079,0.025,,0.0217871,318.31,,2.17871,0.31831,,,,7.85398e-5
1:0.25 (rep 3),1-Compress,1.467,3.52,0.106,0.018,,0.0292333,229.183,,2.92333,0.229183,,,,7.85398e-5
1:0.25 (rep 3),1-Compress,1.833,3.494,0.132,0.018,,0.0364038,229.183,,3.64038,0.229183,,,,7.85398e-5
1:0.25 (rep 3),1-Compress,2.2,3.467,0.159,0.032,,0.04385,407.437,,4.385,0.407437,,,,7.85398e-5
1:0.25 (rep 3),1-Compress,2.567,3.44,0.186,0.052,,0.0512962,662.085,,5.12962,0.662085,,,,7.85398e-5
1:0.25 (rep 3),1-Compress,2.933,3.414,0.212,0.038,,0.0584666,483.831,,5.84666,0.483831,,,,7.85398e-5
1:0.25 (rep 3),1-Compress,3.3,3.387,0.239,0.038,,0.0659129,483.831,,6.59129,0.483831,,,,7.85398e-5
1:0.25 (rep 3),1-Compress,3.667,3.36,0.266,0.038,,0.0733591,483.831,,7.33591,0.483831,,,,7.85398e-5
1:0.25 (rep 3),1-Compress,4.033,3.334,0.292,0.025,,0.0805295,318.31,,8.05295,0.31831,,,,7.85398e-5
1:0.25 (rep 3),1-Compress,4.4,3.307,0.319,0.032,,0.0879757,407.437,,8.79757,0.407437,,,,7.85398e-5
1:0.25 (rep 3),1-Compress,4.767,3.28,0.346,0.045,,0.095422,572.958,,9.5422,0.572958,,,,7.85398e-5
1:0.25 (rep 3),1-Compress,5.133,3.254,0.372,0.059,,0.102592,751.211,,10.2592,0.751211,,,,7.85398e-5
1:0.25 (rep 3),1-Compress,5.5,3.227,0.399,0.052,,0.110039,662.085,,11.0039,0.662085,,,,7.85398e-5
1:0.25 (rep 3),1-Compress,5.867,3.2,0.426,0.066,,0.117485,840.338,,11.7485,0.840338,,,,7.85398e-5
1:0.25 (rep 3),1-Compress,6.233,3.174,0.452,0.052,,0.124655,662.085,,12.4655,0.662085,,,,7.85398e-5
1:0.25 (rep 3),1-Compress,6.6,3.147,0.479,0.052,,0.132101,662.085,,13.2101,0.662085,,,,7.85398e-5
1:0.25 (rep 3),1-Compress,6.967,3.12,0.506,0.059,,0.139548,751.211,,13.9548,0.751211,,,,7.85398e-5
1:0.25 (rep 3),1-Compress,7.333,3.094,0.532,0.066,,0.146718,840.338,,14.6718,0.840338,,,,7.85398e-5
1:0.25 (rep 3),1-Compress,7.7,3.067,0.559,0.059,,0.154164,751.211,,15.4164,0.751211,,,,7.85398e-5
1:0.25 (rep 3),1-Compress,8.067,3.04,0.586,0.066,,0.161611,840.338,,16.1611,0.840338,,,,7.85398e-5
1:0.25 (rep 3),1-Compress,8.433,3.015,0.611,0.066,,0.168505,840.338,,16.8505,0.840338,,,,7.85398e-5
1:0.25 (rep 3),1-Compress,8.8,2.987,0.639,0.066,,0.176227,840.338,,17.6227,0.840338,,,,7.85398e-5
1:0.25 (rep 3),1-Compress,9.167,2.96,0.666,0.066,,0.183673,840.338,,18.3673,0.840338,,,,7.85398e-5
1:0.25 (rep 3),1-Compress,9.533,2.934,0.692,0.066,,0.190844,840.338,,19.0844,0.840338,,,,7.85398e-5
1:0.25 (rep 3),1-Compress,9.9,2.908,0.718,0.072,,0.198014,916.733,,19.8014,0.916733,,,,7.85398e-5
1:0.25 (rep 3),1-Compress,10.267,2.881,0.745,0.066,,0.205461,840.338,,20.5461,0.840338,,,,7.85398e-5
1:0.25 (rep 3),1-Compress,10.633,2.855,0.771,0.066,,0.212631,840.338,,21.2631,0.840338,,,,7.85398e-5
1:0.25 (rep 3),1-Compress,11,2.828,0.798,0.066,,0.220077,840.338,,22.0077,0.840338,,,,7.85398e-5
1:0.25 (rep 3),1-Compress,11.367,2.801,0.825,0.066,,0.227523,840.338,,22.7523,0.840338,,,,7.85398e-5
1:0.25 (rep 3),1-Compress,11.733,2.775,0.851,0.066,,0.234694,840.338,,23.4694,0.840338,,,,7.85398e-5
1:0.25 (rep 3),1-Compress,12.1,2.748,0.878,0.066,,0.24214,840.338,,24.214,0.840338,,,,7.85398e-5
1:0.25 (rep 3),1-Compress,12.467,2.721,0.905,0.072,,0.249586,916.733,,24.9586,0.916733,,,,7.85398e-5
1:0.25 (rep 3),1-Compress,12.833,2.694,0.932,0.066,,0.257033,840.338,,25.7033,0.840338,,,,7.85398e-5
1:0.25 (rep 3),1-Compress,13.2,2.668,0.958,0.072,,0.264203,916.733,,26.4203,0.916733,,,,7.85398e-5
1:0.25 (rep 3),1-Compress,13.567,2.641,0.985,0.066,,0.271649,840.338,,27.1649,0.840338,,,,7.85398e-5
1:0.25 (rep 3),1-Compress,13.933,2.615,1.011,0.072,,0.27882,916.733,,27.882,0.916733,,,,7.85398e-5
1:0.25 (rep 3),1-Compress,14.3,2.588,1.038,0.066,,0.286266,840.338,,28.6266,0.840338,,,,7.85398e-5
1:0.25 (rep 3),1-Compress,14.667,2.561,1.065,0.066,,0.293712,840.338,,29.3712,0.840338,,,,7.85398e-5
1:0.25 (rep 3),1-Compress,15.033,2.535,1.091,0.079,,0.300883,1005.86,,30.0883,1.00586,,,,7.85398e-5
1:0.25 (rep 3),1-Compress,15.4,2.508,1.118,0.086,,0.308329,1094.99,,30.8329,1.09499,,,,7.85398e-5
1:0.25 (rep 3),1-Compress,15.767,2.481,1.145,0.086,,0.315775,1094.99,,31.5775,1.09499,,,,7.85398e-5
1:0.25 (rep 3),1-Compress,16.133,2.455,1.171,0.086,,0.322945,1094.99,,32.2945,1.09499,,,,7.85398e-5
1:0.25 (rep 3),1-Compress,16.5,2.428,1.198,0.093,,0.330392,1184.11,,33.0392,1.18411,,,,7.85398e-5
1:0.25 (rep 3),1-Compress,16.867,2.401,1.225,0.106,,0.337838,1349.63,,33.7838,1.34963,,,,7.85398e-5
1:0.25 (rep 3),1-Compress,17.233,2.375,1.251,0.106,,0.345008,1349.63,,34.5008,1.34963,,,,7.85398e-5
1:0.25 (rep 3),1-Compress,17.6,2.348,1.278,0.113,,0.352454,1438.76,,35.2454,1.43876,,,,7.85398e-5
1:0.25 (rep 3),1-Compress,17.967,2.322,1.304,0.12,,0.359625,1527.89,,35.9625,1.52789,,,,7.85398e-5
1:0.25 (rep 3),1-Compress,18.333,2.295,1.331,0.12,,0.367071,1527.89,,36.7071,1.52789,,,,7.85398e-5
1:0.25 (rep 3),1-Compress,18.7,2.268,1.358,0.12,,0.374517,1527.89,,37.4517,1.52789,,,,7.85398e-5
1:0.25 (rep 3),1-Compress,19.067,2.242,1.384,0.12,,0.381688,1527.89,,38.1688,1.52789,,,,7.85398e-5
1:0.25 (rep 3),1-Compress,19.433,2.215,1.411,0.12,,0.389134,1527.89,,38.9134,1.52789,,,,7.85398e-5
1:0.25 (rep 3),1-Compress,19.8,2.188,1.438,0.12,,0.39658,1527.89,,39.658,1.52789,,,,7.85398e-5
1:0.25 (rep 3),1-Compress,20.167,2.162,1.464,0.12,,0.403751,1527.89,,40.3751,1.52789,,,,7.85398e-5
1:0.25 (rep 3),1-Compress,20.533,2.135,1.491,0.12,,0.411197,1527.89,,41.1197,1.52789,,,,7.85398e-5
1:0.25 (rep 3),1-Compress,20.9,2.108,1.518,0.127,,0.418643,1617.01,,41.8643,1.61701,,,,7.85398e-5
1:0.25 (rep 3),1-Compress,21.267,2.082,1.544,0.127,,0.425814,1617.01,,42.5814,1.61701,,,,7.85398e-5
1:0.25 (rep 3),1-Compress,21.633,2.056,1.57,0.12,,0.432984,1527.89,,43.2984,1.52789,,,,7.85398e-5
1:0.25 (rep 3),1-Compress,22,2.029,1.597,0.127,,0.44043,1617.01,,44.043,1.61701,,,,7.85398e-5
1:0.25 (rep 3),1-Compress,22.367,2.002,1.624,0.133,,0.447876,1693.41,,44.7876,1.69341,,,,7.85398e-5
1:0.25 (rep 3),1-Compress,22.733,1.976,1.65,0.133,,0.455047,1693.41,,45.5047,1.69341,,,,7.85398e-5
1:0.25 (rep 3),1-Compress,23.1,1.949,1.677,0.147,,0.462493,1871.66,,46.2493,1.87166,,,,7.85398e-5
1:0.25 (rep 3),1-Compress,23.467,1.922,1.704,0.154,,0.469939,1960.79,,46.9939,1.96079,,,,7.85398e-5
1:0.25 (rep 3),1-Compress,23.833,1.896,1.73,0.147,,0.47711,1871.66,,47.711,1.87166,,,,7.85398e-5
1:0.25 (rep 3),1-Compress,24.2,1.869,1.757,0.161,,0.484556,2049.92,,48.4556,2.04992,,,,7.85398e-5
1:0.25 (rep 3),1-Compress,24.567,1.842,1.784,0.174,,0.492002,2215.44,,49.2002,2.21544,,,,7.85398e-5
1:0.25 (rep 3),1-Compress,24.933,1.816,1.81,0.167,,0.499173,2126.31,,49.9173,2.12631,,,,7.85398e-5
1:0.25 (rep 3),1-Compress,25.3,1.789,1.837,0.174,,0.506619,2215.44,,50.6619,2.21544,,,,7.85398e-5
1:0.25 (rep 3),1-Compress,25.667,1.762,1.864,0.174,,0.514065,2215.44,,51.4065,2.21544,,,,7.85398e-5
1:0.25 (rep 3),1-Compress,26.033,1.736,1.89,0.174,,0.521236,2215.44,,52.1236,2.21544,,,,7.85398e-5
1:0.25 (rep 3),1-Compress,26.4,1.709,1.917,0.174,,0.528682,2215.44,,52.8682,2.21544,,,,7.85398e-5
1:0.25 (rep 3),1-Compress,26.767,1.682,1.944,0.174,,0.536128,2215.44,,53.6128,2.21544,,,,7.85398e-5
1:0.25 (rep 3),1-Compress,27.133,1.656,1.97,0.174,,0.543298,2215.44,,54.3298,2.21544,,,,7.85398e-5
1:0.25 (rep 3),1-Compress,27.5,1.629,1.997,0.174,,0.550745,2215.44,,55.0745,2.21544,,,,7.85398e-5
1:0.25 (rep 3),1-Compress,27.867,1.602,2.024,0.167,,0.558191,2126.31,,55.8191,2.12631,,,,7.85398e-5
1:0.25 (rep 3),1-Compress,28.233,1.576,2.05,0.181,,0.565361,2304.56,,56.5361,2.30456,,,,7.85398e-5
1:0.25 (rep 3),1-Compress,28.6,1.549,2.077,0.181,,0.572808,2304.56,,57.2808,2.30456,,,,7.85398e-5
1:0.25 (rep 3),1-Compress,28.967,1.522,2.104,0.215,,0.580254,2737.47,,58.0254,2.73747,,,,7.85398e-5
1:0.25 (rep 3),1-Compress,29.333,1.496,2.13,0.222,,0.587424,2826.59,,58.7424,2.82659,,,,7.85398e-5
1:0.25 (rep 3),1-Compress,29.7,1.469,2.157,0.229,,0.59487,2915.72,,59.487,2.91572,,,,7.85398e-5
1:0.25 (rep 3),1-Recover,30.067,1.453,2.173,0.215,,0.599283,2737.47,,59.9283,2.73747,,,,7.85398e-5
1:0.25 (rep 3),1-Recover,30.433,1.48,2.146,0.201,,0.591837,2559.21,,59.1837,2.55921,,,,7.85398e-5
1:0.25 (rep 3),1-Recover,30.8,1.506,2.12,0.208,,0.584666,2648.34,,58.4666,2.64834,,,,7.85398e-5
1:0.25 (rep 3),1-Recover,31.167,1.533,2.093,0.201,,0.57722,2559.21,,57.722,2.55921,,,,7.85398e-5
1:0.25 (rep 3),1-Recover,31.533,1.56,2.066,0.188,,0.569774,2393.69,,56.9774,2.39369,,,,7.85398e-5
1:0.25 (rep 3),1-Recover,31.9,1.586,2.04,0.174,,0.562603,2215.44,,56.2603,2.21544,,,,7.85398e-5
1:0.25 (rep 3),1-Recover,32.267,1.613,2.013,0.174,,0.555157,2215.44,,55.5157,2.21544,,,,7.85398e-5
1:0.25 (rep 3),1-Recover,32.633,1.639,1.987,0.174,,0.547987,2215.44,,54.7987,2.21544,,,,7.85398e-5
1:0.25 (rep 3),1-Recover,33,1.666,1.96,0.174,,0.540541,2215.44,,54.0541,2.21544,,,,7.85398e-5
1:0.25 (rep 3),1-Recover,33.367,1.693,1.933,0.167,,0.533094,2126.31,,53.3094,2.12631,,,,7.85398e-5
1:0.25 (rep 3),1-Recover,33.733,1.719,1.907,0.174,,0.525924,2215.44,,52.5924,2.21544,,,,7.85398e-5
1:0.25 (rep 3),1-Recover,34.1,1.746,1.88,0.174,,0.518478,2215.44,,51.8478,2.21544,,,,7.85398e-5
1:0.25 (rep 3),1-Recover,34.467,1.773,1.853,0.167,,0.511031,2126.31,,51.1031,2.12631,,,,7.85398e-5
1:0.25 (rep 3),1-Recover,34.833,1.799,1.827,0.147,,0.503861,1871.66,,50.3861,1.87166,,,,7.85398e-5
1:0.25 (rep 3),1-Recover,35.2,1.826,1.8,0.154,,0.496415,1960.79,,49.6415,1.96079,,,,7.85398e-5
1:0.25 (rep 3),1-Recover,35.567,1.853,1.773,0.154,,0.488969,1960.79,,48.8969,1.96079,,,,7.85398e-5
1:0.25 (rep 3),1-Recover,35.933,1.879,1.747,0.14,,0.481798,1782.54,,48.1798,1.78254,,,,7.85398e-5
1:0.25 (rep 3),1-Recover,36.3,1.906,1.72,0.127,,0.474352,1617.01,,47.4352,1.61701,,,,7.85398e-5
1:0.25 (rep 3),1-Recover,36.667,1.933,1.693,0.127,,0.466906,1617.01,,46.6906,1.61701,,,,7.85398e-5
1:0.25 (rep 3),1-Recover,37.033,1.959,1.667,0.12,,0.459735,1527.89,,45.9735,1.52789,,,,7.85398e-5
1:0.25 (rep 3),1-Recover,37.4,1.986,1.64,0.12,,0.452289,1527.89,,45.2289,1.52789,,,,7.85398e-5
1:0.25 (rep 3),1-Recover,37.767,2.013,1.613,0.12,,0.444843,1527.89,,44.4843,1.52789,,,,7.85398e-5
1:0.25 (rep 3),1-Recover,38.133,2.039,1.587,0.12,,0.437672,1527.89,,43.7672,1.52789,,,,7.85398e-5
1:0.25 (rep 3),1-Recover,38.5,2.066,1.56,0.12,,0.430226,1527.89,,43.0226,1.52789,,,,7.85398e-5
1:0.25 (rep 3),1-Recover,38.867,2.093,1.533,0.12,,0.42278,1527.89,,42.278,1.52789,,,,7.85398e-5
1:0.25 (rep 3),1-Recover,39.233,2.119,1.507,0.113,,0.415609,1438.76,,41.5609,1.43876,,,,7.85398e-5
1:0.25 (rep 3),1-Recover,39.6,2.146,1.48,0.099,,0.408163,1260.51,,40.8163,1.26051,,,,7.85398e-5
1:0.25 (rep 3),1-Recover,39.967,2.172,1.454,0.113,,0.400993,1438.76,,40.0993,1.43876,,,,7.85398e-5
1:0.25 (rep 3),1-Recover,40.333,2.198,1.428,0.106,,0.393822,1349.63,,39.3822,1.34963,,,,7.85398e-5
1:0.25 (rep 3),1-Recover,40.7,2.226,1.4,0.106,,0.3861,1349.63,,38.61,1.34963,,,,7.85398e-5
1:0.25 (rep 3),1-Recover,41.067,2.252,1.374,0.093,,0.37893,1184.11,,37.893,1.18411,,,,7.85398e-5
1:0.25 (rep 3),1-Recover,41.433,2.278,1.348,0.099,,0.37176,1260.51,,37.176,1.26051,,,,7.85398e-5
1:0.25 (rep 3),1-Recover,41.8,2.305,1.321,0.079,,0.364313,1005.86,,36.4313,1.00586,,,,7.85398e-5
1:0.25 (rep 3),1-Recover,42.167,2.332,1.294,0.072,,0.356867,916.733,,35.6867,0.916733,,,,7.85398e-5
1:0.25 (rep 3),1-Recover,42.533,2.359,1.267,0.086,,0.349421,1094.99,,34.9421,1.09499,,,,7.85398e-5
1:0.25 (rep 3),1-Recover,42.9,2.385,1.241,0.079,,0.34225,1005.86,,34.225,1.00586,,,,7.85398e-5
1:0.25 (rep 3),1-Recover,43.267,2.412,1.214,0.072,,0.334804,916.733,,33.4804,0.916733,,,,7.85398e-5
1:0.25 (rep 3),1-Recover,43.633,2.438,1.188,0.072,,0.327634,916.733,,32.7634,0.916733,,,,7.85398e-5
1:0.25 (rep 3),1-Recover,44,2.465,1.161,0.072,,0.320188,916.733,,32.0188,0.916733,,,,7.85398e-5
1:0.25 (rep 3),1-Recover,44.367,2.492,1.134,0.066,,0.312741,840.338,,31.2741,0.840338,,,,7.85398e-5
1:0.25 (rep 3),1-Recover,44.733,2.518,1.108,0.066,,0.305571,840.338,,30.5571,0.840338,,,,7.85398e-5
1:0.25 (rep 3),1-Recover,45.1,2.545,1.081,0.066,,0.298125,840.338,,29.8125,0.840338,,,,7.85398e-5
1:0.25 (rep 3),1-Recover,45.467,2.572,1.054,0.066,,0.290678,840.338,,29.0678,0.840338,,,,7.85398e-5
1:0.25 (rep 3),1-Recover,45.833,2.598,1.028,0.066,,0.283508,840.338,,28.3508,0.840338,,,,7.85398e-5
1:0.25 (rep 3),1-Recover,46.2,2.625,1.001,0.066,,0.276062,840.338,,27.6062,0.840338,,,,7.85398e-5
1:0.25 (rep 3),1-Recover,46.567,2.652,0.974,0.066,,0.268616,840.338,,26.8616,0.840338,,,,7.85398e-5
1:0.25 (rep 3),1-Recover,46.933,2.678,0.948,0.066,,0.261445,840.338,,26.1445,0.840338,,,,7.85398e-5
1:0.25 (rep 3),1-Recover,47.3,2.705,0.921,0.066,,0.253999,840.338,,25.3999,0.840338,,,,7.85398e-5
1:0.25 (rep 3),1-Recover,47.667,2.732,0.894,0.072,,0.246553,916.733,,24.6553,0.916733,,,,7.85398e-5
1:0.25 (rep 3),1-Recover,48.033,2.758,0.868,0.066,,0.239382,840.338,,23.9382,0.840338,,,,7.85398e-5
1:0.25 (rep 3),1-Recover,48.4,2.785,0.841,0.066,,0.231936,840.338,,23.1936,0.840338,,,,7.85398e-5
1:0.25 (rep 3),1-Recover,48.767,2.812,0.814,0.059,,0.22449,751.211,,22.449,0.751211,,,,7.85398e-5
1:0.25 (rep 3),1-Recover,49.133,2.838,0.788,0.066,,0.217319,840.338,,21.7319,0.840338,,,,7.85398e-5
1:0.25 (rep 3),1-Recover,49.5,2.865,0.761,0.059,,0.209873,751.211,,20.9873,0.751211,,,,7.85398e-5
1:0.25 (rep 3),1-Recover,49.867,2.891,0.735,0.066,,0.202703,840.338,,20.2703,0.840338,,,,7.85398e-5
1:0.25 (rep 3),1-Recover,50.233,2.918,0.708,0.059,,0.195256,751.211,,19.5256,0.751211,,,,7.85398e-5
1:0.25 (rep 3),1-Recover,50.6,2.945,0.681,0.066,,0.18781,840.338,,18.781,0.840338,,,,7.85398e-5
1:0.25 (rep 3),1-Recover,50.967,2.971,0.655,0.052,,0.18064,662.085,,18.064,0.662085,,,,7.85398e-5
1:0.25 (rep 3),1-Recover,51.333,2.998,0.628,0.032,,0.173194,407.437,,17.3194,0.407437,,,,7.85398e-5
1:0.25 (rep 3),1-Recover,51.7,3.024,0.602,0.038,,0.166023,483.831,,16.6023,0.483831,,,,7.85398e-5
1:0.25 (rep 3),1-Recover,52.067,3.051,0.575,0.045,,0.158577,572.958,,15.8577,0.572958,,,,7.85398e-5
1:0.25 (rep 3),1-Recover,52.433,3.078,0.548,0.032,,0.151131,407.437,,15.1131,0.407437,,,,7.85398e-5
1:0.25 (rep 3),1-Recover,52.8,3.104,0.522,0.038,,0.14396,483.831,,14.396,0.483831,,,,7.85398e-5
1:0.25 (rep 3),1-Recover,53.167,3.131,0.495,0.045,,0.136514,572.958,,13.6514,0.572958,,,,7.85398e-5
1:0.25 (rep 3),1-Recover,53.533,3.157,0.469,0.045,,0.129344,572.958,,12.9344,0.572958,,,,7.85398e-5
1:0.25 (rep 3),1-Recover,53.9,3.184,0.442,0.038,,0.121897,483.831,,12.1897,0.483831,,,,7.85398e-5
1:0.25 (rep 3),1-Recover,54.267,3.211,0.415,0.038,,0.114451,483.831,,11.4451,0.483831,,,,7.85398e-5
1:0.25 (rep 3),1-Recover,54.633,3.237,0.389,0.018,,0.107281,229.183,,10.7281,0.229183,,,,7.85398e-5
1:0.25 (rep 3),1-Recover,55,3.264,0.362,0.032,,0.0998345,407.437,,9.98345,0.407437,,,,7.85398e-5
1:0.25 (rep 3),1-Recover,55.367,3.291,0.335,0.032,,0.0923883,407.437,,9.23883,0.407437,,,,7.85398e-5
1:0.25 (rep 3),1-Recover,55.733,3.317,0.309,0.038,,0.0852179,483.831,,8.52179,0.483831,,,,7.85398e-5
1:0.25 (rep 3),1-Recover,56.1,3.344,0.282,0.025,,0.0777716,318.31,,7.77716,0.31831,,,,7.85398e-5
1:0.25 (rep 3),1-Recover,56.467,3.371,0.255,0.018,,0.0703254,229.183,,7.03254,0.229183,,,,7.85398e-5
1:0.25 (rep 3),1-Recover,56.833,3.397,0.229,0.025,,0.063155,318.31,,6.3155,0.31831,,,,7.85398e-5
1:0.25 (rep 3),1-Recover,57.2,3.424,0.202,0.018,,0.0557088,229.183,,5.57088,0.229183,,,,7.85398e-5
1:0.25 (rep 3),1-Recover,57.567,3.451,0.175,0.025,,0.0482625,318.31,,4.82625,0.31831,,,,7.85398e-5
1:0.25 (rep 3),1-Recover,57.933,3.477,0.149,0.032,,0.0410921,407.437,,4.10921,0.407437,,,,7.85398e-5
1:0.25 (rep 3),1-Recover,58.3,3.504,0.122,0.025,,0.0336459,318.31,,3.36459,0.31831,,,,7.85398e-5
1:0.25 (rep 3),1-Recover,58.667,3.531,0.095,0.018,,0.0261997,229.183,,2.61997,0.229183,,,,7.85398e-5
1:0.25 (rep 3),1-Recover,59.033,3.557,0.069,0.018,,0.0190292,229.183,,1.90292,0.229183,,,,7.85398e-5
1:0.25 (rep 3),1-Recover,59.4,3.584,0.042,0.018,,0.011583,229.183,,1.1583,0.229183,,,,7.85398e-5
1:0.25 (rep 3),1-Recover,59.767,3.611,0.015,0.018,,0.00413679,229.183,,0.413679,0.229183,,,,7.85398e-5
1:0.25 (rep 3),2-Compress,60.117,3.62,0.006,0.025,,0.00165472,318.31,,0.165472,0.31831,,,,7.85398e-5
1:0.25 (rep 3),2-Compress,60.483,3.594,0.032,0.038,,0.00882515,483.831,,0.882515,0.483831,,,,7.85398e-5
1:0.25 (rep 3),2-Compress,60.85,3.567,0.059,0.018,,0.0162714,229.183,,1.62714,0.229183,,,,7.85398e-5
1:0.25 (rep 3),2-Compress,61.217,3.541,0.085,0.025,,0.0234418,318.31,,2.34418,0.31831,,,,7.85398e-5
1:0.25 (rep 3),2-Compress,61.583,3.515,0.111,0.018,,0.0306122,229.183,,3.06122,0.229183,,,,7.85398e-5
1:0.25 (rep 3),2-Compress,61.95,3.487,0.139,0.018,,0.0383343,229.183,,3.83343,0.229183,,,,7.85398e-5
1:0.25 (rep 3),2-Compress,62.317,3.461,0.165,0.018,,0.0455047,229.183,,4.55047,0.229183,,,,7.85398e-5
1:0.25 (rep 3),2-Compress,62.683,3.435,0.191,0.025,,0.0526751,318.31,,5.26751,0.31831,,,,7.85398e-5
1:0.25 (rep 3),2-Compress,63.05,3.408,0.218,0.045,,0.0601213,572.958,,6.01213,0.572958,,,,7.85398e-5
1:0.25 (rep 3),2-Compress,63.417,3.381,0.245,0.032,,0.0675676,407.437,,6.75676,0.407437,,,,7.85398e-5
1:0.25 (rep 3),2-Compress,63.783,3.355,0.271,0.025,,0.074738,318.31,,7.4738,0.31831,,,,7.85398e-5
1:0.25 (rep 3),2-Compress,64.15,3.328,0.298,0.025,,0.0821842,318.31,,8.21842,0.31831,,,,7.85398e-5
1:0.25 (rep 3),2-Compress,64.517,3.301,0.325,0.018,,0.0896304,229.183,,8.96304,0.229183,,,,7.85398e-5
1:0.25 (rep 3),2-Compress,64.883,3.275,0.351,0.025,,0.0968009,318.31,,9.68009,0.31831,,,,7.85398e-5
1:0.25 (rep 3),2-Compress,65.25,3.248,0.378,0.045,,0.104247,572.958,,10.4247,0.572958,,,,7.85398e-5
1:0.25 (rep 3),2-Compress,65.617,3.221,0.405,0.052,,0.111693,662.085,,11.1693,0.662085,,,,7.85398e-5
1:0.25 (rep 3),2-Compress,65.983,3.195,0.431,0.045,,0.118864,572.958,,11.8864,0.572958,,,,7.85398e-5
1:0.25 (rep 3),2-Compress,66.35,3.168,0.458,0.052,,0.12631,662.085,,12.631,0.662085,,,,7.85398e-5
1:0.25 (rep 3),2-Compress,66.717,3.141,0.485,0.045,,0.133756,572.958,,13.3756,0.572958,,,,7.85398e-5
1:0.25 (rep 3),2-Compress,67.083,3.115,0.511,0.052,,0.140927,662.085,,14.0927,0.662085,,,,7.85398e-5
1:0.25 (rep 3),2-Compress,67.45,3.088,0.538,0.066,,0.148373,840.338,,14.8373,0.840338,,,,7.85398e-5
1:0.25 (rep 3),2-Compress,67.817,3.061,0.565,0.066,,0.155819,840.338,,15.5819,0.840338,,,,7.85398e-5
1:0.25 (rep 3),2-Compress,68.183,3.035,0.591,0.059,,0.16299,751.211,,16.299,0.751211,,,,7.85398e-5
1:0.25 (rep 3),2-Compress,68.55,3.008,0.618,0.066,,0.170436,840.338,,17.0436,0.840338,,,,7.85398e-5
1:0.25 (rep 3),2-Compress,68.917,2.981,0.645,0.066,,0.177882,840.338,,17.7882,0.840338,,,,7.85398e-5
1:0.25 (rep 3),2-Compress,69.283,2.955,0.671,0.066,,0.185052,840.338,,18.5052,0.840338,,,,7.85398e-5
1:0.25 (rep 3),2-Compress,69.65,2.928,0.698,0.066,,0.192499,840.338,,19.2499,0.840338,,,,7.85398e-5
1:0.25 (rep 3),2-Compress,70.017,2.901,0.725,0.066,,0.199945,840.338,,19.9945,0.840338,,,,7.85398e-5
1:0.25 (rep 3),2-Compress,70.383,2.875,0.751,0.066,,0.207115,840.338,,20.7115,0.840338,,,,7.85398e-5
1:0.25 (rep 3),2-Compress,70.75,2.849,0.777,0.066,,0.214286,840.338,,21.4286,0.840338,,,,7.85398e-5
1:0.25 (rep 3),2-Compress,71.117,2.822,0.804,0.066,,0.221732,840.338,,22.1732,0.840338,,,,7.85398e-5
1:0.25 (rep 3),2-Compress,71.483,2.795,0.831,0.066,,0.229178,840.338,,22.9178,0.840338,,,,7.85398e-5
1:0.25 (rep 3),2-Compress,71.85,2.769,0.857,0.066,,0.236349,840.338,,23.6349,0.840338,,,,7.85398e-5
1:0.25 (rep 3),2-Compress,72.217,2.742,0.884,0.066,,0.243795,840.338,,24.3795,0.840338,,,,7.85398e-5
1:0.25 (rep 3),2-Compress,72.583,2.716,0.91,0.066,,0.250965,840.338,,25.0965,0.840338,,,,7.85398e-5
1:0.25 (rep 3),2-Compress,72.95,2.689,0.937,0.072,,0.258411,916.733,,25.8411,0.916733,,,,7.85398e-5
1:0.25 (rep 3),2-Compress,73.317,2.662,0.964,0.066,,0.265858,840.338,,26.5858,0.840338,,,,7.85398e-5
1:0.25 (rep 3),2-Compress,73.683,2.635,0.991,0.072,,0.273304,916.733,,27.3304,0.916733,,,,7.85398e-5
1:0.25 (rep 3),2-Compress,74.05,2.609,1.017,0.072,,0.280474,916.733,,28.0474,0.916733,,,,7.85398e-5
1:0.25 (rep 3),2-Compress,74.417,2.582,1.044,0.072,,0.287921,916.733,,28.7921,0.916733,,,,7.85398e-5
1:0.25 (rep 3),2-Compress,74.783,2.556,1.07,0.066,,0.295091,840.338,,29.5091,0.840338,,,,7.85398e-5
1:0.25 (rep 3),2-Compress,75.15,2.529,1.097,0.072,,0.302537,916.733,,30.2537,0.916733,,,,7.85398e-5
1:0.25 (rep 3),2-Compress,75.517,2.502,1.124,0.072,,0.309983,916.733,,30.9983,0.916733,,,,7.85398e-5
1:0.25 (rep 3),2-Compress,75.883,2.476,1.15,0.093,,0.317154,1184.11,,31.7154,1.18411,,,,7.85398e-5
1:0.25 (rep 3),2-Compress,76.25,2.449,1.177,0.086,,0.3246,1094.99,,32.46,1.09499,,,,7.85398e-5
1:0.25 (rep 3),2-Compress,76.617,2.422,1.204,0.099,,0.332046,1260.51,,33.2046,1.26051,,,,7.85398e-5
1:0.25 (rep 3),2-Compress,76.983,2.396,1.23,0.086,,0.339217,1094.99,,33.9217,1.09499,,,,7.85398e-5
1:0.25 (rep 3),2-Compress,77.35,2.369,1.257,0.079,,0.346663,1005.86,,34.6663,1.00586,,,,7.85398e-5
1:0.25 (rep 3),2-Compress,77.717,2.342,1.284,0.106,,0.354109,1349.63,,35.4109,1.34963,,,,7.85398e-5
1:0.25 (rep 3),2-Compress,78.083,2.316,1.31,0.099,,0.36128,1260.51,,36.128,1.26051,,,,7.85398e-5
1:0.25 (rep 3),2-Compress,78.45,2.289,1.337,0.113,,0.368726,1438.76,,36.8726,1.43876,,,,7.85398e-5
1:0.25 (rep 3),2-Compress,78.817,2.262,1.364,0.12,,0.376172,1527.89,,37.6172,1.52789,,,,7.85398e-5
1:0.25 (rep 3),2-Compress,79.183,2.236,1.39,0.12,,0.383343,1527.89,,38.3343,1.52789,,,,7.85398e-5
1:0.25 (rep 3),2-Compress,79.55,2.209,1.417,0.12,,0.390789,1527.89,,39.0789,1.52789,,,,7.85398e-5
1:0.25 (rep 3),2-Compress,79.917,2.182,1.444,0.12,,0.398235,1527.89,,39.8235,1.52789,,,,7.85398e-5
1:0.25 (rep 3),2-Compress,80.283,2.156,1.47,0.12,,0.405405,1527.89,,40.5405,1.52789,,,,7.85398e-5
1:0.25 (rep 3),2-Compress,80.65,2.129,1.497,0.12,,0.412852,1527.89,,41.2852,1.52789,,,,7.85398e-5
1:0.25 (rep 3),2-Compress,81.017,2.102,1.524,0.12,,0.420298,1527.89,,42.0298,1.52789,,,,7.85398e-5
1:0.25 (rep 3),2-Compress,81.383,2.076,1.55,0.12,,0.427468,1527.89,,42.7468,1.52789,,,,7.85398e-5
1:0.25 (rep 3),2-Compress,81.75,2.049,1.577,0.12,,0.434915,1527.89,,43.4915,1.52789,,,,7.85398e-5
1:0.25 (rep 3),2-Compress,82.117,2.023,1.603,0.127,,0.442085,1617.01,,44.2085,1.61701,,,,7.85398e-5
1:0.25 (rep 3),2-Compress,82.483,1.997,1.629,0.12,,0.449255,1527.89,,44.9255,1.52789,,,,7.85398e-5
1:0.25 (rep 3),2-Compress,82.85,1.969,1.657,0.127,,0.456977,1617.01,,45.6977,1.61701,,,,7.85398e-5
1:0.25 (rep 3),2-Compress,83.217,1.943,1.683,0.147,,0.464148,1871.66,,46.4148,1.87166,,,,7.85398e-5
1:0.25 (rep 3),2-Compress,83.583,1.917,1.709,0.154,,0.471318,1960.79,,47.1318,1.96079,,,,7.85398e-5
1:0.25 (rep 3),2-Compress,83.95,1.89,1.736,0.147,,0.478764,1871.66,,47.8764,1.87166,,,,7.85398e-5
1:0.25 (rep 3),2-Compress,84.317,1.863,1.763,0.161,,0.486211,2049.92,,48.6211,2.04992,,,,7.85398e-5
1:0.25 (rep 3),2-Compress,84.683,1.837,1.789,0.167,,0.493381,2126.31,,49.3381,2.12631,,,,7.85398e-5
1:0.25 (rep 3),2-Compress,85.05,1.81,1.816,0.167,,0.500827,2126.31,,50.0827,2.12631,,,,7.85398e-5
1:0.25 (rep 3),2-Compress,85.417,1.783,1.843,0.174,,0.508274,2215.44,,50.8274,2.21544,,,,7.85398e-5
1:0.25 (rep 3),2-Compress,85.783,1.757,1.869,0.174,,0.515444,2215.44,,51.5444,2.21544,,,,7.85398e-5
1:0.25 (rep 3),2-Compress,86.15,1.73,1.896,0.174,,0.52289,2215.44,,52.289,2.21544,,,,7.85398e-5
1:0.25 (rep 3),2-Compress,86.517,1.703,1.923,0.174,,0.530336,2215.44,,53.0336,2.21544,,,,7.85398e-5
1:0.25 (rep 3),2-Compress,86.883,1.677,1.949,0.174,,0.537507,2215.44,,53.7507,2.21544,,,,7.85398e-5
1:0.25 (rep 3),2-Compress,87.25,1.65,1.976,0.174,,0.544953,2215.44,,54.4953,2.21544,,,,7.85398e-5
1:0.25 (rep 3),2-Compress,87.617,1.623,2.003,0.174,,0.552399,2215.44,,55.2399,2.21544,,,,7.85398e-5
1:0.25 (rep 3),2-Compress,87.983,1.597,2.029,0.174,,0.55957,2215.44,,55.957,2.21544,,,,7.85398e-5
1:0.25 (rep 3),2-Compress,88.35,1.57,2.056,0.174,,0.567016,2215.44,,56.7016,2.21544,,,,7.85398e-5
1:0.25 (rep 3),2-Compress,88.717,1.543,2.083,0.181,,0.574462,2304.56,,57.4462,2.30456,,,,7.85398e-5
1:0.25 (rep 3),2-Compress,89.083,1.517,2.109,0.188,,0.581633,2393.69,,58.1633,2.39369,,,,7.85398e-5
1:0.25 (rep 3),2-Compress,89.45,1.49,2.136,0.222,,0.589079,2826.59,,58.9079,2.82659,,,,7.85398e-5
1:0.25 (rep 3),2-Compress,89.817,1.463,2.163,0.174,,0.596525,2215.44,,59.6525,2.21544,,,,7.85398e-5
1:0.25 (rep 3),2-Recover,90.17,1.458,2.168,0.174,,0.597904,2215.44,,59.7904,2.21544,,,,7.85398e-5
1:0.25 (rep 3),2-Recover,90.537,1.485,2.141,0.174,,0.590458,2215.44,,59.0458,2.21544,,,,7.85398e-5
1:0.25 (rep 3),2-Recover,90.903,1.511,2.115,0.167,,0.583287,2126.31,,58.3287,2.12631,,,,7.85398e-5
1:0.25 (rep 3),2-Recover,91.27,1.538,2.088,0.174,,0.575841,2215.44,,57.5841,2.21544,,,,7.85398e-5
1:0.25 (rep 3),2-Recover,91.637,1.565,2.061,0.174,,0.568395,2215.44,,56.8395,2.21544,,,,7.85398e-5
1:0.25 (rep 3),2-Recover,92.003,1.591,2.035,0.174,,0.561224,2215.44,,56.1224,2.21544,,,,7.85398e-5
1:0.25 (rep 3),2-Recover,92.37,1.618,2.008,0.174,,0.553778,2215.44,,55.3778,2.21544,,,,7.85398e-5
1:0.25 (rep 3),2-Recover,92.737,1.645,1.981,0.161,,0.546332,2049.92,,54.6332,2.04992,,,,7.85398e-5
1:0.25 (rep 3),2-Recover,93.103,1.671,1.955,0.154,,0.539162,1960.79,,53.9162,1.96079,,,,7.85398e-5
1:0.25 (rep 3),2-Recover,93.47,1.698,1.928,0.161,,0.531715,2049.92,,53.1715,2.04992,,,,7.85398e-5
1:0.25 (rep 3),2-Recover,93.837,1.725,1.901,0.14,,0.524269,1782.54,,52.4269,1.78254,,,,7.85398e-5
1:0.25 (rep 3),2-Recover,94.203,1.751,1.875,0.133,,0.517099,1693.41,,51.7099,1.69341,,,,7.85398e-5
1:0.25 (rep 3),2-Recover,94.57,1.777,1.849,0.133,,0.509928,1693.41,,50.9928,1.69341,,,,7.85398e-5
1:0.25 (rep 3),2-Recover,94.937,1.804,1.822,0.127,,0.502482,1617.01,,50.2482,1.61701,,,,7.85398e-5
1:0.25 (rep 3),2-Recover,95.303,1.831,1.795,0.127,,0.495036,1617.01,,49.5036,1.61701,,,,7.85398e-5
1:0.25 (rep 3),2-Recover,95.67,1.857,1.769,0.127,,0.487865,1617.01,,48.7865,1.61701,,,,7.85398e-5
1:0.25 (rep 3),2-Recover,96.037,1.884,1.742,0.127,,0.480419,1617.01,,48.0419,1.61701,,,,7.85398e-5
1:0.25 (rep 3),2-Recover,96.403,1.91,1.716,0.12,,0.473249,1527.89,,47.3249,1.52789,,,,7.85398e-5
1:0.25 (rep 3),2-Recover,96.77,1.937,1.689,0.12,,0.465803,1527.89,,46.5803,1.52789,,,,7.85398e-5
1:0.25 (rep 3),2-Recover,97.137,1.964,1.662,0.12,,0.458356,1527.89,,45.8356,1.52789,,,,7.85398e-5
1:0.25 (rep 3),2-Recover,97.503,1.99,1.636,0.12,,0.451186,1527.89,,45.1186,1.52789,,,,7.85398e-5
1:0.25 (rep 3),2-Recover,97.87,2.017,1.609,0.113,,0.44374,1438.76,,44.374,1.43876,,,,7.85398e-5
1:0.25 (rep 3),2-Recover,98.237,2.044,1.582,0.12,,0.436293,1527.89,,43.6293,1.52789,,,,7.85398e-5
1:0.25 (rep 3),2-Recover,98.603,2.07,1.556,0.12,,0.429123,1527.89,,42.9123,1.52789,,,,7.85398e-5
1:0.25 (rep 3),2-Recover,98.97,2.097,1.529,0.113,,0.421677,1438.76,,42.1677,1.43876,,,,7.85398e-5
1:0.25 (rep 3),2-Recover,99.337,2.124,1.502,0.093,,0.414231,1184.11,,41.4231,1.18411,,,,7.85398e-5
1:0.25 (rep 3),2-Recover,99.703,2.15,1.476,0.079,,0.40706,1005.86,,40.706,1.00586,,,,7.85398e-5
1:0.25 (rep 3),2-Recover,100.07,2.177,1.449,0.086,,0.399614,1094.99,,39.9614,1.09499,,,,7.85398e-5
1:0.25 (rep 3),2-Recover,100.437,2.204,1.422,0.079,,0.392168,1005.86,,39.2168,1.00586,,,,7.85398e-5
1:0.25 (rep 3),2-Recover,100.803,2.23,1.396,0.093,,0.384997,1184.11,,38.4997,1.18411,,,,7.85398e-5
1:0.25 (rep 3),2-Recover,101.17,2.257,1.369,0.079,,0.377551,1005.86,,37.7551,1.00586,,,,7.85398e-5
1:0.25 (rep 3),2-Recover,101.537,2.284,1.342,0.079,,0.370105,1005.86,,37.0105,1.00586,,,,7.85398e-5
1:0.25 (rep 3),2-Recover,101.903,2.31,1.316,0.072,,0.362934,916.733,,36.2934,0.916733,,,,7.85398e-5
1:0.25 (rep 3),2-Recover,102.27,2.337,1.289,0.072,,0.355488,916.733,,35.5488,0.916733,,,,7.85398e-5
1:0.25 (rep 3),2-Recover,102.637,2.363,1.263,0.066,,0.348318,840.338,,34.8318,0.840338,,,,7.85398e-5
1:0.25 (rep 3),2-Recover,103.003,2.39,1.236,0.072,,0.340871,916.733,,34.0871,0.916733,,,,7.85398e-5
1:0.25 (rep 3),2-Recover,103.37,2.417,1.209,0.066,,0.333425,840.338,,33.3425,0.840338,,,,7.85398e-5
1:0.25 (rep 3),2-Recover,103.737,2.444,1.182,0.066,,0.325979,840.338,,32.5979,0.840338,,,,7.85398e-5
1:0.25 (rep 3),2-Recover,104.103,2.47,1.156,0.066,,0.318809,840.338,,31.8809,0.840338,,,,7.85398e-5
1:0.25 (rep 3),2-Recover,104.47,2.496,1.13,0.066,,0.311638,840.338,,31.1638,0.840338,,,,7.85398e-5
1:0.25 (rep 3),2-Recover,104.837,2.524,1.102,0.066,,0.303916,840.338,,30.3916,0.840338,,,,7.85398e-5
1:0.25 (rep 3),2-Recover,105.203,2.55,1.076,0.066,,0.296746,840.338,,29.6746,0.840338,,,,7.85398e-5
1:0.25 (rep 3),2-Recover,105.57,2.577,1.049,0.072,,0.2893,916.733,,28.93,0.916733,,,,7.85398e-5
1:0.25 (rep 3),2-Recover,105.937,2.603,1.023,0.066,,0.282129,840.338,,28.2129,0.840338,,,,7.85398e-5
1:0.25 (rep 3),2-Recover,106.303,2.629,0.997,0.066,,0.274959,840.338,,27.4959,0.840338,,,,7.85398e-5
1:0.25 (rep 3),2-Recover,106.67,2.657,0.969,0.066,,0.267237,840.338,,26.7237,0.840338,,,,7.85398e-5
1:0.25 (rep 3),2-Recover,107.037,2.683,0.943,0.066,,0.260066,840.338,,26.0066,0.840338,,,,7.85398e-5
1:0.25 (rep 3),2-Recover,107.403,2.709,0.917,0.059,,0.252896,751.211,,25.2896,0.751211,,,,7.85398e-5
1:0.25 (rep 3),2-Recover,107.77,2.736,0.89,0.059,,0.24545,751.211,,24.545,0.751211,,,,7.85398e-5
1:0.25 (rep 3),2-Recover,108.137,2.763,0.863,0.059,,0.238003,751.211,,23.8003,0.751211,,,,7.85398e-5
1:0.25 (rep 3),2-Recover,108.503,2.789,0.837,0.066,,0.230833,840.338,,23.0833,0.840338,,,,7.85398e-5
1:0.25 (rep 3),2-Recover,108.87,2.816,0.81,0.066,,0.223387,840.338,,22.3387,0.840338,,,,7.85398e-5
1:0.25 (rep 3),2-Recover,109.237,2.843,0.783,0.052,,0.21594,662.085,,21.594,0.662085,,,,7.85398e-5
1:0.25 (rep 3),2-Recover,109.603,2.869,0.757,0.045,,0.20877,572.958,,20.877,0.572958,,,,7.85398e-5
1:0.25 (rep 3),2-Recover,109.97,2.896,0.73,0.045,,0.201324,572.958,,20.1324,0.572958,,,,7.85398e-5
1:0.25 (rep 3),2-Recover,110.337,2.923,0.703,0.038,,0.193878,483.831,,19.3878,0.483831,,,,7.85398e-5
1:0.25 (rep 3),2-Recover,110.703,2.949,0.677,0.052,,0.186707,662.085,,18.6707,0.662085,,,,7.85398e-5
1:0.25 (rep 3),2-Recover,111.07,2.976,0.65,0.052,,0.179261,662.085,,17.9261,0.662085,,,,7.85398e-5
1:0.25 (rep 3),2-Recover,111.437,3.003,0.623,0.045,,0.171815,572.958,,17.1815,0.572958,,,,7.85398e-5
1:0.25 (rep 3),2-Recover,111.803,3.029,0.597,0.025,,0.164644,318.31,,16.4644,0.31831,,,,7.85398e-5
1:0.25 (rep 3),2-Recover,112.17,3.056,0.57,0.018,,0.157198,229.183,,15.7198,0.229183,,,,7.85398e-5
1:0.25 (rep 3),2-Recover,112.537,3.083,0.543,0.032,,0.149752,407.437,,14.9752,0.407437,,,,7.85398e-5
1:0.25 (rep 3),2-Recover,112.903,3.109,0.517,0.032,,0.142581,407.437,,14.2581,0.407437,,,,7.85398e-5
1:0.25 (rep 3),2-Recover,113.27,3.136,0.49,0.025,,0.135135,318.31,,13.5135,0.31831,,,,7.85398e-5
1:0.25 (rep 3),2-Recover,113.637,3.163,0.463,0.045,,0.127689,572.958,,12.7689,0.572958,,,,7.85398e-5
1:0.25 (rep 3),2-Recover,114.003,3.189,0.437,0.025,,0.120518,318.31,,12.0518,0.31831,,,,7.85398e-5
1:0.25 (rep 3),2-Recover,114.37,3.216,0.41,0.025,,0.113072,318.31,,11.3072,0.31831,,,,7.85398e-5
1:0.25 (rep 3),2-Recover,114.737,3.243,0.383,0.018,,0.105626,229.183,,10.5626,0.229183,,,,7.85398e-5
1:0.25 (rep 3),2-Recover,115.103,3.269,0.357,0.018,,0.0984556,229.183,,9.84556,0.229183,,,,7.85398e-5
1:0.25 (rep 3),2-Recover,115.47,3.295,0.331,0.025,,0.0912852,318.31,,9.12852,0.31831,,,,7.85398e-5
1:0.25 (rep 3),2-Recover,115.837,3.322,0.304,0.025,,0.0838389,318.31,,8.38389,0.31831,,,,7.85398e-5
1:0.25 (rep 3),2-Recover,116.203,3.349,0.277,0.018,,0.0763927,229.183,,7.63927,0.229183,,,,7.85398e-5
1:0.25 (rep 3),2-Recover,116.57,3.375,0.251,0.025,,0.0692223,318.31,,6.92223,0.31831,,,,7.85398e-5
1:0.25 (rep 3),2-Recover,116.937,3.402,0.224,0.018,,0.0617761,229.183,,6.17761,0.229183,,,,7.85398e-5
1:0.25 (rep 3),2-Recover,117.303,3.428,0.198,0.018,,0.0546056,229.183,,5.46056,0.229183,,,,7.85398e-5
1:0.25 (rep 3),2-Recover,117.67,3.455,0.171,0.018,,0.0471594,229.183,,4.71594,0.229183,,,,7.85398e-5
1:0.25 (rep 3),2-Recover,118.037,3.482,0.144,0.025,,0.0397132,318.31,,3.97132,0.31831,,,,7.85398e-5
1:0.25 (rep 3),2-Recover,118.403,3.508,0.118,0.025,,0.0325427,318.31,,3.25427,0.31831,,,,7.85398e-5
1:0.25 (rep 3),2-Recover,118.77,3.535,0.091,0.018,,0.0250965,229.183,,2.50965,0.229183,,,,7.85398e-5
1:0.25 (rep 3),2-Recover,119.137,3.562,0.064,0.011,,0.0176503,140.056,,1.76503,0.140056,,,,7.85398e-5
1:0.25 (rep 3),2-Recover,119.503,3.588,0.038,0.011,,0.0104799,140.056,,1.04799,0.140056,,,,7.85398e-5
1:0.25 (rep 3),2-Recover,119.87,3.615,0.011,0.011,,0.00303365,140.056,,0.303365,0.140056,,,,7.85398e-5
1:0.25 (rep 3),3-Compress,120.223,3.616,0.01,0.018,,0.00275786,229.183,,0.275786,0.229183,,,,7.85398e-5
1:0.25 (rep 3),3-Compress,120.59,3.589,0.037,0.025,,0.0102041,318.31,,1.02041,0.31831,,,,7.85398e-5
1:0.25 (rep 3),3-Compress,120.957,3.563,0.063,0.018,,0.0173745,229.183,,1.73745,0.229183,,,,7.85398e-5
1:0.25 (rep 3),3-Compress,121.323,3.536,0.09,0.018,,0.0248207,229.183,,2.48207,0.229183,,,,7.85398e-5
1:0.25 (rep 3),3-Compress,121.69,3.51,0.116,0.018,,0.0319912,229.183,,3.19912,0.229183,,,,7.85398e-5
1:0.25 (rep 3),3-Compress,122.057,3.483,0.143,0.018,,0.0394374,229.183,,3.94374,0.229183,,,,7.85398e-5
1:0.25 (rep 3),3-Compress,122.423,3.456,0.17,0.018,,0.0468836,229.183,,4.68836,0.229183,,,,7.85398e-5
1:0.25 (rep 3),3-Compress,122.79,3.43,0.196,0.018,,0.0540541,229.183,,5.40541,0.229183,,,,7.85398e-5
1:0.25 (rep 3),3-Compress,123.157,3.403,0.223,0.025,,0.0615003,318.31,,6.15003,0.31831,,,,7.85398e-5
1:0.25 (rep 3),3-Compress,123.523,3.377,0.249,0.032,,0.0686707,407.437,,6.86707,0.407437,,,,7.85398e-5
1:0.25 (rep 3),3-Compress,123.89,3.35,0.276,0.018,,0.0761169,229.183,,7.61169,0.229183,,,,7.85398e-5
1:0.25 (rep 3),3-Compress,124.257,3.323,0.303,0.032,,0.0835632,407.437,,8.35632,0.407437,,,,7.85398e-5
1:0.25 (rep 3),3-Compress,124.623,3.297,0.329,0.018,,0.0907336,229.183,,9.07336,0.229183,,,,7.85398e-5
1:0.25 (rep 3),3-Compress,124.99,3.27,0.356,0.018,,0.0981798,229.183,,9.81798,0.229183,,,,7.85398e-5
1:0.25 (rep 3),3-Compress,125.357,3.243,0.383,0.025,,0.105626,318.31,,10.5626,0.31831,,,,7.85398e-5
1:0.25 (rep 3),3-Compress,125.723,3.217,0.409,0.025,,0.112796,318.31,,11.2796,0.31831,,,,7.85398e-5
1:0.25 (rep 3),3-Compress,126.09,3.19,0.436,0.045,,0.120243,572.958,,12.0243,0.572958,,,,7.85398e-5
1:0.25 (rep 3),3-Compress,126.457,3.163,0.463,0.052,,0.127689,662.085,,12.7689,0.662085,,,,7.85398e-5
1:0.25 (rep 3),3-Compress,126.823,3.137,0.489,0.045,,0.134859,572.958,,13.4859,0.572958,,,,7.85398e-5
1:0.25 (rep 3),3-Compress,127.19,3.11,0.516,0.059,,0.142306,751.211,,14.2306,0.751211,,,,7.85398e-5
1:0.25 (rep 3),3-Compress,127.557,3.083,0.543,0.038,,0.149752,483.831,,14.9752,0.483831,,,,7.85398e-5
1:0.25 (rep 3),3-Compress,127.923,3.057,0.569,0.045,,0.156922,572.958,,15.6922,0.572958,,,,7.85398e-5
1:0.25 (rep 3),3-Compress,128.29,3.03,0.596,0.059,,0.164368,751.211,,16.4368,0.751211,,,,7.85398e-5
1:0.25 (rep 3),3-Compress,128.657,3.003,0.623,0.066,,0.171815,840.338,,17.1815,0.840338,,,,7.85398e-5
1:0.25 (rep 3),3-Compress,129.023,2.977,0.649,0.059,,0.178985,751.211,,17.8985,0.751211,,,,7.85398e-5
1:0.25 (rep 3),3-Compress,129.39,2.95,0.676,0.066,,0.186431,840.338,,18.6431,0.840338,,,,7.85398e-5
1:0.25 (rep 3),3-Compress,129.757,2.923,0.703,0.066,,0.193878,840.338,,19.3878,0.840338,,,,7.85398e-5
1:0.25 (rep 3),3-Compress,130.123,2.897,0.729,0.066,,0.201048,840.338,,20.1048,0.840338,,,,7.85398e-5
1:0.25 (rep 3),3-Compress,130.49,2.87,0.756,0.059,,0.208494,751.211,,20.8494,0.751211,,,,7.85398e-5
1:0.25 (rep 3),3-Compress,130.857,2.844,0.782,0.066,,0.215665,840.338,,21.5665,0.840338,,,,7.85398e-5
1:0.25 (rep 3),3-Compress,131.223,2.818,0.808,0.066,,0.222835,840.338,,22.2835,0.840338,,,,7.85398e-5
1:0.25 (rep 3),3-Compress,131.59,2.79,0.836,0.066,,0.230557,840.338,,23.0557,0.840338,,,,7.85398e-5
1:0.25 (rep 3),3-Compress,131.957,2.764,0.862,0.066,,0.237728,840.338,,23.7728,0.840338,,,,7.85398e-5
1:0.25 (rep 3),3-Compress,132.323,2.737,0.889,0.066,,0.245174,840.338,,24.5174,0.840338,,,,7.85398e-5
1:0.25 (rep 3),3-Compress,132.69,2.711,0.915,0.066,,0.252344,840.338,,25.2344,0.840338,,,,7.85398e-5
1:0.25 (rep 3),3-Compress,133.057,2.684,0.942,0.066,,0.25979,840.338,,25.979,0.840338,,,,7.85398e-5
1:0.25 (rep 3),3-Compress,133.423,2.657,0.969,0.066,,0.267237,840.338,,26.7237,0.840338,,,,7.85398e-5
1:0.25 (rep 3),3-Compress,133.79,2.631,0.995,0.066,,0.274407,840.338,,27.4407,0.840338,,,,7.85398e-5
1:0.25 (rep 3),3-Compress,134.157,2.604,1.022,0.066,,0.281853,840.338,,28.1853,0.840338,,,,7.85398e-5
1:0.25 (rep 3),3-Compress,134.523,2.578,1.048,0.066,,0.289024,840.338,,28.9024,0.840338,,,,7.85398e-5
1:0.25 (rep 3),3-Compress,134.89,2.551,1.075,0.072,,0.29647,916.733,,29.647,0.916733,,,,7.85398e-5
1:0.25 (rep 3),3-Compress,135.257,2.524,1.102,0.066,,0.303916,840.338,,30.3916,0.840338,,,,7.85398e-5
1:0.25 (rep 3),3-Compress,135.623,2.498,1.128,0.066,,0.311087,840.338,,31.1087,0.840338,,,,7.85398e-5
1:0.25 (rep 3),3-Compress,135.99,2.471,1.155,0.079,,0.318533,1005.86,,31.8533,1.00586,,,,7.85398e-5
1:0.25 (rep 3),3-Compress,136.357,2.444,1.182,0.072,,0.325979,916.733,,32.5979,0.916733,,,,7.85398e-5
1:0.25 (rep 3),3-Compress,136.723,2.418,1.208,0.086,,0.333149,1094.99,,33.3149,1.09499,,,,7.85398e-5
1:0.25 (rep 3),3-Compress,137.09,2.391,1.235,0.072,,0.340596,916.733,,34.0596,0.916733,,,,7.85398e-5
1:0.25 (rep 3),3-Compress,137.457,2.364,1.262,0.072,,0.348042,916.733,,34.8042,0.916733,,,,7.85398e-5
1:0.25 (rep 3),3-Compress,137.823,2.338,1.288,0.066,,0.355212,840.338,,35.5212,0.840338,,,,7.85398e-5
1:0.25 (rep 3),3-Compress,138.19,2.311,1.315,0.079,,0.362659,1005.86,,36.2659,1.00586,,,,7.85398e-5
1:0.25 (rep 3),3-Compress,138.557,2.284,1.342,0.086,,0.370105,1094.99,,37.0105,1.09499,,,,7.85398e-5
1:0.25 (rep 3),3-Compress,138.923,2.258,1.368,0.099,,0.377275,1260.51,,37.7275,1.26051,,,,7.85398e-5
1:0.25 (rep 3),3-Compress,139.29,2.231,1.395,0.099,,0.384721,1260.51,,38.4721,1.26051,,,,7.85398e-5
1:0.25 (rep 3),3-Compress,139.657,2.204,1.422,0.113,,0.392168,1438.76,,39.2168,1.43876,,,,7.85398e-5
1:0.25 (rep 3),3-Compress,140.023,2.178,1.448,0.086,,0.399338,1094.99,,39.9338,1.09499,,,,7.85398e-5
1:0.25 (rep 3),3-Compress,140.39,2.151,1.475,0.113,,0.406784,1438.76,,40.6784,1.43876,,,,7.85398e-5
1:0.25 (rep 3),3-Compress,140.757,2.125,1.501,0.113,,0.413955,1438.76,,41.3955,1.43876,,,,7.85398e-5
1:0.25 (rep 3),3-Compress,141.123,2.098,1.528,0.113,,0.421401,1438.76,,42.1401,1.43876,,,,7.85398e-5
1:0.25 (rep 3),3-Compress,141.49,2.071,1.555,0.12,,0.428847,1527.89,,42.8847,1.52789,,,,7.85398e-5
1:0.25 (rep 3),3-Compress,141.857,2.045,1.581,0.12,,0.436018,1527.89,,43.6018,1.52789,,,,7.85398e-5
1:0.25 (rep 3),3-Compress,142.223,2.018,1.608,0.12,,0.443464,1527.89,,44.3464,1.52789,,,,7.85398e-5
1:0.25 (rep 3),3-Compress,142.59,1.992,1.634,0.12,,0.450634,1527.89,,45.0634,1.52789,,,,7.85398e-5
1:0.25 (rep 3),3-Compress,142.957,1.965,1.661,0.12,,0.458081,1527.89,,45.8081,1.52789,,,,7.85398e-5
1:0.25 (rep 3),3-Compress,143.323,1.938,1.688,0.127,,0.465527,1617.01,,46.5527,1.61701,,,,7.85398e-5
1:0.25 (rep 3),3-Compress,143.69,1.912,1.714,0.12,,0.472697,1527.89,,47.2697,1.52789,,,,7.85398e-5
1:0.25 (rep 3),3-Compress,144.057,1.885,1.741,0.127,,0.480143,1617.01,,48.0143,1.61701,,,,7.85398e-5
1:0.25 (rep 3),3-Compress,144.423,1.859,1.767,0.133,,0.487314,1693.41,,48.7314,1.69341,,,,7.85398e-5
1:0.25 (rep 3),3-Compress,144.79,1.832,1.794,0.127,,0.49476,1617.01,,49.476,1.61701,,,,7.85398e-5
1:0.25 (rep 3),3-Compress,145.157,1.805,1.821,0.133,,0.502206,1693.41,,50.2206,1.69341,,,,7.85398e-5
1:0.25 (rep 3),3-Compress,145.523,1.779,1.847,0.127,,0.509377,1617.01,,50.9377,1.61701,,,,7.85398e-5
1:0.25 (rep 3),3-Compress,145.89,1.752,1.874,0.154,,0.516823,1960.79,,51.6823,1.96079,,,,7.85398e-5
1:0.25 (rep 3),3-Compress,146.257,1.725,1.901,0.161,,0.524269,2049.92,,52.4269,2.04992,,,,7.85398e-5
1:0.25 (rep 3),3-Compress,146.623,1.699,1.927,0.174,,0.53144,2215.44,,53.144,2.21544,,,,7.85398e-5
1:0.25 (rep 3),3-Compress,146.99,1.672,1.954,0.174,,0.538886,2215.44,,53.8886,2.21544,,,,7.85398e-5
1:0.25 (rep 3),3-Compress,147.357,1.645,1.981,0.174,,0.546332,2215.44,,54.6332,2.21544,,,,7.85398e-5
1:0.25 (rep 3),3-Compress,147.723,1.619,2.007,0.174,,0.553502,2215.44,,55.3502,2.21544,,,,7.85398e-5
1:0.25 (rep 3),3-Compress,148.09,1.592,2.034,0.174,,0.560949,2215.44,,56.0949,2.21544,,,,7.85398e-5
1:0.25 (rep 3),3-Compress,148.457,1.565,2.061,0.174,,0.568395,2215.44,,56.8395,2.21544,,,,7.85398e-5
1:0.25 (rep 3),3-Compress,148.823,1.539,2.087,0.161,,0.575565,2049.92,,57.5565,2.04992,,,,7.85398e-5
1:0.25 (rep 3),3-Compress,149.19,1.512,2.114,0.174,,0.583012,2215.44,,58.3012,2.21544,,,,7.85398e-5
1:0.25 (rep 3),3-Compress,149.557,1.485,2.141,0.174,,0.590458,2215.44,,59.0458,2.21544,,,,7.85398e-5
1:0.25 (rep 3),3-Compress,149.923,1.459,2.167,0.174,,0.597628,2215.44,,59.7628,2.21544,,,,7.85398e-5
1:0.25 (rep 3),3-Recover,150.267,1.462,2.164,0.174,,0.596801,2215.44,,59.6801,2.21544,,,,7.85398e-5
1:0.25 (rep 3),3-Recover,150.633,1.488,2.138,0.174,,0.58963,2215.44,,58.963,2.21544,,,,7.85398e-5
1:0.25 (rep 3),3-Recover,151,1.515,2.111,0.174,,0.582184,2215.44,,58.2184,2.21544,,,,7.85398e-5
1:0.25 (rep 3),3-Recover,151.367,1.542,2.084,0.174,,0.574738,2215.44,,57.4738,2.21544,,,,7.85398e-5
1:0.25 (rep 3),3-Recover,151.733,1.568,2.058,0.174,,0.567568,2215.44,,56.7568,2.21544,,,,7.85398e-5
1:0.25 (rep 3),3-Recover,152.1,1.595,2.031,0.174,,0.560121,2215.44,,56.0121,2.21544,,,,7.85398e-5
1:0.25 (rep 3),3-Recover,152.467,1.622,2.004,0.174,,0.552675,2215.44,,55.2675,2.21544,,,,7.85398e-5
1:0.25 (rep 3),3-Recover,152.833,1.648,1.978,0.161,,0.545505,2049.92,,54.5505,2.04992,,,,7.85398e-5
1:0.25 (rep 3),3-Recover,153.2,1.675,1.951,0.161,,0.538058,2049.92,,53.8058,2.04992,,,,7.85398e-5
1:0.25 (rep 3),3-Recover,153.567,1.702,1.924,0.133,,0.530612,1693.41,,53.0612,1.69341,,,,7.85398e-5
1:0.25 (rep 3),3-Recover,153.933,1.728,1.898,0.147,,0.523442,1871.66,,52.3442,1.87166,,,,7.85398e-5
1:0.25 (rep 3),3-Recover,154.3,1.755,1.871,0.133,,0.515996,1693.41,,51.5996,1.69341,,,,7.85398e-5
1:0.25 (rep 3),3-Recover,154.667,1.782,1.844,0.127,,0.508549,1617.01,,50.8549,1.61701,,,,7.85398e-5
1:0.25 (rep 3),3-Recover,155.033,1.808,1.818,0.127,,0.501379,1617.01,,50.1379,1.61701,,,,7.85398e-5
1:0.25 (rep 3),3-Recover,155.4,1.835,1.791,0.12,,0.493933,1527.89,,49.3933,1.52789,,,,7.85398e-5
1:0.25 (rep 3),3-Recover,155.767,1.862,1.764,0.12,,0.486486,1527.89,,48.6486,1.52789,,,,7.85398e-5
1:0.25 (rep 3),3-Recover,156.133,1.888,1.738,0.127,,0.479316,1617.01,,47.9316,1.61701,,,,7.85398e-5
1:0.25 (rep 3),3-Recover,156.5,1.915,1.711,0.12,,0.47187,1527.89,,47.187,1.52789,,,,7.85398e-5
1:0.25 (rep 3),3-Recover,156.867,1.942,1.684,0.12,,0.464424,1527.89,,46.4424,1.52789,,,,7.85398e-5
1:0.25 (rep 3),3-Recover,157.233,1.968,1.658,0.12,,0.457253,1527.89,,45.7253,1.52789,,,,7.85398e-5
1:0.25 (rep 3),3-Recover,157.6,1.995,1.631,0.12,,0.449807,1527.89,,44.9807,1.52789,,,,7.85398e-5
1:0.25 (rep 3),3-Recover,157.967,2.022,1.604,0.099,,0.442361,1260.51,,44.2361,1.26051,,,,7.85398e-5
1:0.25 (rep 3),3-Recover,158.333,2.048,1.578,0.099,,0.43519,1260.51,,43.519,1.26051,,,,7.85398e-5
1:0.25 (rep 3),3-Recover,158.7,2.075,1.551,0.099,,0.427744,1260.51,,42.7744,1.26051,,,,7.85398e-5
1:0.25 (rep 3),3-Recover,159.067,2.101,1.525,0.113,,0.420574,1438.76,,42.0574,1.43876,,,,7.85398e-5
1:0.25 (rep 3),3-Recover,159.433,2.128,1.498,0.099,,0.413127,1260.51,,41.3127,1.26051,,,,7.85398e-5
1:0.25 (rep 3),3-Recover,159.8,2.155,1.471,0.079,,0.405681,1005.86,,40.5681,1.00586,,,,7.85398e-5
1:0.25 (rep 3),3-Recover,160.167,2.181,1.445,0.079,,0.398511,1005.86,,39.8511,1.00586,,,,7.85398e-5
1:0.25 (rep 3),3-Recover,160.533,2.208,1.418,0.072,,0.391065,916.733,,39.1065,0.916733,,,,7.85398e-5
1:0.25 (rep 3),3-Recover,160.9,2.234,1.392,0.066,,0.383894,840.338,,38.3894,0.840338,,,,7.85398e-5
1:0.25 (rep 3),3-Recover,161.267,2.261,1.365,0.079,,0.376448,1005.86,,37.6448,1.00586,,,,7.85398e-5
1:0.25 (rep 3),3-Recover,161.633,2.288,1.338,0.079,,0.369002,1005.86,,36.9002,1.00586,,,,7.85398e-5
1:0.25 (rep 3),3-Recover,162,2.314,1.312,0.072,,0.361831,916.733,,36.1831,0.916733,,,,7.85398e-5
1:0.25 (rep 3),3-Recover,162.367,2.341,1.285,0.072,,0.354385,916.733,,35.4385,0.916733,,,,7.85398e-5
1:0.25 (rep 3),3-Recover,162.733,2.367,1.259,0.066,,0.347215,840.338,,34.7215,0.840338,,,,7.85398e-5
1:0.25 (rep 3),3-Recover,163.1,2.394,1.232,0.066,,0.339768,840.338,,33.9768,0.840338,,,,7.85398e-5
1:0.25 (rep 3),3-Recover,163.467,2.421,1.205,0.072,,0.332322,916.733,,33.2322,0.916733,,,,7.85398e-5
1:0.25 (rep 3),3-Recover,163.833,2.447,1.179,0.066,,0.325152,840.338,,32.5152,0.840338,,,,7.85398e-5
1:0.25 (rep 3),3-Recover,164.2,2.474,1.152,0.066,,0.317705,840.338,,31.7705,0.840338,,,,7.85398e-5
1:0.25 (rep 3),3-Recover,164.567,2.501,1.125,0.066,,0.310259,840.338,,31.0259,0.840338,,,,7.85398e-5
1:0.25 (rep 3),3-Recover,164.933,2.527,1.099,0.066,,0.303089,840.338,,30.3089,0.840338,,,,7.85398e-5
1:0.25 (rep 3),3-Recover,165.3,2.554,1.072,0.066,,0.295643,840.338,,29.5643,0.840338,,,,7.85398e-5
1:0.25 (rep 3),3-Recover,165.667,2.581,1.045,0.066,,0.288196,840.338,,28.8196,0.840338,,,,7.85398e-5
1:0.25 (rep 3),3-Recover,166.033,2.607,1.019,0.066,,0.281026,840.338,,28.1026,0.840338,,,,7.85398e-5
1:0.25 (rep 3),3-Recover,166.4,2.634,0.992,0.059,,0.27358,751.211,,27.358,0.751211,,,,7.85398e-5
1:0.25 (rep 3),3-Recover,166.767,2.661,0.965,0.066,,0.266133,840.338,,26.6133,0.840338,,,,7.85398e-5
1:0.25 (rep 3),3-Recover,167.133,2.687,0.939,0.066,,0.258963,840.338,,25.8963,0.840338,,,,7.85398e-5
1:0.25 (rep 3),3-Recover,167.5,2.714,0.912,0.066,,0.251517,840.338,,25.1517,0.840338,,,,7.85398e-5
1:0.25 (rep 3),3-Recover,167.867,2.741,0.885,0.066,,0.244071,840.338,,24.4071,0.840338,,,,7.85398e-5
1:0.25 (rep 3),3-Recover,168.233,2.767,0.859,0.052,,0.2369,662.085,,23.69,0.662085,,,,7.85398e-5
1:0.25 (rep 3),3-Recover,168.6,2.794,0.832,0.059,,0.229454,751.211,,22.9454,0.751211,,,,7.85398e-5
1:0.25 (rep 3),3-Recover,168.967,2.821,0.805,0.059,,0.222008,751.211,,22.2008,0.751211,,,,7.85398e-5
1:0.25 (rep 3),3-Recover,169.333,2.847,0.779,0.059,,0.214837,751.211,,21.4837,0.751211,,,,7.85398e-5
1:0.25 (rep 3),3-Recover,169.7,2.874,0.752,0.052,,0.207391,662.085,,20.7391,0.662085,,,,7.85398e-5
1:0.25 (rep 3),3-Recover,170.067,2.9,0.726,0.038,,0.200221,483.831,,20.0221,0.483831,,,,7.85398e-5
1:0.25 (rep 3),3-Recover,170.433,2.926,0.7,0.038,,0.19305,483.831,,19.305,0.483831,,,,7.85398e-5
1:0.25 (rep 3),3-Recover,170.8,2.954,0.672,0.038,,0.185328,483.831,,18.5328,0.483831,,,,7.85398e-5
1:0.25 (rep 3),3-Recover,171.167,2.98,0.646,0.059,,0.178158,751.211,,17.8158,0.751211,,,,7.85398e-5
1:0.25 (rep 3),3-Recover,171.533,3.007,0.619,0.045,,0.170712,572.958,,17.0712,0.572958,,,,7.85398e-5
1:0.25 (rep 3),3-Recover,171.9,3.033,0.593,0.032,,0.163541,407.437,,16.3541,0.407437,,,,7.85398e-5
1:0.25 (rep 3),3-Recover,172.267,3.06,0.566,0.038,,0.156095,483.831,,15.6095,0.483831,,,,7.85398e-5
1:0.25 (rep 3),3-Recover,172.633,3.086,0.54,0.032,,0.148924,407.437,,14.8924,0.407437,,,,7.85398e-5
1:0.25 (rep 3),3-Recover,173,3.113,0.513,0.018,,0.141478,229.183,,14.1478,0.229183,,,,7.85398e-5
1:0.25 (rep 3),3-Recover,173.367,3.14,0.486,0.018,,0.134032,229.183,,13.4032,0.229183,,,,7.85398e-5
1:0.25 (rep 3),3-Recover,173.733,3.166,0.46,0.025,,0.126862,318.31,,12.6862,0.31831,,,,7.85398e-5
1:0.25 (rep 3),3-Recover,174.1,3.193,0.433,0.032,,0.119415,407.437,,11.9415,0.407437,,,,7.85398e-5
1:0.25 (rep 3),3-Recover,174.467,3.22,0.406,0.018,,0.111969,229.183,,11.1969,0.229183,,,,7.85398e-5
1:0.25 (rep 3),3-Recover,174.833,3.246,0.38,0.025,,0.104799,318.31,,10.4799,0.31831,,,,7.85398e-5
1:0.25 (rep 3),3-Recover,175.2,3.273,0.353,0.018,,0.0973525,229.183,,9.73525,0.229183,,,,7.85398e-5
1:0.25 (rep 3),3-Recover,175.567,3.3,0.326,0.018,,0.0899062,229.183,,8.99062,0.229183,,,,7.85398e-5
1:0.25 (rep 3),3-Recover,175.933,3.326,0.3,0.018,,0.0827358,229.183,,8.27358,0.229183,,,,7.85398e-5
1:0.25 (rep 3),3-Recover,176.3,3.353,0.273,0.032,,0.0752896,407.437,,7.52896,0.407437,,,,7.85398e-5
1:0.25 (rep 3),3-Recover,176.667,3.38,0.246,0.025,,0.0678434,318.31,,6.78434,0.31831,,,,7.85398e-5
1:0.25 (rep 3),3-Recover,177.033,3.406,0.22,0.032,,0.0606729,407.437,,6.06729,0.407437,,,,7.85398e-5
1:0.25 (rep 3),3-Recover,177.4,3.433,0.193,0.018,,0.0532267,229.183,,5.32267,0.229183,,,,7.85398e-5
1:0.25 (rep 3),3-Recover,177.767,3.46,0.166,0.018,,0.0457805,229.183,,4.57805,0.229183,,,,7.85398e-5
1:0.25 (rep 3),3-Recover,178.133,3.486,0.14,0.018,,0.03861,229.183,,3.861,0.229183,,,,7.85398e-5
1:0.25 (rep 3),3-Recover,178.5,3.513,0.113,0.018,,0.0311638,229.183,,3.11638,0.229183,,,,7.85398e-5
1:0.25 (rep 3),3-Recover,178.867,3.54,0.086,0.025,,0.0237176,318.31,,2.37176,0.31831,,,,7.85398e-5
1:0.25 (rep 3),3-Recover,179.233,3.566,0.06,0.011,,0.0165472,140.056,,1.65472,0.140056,,,,7.85398e-5
1:0.25 (rep 3),3-Recover,179.6,3.593,0.033,0.011,,0.00910094,140.056,,0.910094,0.140056,,,,7.85398e-5
1:0.25 (rep 3),3-Recover,179.967,3.619,0.007,0.011,,0.0019305,140.056,,0.19305,0.140056,,,,7.85398e-5
1:0.25 (rep 3),3-Recover,180.1,3.626,0,0.018,,0,229.183,,0,0.229183,,,,7.85398e-5