File: data/beta_1-1-1_3.csv
SetName,Cycle,Time_S,Size_mm,Displacement_mm,Force_N,,Strain,Stress(Pascal),,%Strain,Stress(kPa),,,,Area(m^2)
Test1,1-Compress,0.000,3.839,-0,-0.003,,0,-38.1972,,0,-0.0381972,,,,7.85398e-5
Test1,1-Compress,0.367,3.812,0.027,-0.003,,0.00703308,-38.1972,,0.703308,-0.0381972,,,,7.85398e-5
Test1,1-Compress,0.733,3.784,0.055,-0.003,,0.0143266,-38.1972,,1.43266,-0.0381972,,,,7.85398e-5
Test1,1-Compress,1.100,3.755,0.084,-0.003,,0.0218807,-38.1972,,2.18807,-0.0381972,,,,7.85398e-5
Test1,1-Compress,1.467,3.727,0.112,0.003,,0.0291743,38.1972,,2.91743,0.0381972,,,,7.85398e-5
Test1,1-Compress,1.833,3.699,0.14,0.003,,0.0364678,38.1972,,3.64678,0.0381972,,,,7.85398e-5
Test1,1-Compress,2.200,3.671,0.168,0.003,,0.0437614,38.1972,,4.37614,0.0381972,,,,7.85398e-5
Test1,1-Compress,2.567,3.642,0.197,-0.003,,0.0513154,-38.1972,,5.13154,-0.0381972,,,,7.85398e-5
Test1,1-Compress,2.933,3.614,0.225,-0.003,,0.058609,-38.1972,,5.8609,-0.0381972,,,,7.85398e-5
Test1,1-Compress,3.300,3.586,0.253,-0.003,,0.0659026,-38.1972,,6.59026,-0.0381972,,,,7.85398e-5
Test1,1-Compress,3.667,3.558,0.281,-0.003,,0.0731961,-38.1972,,7.31961,-0.0381972,,,,7.85398e-5
Test1,1-Compress,4.033,3.53,0.309,0.003,,0.0804897,38.1972,,8.04897,0.0381972,,,,7.85398e-5
Test1,1-Compress,4.400,3.502,0.337,0.010,,0.0877833,127.324,,8.77833,0.127324,,,,7.85398e-5
Test1,1-Compress,4.767,3.473,0.366,0.010,,0.0953373,127.324,,9.53373,0.127324,,,,7.85398e-5
Test1,1-Compress,5.133,3.446,0.393,-0.003,,0.10237,-38.1972,,10.237,-0.0381972,,,,7.85398e-5
Test1,1-Compress,5.500,3.417,0.422,0.003,,0.109924,38.1972,,10.9924,0.0381972,,,,7.85398e-5
Test1,1-Compress,5.867,3.389,0.45,0.003,,0.117218,38.1972,,11.7218,0.0381972,,,,7.85398e-5
Test1,1-Compress,6.233,3.361,0.478,-0.003,,0.124512,-38.1972,,12.4512,-0.0381972,,,,7.85398e-5
Test1,1-Compress,6.600,3.333,0.506,0.003,,0.131805,38.1972,,13.1805,0.0381972,,,,7.85398e-5
Test1,1-Compress,6.967,3.304,0.535,0.017,,0.139359,216.451,,13.9359,0.216451,,,,7.85398e-5
Test1,1-Compress,7.333,3.277,0.562,0.010,,0.146392,127.324,,14.6392,0.127324,,,,7.85398e-5
Test1,1-Compress,7.700,3.248,0.591,-0.003,,0.153946,-38.1972,,15.3946,-0.0381972,,,,7.85398e-5
Test1,1-Compress,8.067,3.219,0.62,-0.003,,0.1615,-38.1972,,16.15,-0.0381972,,,,7.85398e-5
Test1,1-Compress,8.433,3.192,0.647,-0.003,,0.168533,-38.1972,,16.8533,-0.0381972,,,,7.85398e-5
Test1,1-Compress,8.800,3.163,0.676,-0.003,,0.176088,-38.1972,,17.6088,-0.0381972,,,,7.85398e-5
Test1,1-Compress,9.167,3.135,0.704,0.003,,0.183381,38.1972,,18.3381,0.0381972,,,,7.85398e-5
Test1,1-Compress,9.533,3.107,0.732,0.003,,0.190675,38.1972,,19.0675,0.0381972,,,,7.85398e-5
Test1,1-Compress,9.900,3.079,0.76,0.010,,0.197968,127.324,,19.7968,0.127324,,,,7.85398e-5
Test1,1-Compress,10.267,3.05,0.789,0.003,,0.205522,38.1972,,20.5522,0.0381972,,,,7.85398e-5
Test1,1-Compress,10.633,3.022,0.817,0.010,,0.212816,127.324,,21.2816,0.127324,,,,7.85398e-5
Test1,1-Compress,11.000,2.994,0.845,0.003,,0.220109,38.1972,,22.0109,0.0381972,,,,7.85398e-5
Test1,1-Compress,11.367,2.966,0.873,0.003,,0.227403,38.1972,,22.7403,0.0381972,,,,7.85398e-5
Test1,1-Compress,11.733,2.938,0.901,0.003,,0.234697,38.1972,,23.4697,0.0381972,,,,7.85398e-5
Test1,1-Compress,12.100,2.91,0.929,0.017,,0.24199,216.451,,24.199,0.216451,,,,7.85398e-5
Test1,1-Compress,12.467,2.881,0.958,0.017,,0.249544,216.451,,24.9544,0.216451,,,,7.85398e-5
Test1,1-Compress,12.833,2.854,0.985,0.024,,0.256577,305.578,,25.6577,0.305578,,,,7.85398e-5
Test1,1-Compress,13.200,2.825,1.014,0.010,,0.264131,127.324,,26.4131,0.127324,,,,7.85398e-5
Test1,1-Compress,13.567,2.797,1.042,0.003,,0.271425,38.1972,,27.1425,0.0381972,,,,7.85398e-5
Test1,1-Compress,13.933,2.769,1.07,0.003,,0.278718,38.1972,,27.8718,0.0381972,,,,7.85398e-5
Test1,1-Compress,14.300,2.741,1.098,0.003,,0.286012,38.1972,,28.6012,0.0381972,,,,7.85398e-5
Test1,1-Compress,14.667,2.712,1.127,0.017,,0.293566,216.451,,29.3566,0.216451,,,,7.85398e-5
Test1,1-Compress,15.033,2.685,1.154,0.024,,0.300599,305.578,,30.0599,0.305578,,,,7.85398e-5
Test1,1-Compress,15.400,2.656,1.183,0.024,,0.308153,305.578,,30.8153,0.305578,,,,7.85398e-5
Test1,1-Compress,15.767,2.627,1.212,0.010,,0.315707,127.324,,31.5707,0.127324,,,,7.85398e-5
Test1,1-Compress,16.133,2.6,1.239,0.003,,0.32274,38.1972,,32.274,0.0381972,,,,7.85398e-5
Test1,1-Compress,16.500,2.571,1.268,0.003,,0.330294,38.1972,,33.0294,0.0381972,,,,7.85398e-5
Test1,1-Compress,16.867,2.543,1.296,0.010,,0.337588,127.324,,33.7588,0.127324,,,,7.85398e-5
Test1,1-Compress,17.233,2.515,1.324,0.024,,0.344881,305.578,,34.4881,0.305578,,,,7.85398e-5
Test1,1-Compress,17.600,2.487,1.352,0.031,,0.352175,394.704,,35.2175,0.394704,,,,7.85398e-5
Test1,1-Compress,17.967,2.458,1.381,0.024,,0.359729,305.578,,35.9729,0.305578,,,,7.85398e-5
Test1,1-Compress,18.333,2.43,1.409,0.017,,0.367023,216.451,,36.7023,0.216451,,,,7.85398e-5
Test1,1-Compress,18.700,2.402,1.437,0.024,,0.374316,305.578,,37.4316,0.305578,,,,7.85398e-5
Test1,1-Compress,19.067,2.374,1.465,0.044,,0.38161,560.226,,38.161,0.560226,,,,7.85398e-5
Test1,1-Compress,19.433,2.346,1.493,0.010,,0.388903,127.324,,38.8903,0.127324,,,,7.85398e-5
Test1,1-Compress,19.800,2.318,1.521,0.037,,0.396197,471.099,,39.6197,0.471099,,,,7.85398e-5
Test1,1-Compress,20.167,2.289,1.55,0.031,,0.403751,394.704,,40.3751,0.394704,,,,7.85398e-5
Test1,1-Compress,20.533,2.261,1.578,0.024,,0.411045,305.578,,41.1045,0.305578,,,,7.85398e-5
Test1,1-Compress,20.900,2.233,1.606,0.044,,0.418338,560.226,,41.8338,0.560226,,,,7.85398e-5
Test1,1-Compress,21.267,2.205,1.634,0.003,,0.425632,38.1972,,42.5632,0.0381972,,,,7.85398e-5
Test1,1-Compress,21.633,2.177,1.662,0.017,,0.432925,216.451,,43.2925,0.216451,,,,7.85398e-5
Test1,1-Compress,22.000,2.149,1.69,0.024,,0.440219,305.578,,44.0219,0.305578,,,,7.85398e-5
Test1,1-Compress,22.367,2.12,1.719,0.024,,0.447773,305.578,,44.7773,0.305578,,,,7.85398e-5
Test1,1-Compress,22.733,2.092,1.747,0.031,,0.455066,394.704,,45.5066,0.394704,,,,7.85398e-5
Test1,1-Compress,23.100,2.064,1.775,0.037,,0.46236,471.099,,46.236,0.471099,,,,7.85398e-5
Test1,1-Compress,23.467,2.035,1.804,0.024,,0.469914,305.578,,46.9914,0.305578,,,,7.85398e-5
Test1,1-Compress,23.833,2.008,1.831,0.017,,0.476947,216.451,,47.6947,0.216451,,,,7.85398e-5
Test1,1-Compress,24.200,1.979,1.86,0.010,,0.484501,127.324,,48.4501,0.127324,,,,7.85398e-5
Test1,1-Compress,24.567,1.951,1.888,0.017,,0.491795,216.451,,49.1795,0.216451,,,,7.85398e-5
Test1,1-Compress,24.933,1.923,1.916,0.037,,0.499088,471.099,,49.9088,0.471099,,,,7.85398e-5
Test1,1-Compress,25.300,1.895,1.944,0.044,,0.506382,560.226,,50.6382,0.560226,,,,7.85398e-5
Test1,1-Compress,25.667,1.866,1.973,0.051,,0.513936,649.352,,51.3936,0.649352,,,,7.85398e-5
Test1,1-Compress,26.033,1.838,2.001,0.044,,0.521229,560.226,,52.1229,0.560226,,,,7.85398e-5
Test1,1-Compress,26.400,1.81,2.029,0.031,,0.528523,394.704,,52.8523,0.394704,,,,7.85398e-5
Test1,1-Compress,26.767,1.782,2.057,0.037,,0.535817,471.099,,53.5817,0.471099,,,,7.85398e-5
Test1,1-Compress,27.133,1.754,2.085,0.051,,0.54311,649.352,,54.311,0.649352,,,,7.85398e-5
Test1,1-Compress,27.500,1.726,2.113,0.044,,0.550404,560.226,,55.0404,0.560226,,,,7.85398e-5
Test1,1-Compress,27.867,1.697,2.142,0.051,,0.557958,649.352,,55.7958,0.649352,,,,7.85398e-5
Test1,1-Compress,28.233,1.669,2.17,0.051,,0.565251,649.352,,56.5251,0.649352,,,,7.85398e-5
Test1,1-Compress,28.600,1.641,2.198,0.051,,0.572545,649.352,,57.2545,0.649352,,,,7.85398e-5
Test1,1-Compress,28.967,1.613,2.226,0.051,,0.579838,649.352,,57.9838,0.649352,,,,7.85398e-5
Test1,1-Compress,29.333,1.585,2.254,0.051,,0.587132,649.352,,58.7132,0.649352,,,,7.85398e-5
Test1,1-Compress,29.700,1.556,2.283,0.051,,0.594686,649.352,,59.4686,0.649352,,,,7.85398e-5
Test1,1-Recover,30.067,1.539,2.3,0.051,,0.599114,649.352,,59.9114,0.649352,,,,7.85398e-5
Test1,1-Recover,30.433,1.567,2.272,0.051,,0.591821,649.352,,59.1821,0.649352,,,,7.85398e-5
Test1,1-Recover,30.800,1.596,2.243,0.051,,0.584267,649.352,,58.4267,0.649352,,,,7.85398e-5
Test1,1-Recover,31.167,1.624,2.215,0.051,,0.576973,649.352,,57.6973,0.649352,,,,7.85398e-5
Test1,1-Recover,31.533,1.652,2.187,0.044,,0.56968,560.226,,56.968,0.560226,,,,7.85398e-5
Test1,1-Recover,31.900,1.68,2.159,0.044,,0.562386,560.226,,56.2386,0.560226,,,,7.85398e-5
Test1,1-Recover,32.267,1.708,2.131,0.044,,0.555092,560.226,,55.5092,0.560226,,,,7.85398e-5
Test1,1-Recover,32.633,1.736,2.103,0.044,,0.547799,560.226,,54.7799,0.560226,,,,7.85398e-5
Test1,1-Recover,33.000,1.765,2.074,0.044,,0.540245,560.226,,54.0245,0.560226,,,,7.85398e-5
Test1,1-Recover,33.367,1.793,2.046,0.024,,0.532951,305.578,,53.2951,0.305578,,,,7.85398e-5
Test1,1-Recover,33.733,1.821,2.018,0.010,,0.525658,127.324,,52.5658,0.127324,,,,7.85398e-5
Test1,1-Recover,34.100,1.849,1.99,0.003,,0.518364,38.1972,,51.8364,0.0381972,,,,7.85398e-5
Test1,1-Recover,34.467,1.878,1.961,0.017,,0.51081,216.451,,51.081,0.216451,,,,7.85398e-5
Test1,1-Recover,34.833,1.905,1.934,0.031,,0.503777,394.704,,50.3777,0.394704,,,,7.85398e-5
Test1,1-Recover,35.200,1.934,1.905,0.024,,0.496223,305.578,,49.6223,0.305578,,,,7.85398e-5
Test1,1-Recover,35.567,1.962,1.877,0.024,,0.488929,305.578,,48.8929,0.305578,,,,7.85398e-5
Test1,1-Recover,35.933,1.99,1.849,0.010,,0.481636,127.324,,48.1636,0.127324,,,,7.85398e-5
Test1,1-Recover,36.300,2.018,1.821,0.003,,0.474342,38.1972,,47.4342,0.0381972,,,,7.85398e-5
Test1,1-Recover,36.667,2.047,1.792,0.010,,0.466788,127.324,,46.6788,0.127324,,,,7.85398e-5
Test1,1-Recover,37.033,2.074,1.765,0.010,,0.459755,127.324,,45.9755,0.127324,,,,7.85398e-5
Test1,1-Recover,37.400,2.103,1.736,0.024,,0.452201,305.578,,45.2201,0.305578,,,,7.85398e-5
Test1,1-Recover,37.767,2.131,1.708,0.010,,0.444908,127.324,,44.4908,0.127324,,,,7.85398e-5
Test1,1-Recover,38.133,2.159,1.68,0.010,,0.437614,127.324,,43.7614,0.127324,,,,7.85398e-5
Test1,1-Recover,38.500,2.188,1.651,0.003,,0.43006,38.1972,,43.006,0.0381972,,,,7.85398e-5
Test1,1-Recover,38.867,2.216,1.623,0.003,,0.422766,38.1972,,42.2766,0.0381972,,,,7.85398e-5
Test1,1-Recover,39.233,2.244,1.595,0.003,,0.415473,38.1972,,41.5473,0.0381972,,,,7.85398e-5
Test1,1-Recover,39.600,2.272,1.567,0.010,,0.408179,127.324,,40.8179,0.127324,,,,7.85398e-5
Test1,1-Recover,39.967,2.3,1.539,0.017,,0.400886,216.451,,40.0886,0.216451,,,,7.85398e-5
Test1,1-Recover,40.333,2.328,1.511,0.010,,0.393592,127.324,,39.3592,0.127324,,,,7.85398e-5
Test1,1-Recover,40.700,2.357,1.482,0.010,,0.386038,127.324,,38.6038,0.127324,,,,7.85398e-5
Test1,1-Recover,41.067,2.385,1.454,0.003,,0.378744,38.1972,,37.8744,0.0381972,,,,7.85398e-5
Test1,1-Recover,41.433,2.413,1.426,0.003,,0.371451,38.1972,,37.1451,0.0381972,,,,7.85398e-5
Test1,1-Recover,41.800,2.441,1.398,0.003,,0.364157,38.1972,,36.4157,0.0381972,,,,7.85398e-5
Test1,1-Recover,42.167,2.47,1.369,0.010,,0.356603,127.324,,35.6603,0.127324,,,,7.85398e-5
Test1,1-Recover,42.533,2.497,1.342,0.010,,0.34957,127.324,,34.957,0.127324,,,,7.85398e-5
Test1,1-Recover,42.900,2.526,1.313,-0.003,,0.342016,-38.1972,,34.2016,-0.0381972,,,,7.85398e-5
Test1,1-Recover,43.267,2.554,1.285,-0.003,,0.334723,-38.1972,,33.4723,-0.0381972,,,,7.85398e-5
Test1,1-Recover,43.633,2.582,1.257,-0.003,,0.327429,-38.1972,,32.7429,-0.0381972,,,,7.85398e-5
Test1,1-Recover,44.000,2.61,1.229,-0.003,,0.320135,-38.1972,,32.0135,-0.0381972,,,,7.85398e-5
Test1,1-Recover,44.367,2.639,1.2,0.003,,0.312581,38.1972,,31.2581,0.0381972,,,,7.85398e-5
Test1,1-Recover,44.733,2.666,1.173,0.010,,0.305548,127.324,,30.5548,0.127324,,,,7.85398e-5
Test1,1-Recover,45.100,2.695,1.144,0.003,,0.297994,38.1972,,29.7994,0.0381972,,,,7.85398e-5
Test1,1-Recover,45.467,2.723,1.116,-0.003,,0.290701,-38.1972,,29.0701,-0.0381972,,,,7.85398e-5
Test1,1-Recover,45.833,2.751,1.088,-0.003,,0.283407,-38.1972,,28.3407,-0.0381972,,,,7.85398e-5
Test1,1-Recover,46.200,2.78,1.059,-0.003,,0.275853,-38.1972,,27.5853,-0.0381972,,,,7.85398e-5
Test1,1-Recover,46.567,2.808,1.031,0.003,,0.26856,38.1972,,26.856,0.0381972,,,,7.85398e-5
Test1,1-Recover,46.933,2.836,1.003,0.003,,0.261266,38.1972,,26.1266,0.0381972,,,,7.85398e-5
Test1,1-Recover,47.300,2.864,0.975,0.010,,0.253972,127.324,,25.3972,0.127324,,,,7.85398e-5
Test1,1-Recover,47.667,2.892,0.947,0.003,,0.246679,38.1972,,24.6679,0.0381972,,,,7.85398e-5
Test1,1-Recover,48.033,2.92,0.919,-0.003,,0.239385,-38.1972,,23.9385,-0.0381972,,,,7.85398e-5
Test1,1-Recover,48.400,2.949,0.89,-0.003,,0.231831,-38.1972,,23.1831,-0.0381972,,,,7.85398e-5
Test1,1-Recover,48.767,2.977,0.862,-0.003,,0.224538,-38.1972,,22.4538,-0.0381972,,,,7.85398e-5
Test1,1-Recover,49.133,3.005,0.834,0.003,,0.217244,38.1972,,21.7244,0.0381972,,,,7.85398e-5
Test1,1-Recover,49.500,3.033,0.806,0.003,,0.209951,38.1972,,20.9951,0.0381972,,,,7.85398e-5
Test1,1-Recover,49.867,3.062,0.777,0.010,,0.202396,127.324,,20.2396,0.127324,,,,7.85398e-5
Test1,1-Recover,50.233,3.089,0.75,0.003,,0.195363,38.1972,,19.5363,0.0381972,,,,7.85398e-5
Test1,1-Recover,50.600,3.118,0.721,-0.003,,0.187809,-38.1972,,18.7809,-0.0381972,,,,7.85398e-5
Test1,1-Recover,50.967,3.146,0.693,-0.003,,0.180516,-38.1972,,18.0516,-0.0381972,,,,7.85398e-5
Test1,1-Recover,51.333,3.174,0.665,-0.003,,0.173222,-38.1972,,17.3222,-0.0381972,,,,7.85398e-5
Test1,1-Recover,51.700,3.202,0.637,0.003,,0.165929,38.1972,,16.5929,0.0381972,,,,7.85398e-5
Test1,1-Recover,52.067,3.231,0.608,0.003,,0.158375,38.1972,,15.8375,0.0381972,,,,7.85398e-5
Test1,1-Recover,52.433,3.258,0.581,0.010,,0.151341,127.324,,15.1341,0.127324,,,,7.85398e-5
Test1,1-Recover,52.800,3.287,0.552,0.003,,0.143787,38.1972,,14.3787,0.0381972,,,,7.85398e-5
Test1,1-Recover,53.167,3.316,0.523,-0.003,,0.136233,-38.1972,,13.6233,-0.0381972,,,,7.85398e-5
Test1,1-Recover,53.533,3.343,0.496,-0.003,,0.1292,-38.1972,,12.92,-0.0381972,,,,7.85398e-5
Test1,1-Recover,53.900,3.372,0.467,-0.003,,0.121646,-38.1972,,12.1646,-0.0381972,,,,7.85398e-5
Test1,1-Recover,54.267,3.4,0.439,0.003,,0.114353,38.1972,,11.4353,0.0381972,,,,7.85398e-5
Test1,1-Recover,54.633,3.428,0.411,0.003,,0.107059,38.1972,,10.7059,0.0381972,,,,7.85398e-5
Test1,1-Recover,55.000,3.456,0.383,0.010,,0.0997656,127.324,,9.97656,0.127324,,,,7.85398e-5
Test1,1-Recover,55.367,3.484,0.355,-0.003,,0.092472,-38.1972,,9.2472,-0.0381972,,,,7.85398e-5
Test1,1-Recover,55.733,3.512,0.327,-0.003,,0.0851784,-38.1972,,8.51784,-0.0381972,,,,7.85398e-5
Test1,1-Recover,56.100,3.541,0.298,-0.003,,0.0776244,-38.1972,,7.76244,-0.0381972,,,,7.85398e-5
Test1,1-Recover,56.467,3.569,0.27,-0.003,,0.0703308,-38.1972,,7.03308,-0.0381972,,,,7.85398e-5
Test1,1-Recover,56.833,3.597,0.242,0.003,,0.0630372,38.1972,,6.30372,0.0381972,,,,7.85398e-5
Test1,1-Recover,57.200,3.625,0.214,0.003,,0.0557437,38.1972,,5.57437,0.0381972,,,,7.85398e-5
Test1,1-Recover,57.567,3.654,0.185,0.003,,0.0481896,38.1972,,4.81896,0.0381972,,,,7.85398e-5
Test1,1-Recover,57.933,3.681,0.158,-0.003,,0.0411566,-38.1972,,4.11566,-0.0381972,,,,7.85398e-5
Test1,1-Recover,58.300,3.71,0.129,-0.003,,0.0336025,-38.1972,,3.36025,-0.0381972,,,,7.85398e-5
Test1,1-Recover,58.667,3.738,0.101,-0.003,,0.0263089,-38.1972,,2.63089,-0.0381972,,,,7.85398e-5
Test1,1-Recover,59.033,3.766,0.073,-0.003,,0.0190154,-38.1972,,1.90154,-0.0381972,,,,7.85398e-5
Test1,1-Recover,59.400,3.794,0.045,0.003,,0.0117218,38.1972,,1.17218,0.0381972,,,,7.85398e-5
Test1,1-Recover,59.767,3.823,0.016,0.003,,0.00416775,38.1972,,0.416775,0.0381972,,,,7.85398e-5
Test1,2-Compress,60.117,3.833,0.006,0.003,,0.00156291,38.1972,,0.156291,0.0381972,,,,7.85398e-5
Test1,2-Compress,60.483,3.806,0.033,-0.003,,0.00859599,-38.1972,,0.859599,-0.0381972,,,,7.85398e-5
Test1,2-Compress,60.850,3.777,0.062,-0.003,,0.01615,-38.1972,,1.615,-0.0381972,,,,7.85398e-5
Test1,2-Compress,61.217,3.749,0.09,-0.003,,0.0234436,-38.1972,,2.34436,-0.0381972,,,,7.85398e-5
Test1,2-Compress,61.583,3.721,0.118,-0.003,,0.0307372,-38.1972,,3.07372,-0.0381972,,,,7.85398e-5
Test1,2-Compress,61.950,3.693,0.146,0.003,,0.0380307,38.1972,,3.80307,0.0381972,,,,7.85398e-5
Test1,2-Compress,62.317,3.664,0.175,0.010,,0.0455848,127.324,,4.55848,0.127324,,,,7.85398e-5
Test1,2-Compress,62.683,3.637,0.202,0.010,,0.0526179,127.324,,5.26179,0.127324,,,,7.85398e-5
Test1,2-Compress,63.050,3.608,0.231,-0.003,,0.0601719,-38.1972,,6.01719,-0.0381972,,,,7.85398e-5
Test1,2-Compress,63.417,3.58,0.259,-0.003,,0.0674655,-38.1972,,6.74655,-0.0381972,,,,7.85398e-5
Test1,2-Compress,63.783,3.552,0.287,-0.003,,0.0747591,-38.1972,,7.47591,-0.0381972,,,,7.85398e-5
Test1,2-Compress,64.150,3.524,0.315,-0.003,,0.0820526,-38.1972,,8.20526,-0.0381972,,,,7.85398e-5
Test1,2-Compress,64.517,3.495,0.344,0.003,,0.0896067,38.1972,,8.96067,0.0381972,,,,7.85398e-5
Test1,2-Compress,64.883,3.467,0.372,0.003,,0.0969002,38.1972,,9.69002,0.0381972,,,,7.85398e-5
Test1,2-Compress,65.250,3.439,0.4,0.003,,0.104194,38.1972,,10.4194,0.0381972,,,,7.85398e-5
Test1,2-Compress,65.617,3.411,0.428,-0.003,,0.111487,-38.1972,,11.1487,-0.0381972,,,,7.85398e-5
Test1,2-Compress,65.983,3.383,0.456,-0.003,,0.118781,-38.1972,,11.8781,-0.0381972,,,,7.85398e-5
Test1,2-Compress,66.350,3.354,0.485,-0.003,,0.126335,-38.1972,,12.6335,-0.0381972,,,,7.85398e-5
Test1,2-Compress,66.717,3.326,0.513,-0.003,,0.133629,-38.1972,,13.3629,-0.0381972,,,,7.85398e-5
Test1,2-Compress,67.083,3.298,0.541,0.003,,0.140922,38.1972,,14.0922,0.0381972,,,,7.85398e-5
Test1,2-Compress,67.450,3.27,0.569,0.003,,0.148216,38.1972,,14.8216,0.0381972,,,,7.85398e-5
Test1,2-Compress,67.817,3.241,0.598,0.003,,0.15577,38.1972,,15.577,0.0381972,,,,7.85398e-5
Test1,2-Compress,68.183,3.214,0.625,-0.003,,0.162803,-38.1972,,16.2803,-0.0381972,,,,7.85398e-5
Test1,2-Compress,68.550,3.185,0.654,-0.003,,0.170357,-38.1972,,17.0357,-0.0381972,,,,7.85398e-5
Test1,2-Compress,68.917,3.157,0.682,-0.003,,0.17765,-38.1972,,17.765,-0.0381972,,,,7.85398e-5
Test1,2-Compress,69.283,3.129,0.71,-0.003,,0.184944,-38.1972,,18.4944,-0.0381972,,,,7.85398e-5
Test1,2-Compress,69.650,3.101,0.738,0.003,,0.192238,38.1972,,19.2238,0.0381972,,,,7.85398e-5
Test1,2-Compress,70.017,3.072,0.767,0.010,,0.199792,127.324,,19.9792,0.127324,,,,7.85398e-5
Test1,2-Compress,70.383,3.045,0.794,0.010,,0.206825,127.324,,20.6825,0.127324,,,,7.85398e-5
Test1,2-Compress,70.750,3.016,0.823,-0.003,,0.214379,-38.1972,,21.4379,-0.0381972,,,,7.85398e-5
Test1,2-Compress,71.117,2.988,0.851,0.010,,0.221672,127.324,,22.1672,0.127324,,,,7.85398e-5
Test1,2-Compress,71.483,2.96,0.879,0.003,,0.228966,38.1972,,22.8966,0.0381972,,,,7.85398e-5
Test1,2-Compress,71.850,2.931,0.908,0.003,,0.23652,38.1972,,23.652,0.0381972,,,,7.85398e-5
Test1,2-Compress,72.217,2.903,0.936,0.003,,0.243813,38.1972,,24.3813,0.0381972,,,,7.85398e-5
Test1,2-Compress,72.583,2.875,0.964,0.010,,0.251107,127.324,,25.1107,0.127324,,,,7.85398e-5
Test1,2-Compress,72.950,2.847,0.992,0.017,,0.258401,216.451,,25.8401,0.216451,,,,7.85398e-5
Test1,2-Compress,73.317,2.819,1.02,0.017,,0.265694,216.451,,26.5694,0.216451,,,,7.85398e-5
Test1,2-Compress,73.683,2.791,1.048,0.010,,0.272988,127.324,,27.2988,0.127324,,,,7.85398e-5
Test1,2-Compress,74.050,2.762,1.077,0.010,,0.280542,127.324,,28.0542,0.127324,,,,7.85398e-5
Test1,2-Compress,74.417,2.734,1.105,0.003,,0.287835,38.1972,,28.7835,0.0381972,,,,7.85398e-5
Test1,2-Compress,74.783,2.706,1.133,0.010,,0.295129,127.324,,29.5129,0.127324,,,,7.85398e-5
Test1,2-Compress,75.150,2.678,1.161,0.017,,0.302423,216.451,,30.2423,0.216451,,,,7.85398e-5
Test1,2-Compress,75.517,2.649,1.19,0.031,,0.309977,394.704,,30.9977,0.394704,,,,7.85398e-5
Test1,2-Compress,75.883,2.622,1.217,0.017,,0.31701,216.451,,31.701,0.216451,,,,7.85398e-5
Test1,2-Compress,76.250,2.593,1.246,0.010,,0.324564,127.324,,32.4564,0.127324,,,,7.85398e-5
Test1,2-Compress,76.617,2.565,1.274,0.003,,0.331857,38.1972,,33.1857,0.0381972,,,,7.85398e-5
Test1,2-Compress,76.983,2.537,1.302,0.003,,0.339151,38.1972,,33.9151,0.0381972,,,,7.85398e-5
Test1,2-Compress,77.350,2.509,1.33,0.010,,0.346444,127.324,,34.6444,0.127324,,,,7.85398e-5
Test1,2-Compress,77.717,2.48,1.359,0.024,,0.353998,305.578,,35.3998,0.305578,,,,7.85398e-5
Test1,2-Compress,78.083,2.453,1.386,0.031,,0.361032,394.704,,36.1032,0.394704,,,,7.85398e-5
Test1,2-Compress,78.450,2.424,1.415,0.031,,0.368586,394.704,,36.8586,0.394704,,,,7.85398e-5
Test1,2-Compress,78.817,2.395,1.444,0.031,,0.37614,394.704,,37.614,0.394704,,,,7.85398e-5
Test1,2-Compress,79.183,2.368,1.471,0.031,,0.383173,394.704,,38.3173,0.394704,,,,7.85398e-5
Test1,2-Compress,79.550,2.339,1.5,0.010,,0.390727,127.324,,39.0727,0.127324,,,,7.85398e-5
Test1,2-Compress,79.917,2.311,1.528,0.037,,0.39802,471.099,,39.802,0.471099,,,,7.85398e-5
Test1,2-Compress,80.283,2.283,1.556,0.031,,0.405314,394.704,,40.5314,0.394704,,,,7.85398e-5
Test1,2-Compress,80.650,2.255,1.584,0.037,,0.412607,471.099,,41.2607,0.471099,,,,7.85398e-5
Test1,2-Compress,81.017,2.227,1.612,0.037,,0.419901,471.099,,41.9901,0.471099,,,,7.85398e-5
Test1,2-Compress,81.383,2.199,1.64,0.031,,0.427195,394.704,,42.7195,0.394704,,,,7.85398e-5
Test1,2-Compress,81.750,2.17,1.669,0.031,,0.434749,394.704,,43.4749,0.394704,,,,7.85398e-5
Test1,2-Compress,82.117,2.142,1.697,0.003,,0.442042,38.1972,,44.2042,0.0381972,,,,7.85398e-5
Test1,2-Compress,82.483,2.114,1.725,0.031,,0.449336,394.704,,44.9336,0.394704,,,,7.85398e-5
Test1,2-Compress,82.850,2.086,1.753,0.044,,0.456629,560.226,,45.6629,0.560226,,,,7.85398e-5
Test1,2-Compress,83.217,2.057,1.782,0.031,,0.464183,394.704,,46.4183,0.394704,,,,7.85398e-5
Test1,2-Compress,83.583,2.03,1.809,0.031,,0.471216,394.704,,47.1216,0.394704,,,,7.85398e-5
Test1,2-Compress,83.950,2.001,1.838,0.031,,0.478771,394.704,,47.8771,0.394704,,,,7.85398e-5
Test1,2-Compress,84.317,1.973,1.866,0.051,,0.486064,649.352,,48.6064,0.649352,,,,7.85398e-5
Test1,2-Compress,84.683,1.945,1.894,0.051,,0.493358,649.352,,49.3358,0.649352,,,,7.85398e-5
Test1,2-Compress,85.050,1.917,1.922,0.051,,0.500651,649.352,,50.0651,0.649352,,,,7.85398e-5
Test1,2-Compress,85.417,1.888,1.951,0.051,,0.508205,649.352,,50.8205,0.649352,,,,7.85398e-5
Test1,2-Compress,85.783,1.861,1.978,0.044,,0.515238,560.226,,51.5238,0.560226,,,,7.85398e-5
Test1,2-Compress,86.150,1.832,2.007,0.051,,0.522792,649.352,,52.2792,0.649352,,,,7.85398e-5
Test1,2-Compress,86.517,1.803,2.036,0.051,,0.530346,649.352,,53.0346,0.649352,,,,7.85398e-5
Test1,2-Compress,86.883,1.776,2.063,0.051,,0.53738,649.352,,53.738,0.649352,,,,7.85398e-5
Test1,2-Compress,87.250,1.747,2.092,0.051,,0.544934,649.352,,54.4934,0.649352,,,,7.85398e-5
Test1,2-Compress,87.617,1.719,2.12,0.058,,0.552227,738.479,,55.2227,0.738479,,,,7.85398e-5
Test1,2-Compress,87.983,1.691,2.148,0.051,,0.559521,649.352,,55.9521,0.649352,,,,7.85398e-5
Test1,2-Compress,88.350,1.663,2.176,0.051,,0.566814,649.352,,56.6814,0.649352,,,,7.85398e-5
Test1,2-Compress,88.717,1.634,2.205,0.051,,0.574368,649.352,,57.4368,0.649352,,,,7.85398e-5
Test1,2-Compress,89.083,1.607,2.232,0.051,,0.581401,649.352,,58.1401,0.649352,,,,7.85398e-5
Test1,2-Compress,89.450,1.578,2.261,0.051,,0.588955,649.352,,58.8955,0.649352,,,,7.85398e-5
Test1,2-Compress,89.817,1.55,2.289,0.058,,0.596249,738.479,,59.6249,0.738479,,,,7.85398e-5
Test1,2-Recover,90.170,1.544,2.295,0.051,,0.597812,649.352,,59.7812,0.649352,,,,7.85398e-5
Test1,2-Recover,90.537,1.572,2.267,0.051,,0.590518,649.352,,59.0518,0.649352,,,,7.85398e-5
Test1,2-Recover,90.903,1.6,2.239,0.051,,0.583225,649.352,,58.3225,0.649352,,,,7.85398e-5
Test1,2-Recover,91.270,1.629,2.21,0.051,,0.575671,649.352,,57.5671,0.649352,,,,7.85398e-5
Test1,2-Recover,91.637,1.657,2.182,0.031,,0.568377,394.704,,56.8377,0.394704,,,,7.85398e-5
Test1,2-Recover,92.003,1.685,2.154,0.024,,0.561084,305.578,,56.1084,0.305578,,,,7.85398e-5
Test1,2-Recover,92.370,1.713,2.126,0.044,,0.55379,560.226,,55.379,0.560226,,,,7.85398e-5
Test1,2-Recover,92.737,1.742,2.097,0.051,,0.546236,649.352,,54.6236,0.649352,,,,7.85398e-5
Test1,2-Recover,93.103,1.769,2.07,0.044,,0.539203,560.226,,53.9203,0.560226,,,,7.85398e-5
Test1,2-Recover,93.470,1.798,2.041,0.044,,0.531649,560.226,,53.1649,0.560226,,,,7.85398e-5
Test1,2-Recover,93.837,1.826,2.013,0.044,,0.524355,560.226,,52.4355,0.560226,,,,7.85398e-5
Test1,2-Recover,94.203,1.854,1.985,0.024,,0.517062,305.578,,51.7062,0.305578,,,,7.85398e-5
Test1,2-Recover,94.570,1.882,1.957,0.003,,0.509768,38.1972,,50.9768,0.0381972,,,,7.85398e-5
Test1,2-Recover,94.937,1.911,1.928,0.010,,0.502214,127.324,,50.2214,0.127324,,,,7.85398e-5
Test1,2-Recover,95.303,1.938,1.901,0.010,,0.495181,127.324,,49.5181,0.127324,,,,7.85398e-5
Test1,2-Recover,95.670,1.967,1.872,0.031,,0.487627,394.704,,48.7627,0.394704,,,,7.85398e-5
Test1,2-Recover,96.037,1.996,1.843,0.024,,0.480073,305.578,,48.0073,0.305578,,,,7.85398e-5
Test1,2-Recover,96.403,2.023,1.816,0.010,,0.47304,127.324,,47.304,0.127324,,,,7.85398e-5
Test1,2-Recover,96.770,2.052,1.787,0.003,,0.465486,38.1972,,46.5486,0.0381972,,,,7.85398e-5
Test1,2-Recover,97.137,2.08,1.759,0.003,,0.458192,38.1972,,45.8192,0.0381972,,,,7.85398e-5
Test1,2-Recover,97.503,2.108,1.731,0.003,,0.450899,38.1972,,45.0899,0.0381972,,,,7.85398e-5
Test1,2-Recover,97.870,2.136,1.703,0.010,,0.443605,127.324,,44.3605,0.127324,,,,7.85398e-5
Test1,2-Recover,98.237,2.164,1.675,0.003,,0.436312,38.1972,,43.6312,0.0381972,,,,7.85398e-5
Test1,2-Recover,98.603,2.192,1.647,0.003,,0.429018,38.1972,,42.9018,0.0381972,,,,7.85398e-5
Test1,2-Recover,98.970,2.221,1.618,0.003,,0.421464,38.1972,,42.1464,0.0381972,,,,7.85398e-5
Test1,2-Recover,99.337,2.249,1.59,0.003,,0.41417,38.1972,,41.417,0.0381972,,,,7.85398e-5
Test1,2-Recover,99.703,2.277,1.562,0.003,,0.406877,38.1972,,40.6877,0.0381972,,,,7.85398e-5
Test1,2-Recover,100.070,2.305,1.534,0.003,,0.399583,38.1972,,39.9583,0.0381972,,,,7.85398e-5
Test1,2-Recover,100.437,2.334,1.505,0.010,,0.392029,127.324,,39.2029,0.127324,,,,7.85398e-5
Test1,2-Recover,100.803,2.361,1.478,0.010,,0.384996,127.324,,38.4996,0.127324,,,,7.85398e-5
Test1,2-Recover,101.170,2.39,1.449,0.003,,0.377442,38.1972,,37.7442,0.0381972,,,,7.85398e-5
Test1,2-Recover,101.537,2.418,1.421,-0.003,,0.370148,-38.1972,,37.0148,-0.0381972,,,,7.85398e-5
Test1,2-Recover,101.903,2.446,1.393,0.003,,0.362855,38.1972,,36.2855,0.0381972,,,,7.85398e-5
Test1,2-Recover,102.270,2.474,1.365,0.003,,0.355561,38.1972,,35.5561,0.0381972,,,,7.85398e-5
Test1,2-Recover,102.637,2.503,1.336,0.010,,0.348007,127.324,,34.8007,0.127324,,,,7.85398e-5
Test1,2-Recover,103.003,2.53,1.309,0.010,,0.340974,127.324,,34.0974,0.127324,,,,7.85398e-5
Test1,2-Recover,103.370,2.559,1.28,-0.003,,0.33342,-38.1972,,33.342,-0.0381972,,,,7.85398e-5
Test1,2-Recover,103.737,2.588,1.251,-0.003,,0.325866,-38.1972,,32.5866,-0.0381972,,,,7.85398e-5
Test1,2-Recover,104.103,2.615,1.224,-0.003,,0.318833,-38.1972,,31.8833,-0.0381972,,,,7.85398e-5
Test1,2-Recover,104.470,2.644,1.195,-0.003,,0.311279,-38.1972,,31.1279,-0.0381972,,,,7.85398e-5
Test1,2-Recover,104.837,2.672,1.167,0.003,,0.303985,38.1972,,30.3985,0.0381972,,,,7.85398e-5
Test1,2-Recover,105.203,2.7,1.139,0.003,,0.296692,38.1972,,29.6692,0.0381972,,,,7.85398e-5
Test1,2-Recover,105.570,2.728,1.111,0.010,,0.289398,127.324,,28.9398,0.127324,,,,7.85398e-5
Test1,2-Recover,105.937,2.756,1.083,-0.003,,0.282105,-38.1972,,28.2105,-0.0381972,,,,7.85398e-5
Test1,2-Recover,106.303,2.784,1.055,-0.003,,0.274811,-38.1972,,27.4811,-0.0381972,,,,7.85398e-5
Test1,2-Recover,106.670,2.813,1.026,-0.003,,0.267257,-38.1972,,26.7257,-0.0381972,,,,7.85398e-5
Test1,2-Recover,107.037,2.841,0.998,-0.003,,0.259964,-38.1972,,25.9964,-0.0381972,,,,7.85398e-5
Test1,2-Recover,107.403,2.869,0.97,0.003,,0.25267,38.1972,,25.267,0.0381972,,,,7.85398e-5
Test1,2-Recover,107.770,2.897,0.942,0.010,,0.245376,127.324,,24.5376,0.127324,,,,7.85398e-5
Test1,2-Recover,108.137,2.926,0.913,0.003,,0.237822,38.1972,,23.7822,0.0381972,,,,7.85398e-5
Test1,2-Recover,108.503,2.954,0.885,-0.003,,0.230529,-38.1972,,23.0529,-0.0381972,,,,7.85398e-5
Test1,2-Recover,108.870,2.982,0.857,-0.003,,0.223235,-38.1972,,22.3235,-0.0381972,,,,7.85398e-5
Test1,2-Recover,109.237,3.01,0.829,-0.003,,0.215942,-38.1972,,21.5942,-0.0381972,,,,7.85398e-5
Test1,2-Recover,109.603,3.038,0.801,-0.003,,0.208648,-38.1972,,20.8648,-0.0381972,,,,7.85398e-5
Test1,2-Recover,109.970,3.066,0.773,0.003,,0.201355,38.1972,,20.1355,0.0381972,,,,7.85398e-5
Test1,2-Recover,110.337,3.095,0.744,0.010,,0.1938,127.324,,19.38,0.127324,,,,7.85398e-5
Test1,2-Recover,110.703,3.122,0.717,-0.003,,0.186767,-38.1972,,18.6767,-0.0381972,,,,7.85398e-5
Test1,2-Recover,111.070,3.151,0.688,-0.003,,0.179213,-38.1972,,17.9213,-0.0381972,,,,7.85398e-5
Test1,2-Recover,111.437,3.18,0.659,-0.003,,0.171659,-38.1972,,17.1659,-0.0381972,,,,7.85398e-5
Test1,2-Recover,111.803,3.207,0.632,-0.003,,0.164626,-38.1972,,16.4626,-0.0381972,,,,7.85398e-5
Test1,2-Recover,112.170,3.236,0.603,0.003,,0.157072,38.1972,,15.7072,0.0381972,,,,7.85398e-5
Test1,2-Recover,112.537,3.264,0.575,0.003,,0.149779,38.1972,,14.9779,0.0381972,,,,7.85398e-5
Test1,2-Recover,112.903,3.292,0.547,0.003,,0.142485,38.1972,,14.2485,0.0381972,,,,7.85398e-5
Test1,2-Recover,113.270,3.32,0.519,0.003,,0.135191,38.1972,,13.5191,0.0381972,,,,7.85398e-5
Test1,2-Recover,113.637,3.349,0.49,-0.003,,0.127637,-38.1972,,12.7637,-0.0381972,,,,7.85398e-5
Test1,2-Recover,114.003,3.376,0.463,-0.003,,0.120604,-38.1972,,12.0604,-0.0381972,,,,7.85398e-5
Test1,2-Recover,114.370,3.405,0.434,-0.003,,0.11305,-38.1972,,11.305,-0.0381972,,,,7.85398e-5
Test1,2-Recover,114.737,3.433,0.406,0.003,,0.105757,38.1972,,10.5757,0.0381972,,,,7.85398e-5
Test1,2-Recover,115.103,3.461,0.378,0.003,,0.0984631,38.1972,,9.84631,0.0381972,,,,7.85398e-5
Test1,2-Recover,115.470,3.489,0.35,0.003,,0.0911696,38.1972,,9.11696,0.0381972,,,,7.85398e-5
Test1,2-Recover,115.837,3.518,0.321,-0.003,,0.0836155,-38.1972,,8.36155,-0.0381972,,,,7.85398e-5
Test1,2-Recover,116.203,3.546,0.293,-0.003,,0.076322,-38.1972,,7.6322,-0.0381972,,,,7.85398e-5
Test1,2-Recover,116.570,3.574,0.265,-0.003,,0.0690284,-38.1972,,6.90284,-0.0381972,,,,7.85398e-5
Test1,2-Recover,116.937,3.602,0.237,-0.003,,0.0617348,-38.1972,,6.17348,-0.0381972,,,,7.85398e-5
Test1,2-Recover,117.303,3.63,0.209,-0.003,,0.0544413,-38.1972,,5.44413,-0.0381972,,,,7.85398e-5
Test1,2-Recover,117.670,3.658,0.181,0.003,,0.0471477,38.1972,,4.71477,0.0381972,,,,7.85398e-5
Test1,2-Recover,118.037,3.687,0.152,0.010,,0.0395936,127.324,,3.95936,0.127324,,,,7.85398e-5
Test1,2-Recover,118.403,3.714,0.125,-0.003,,0.0325606,-38.1972,,3.25606,-0.0381972,,,,7.85398e-5
Test1,2-Recover,118.770,3.743,0.096,-0.003,,0.0250065,-38.1972,,2.50065,-0.0381972,,,,7.85398e-5
Test1,2-Recover,119.137,3.772,0.067,-0.003,,0.0174525,-38.1972,,1.74525,-0.0381972,,,,7.85398e-5
Test1,2-Recover,119.503,3.799,0.04,-0.003,,0.0104194,-38.1972,,1.04194,-0.0381972,,,,7.85398e-5
Test1,2-Recover,119.870,3.828,0.011,0.003,,0.00286533,38.1972,,0.286533,0.0381972,,,,7.85398e-5
Test1,3-Compress,120.213,3.829,0.01,0.003,,0.00260485,38.1972,,0.260485,0.0381972,,,,7.85398e-5
Test1,3-Compress,120.580,3.801,0.038,0.003,,0.00989841,38.1972,,0.989841,0.0381972,,,,7.85398e-5
Test1,3-Compress,120.947,3.773,0.066,-0.003,,0.017192,-38.1972,,1.7192,-0.0381972,,,,7.85398e-5
Test1,3-Compress,121.313,3.745,0.094,-0.003,,0.0244855,-38.1972,,2.44855,-0.0381972,,,,7.85398e-5
Test1,3-Compress,121.680,3.716,0.123,-0.003,,0.0320396,-38.1972,,3.20396,-0.0381972,,,,7.85398e-5
Test1,3-Compress,122.047,3.688,0.151,-0.003,,0.0393332,-38.1972,,3.93332,-0.0381972,,,,7.85398e-5
Test1,3-Compress,122.413,3.66,0.179,0.003,,0.0466267,38.1972,,4.66267,0.0381972,,,,7.85398e-5
Test1,3-Compress,122.780,3.632,0.207,-0.003,,0.0539203,-38.1972,,5.39203,-0.0381972,,,,7.85398e-5
Test1,3-Compress,123.147,3.603,0.236,0.003,,0.0614743,38.1972,,6.14743,0.0381972,,,,7.85398e-5
Test1,3-Compress,123.513,3.576,0.263,0.003,,0.0685074,38.1972,,6.85074,0.0381972,,,,7.85398e-5
Test1,3-Compress,123.880,3.547,0.292,-0.003,,0.0760615,-38.1972,,7.60615,-0.0381972,,,,7.85398e-5
Test1,3-Compress,124.247,3.519,0.32,-0.003,,0.083355,-38.1972,,8.3355,-0.0381972,,,,7.85398e-5
Test1,3-Compress,124.613,3.491,0.348,-0.003,,0.0906486,-38.1972,,9.06486,-0.0381972,,,,7.85398e-5
Test1,3-Compress,124.980,3.463,0.376,-0.003,,0.0979422,-38.1972,,9.79422,-0.0381972,,,,7.85398e-5
Test1,3-Compress,125.347,3.434,0.405,0.010,,0.105496,127.324,,10.5496,0.127324,,,,7.85398e-5
Test1,3-Compress,125.713,3.407,0.432,0.010,,0.112529,127.324,,11.2529,0.127324,,,,7.85398e-5
Test1,3-Compress,126.080,3.378,0.461,0.003,,0.120083,38.1972,,12.0083,0.0381972,,,,7.85398e-5
Test1,3-Compress,126.447,3.35,0.489,-0.003,,0.127377,-38.1972,,12.7377,-0.0381972,,,,7.85398e-5
Test1,3-Compress,126.813,3.322,0.517,-0.003,,0.13467,-38.1972,,13.467,-0.0381972,,,,7.85398e-5
Test1,3-Compress,127.180,3.293,0.546,-0.003,,0.142225,-38.1972,,14.2225,-0.0381972,,,,7.85398e-5
Test1,3-Compress,127.547,3.265,0.574,0.003,,0.149518,38.1972,,14.9518,0.0381972,,,,7.85398e-5
Test1,3-Compress,127.913,3.237,0.602,0.003,,0.156812,38.1972,,15.6812,0.0381972,,,,7.85398e-5
Test1,3-Compress,128.280,3.209,0.63,0.003,,0.164105,38.1972,,16.4105,0.0381972,,,,7.85398e-5
Test1,3-Compress,128.647,3.181,0.658,-0.003,,0.171399,-38.1972,,17.1399,-0.0381972,,,,7.85398e-5
Test1,3-Compress,129.013,3.153,0.686,-0.003,,0.178692,-38.1972,,17.8692,-0.0381972,,,,7.85398e-5
Test1,3-Compress,129.380,3.124,0.715,-0.003,,0.186246,-38.1972,,18.6246,-0.0381972,,,,7.85398e-5
Test1,3-Compress,129.747,3.096,0.743,-0.003,,0.19354,-38.1972,,19.354,-0.0381972,,,,7.85398e-5
Test1,3-Compress,130.113,3.068,0.771,0.003,,0.200834,38.1972,,20.0834,0.0381972,,,,7.85398e-5
Test1,3-Compress,130.480,3.04,0.799,0.010,,0.208127,127.324,,20.8127,0.127324,,,,7.85398e-5
Test1,3-Compress,130.847,3.011,0.828,0.003,,0.215681,38.1972,,21.5681,0.0381972,,,,7.85398e-5
Test1,3-Compress,131.213,2.984,0.855,0.003,,0.222714,38.1972,,22.2714,0.0381972,,,,7.85398e-5
Test1,3-Compress,131.580,2.955,0.884,0.010,,0.230268,127.324,,23.0268,0.127324,,,,7.85398e-5
Test1,3-Compress,131.947,2.927,0.912,0.003,,0.237562,38.1972,,23.7562,0.0381972,,,,7.85398e-5
Test1,3-Compress,132.313,2.899,0.94,-0.003,,0.244855,-38.1972,,24.4855,-0.0381972,,,,7.85398e-5
Test1,3-Compress,132.680,2.871,0.968,0.003,,0.252149,38.1972,,25.2149,0.0381972,,,,7.85398e-5
Test1,3-Compress,133.047,2.842,0.997,0.017,,0.259703,216.451,,25.9703,0.216451,,,,7.85398e-5
Test1,3-Compress,133.413,2.815,1.024,0.024,,0.266736,305.578,,26.6736,0.305578,,,,7.85398e-5
Test1,3-Compress,133.780,2.786,1.053,0.010,,0.27429,127.324,,27.429,0.127324,,,,7.85398e-5
Test1,3-Compress,134.147,2.757,1.082,0.003,,0.281844,38.1972,,28.1844,0.0381972,,,,7.85398e-5
Test1,3-Compress,134.513,2.73,1.109,0.010,,0.288877,127.324,,28.8877,0.127324,,,,7.85398e-5
Test1,3-Compress,134.880,2.701,1.138,0.003,,0.296431,38.1972,,29.6431,0.0381972,,,,7.85398e-5
Test1,3-Compress,135.247,2.673,1.166,0.003,,0.303725,38.1972,,30.3725,0.0381972,,,,7.85398e-5
Test1,3-Compress,135.613,2.645,1.194,0.010,,0.311018,127.324,,31.1018,0.127324,,,,7.85398e-5
Test1,3-Compress,135.980,2.617,1.222,0.010,,0.318312,127.324,,31.8312,0.127324,,,,7.85398e-5
Test1,3-Compress,136.347,2.589,1.25,0.024,,0.325606,305.578,,32.5606,0.305578,,,,7.85398e-5
Test1,3-Compress,136.713,2.561,1.278,0.017,,0.332899,216.451,,33.2899,0.216451,,,,7.85398e-5
Test1,3-Compress,137.080,2.532,1.307,0.003,,0.340453,38.1972,,34.0453,0.0381972,,,,7.85398e-5
Test1,3-Compress,137.447,2.504,1.335,0.003,,0.347747,38.1972,,34.7747,0.0381972,,,,7.85398e-5
Test1,3-Compress,137.813,2.476,1.363,0.003,,0.35504,38.1972,,35.504,0.0381972,,,,7.85398e-5
Test1,3-Compress,138.180,2.448,1.391,0.017,,0.362334,216.451,,36.2334,0.216451,,,,7.85398e-5
Test1,3-Compress,138.547,2.419,1.42,0.031,,0.369888,394.704,,36.9888,0.394704,,,,7.85398e-5
Test1,3-Compress,138.913,2.392,1.447,0.024,,0.376921,305.578,,37.6921,0.305578,,,,7.85398e-5
Test1,3-Compress,139.280,2.363,1.476,0.024,,0.384475,305.578,,38.4475,0.305578,,,,7.85398e-5
Test1,3-Compress,139.647,2.335,1.504,0.024,,0.391769,305.578,,39.1769,0.305578,,,,7.85398e-5
Test1,3-Compress,140.013,2.307,1.532,0.031,,0.399062,394.704,,39.9062,0.394704,,,,7.85398e-5
Test1,3-Compress,140.380,2.279,1.56,0.003,,0.406356,38.1972,,40.6356,0.0381972,,,,7.85398e-5
Test1,3-Compress,140.747,2.25,1.589,0.031,,0.41391,394.704,,41.391,0.394704,,,,7.85398e-5
Test1,3-Compress,141.113,2.223,1.616,0.044,,0.420943,560.226,,42.0943,0.560226,,,,7.85398e-5
Test1,3-Compress,141.480,2.194,1.645,0.037,,0.428497,471.099,,42.8497,0.471099,,,,7.85398e-5
Test1,3-Compress,141.847,2.165,1.674,0.024,,0.436051,305.578,,43.6051,0.305578,,,,7.85398e-5
Test1,3-Compress,142.213,2.138,1.701,0.010,,0.443084,127.324,,44.3084,0.127324,,,,7.85398e-5
Test1,3-Compress,142.580,2.109,1.73,0.024,,0.450638,305.578,,45.0638,0.305578,,,,7.85398e-5
Test1,3-Compress,142.947,2.081,1.758,0.037,,0.457932,471.099,,45.7932,0.471099,,,,7.85398e-5
Test1,3-Compress,143.313,2.053,1.786,0.044,,0.465225,560.226,,46.5225,0.560226,,,,7.85398e-5
Test1,3-Compress,143.680,2.025,1.814,0.037,,0.472519,471.099,,47.2519,0.471099,,,,7.85398e-5
Test1,3-Compress,144.047,1.997,1.842,0.044,,0.479812,560.226,,47.9812,0.560226,,,,7.85398e-5
Test1,3-Compress,144.413,1.969,1.87,0.024,,0.487106,305.578,,48.7106,0.305578,,,,7.85398e-5
Test1,3-Compress,144.780,1.94,1.899,0.017,,0.49466,216.451,,49.466,0.216451,,,,7.85398e-5
Test1,3-Compress,145.147,1.912,1.927,0.051,,0.501954,649.352,,50.1954,0.649352,,,,7.85398e-5
Test1,3-Compress,145.513,1.884,1.955,0.051,,0.509247,649.352,,50.9247,0.649352,,,,7.85398e-5
Test1,3-Compress,145.880,1.856,1.983,0.051,,0.516541,649.352,,51.6541,0.649352,,,,7.85398e-5
Test1,3-Compress,146.247,1.827,2.012,0.051,,0.524095,649.352,,52.4095,0.649352,,,,7.85398e-5
Test1,3-Compress,146.613,1.799,2.04,0.051,,0.531388,649.352,,53.1388,0.649352,,,,7.85398e-5
Test1,3-Compress,146.980,1.771,2.068,0.051,,0.538682,649.352,,53.8682,0.649352,,,,7.85398e-5
Test1,3-Compress,147.347,1.743,2.096,0.051,,0.545976,649.352,,54.5976,0.649352,,,,7.85398e-5
Test1,3-Compress,147.713,1.715,2.124,0.051,,0.553269,649.352,,55.3269,0.649352,,,,7.85398e-5
Test1,3-Compress,148.080,1.687,2.152,0.051,,0.560563,649.352,,56.0563,0.649352,,,,7.85398e-5
Test1,3-Compress,148.447,1.658,2.181,0.058,,0.568117,738.479,,56.8117,0.738479,,,,7.85398e-5
Test1,3-Compress,148.813,1.631,2.208,0.051,,0.57515,649.352,,57.515,0.649352,,,,7.85398e-5
Test1,3-Compress,149.180,1.602,2.237,0.051,,0.582704,649.352,,58.2704,0.649352,,,,7.85398e-5
Test1,3-Compress,149.547,1.573,2.266,0.051,,0.590258,649.352,,59.0258,0.649352,,,,7.85398e-5
Test1,3-Compress,149.913,1.546,2.293,0.051,,0.597291,649.352,,59.7291,0.649352,,,,7.85398e-5
Test1,3-Recover,150.267,1.549,2.29,0.051,,0.59651,649.352,,59.651,0.649352,,,,7.85398e-5
Test1,3-Recover,150.633,1.576,2.263,0.051,,0.589476,649.352,,58.9476,0.649352,,,,7.85398e-5
Test1,3-Recover,151.000,1.605,2.234,0.051,,0.581922,649.352,,58.1922,0.649352,,,,7.85398e-5
Test1,3-Recover,151.367,1.633,2.206,0.051,,0.574629,649.352,,57.4629,0.649352,,,,7.85398e-5
Test1,3-Recover,151.733,1.661,2.178,0.051,,0.567335,649.352,,56.7335,0.649352,,,,7.85398e-5
Test1,3-Recover,152.100,1.689,2.15,0.051,,0.560042,649.352,,56.0042,0.649352,,,,7.85398e-5
Test1,3-Recover,152.467,1.718,2.121,0.037,,0.552488,471.099,,55.2488,0.471099,,,,7.85398e-5
Test1,3-Recover,152.833,1.746,2.093,0.031,,0.545194,394.704,,54.5194,0.394704,,,,7.85398e-5
Test1,3-Recover,153.200,1.774,2.065,0.044,,0.5379,560.226,,53.79,0.560226,,,,7.85398e-5
Test1,3-Recover,153.567,1.802,2.037,0.037,,0.530607,471.099,,53.0607,0.471099,,,,7.85398e-5
Test1,3-Recover,153.933,1.83,2.009,0.037,,0.523313,471.099,,52.3313,0.471099,,,,7.85398e-5
Test1,3-Recover,154.300,1.859,1.98,0.044,,0.515759,560.226,,51.5759,0.560226,,,,7.85398e-5
Test1,3-Recover,154.667,1.887,1.952,0.037,,0.508466,471.099,,50.8466,0.471099,,,,7.85398e-5
Test1,3-Recover,155.033,1.915,1.924,0.017,,0.501172,216.451,,50.1172,0.216451,,,,7.85398e-5
Test1,3-Recover,155.400,1.943,1.896,0.031,,0.493879,394.704,,49.3879,0.394704,,,,7.85398e-5
Test1,3-Recover,155.767,1.972,1.867,0.017,,0.486325,216.451,,48.6325,0.216451,,,,7.85398e-5
Test1,3-Recover,156.133,1.999,1.84,0.037,,0.479291,471.099,,47.9291,0.471099,,,,7.85398e-5
Test1,3-Recover,156.500,2.028,1.811,0.024,,0.471737,305.578,,47.1737,0.305578,,,,7.85398e-5
Test1,3-Recover,156.867,2.056,1.783,0.017,,0.464444,216.451,,46.4444,0.216451,,,,7.85398e-5
Test1,3-Recover,157.233,2.084,1.755,0.010,,0.45715,127.324,,45.715,0.127324,,,,7.85398e-5
Test1,3-Recover,157.600,2.112,1.727,0.003,,0.449857,38.1972,,44.9857,0.0381972,,,,7.85398e-5
Test1,3-Recover,157.967,2.141,1.698,0.003,,0.442303,38.1972,,44.2303,0.0381972,,,,7.85398e-5
Test1,3-Recover,158.333,2.168,1.671,0.017,,0.43527,216.451,,43.527,0.216451,,,,7.85398e-5
Test1,3-Recover,158.700,2.197,1.642,0.017,,0.427716,216.451,,42.7716,0.216451,,,,7.85398e-5
Test1,3-Recover,159.067,2.225,1.614,0.017,,0.420422,216.451,,42.0422,0.216451,,,,7.85398e-5
Test1,3-Recover,159.433,2.253,1.586,0.010,,0.413128,127.324,,41.3128,0.127324,,,,7.85398e-5
Test1,3-Recover,159.800,2.282,1.557,0.003,,0.405574,38.1972,,40.5574,0.0381972,,,,7.85398e-5
Test1,3-Recover,160.167,2.31,1.529,0.003,,0.398281,38.1972,,39.8281,0.0381972,,,,7.85398e-5
Test1,3-Recover,160.533,2.338,1.501,0.003,,0.390987,38.1972,,39.0987,0.0381972,,,,7.85398e-5
Test1,3-Recover,160.900,2.366,1.473,0.010,,0.383694,127.324,,38.3694,0.127324,,,,7.85398e-5
Test1,3-Recover,161.267,2.394,1.445,0.010,,0.3764,127.324,,37.64,0.127324,,,,7.85398e-5
Test1,3-Recover,161.633,2.422,1.417,0.003,,0.369107,38.1972,,36.9107,0.0381972,,,,7.85398e-5
Test1,3-Recover,162.000,2.451,1.388,0.010,,0.361552,127.324,,36.1552,0.127324,,,,7.85398e-5
Test1,3-Recover,162.367,2.479,1.36,0.003,,0.354259,38.1972,,35.4259,0.0381972,,,,7.85398e-5
Test1,3-Recover,162.733,2.507,1.332,0.003,,0.346965,38.1972,,34.6965,0.0381972,,,,7.85398e-5
Test1,3-Recover,163.100,2.535,1.304,0.003,,0.339672,38.1972,,33.9672,0.0381972,,,,7.85398e-5
Test1,3-Recover,163.467,2.564,1.275,0.010,,0.332118,127.324,,33.2118,0.127324,,,,7.85398e-5
Test1,3-Recover,163.833,2.591,1.248,0.003,,0.325085,38.1972,,32.5085,0.0381972,,,,7.85398e-5
Test1,3-Recover,164.200,2.62,1.219,0.003,,0.317531,38.1972,,31.7531,0.0381972,,,,7.85398e-5
Test1,3-Recover,164.567,2.648,1.191,-0.003,,0.310237,-38.1972,,31.0237,-0.0381972,,,,7.85398e-5
Test1,3-Recover,164.933,2.676,1.163,-0.003,,0.302943,-38.1972,,30.2943,-0.0381972,,,,7.85398e-5
Test1,3-Recover,165.300,2.704,1.135,0.003,,0.29565,38.1972,,29.565,0.0381972,,,,7.85398e-5
Test1,3-Recover,165.667,2.733,1.106,0.010,,0.288096,127.324,,28.8096,0.127324,,,,7.85398e-5
Test1,3-Recover,166.033,2.76,1.079,0.010,,0.281063,127.324,,28.1063,0.127324,,,,7.85398e-5
Test1,3-Recover,166.400,2.789,1.05,0.003,,0.273509,38.1972,,27.3509,0.0381972,,,,7.85398e-5
Test1,3-Recover,166.767,2.818,1.021,-0.003,,0.265955,-38.1972,,26.5955,-0.0381972,,,,7.85398e-5
Test1,3-Recover,167.133,2.845,0.994,-0.003,,0.258922,-38.1972,,25.8922,-0.0381972,,,,7.85398e-5
Test1,3-Recover,167.500,2.874,0.965,-0.003,,0.251368,-38.1972,,25.1368,-0.0381972,,,,7.85398e-5
Test1,3-Recover,167.867,2.902,0.937,0.003,,0.244074,38.1972,,24.4074,0.0381972,,,,7.85398e-5
Test1,3-Recover,168.233,2.93,0.909,0.003,,0.23678,38.1972,,23.678,0.0381972,,,,7.85398e-5
Test1,3-Recover,168.600,2.958,0.881,0.010,,0.229487,127.324,,22.9487,0.127324,,,,7.85398e-5
Test1,3-Recover,168.967,2.987,0.852,-0.003,,0.221933,-38.1972,,22.1933,-0.0381972,,,,7.85398e-5
Test1,3-Recover,169.333,3.014,0.825,-0.003,,0.2149,-38.1972,,21.49,-0.0381972,,,,7.85398e-5
Test1,3-Recover,169.700,3.043,0.796,-0.003,,0.207346,-38.1972,,20.7346,-0.0381972,,,,7.85398e-5
Test1,3-Recover,170.067,3.071,0.768,-0.003,,0.200052,-38.1972,,20.0052,-0.0381972,,,,7.85398e-5
Test1,3-Recover,170.433,3.099,0.74,0.003,,0.192759,38.1972,,19.2759,0.0381972,,,,7.85398e-5
Test1,3-Recover,170.800,3.127,0.712,0.003,,0.185465,38.1972,,18.5465,0.0381972,,,,7.85398e-5
Test1,3-Recover,171.167,3.156,0.683,0.003,,0.177911,38.1972,,17.7911,0.0381972,,,,7.85398e-5
Test1,3-Recover,171.533,3.184,0.655,-0.003,,0.170617,-38.1972,,17.0617,-0.0381972,,,,7.85398e-5
Test1,3-Recover,171.900,3.212,0.627,-0.003,,0.163324,-38.1972,,16.3324,-0.0381972,,,,7.85398e-5
Test1,3-Recover,172.267,3.24,0.599,-0.003,,0.15603,-38.1972,,15.603,-0.0381972,,,,7.85398e-5
Test1,3-Recover,172.633,3.268,0.571,-0.003,,0.148737,-38.1972,,14.8737,-0.0381972,,,,7.85398e-5
Test1,3-Recover,173.000,3.296,0.543,0.003,,0.141443,38.1972,,14.1443,0.0381972,,,,7.85398e-5
Test1,3-Recover,173.367,3.325,0.514,0.003,,0.133889,38.1972,,13.3889,0.0381972,,,,7.85398e-5
Test1,3-Recover,173.733,3.352,0.487,0.010,,0.126856,127.324,,12.6856,0.127324,,,,7.85398e-5
Test1,3-Recover,174.100,3.381,0.458,-0.003,,0.119302,-38.1972,,11.9302,-0.0381972,,,,7.85398e-5
Test1,3-Recover,174.467,3.41,0.429,-0.003,,0.111748,-38.1972,,11.1748,-0.0381972,,,,7.85398e-5
Test1,3-Recover,174.833,3.437,0.402,-0.003,,0.104715,-38.1972,,10.4715,-0.0381972,,,,7.85398e-5
Test1,3-Recover,175.200,3.466,0.373,-0.003,,0.0971607,-38.1972,,9.71607,-0.0381972,,,,7.85398e-5
Test1,3-Recover,175.567,3.494,0.345,0.003,,0.0898672,38.1972,,8.98672,0.0381972,,,,7.85398e-5
Test1,3-Recover,175.933,3.522,0.317,0.003,,0.0825736,38.1972,,8.25736,0.0381972,,,,7.85398e-5
Test1,3-Recover,176.300,3.55,0.289,0.003,,0.07528,38.1972,,7.528,0.0381972,,,,7.85398e-5
Test1,3-Recover,176.667,3.579,0.26,-0.003,,0.067726,-38.1972,,6.7726,-0.0381972,,,,7.85398e-5
Test1,3-Recover,177.033,3.606,0.233,-0.003,,0.0606929,-38.1972,,6.06929,-0.0381972,,,,7.85398e-5
Test1,3-Recover,177.400,3.635,0.204,-0.003,,0.0531388,-38.1972,,5.31388,-0.0381972,,,,7.85398e-5
Test1,3-Recover,177.767,3.663,0.176,0.003,,0.0458453,38.1972,,4.58453,0.0381972,,,,7.85398e-5
Test1,3-Recover,178.133,3.691,0.148,0.003,,0.0385517,38.1972,,3.85517,0.0381972,,,,7.85398e-5
Test1,3-Recover,178.500,3.719,0.12,0.017,,0.0312581,216.451,,3.12581,0.216451,,,,7.85398e-5
Test1,3-Recover,178.867,3.748,0.091,0.003,,0.0237041,38.1972,,2.37041,0.0381972,,,,7.85398e-5
Test1,3-Recover,179.233,3.776,0.063,-0.003,,0.0164105,-38.1972,,1.64105,-0.0381972,,,,7.85398e-5
Test1,3-Recover,179.600,3.804,0.035,-0.003,,0.00911696,-38.1972,,0.911696,-0.0381972,,,,7.85398e-5
Test1,3-Recover,179.967,3.832,0.007,-0.003,,0.00182339,-38.1972,,0.182339,-0.0381972,,,,7.85398e-5
Test1,3-Recover,180.100,3.839,-0,0.010,,0,127.324,,0,0.127324,,,,7.85398e-5