File: data/beta_1-1-1_2.csv
SetName,Cycle,Time_S,Size_mm,Displacement_mm,Force_N,,Strain,Stress(Pascal),,%Strain,Stress(kPa),,,,Area(m^2)
Test1,1-Compress,0.000,4.005,-0,-0.002,,0,-25.4648,,0,-0.0254648,,,,7.85398e-5
Test1,1-Compress,0.333,3.979,0.026,0.012,,0.00649189,152.789,,0.649189,0.152789,,,,7.85398e-5
Test1,1-Compress,0.667,3.952,0.053,0.012,,0.0132335,152.789,,1.32335,0.152789,,,,7.85398e-5
Test1,1-Compress,1.000,3.926,0.079,-0.002,,0.0197253,-25.4648,,1.97253,-0.0254648,,,,7.85398e-5
Test1,1-Compress,1.333,3.899,0.106,0.012,,0.0264669,152.789,,2.64669,0.152789,,,,7.85398e-5
Test1,1-Compress,1.667,3.872,0.133,0.012,,0.0332085,152.789,,3.32085,0.152789,,,,7.85398e-5
Test1,1-Compress,2.000,3.846,0.159,0.012,,0.0397004,152.789,,3.97004,0.152789,,,,7.85398e-5
Test1,1-Compress,2.333,3.819,0.186,0.005,,0.0464419,63.662,,4.64419,0.063662,,,,7.85398e-5
Test1,1-Compress,2.667,3.792,0.213,0.012,,0.0531835,152.789,,5.31835,0.152789,,,,7.85398e-5
Test1,1-Compress,3.000,3.765,0.24,0.005,,0.0599251,63.662,,5.99251,0.063662,,,,7.85398e-5
Test1,1-Compress,3.333,3.739,0.266,0.019,,0.066417,241.916,,6.6417,0.241916,,,,7.85398e-5
Test1,1-Compress,3.667,3.712,0.293,0.012,,0.0731586,152.789,,7.31586,0.152789,,,,7.85398e-5
Test1,1-Compress,4.000,3.685,0.32,-0.002,,0.0799001,-25.4648,,7.99001,-0.0254648,,,,7.85398e-5
Test1,1-Compress,4.333,3.659,0.346,0.005,,0.086392,63.662,,8.6392,0.063662,,,,7.85398e-5
Test1,1-Compress,4.667,3.631,0.374,-0.002,,0.0933833,-25.4648,,9.33833,-0.0254648,,,,7.85398e-5
Test1,1-Compress,5.000,3.605,0.4,-0.002,,0.0998752,-25.4648,,9.98752,-0.0254648,,,,7.85398e-5
Test1,1-Compress,5.333,3.579,0.426,-0.009,,0.106367,-114.592,,10.6367,-0.114592,,,,7.85398e-5
Test1,1-Compress,5.667,3.551,0.454,-0.009,,0.113358,-114.592,,11.3358,-0.114592,,,,7.85398e-5
Test1,1-Compress,6.000,3.525,0.48,-0.002,,0.11985,-25.4648,,11.985,-0.0254648,,,,7.85398e-5
Test1,1-Compress,6.333,3.498,0.507,-0.002,,0.126592,-25.4648,,12.6592,-0.0254648,,,,7.85398e-5
Test1,1-Compress,6.667,3.471,0.534,-0.009,,0.133333,-114.592,,13.3333,-0.114592,,,,7.85398e-5
Test1,1-Compress,7.000,3.445,0.56,-0.002,,0.139825,-25.4648,,13.9825,-0.0254648,,,,7.85398e-5
Test1,1-Compress,7.333,3.418,0.587,0.005,,0.146567,63.662,,14.6567,0.063662,,,,7.85398e-5
Test1,1-Compress,7.667,3.391,0.614,-0.002,,0.153308,-25.4648,,15.3308,-0.0254648,,,,7.85398e-5
Test1,1-Compress,8.000,3.364,0.641,-0.002,,0.16005,-25.4648,,16.005,-0.0254648,,,,7.85398e-5
Test1,1-Compress,8.333,3.338,0.667,0.005,,0.166542,63.662,,16.6542,0.063662,,,,7.85398e-5
Test1,1-Compress,8.667,3.311,0.694,0.012,,0.173283,152.789,,17.3283,0.152789,,,,7.85398e-5
Test1,1-Compress,9.000,3.284,0.721,0.012,,0.180025,152.789,,18.0025,0.152789,,,,7.85398e-5
Test1,1-Compress,9.333,3.258,0.747,0.019,,0.186517,241.916,,18.6517,0.241916,,,,7.85398e-5
Test1,1-Compress,9.667,3.23,0.775,0.019,,0.193508,241.916,,19.3508,0.241916,,,,7.85398e-5
Test1,1-Compress,10.000,3.204,0.801,0.012,,0.2,152.789,,20,0.152789,,,,7.85398e-5
Test1,1-Compress,10.333,3.177,0.828,0.019,,0.206742,241.916,,20.6742,0.241916,,,,7.85398e-5
Test1,1-Compress,10.667,3.15,0.855,0.012,,0.213483,152.789,,21.3483,0.152789,,,,7.85398e-5
Test1,1-Compress,11.000,3.124,0.881,0.012,,0.219975,152.789,,21.9975,0.152789,,,,7.85398e-5
Test1,1-Compress,11.333,3.097,0.908,0.012,,0.226717,152.789,,22.6717,0.152789,,,,7.85398e-5
Test1,1-Compress,11.667,3.07,0.935,0.012,,0.233458,152.789,,23.3458,0.152789,,,,7.85398e-5
Test1,1-Compress,12.000,3.043,0.962,0.025,,0.2402,318.31,,24.02,0.31831,,,,7.85398e-5
Test1,1-Compress,12.333,3.017,0.988,-0.002,,0.246692,-25.4648,,24.6692,-0.0254648,,,,7.85398e-5
Test1,1-Compress,12.667,2.99,1.015,0.005,,0.253433,63.662,,25.3433,0.063662,,,,7.85398e-5
Test1,1-Compress,13.000,2.963,1.042,0.019,,0.260175,241.916,,26.0175,0.241916,,,,7.85398e-5
Test1,1-Compress,13.333,2.937,1.068,0.005,,0.266667,63.662,,26.6667,0.063662,,,,7.85398e-5
Test1,1-Compress,13.667,2.909,1.096,0.005,,0.273658,63.662,,27.3658,0.063662,,,,7.85398e-5
Test1,1-Compress,14.000,2.883,1.122,0.032,,0.28015,407.437,,28.015,0.407437,,,,7.85398e-5
Test1,1-Compress,14.333,2.856,1.149,0.019,,0.286891,241.916,,28.6891,0.241916,,,,7.85398e-5
Test1,1-Compress,14.667,2.829,1.176,0.019,,0.293633,241.916,,29.3633,0.241916,,,,7.85398e-5
Test1,1-Compress,15.000,2.803,1.202,0.005,,0.300125,63.662,,30.0125,0.063662,,,,7.85398e-5
Test1,1-Compress,15.333,2.776,1.229,0.005,,0.306866,63.662,,30.6866,0.063662,,,,7.85398e-5
Test1,1-Compress,15.667,2.749,1.256,0.012,,0.313608,152.789,,31.3608,0.152789,,,,7.85398e-5
Test1,1-Compress,16.000,2.723,1.282,0.032,,0.3201,407.437,,32.01,0.407437,,,,7.85398e-5
Test1,1-Compress,16.333,2.696,1.309,0.032,,0.326841,407.437,,32.6841,0.407437,,,,7.85398e-5
Test1,1-Compress,16.667,2.669,1.336,0.039,,0.333583,496.564,,33.3583,0.496564,,,,7.85398e-5
Test1,1-Compress,17.000,2.642,1.363,0.039,,0.340325,496.564,,34.0325,0.496564,,,,7.85398e-5
Test1,1-Compress,17.333,2.616,1.389,0.032,,0.346816,407.437,,34.6816,0.407437,,,,7.85398e-5
Test1,1-Compress,17.667,2.589,1.416,0.032,,0.353558,407.437,,35.3558,0.407437,,,,7.85398e-5
Test1,1-Compress,18.000,2.562,1.443,0.039,,0.3603,496.564,,36.03,0.496564,,,,7.85398e-5
Test1,1-Compress,18.333,2.536,1.469,0.039,,0.366792,496.564,,36.6792,0.496564,,,,7.85398e-5
Test1,1-Compress,18.667,2.508,1.497,0.032,,0.373783,407.437,,37.3783,0.407437,,,,7.85398e-5
Test1,1-Compress,19.000,2.482,1.523,0.032,,0.380275,407.437,,38.0275,0.407437,,,,7.85398e-5
Test1,1-Compress,19.333,2.455,1.55,0.039,,0.387016,496.564,,38.7016,0.496564,,,,7.85398e-5
Test1,1-Compress,19.667,2.428,1.577,0.039,,0.393758,496.564,,39.3758,0.496564,,,,7.85398e-5
Test1,1-Compress,20.000,2.402,1.603,0.039,,0.40025,496.564,,40.025,0.496564,,,,7.85398e-5
Test1,1-Compress,20.333,2.375,1.63,0.039,,0.406991,496.564,,40.6991,0.496564,,,,7.85398e-5
Test1,1-Compress,20.667,2.348,1.657,0.039,,0.413733,496.564,,41.3733,0.496564,,,,7.85398e-5
Test1,1-Compress,21.000,2.321,1.684,0.039,,0.420474,496.564,,42.0474,0.496564,,,,7.85398e-5
Test1,1-Compress,21.333,2.295,1.71,0.039,,0.426966,496.564,,42.6966,0.496564,,,,7.85398e-5
Test1,1-Compress,21.667,2.268,1.737,0.039,,0.433708,496.564,,43.3708,0.496564,,,,7.85398e-5
Test1,1-Compress,22.000,2.241,1.764,0.039,,0.440449,496.564,,44.0449,0.496564,,,,7.85398e-5
Test1,1-Compress,22.333,2.215,1.79,0.046,,0.446941,585.69,,44.6941,0.58569,,,,7.85398e-5
Test1,1-Compress,22.667,2.188,1.817,0.046,,0.453683,585.69,,45.3683,0.58569,,,,7.85398e-5
Test1,1-Compress,23.000,2.161,1.844,0.046,,0.460424,585.69,,46.0424,0.58569,,,,7.85398e-5
Test1,1-Compress,23.333,2.134,1.871,0.046,,0.467166,585.69,,46.7166,0.58569,,,,7.85398e-5
Test1,1-Compress,23.667,2.107,1.898,0.046,,0.473908,585.69,,47.3908,0.58569,,,,7.85398e-5
Test1,1-Compress,24.000,2.081,1.924,0.046,,0.4804,585.69,,48.04,0.58569,,,,7.85398e-5
Test1,1-Compress,24.333,2.055,1.95,0.046,,0.486891,585.69,,48.6891,0.58569,,,,7.85398e-5
Test1,1-Compress,24.667,2.027,1.978,0.046,,0.493883,585.69,,49.3883,0.58569,,,,7.85398e-5
Test1,1-Compress,25.000,2,2.005,0.039,,0.500624,496.564,,50.0624,0.496564,,,,7.85398e-5
Test1,1-Compress,25.333,1.974,2.031,0.053,,0.507116,674.817,,50.7116,0.674817,,,,7.85398e-5
Test1,1-Compress,25.667,1.947,2.058,0.039,,0.513858,496.564,,51.3858,0.496564,,,,7.85398e-5
Test1,1-Compress,26.000,1.921,2.084,0.046,,0.52035,585.69,,52.035,0.58569,,,,7.85398e-5
Test1,1-Compress,26.333,1.894,2.111,0.039,,0.527091,496.564,,52.7091,0.496564,,,,7.85398e-5
Test1,1-Compress,26.667,1.866,2.139,0.039,,0.534082,496.564,,53.4082,0.496564,,,,7.85398e-5
Test1,1-Compress,27.000,1.84,2.165,0.039,,0.540574,496.564,,54.0574,0.496564,,,,7.85398e-5
Test1,1-Compress,27.333,1.814,2.191,0.039,,0.547066,496.564,,54.7066,0.496564,,,,7.85398e-5
Test1,1-Compress,27.667,1.787,2.218,0.039,,0.553808,496.564,,55.3808,0.496564,,,,7.85398e-5
Test1,1-Compress,28.000,1.76,2.245,0.039,,0.560549,496.564,,56.0549,0.496564,,,,7.85398e-5
Test1,1-Compress,28.333,1.733,2.272,0.039,,0.567291,496.564,,56.7291,0.496564,,,,7.85398e-5
Test1,1-Compress,28.667,1.706,2.299,0.039,,0.574032,496.564,,57.4032,0.496564,,,,7.85398e-5
Test1,1-Compress,29.000,1.68,2.325,0.039,,0.580524,496.564,,58.0524,0.496564,,,,7.85398e-5
Test1,1-Compress,29.333,1.653,2.352,0.039,,0.587266,496.564,,58.7266,0.496564,,,,7.85398e-5
Test1,1-Compress,29.667,1.626,2.379,0.039,,0.594007,496.564,,59.4007,0.496564,,,,7.85398e-5
Test1,1-Compress,30.000,1.602,2.403,0.039,,0.6,496.564,,60,0.496564,,,,7.85398e-5
Test1,1-Recover,30.333,1.627,2.378,0.046,,0.593758,585.69,,59.3758,0.58569,,,,7.85398e-5
Test1,1-Recover,30.667,1.654,2.351,0.046,,0.587016,585.69,,58.7016,0.58569,,,,7.85398e-5
Test1,1-Recover,31.000,1.68,2.325,0.046,,0.580524,585.69,,58.0524,0.58569,,,,7.85398e-5
Test1,1-Recover,31.333,1.707,2.298,0.046,,0.573783,585.69,,57.3783,0.58569,,,,7.85398e-5
Test1,1-Recover,31.667,1.734,2.271,0.046,,0.567041,585.69,,56.7041,0.58569,,,,7.85398e-5
Test1,1-Recover,32.000,1.761,2.244,0.046,,0.5603,585.69,,56.03,0.58569,,,,7.85398e-5
Test1,1-Recover,32.333,1.787,2.218,0.053,,0.553808,674.817,,55.3808,0.674817,,,,7.85398e-5
Test1,1-Recover,32.667,1.814,2.191,0.053,,0.547066,674.817,,54.7066,0.674817,,,,7.85398e-5
Test1,1-Recover,33.000,1.841,2.164,0.053,,0.540325,674.817,,54.0325,0.674817,,,,7.85398e-5
Test1,1-Recover,33.333,1.867,2.138,0.046,,0.533833,585.69,,53.3833,0.58569,,,,7.85398e-5
Test1,1-Recover,33.667,1.895,2.11,0.039,,0.526841,496.564,,52.6841,0.496564,,,,7.85398e-5
Test1,1-Recover,34.000,1.921,2.084,0.046,,0.52035,585.69,,52.035,0.58569,,,,7.85398e-5
Test1,1-Recover,34.333,1.947,2.058,0.039,,0.513858,496.564,,51.3858,0.496564,,,,7.85398e-5
Test1,1-Recover,34.667,1.975,2.03,0.039,,0.506866,496.564,,50.6866,0.496564,,,,7.85398e-5
Test1,1-Recover,35.000,2.001,2.004,0.039,,0.500375,496.564,,50.0375,0.496564,,,,7.85398e-5
Test1,1-Recover,35.333,2.028,1.977,0.039,,0.493633,496.564,,49.3633,0.496564,,,,7.85398e-5
Test1,1-Recover,35.667,2.055,1.95,0.039,,0.486891,496.564,,48.6891,0.496564,,,,7.85398e-5
Test1,1-Recover,36.000,2.081,1.924,0.039,,0.4804,496.564,,48.04,0.496564,,,,7.85398e-5
Test1,1-Recover,36.333,2.108,1.897,0.039,,0.473658,496.564,,47.3658,0.496564,,,,7.85398e-5
Test1,1-Recover,36.667,2.135,1.87,0.032,,0.466916,407.437,,46.6916,0.407437,,,,7.85398e-5
Test1,1-Recover,37.000,2.162,1.843,0.039,,0.460175,496.564,,46.0175,0.496564,,,,7.85398e-5
Test1,1-Recover,37.333,2.188,1.817,0.039,,0.453683,496.564,,45.3683,0.496564,,,,7.85398e-5
Test1,1-Recover,37.667,2.215,1.79,0.025,,0.446941,318.31,,44.6941,0.31831,,,,7.85398e-5
Test1,1-Recover,38.000,2.242,1.763,0.019,,0.4402,241.916,,44.02,0.241916,,,,7.85398e-5
Test1,1-Recover,38.333,2.268,1.737,0.019,,0.433708,241.916,,43.3708,0.241916,,,,7.85398e-5
Test1,1-Recover,38.667,2.295,1.71,0.039,,0.426966,496.564,,42.6966,0.496564,,,,7.85398e-5
Test1,1-Recover,39.000,2.322,1.683,0.039,,0.420225,496.564,,42.0225,0.496564,,,,7.85398e-5
Test1,1-Recover,39.333,2.349,1.656,0.005,,0.413483,63.662,,41.3483,0.063662,,,,7.85398e-5
Test1,1-Recover,39.667,2.376,1.629,0.019,,0.406742,241.916,,40.6742,0.241916,,,,7.85398e-5
Test1,1-Recover,40.000,2.402,1.603,0.025,,0.40025,318.31,,40.025,0.31831,,,,7.85398e-5
Test1,1-Recover,40.333,2.429,1.576,0.019,,0.393508,241.916,,39.3508,0.241916,,,,7.85398e-5
Test1,1-Recover,40.667,2.456,1.549,0.012,,0.386767,152.789,,38.6767,0.152789,,,,7.85398e-5
Test1,1-Recover,41.000,2.483,1.522,0.019,,0.380025,241.916,,38.0025,0.241916,,,,7.85398e-5
Test1,1-Recover,41.333,2.509,1.496,0.032,,0.373533,407.437,,37.3533,0.407437,,,,7.85398e-5
Test1,1-Recover,41.667,2.536,1.469,0.019,,0.366792,241.916,,36.6792,0.241916,,,,7.85398e-5
Test1,1-Recover,42.000,2.563,1.442,0.025,,0.36005,318.31,,36.005,0.31831,,,,7.85398e-5
Test1,1-Recover,42.333,2.589,1.416,0.019,,0.353558,241.916,,35.3558,0.241916,,,,7.85398e-5
Test1,1-Recover,42.667,2.616,1.389,0.012,,0.346816,152.789,,34.6816,0.152789,,,,7.85398e-5
Test1,1-Recover,43.000,2.643,1.362,0.012,,0.340075,152.789,,34.0075,0.152789,,,,7.85398e-5
Test1,1-Recover,43.333,2.669,1.336,0.019,,0.333583,241.916,,33.3583,0.241916,,,,7.85398e-5
Test1,1-Recover,43.667,2.697,1.308,0.012,,0.326592,152.789,,32.6592,0.152789,,,,7.85398e-5
Test1,1-Recover,44.000,2.723,1.282,0.005,,0.3201,63.662,,32.01,0.063662,,,,7.85398e-5
Test1,1-Recover,44.333,2.75,1.255,-0.002,,0.313358,-25.4648,,31.3358,-0.0254648,,,,7.85398e-5
Test1,1-Recover,44.667,2.777,1.228,-0.002,,0.306617,-25.4648,,30.6617,-0.0254648,,,,7.85398e-5
Test1,1-Recover,45.000,2.803,1.202,-0.002,,0.300125,-25.4648,,30.0125,-0.0254648,,,,7.85398e-5
Test1,1-Recover,45.333,2.83,1.175,-0.009,,0.293383,-114.592,,29.3383,-0.114592,,,,7.85398e-5
Test1,1-Recover,45.667,2.857,1.148,-0.009,,0.286642,-114.592,,28.6642,-0.114592,,,,7.85398e-5
Test1,1-Recover,46.000,2.884,1.121,-0.009,,0.2799,-114.592,,27.99,-0.114592,,,,7.85398e-5
Test1,1-Recover,46.333,2.91,1.095,-0.009,,0.273408,-114.592,,27.3408,-0.114592,,,,7.85398e-5
Test1,1-Recover,46.667,2.937,1.068,-0.009,,0.266667,-114.592,,26.6667,-0.114592,,,,7.85398e-5
Test1,1-Recover,47.000,2.964,1.041,-0.009,,0.259925,-114.592,,25.9925,-0.114592,,,,7.85398e-5
Test1,1-Recover,47.333,2.99,1.015,-0.002,,0.253433,-25.4648,,25.3433,-0.0254648,,,,7.85398e-5
Test1,1-Recover,47.667,3.018,0.987,0.005,,0.246442,63.662,,24.6442,0.063662,,,,7.85398e-5
Test1,1-Recover,48.000,3.044,0.961,0.005,,0.23995,63.662,,23.995,0.063662,,,,7.85398e-5
Test1,1-Recover,48.333,3.07,0.935,0.012,,0.233458,152.789,,23.3458,0.152789,,,,7.85398e-5
Test1,1-Recover,48.667,3.098,0.907,0.005,,0.226467,63.662,,22.6467,0.063662,,,,7.85398e-5
Test1,1-Recover,49.000,3.124,0.881,0.012,,0.219975,152.789,,21.9975,0.152789,,,,7.85398e-5
Test1,1-Recover,49.333,3.151,0.854,0.012,,0.213233,152.789,,21.3233,0.152789,,,,7.85398e-5
Test1,1-Recover,49.667,3.178,0.827,0.005,,0.206492,63.662,,20.6492,0.063662,,,,7.85398e-5
Test1,1-Recover,50.000,3.204,0.801,0.005,,0.2,63.662,,20,0.063662,,,,7.85398e-5
Test1,1-Recover,50.333,3.231,0.774,0.012,,0.193258,152.789,,19.3258,0.152789,,,,7.85398e-5
Test1,1-Recover,50.667,3.258,0.747,-0.002,,0.186517,-25.4648,,18.6517,-0.0254648,,,,7.85398e-5
Test1,1-Recover,51.000,3.284,0.721,-0.002,,0.180025,-25.4648,,18.0025,-0.0254648,,,,7.85398e-5
Test1,1-Recover,51.333,3.311,0.694,-0.002,,0.173283,-25.4648,,17.3283,-0.0254648,,,,7.85398e-5
Test1,1-Recover,51.667,3.338,0.667,-0.009,,0.166542,-114.592,,16.6542,-0.114592,,,,7.85398e-5
Test1,1-Recover,52.000,3.365,0.64,-0.009,,0.1598,-114.592,,15.98,-0.114592,,,,7.85398e-5
Test1,1-Recover,52.333,3.391,0.614,-0.009,,0.153308,-114.592,,15.3308,-0.114592,,,,7.85398e-5
Test1,1-Recover,52.667,3.418,0.587,-0.002,,0.146567,-25.4648,,14.6567,-0.0254648,,,,7.85398e-5
Test1,1-Recover,53.000,3.445,0.56,-0.002,,0.139825,-25.4648,,13.9825,-0.0254648,,,,7.85398e-5
Test1,1-Recover,53.333,3.472,0.533,-0.009,,0.133084,-114.592,,13.3084,-0.114592,,,,7.85398e-5
Test1,1-Recover,53.667,3.499,0.506,-0.002,,0.126342,-25.4648,,12.6342,-0.0254648,,,,7.85398e-5
Test1,1-Recover,54.000,3.525,0.48,-0.002,,0.11985,-25.4648,,11.985,-0.0254648,,,,7.85398e-5
Test1,1-Recover,54.333,3.552,0.453,0.005,,0.113109,63.662,,11.3109,0.063662,,,,7.85398e-5
Test1,1-Recover,54.667,3.579,0.426,-0.002,,0.106367,-25.4648,,10.6367,-0.0254648,,,,7.85398e-5
Test1,1-Recover,55.000,3.606,0.399,-0.002,,0.0996255,-25.4648,,9.96255,-0.0254648,,,,7.85398e-5
Test1,1-Recover,55.333,3.632,0.373,-0.002,,0.0931336,-25.4648,,9.31336,-0.0254648,,,,7.85398e-5
Test1,1-Recover,55.667,3.659,0.346,0.012,,0.086392,152.789,,8.6392,0.152789,,,,7.85398e-5
Test1,1-Recover,56.000,3.686,0.319,-0.002,,0.0796504,-25.4648,,7.96504,-0.0254648,,,,7.85398e-5
Test1,1-Recover,56.333,3.712,0.293,-0.002,,0.0731586,-25.4648,,7.31586,-0.0254648,,,,7.85398e-5
Test1,1-Recover,56.667,3.74,0.265,0.005,,0.0661673,63.662,,6.61673,0.063662,,,,7.85398e-5
Test1,1-Recover,57.000,3.766,0.239,0.005,,0.0596754,63.662,,5.96754,0.063662,,,,7.85398e-5
Test1,1-Recover,57.333,3.792,0.213,0.019,,0.0531835,241.916,,5.31835,0.241916,,,,7.85398e-5
Test1,1-Recover,57.667,3.82,0.185,0.012,,0.0461923,152.789,,4.61923,0.152789,,,,7.85398e-5
Test1,1-Recover,58.000,3.846,0.159,0.019,,0.0397004,241.916,,3.97004,0.241916,,,,7.85398e-5
Test1,1-Recover,58.333,3.873,0.132,-0.009,,0.0329588,-114.592,,3.29588,-0.114592,,,,7.85398e-5
Test1,1-Recover,58.667,3.9,0.105,-0.002,,0.0262172,-25.4648,,2.62172,-0.0254648,,,,7.85398e-5
Test1,1-Recover,59.000,3.926,0.079,0.005,,0.0197253,63.662,,1.97253,0.063662,,,,7.85398e-5
Test1,1-Recover,59.333,3.953,0.052,-0.002,,0.0129838,-25.4648,,1.29838,-0.0254648,,,,7.85398e-5
Test1,1-Recover,59.667,3.98,0.025,0.012,,0.0062422,152.789,,0.62422,0.152789,,,,7.85398e-5
Test1,1-Recover,60.000,4.005,-0,-0.002,,0,-25.4648,,0,-0.0254648,,,,7.85398e-5
Test1,2-Compress,60.317,3.983,0.022,0.005,,0.00549313,63.662,,0.549313,0.063662,,,,7.85398e-5
Test1,2-Compress,60.650,3.957,0.048,0.005,,0.011985,63.662,,1.1985,0.063662,,,,7.85398e-5
Test1,2-Compress,60.983,3.93,0.075,-0.002,,0.0187266,-25.4648,,1.87266,-0.0254648,,,,7.85398e-5
Test1,2-Compress,61.317,3.903,0.102,-0.002,,0.0254682,-25.4648,,2.54682,-0.0254648,,,,7.85398e-5
Test1,2-Compress,61.650,3.877,0.128,0.005,,0.03196,63.662,,3.196,0.063662,,,,7.85398e-5
Test1,2-Compress,61.983,3.85,0.155,0.005,,0.0387016,63.662,,3.87016,0.063662,,,,7.85398e-5
Test1,2-Compress,62.317,3.823,0.182,-0.015,,0.0454432,-190.986,,4.54432,-0.190986,,,,7.85398e-5
Test1,2-Compress,62.650,3.796,0.209,-0.002,,0.0521848,-25.4648,,5.21848,-0.0254648,,,,7.85398e-5
Test1,2-Compress,62.983,3.77,0.235,-0.002,,0.0586767,-25.4648,,5.86767,-0.0254648,,,,7.85398e-5
Test1,2-Compress,63.317,3.743,0.262,0.019,,0.0654182,241.916,,6.54182,0.241916,,,,7.85398e-5
Test1,2-Compress,63.650,3.716,0.289,0.012,,0.0721598,152.789,,7.21598,0.152789,,,,7.85398e-5
Test1,2-Compress,63.983,3.69,0.315,0.005,,0.0786517,63.662,,7.86517,0.063662,,,,7.85398e-5
Test1,2-Compress,64.317,3.662,0.343,0.012,,0.0856429,152.789,,8.56429,0.152789,,,,7.85398e-5
Test1,2-Compress,64.650,3.636,0.369,0.005,,0.0921348,63.662,,9.21348,0.063662,,,,7.85398e-5
Test1,2-Compress,64.983,3.61,0.395,0.012,,0.0986267,152.789,,9.86267,0.152789,,,,7.85398e-5
Test1,2-Compress,65.317,3.582,0.423,0.019,,0.105618,241.916,,10.5618,0.241916,,,,7.85398e-5
Test1,2-Compress,65.650,3.556,0.449,0.019,,0.11211,241.916,,11.211,0.241916,,,,7.85398e-5
Test1,2-Compress,65.983,3.529,0.476,0.005,,0.118851,63.662,,11.8851,0.063662,,,,7.85398e-5
Test1,2-Compress,66.317,3.502,0.503,-0.002,,0.125593,-25.4648,,12.5593,-0.0254648,,,,7.85398e-5
Test1,2-Compress,66.650,3.476,0.529,0.012,,0.132085,152.789,,13.2085,0.152789,,,,7.85398e-5
Test1,2-Compress,66.983,3.449,0.556,0.012,,0.138826,152.789,,13.8826,0.152789,,,,7.85398e-5
Test1,2-Compress,67.317,3.422,0.583,-0.002,,0.145568,-25.4648,,14.5568,-0.0254648,,,,7.85398e-5
Test1,2-Compress,67.650,3.395,0.61,0.005,,0.15231,63.662,,15.231,0.063662,,,,7.85398e-5
Test1,2-Compress,67.983,3.369,0.636,-0.002,,0.158801,-25.4648,,15.8801,-0.0254648,,,,7.85398e-5
Test1,2-Compress,68.317,3.342,0.663,0.005,,0.165543,63.662,,16.5543,0.063662,,,,7.85398e-5
Test1,2-Compress,68.650,3.315,0.69,0.005,,0.172285,63.662,,17.2285,0.063662,,,,7.85398e-5
Test1,2-Compress,68.983,3.288,0.717,-0.002,,0.179026,-25.4648,,17.9026,-0.0254648,,,,7.85398e-5
Test1,2-Compress,69.317,3.261,0.744,-0.002,,0.185768,-25.4648,,18.5768,-0.0254648,,,,7.85398e-5
Test1,2-Compress,69.650,3.235,0.77,-0.002,,0.19226,-25.4648,,19.226,-0.0254648,,,,7.85398e-5
Test1,2-Compress,69.983,3.208,0.797,-0.009,,0.199001,-114.592,,19.9001,-0.114592,,,,7.85398e-5
Test1,2-Compress,70.317,3.181,0.824,-0.009,,0.205743,-114.592,,20.5743,-0.114592,,,,7.85398e-5
Test1,2-Compress,70.650,3.154,0.851,0.005,,0.212484,63.662,,21.2484,0.063662,,,,7.85398e-5
Test1,2-Compress,70.983,3.128,0.877,-0.009,,0.218976,-114.592,,21.8976,-0.114592,,,,7.85398e-5
Test1,2-Compress,71.317,3.101,0.904,-0.009,,0.225718,-114.592,,22.5718,-0.114592,,,,7.85398e-5
Test1,2-Compress,71.650,3.074,0.931,0.005,,0.232459,63.662,,23.2459,0.063662,,,,7.85398e-5
Test1,2-Compress,71.983,3.048,0.957,0.025,,0.238951,318.31,,23.8951,0.31831,,,,7.85398e-5
Test1,2-Compress,72.317,3.02,0.985,0.025,,0.245943,318.31,,24.5943,0.31831,,,,7.85398e-5
Test1,2-Compress,72.650,2.994,1.011,0.019,,0.252434,241.916,,25.2434,0.241916,,,,7.85398e-5
Test1,2-Compress,72.983,2.968,1.037,0.025,,0.258926,318.31,,25.8926,0.31831,,,,7.85398e-5
Test1,2-Compress,73.317,2.94,1.065,0.019,,0.265918,241.916,,26.5918,0.241916,,,,7.85398e-5
Test1,2-Compress,73.650,2.914,1.091,0.032,,0.272409,407.437,,27.2409,0.407437,,,,7.85398e-5
Test1,2-Compress,73.983,2.888,1.117,0.032,,0.278901,407.437,,27.8901,0.407437,,,,7.85398e-5
Test1,2-Compress,74.317,2.86,1.145,0.025,,0.285893,318.31,,28.5893,0.31831,,,,7.85398e-5
Test1,2-Compress,74.650,2.834,1.171,0.025,,0.292385,318.31,,29.2385,0.31831,,,,7.85398e-5
Test1,2-Compress,74.983,2.807,1.198,0.032,,0.299126,407.437,,29.9126,0.407437,,,,7.85398e-5
Test1,2-Compress,75.317,2.78,1.225,0.025,,0.305868,318.31,,30.5868,0.31831,,,,7.85398e-5
Test1,2-Compress,75.650,2.754,1.251,0.012,,0.31236,152.789,,31.236,0.152789,,,,7.85398e-5
Test1,2-Compress,75.983,2.727,1.278,0.025,,0.319101,318.31,,31.9101,0.31831,,,,7.85398e-5
Test1,2-Compress,76.317,2.7,1.305,0.025,,0.325843,318.31,,32.5843,0.31831,,,,7.85398e-5
Test1,2-Compress,76.650,2.673,1.332,0.032,,0.332584,407.437,,33.2584,0.407437,,,,7.85398e-5
Test1,2-Compress,76.983,2.647,1.358,0.039,,0.339076,496.564,,33.9076,0.496564,,,,7.85398e-5
Test1,2-Compress,77.317,2.62,1.385,0.039,,0.345818,496.564,,34.5818,0.496564,,,,7.85398e-5
Test1,2-Compress,77.650,2.593,1.412,0.019,,0.352559,241.916,,35.2559,0.241916,,,,7.85398e-5
Test1,2-Compress,77.983,2.567,1.438,0.032,,0.359051,407.437,,35.9051,0.407437,,,,7.85398e-5
Test1,2-Compress,78.317,2.539,1.466,0.039,,0.366042,496.564,,36.6042,0.496564,,,,7.85398e-5
Test1,2-Compress,78.650,2.513,1.492,0.039,,0.372534,496.564,,37.2534,0.496564,,,,7.85398e-5
Test1,2-Compress,78.983,2.486,1.519,0.039,,0.379276,496.564,,37.9276,0.496564,,,,7.85398e-5
Test1,2-Compress,79.317,2.459,1.546,0.039,,0.386017,496.564,,38.6017,0.496564,,,,7.85398e-5
Test1,2-Compress,79.650,2.433,1.572,0.046,,0.392509,585.69,,39.2509,0.58569,,,,7.85398e-5
Test1,2-Compress,79.983,2.406,1.599,0.046,,0.399251,585.69,,39.9251,0.58569,,,,7.85398e-5
Test1,2-Compress,80.317,2.379,1.626,0.046,,0.405993,585.69,,40.5993,0.58569,,,,7.85398e-5
Test1,2-Compress,80.650,2.352,1.653,0.046,,0.412734,585.69,,41.2734,0.58569,,,,7.85398e-5
Test1,2-Compress,80.983,2.326,1.679,0.046,,0.419226,585.69,,41.9226,0.58569,,,,7.85398e-5
Test1,2-Compress,81.317,2.299,1.706,0.039,,0.425968,496.564,,42.5968,0.496564,,,,7.85398e-5
Test1,2-Compress,81.650,2.272,1.733,0.039,,0.432709,496.564,,43.2709,0.496564,,,,7.85398e-5
Test1,2-Compress,81.983,2.246,1.759,0.053,,0.439201,674.817,,43.9201,0.674817,,,,7.85398e-5
Test1,2-Compress,82.317,2.219,1.786,0.039,,0.445943,496.564,,44.5943,0.496564,,,,7.85398e-5
Test1,2-Compress,82.650,2.192,1.813,0.039,,0.452684,496.564,,45.2684,0.496564,,,,7.85398e-5
Test1,2-Compress,82.983,2.165,1.84,0.039,,0.459426,496.564,,45.9426,0.496564,,,,7.85398e-5
Test1,2-Compress,83.317,2.138,1.867,0.039,,0.466167,496.564,,46.6167,0.496564,,,,7.85398e-5
Test1,2-Compress,83.650,2.112,1.893,0.039,,0.472659,496.564,,47.2659,0.496564,,,,7.85398e-5
Test1,2-Compress,83.983,2.085,1.92,0.039,,0.479401,496.564,,47.9401,0.496564,,,,7.85398e-5
Test1,2-Compress,84.317,2.058,1.947,0.039,,0.486142,496.564,,48.6142,0.496564,,,,7.85398e-5
Test1,2-Compress,84.650,2.031,1.974,0.039,,0.492884,496.564,,49.2884,0.496564,,,,7.85398e-5
Test1,2-Compress,84.983,2.005,2,0.039,,0.499376,496.564,,49.9376,0.496564,,,,7.85398e-5
Test1,2-Compress,85.317,1.978,2.027,0.039,,0.506117,496.564,,50.6117,0.496564,,,,7.85398e-5
Test1,2-Compress,85.650,1.951,2.054,0.039,,0.512859,496.564,,51.2859,0.496564,,,,7.85398e-5
Test1,2-Compress,85.983,1.925,2.08,0.039,,0.519351,496.564,,51.9351,0.496564,,,,7.85398e-5
Test1,2-Compress,86.317,1.898,2.107,0.039,,0.526092,496.564,,52.6092,0.496564,,,,7.85398e-5
Test1,2-Compress,86.650,1.871,2.134,0.046,,0.532834,585.69,,53.2834,0.58569,,,,7.85398e-5
Test1,2-Compress,86.983,1.845,2.16,0.046,,0.539326,585.69,,53.9326,0.58569,,,,7.85398e-5
Test1,2-Compress,87.317,1.817,2.188,0.046,,0.546317,585.69,,54.6317,0.58569,,,,7.85398e-5
Test1,2-Compress,87.650,1.791,2.214,0.046,,0.552809,585.69,,55.2809,0.58569,,,,7.85398e-5
Test1,2-Compress,87.983,1.765,2.24,0.046,,0.559301,585.69,,55.9301,0.58569,,,,7.85398e-5
Test1,2-Compress,88.317,1.737,2.268,0.046,,0.566292,585.69,,56.6292,0.58569,,,,7.85398e-5
Test1,2-Compress,88.650,1.711,2.294,0.053,,0.572784,674.817,,57.2784,0.674817,,,,7.85398e-5
Test1,2-Compress,88.983,1.684,2.321,0.053,,0.579526,674.817,,57.9526,0.674817,,,,7.85398e-5
Test1,2-Compress,89.317,1.657,2.348,0.053,,0.586267,674.817,,58.6267,0.674817,,,,7.85398e-5
Test1,2-Compress,89.650,1.631,2.374,0.053,,0.592759,674.817,,59.2759,0.674817,,,,7.85398e-5
Test1,2-Compress,89.983,1.604,2.401,0.046,,0.599501,585.69,,59.9501,0.58569,,,,7.85398e-5
Test1,2-Recover,90.303,1.621,2.384,0.046,,0.595256,585.69,,59.5256,0.58569,,,,7.85398e-5
Test1,2-Recover,90.637,1.648,2.357,0.046,,0.588514,585.69,,58.8514,0.58569,,,,7.85398e-5
Test1,2-Recover,90.970,1.675,2.33,0.039,,0.581773,496.564,,58.1773,0.496564,,,,7.85398e-5
Test1,2-Recover,91.303,1.701,2.304,0.039,,0.575281,496.564,,57.5281,0.496564,,,,7.85398e-5
Test1,2-Recover,91.637,1.729,2.276,0.039,,0.56829,496.564,,56.829,0.496564,,,,7.85398e-5
Test1,2-Recover,91.970,1.755,2.25,0.039,,0.561798,496.564,,56.1798,0.496564,,,,7.85398e-5
Test1,2-Recover,92.303,1.782,2.223,0.039,,0.555056,496.564,,55.5056,0.496564,,,,7.85398e-5
Test1,2-Recover,92.637,1.809,2.196,0.039,,0.548315,496.564,,54.8315,0.496564,,,,7.85398e-5
Test1,2-Recover,92.970,1.835,2.17,0.039,,0.541823,496.564,,54.1823,0.496564,,,,7.85398e-5
Test1,2-Recover,93.303,1.862,2.143,0.039,,0.535081,496.564,,53.5081,0.496564,,,,7.85398e-5
Test1,2-Recover,93.637,1.889,2.116,0.039,,0.52834,496.564,,52.834,0.496564,,,,7.85398e-5
Test1,2-Recover,93.970,1.916,2.089,0.039,,0.521598,496.564,,52.1598,0.496564,,,,7.85398e-5
Test1,2-Recover,94.303,1.942,2.063,0.039,,0.515106,496.564,,51.5106,0.496564,,,,7.85398e-5
Test1,2-Recover,94.637,1.969,2.036,0.039,,0.508365,496.564,,50.8365,0.496564,,,,7.85398e-5
Test1,2-Recover,94.970,1.996,2.009,0.039,,0.501623,496.564,,50.1623,0.496564,,,,7.85398e-5
Test1,2-Recover,95.303,2.022,1.983,0.039,,0.495131,496.564,,49.5131,0.496564,,,,7.85398e-5
Test1,2-Recover,95.637,2.049,1.956,0.046,,0.48839,585.69,,48.839,0.58569,,,,7.85398e-5
Test1,2-Recover,95.970,2.076,1.929,0.046,,0.481648,585.69,,48.1648,0.58569,,,,7.85398e-5
Test1,2-Recover,96.303,2.102,1.903,0.039,,0.475156,496.564,,47.5156,0.496564,,,,7.85398e-5
Test1,2-Recover,96.637,2.13,1.875,0.039,,0.468165,496.564,,46.8165,0.496564,,,,7.85398e-5
Test1,2-Recover,96.970,2.156,1.849,0.032,,0.461673,407.437,,46.1673,0.407437,,,,7.85398e-5
Test1,2-Recover,97.303,2.183,1.822,0.032,,0.454931,407.437,,45.4931,0.407437,,,,7.85398e-5
Test1,2-Recover,97.637,2.21,1.795,0.039,,0.44819,496.564,,44.819,0.496564,,,,7.85398e-5
Test1,2-Recover,97.970,2.236,1.769,0.032,,0.441698,407.437,,44.1698,0.407437,,,,7.85398e-5
Test1,2-Recover,98.303,2.263,1.742,0.025,,0.434956,318.31,,43.4956,0.31831,,,,7.85398e-5
Test1,2-Recover,98.637,2.29,1.715,0.032,,0.428215,407.437,,42.8215,0.407437,,,,7.85398e-5
Test1,2-Recover,98.970,2.317,1.688,0.032,,0.421473,407.437,,42.1473,0.407437,,,,7.85398e-5
Test1,2-Recover,99.303,2.343,1.662,0.025,,0.414981,318.31,,41.4981,0.31831,,,,7.85398e-5
Test1,2-Recover,99.637,2.37,1.635,0.039,,0.40824,496.564,,40.824,0.496564,,,,7.85398e-5
Test1,2-Recover,99.970,2.397,1.608,0.032,,0.401498,407.437,,40.1498,0.407437,,,,7.85398e-5
Test1,2-Recover,100.303,2.423,1.582,0.019,,0.395006,241.916,,39.5006,0.241916,,,,7.85398e-5
Test1,2-Recover,100.637,2.451,1.554,0.025,,0.388015,318.31,,38.8015,0.31831,,,,7.85398e-5
Test1,2-Recover,100.970,2.477,1.528,0.019,,0.381523,241.916,,38.1523,0.241916,,,,7.85398e-5
Test1,2-Recover,101.303,2.503,1.502,-0.002,,0.375031,-25.4648,,37.5031,-0.0254648,,,,7.85398e-5
Test1,2-Recover,101.637,2.531,1.474,0.005,,0.36804,63.662,,36.804,0.063662,,,,7.85398e-5
Test1,2-Recover,101.970,2.557,1.448,0.012,,0.361548,152.789,,36.1548,0.152789,,,,7.85398e-5
Test1,2-Recover,102.303,2.584,1.421,-0.002,,0.354806,-25.4648,,35.4806,-0.0254648,,,,7.85398e-5
Test1,2-Recover,102.637,2.611,1.394,-0.009,,0.348065,-114.592,,34.8065,-0.114592,,,,7.85398e-5
Test1,2-Recover,102.970,2.637,1.368,0.012,,0.341573,152.789,,34.1573,0.152789,,,,7.85398e-5
Test1,2-Recover,103.303,2.664,1.341,-0.002,,0.334831,-25.4648,,33.4831,-0.0254648,,,,7.85398e-5
Test1,2-Recover,103.637,2.691,1.314,-0.009,,0.32809,-114.592,,32.809,-0.114592,,,,7.85398e-5
Test1,2-Recover,103.970,2.718,1.287,-0.002,,0.321348,-25.4648,,32.1348,-0.0254648,,,,7.85398e-5
Test1,2-Recover,104.303,2.744,1.261,-0.002,,0.314856,-25.4648,,31.4856,-0.0254648,,,,7.85398e-5
Test1,2-Recover,104.637,2.771,1.234,0.005,,0.308115,63.662,,30.8115,0.063662,,,,7.85398e-5
Test1,2-Recover,104.970,2.798,1.207,-0.002,,0.301373,-25.4648,,30.1373,-0.0254648,,,,7.85398e-5
Test1,2-Recover,105.303,2.824,1.181,0.012,,0.294881,152.789,,29.4881,0.152789,,,,7.85398e-5
Test1,2-Recover,105.637,2.852,1.153,0.012,,0.28789,152.789,,28.789,0.152789,,,,7.85398e-5
Test1,2-Recover,105.970,2.878,1.127,0.012,,0.281398,152.789,,28.1398,0.152789,,,,7.85398e-5
Test1,2-Recover,106.303,2.905,1.1,0.005,,0.274657,63.662,,27.4657,0.063662,,,,7.85398e-5
Test1,2-Recover,106.637,2.932,1.073,0.012,,0.267915,152.789,,26.7915,0.152789,,,,7.85398e-5
Test1,2-Recover,106.970,2.958,1.047,0.012,,0.261423,152.789,,26.1423,0.152789,,,,7.85398e-5
Test1,2-Recover,107.303,2.985,1.02,0.005,,0.254682,63.662,,25.4682,0.063662,,,,7.85398e-5
Test1,2-Recover,107.637,3.012,0.993,-0.002,,0.24794,-25.4648,,24.794,-0.0254648,,,,7.85398e-5
Test1,2-Recover,107.970,3.039,0.966,-0.009,,0.241199,-114.592,,24.1199,-0.114592,,,,7.85398e-5
Test1,2-Recover,108.303,3.065,0.94,0.005,,0.234707,63.662,,23.4707,0.063662,,,,7.85398e-5
Test1,2-Recover,108.637,3.092,0.913,0.005,,0.227965,63.662,,22.7965,0.063662,,,,7.85398e-5
Test1,2-Recover,108.970,3.119,0.886,-0.009,,0.221223,-114.592,,22.1223,-0.114592,,,,7.85398e-5
Test1,2-Recover,109.303,3.145,0.86,-0.002,,0.214732,-25.4648,,21.4732,-0.0254648,,,,7.85398e-5
Test1,2-Recover,109.637,3.173,0.832,-0.009,,0.20774,-114.592,,20.774,-0.114592,,,,7.85398e-5
Test1,2-Recover,109.970,3.199,0.806,-0.002,,0.201248,-25.4648,,20.1248,-0.0254648,,,,7.85398e-5
Test1,2-Recover,110.303,3.225,0.78,-0.009,,0.194757,-114.592,,19.4757,-0.114592,,,,7.85398e-5
Test1,2-Recover,110.637,3.253,0.752,-0.009,,0.187765,-114.592,,18.7765,-0.114592,,,,7.85398e-5
Test1,2-Recover,110.970,3.279,0.726,-0.002,,0.181273,-25.4648,,18.1273,-0.0254648,,,,7.85398e-5
Test1,2-Recover,111.303,3.306,0.699,-0.009,,0.174532,-114.592,,17.4532,-0.114592,,,,7.85398e-5
Test1,2-Recover,111.637,3.333,0.672,-0.002,,0.16779,-25.4648,,16.779,-0.0254648,,,,7.85398e-5
Test1,2-Recover,111.970,3.359,0.646,-0.002,,0.161298,-25.4648,,16.1298,-0.0254648,,,,7.85398e-5
Test1,2-Recover,112.303,3.386,0.619,0.005,,0.154557,63.662,,15.4557,0.063662,,,,7.85398e-5
Test1,2-Recover,112.637,3.413,0.592,0.005,,0.147815,63.662,,14.7815,0.063662,,,,7.85398e-5
Test1,2-Recover,112.970,3.44,0.565,0.005,,0.141074,63.662,,14.1074,0.063662,,,,7.85398e-5
Test1,2-Recover,113.303,3.466,0.539,0.019,,0.134582,241.916,,13.4582,0.241916,,,,7.85398e-5
Test1,2-Recover,113.637,3.493,0.512,0.012,,0.12784,152.789,,12.784,0.152789,,,,7.85398e-5
Test1,2-Recover,113.970,3.52,0.485,0.012,,0.121099,152.789,,12.1099,0.152789,,,,7.85398e-5
Test1,2-Recover,114.303,3.546,0.459,0.012,,0.114607,152.789,,11.4607,0.152789,,,,7.85398e-5
Test1,2-Recover,114.637,3.574,0.431,0.012,,0.107615,152.789,,10.7615,0.152789,,,,7.85398e-5
Test1,2-Recover,114.970,3.6,0.405,-0.002,,0.101124,-25.4648,,10.1124,-0.0254648,,,,7.85398e-5
Test1,2-Recover,115.303,3.626,0.379,-0.015,,0.0946317,-190.986,,9.46317,-0.190986,,,,7.85398e-5
Test1,2-Recover,115.637,3.654,0.351,-0.009,,0.0876404,-114.592,,8.76404,-0.114592,,,,7.85398e-5
Test1,2-Recover,115.970,3.68,0.325,-0.009,,0.0811486,-114.592,,8.11486,-0.114592,,,,7.85398e-5
Test1,2-Recover,116.303,3.707,0.298,-0.002,,0.074407,-25.4648,,7.4407,-0.0254648,,,,7.85398e-5
Test1,2-Recover,116.637,3.734,0.271,0.019,,0.0676654,241.916,,6.76654,0.241916,,,,7.85398e-5
Test1,2-Recover,116.970,3.76,0.245,-0.002,,0.0611735,-25.4648,,6.11735,-0.0254648,,,,7.85398e-5
Test1,2-Recover,117.303,3.787,0.218,0.005,,0.054432,63.662,,5.4432,0.063662,,,,7.85398e-5
Test1,2-Recover,117.637,3.814,0.191,-0.002,,0.0476904,-25.4648,,4.76904,-0.0254648,,,,7.85398e-5
Test1,2-Recover,117.970,3.841,0.164,0.005,,0.0409488,63.662,,4.09488,0.063662,,,,7.85398e-5
Test1,2-Recover,118.303,3.867,0.138,-0.002,,0.0344569,-25.4648,,3.44569,-0.0254648,,,,7.85398e-5
Test1,2-Recover,118.637,3.894,0.111,0.005,,0.0277154,63.662,,2.77154,0.063662,,,,7.85398e-5
Test1,2-Recover,118.970,3.921,0.084,0.025,,0.0209738,318.31,,2.09738,0.31831,,,,7.85398e-5
Test1,2-Recover,119.303,3.947,0.058,0.012,,0.0144819,152.789,,1.44819,0.152789,,,,7.85398e-5
Test1,2-Recover,119.637,3.975,0.03,0.005,,0.00749064,63.662,,0.749064,0.063662,,,,7.85398e-5
Test1,2-Recover,119.970,4.001,0.004,0.025,,0.000998752,318.31,,0.0998752,0.31831,,,,7.85398e-5
Test1,3-Compress,120.280,3.989,0.016,0.012,,0.00399501,152.789,,0.399501,0.152789,,,,7.85398e-5
Test1,3-Compress,120.613,3.963,0.042,0.012,,0.0104869,152.789,,1.04869,0.152789,,,,7.85398e-5
Test1,3-Compress,120.947,3.936,0.069,0.005,,0.0172285,63.662,,1.72285,0.063662,,,,7.85398e-5
Test1,3-Compress,121.280,3.909,0.096,-0.002,,0.02397,-25.4648,,2.397,-0.0254648,,,,7.85398e-5
Test1,3-Compress,121.613,3.883,0.122,0.005,,0.0304619,63.662,,3.04619,0.063662,,,,7.85398e-5
Test1,3-Compress,121.947,3.855,0.15,0.012,,0.0374532,152.789,,3.74532,0.152789,,,,7.85398e-5
Test1,3-Compress,122.280,3.829,0.176,0.005,,0.0439451,63.662,,4.39451,0.063662,,,,7.85398e-5
Test1,3-Compress,122.613,3.803,0.202,-0.009,,0.050437,-114.592,,5.0437,-0.114592,,,,7.85398e-5
Test1,3-Compress,122.947,3.775,0.23,-0.002,,0.0574282,-25.4648,,5.74282,-0.0254648,,,,7.85398e-5
Test1,3-Compress,123.280,3.749,0.256,-0.009,,0.0639201,-114.592,,6.39201,-0.114592,,,,7.85398e-5
Test1,3-Compress,123.613,3.722,0.283,0.019,,0.0706617,241.916,,7.06617,0.241916,,,,7.85398e-5
Test1,3-Compress,123.947,3.695,0.31,-0.002,,0.0774032,-25.4648,,7.74032,-0.0254648,,,,7.85398e-5
Test1,3-Compress,124.280,3.669,0.336,-0.002,,0.0838951,-25.4648,,8.38951,-0.0254648,,,,7.85398e-5
Test1,3-Compress,124.613,3.642,0.363,0.012,,0.0906367,152.789,,9.06367,0.152789,,,,7.85398e-5
Test1,3-Compress,124.947,3.615,0.39,-0.002,,0.0973783,-25.4648,,9.73783,-0.0254648,,,,7.85398e-5
Test1,3-Compress,125.280,3.588,0.417,-0.002,,0.10412,-25.4648,,10.412,-0.0254648,,,,7.85398e-5
Test1,3-Compress,125.613,3.562,0.443,-0.002,,0.110612,-25.4648,,11.0612,-0.0254648,,,,7.85398e-5
Test1,3-Compress,125.947,3.535,0.47,0.005,,0.117353,63.662,,11.7353,0.063662,,,,7.85398e-5
Test1,3-Compress,126.280,3.508,0.497,-0.009,,0.124095,-114.592,,12.4095,-0.114592,,,,7.85398e-5
Test1,3-Compress,126.613,3.482,0.523,-0.002,,0.130587,-25.4648,,13.0587,-0.0254648,,,,7.85398e-5
Test1,3-Compress,126.947,3.454,0.551,-0.009,,0.137578,-114.592,,13.7578,-0.114592,,,,7.85398e-5
Test1,3-Compress,127.280,3.428,0.577,0.012,,0.14407,152.789,,14.407,0.152789,,,,7.85398e-5
Test1,3-Compress,127.613,3.402,0.603,-0.002,,0.150562,-25.4648,,15.0562,-0.0254648,,,,7.85398e-5
Test1,3-Compress,127.947,3.374,0.631,-0.009,,0.157553,-114.592,,15.7553,-0.114592,,,,7.85398e-5
Test1,3-Compress,128.280,3.348,0.657,-0.009,,0.164045,-114.592,,16.4045,-0.114592,,,,7.85398e-5
Test1,3-Compress,128.613,3.321,0.684,-0.009,,0.170787,-114.592,,17.0787,-0.114592,,,,7.85398e-5
Test1,3-Compress,128.947,3.294,0.711,-0.002,,0.177528,-25.4648,,17.7528,-0.0254648,,,,7.85398e-5
Test1,3-Compress,129.280,3.268,0.737,-0.002,,0.18402,-25.4648,,18.402,-0.0254648,,,,7.85398e-5
Test1,3-Compress,129.613,3.241,0.764,0.005,,0.190762,63.662,,19.0762,0.063662,,,,7.85398e-5
Test1,3-Compress,129.947,3.214,0.791,0.019,,0.197503,241.916,,19.7503,0.241916,,,,7.85398e-5
Test1,3-Compress,130.280,3.187,0.818,0.019,,0.204245,241.916,,20.4245,0.241916,,,,7.85398e-5
Test1,3-Compress,130.613,3.161,0.844,0.005,,0.210737,63.662,,21.0737,0.063662,,,,7.85398e-5
Test1,3-Compress,130.947,3.134,0.871,0.032,,0.217478,407.437,,21.7478,0.407437,,,,7.85398e-5
Test1,3-Compress,131.280,3.107,0.898,0.019,,0.22422,241.916,,22.422,0.241916,,,,7.85398e-5
Test1,3-Compress,131.613,3.081,0.924,0.025,,0.230712,318.31,,23.0712,0.31831,,,,7.85398e-5
Test1,3-Compress,131.947,3.053,0.952,0.032,,0.237703,407.437,,23.7703,0.407437,,,,7.85398e-5
Test1,3-Compress,132.280,3.027,0.978,0.032,,0.244195,407.437,,24.4195,0.407437,,,,7.85398e-5
Test1,3-Compress,132.613,3,1.005,0.025,,0.250936,318.31,,25.0936,0.31831,,,,7.85398e-5
Test1,3-Compress,132.947,2.973,1.032,0.012,,0.257678,152.789,,25.7678,0.152789,,,,7.85398e-5
Test1,3-Compress,133.280,2.947,1.058,0.032,,0.26417,407.437,,26.417,0.407437,,,,7.85398e-5
Test1,3-Compress,133.613,2.92,1.085,0.025,,0.270911,318.31,,27.0911,0.31831,,,,7.85398e-5
Test1,3-Compress,133.947,2.893,1.112,0.012,,0.277653,152.789,,27.7653,0.152789,,,,7.85398e-5
Test1,3-Compress,134.280,2.866,1.139,0.005,,0.284395,63.662,,28.4395,0.063662,,,,7.85398e-5
Test1,3-Compress,134.613,2.84,1.165,0.012,,0.290886,152.789,,29.0886,0.152789,,,,7.85398e-5
Test1,3-Compress,134.947,2.813,1.192,0.032,,0.297628,407.437,,29.7628,0.407437,,,,7.85398e-5
Test1,3-Compress,135.280,2.786,1.219,0.019,,0.30437,241.916,,30.437,0.241916,,,,7.85398e-5
Test1,3-Compress,135.613,2.76,1.245,-0.009,,0.310861,-114.592,,31.0861,-0.114592,,,,7.85398e-5
Test1,3-Compress,135.947,2.732,1.273,0.032,,0.317853,407.437,,31.7853,0.407437,,,,7.85398e-5
Test1,3-Compress,136.280,2.706,1.299,0.032,,0.324345,407.437,,32.4345,0.407437,,,,7.85398e-5
Test1,3-Compress,136.613,2.68,1.325,0.032,,0.330836,407.437,,33.0836,0.407437,,,,7.85398e-5
Test1,3-Compress,136.947,2.652,1.353,0.032,,0.337828,407.437,,33.7828,0.407437,,,,7.85398e-5
Test1,3-Compress,137.280,2.626,1.379,0.032,,0.34432,407.437,,34.432,0.407437,,,,7.85398e-5
Test1,3-Compress,137.613,2.599,1.406,0.032,,0.351061,407.437,,35.1061,0.407437,,,,7.85398e-5
Test1,3-Compress,137.947,2.572,1.433,0.039,,0.357803,496.564,,35.7803,0.496564,,,,7.85398e-5
Test1,3-Compress,138.280,2.546,1.459,0.032,,0.364295,407.437,,36.4295,0.407437,,,,7.85398e-5
Test1,3-Compress,138.613,2.519,1.486,0.039,,0.371036,496.564,,37.1036,0.496564,,,,7.85398e-5
Test1,3-Compress,138.947,2.492,1.513,0.039,,0.377778,496.564,,37.7778,0.496564,,,,7.85398e-5
Test1,3-Compress,139.280,2.465,1.54,0.039,,0.384519,496.564,,38.4519,0.496564,,,,7.85398e-5
Test1,3-Compress,139.613,2.439,1.566,0.039,,0.391011,496.564,,39.1011,0.496564,,,,7.85398e-5
Test1,3-Compress,139.947,2.412,1.593,0.039,,0.397753,496.564,,39.7753,0.496564,,,,7.85398e-5
Test1,3-Compress,140.280,2.385,1.62,0.039,,0.404494,496.564,,40.4494,0.496564,,,,7.85398e-5
Test1,3-Compress,140.613,2.359,1.646,0.039,,0.410986,496.564,,41.0986,0.496564,,,,7.85398e-5
Test1,3-Compress,140.947,2.331,1.674,0.039,,0.417978,496.564,,41.7978,0.496564,,,,7.85398e-5
Test1,3-Compress,141.280,2.305,1.7,0.039,,0.424469,496.564,,42.4469,0.496564,,,,7.85398e-5
Test1,3-Compress,141.613,2.278,1.727,0.039,,0.431211,496.564,,43.1211,0.496564,,,,7.85398e-5
Test1,3-Compress,141.947,2.251,1.754,0.039,,0.437953,496.564,,43.7953,0.496564,,,,7.85398e-5
Test1,3-Compress,142.280,2.225,1.78,0.039,,0.444444,496.564,,44.4444,0.496564,,,,7.85398e-5
Test1,3-Compress,142.613,2.198,1.807,0.039,,0.451186,496.564,,45.1186,0.496564,,,,7.85398e-5
Test1,3-Compress,142.947,2.171,1.834,0.039,,0.457928,496.564,,45.7928,0.496564,,,,7.85398e-5
Test1,3-Compress,143.280,2.144,1.861,0.039,,0.464669,496.564,,46.4669,0.496564,,,,7.85398e-5
Test1,3-Compress,143.613,2.118,1.887,0.039,,0.471161,496.564,,47.1161,0.496564,,,,7.85398e-5
Test1,3-Compress,143.947,2.091,1.914,0.039,,0.477903,496.564,,47.7903,0.496564,,,,7.85398e-5
Test1,3-Compress,144.280,2.064,1.941,0.046,,0.484644,585.69,,48.4644,0.58569,,,,7.85398e-5
Test1,3-Compress,144.613,2.038,1.967,0.046,,0.491136,585.69,,49.1136,0.58569,,,,7.85398e-5
Test1,3-Compress,144.947,2.01,1.995,0.046,,0.498127,585.69,,49.8127,0.58569,,,,7.85398e-5
Test1,3-Compress,145.280,1.984,2.021,0.053,,0.504619,674.817,,50.4619,0.674817,,,,7.85398e-5
Test1,3-Compress,145.613,1.958,2.047,0.053,,0.511111,674.817,,51.1111,0.674817,,,,7.85398e-5
Test1,3-Compress,145.947,1.93,2.075,0.053,,0.518102,674.817,,51.8102,0.674817,,,,7.85398e-5
Test1,3-Compress,146.280,1.904,2.101,0.046,,0.524594,585.69,,52.4594,0.58569,,,,7.85398e-5
Test1,3-Compress,146.613,1.877,2.128,0.046,,0.531336,585.69,,53.1336,0.58569,,,,7.85398e-5
Test1,3-Compress,146.947,1.85,2.155,0.046,,0.538077,585.69,,53.8077,0.58569,,,,7.85398e-5
Test1,3-Compress,147.280,1.824,2.181,0.046,,0.544569,585.69,,54.4569,0.58569,,,,7.85398e-5
Test1,3-Compress,147.613,1.797,2.208,0.039,,0.551311,496.564,,55.1311,0.496564,,,,7.85398e-5
Test1,3-Compress,147.947,1.77,2.235,0.039,,0.558052,496.564,,55.8052,0.496564,,,,7.85398e-5
Test1,3-Compress,148.280,1.743,2.262,0.039,,0.564794,496.564,,56.4794,0.496564,,,,7.85398e-5
Test1,3-Compress,148.613,1.717,2.288,0.039,,0.571286,496.564,,57.1286,0.496564,,,,7.85398e-5
Test1,3-Compress,148.947,1.69,2.315,0.039,,0.578027,496.564,,57.8027,0.496564,,,,7.85398e-5
Test1,3-Compress,149.280,1.663,2.342,0.039,,0.584769,496.564,,58.4769,0.496564,,,,7.85398e-5
Test1,3-Compress,149.613,1.637,2.368,0.039,,0.591261,496.564,,59.1261,0.496564,,,,7.85398e-5
Test1,3-Compress,149.947,1.609,2.396,0.039,,0.598252,496.564,,59.8252,0.496564,,,,7.85398e-5
Test1,3-Recover,150.267,1.616,2.389,0.039,,0.596504,496.564,,59.6504,0.496564,,,,7.85398e-5
Test1,3-Recover,150.600,1.642,2.363,0.039,,0.590012,496.564,,59.0012,0.496564,,,,7.85398e-5
Test1,3-Recover,150.933,1.668,2.337,0.039,,0.583521,496.564,,58.3521,0.496564,,,,7.85398e-5
Test1,3-Recover,151.267,1.696,2.309,0.039,,0.576529,496.564,,57.6529,0.496564,,,,7.85398e-5
Test1,3-Recover,151.600,1.722,2.283,0.039,,0.570037,496.564,,57.0037,0.496564,,,,7.85398e-5
Test1,3-Recover,151.933,1.749,2.256,0.046,,0.563296,585.69,,56.3296,0.58569,,,,7.85398e-5
Test1,3-Recover,152.267,1.776,2.229,0.046,,0.556554,585.69,,55.6554,0.58569,,,,7.85398e-5
Test1,3-Recover,152.600,1.802,2.203,0.046,,0.550062,585.69,,55.0062,0.58569,,,,7.85398e-5
Test1,3-Recover,152.933,1.829,2.176,0.046,,0.543321,585.69,,54.3321,0.58569,,,,7.85398e-5
Test1,3-Recover,153.267,1.856,2.149,0.046,,0.536579,585.69,,53.6579,0.58569,,,,7.85398e-5
Test1,3-Recover,153.600,1.883,2.122,0.046,,0.529838,585.69,,52.9838,0.58569,,,,7.85398e-5
Test1,3-Recover,153.933,1.909,2.096,0.046,,0.523346,585.69,,52.3346,0.58569,,,,7.85398e-5
Test1,3-Recover,154.267,1.936,2.069,0.046,,0.516604,585.69,,51.6604,0.58569,,,,7.85398e-5
Test1,3-Recover,154.600,1.963,2.042,0.046,,0.509863,585.69,,50.9863,0.58569,,,,7.85398e-5
Test1,3-Recover,154.933,1.989,2.016,0.039,,0.503371,496.564,,50.3371,0.496564,,,,7.85398e-5
Test1,3-Recover,155.267,2.017,1.988,0.039,,0.49638,496.564,,49.638,0.496564,,,,7.85398e-5
Test1,3-Recover,155.600,2.043,1.962,0.039,,0.489888,496.564,,48.9888,0.496564,,,,7.85398e-5
Test1,3-Recover,155.933,2.069,1.936,0.046,,0.483396,585.69,,48.3396,0.58569,,,,7.85398e-5
Test1,3-Recover,156.267,2.097,1.908,0.039,,0.476404,496.564,,47.6404,0.496564,,,,7.85398e-5
Test1,3-Recover,156.600,2.123,1.882,0.039,,0.469913,496.564,,46.9913,0.496564,,,,7.85398e-5
Test1,3-Recover,156.933,2.15,1.855,0.032,,0.463171,407.437,,46.3171,0.407437,,,,7.85398e-5
Test1,3-Recover,157.267,2.177,1.828,0.025,,0.456429,318.31,,45.6429,0.31831,,,,7.85398e-5
Test1,3-Recover,157.600,2.203,1.802,0.025,,0.449938,318.31,,44.9938,0.31831,,,,7.85398e-5
Test1,3-Recover,157.933,2.23,1.775,0.019,,0.443196,241.916,,44.3196,0.241916,,,,7.85398e-5
Test1,3-Recover,158.267,2.257,1.748,0.032,,0.436454,407.437,,43.6454,0.407437,,,,7.85398e-5
Test1,3-Recover,158.600,2.284,1.721,0.039,,0.429713,496.564,,42.9713,0.496564,,,,7.85398e-5
Test1,3-Recover,158.933,2.31,1.695,0.019,,0.423221,241.916,,42.3221,0.241916,,,,7.85398e-5
Test1,3-Recover,159.267,2.337,1.668,0.025,,0.416479,318.31,,41.6479,0.31831,,,,7.85398e-5
Test1,3-Recover,159.600,2.364,1.641,0.019,,0.409738,241.916,,40.9738,0.241916,,,,7.85398e-5
Test1,3-Recover,159.933,2.391,1.614,-0.002,,0.402996,-25.4648,,40.2996,-0.0254648,,,,7.85398e-5
Test1,3-Recover,160.267,2.418,1.587,0.005,,0.396255,63.662,,39.6255,0.063662,,,,7.85398e-5
Test1,3-Recover,160.600,2.444,1.561,0.005,,0.389763,63.662,,38.9763,0.063662,,,,7.85398e-5
Test1,3-Recover,160.933,2.471,1.534,0.012,,0.383021,152.789,,38.3021,0.152789,,,,7.85398e-5
Test1,3-Recover,161.267,2.498,1.507,0.012,,0.37628,152.789,,37.628,0.152789,,,,7.85398e-5
Test1,3-Recover,161.600,2.525,1.48,-0.002,,0.369538,-25.4648,,36.9538,-0.0254648,,,,7.85398e-5
Test1,3-Recover,161.933,2.551,1.454,0.012,,0.363046,152.789,,36.3046,0.152789,,,,7.85398e-5
Test1,3-Recover,162.267,2.578,1.427,0.019,,0.356305,241.916,,35.6305,0.241916,,,,7.85398e-5
Test1,3-Recover,162.600,2.605,1.4,0.019,,0.349563,241.916,,34.9563,0.241916,,,,7.85398e-5
Test1,3-Recover,162.933,2.631,1.374,0.012,,0.343071,152.789,,34.3071,0.152789,,,,7.85398e-5
Test1,3-Recover,163.267,2.658,1.347,0.019,,0.33633,241.916,,33.633,0.241916,,,,7.85398e-5
Test1,3-Recover,163.600,2.685,1.32,0.025,,0.329588,318.31,,32.9588,0.31831,,,,7.85398e-5
Test1,3-Recover,163.933,2.711,1.294,0.012,,0.323096,152.789,,32.3096,0.152789,,,,7.85398e-5
Test1,3-Recover,164.267,2.739,1.266,0.012,,0.316105,152.789,,31.6105,0.152789,,,,7.85398e-5
Test1,3-Recover,164.600,2.765,1.24,0.012,,0.309613,152.789,,30.9613,0.152789,,,,7.85398e-5
Test1,3-Recover,164.933,2.791,1.214,-0.002,,0.303121,-25.4648,,30.3121,-0.0254648,,,,7.85398e-5
Test1,3-Recover,165.267,2.819,1.186,0.005,,0.29613,63.662,,29.613,0.063662,,,,7.85398e-5
Test1,3-Recover,165.600,2.845,1.16,0.005,,0.289638,63.662,,28.9638,0.063662,,,,7.85398e-5
Test1,3-Recover,165.933,2.872,1.133,-0.002,,0.282896,-25.4648,,28.2896,-0.0254648,,,,7.85398e-5
Test1,3-Recover,166.267,2.899,1.106,-0.002,,0.276155,-25.4648,,27.6155,-0.0254648,,,,7.85398e-5
Test1,3-Recover,166.600,2.925,1.08,-0.009,,0.269663,-114.592,,26.9663,-0.114592,,,,7.85398e-5
Test1,3-Recover,166.933,2.952,1.053,-0.002,,0.262921,-25.4648,,26.2921,-0.0254648,,,,7.85398e-5
Test1,3-Recover,167.267,2.979,1.026,-0.002,,0.25618,-25.4648,,25.618,-0.0254648,,,,7.85398e-5
Test1,3-Recover,167.600,3.006,0.999,0.005,,0.249438,63.662,,24.9438,0.063662,,,,7.85398e-5
Test1,3-Recover,167.933,3.032,0.973,-0.009,,0.242946,-114.592,,24.2946,-0.114592,,,,7.85398e-5
Test1,3-Recover,168.267,3.059,0.946,-0.009,,0.236205,-114.592,,23.6205,-0.114592,,,,7.85398e-5
Test1,3-Recover,168.600,3.086,0.919,-0.009,,0.229463,-114.592,,22.9463,-0.114592,,,,7.85398e-5
Test1,3-Recover,168.933,3.113,0.892,0.012,,0.222722,152.789,,22.2722,0.152789,,,,7.85398e-5
Test1,3-Recover,169.267,3.14,0.865,-0.002,,0.21598,-25.4648,,21.598,-0.0254648,,,,7.85398e-5
Test1,3-Recover,169.600,3.166,0.839,-0.002,,0.209488,-25.4648,,20.9488,-0.0254648,,,,7.85398e-5
Test1,3-Recover,169.933,3.192,0.813,0.005,,0.202996,63.662,,20.2996,0.063662,,,,7.85398e-5
Test1,3-Recover,170.267,3.22,0.785,0.012,,0.196005,152.789,,19.6005,0.152789,,,,7.85398e-5
Test1,3-Recover,170.600,3.246,0.759,0.005,,0.189513,63.662,,18.9513,0.063662,,,,7.85398e-5
Test1,3-Recover,170.933,3.273,0.732,0.012,,0.182772,152.789,,18.2772,0.152789,,,,7.85398e-5
Test1,3-Recover,171.267,3.3,0.705,0.012,,0.17603,152.789,,17.603,0.152789,,,,7.85398e-5
Test1,3-Recover,171.600,3.326,0.679,0.012,,0.169538,152.789,,16.9538,0.152789,,,,7.85398e-5
Test1,3-Recover,171.933,3.353,0.652,0.012,,0.162797,152.789,,16.2797,0.152789,,,,7.85398e-5
Test1,3-Recover,172.267,3.38,0.625,0.005,,0.156055,63.662,,15.6055,0.063662,,,,7.85398e-5
Test1,3-Recover,172.600,3.407,0.598,-0.002,,0.149313,-25.4648,,14.9313,-0.0254648,,,,7.85398e-5
Test1,3-Recover,172.933,3.433,0.572,-0.002,,0.142821,-25.4648,,14.2821,-0.0254648,,,,7.85398e-5
Test1,3-Recover,173.267,3.46,0.545,-0.002,,0.13608,-25.4648,,13.608,-0.0254648,,,,7.85398e-5
Test1,3-Recover,173.600,3.487,0.518,-0.009,,0.129338,-114.592,,12.9338,-0.114592,,,,7.85398e-5
Test1,3-Recover,173.933,3.514,0.491,-0.009,,0.122597,-114.592,,12.2597,-0.114592,,,,7.85398e-5
Test1,3-Recover,174.267,3.541,0.464,0.005,,0.115855,63.662,,11.5855,0.063662,,,,7.85398e-5
Test1,3-Recover,174.600,3.567,0.438,0.005,,0.109363,63.662,,10.9363,0.063662,,,,7.85398e-5
Test1,3-Recover,174.933,3.594,0.411,-0.002,,0.102622,-25.4648,,10.2622,-0.0254648,,,,7.85398e-5
Test1,3-Recover,175.267,3.621,0.384,-0.009,,0.0958801,-114.592,,9.58801,-0.114592,,,,7.85398e-5
Test1,3-Recover,175.600,3.647,0.358,0.005,,0.0893883,63.662,,8.93883,0.063662,,,,7.85398e-5
Test1,3-Recover,175.933,3.674,0.331,0.012,,0.0826467,152.789,,8.26467,0.152789,,,,7.85398e-5
Test1,3-Recover,176.267,3.701,0.304,0.005,,0.0759051,63.662,,7.59051,0.063662,,,,7.85398e-5
Test1,3-Recover,176.600,3.728,0.277,0.019,,0.0691635,241.916,,6.91635,0.241916,,,,7.85398e-5
Test1,3-Recover,176.933,3.754,0.251,-0.009,,0.0626717,-114.592,,6.26717,-0.114592,,,,7.85398e-5
Test1,3-Recover,177.267,3.781,0.224,0.012,,0.0559301,152.789,,5.59301,0.152789,,,,7.85398e-5
Test1,3-Recover,177.600,3.808,0.197,0.032,,0.0491885,407.437,,4.91885,0.407437,,,,7.85398e-5
Test1,3-Recover,177.933,3.834,0.171,0.012,,0.0426966,152.789,,4.26966,0.152789,,,,7.85398e-5
Test1,3-Recover,178.267,3.862,0.143,0.019,,0.0357054,241.916,,3.57054,0.241916,,,,7.85398e-5
Test1,3-Recover,178.600,3.888,0.117,0.012,,0.0292135,152.789,,2.92135,0.152789,,,,7.85398e-5
Test1,3-Recover,178.933,3.914,0.091,0.012,,0.0227216,152.789,,2.27216,0.152789,,,,7.85398e-5
Test1,3-Recover,179.267,3.942,0.063,0.005,,0.0157303,63.662,,1.57303,0.063662,,,,7.85398e-5
Test1,3-Recover,179.600,3.968,0.037,0.012,,0.00923845,152.789,,0.923845,0.152789,,,,7.85398e-5
Test1,3-Recover,179.933,3.995,0.01,-0.009,,0.00249688,-114.592,,0.249688,-0.114592,,,,7.85398e-5
Test1,3-Recover,180.100,4.005,-0,0.019,,0,241.916,,0,0.241916,,,,7.85398e-5