File: data/beta_1-3-1_2.csv
SetName,Cycle,Time_S,Size_mm,Displacement_mm,Force_N,,Strain,Stress(Pascal),,%Strain,Stress(kPa),,,,Area(m^2)
Test1,1-Compress,0.000,6.901,-0,0.039,,0,496.564,,0,0.496564,,,,7.85398e-5
Test1,1-Compress,0.333,6.858,0.043,0.039,,0.00623098,496.564,,0.623098,0.496564,,,,7.85398e-5
Test1,1-Compress,0.667,6.811,0.09,0.039,,0.0130416,496.564,,1.30416,0.496564,,,,7.85398e-5
Test1,1-Compress,1.000,6.765,0.136,0.039,,0.0197073,496.564,,1.97073,0.496564,,,,7.85398e-5
Test1,1-Compress,1.333,6.72,0.181,0.039,,0.0262281,496.564,,2.62281,0.496564,,,,7.85398e-5
Test1,1-Compress,1.667,6.673,0.228,0.039,,0.0330387,496.564,,3.30387,0.496564,,,,7.85398e-5
Test1,1-Compress,2.000,6.627,0.274,0.039,,0.0397044,496.564,,3.97044,0.496564,,,,7.85398e-5
Test1,1-Compress,2.333,6.582,0.319,0.039,,0.0462252,496.564,,4.62252,0.496564,,,,7.85398e-5
Test1,1-Compress,2.667,6.535,0.366,0.039,,0.0530358,496.564,,5.30358,0.496564,,,,7.85398e-5
Test1,1-Compress,3.000,6.489,0.412,0.039,,0.0597015,496.564,,5.97015,0.496564,,,,7.85398e-5
Test1,1-Compress,3.333,6.443,0.458,0.039,,0.0663672,496.564,,6.63672,0.496564,,,,7.85398e-5
Test1,1-Compress,3.667,6.396,0.505,0.039,,0.0731778,496.564,,7.31778,0.496564,,,,7.85398e-5
Test1,1-Compress,4.000,6.351,0.55,0.039,,0.0796986,496.564,,7.96986,0.496564,,,,7.85398e-5
Test1,1-Compress,4.333,6.305,0.596,0.039,,0.0863643,496.564,,8.63643,0.496564,,,,7.85398e-5
Test1,1-Compress,4.667,6.258,0.643,0.046,,0.0931749,585.69,,9.31749,0.58569,,,,7.85398e-5
Test1,1-Compress,5.000,6.212,0.689,0.046,,0.0998406,585.69,,9.98406,0.58569,,,,7.85398e-5
Test1,1-Compress,5.333,6.167,0.734,0.046,,0.106361,585.69,,10.6361,0.58569,,,,7.85398e-5
Test1,1-Compress,5.667,6.12,0.781,0.046,,0.113172,585.69,,11.3172,0.58569,,,,7.85398e-5
Test1,1-Compress,6.000,6.074,0.827,0.046,,0.119838,585.69,,11.9838,0.58569,,,,7.85398e-5
Test1,1-Compress,6.333,6.028,0.873,0.053,,0.126503,674.817,,12.6503,0.674817,,,,7.85398e-5
Test1,1-Compress,6.667,5.982,0.919,0.046,,0.133169,585.69,,13.3169,0.58569,,,,7.85398e-5
Test1,1-Compress,7.000,5.936,0.965,0.039,,0.139835,496.564,,13.9835,0.496564,,,,7.85398e-5
Test1,1-Compress,7.333,5.89,1.011,0.053,,0.146501,674.817,,14.6501,0.674817,,,,7.85398e-5
Test1,1-Compress,7.667,5.843,1.058,0.039,,0.153311,496.564,,15.3311,0.496564,,,,7.85398e-5
Test1,1-Compress,8.000,5.797,1.104,0.046,,0.159977,585.69,,15.9977,0.58569,,,,7.85398e-5
Test1,1-Compress,8.333,5.752,1.149,0.039,,0.166498,496.564,,16.6498,0.496564,,,,7.85398e-5
Test1,1-Compress,8.667,5.705,1.196,0.039,,0.173308,496.564,,17.3308,0.496564,,,,7.85398e-5
Test1,1-Compress,9.000,5.659,1.242,0.039,,0.179974,496.564,,17.9974,0.496564,,,,7.85398e-5
Test1,1-Compress,9.333,5.614,1.287,0.039,,0.186495,496.564,,18.6495,0.496564,,,,7.85398e-5
Test1,1-Compress,9.667,5.566,1.335,0.039,,0.19345,496.564,,19.345,0.496564,,,,7.85398e-5
Test1,1-Compress,10.000,5.521,1.38,0.039,,0.199971,496.564,,19.9971,0.496564,,,,7.85398e-5
Test1,1-Compress,10.333,5.475,1.426,0.039,,0.206637,496.564,,20.6637,0.496564,,,,7.85398e-5
Test1,1-Compress,10.667,5.429,1.472,0.039,,0.213302,496.564,,21.3302,0.496564,,,,7.85398e-5
Test1,1-Compress,11.000,5.383,1.518,0.039,,0.219968,496.564,,21.9968,0.496564,,,,7.85398e-5
Test1,1-Compress,11.333,5.337,1.564,0.039,,0.226634,496.564,,22.6634,0.496564,,,,7.85398e-5
Test1,1-Compress,11.667,5.29,1.611,0.039,,0.233444,496.564,,23.3444,0.496564,,,,7.85398e-5
Test1,1-Compress,12.000,5.244,1.657,0.039,,0.24011,496.564,,24.011,0.496564,,,,7.85398e-5
Test1,1-Compress,12.333,5.199,1.702,0.039,,0.246631,496.564,,24.6631,0.496564,,,,7.85398e-5
Test1,1-Compress,12.667,5.152,1.749,0.046,,0.253442,585.69,,25.3442,0.58569,,,,7.85398e-5
Test1,1-Compress,13.000,5.106,1.795,0.046,,0.260107,585.69,,26.0107,0.58569,,,,7.85398e-5
Test1,1-Compress,13.333,5.061,1.84,0.046,,0.266628,585.69,,26.6628,0.58569,,,,7.85398e-5
Test1,1-Compress,13.667,5.014,1.887,0.046,,0.273439,585.69,,27.3439,0.58569,,,,7.85398e-5
Test1,1-Compress,14.000,4.968,1.933,0.046,,0.280104,585.69,,28.0104,0.58569,,,,7.85398e-5
Test1,1-Compress,14.333,4.922,1.979,0.046,,0.28677,585.69,,28.677,0.58569,,,,7.85398e-5
Test1,1-Compress,14.667,4.875,2.026,0.059,,0.293581,751.211,,29.3581,0.751211,,,,7.85398e-5
Test1,1-Compress,15.000,4.83,2.071,0.053,,0.300101,674.817,,30.0101,0.674817,,,,7.85398e-5
Test1,1-Compress,15.333,4.784,2.117,0.046,,0.306767,585.69,,30.6767,0.58569,,,,7.85398e-5
Test1,1-Compress,15.667,4.737,2.164,0.046,,0.313578,585.69,,31.3578,0.58569,,,,7.85398e-5
Test1,1-Compress,16.000,4.691,2.21,0.046,,0.320243,585.69,,32.0243,0.58569,,,,7.85398e-5
Test1,1-Compress,16.333,4.646,2.255,0.039,,0.326764,496.564,,32.6764,0.496564,,,,7.85398e-5
Test1,1-Compress,16.667,4.599,2.302,0.039,,0.333575,496.564,,33.3575,0.496564,,,,7.85398e-5
Test1,1-Compress,17.000,4.553,2.348,0.039,,0.340241,496.564,,34.0241,0.496564,,,,7.85398e-5
Test1,1-Compress,17.333,4.507,2.394,0.039,,0.346906,496.564,,34.6906,0.496564,,,,7.85398e-5
Test1,1-Compress,17.667,4.461,2.44,0.039,,0.353572,496.564,,35.3572,0.496564,,,,7.85398e-5
Test1,1-Compress,18.000,4.415,2.486,0.039,,0.360238,496.564,,36.0238,0.496564,,,,7.85398e-5
Test1,1-Compress,18.333,4.369,2.532,0.039,,0.366903,496.564,,36.6903,0.496564,,,,7.85398e-5
Test1,1-Compress,18.667,4.322,2.579,0.039,,0.373714,496.564,,37.3714,0.496564,,,,7.85398e-5
Test1,1-Compress,19.000,4.277,2.624,0.039,,0.380235,496.564,,38.0235,0.496564,,,,7.85398e-5
Test1,1-Compress,19.333,4.231,2.67,0.039,,0.3869,496.564,,38.69,0.496564,,,,7.85398e-5
Test1,1-Compress,19.667,4.184,2.717,0.039,,0.393711,496.564,,39.3711,0.496564,,,,7.85398e-5
Test1,1-Compress,20.000,4.138,2.763,0.039,,0.400377,496.564,,40.0377,0.496564,,,,7.85398e-5
Test1,1-Compress,20.333,4.093,2.808,0.039,,0.406898,496.564,,40.6898,0.496564,,,,7.85398e-5
Test1,1-Compress,20.667,4.046,2.855,0.046,,0.413708,585.69,,41.3708,0.58569,,,,7.85398e-5
Test1,1-Compress,21.000,4,2.901,0.046,,0.420374,585.69,,42.0374,0.58569,,,,7.85398e-5
Test1,1-Compress,21.333,3.955,2.946,0.046,,0.426895,585.69,,42.6895,0.58569,,,,7.85398e-5
Test1,1-Compress,21.667,3.908,2.993,0.046,,0.433705,585.69,,43.3705,0.58569,,,,7.85398e-5
Test1,1-Compress,22.000,3.862,3.039,0.053,,0.440371,674.817,,44.0371,0.674817,,,,7.85398e-5
Test1,1-Compress,22.333,3.816,3.085,0.053,,0.447037,674.817,,44.7037,0.674817,,,,7.85398e-5
Test1,1-Compress,22.667,3.769,3.132,0.053,,0.453847,674.817,,45.3847,0.674817,,,,7.85398e-5
Test1,1-Compress,23.000,3.724,3.177,0.053,,0.460368,674.817,,46.0368,0.674817,,,,7.85398e-5
Test1,1-Compress,23.333,3.678,3.223,0.053,,0.467034,674.817,,46.7034,0.674817,,,,7.85398e-5
Test1,1-Compress,23.667,3.631,3.27,0.046,,0.473844,585.69,,47.3844,0.58569,,,,7.85398e-5
Test1,1-Compress,24.000,3.585,3.316,0.046,,0.48051,585.69,,48.051,0.58569,,,,7.85398e-5
Test1,1-Compress,24.333,3.54,3.361,0.046,,0.487031,585.69,,48.7031,0.58569,,,,7.85398e-5
Test1,1-Compress,24.667,3.493,3.408,0.039,,0.493841,496.564,,49.3841,0.496564,,,,7.85398e-5
Test1,1-Compress,25.000,3.447,3.454,0.039,,0.500507,496.564,,50.0507,0.496564,,,,7.85398e-5
Test1,1-Compress,25.333,3.402,3.499,0.053,,0.507028,674.817,,50.7028,0.674817,,,,7.85398e-5
Test1,1-Compress,25.667,3.354,3.547,0.046,,0.513983,585.69,,51.3983,0.58569,,,,7.85398e-5
Test1,1-Compress,26.000,3.309,3.592,0.053,,0.520504,674.817,,52.0504,0.674817,,,,7.85398e-5
Test1,1-Compress,26.333,3.263,3.638,0.053,,0.52717,674.817,,52.717,0.674817,,,,7.85398e-5
Test1,1-Compress,26.667,3.216,3.685,0.053,,0.533981,674.817,,53.3981,0.674817,,,,7.85398e-5
Test1,1-Compress,27.000,3.171,3.73,0.046,,0.540501,585.69,,54.0501,0.58569,,,,7.85398e-5
Test1,1-Compress,27.333,3.125,3.776,0.046,,0.547167,585.69,,54.7167,0.58569,,,,7.85398e-5
Test1,1-Compress,27.667,3.078,3.823,0.046,,0.553978,585.69,,55.3978,0.58569,,,,7.85398e-5
Test1,1-Compress,28.000,3.032,3.869,0.059,,0.560643,751.211,,56.0643,0.751211,,,,7.85398e-5
Test1,1-Compress,28.333,2.987,3.914,0.059,,0.567164,751.211,,56.7164,0.751211,,,,7.85398e-5
Test1,1-Compress,28.667,2.94,3.961,0.059,,0.573975,751.211,,57.3975,0.751211,,,,7.85398e-5
Test1,1-Compress,29.000,2.894,4.007,0.053,,0.58064,674.817,,58.064,0.674817,,,,7.85398e-5
Test1,1-Compress,29.333,2.849,4.052,0.066,,0.587161,840.338,,58.7161,0.840338,,,,7.85398e-5
Test1,1-Compress,29.667,2.801,4.1,0.046,,0.594117,585.69,,59.4117,0.58569,,,,7.85398e-5
Test1,1-Compress,30.000,2.76,4.141,0.087,,0.600058,1107.72,,60.0058,1.10772,,,,7.85398e-5
Test1,1-Recover,30.333,2.801,4.1,0.080,,0.594117,1018.59,,59.4117,1.01859,,,,7.85398e-5
Test1,1-Recover,30.667,2.848,4.053,0.059,,0.587306,751.211,,58.7306,0.751211,,,,7.85398e-5
Test1,1-Recover,31.000,2.893,4.008,0.059,,0.580785,751.211,,58.0785,0.751211,,,,7.85398e-5
Test1,1-Recover,31.333,2.939,3.962,0.059,,0.57412,751.211,,57.412,0.751211,,,,7.85398e-5
Test1,1-Recover,31.667,2.986,3.915,0.066,,0.567309,840.338,,56.7309,0.840338,,,,7.85398e-5
Test1,1-Recover,32.000,3.032,3.869,0.046,,0.560643,585.69,,56.0643,0.58569,,,,7.85398e-5
Test1,1-Recover,32.333,3.078,3.823,0.053,,0.553978,674.817,,55.3978,0.674817,,,,7.85398e-5
Test1,1-Recover,32.667,3.124,3.777,0.053,,0.547312,674.817,,54.7312,0.674817,,,,7.85398e-5
Test1,1-Recover,33.000,3.17,3.731,0.039,,0.540646,496.564,,54.0646,0.496564,,,,7.85398e-5
Test1,1-Recover,33.333,3.216,3.685,0.046,,0.533981,585.69,,53.3981,0.58569,,,,7.85398e-5
Test1,1-Recover,33.667,3.263,3.638,0.046,,0.52717,585.69,,52.717,0.58569,,,,7.85398e-5
Test1,1-Recover,34.000,3.308,3.593,0.046,,0.520649,585.69,,52.0649,0.58569,,,,7.85398e-5
Test1,1-Recover,34.333,3.354,3.547,0.039,,0.513983,496.564,,51.3983,0.496564,,,,7.85398e-5
Test1,1-Recover,34.667,3.401,3.5,0.039,,0.507173,496.564,,50.7173,0.496564,,,,7.85398e-5
Test1,1-Recover,35.000,3.447,3.454,0.039,,0.500507,496.564,,50.0507,0.496564,,,,7.85398e-5
Test1,1-Recover,35.333,3.492,3.409,0.039,,0.493986,496.564,,49.3986,0.496564,,,,7.85398e-5
Test1,1-Recover,35.667,3.539,3.362,0.039,,0.487176,496.564,,48.7176,0.496564,,,,7.85398e-5
Test1,1-Recover,36.000,3.585,3.316,0.039,,0.48051,496.564,,48.051,0.496564,,,,7.85398e-5
Test1,1-Recover,36.333,3.63,3.271,0.039,,0.473989,496.564,,47.3989,0.496564,,,,7.85398e-5
Test1,1-Recover,36.667,3.678,3.223,0.046,,0.467034,585.69,,46.7034,0.58569,,,,7.85398e-5
Test1,1-Recover,37.000,3.723,3.178,0.046,,0.460513,585.69,,46.0513,0.58569,,,,7.85398e-5
Test1,1-Recover,37.333,3.769,3.132,0.046,,0.453847,585.69,,45.3847,0.58569,,,,7.85398e-5
Test1,1-Recover,37.667,3.816,3.085,0.046,,0.447037,585.69,,44.7037,0.58569,,,,7.85398e-5
Test1,1-Recover,38.000,3.861,3.04,0.053,,0.440516,674.817,,44.0516,0.674817,,,,7.85398e-5
Test1,1-Recover,38.333,3.907,2.994,0.053,,0.43385,674.817,,43.385,0.674817,,,,7.85398e-5
Test1,1-Recover,38.667,3.954,2.947,0.053,,0.42704,674.817,,42.704,0.674817,,,,7.85398e-5
Test1,1-Recover,39.000,4,2.901,0.046,,0.420374,585.69,,42.0374,0.58569,,,,7.85398e-5
Test1,1-Recover,39.333,4.045,2.856,0.046,,0.413853,585.69,,41.3853,0.58569,,,,7.85398e-5
Test1,1-Recover,39.667,4.092,2.809,0.046,,0.407042,585.69,,40.7042,0.58569,,,,7.85398e-5
Test1,1-Recover,40.000,4.138,2.763,0.046,,0.400377,585.69,,40.0377,0.58569,,,,7.85398e-5
Test1,1-Recover,40.333,4.183,2.718,0.046,,0.393856,585.69,,39.3856,0.58569,,,,7.85398e-5
Test1,1-Recover,40.667,4.231,2.67,0.039,,0.3869,496.564,,38.69,0.496564,,,,7.85398e-5
Test1,1-Recover,41.000,4.276,2.625,0.039,,0.38038,496.564,,38.038,0.496564,,,,7.85398e-5
Test1,1-Recover,41.333,4.322,2.579,0.039,,0.373714,496.564,,37.3714,0.496564,,,,7.85398e-5
Test1,1-Recover,41.667,4.369,2.532,0.039,,0.366903,496.564,,36.6903,0.496564,,,,7.85398e-5
Test1,1-Recover,42.000,4.414,2.487,0.039,,0.360383,496.564,,36.0383,0.496564,,,,7.85398e-5
Test1,1-Recover,42.333,4.46,2.441,0.039,,0.353717,496.564,,35.3717,0.496564,,,,7.85398e-5
Test1,1-Recover,42.667,4.507,2.394,0.039,,0.346906,496.564,,34.6906,0.496564,,,,7.85398e-5
Test1,1-Recover,43.000,4.553,2.348,0.039,,0.340241,496.564,,34.0241,0.496564,,,,7.85398e-5
Test1,1-Recover,43.333,4.598,2.303,0.039,,0.33372,496.564,,33.372,0.496564,,,,7.85398e-5
Test1,1-Recover,43.667,4.645,2.256,0.039,,0.326909,496.564,,32.6909,0.496564,,,,7.85398e-5
Test1,1-Recover,44.000,4.691,2.21,0.039,,0.320243,496.564,,32.0243,0.496564,,,,7.85398e-5
Test1,1-Recover,44.333,4.736,2.165,0.039,,0.313723,496.564,,31.3723,0.496564,,,,7.85398e-5
Test1,1-Recover,44.667,4.784,2.117,0.039,,0.306767,496.564,,30.6767,0.496564,,,,7.85398e-5
Test1,1-Recover,45.000,4.829,2.072,0.046,,0.300246,585.69,,30.0246,0.58569,,,,7.85398e-5
Test1,1-Recover,45.333,4.875,2.026,0.046,,0.293581,585.69,,29.3581,0.58569,,,,7.85398e-5
Test1,1-Recover,45.667,4.922,1.979,0.046,,0.28677,585.69,,28.677,0.58569,,,,7.85398e-5
Test1,1-Recover,46.000,4.967,1.934,0.039,,0.280249,496.564,,28.0249,0.496564,,,,7.85398e-5
Test1,1-Recover,46.333,5.013,1.888,0.039,,0.273584,496.564,,27.3584,0.496564,,,,7.85398e-5
Test1,1-Recover,46.667,5.06,1.841,0.046,,0.266773,585.69,,26.6773,0.58569,,,,7.85398e-5
Test1,1-Recover,47.000,5.106,1.795,0.046,,0.260107,585.69,,26.0107,0.58569,,,,7.85398e-5
Test1,1-Recover,47.333,5.151,1.75,0.039,,0.253586,496.564,,25.3586,0.496564,,,,7.85398e-5
Test1,1-Recover,47.667,5.198,1.703,0.046,,0.246776,585.69,,24.6776,0.58569,,,,7.85398e-5
Test1,1-Recover,48.000,5.244,1.657,0.039,,0.24011,496.564,,24.011,0.496564,,,,7.85398e-5
Test1,1-Recover,48.333,5.29,1.611,0.039,,0.233444,496.564,,23.3444,0.496564,,,,7.85398e-5
Test1,1-Recover,48.667,5.337,1.564,0.039,,0.226634,496.564,,22.6634,0.496564,,,,7.85398e-5
Test1,1-Recover,49.000,5.382,1.519,0.039,,0.220113,496.564,,22.0113,0.496564,,,,7.85398e-5
Test1,1-Recover,49.333,5.428,1.473,0.039,,0.213447,496.564,,21.3447,0.496564,,,,7.85398e-5
Test1,1-Recover,49.667,5.475,1.426,0.032,,0.206637,407.437,,20.6637,0.407437,,,,7.85398e-5
Test1,1-Recover,50.000,5.521,1.38,0.039,,0.199971,496.564,,19.9971,0.496564,,,,7.85398e-5
Test1,1-Recover,50.333,5.566,1.335,0.039,,0.19345,496.564,,19.345,0.496564,,,,7.85398e-5
Test1,1-Recover,50.667,5.613,1.288,0.032,,0.18664,407.437,,18.664,0.407437,,,,7.85398e-5
Test1,1-Recover,51.000,5.659,1.242,0.032,,0.179974,407.437,,17.9974,0.407437,,,,7.85398e-5
Test1,1-Recover,51.333,5.704,1.197,0.039,,0.173453,496.564,,17.3453,0.496564,,,,7.85398e-5
Test1,1-Recover,51.667,5.752,1.149,0.019,,0.166498,241.916,,16.6498,0.241916,,,,7.85398e-5
Test1,1-Recover,52.000,5.797,1.104,0.025,,0.159977,318.31,,15.9977,0.31831,,,,7.85398e-5
Test1,1-Recover,52.333,5.843,1.058,0.032,,0.153311,407.437,,15.3311,0.407437,,,,7.85398e-5
Test1,1-Recover,52.667,5.89,1.011,0.025,,0.146501,318.31,,14.6501,0.31831,,,,7.85398e-5
Test1,1-Recover,53.000,5.935,0.966,0.039,,0.13998,496.564,,13.998,0.496564,,,,7.85398e-5
Test1,1-Recover,53.333,5.981,0.92,0.025,,0.133314,318.31,,13.3314,0.31831,,,,7.85398e-5
Test1,1-Recover,53.667,6.028,0.873,0.032,,0.126503,407.437,,12.6503,0.407437,,,,7.85398e-5
Test1,1-Recover,54.000,6.074,0.827,0.039,,0.119838,496.564,,11.9838,0.496564,,,,7.85398e-5
Test1,1-Recover,54.333,6.119,0.782,0.039,,0.113317,496.564,,11.3317,0.496564,,,,7.85398e-5
Test1,1-Recover,54.667,6.166,0.735,0.046,,0.106506,585.69,,10.6506,0.58569,,,,7.85398e-5
Test1,1-Recover,55.000,6.212,0.689,0.025,,0.0998406,318.31,,9.98406,0.31831,,,,7.85398e-5
Test1,1-Recover,55.333,6.257,0.644,0.039,,0.0933198,496.564,,9.33198,0.496564,,,,7.85398e-5
Test1,1-Recover,55.667,6.305,0.596,0.039,,0.0863643,496.564,,8.63643,0.496564,,,,7.85398e-5
Test1,1-Recover,56.000,6.35,0.551,0.046,,0.0798435,585.69,,7.98435,0.58569,,,,7.85398e-5
Test1,1-Recover,56.333,6.396,0.505,0.039,,0.0731778,496.564,,7.31778,0.496564,,,,7.85398e-5
Test1,1-Recover,56.667,6.443,0.458,0.039,,0.0663672,496.564,,6.63672,0.496564,,,,7.85398e-5
Test1,1-Recover,57.000,6.488,0.413,0.039,,0.0598464,496.564,,5.98464,0.496564,,,,7.85398e-5
Test1,1-Recover,57.333,6.534,0.367,0.039,,0.0531807,496.564,,5.31807,0.496564,,,,7.85398e-5
Test1,1-Recover,57.667,6.581,0.32,0.039,,0.0463701,496.564,,4.63701,0.496564,,,,7.85398e-5
Test1,1-Recover,58.000,6.627,0.274,0.039,,0.0397044,496.564,,3.97044,0.496564,,,,7.85398e-5
Test1,1-Recover,58.333,6.672,0.229,0.032,,0.0331836,407.437,,3.31836,0.407437,,,,7.85398e-5
Test1,1-Recover,58.667,6.719,0.182,0.032,,0.026373,407.437,,2.6373,0.407437,,,,7.85398e-5
Test1,1-Recover,59.000,6.765,0.136,0.025,,0.0197073,318.31,,1.97073,0.31831,,,,7.85398e-5
Test1,1-Recover,59.333,6.811,0.09,0.032,,0.0130416,407.437,,1.30416,0.407437,,,,7.85398e-5
Test1,1-Recover,59.667,6.857,0.044,0.025,,0.00637589,318.31,,0.637589,0.31831,,,,7.85398e-5
Test1,1-Recover,60.000,6.901,-0,0.005,,0,63.662,,0,0.063662,,,,7.85398e-5
Test1,2-Compress,60.317,6.864,0.037,0.039,,0.00536154,496.564,,0.536154,0.496564,,,,7.85398e-5
Test1,2-Compress,60.650,6.819,0.082,0.032,,0.0118823,407.437,,1.18823,0.407437,,,,7.85398e-5
Test1,2-Compress,60.983,6.773,0.128,0.039,,0.018548,496.564,,1.8548,0.496564,,,,7.85398e-5
Test1,2-Compress,61.317,6.726,0.175,0.039,,0.0253586,496.564,,2.53586,0.496564,,,,7.85398e-5
Test1,2-Compress,61.650,6.681,0.22,0.039,,0.0318794,496.564,,3.18794,0.496564,,,,7.85398e-5
Test1,2-Compress,61.983,6.635,0.266,0.046,,0.0385451,585.69,,3.85451,0.58569,,,,7.85398e-5
Test1,2-Compress,62.317,6.588,0.313,0.039,,0.0453557,496.564,,4.53557,0.496564,,,,7.85398e-5
Test1,2-Compress,62.650,6.542,0.359,0.039,,0.0520214,496.564,,5.20214,0.496564,,,,7.85398e-5
Test1,2-Compress,62.983,6.497,0.404,0.039,,0.0585422,496.564,,5.85422,0.496564,,,,7.85398e-5
Test1,2-Compress,63.317,6.45,0.451,0.032,,0.0653528,407.437,,6.53528,0.407437,,,,7.85398e-5
Test1,2-Compress,63.650,6.404,0.497,0.039,,0.0720185,496.564,,7.20185,0.496564,,,,7.85398e-5
Test1,2-Compress,63.983,6.358,0.543,0.039,,0.0786842,496.564,,7.86842,0.496564,,,,7.85398e-5
Test1,2-Compress,64.317,6.311,0.59,0.039,,0.0854949,496.564,,8.54949,0.496564,,,,7.85398e-5
Test1,2-Compress,64.650,6.266,0.635,0.039,,0.0920156,496.564,,9.20156,0.496564,,,,7.85398e-5
Test1,2-Compress,64.983,6.22,0.681,0.039,,0.0986814,496.564,,9.86814,0.496564,,,,7.85398e-5
Test1,2-Compress,65.317,6.173,0.728,0.039,,0.105492,496.564,,10.5492,0.496564,,,,7.85398e-5
Test1,2-Compress,65.650,6.127,0.774,0.032,,0.112158,407.437,,11.2158,0.407437,,,,7.85398e-5
Test1,2-Compress,65.983,6.082,0.819,0.039,,0.118678,496.564,,11.8678,0.496564,,,,7.85398e-5
Test1,2-Compress,66.317,6.035,0.866,0.039,,0.125489,496.564,,12.5489,0.496564,,,,7.85398e-5
Test1,2-Compress,66.650,5.989,0.912,0.039,,0.132155,496.564,,13.2155,0.496564,,,,7.85398e-5
Test1,2-Compress,66.983,5.944,0.957,0.039,,0.138676,496.564,,13.8676,0.496564,,,,7.85398e-5
Test1,2-Compress,67.317,5.896,1.005,0.039,,0.145631,496.564,,14.5631,0.496564,,,,7.85398e-5
Test1,2-Compress,67.650,5.851,1.05,0.039,,0.152152,496.564,,15.2152,0.496564,,,,7.85398e-5
Test1,2-Compress,67.983,5.805,1.096,0.039,,0.158818,496.564,,15.8818,0.496564,,,,7.85398e-5
Test1,2-Compress,68.317,5.758,1.143,0.039,,0.165628,496.564,,16.5628,0.496564,,,,7.85398e-5
Test1,2-Compress,68.650,5.713,1.188,0.039,,0.172149,496.564,,17.2149,0.496564,,,,7.85398e-5
Test1,2-Compress,68.983,5.667,1.234,0.046,,0.178815,585.69,,17.8815,0.58569,,,,7.85398e-5
Test1,2-Compress,69.317,5.62,1.281,0.039,,0.185625,496.564,,18.5625,0.496564,,,,7.85398e-5
Test1,2-Compress,69.650,5.574,1.327,0.039,,0.192291,496.564,,19.2291,0.496564,,,,7.85398e-5
Test1,2-Compress,69.983,5.528,1.373,0.046,,0.198957,585.69,,19.8957,0.58569,,,,7.85398e-5
Test1,2-Compress,70.317,5.482,1.419,0.046,,0.205622,585.69,,20.5622,0.58569,,,,7.85398e-5
Test1,2-Compress,70.650,5.436,1.465,0.046,,0.212288,585.69,,21.2288,0.58569,,,,7.85398e-5
Test1,2-Compress,70.983,5.391,1.51,0.046,,0.218809,585.69,,21.8809,0.58569,,,,7.85398e-5
Test1,2-Compress,71.317,5.343,1.558,0.046,,0.225764,585.69,,22.5764,0.58569,,,,7.85398e-5
Test1,2-Compress,71.650,5.298,1.603,0.046,,0.232285,585.69,,23.2285,0.58569,,,,7.85398e-5
Test1,2-Compress,71.983,5.252,1.649,0.046,,0.238951,585.69,,23.8951,0.58569,,,,7.85398e-5
Test1,2-Compress,72.317,5.205,1.696,0.039,,0.245761,496.564,,24.5761,0.496564,,,,7.85398e-5
Test1,2-Compress,72.650,5.16,1.741,0.046,,0.252282,585.69,,25.2282,0.58569,,,,7.85398e-5
Test1,2-Compress,72.983,5.114,1.787,0.039,,0.258948,496.564,,25.8948,0.496564,,,,7.85398e-5
Test1,2-Compress,73.317,5.067,1.834,0.039,,0.265759,496.564,,26.5759,0.496564,,,,7.85398e-5
Test1,2-Compress,73.650,5.021,1.88,0.039,,0.272424,496.564,,27.2424,0.496564,,,,7.85398e-5
Test1,2-Compress,73.983,4.976,1.925,0.039,,0.278945,496.564,,27.8945,0.496564,,,,7.85398e-5
Test1,2-Compress,74.317,4.929,1.972,0.039,,0.285756,496.564,,28.5756,0.496564,,,,7.85398e-5
Test1,2-Compress,74.650,4.883,2.018,0.039,,0.292421,496.564,,29.2421,0.496564,,,,7.85398e-5
Test1,2-Compress,74.983,4.837,2.064,0.039,,0.299087,496.564,,29.9087,0.496564,,,,7.85398e-5
Test1,2-Compress,75.317,4.79,2.111,0.039,,0.305898,496.564,,30.5898,0.496564,,,,7.85398e-5
Test1,2-Compress,75.650,4.745,2.156,0.039,,0.312418,496.564,,31.2418,0.496564,,,,7.85398e-5
Test1,2-Compress,75.983,4.699,2.202,0.039,,0.319084,496.564,,31.9084,0.496564,,,,7.85398e-5
Test1,2-Compress,76.317,4.652,2.249,0.039,,0.325895,496.564,,32.5895,0.496564,,,,7.85398e-5
Test1,2-Compress,76.650,4.606,2.295,0.039,,0.33256,496.564,,33.256,0.496564,,,,7.85398e-5
Test1,2-Compress,76.983,4.561,2.34,0.046,,0.339081,585.69,,33.9081,0.58569,,,,7.85398e-5
Test1,2-Compress,77.317,4.514,2.387,0.046,,0.345892,585.69,,34.5892,0.58569,,,,7.85398e-5
Test1,2-Compress,77.650,4.468,2.433,0.046,,0.352558,585.69,,35.2558,0.58569,,,,7.85398e-5
Test1,2-Compress,77.983,4.423,2.478,0.046,,0.359078,585.69,,35.9078,0.58569,,,,7.85398e-5
Test1,2-Compress,78.317,4.375,2.526,0.046,,0.366034,585.69,,36.6034,0.58569,,,,7.85398e-5
Test1,2-Compress,78.650,4.33,2.571,0.053,,0.372555,674.817,,37.2555,0.674817,,,,7.85398e-5
Test1,2-Compress,78.983,4.284,2.617,0.059,,0.37922,751.211,,37.922,0.751211,,,,7.85398e-5
Test1,2-Compress,79.317,4.238,2.663,0.053,,0.385886,674.817,,38.5886,0.674817,,,,7.85398e-5
Test1,2-Compress,79.650,4.192,2.709,0.053,,0.392552,674.817,,39.2552,0.674817,,,,7.85398e-5
Test1,2-Compress,79.983,4.146,2.755,0.053,,0.399218,674.817,,39.9218,0.674817,,,,7.85398e-5
Test1,2-Compress,80.317,4.099,2.802,0.046,,0.406028,585.69,,40.6028,0.58569,,,,7.85398e-5
Test1,2-Compress,80.650,4.053,2.848,0.039,,0.412694,496.564,,41.2694,0.496564,,,,7.85398e-5
Test1,2-Compress,80.983,4.008,2.893,0.039,,0.419215,496.564,,41.9215,0.496564,,,,7.85398e-5
Test1,2-Compress,81.317,3.961,2.94,0.039,,0.426025,496.564,,42.6025,0.496564,,,,7.85398e-5
Test1,2-Compress,81.650,3.915,2.986,0.039,,0.432691,496.564,,43.2691,0.496564,,,,7.85398e-5
Test1,2-Compress,81.983,3.87,3.031,0.039,,0.439212,496.564,,43.9212,0.496564,,,,7.85398e-5
Test1,2-Compress,82.317,3.822,3.079,0.039,,0.446167,496.564,,44.6167,0.496564,,,,7.85398e-5
Test1,2-Compress,82.650,3.777,3.124,0.039,,0.452688,496.564,,45.2688,0.496564,,,,7.85398e-5
Test1,2-Compress,82.983,3.731,3.17,0.039,,0.459354,496.564,,45.9354,0.496564,,,,7.85398e-5
Test1,2-Compress,83.317,3.684,3.217,0.039,,0.466164,496.564,,46.6164,0.496564,,,,7.85398e-5
Test1,2-Compress,83.650,3.639,3.262,0.039,,0.472685,496.564,,47.2685,0.496564,,,,7.85398e-5
Test1,2-Compress,83.983,3.593,3.308,0.039,,0.479351,496.564,,47.9351,0.496564,,,,7.85398e-5
Test1,2-Compress,84.317,3.546,3.355,0.039,,0.486161,496.564,,48.6161,0.496564,,,,7.85398e-5
Test1,2-Compress,84.650,3.5,3.401,0.039,,0.492827,496.564,,49.2827,0.496564,,,,7.85398e-5
Test1,2-Compress,84.983,3.455,3.446,0.046,,0.499348,585.69,,49.9348,0.58569,,,,7.85398e-5
Test1,2-Compress,85.317,3.408,3.493,0.046,,0.506159,585.69,,50.6159,0.58569,,,,7.85398e-5
Test1,2-Compress,85.650,3.362,3.539,0.046,,0.512824,585.69,,51.2824,0.58569,,,,7.85398e-5
Test1,2-Compress,85.983,3.317,3.584,0.046,,0.519345,585.69,,51.9345,0.58569,,,,7.85398e-5
Test1,2-Compress,86.317,3.269,3.632,0.046,,0.526301,585.69,,52.6301,0.58569,,,,7.85398e-5
Test1,2-Compress,86.650,3.224,3.677,0.053,,0.532821,674.817,,53.2821,0.674817,,,,7.85398e-5
Test1,2-Compress,86.983,3.178,3.723,0.053,,0.539487,674.817,,53.9487,0.674817,,,,7.85398e-5
Test1,2-Compress,87.317,3.131,3.77,0.053,,0.546298,674.817,,54.6298,0.674817,,,,7.85398e-5
Test1,2-Compress,87.650,3.086,3.815,0.066,,0.552818,840.338,,55.2818,0.840338,,,,7.85398e-5
Test1,2-Compress,87.983,3.04,3.861,0.066,,0.559484,840.338,,55.9484,0.840338,,,,7.85398e-5
Test1,2-Compress,88.317,2.993,3.908,0.073,,0.566295,929.465,,56.6295,0.929465,,,,7.85398e-5
Test1,2-Compress,88.650,2.947,3.954,0.073,,0.57296,929.465,,57.296,0.929465,,,,7.85398e-5
Test1,2-Compress,88.983,2.902,3.999,0.073,,0.579481,929.465,,57.9481,0.929465,,,,7.85398e-5
Test1,2-Compress,89.317,2.855,4.046,0.066,,0.586292,840.338,,58.6292,0.840338,,,,7.85398e-5
Test1,2-Compress,89.650,2.809,4.092,0.080,,0.592958,1018.59,,59.2958,1.01859,,,,7.85398e-5
Test1,2-Compress,89.983,2.763,4.138,0.087,,0.599623,1107.72,,59.9623,1.10772,,,,7.85398e-5
Test1,2-Recover,90.303,2.791,4.11,0.066,,0.595566,840.338,,59.5566,0.840338,,,,7.85398e-5
Test1,2-Recover,90.637,2.838,4.063,0.066,,0.588755,840.338,,58.8755,0.840338,,,,7.85398e-5
Test1,2-Recover,90.970,2.884,4.017,0.053,,0.58209,674.817,,58.209,0.674817,,,,7.85398e-5
Test1,2-Recover,91.303,2.93,3.971,0.053,,0.575424,674.817,,57.5424,0.674817,,,,7.85398e-5
Test1,2-Recover,91.637,2.977,3.924,0.053,,0.568613,674.817,,56.8613,0.674817,,,,7.85398e-5
Test1,2-Recover,91.970,3.022,3.879,0.046,,0.562092,585.69,,56.2092,0.58569,,,,7.85398e-5
Test1,2-Recover,92.303,3.068,3.833,0.046,,0.555427,585.69,,55.5427,0.58569,,,,7.85398e-5
Test1,2-Recover,92.637,3.115,3.786,0.046,,0.548616,585.69,,54.8616,0.58569,,,,7.85398e-5
Test1,2-Recover,92.970,3.161,3.74,0.046,,0.54195,585.69,,54.195,0.58569,,,,7.85398e-5
Test1,2-Recover,93.303,3.206,3.695,0.046,,0.53543,585.69,,53.543,0.58569,,,,7.85398e-5
Test1,2-Recover,93.637,3.253,3.648,0.046,,0.528619,585.69,,52.8619,0.58569,,,,7.85398e-5
Test1,2-Recover,93.970,3.299,3.602,0.046,,0.521953,585.69,,52.1953,0.58569,,,,7.85398e-5
Test1,2-Recover,94.303,3.345,3.556,0.046,,0.515288,585.69,,51.5288,0.58569,,,,7.85398e-5
Test1,2-Recover,94.637,3.391,3.51,0.053,,0.508622,674.817,,50.8622,0.674817,,,,7.85398e-5
Test1,2-Recover,94.970,3.437,3.464,0.053,,0.501956,674.817,,50.1956,0.674817,,,,7.85398e-5
Test1,2-Recover,95.303,3.483,3.418,0.053,,0.495291,674.817,,49.5291,0.674817,,,,7.85398e-5
Test1,2-Recover,95.637,3.53,3.371,0.053,,0.48848,674.817,,48.848,0.674817,,,,7.85398e-5
Test1,2-Recover,95.970,3.576,3.325,0.046,,0.481814,585.69,,48.1814,0.58569,,,,7.85398e-5
Test1,2-Recover,96.303,3.621,3.28,0.053,,0.475293,674.817,,47.5293,0.674817,,,,7.85398e-5
Test1,2-Recover,96.637,3.668,3.233,0.046,,0.468483,585.69,,46.8483,0.58569,,,,7.85398e-5
Test1,2-Recover,96.970,3.713,3.188,0.046,,0.461962,585.69,,46.1962,0.58569,,,,7.85398e-5
Test1,2-Recover,97.303,3.759,3.142,0.039,,0.455296,496.564,,45.5296,0.496564,,,,7.85398e-5
Test1,2-Recover,97.637,3.807,3.094,0.039,,0.448341,496.564,,44.8341,0.496564,,,,7.85398e-5
Test1,2-Recover,97.970,3.852,3.049,0.039,,0.44182,496.564,,44.182,0.496564,,,,7.85398e-5
Test1,2-Recover,98.303,3.898,3.003,0.039,,0.435154,496.564,,43.5154,0.496564,,,,7.85398e-5
Test1,2-Recover,98.637,3.944,2.957,0.039,,0.428489,496.564,,42.8489,0.496564,,,,7.85398e-5
Test1,2-Recover,98.970,3.99,2.911,0.039,,0.421823,496.564,,42.1823,0.496564,,,,7.85398e-5
Test1,2-Recover,99.303,4.036,2.865,0.039,,0.415157,496.564,,41.5157,0.496564,,,,7.85398e-5
Test1,2-Recover,99.637,4.083,2.818,0.039,,0.408347,496.564,,40.8347,0.496564,,,,7.85398e-5
Test1,2-Recover,99.970,4.129,2.772,0.039,,0.401681,496.564,,40.1681,0.496564,,,,7.85398e-5
Test1,2-Recover,100.303,4.174,2.727,0.039,,0.39516,496.564,,39.516,0.496564,,,,7.85398e-5
Test1,2-Recover,100.637,4.221,2.68,0.039,,0.38835,496.564,,38.835,0.496564,,,,7.85398e-5
Test1,2-Recover,100.970,4.267,2.634,0.039,,0.381684,496.564,,38.1684,0.496564,,,,7.85398e-5
Test1,2-Recover,101.303,4.312,2.589,0.046,,0.375163,585.69,,37.5163,0.58569,,,,7.85398e-5
Test1,2-Recover,101.637,4.359,2.542,0.046,,0.368352,585.69,,36.8352,0.58569,,,,7.85398e-5
Test1,2-Recover,101.970,4.405,2.496,0.046,,0.361687,585.69,,36.1687,0.58569,,,,7.85398e-5
Test1,2-Recover,102.303,4.451,2.45,0.046,,0.355021,585.69,,35.5021,0.58569,,,,7.85398e-5
Test1,2-Recover,102.637,4.498,2.403,0.046,,0.34821,585.69,,34.821,0.58569,,,,7.85398e-5
Test1,2-Recover,102.970,4.543,2.358,0.046,,0.34169,585.69,,34.169,0.58569,,,,7.85398e-5
Test1,2-Recover,103.303,4.589,2.312,0.053,,0.335024,674.817,,33.5024,0.674817,,,,7.85398e-5
Test1,2-Recover,103.637,4.636,2.265,0.053,,0.328213,674.817,,32.8213,0.674817,,,,7.85398e-5
Test1,2-Recover,103.970,4.682,2.219,0.046,,0.321548,585.69,,32.1548,0.58569,,,,7.85398e-5
Test1,2-Recover,104.303,4.727,2.174,0.039,,0.315027,496.564,,31.5027,0.496564,,,,7.85398e-5
Test1,2-Recover,104.637,4.774,2.127,0.039,,0.308216,496.564,,30.8216,0.496564,,,,7.85398e-5
Test1,2-Recover,104.970,4.82,2.081,0.039,,0.30155,496.564,,30.155,0.496564,,,,7.85398e-5
Test1,2-Recover,105.303,4.866,2.035,0.039,,0.294885,496.564,,29.4885,0.496564,,,,7.85398e-5
Test1,2-Recover,105.637,4.912,1.989,0.039,,0.288219,496.564,,28.8219,0.496564,,,,7.85398e-5
Test1,2-Recover,105.970,4.958,1.943,0.039,,0.281553,496.564,,28.1553,0.496564,,,,7.85398e-5
Test1,2-Recover,106.303,5.004,1.897,0.039,,0.274888,496.564,,27.4888,0.496564,,,,7.85398e-5
Test1,2-Recover,106.637,5.051,1.85,0.039,,0.268077,496.564,,26.8077,0.496564,,,,7.85398e-5
Test1,2-Recover,106.970,5.096,1.805,0.039,,0.261556,496.564,,26.1556,0.496564,,,,7.85398e-5
Test1,2-Recover,107.303,5.142,1.759,0.039,,0.254891,496.564,,25.4891,0.496564,,,,7.85398e-5
Test1,2-Recover,107.637,5.189,1.712,0.039,,0.24808,496.564,,24.808,0.496564,,,,7.85398e-5
Test1,2-Recover,107.970,5.235,1.666,0.039,,0.241414,496.564,,24.1414,0.496564,,,,7.85398e-5
Test1,2-Recover,108.303,5.28,1.621,0.039,,0.234893,496.564,,23.4893,0.496564,,,,7.85398e-5
Test1,2-Recover,108.637,5.327,1.574,0.039,,0.228083,496.564,,22.8083,0.496564,,,,7.85398e-5
Test1,2-Recover,108.970,5.373,1.528,0.039,,0.221417,496.564,,22.1417,0.496564,,,,7.85398e-5
Test1,2-Recover,109.303,5.418,1.483,0.032,,0.214896,407.437,,21.4896,0.407437,,,,7.85398e-5
Test1,2-Recover,109.637,5.465,1.436,0.032,,0.208086,407.437,,20.8086,0.407437,,,,7.85398e-5
Test1,2-Recover,109.970,5.511,1.39,0.039,,0.20142,496.564,,20.142,0.496564,,,,7.85398e-5
Test1,2-Recover,110.303,5.557,1.344,0.046,,0.194754,585.69,,19.4754,0.58569,,,,7.85398e-5
Test1,2-Recover,110.637,5.604,1.297,0.046,,0.187944,585.69,,18.7944,0.58569,,,,7.85398e-5
Test1,2-Recover,110.970,5.649,1.252,0.032,,0.181423,407.437,,18.1423,0.407437,,,,7.85398e-5
Test1,2-Recover,111.303,5.695,1.206,0.032,,0.174757,407.437,,17.4757,0.407437,,,,7.85398e-5
Test1,2-Recover,111.637,5.742,1.159,0.039,,0.167947,496.564,,16.7947,0.496564,,,,7.85398e-5
Test1,2-Recover,111.970,5.788,1.113,0.039,,0.161281,496.564,,16.1281,0.496564,,,,7.85398e-5
Test1,2-Recover,112.303,5.833,1.068,0.039,,0.15476,496.564,,15.476,0.496564,,,,7.85398e-5
Test1,2-Recover,112.637,5.88,1.021,0.039,,0.14795,496.564,,14.795,0.496564,,,,7.85398e-5
Test1,2-Recover,112.970,5.926,0.975,0.039,,0.141284,496.564,,14.1284,0.496564,,,,7.85398e-5
Test1,2-Recover,113.303,5.971,0.93,0.039,,0.134763,496.564,,13.4763,0.496564,,,,7.85398e-5
Test1,2-Recover,113.637,6.019,0.882,0.032,,0.127808,407.437,,12.7808,0.407437,,,,7.85398e-5
Test1,2-Recover,113.970,6.064,0.837,0.032,,0.121287,407.437,,12.1287,0.407437,,,,7.85398e-5
Test1,2-Recover,114.303,6.11,0.791,0.039,,0.114621,496.564,,11.4621,0.496564,,,,7.85398e-5
Test1,2-Recover,114.637,6.157,0.744,0.032,,0.10781,407.437,,10.781,0.407437,,,,7.85398e-5
Test1,2-Recover,114.970,6.202,0.699,0.025,,0.10129,318.31,,10.129,0.31831,,,,7.85398e-5
Test1,2-Recover,115.303,6.248,0.653,0.025,,0.094624,318.31,,9.4624,0.31831,,,,7.85398e-5
Test1,2-Recover,115.637,6.295,0.606,0.039,,0.0878134,496.564,,8.78134,0.496564,,,,7.85398e-5
Test1,2-Recover,115.970,6.341,0.56,0.039,,0.0811477,496.564,,8.11477,0.496564,,,,7.85398e-5
Test1,2-Recover,116.303,6.386,0.515,0.039,,0.0746269,496.564,,7.46269,0.496564,,,,7.85398e-5
Test1,2-Recover,116.637,6.433,0.468,0.046,,0.0678163,585.69,,6.78163,0.58569,,,,7.85398e-5
Test1,2-Recover,116.970,6.479,0.422,0.039,,0.0611506,496.564,,6.11506,0.496564,,,,7.85398e-5
Test1,2-Recover,117.303,6.524,0.377,0.032,,0.0546298,407.437,,5.46298,0.407437,,,,7.85398e-5
Test1,2-Recover,117.637,6.572,0.329,0.025,,0.0476743,318.31,,4.76743,0.31831,,,,7.85398e-5
Test1,2-Recover,117.970,6.617,0.284,0.032,,0.0411535,407.437,,4.11535,0.407437,,,,7.85398e-5
Test1,2-Recover,118.303,6.663,0.238,0.039,,0.0344878,496.564,,3.44878,0.496564,,,,7.85398e-5
Test1,2-Recover,118.637,6.71,0.191,0.032,,0.0276771,407.437,,2.76771,0.407437,,,,7.85398e-5
Test1,2-Recover,118.970,6.755,0.146,0.025,,0.0211564,318.31,,2.11564,0.31831,,,,7.85398e-5
Test1,2-Recover,119.303,6.801,0.1,0.039,,0.0144907,496.564,,1.44907,0.496564,,,,7.85398e-5
Test1,2-Recover,119.637,6.848,0.053,0.032,,0.00768005,407.437,,0.768005,0.407437,,,,7.85398e-5
Test1,2-Recover,119.970,6.894,0.007,0.032,,0.00101435,407.437,,0.101435,0.407437,,,,7.85398e-5
Test1,3-Compress,120.290,6.874,0.027,0.046,,0.00391248,585.69,,0.391248,0.58569,,,,7.85398e-5
Test1,3-Compress,120.623,6.828,0.073,0.032,,0.0105782,407.437,,1.05782,0.407437,,,,7.85398e-5
Test1,3-Compress,120.957,6.781,0.12,0.039,,0.0173888,496.564,,1.73888,0.496564,,,,7.85398e-5
Test1,3-Compress,121.290,6.736,0.165,0.039,,0.0239096,496.564,,2.39096,0.496564,,,,7.85398e-5
Test1,3-Compress,121.623,6.69,0.211,0.039,,0.0305753,496.564,,3.05753,0.496564,,,,7.85398e-5
Test1,3-Compress,121.957,6.643,0.258,0.032,,0.0373859,407.437,,3.73859,0.407437,,,,7.85398e-5
Test1,3-Compress,122.290,6.597,0.304,0.039,,0.0440516,496.564,,4.40516,0.496564,,,,7.85398e-5
Test1,3-Compress,122.623,6.551,0.35,0.039,,0.0507173,496.564,,5.07173,0.496564,,,,7.85398e-5
Test1,3-Compress,122.957,6.505,0.396,0.039,,0.057383,496.564,,5.7383,0.496564,,,,7.85398e-5
Test1,3-Compress,123.290,6.459,0.442,0.039,,0.0640487,496.564,,6.40487,0.496564,,,,7.85398e-5
Test1,3-Compress,123.623,6.413,0.488,0.032,,0.0707144,407.437,,7.07144,0.407437,,,,7.85398e-5
Test1,3-Compress,123.957,6.366,0.535,0.039,,0.077525,496.564,,7.7525,0.496564,,,,7.85398e-5
Test1,3-Compress,124.290,6.32,0.581,0.039,,0.0841907,496.564,,8.41907,0.496564,,,,7.85398e-5
Test1,3-Compress,124.623,6.275,0.626,0.039,,0.0907115,496.564,,9.07115,0.496564,,,,7.85398e-5
Test1,3-Compress,124.957,6.228,0.673,0.039,,0.0975221,496.564,,9.75221,0.496564,,,,7.85398e-5
Test1,3-Compress,125.290,6.183,0.718,0.039,,0.104043,496.564,,10.4043,0.496564,,,,7.85398e-5
Test1,3-Compress,125.623,6.137,0.764,0.039,,0.110709,496.564,,11.0709,0.496564,,,,7.85398e-5
Test1,3-Compress,125.957,6.09,0.811,0.046,,0.117519,585.69,,11.7519,0.58569,,,,7.85398e-5
Test1,3-Compress,126.290,6.044,0.857,0.046,,0.124185,585.69,,12.4185,0.58569,,,,7.85398e-5
Test1,3-Compress,126.623,5.998,0.903,0.046,,0.130851,585.69,,13.0851,0.58569,,,,7.85398e-5
Test1,3-Compress,126.957,5.952,0.949,0.039,,0.137516,496.564,,13.7516,0.496564,,,,7.85398e-5
Test1,3-Compress,127.290,5.906,0.995,0.046,,0.144182,585.69,,14.4182,0.58569,,,,7.85398e-5
Test1,3-Compress,127.623,5.86,1.041,0.046,,0.150848,585.69,,15.0848,0.58569,,,,7.85398e-5
Test1,3-Compress,127.957,5.813,1.088,0.046,,0.157658,585.69,,15.7658,0.58569,,,,7.85398e-5
Test1,3-Compress,128.290,5.767,1.134,0.039,,0.164324,496.564,,16.4324,0.496564,,,,7.85398e-5
Test1,3-Compress,128.623,5.722,1.179,0.046,,0.170845,585.69,,17.0845,0.58569,,,,7.85398e-5
Test1,3-Compress,128.957,5.675,1.226,0.039,,0.177655,496.564,,17.7655,0.496564,,,,7.85398e-5
Test1,3-Compress,129.290,5.629,1.272,0.039,,0.184321,496.564,,18.4321,0.496564,,,,7.85398e-5
Test1,3-Compress,129.623,5.584,1.317,0.039,,0.190842,496.564,,19.0842,0.496564,,,,7.85398e-5
Test1,3-Compress,129.957,5.537,1.364,0.039,,0.197653,496.564,,19.7653,0.496564,,,,7.85398e-5
Test1,3-Compress,130.290,5.491,1.41,0.039,,0.204318,496.564,,20.4318,0.496564,,,,7.85398e-5
Test1,3-Compress,130.623,5.445,1.456,0.039,,0.210984,496.564,,21.0984,0.496564,,,,7.85398e-5
Test1,3-Compress,130.957,5.398,1.503,0.039,,0.217795,496.564,,21.7795,0.496564,,,,7.85398e-5
Test1,3-Compress,131.290,5.353,1.548,0.039,,0.224315,496.564,,22.4315,0.496564,,,,7.85398e-5
Test1,3-Compress,131.623,5.307,1.594,0.039,,0.230981,496.564,,23.0981,0.496564,,,,7.85398e-5
Test1,3-Compress,131.957,5.26,1.641,0.039,,0.237792,496.564,,23.7792,0.496564,,,,7.85398e-5
Test1,3-Compress,132.290,5.214,1.687,0.039,,0.244457,496.564,,24.4457,0.496564,,,,7.85398e-5
Test1,3-Compress,132.623,5.169,1.732,0.039,,0.250978,496.564,,25.0978,0.496564,,,,7.85398e-5
Test1,3-Compress,132.957,5.122,1.779,0.039,,0.257789,496.564,,25.7789,0.496564,,,,7.85398e-5
Test1,3-Compress,133.290,5.076,1.825,0.039,,0.264454,496.564,,26.4454,0.496564,,,,7.85398e-5
Test1,3-Compress,133.623,5.031,1.87,0.046,,0.270975,585.69,,27.0975,0.58569,,,,7.85398e-5
Test1,3-Compress,133.957,4.984,1.917,0.046,,0.277786,585.69,,27.7786,0.58569,,,,7.85398e-5
Test1,3-Compress,134.290,4.938,1.963,0.046,,0.284452,585.69,,28.4452,0.58569,,,,7.85398e-5
Test1,3-Compress,134.623,4.892,2.009,0.046,,0.291117,585.69,,29.1117,0.58569,,,,7.85398e-5
Test1,3-Compress,134.957,4.845,2.056,0.046,,0.297928,585.69,,29.7928,0.58569,,,,7.85398e-5
Test1,3-Compress,135.290,4.8,2.101,0.046,,0.304449,585.69,,30.4449,0.58569,,,,7.85398e-5
Test1,3-Compress,135.623,4.754,2.147,0.046,,0.311114,585.69,,31.1114,0.58569,,,,7.85398e-5
Test1,3-Compress,135.957,4.707,2.194,0.053,,0.317925,674.817,,31.7925,0.674817,,,,7.85398e-5
Test1,3-Compress,136.290,4.662,2.239,0.053,,0.324446,674.817,,32.4446,0.674817,,,,7.85398e-5
Test1,3-Compress,136.623,4.616,2.285,0.053,,0.331111,674.817,,33.1111,0.674817,,,,7.85398e-5
Test1,3-Compress,136.957,4.569,2.332,0.039,,0.337922,496.564,,33.7922,0.496564,,,,7.85398e-5
Test1,3-Compress,137.290,4.523,2.378,0.046,,0.344588,585.69,,34.4588,0.58569,,,,7.85398e-5
Test1,3-Compress,137.623,4.478,2.423,0.039,,0.351109,496.564,,35.1109,0.496564,,,,7.85398e-5
Test1,3-Compress,137.957,4.431,2.47,0.039,,0.357919,496.564,,35.7919,0.496564,,,,7.85398e-5
Test1,3-Compress,138.290,4.385,2.516,0.039,,0.364585,496.564,,36.4585,0.496564,,,,7.85398e-5
Test1,3-Compress,138.623,4.339,2.562,0.039,,0.371251,496.564,,37.1251,0.496564,,,,7.85398e-5
Test1,3-Compress,138.957,4.292,2.609,0.039,,0.378061,496.564,,37.8061,0.496564,,,,7.85398e-5
Test1,3-Compress,139.290,4.247,2.654,0.039,,0.384582,496.564,,38.4582,0.496564,,,,7.85398e-5
Test1,3-Compress,139.623,4.201,2.7,0.039,,0.391248,496.564,,39.1248,0.496564,,,,7.85398e-5
Test1,3-Compress,139.957,4.154,2.747,0.039,,0.398058,496.564,,39.8058,0.496564,,,,7.85398e-5
Test1,3-Compress,140.290,4.109,2.792,0.039,,0.404579,496.564,,40.4579,0.496564,,,,7.85398e-5
Test1,3-Compress,140.623,4.063,2.838,0.039,,0.411245,496.564,,41.1245,0.496564,,,,7.85398e-5
Test1,3-Compress,140.957,4.016,2.885,0.039,,0.418055,496.564,,41.8055,0.496564,,,,7.85398e-5
Test1,3-Compress,141.290,3.97,2.931,0.039,,0.424721,496.564,,42.4721,0.496564,,,,7.85398e-5
Test1,3-Compress,141.623,3.925,2.976,0.046,,0.431242,585.69,,43.1242,0.58569,,,,7.85398e-5
Test1,3-Compress,141.957,3.878,3.023,0.046,,0.438052,585.69,,43.8052,0.58569,,,,7.85398e-5
Test1,3-Compress,142.290,3.832,3.069,0.046,,0.444718,585.69,,44.4718,0.58569,,,,7.85398e-5
Test1,3-Compress,142.623,3.786,3.115,0.046,,0.451384,585.69,,45.1384,0.58569,,,,7.85398e-5
Test1,3-Compress,142.957,3.739,3.162,0.046,,0.458194,585.69,,45.8194,0.58569,,,,7.85398e-5
Test1,3-Compress,143.290,3.694,3.207,0.053,,0.464715,674.817,,46.4715,0.674817,,,,7.85398e-5
Test1,3-Compress,143.623,3.648,3.253,0.053,,0.471381,674.817,,47.1381,0.674817,,,,7.85398e-5
Test1,3-Compress,143.957,3.601,3.3,0.053,,0.478192,674.817,,47.8192,0.674817,,,,7.85398e-5
Test1,3-Compress,144.290,3.555,3.346,0.053,,0.484857,674.817,,48.4857,0.674817,,,,7.85398e-5
Test1,3-Compress,144.623,3.51,3.391,0.053,,0.491378,674.817,,49.1378,0.674817,,,,7.85398e-5
Test1,3-Compress,144.957,3.463,3.438,0.046,,0.498189,585.69,,49.8189,0.58569,,,,7.85398e-5
Test1,3-Compress,145.290,3.417,3.484,0.053,,0.504854,674.817,,50.4854,0.674817,,,,7.85398e-5
Test1,3-Compress,145.623,3.372,3.529,0.039,,0.511375,496.564,,51.1375,0.496564,,,,7.85398e-5
Test1,3-Compress,145.957,3.325,3.576,0.046,,0.518186,585.69,,51.8186,0.58569,,,,7.85398e-5
Test1,3-Compress,146.290,3.279,3.622,0.053,,0.524851,674.817,,52.4851,0.674817,,,,7.85398e-5
Test1,3-Compress,146.623,3.233,3.668,0.059,,0.531517,751.211,,53.1517,0.751211,,,,7.85398e-5
Test1,3-Compress,146.957,3.186,3.715,0.053,,0.538328,674.817,,53.8328,0.674817,,,,7.85398e-5
Test1,3-Compress,147.290,3.141,3.76,0.059,,0.544849,751.211,,54.4849,0.751211,,,,7.85398e-5
Test1,3-Compress,147.623,3.095,3.806,0.059,,0.551514,751.211,,55.1514,0.751211,,,,7.85398e-5
Test1,3-Compress,147.957,3.048,3.853,0.059,,0.558325,751.211,,55.8325,0.751211,,,,7.85398e-5
Test1,3-Compress,148.290,3.002,3.899,0.053,,0.564991,674.817,,56.4991,0.674817,,,,7.85398e-5
Test1,3-Compress,148.623,2.957,3.944,0.066,,0.571511,840.338,,57.1511,0.840338,,,,7.85398e-5
Test1,3-Compress,148.957,2.91,3.991,0.087,,0.578322,1107.72,,57.8322,1.10772,,,,7.85398e-5
Test1,3-Compress,149.290,2.864,4.037,0.080,,0.584988,1018.59,,58.4988,1.01859,,,,7.85398e-5
Test1,3-Compress,149.623,2.819,4.082,0.087,,0.591508,1107.72,,59.1508,1.10772,,,,7.85398e-5
Test1,3-Compress,149.957,2.772,4.129,0.093,,0.598319,1184.11,,59.8319,1.18411,,,,7.85398e-5
Test1,3-Recover,150.267,2.782,4.119,0.066,,0.59687,840.338,,59.687,0.840338,,,,7.85398e-5
Test1,3-Recover,150.600,2.828,4.073,0.066,,0.590204,840.338,,59.0204,0.840338,,,,7.85398e-5
Test1,3-Recover,150.933,2.873,4.028,0.053,,0.583684,674.817,,58.3684,0.674817,,,,7.85398e-5
Test1,3-Recover,151.267,2.92,3.981,0.059,,0.576873,751.211,,57.6873,0.751211,,,,7.85398e-5
Test1,3-Recover,151.600,2.966,3.935,0.046,,0.570207,585.69,,57.0207,0.58569,,,,7.85398e-5
Test1,3-Recover,151.933,3.011,3.89,0.053,,0.563686,674.817,,56.3686,0.674817,,,,7.85398e-5
Test1,3-Recover,152.267,3.058,3.843,0.053,,0.556876,674.817,,55.6876,0.674817,,,,7.85398e-5
Test1,3-Recover,152.600,3.104,3.797,0.059,,0.55021,751.211,,55.021,0.751211,,,,7.85398e-5
Test1,3-Recover,152.933,3.15,3.751,0.053,,0.543544,674.817,,54.3544,0.674817,,,,7.85398e-5
Test1,3-Recover,153.267,3.197,3.704,0.053,,0.536734,674.817,,53.6734,0.674817,,,,7.85398e-5
Test1,3-Recover,153.600,3.242,3.659,0.046,,0.530213,585.69,,53.0213,0.58569,,,,7.85398e-5
Test1,3-Recover,153.933,3.288,3.613,0.053,,0.523547,674.817,,52.3547,0.674817,,,,7.85398e-5
Test1,3-Recover,154.267,3.335,3.566,0.046,,0.516737,585.69,,51.6737,0.58569,,,,7.85398e-5
Test1,3-Recover,154.600,3.381,3.52,0.046,,0.510071,585.69,,51.0071,0.58569,,,,7.85398e-5
Test1,3-Recover,154.933,3.426,3.475,0.039,,0.50355,496.564,,50.355,0.496564,,,,7.85398e-5
Test1,3-Recover,155.267,3.473,3.428,0.039,,0.49674,496.564,,49.674,0.496564,,,,7.85398e-5
Test1,3-Recover,155.600,3.519,3.382,0.039,,0.490074,496.564,,49.0074,0.496564,,,,7.85398e-5
Test1,3-Recover,155.933,3.564,3.337,0.039,,0.483553,496.564,,48.3553,0.496564,,,,7.85398e-5
Test1,3-Recover,156.267,3.612,3.289,0.039,,0.476598,496.564,,47.6598,0.496564,,,,7.85398e-5
Test1,3-Recover,156.600,3.657,3.244,0.039,,0.470077,496.564,,47.0077,0.496564,,,,7.85398e-5
Test1,3-Recover,156.933,3.703,3.198,0.039,,0.463411,496.564,,46.3411,0.496564,,,,7.85398e-5
Test1,3-Recover,157.267,3.75,3.151,0.039,,0.4566,496.564,,45.66,0.496564,,,,7.85398e-5
Test1,3-Recover,157.600,3.795,3.106,0.039,,0.45008,496.564,,45.008,0.496564,,,,7.85398e-5
Test1,3-Recover,157.933,3.841,3.06,0.039,,0.443414,496.564,,44.3414,0.496564,,,,7.85398e-5
Test1,3-Recover,158.267,3.888,3.013,0.046,,0.436603,585.69,,43.6603,0.58569,,,,7.85398e-5
Test1,3-Recover,158.600,3.934,2.967,0.046,,0.429938,585.69,,42.9938,0.58569,,,,7.85398e-5
Test1,3-Recover,158.933,3.979,2.922,0.046,,0.423417,585.69,,42.3417,0.58569,,,,7.85398e-5
Test1,3-Recover,159.267,4.026,2.875,0.046,,0.416606,585.69,,41.6606,0.58569,,,,7.85398e-5
Test1,3-Recover,159.600,4.072,2.829,0.046,,0.409941,585.69,,40.9941,0.58569,,,,7.85398e-5
Test1,3-Recover,159.933,4.117,2.784,0.046,,0.40342,585.69,,40.342,0.58569,,,,7.85398e-5
Test1,3-Recover,160.267,4.165,2.736,0.046,,0.396464,585.69,,39.6464,0.58569,,,,7.85398e-5
Test1,3-Recover,160.600,4.21,2.691,0.046,,0.389943,585.69,,38.9943,0.58569,,,,7.85398e-5
Test1,3-Recover,160.933,4.256,2.645,0.053,,0.383278,674.817,,38.3278,0.674817,,,,7.85398e-5
Test1,3-Recover,161.267,4.303,2.598,0.039,,0.376467,496.564,,37.6467,0.496564,,,,7.85398e-5
Test1,3-Recover,161.600,4.348,2.553,0.039,,0.369946,496.564,,36.9946,0.496564,,,,7.85398e-5
Test1,3-Recover,161.933,4.394,2.507,0.039,,0.363281,496.564,,36.3281,0.496564,,,,7.85398e-5
Test1,3-Recover,162.267,4.441,2.46,0.039,,0.35647,496.564,,35.647,0.496564,,,,7.85398e-5
Test1,3-Recover,162.600,4.487,2.414,0.039,,0.349804,496.564,,34.9804,0.496564,,,,7.85398e-5
Test1,3-Recover,162.933,4.533,2.368,0.039,,0.343139,496.564,,34.3139,0.496564,,,,7.85398e-5
Test1,3-Recover,163.267,4.579,2.322,0.039,,0.336473,496.564,,33.6473,0.496564,,,,7.85398e-5
Test1,3-Recover,163.600,4.625,2.276,0.039,,0.329807,496.564,,32.9807,0.496564,,,,7.85398e-5
Test1,3-Recover,163.933,4.67,2.231,0.039,,0.323286,496.564,,32.3286,0.496564,,,,7.85398e-5
Test1,3-Recover,164.267,4.718,2.183,0.039,,0.316331,496.564,,31.6331,0.496564,,,,7.85398e-5
Test1,3-Recover,164.600,4.763,2.138,0.039,,0.30981,496.564,,30.981,0.496564,,,,7.85398e-5
Test1,3-Recover,164.933,4.809,2.092,0.039,,0.303144,496.564,,30.3144,0.496564,,,,7.85398e-5
Test1,3-Recover,165.267,4.856,2.045,0.039,,0.296334,496.564,,29.6334,0.496564,,,,7.85398e-5
Test1,3-Recover,165.600,4.901,2,0.039,,0.289813,496.564,,28.9813,0.496564,,,,7.85398e-5
Test1,3-Recover,165.933,4.947,1.954,0.039,,0.283147,496.564,,28.3147,0.496564,,,,7.85398e-5
Test1,3-Recover,166.267,4.994,1.907,0.046,,0.276337,585.69,,27.6337,0.58569,,,,7.85398e-5
Test1,3-Recover,166.600,5.04,1.861,0.046,,0.269671,585.69,,26.9671,0.58569,,,,7.85398e-5
Test1,3-Recover,166.933,5.085,1.816,0.046,,0.26315,585.69,,26.315,0.58569,,,,7.85398e-5
Test1,3-Recover,167.267,5.132,1.769,0.046,,0.25634,585.69,,25.634,0.58569,,,,7.85398e-5
Test1,3-Recover,167.600,5.178,1.723,0.039,,0.249674,496.564,,24.9674,0.496564,,,,7.85398e-5
Test1,3-Recover,167.933,5.224,1.677,0.039,,0.243008,496.564,,24.3008,0.496564,,,,7.85398e-5
Test1,3-Recover,168.267,5.27,1.631,0.039,,0.236343,496.564,,23.6343,0.496564,,,,7.85398e-5
Test1,3-Recover,168.600,5.316,1.585,0.039,,0.229677,496.564,,22.9677,0.496564,,,,7.85398e-5
Test1,3-Recover,168.933,5.362,1.539,0.039,,0.223011,496.564,,22.3011,0.496564,,,,7.85398e-5
Test1,3-Recover,169.267,5.409,1.492,0.039,,0.216201,496.564,,21.6201,0.496564,,,,7.85398e-5
Test1,3-Recover,169.600,5.455,1.446,0.039,,0.209535,496.564,,20.9535,0.496564,,,,7.85398e-5
Test1,3-Recover,169.933,5.5,1.401,0.039,,0.203014,496.564,,20.3014,0.496564,,,,7.85398e-5
Test1,3-Recover,170.267,5.547,1.354,0.039,,0.196203,496.564,,19.6203,0.496564,,,,7.85398e-5
Test1,3-Recover,170.600,5.593,1.308,0.039,,0.189538,496.564,,18.9538,0.496564,,,,7.85398e-5
Test1,3-Recover,170.933,5.638,1.263,0.039,,0.183017,496.564,,18.3017,0.496564,,,,7.85398e-5
Test1,3-Recover,171.267,5.686,1.215,0.039,,0.176061,496.564,,17.6061,0.496564,,,,7.85398e-5
Test1,3-Recover,171.600,5.731,1.17,0.039,,0.169541,496.564,,16.9541,0.496564,,,,7.85398e-5
Test1,3-Recover,171.933,5.777,1.124,0.039,,0.162875,496.564,,16.2875,0.496564,,,,7.85398e-5
Test1,3-Recover,172.267,5.824,1.077,0.039,,0.156064,496.564,,15.6064,0.496564,,,,7.85398e-5
Test1,3-Recover,172.600,5.869,1.032,0.039,,0.149544,496.564,,14.9544,0.496564,,,,7.85398e-5
Test1,3-Recover,172.933,5.915,0.986,0.025,,0.142878,318.31,,14.2878,0.31831,,,,7.85398e-5
Test1,3-Recover,173.267,5.962,0.939,0.032,,0.136067,407.437,,13.6067,0.407437,,,,7.85398e-5
Test1,3-Recover,173.600,6.008,0.893,0.032,,0.129402,407.437,,12.9402,0.407437,,,,7.85398e-5
Test1,3-Recover,173.933,6.053,0.848,0.032,,0.122881,407.437,,12.2881,0.407437,,,,7.85398e-5
Test1,3-Recover,174.267,6.1,0.801,0.039,,0.11607,496.564,,11.607,0.496564,,,,7.85398e-5
Test1,3-Recover,174.600,6.146,0.755,0.032,,0.109404,407.437,,10.9404,0.407437,,,,7.85398e-5
Test1,3-Recover,174.933,6.191,0.71,0.032,,0.102884,407.437,,10.2884,0.407437,,,,7.85398e-5
Test1,3-Recover,175.267,6.239,0.662,0.039,,0.0959281,496.564,,9.59281,0.496564,,,,7.85398e-5
Test1,3-Recover,175.600,6.284,0.617,0.039,,0.0894073,496.564,,8.94073,0.496564,,,,7.85398e-5
Test1,3-Recover,175.933,6.33,0.571,0.039,,0.0827416,496.564,,8.27416,0.496564,,,,7.85398e-5
Test1,3-Recover,176.267,6.377,0.524,0.032,,0.075931,407.437,,7.5931,0.407437,,,,7.85398e-5
Test1,3-Recover,176.600,6.422,0.479,0.032,,0.0694102,407.437,,6.94102,0.407437,,,,7.85398e-5
Test1,3-Recover,176.933,6.468,0.433,0.039,,0.0627445,496.564,,6.27445,0.496564,,,,7.85398e-5
Test1,3-Recover,177.267,6.515,0.386,0.039,,0.0559339,496.564,,5.59339,0.496564,,,,7.85398e-5
Test1,3-Recover,177.600,6.561,0.34,0.039,,0.0492682,496.564,,4.92682,0.496564,,,,7.85398e-5
Test1,3-Recover,177.933,6.606,0.295,0.039,,0.0427474,496.564,,4.27474,0.496564,,,,7.85398e-5
Test1,3-Recover,178.267,6.653,0.248,0.032,,0.0359368,407.437,,3.59368,0.407437,,,,7.85398e-5
Test1,3-Recover,178.600,6.699,0.202,0.032,,0.0292711,407.437,,2.92711,0.407437,,,,7.85398e-5
Test1,3-Recover,178.933,6.745,0.156,0.039,,0.0226054,496.564,,2.26054,0.496564,,,,7.85398e-5
Test1,3-Recover,179.267,6.792,0.109,0.039,,0.0157948,496.564,,1.57948,0.496564,,,,7.85398e-5
Test1,3-Recover,179.600,6.837,0.064,0.039,,0.00927402,496.564,,0.927402,0.496564,,,,7.85398e-5
Test1,3-Recover,179.933,6.883,0.018,0.039,,0.00260832,496.564,,0.260832,0.496564,,,,7.85398e-5
Test1,3-Recover,180.100,6.901,-0,0.039,,0,496.564,,0,0.496564,,,,7.85398e-5