File: data/gamma_1-0_2.csv
SetName,Cycle,Time_S,Size_mm,Displacement_mm,Force_N,,Strain,Stress(Pascal),,%Strain,Stress(kPa),,,,Area(m^2)
Test1,1-Compress,0.000,2.689,-0,0.027,,0,343.775,,0,0.343775,,,,7.85398e-5
Test1,1-Compress,0.333,2.672,0.017,0.027,,0.00632205,343.775,,0.632205,0.343775,,,,7.85398e-5
Test1,1-Compress,0.667,2.653,0.036,0.027,,0.0133879,343.775,,1.33879,0.343775,,,,7.85398e-5
Test1,1-Compress,1.000,2.635,0.054,0.027,,0.0200818,343.775,,2.00818,0.343775,,,,7.85398e-5
Test1,1-Compress,1.333,2.618,0.071,0.027,,0.0264039,343.775,,2.64039,0.343775,,,,7.85398e-5
Test1,1-Compress,1.667,2.599,0.09,0.027,,0.0334697,343.775,,3.34697,0.343775,,,,7.85398e-5
Test1,1-Compress,2.000,2.582,0.107,0.027,,0.0397917,343.775,,3.97917,0.343775,,,,7.85398e-5
Test1,1-Compress,2.333,2.564,0.125,0.027,,0.0464857,343.775,,4.64857,0.343775,,,,7.85398e-5
Test1,1-Compress,2.667,2.546,0.143,0.027,,0.0531796,343.775,,5.31796,0.343775,,,,7.85398e-5
Test1,1-Compress,3.000,2.528,0.161,0.027,,0.0598736,343.775,,5.98736,0.343775,,,,7.85398e-5
Test1,1-Compress,3.333,2.51,0.179,0.027,,0.0665675,343.775,,6.65675,0.343775,,,,7.85398e-5
Test1,1-Compress,3.667,2.492,0.197,0.027,,0.0732614,343.775,,7.32614,0.343775,,,,7.85398e-5
Test1,1-Compress,4.000,2.474,0.215,0.027,,0.0799554,343.775,,7.99554,0.343775,,,,7.85398e-5
Test1,1-Compress,4.333,2.456,0.233,0.027,,0.0866493,343.775,,8.66493,0.343775,,,,7.85398e-5
Test1,1-Compress,4.667,2.438,0.251,0.034,,0.0933433,432.902,,9.33433,0.432902,,,,7.85398e-5
Test1,1-Compress,5.000,2.42,0.269,0.034,,0.100037,432.902,,10.0037,0.432902,,,,7.85398e-5
Test1,1-Compress,5.333,2.402,0.287,0.027,,0.106731,343.775,,10.6731,0.343775,,,,7.85398e-5
Test1,1-Compress,5.667,2.384,0.305,0.027,,0.113425,343.775,,11.3425,0.343775,,,,7.85398e-5
Test1,1-Compress,6.000,2.366,0.323,0.041,,0.120119,522.028,,12.0119,0.522028,,,,7.85398e-5
Test1,1-Compress,6.333,2.348,0.341,0.027,,0.126813,343.775,,12.6813,0.343775,,,,7.85398e-5
Test1,1-Compress,6.667,2.33,0.359,0.041,,0.133507,522.028,,13.3507,0.522028,,,,7.85398e-5
Test1,1-Compress,7.000,2.313,0.376,0.027,,0.139829,343.775,,13.9829,0.343775,,,,7.85398e-5
Test1,1-Compress,7.333,2.295,0.394,0.041,,0.146523,522.028,,14.6523,0.522028,,,,7.85398e-5
Test1,1-Compress,7.667,2.276,0.413,0.034,,0.153589,432.902,,15.3589,0.432902,,,,7.85398e-5
Test1,1-Compress,8.000,2.259,0.43,0.048,,0.159911,611.155,,15.9911,0.611155,,,,7.85398e-5
Test1,1-Compress,8.333,2.241,0.448,0.048,,0.166605,611.155,,16.6605,0.611155,,,,7.85398e-5
Test1,1-Compress,8.667,2.223,0.466,0.048,,0.173299,611.155,,17.3299,0.611155,,,,7.85398e-5
Test1,1-Compress,9.000,2.205,0.484,0.041,,0.179993,522.028,,17.9993,0.522028,,,,7.85398e-5
Test1,1-Compress,9.333,2.187,0.502,0.041,,0.186687,522.028,,18.6687,0.522028,,,,7.85398e-5
Test1,1-Compress,9.667,2.169,0.52,0.048,,0.19338,611.155,,19.338,0.611155,,,,7.85398e-5
Test1,1-Compress,10.000,2.151,0.538,0.054,,0.200074,687.549,,20.0074,0.687549,,,,7.85398e-5
Test1,1-Compress,10.333,2.133,0.556,0.048,,0.206768,611.155,,20.6768,0.611155,,,,7.85398e-5
Test1,1-Compress,10.667,2.115,0.574,0.054,,0.213462,687.549,,21.3462,0.687549,,,,7.85398e-5
Test1,1-Compress,11.000,2.097,0.592,0.041,,0.220156,522.028,,22.0156,0.522028,,,,7.85398e-5
Test1,1-Compress,11.333,2.079,0.61,0.068,,0.22685,865.803,,22.685,0.865803,,,,7.85398e-5
Test1,1-Compress,11.667,2.061,0.628,0.048,,0.233544,611.155,,23.3544,0.611155,,,,7.85398e-5
Test1,1-Compress,12.000,2.043,0.646,0.048,,0.240238,611.155,,24.0238,0.611155,,,,7.85398e-5
Test1,1-Compress,12.333,2.026,0.663,0.061,,0.24656,776.676,,24.656,0.776676,,,,7.85398e-5
Test1,1-Compress,12.667,2.007,0.682,0.054,,0.253626,687.549,,25.3626,0.687549,,,,7.85398e-5
Test1,1-Compress,13.000,1.989,0.7,0.061,,0.26032,776.676,,26.032,0.776676,,,,7.85398e-5
Test1,1-Compress,13.333,1.971,0.718,0.068,,0.267014,865.803,,26.7014,0.865803,,,,7.85398e-5
Test1,1-Compress,13.667,1.954,0.735,0.075,,0.273336,954.93,,27.3336,0.95493,,,,7.85398e-5
Test1,1-Compress,14.000,1.936,0.753,0.082,,0.28003,1044.06,,28.003,1.04406,,,,7.85398e-5
Test1,1-Compress,14.333,1.918,0.771,0.082,,0.286724,1044.06,,28.6724,1.04406,,,,7.85398e-5
Test1,1-Compress,14.667,1.899,0.79,0.082,,0.29379,1044.06,,29.379,1.04406,,,,7.85398e-5
Test1,1-Compress,15.000,1.882,0.807,0.082,,0.300112,1044.06,,30.0112,1.04406,,,,7.85398e-5
Test1,1-Compress,15.333,1.864,0.825,0.082,,0.306806,1044.06,,30.6806,1.04406,,,,7.85398e-5
Test1,1-Compress,15.667,1.846,0.843,0.082,,0.313499,1044.06,,31.3499,1.04406,,,,7.85398e-5
Test1,1-Compress,16.000,1.828,0.861,0.082,,0.320193,1044.06,,32.0193,1.04406,,,,7.85398e-5
Test1,1-Compress,16.333,1.81,0.879,0.082,,0.326887,1044.06,,32.6887,1.04406,,,,7.85398e-5
Test1,1-Compress,16.667,1.792,0.897,0.082,,0.333581,1044.06,,33.3581,1.04406,,,,7.85398e-5
Test1,1-Compress,17.000,1.774,0.915,0.082,,0.340275,1044.06,,34.0275,1.04406,,,,7.85398e-5
Test1,1-Compress,17.333,1.756,0.933,0.082,,0.346969,1044.06,,34.6969,1.04406,,,,7.85398e-5
Test1,1-Compress,17.667,1.738,0.951,0.082,,0.353663,1044.06,,35.3663,1.04406,,,,7.85398e-5
Test1,1-Compress,18.000,1.72,0.969,0.082,,0.360357,1044.06,,36.0357,1.04406,,,,7.85398e-5
Test1,1-Compress,18.333,1.702,0.987,0.082,,0.367051,1044.06,,36.7051,1.04406,,,,7.85398e-5
Test1,1-Compress,18.667,1.684,1.005,0.082,,0.373745,1044.06,,37.3745,1.04406,,,,7.85398e-5
Test1,1-Compress,19.000,1.667,1.022,0.082,,0.380067,1044.06,,38.0067,1.04406,,,,7.85398e-5
Test1,1-Compress,19.333,1.649,1.04,0.082,,0.386761,1044.06,,38.6761,1.04406,,,,7.85398e-5
Test1,1-Compress,19.667,1.63,1.059,0.082,,0.393827,1044.06,,39.3827,1.04406,,,,7.85398e-5
Test1,1-Compress,20.000,1.612,1.077,0.082,,0.400521,1044.06,,40.0521,1.04406,,,,7.85398e-5
Test1,1-Compress,20.333,1.595,1.094,0.082,,0.406843,1044.06,,40.6843,1.04406,,,,7.85398e-5
Test1,1-Compress,20.667,1.577,1.112,0.082,,0.413537,1044.06,,41.3537,1.04406,,,,7.85398e-5
Test1,1-Compress,21.000,1.559,1.13,0.082,,0.420231,1044.06,,42.0231,1.04406,,,,7.85398e-5
Test1,1-Compress,21.333,1.541,1.148,0.082,,0.426925,1044.06,,42.6925,1.04406,,,,7.85398e-5
Test1,1-Compress,21.667,1.523,1.166,0.095,,0.433618,1209.58,,43.3618,1.20958,,,,7.85398e-5
Test1,1-Compress,22.000,1.505,1.184,0.102,,0.440312,1298.7,,44.0312,1.2987,,,,7.85398e-5
Test1,1-Compress,22.333,1.487,1.202,0.095,,0.447006,1209.58,,44.7006,1.20958,,,,7.85398e-5
Test1,1-Compress,22.667,1.469,1.22,0.109,,0.4537,1387.83,,45.37,1.38783,,,,7.85398e-5
Test1,1-Compress,23.000,1.451,1.238,0.116,,0.460394,1476.96,,46.0394,1.47696,,,,7.85398e-5
Test1,1-Compress,23.333,1.434,1.255,0.116,,0.466716,1476.96,,46.6716,1.47696,,,,7.85398e-5
Test1,1-Compress,23.667,1.415,1.274,0.109,,0.473782,1387.83,,47.3782,1.38783,,,,7.85398e-5
Test1,1-Compress,24.000,1.397,1.292,0.109,,0.480476,1387.83,,48.0476,1.38783,,,,7.85398e-5
Test1,1-Compress,24.333,1.379,1.31,0.129,,0.48717,1642.48,,48.717,1.64248,,,,7.85398e-5
Test1,1-Compress,24.667,1.361,1.328,0.122,,0.493864,1553.35,,49.3864,1.55335,,,,7.85398e-5
Test1,1-Compress,25.000,1.343,1.346,0.129,,0.500558,1642.48,,50.0558,1.64248,,,,7.85398e-5
Test1,1-Compress,25.333,1.326,1.363,0.116,,0.50688,1476.96,,50.688,1.47696,,,,7.85398e-5
Test1,1-Compress,25.667,1.307,1.382,0.122,,0.513946,1553.35,,51.3946,1.55335,,,,7.85398e-5
Test1,1-Compress,26.000,1.29,1.399,0.136,,0.520268,1731.61,,52.0268,1.73161,,,,7.85398e-5
Test1,1-Compress,26.333,1.272,1.417,0.136,,0.526962,1731.61,,52.6962,1.73161,,,,7.85398e-5
Test1,1-Compress,26.667,1.253,1.436,0.136,,0.534028,1731.61,,53.4028,1.73161,,,,7.85398e-5
Test1,1-Compress,27.000,1.236,1.453,0.136,,0.54035,1731.61,,54.035,1.73161,,,,7.85398e-5
Test1,1-Compress,27.333,1.218,1.471,0.136,,0.547044,1731.61,,54.7044,1.73161,,,,7.85398e-5
Test1,1-Compress,27.667,1.2,1.489,0.136,,0.553737,1731.61,,55.3737,1.73161,,,,7.85398e-5
Test1,1-Compress,28.000,1.182,1.507,0.136,,0.560431,1731.61,,56.0431,1.73161,,,,7.85398e-5
Test1,1-Compress,28.333,1.164,1.525,0.136,,0.567125,1731.61,,56.7125,1.73161,,,,7.85398e-5
Test1,1-Compress,28.667,1.146,1.543,0.136,,0.573819,1731.61,,57.3819,1.73161,,,,7.85398e-5
Test1,1-Compress,29.000,1.128,1.561,0.136,,0.580513,1731.61,,58.0513,1.73161,,,,7.85398e-5
Test1,1-Compress,29.333,1.11,1.579,0.136,,0.587207,1731.61,,58.7207,1.73161,,,,7.85398e-5
Test1,1-Compress,29.667,1.092,1.597,0.129,,0.593901,1642.48,,59.3901,1.64248,,,,7.85398e-5
Test1,1-Compress,30.000,1.076,1.613,0.136,,0.599851,1731.61,,59.9851,1.73161,,,,7.85398e-5
Test1,1-Recover,30.333,1.093,1.596,0.129,,0.593529,1642.48,,59.3529,1.64248,,,,7.85398e-5
Test1,1-Recover,30.667,1.111,1.578,0.136,,0.586835,1731.61,,58.6835,1.73161,,,,7.85398e-5
Test1,1-Recover,31.000,1.129,1.56,0.136,,0.580141,1731.61,,58.0141,1.73161,,,,7.85398e-5
Test1,1-Recover,31.333,1.147,1.542,0.136,,0.573447,1731.61,,57.3447,1.73161,,,,7.85398e-5
Test1,1-Recover,31.667,1.165,1.524,0.136,,0.566753,1731.61,,56.6753,1.73161,,,,7.85398e-5
Test1,1-Recover,32.000,1.183,1.506,0.136,,0.56006,1731.61,,56.006,1.73161,,,,7.85398e-5
Test1,1-Recover,32.333,1.201,1.488,0.136,,0.553366,1731.61,,55.3366,1.73161,,,,7.85398e-5
Test1,1-Recover,32.667,1.219,1.47,0.136,,0.546672,1731.61,,54.6672,1.73161,,,,7.85398e-5
Test1,1-Recover,33.000,1.237,1.452,0.129,,0.539978,1642.48,,53.9978,1.64248,,,,7.85398e-5
Test1,1-Recover,33.333,1.254,1.435,0.116,,0.533656,1476.96,,53.3656,1.47696,,,,7.85398e-5
Test1,1-Recover,33.667,1.273,1.416,0.102,,0.52659,1298.7,,52.659,1.2987,,,,7.85398e-5
Test1,1-Recover,34.000,1.291,1.398,0.102,,0.519896,1298.7,,51.9896,1.2987,,,,7.85398e-5
Test1,1-Recover,34.333,1.308,1.381,0.109,,0.513574,1387.83,,51.3574,1.38783,,,,7.85398e-5
Test1,1-Recover,34.667,1.327,1.362,0.095,,0.506508,1209.58,,50.6508,1.20958,,,,7.85398e-5
Test1,1-Recover,35.000,1.344,1.345,0.088,,0.500186,1120.45,,50.0186,1.12045,,,,7.85398e-5
Test1,1-Recover,35.333,1.362,1.327,0.082,,0.493492,1044.06,,49.3492,1.04406,,,,7.85398e-5
Test1,1-Recover,35.667,1.38,1.309,0.082,,0.486798,1044.06,,48.6798,1.04406,,,,7.85398e-5
Test1,1-Recover,36.000,1.398,1.291,0.082,,0.480104,1044.06,,48.0104,1.04406,,,,7.85398e-5
Test1,1-Recover,36.333,1.416,1.273,0.082,,0.47341,1044.06,,47.341,1.04406,,,,7.85398e-5
Test1,1-Recover,36.667,1.435,1.254,0.082,,0.466344,1044.06,,46.6344,1.04406,,,,7.85398e-5
Test1,1-Recover,37.000,1.452,1.237,0.082,,0.460022,1044.06,,46.0022,1.04406,,,,7.85398e-5
Test1,1-Recover,37.333,1.47,1.219,0.082,,0.453328,1044.06,,45.3328,1.04406,,,,7.85398e-5
Test1,1-Recover,37.667,1.488,1.201,0.082,,0.446634,1044.06,,44.6634,1.04406,,,,7.85398e-5
Test1,1-Recover,38.000,1.506,1.183,0.082,,0.43994,1044.06,,43.994,1.04406,,,,7.85398e-5
Test1,1-Recover,38.333,1.524,1.165,0.082,,0.433247,1044.06,,43.3247,1.04406,,,,7.85398e-5
Test1,1-Recover,38.667,1.542,1.147,0.082,,0.426553,1044.06,,42.6553,1.04406,,,,7.85398e-5
Test1,1-Recover,39.000,1.56,1.129,0.082,,0.419859,1044.06,,41.9859,1.04406,,,,7.85398e-5
Test1,1-Recover,39.333,1.578,1.111,0.082,,0.413165,1044.06,,41.3165,1.04406,,,,7.85398e-5
Test1,1-Recover,39.667,1.596,1.093,0.082,,0.406471,1044.06,,40.6471,1.04406,,,,7.85398e-5
Test1,1-Recover,40.000,1.613,1.076,0.082,,0.400149,1044.06,,40.0149,1.04406,,,,7.85398e-5
Test1,1-Recover,40.333,1.631,1.058,0.082,,0.393455,1044.06,,39.3455,1.04406,,,,7.85398e-5
Test1,1-Recover,40.667,1.65,1.039,0.075,,0.386389,954.93,,38.6389,0.95493,,,,7.85398e-5
Test1,1-Recover,41.000,1.667,1.022,0.082,,0.380067,1044.06,,38.0067,1.04406,,,,7.85398e-5
Test1,1-Recover,41.333,1.685,1.004,0.075,,0.373373,954.93,,37.3373,0.95493,,,,7.85398e-5
Test1,1-Recover,41.667,1.704,0.985,0.054,,0.366307,687.549,,36.6307,0.687549,,,,7.85398e-5
Test1,1-Recover,42.000,1.721,0.968,0.041,,0.359985,522.028,,35.9985,0.522028,,,,7.85398e-5
Test1,1-Recover,42.333,1.739,0.95,0.048,,0.353291,611.155,,35.3291,0.611155,,,,7.85398e-5
Test1,1-Recover,42.667,1.757,0.932,0.041,,0.346597,522.028,,34.6597,0.522028,,,,7.85398e-5
Test1,1-Recover,43.000,1.775,0.914,0.061,,0.339903,776.676,,33.9903,0.776676,,,,7.85398e-5
Test1,1-Recover,43.333,1.793,0.896,0.048,,0.333209,611.155,,33.3209,0.611155,,,,7.85398e-5
Test1,1-Recover,43.667,1.811,0.878,0.034,,0.326515,432.902,,32.6515,0.432902,,,,7.85398e-5
Test1,1-Recover,44.000,1.829,0.86,0.027,,0.319821,343.775,,31.9821,0.343775,,,,7.85398e-5
Test1,1-Recover,44.333,1.847,0.842,0.048,,0.313128,611.155,,31.3128,0.611155,,,,7.85398e-5
Test1,1-Recover,44.667,1.865,0.824,0.027,,0.306434,343.775,,30.6434,0.343775,,,,7.85398e-5
Test1,1-Recover,45.000,1.883,0.806,0.034,,0.29974,432.902,,29.974,0.432902,,,,7.85398e-5
Test1,1-Recover,45.333,1.9,0.789,0.027,,0.293418,343.775,,29.3418,0.343775,,,,7.85398e-5
Test1,1-Recover,45.667,1.919,0.77,0.027,,0.286352,343.775,,28.6352,0.343775,,,,7.85398e-5
Test1,1-Recover,46.000,1.937,0.752,0.041,,0.279658,522.028,,27.9658,0.522028,,,,7.85398e-5
Test1,1-Recover,46.333,1.955,0.734,0.034,,0.272964,432.902,,27.2964,0.432902,,,,7.85398e-5
Test1,1-Recover,46.667,1.972,0.717,0.041,,0.266642,522.028,,26.6642,0.522028,,,,7.85398e-5
Test1,1-Recover,47.000,1.99,0.699,0.041,,0.259948,522.028,,25.9948,0.522028,,,,7.85398e-5
Test1,1-Recover,47.333,2.008,0.681,0.027,,0.253254,343.775,,25.3254,0.343775,,,,7.85398e-5
Test1,1-Recover,47.667,2.027,0.662,0.034,,0.246188,432.902,,24.6188,0.432902,,,,7.85398e-5
Test1,1-Recover,48.000,2.044,0.645,0.027,,0.239866,343.775,,23.9866,0.343775,,,,7.85398e-5
Test1,1-Recover,48.333,2.062,0.627,0.027,,0.233172,343.775,,23.3172,0.343775,,,,7.85398e-5
Test1,1-Recover,48.667,2.081,0.608,0.027,,0.226106,343.775,,22.6106,0.343775,,,,7.85398e-5
Test1,1-Recover,49.000,2.098,0.591,0.027,,0.219784,343.775,,21.9784,0.343775,,,,7.85398e-5
Test1,1-Recover,49.333,2.116,0.573,0.034,,0.21309,432.902,,21.309,0.432902,,,,7.85398e-5
Test1,1-Recover,49.667,2.134,0.555,0.027,,0.206396,343.775,,20.6396,0.343775,,,,7.85398e-5
Test1,1-Recover,50.000,2.152,0.537,0.027,,0.199702,343.775,,19.9702,0.343775,,,,7.85398e-5
Test1,1-Recover,50.333,2.17,0.519,0.027,,0.193009,343.775,,19.3009,0.343775,,,,7.85398e-5
Test1,1-Recover,50.667,2.188,0.501,0.027,,0.186315,343.775,,18.6315,0.343775,,,,7.85398e-5
Test1,1-Recover,51.000,2.206,0.483,0.027,,0.179621,343.775,,17.9621,0.343775,,,,7.85398e-5
Test1,1-Recover,51.333,2.223,0.466,0.027,,0.173299,343.775,,17.3299,0.343775,,,,7.85398e-5
Test1,1-Recover,51.667,2.242,0.447,0.027,,0.166233,343.775,,16.6233,0.343775,,,,7.85398e-5
Test1,1-Recover,52.000,2.26,0.429,0.027,,0.159539,343.775,,15.9539,0.343775,,,,7.85398e-5
Test1,1-Recover,52.333,2.277,0.412,0.027,,0.153217,343.775,,15.3217,0.343775,,,,7.85398e-5
Test1,1-Recover,52.667,2.296,0.393,0.034,,0.146151,432.902,,14.6151,0.432902,,,,7.85398e-5
Test1,1-Recover,53.000,2.314,0.375,0.027,,0.139457,343.775,,13.9457,0.343775,,,,7.85398e-5
Test1,1-Recover,53.333,2.331,0.358,0.027,,0.133135,343.775,,13.3135,0.343775,,,,7.85398e-5
Test1,1-Recover,53.667,2.349,0.34,0.034,,0.126441,432.902,,12.6441,0.432902,,,,7.85398e-5
Test1,1-Recover,54.000,2.367,0.322,0.027,,0.119747,343.775,,11.9747,0.343775,,,,7.85398e-5
Test1,1-Recover,54.333,2.385,0.304,0.034,,0.113053,432.902,,11.3053,0.432902,,,,7.85398e-5
Test1,1-Recover,54.667,2.403,0.286,0.034,,0.106359,432.902,,10.6359,0.432902,,,,7.85398e-5
Test1,1-Recover,55.000,2.421,0.268,0.027,,0.0996653,343.775,,9.96653,0.343775,,,,7.85398e-5
Test1,1-Recover,55.333,2.439,0.25,0.027,,0.0929714,343.775,,9.29714,0.343775,,,,7.85398e-5
Test1,1-Recover,55.667,2.458,0.231,0.027,,0.0859055,343.775,,8.59055,0.343775,,,,7.85398e-5
Test1,1-Recover,56.000,2.475,0.214,0.027,,0.0795835,343.775,,7.95835,0.343775,,,,7.85398e-5
Test1,1-Recover,56.333,2.492,0.197,0.027,,0.0732614,343.775,,7.32614,0.343775,,,,7.85398e-5
Test1,1-Recover,56.667,2.511,0.178,0.027,,0.0661956,343.775,,6.61956,0.343775,,,,7.85398e-5
Test1,1-Recover,57.000,2.529,0.16,0.027,,0.0595017,343.775,,5.95017,0.343775,,,,7.85398e-5
Test1,1-Recover,57.333,2.547,0.142,0.027,,0.0528077,343.775,,5.28077,0.343775,,,,7.85398e-5
Test1,1-Recover,57.667,2.565,0.124,0.027,,0.0461138,343.775,,4.61138,0.343775,,,,7.85398e-5
Test1,1-Recover,58.000,2.583,0.106,0.027,,0.0394199,343.775,,3.94199,0.343775,,,,7.85398e-5
Test1,1-Recover,58.333,2.6,0.089,0.027,,0.0330978,343.775,,3.30978,0.343775,,,,7.85398e-5
Test1,1-Recover,58.667,2.619,0.07,0.027,,0.026032,343.775,,2.6032,0.343775,,,,7.85398e-5
Test1,1-Recover,59.000,2.636,0.053,0.027,,0.0197099,343.775,,1.97099,0.343775,,,,7.85398e-5
Test1,1-Recover,59.333,2.654,0.035,0.027,,0.013016,343.775,,1.3016,0.343775,,,,7.85398e-5
Test1,1-Recover,59.667,2.673,0.016,0.027,,0.00595017,343.775,,0.595017,0.343775,,,,7.85398e-5
Test1,1-Recover,60.000,2.689,-0,0.027,,0,343.775,,0,0.343775,,,,7.85398e-5
Test1,2-Compress,60.317,2.674,0.015,0.027,,0.00557828,343.775,,0.557828,0.343775,,,,7.85398e-5
Test1,2-Compress,60.650,2.656,0.033,0.027,,0.0122722,343.775,,1.22722,0.343775,,,,7.85398e-5
Test1,2-Compress,60.983,2.638,0.051,0.027,,0.0189662,343.775,,1.89662,0.343775,,,,7.85398e-5
Test1,2-Compress,61.317,2.62,0.069,0.027,,0.0256601,343.775,,2.56601,0.343775,,,,7.85398e-5
Test1,2-Compress,61.650,2.602,0.087,0.027,,0.032354,343.775,,3.2354,0.343775,,,,7.85398e-5
Test1,2-Compress,61.983,2.584,0.105,0.034,,0.039048,432.902,,3.9048,0.432902,,,,7.85398e-5
Test1,2-Compress,62.317,2.566,0.123,0.027,,0.0457419,343.775,,4.57419,0.343775,,,,7.85398e-5
Test1,2-Compress,62.650,2.549,0.14,0.027,,0.052064,343.775,,5.2064,0.343775,,,,7.85398e-5
Test1,2-Compress,62.983,2.531,0.158,0.034,,0.0587579,432.902,,5.87579,0.432902,,,,7.85398e-5
Test1,2-Compress,63.317,2.512,0.177,0.027,,0.0658237,343.775,,6.58237,0.343775,,,,7.85398e-5
Test1,2-Compress,63.650,2.494,0.195,0.027,,0.0725177,343.775,,7.25177,0.343775,,,,7.85398e-5
Test1,2-Compress,63.983,2.477,0.212,0.027,,0.0788397,343.775,,7.88397,0.343775,,,,7.85398e-5
Test1,2-Compress,64.317,2.459,0.23,0.027,,0.0855337,343.775,,8.55337,0.343775,,,,7.85398e-5
Test1,2-Compress,64.650,2.441,0.248,0.027,,0.0922276,343.775,,9.22276,0.343775,,,,7.85398e-5
Test1,2-Compress,64.983,2.423,0.266,0.027,,0.0989215,343.775,,9.89215,0.343775,,,,7.85398e-5
Test1,2-Compress,65.317,2.405,0.284,0.027,,0.105615,343.775,,10.5615,0.343775,,,,7.85398e-5
Test1,2-Compress,65.650,2.387,0.302,0.027,,0.112309,343.775,,11.2309,0.343775,,,,7.85398e-5
Test1,2-Compress,65.983,2.369,0.32,0.027,,0.119003,343.775,,11.9003,0.343775,,,,7.85398e-5
Test1,2-Compress,66.317,2.351,0.338,0.027,,0.125697,343.775,,12.5697,0.343775,,,,7.85398e-5
Test1,2-Compress,66.650,2.333,0.356,0.027,,0.132391,343.775,,13.2391,0.343775,,,,7.85398e-5
Test1,2-Compress,66.983,2.316,0.373,0.027,,0.138713,343.775,,13.8713,0.343775,,,,7.85398e-5
Test1,2-Compress,67.317,2.297,0.392,0.034,,0.145779,432.902,,14.5779,0.432902,,,,7.85398e-5
Test1,2-Compress,67.650,2.279,0.41,0.034,,0.152473,432.902,,15.2473,0.432902,,,,7.85398e-5
Test1,2-Compress,67.983,2.261,0.428,0.034,,0.159167,432.902,,15.9167,0.432902,,,,7.85398e-5
Test1,2-Compress,68.317,2.243,0.446,0.027,,0.165861,343.775,,16.5861,0.343775,,,,7.85398e-5
Test1,2-Compress,68.650,2.225,0.464,0.027,,0.172555,343.775,,17.2555,0.343775,,,,7.85398e-5
Test1,2-Compress,68.983,2.207,0.482,0.027,,0.179249,343.775,,17.9249,0.343775,,,,7.85398e-5
Test1,2-Compress,69.317,2.19,0.499,0.034,,0.185571,432.902,,18.5571,0.432902,,,,7.85398e-5
Test1,2-Compress,69.650,2.172,0.517,0.027,,0.192265,343.775,,19.2265,0.343775,,,,7.85398e-5
Test1,2-Compress,69.983,2.154,0.535,0.041,,0.198959,522.028,,19.8959,0.522028,,,,7.85398e-5
Test1,2-Compress,70.317,2.135,0.554,0.054,,0.206025,687.549,,20.6025,0.687549,,,,7.85398e-5
Test1,2-Compress,70.650,2.118,0.571,0.048,,0.212347,611.155,,21.2347,0.611155,,,,7.85398e-5
Test1,2-Compress,70.983,2.1,0.589,0.048,,0.219041,611.155,,21.9041,0.611155,,,,7.85398e-5
Test1,2-Compress,71.317,2.082,0.607,0.048,,0.225734,611.155,,22.5734,0.611155,,,,7.85398e-5
Test1,2-Compress,71.650,2.064,0.625,0.048,,0.232428,611.155,,23.2428,0.611155,,,,7.85398e-5
Test1,2-Compress,71.983,2.046,0.643,0.054,,0.239122,687.549,,23.9122,0.687549,,,,7.85398e-5
Test1,2-Compress,72.317,2.028,0.661,0.054,,0.245816,687.549,,24.5816,0.687549,,,,7.85398e-5
Test1,2-Compress,72.650,2.01,0.679,0.054,,0.25251,687.549,,25.251,0.687549,,,,7.85398e-5
Test1,2-Compress,72.983,1.992,0.697,0.054,,0.259204,687.549,,25.9204,0.687549,,,,7.85398e-5
Test1,2-Compress,73.317,1.974,0.715,0.048,,0.265898,611.155,,26.5898,0.611155,,,,7.85398e-5
Test1,2-Compress,73.650,1.957,0.732,0.054,,0.27222,687.549,,27.222,0.687549,,,,7.85398e-5
Test1,2-Compress,73.983,1.939,0.75,0.061,,0.278914,776.676,,27.8914,0.776676,,,,7.85398e-5
Test1,2-Compress,74.317,1.92,0.769,0.061,,0.28598,776.676,,28.598,0.776676,,,,7.85398e-5
Test1,2-Compress,74.650,1.902,0.787,0.054,,0.292674,687.549,,29.2674,0.687549,,,,7.85398e-5
Test1,2-Compress,74.983,1.885,0.804,0.054,,0.298996,687.549,,29.8996,0.687549,,,,7.85398e-5
Test1,2-Compress,75.317,1.866,0.823,0.041,,0.306062,522.028,,30.6062,0.522028,,,,7.85398e-5
Test1,2-Compress,75.650,1.848,0.841,0.075,,0.312756,954.93,,31.2756,0.95493,,,,7.85398e-5
Test1,2-Compress,75.983,1.831,0.858,0.082,,0.319078,1044.06,,31.9078,1.04406,,,,7.85398e-5
Test1,2-Compress,76.317,1.813,0.876,0.068,,0.325772,865.803,,32.5772,0.865803,,,,7.85398e-5
Test1,2-Compress,76.650,1.795,0.894,0.082,,0.332466,1044.06,,33.2466,1.04406,,,,7.85398e-5
Test1,2-Compress,76.983,1.777,0.912,0.082,,0.33916,1044.06,,33.916,1.04406,,,,7.85398e-5
Test1,2-Compress,77.317,1.759,0.93,0.075,,0.345853,954.93,,34.5853,0.95493,,,,7.85398e-5
Test1,2-Compress,77.650,1.741,0.948,0.082,,0.352547,1044.06,,35.2547,1.04406,,,,7.85398e-5
Test1,2-Compress,77.983,1.723,0.966,0.082,,0.359241,1044.06,,35.9241,1.04406,,,,7.85398e-5
Test1,2-Compress,78.317,1.705,0.984,0.082,,0.365935,1044.06,,36.5935,1.04406,,,,7.85398e-5
Test1,2-Compress,78.650,1.687,1.002,0.082,,0.372629,1044.06,,37.2629,1.04406,,,,7.85398e-5
Test1,2-Compress,78.983,1.669,1.02,0.082,,0.379323,1044.06,,37.9323,1.04406,,,,7.85398e-5
Test1,2-Compress,79.317,1.651,1.038,0.082,,0.386017,1044.06,,38.6017,1.04406,,,,7.85398e-5
Test1,2-Compress,79.650,1.633,1.056,0.082,,0.392711,1044.06,,39.2711,1.04406,,,,7.85398e-5
Test1,2-Compress,79.983,1.615,1.074,0.082,,0.399405,1044.06,,39.9405,1.04406,,,,7.85398e-5
Test1,2-Compress,80.317,1.597,1.092,0.082,,0.406099,1044.06,,40.6099,1.04406,,,,7.85398e-5
Test1,2-Compress,80.650,1.58,1.109,0.082,,0.412421,1044.06,,41.2421,1.04406,,,,7.85398e-5
Test1,2-Compress,80.983,1.562,1.127,0.082,,0.419115,1044.06,,41.9115,1.04406,,,,7.85398e-5
Test1,2-Compress,81.317,1.543,1.146,0.082,,0.426181,1044.06,,42.6181,1.04406,,,,7.85398e-5
Test1,2-Compress,81.650,1.526,1.163,0.088,,0.432503,1120.45,,43.2503,1.12045,,,,7.85398e-5
Test1,2-Compress,81.983,1.508,1.181,0.088,,0.439197,1120.45,,43.9197,1.12045,,,,7.85398e-5
Test1,2-Compress,82.317,1.489,1.2,0.088,,0.446263,1120.45,,44.6263,1.12045,,,,7.85398e-5
Test1,2-Compress,82.650,1.471,1.218,0.082,,0.452956,1044.06,,45.2956,1.04406,,,,7.85398e-5
Test1,2-Compress,82.983,1.454,1.235,0.088,,0.459279,1120.45,,45.9279,1.12045,,,,7.85398e-5
Test1,2-Compress,83.317,1.436,1.253,0.088,,0.465972,1120.45,,46.5972,1.12045,,,,7.85398e-5
Test1,2-Compress,83.650,1.418,1.271,0.088,,0.472666,1120.45,,47.2666,1.12045,,,,7.85398e-5
Test1,2-Compress,83.983,1.4,1.289,0.088,,0.47936,1120.45,,47.936,1.12045,,,,7.85398e-5
Test1,2-Compress,84.317,1.382,1.307,0.095,,0.486054,1209.58,,48.6054,1.20958,,,,7.85398e-5
Test1,2-Compress,84.650,1.364,1.325,0.102,,0.492748,1298.7,,49.2748,1.2987,,,,7.85398e-5
Test1,2-Compress,84.983,1.346,1.343,0.088,,0.499442,1120.45,,49.9442,1.12045,,,,7.85398e-5
Test1,2-Compress,85.317,1.328,1.361,0.122,,0.506136,1553.35,,50.6136,1.55335,,,,7.85398e-5
Test1,2-Compress,85.650,1.31,1.379,0.129,,0.51283,1642.48,,51.283,1.64248,,,,7.85398e-5
Test1,2-Compress,85.983,1.293,1.396,0.122,,0.519152,1553.35,,51.9152,1.55335,,,,7.85398e-5
Test1,2-Compress,86.317,1.274,1.415,0.122,,0.526218,1553.35,,52.6218,1.55335,,,,7.85398e-5
Test1,2-Compress,86.650,1.256,1.433,0.136,,0.532912,1731.61,,53.2912,1.73161,,,,7.85398e-5
Test1,2-Compress,86.983,1.238,1.451,0.129,,0.539606,1642.48,,53.9606,1.64248,,,,7.85398e-5
Test1,2-Compress,87.317,1.22,1.469,0.136,,0.5463,1731.61,,54.63,1.73161,,,,7.85398e-5
Test1,2-Compress,87.650,1.203,1.486,0.136,,0.552622,1731.61,,55.2622,1.73161,,,,7.85398e-5
Test1,2-Compress,87.983,1.185,1.504,0.136,,0.559316,1731.61,,55.9316,1.73161,,,,7.85398e-5
Test1,2-Compress,88.317,1.167,1.522,0.136,,0.56601,1731.61,,56.601,1.73161,,,,7.85398e-5
Test1,2-Compress,88.650,1.149,1.54,0.136,,0.572704,1731.61,,57.2704,1.73161,,,,7.85398e-5
Test1,2-Compress,88.983,1.131,1.558,0.136,,0.579398,1731.61,,57.9398,1.73161,,,,7.85398e-5
Test1,2-Compress,89.317,1.112,1.577,0.136,,0.586463,1731.61,,58.6463,1.73161,,,,7.85398e-5
Test1,2-Compress,89.650,1.095,1.594,0.136,,0.592785,1731.61,,59.2785,1.73161,,,,7.85398e-5
Test1,2-Compress,89.983,1.077,1.612,0.136,,0.599479,1731.61,,59.9479,1.73161,,,,7.85398e-5
Test1,2-Recover,90.303,1.089,1.6,0.136,,0.595017,1731.61,,59.5017,1.73161,,,,7.85398e-5
Test1,2-Recover,90.637,1.108,1.581,0.136,,0.587951,1731.61,,58.7951,1.73161,,,,7.85398e-5
Test1,2-Recover,90.970,1.126,1.563,0.136,,0.581257,1731.61,,58.1257,1.73161,,,,7.85398e-5
Test1,2-Recover,91.303,1.143,1.546,0.136,,0.574935,1731.61,,57.4935,1.73161,,,,7.85398e-5
Test1,2-Recover,91.637,1.161,1.528,0.136,,0.568241,1731.61,,56.8241,1.73161,,,,7.85398e-5
Test1,2-Recover,91.970,1.179,1.51,0.136,,0.561547,1731.61,,56.1547,1.73161,,,,7.85398e-5
Test1,2-Recover,92.303,1.197,1.492,0.136,,0.554853,1731.61,,55.4853,1.73161,,,,7.85398e-5
Test1,2-Recover,92.637,1.215,1.474,0.136,,0.548159,1731.61,,54.8159,1.73161,,,,7.85398e-5
Test1,2-Recover,92.970,1.233,1.456,0.129,,0.541465,1642.48,,54.1465,1.64248,,,,7.85398e-5
Test1,2-Recover,93.303,1.251,1.438,0.122,,0.534771,1553.35,,53.4771,1.55335,,,,7.85398e-5
Test1,2-Recover,93.637,1.269,1.42,0.102,,0.528077,1298.7,,52.8077,1.2987,,,,7.85398e-5
Test1,2-Recover,93.970,1.287,1.402,0.095,,0.521383,1209.58,,52.1383,1.20958,,,,7.85398e-5
Test1,2-Recover,94.303,1.304,1.385,0.095,,0.515061,1209.58,,51.5061,1.20958,,,,7.85398e-5
Test1,2-Recover,94.637,1.323,1.366,0.102,,0.507996,1298.7,,50.7996,1.2987,,,,7.85398e-5
Test1,2-Recover,94.970,1.341,1.348,0.109,,0.501302,1387.83,,50.1302,1.38783,,,,7.85398e-5
Test1,2-Recover,95.303,1.359,1.33,0.088,,0.494608,1120.45,,49.4608,1.12045,,,,7.85398e-5
Test1,2-Recover,95.637,1.377,1.312,0.088,,0.487914,1120.45,,48.7914,1.12045,,,,7.85398e-5
Test1,2-Recover,95.970,1.394,1.295,0.088,,0.481592,1120.45,,48.1592,1.12045,,,,7.85398e-5
Test1,2-Recover,96.303,1.412,1.277,0.088,,0.474898,1120.45,,47.4898,1.12045,,,,7.85398e-5
Test1,2-Recover,96.637,1.431,1.258,0.082,,0.467832,1044.06,,46.7832,1.04406,,,,7.85398e-5
Test1,2-Recover,96.970,1.448,1.241,0.082,,0.46151,1044.06,,46.151,1.04406,,,,7.85398e-5
Test1,2-Recover,97.303,1.466,1.223,0.082,,0.454816,1044.06,,45.4816,1.04406,,,,7.85398e-5
Test1,2-Recover,97.637,1.485,1.204,0.082,,0.44775,1044.06,,44.775,1.04406,,,,7.85398e-5
Test1,2-Recover,97.970,1.502,1.187,0.082,,0.441428,1044.06,,44.1428,1.04406,,,,7.85398e-5
Test1,2-Recover,98.303,1.52,1.169,0.082,,0.434734,1044.06,,43.4734,1.04406,,,,7.85398e-5
Test1,2-Recover,98.637,1.538,1.151,0.082,,0.42804,1044.06,,42.804,1.04406,,,,7.85398e-5
Test1,2-Recover,98.970,1.556,1.133,0.082,,0.421346,1044.06,,42.1346,1.04406,,,,7.85398e-5
Test1,2-Recover,99.303,1.574,1.115,0.082,,0.414652,1044.06,,41.4652,1.04406,,,,7.85398e-5
Test1,2-Recover,99.637,1.592,1.097,0.082,,0.407958,1044.06,,40.7958,1.04406,,,,7.85398e-5
Test1,2-Recover,99.970,1.61,1.079,0.082,,0.401264,1044.06,,40.1264,1.04406,,,,7.85398e-5
Test1,2-Recover,100.303,1.628,1.061,0.075,,0.39457,954.93,,39.457,0.95493,,,,7.85398e-5
Test1,2-Recover,100.637,1.646,1.043,0.082,,0.387877,1044.06,,38.7877,1.04406,,,,7.85398e-5
Test1,2-Recover,100.970,1.664,1.025,0.082,,0.381183,1044.06,,38.1183,1.04406,,,,7.85398e-5
Test1,2-Recover,101.303,1.681,1.008,0.075,,0.374861,954.93,,37.4861,0.95493,,,,7.85398e-5
Test1,2-Recover,101.637,1.7,0.989,0.061,,0.367795,776.676,,36.7795,0.776676,,,,7.85398e-5
Test1,2-Recover,101.970,1.718,0.971,0.041,,0.361101,522.028,,36.1101,0.522028,,,,7.85398e-5
Test1,2-Recover,102.303,1.735,0.954,0.061,,0.354779,776.676,,35.4779,0.776676,,,,7.85398e-5
Test1,2-Recover,102.637,1.754,0.935,0.068,,0.347713,865.803,,34.7713,0.865803,,,,7.85398e-5
Test1,2-Recover,102.970,1.771,0.918,0.061,,0.341391,776.676,,34.1391,0.776676,,,,7.85398e-5
Test1,2-Recover,103.303,1.789,0.9,0.048,,0.334697,611.155,,33.4697,0.611155,,,,7.85398e-5
Test1,2-Recover,103.637,1.807,0.882,0.061,,0.328003,776.676,,32.8003,0.776676,,,,7.85398e-5
Test1,2-Recover,103.970,1.825,0.864,0.061,,0.321309,776.676,,32.1309,0.776676,,,,7.85398e-5
Test1,2-Recover,104.303,1.843,0.846,0.054,,0.314615,687.549,,31.4615,0.687549,,,,7.85398e-5
Test1,2-Recover,104.637,1.862,0.827,0.041,,0.307549,522.028,,30.7549,0.522028,,,,7.85398e-5
Test1,2-Recover,104.970,1.879,0.81,0.048,,0.301227,611.155,,30.1227,0.611155,,,,7.85398e-5
Test1,2-Recover,105.303,1.897,0.792,0.048,,0.294533,611.155,,29.4533,0.611155,,,,7.85398e-5
Test1,2-Recover,105.637,1.915,0.774,0.027,,0.287839,343.775,,28.7839,0.343775,,,,7.85398e-5
Test1,2-Recover,105.970,1.933,0.756,0.034,,0.281145,432.902,,28.1145,0.432902,,,,7.85398e-5
Test1,2-Recover,106.303,1.951,0.738,0.041,,0.274451,522.028,,27.4451,0.522028,,,,7.85398e-5
Test1,2-Recover,106.637,1.969,0.72,0.034,,0.267758,432.902,,26.7758,0.432902,,,,7.85398e-5
Test1,2-Recover,106.970,1.987,0.702,0.034,,0.261064,432.902,,26.1064,0.432902,,,,7.85398e-5
Test1,2-Recover,107.303,2.005,0.684,0.034,,0.25437,432.902,,25.437,0.432902,,,,7.85398e-5
Test1,2-Recover,107.637,2.023,0.666,0.027,,0.247676,343.775,,24.7676,0.343775,,,,7.85398e-5
Test1,2-Recover,107.970,2.04,0.649,0.034,,0.241354,432.902,,24.1354,0.432902,,,,7.85398e-5
Test1,2-Recover,108.303,2.058,0.631,0.027,,0.23466,343.775,,23.466,0.343775,,,,7.85398e-5
Test1,2-Recover,108.637,2.077,0.612,0.027,,0.227594,343.775,,22.7594,0.343775,,,,7.85398e-5
Test1,2-Recover,108.970,2.095,0.594,0.027,,0.2209,343.775,,22.09,0.343775,,,,7.85398e-5
Test1,2-Recover,109.303,2.112,0.577,0.027,,0.214578,343.775,,21.4578,0.343775,,,,7.85398e-5
Test1,2-Recover,109.637,2.13,0.559,0.027,,0.207884,343.775,,20.7884,0.343775,,,,7.85398e-5
Test1,2-Recover,109.970,2.148,0.541,0.034,,0.20119,432.902,,20.119,0.432902,,,,7.85398e-5
Test1,2-Recover,110.303,2.166,0.523,0.027,,0.194496,343.775,,19.4496,0.343775,,,,7.85398e-5
Test1,2-Recover,110.637,2.184,0.505,0.034,,0.187802,432.902,,18.7802,0.432902,,,,7.85398e-5
Test1,2-Recover,110.970,2.202,0.487,0.027,,0.181108,343.775,,18.1108,0.343775,,,,7.85398e-5
Test1,2-Recover,111.303,2.22,0.469,0.034,,0.174414,432.902,,17.4414,0.432902,,,,7.85398e-5
Test1,2-Recover,111.637,2.238,0.451,0.027,,0.16772,343.775,,16.772,0.343775,,,,7.85398e-5
Test1,2-Recover,111.970,2.256,0.433,0.027,,0.161026,343.775,,16.1026,0.343775,,,,7.85398e-5
Test1,2-Recover,112.303,2.274,0.415,0.027,,0.154332,343.775,,15.4332,0.343775,,,,7.85398e-5
Test1,2-Recover,112.637,2.292,0.397,0.027,,0.147639,343.775,,14.7639,0.343775,,,,7.85398e-5
Test1,2-Recover,112.970,2.31,0.379,0.027,,0.140945,343.775,,14.0945,0.343775,,,,7.85398e-5
Test1,2-Recover,113.303,2.327,0.362,0.027,,0.134623,343.775,,13.4623,0.343775,,,,7.85398e-5
Test1,2-Recover,113.637,2.346,0.343,0.027,,0.127557,343.775,,12.7557,0.343775,,,,7.85398e-5
Test1,2-Recover,113.970,2.364,0.325,0.027,,0.120863,343.775,,12.0863,0.343775,,,,7.85398e-5
Test1,2-Recover,114.303,2.382,0.307,0.027,,0.114169,343.775,,11.4169,0.343775,,,,7.85398e-5
Test1,2-Recover,114.637,2.399,0.29,0.027,,0.107847,343.775,,10.7847,0.343775,,,,7.85398e-5
Test1,2-Recover,114.970,2.417,0.272,0.027,,0.101153,343.775,,10.1153,0.343775,,,,7.85398e-5
Test1,2-Recover,115.303,2.435,0.254,0.027,,0.0944589,343.775,,9.44589,0.343775,,,,7.85398e-5
Test1,2-Recover,115.637,2.454,0.235,0.027,,0.0873931,343.775,,8.73931,0.343775,,,,7.85398e-5
Test1,2-Recover,115.970,2.471,0.218,0.027,,0.081071,343.775,,8.1071,0.343775,,,,7.85398e-5
Test1,2-Recover,116.303,2.489,0.2,0.027,,0.0743771,343.775,,7.43771,0.343775,,,,7.85398e-5
Test1,2-Recover,116.637,2.507,0.182,0.027,,0.0676832,343.775,,6.76832,0.343775,,,,7.85398e-5
Test1,2-Recover,116.970,2.525,0.164,0.027,,0.0609892,343.775,,6.09892,0.343775,,,,7.85398e-5
Test1,2-Recover,117.303,2.543,0.146,0.027,,0.0542953,343.775,,5.42953,0.343775,,,,7.85398e-5
Test1,2-Recover,117.637,2.561,0.128,0.020,,0.0476013,254.648,,4.76013,0.254648,,,,7.85398e-5
Test1,2-Recover,117.970,2.579,0.11,0.027,,0.0409074,343.775,,4.09074,0.343775,,,,7.85398e-5
Test1,2-Recover,118.303,2.597,0.092,0.034,,0.0342135,432.902,,3.42135,0.432902,,,,7.85398e-5
Test1,2-Recover,118.637,2.615,0.074,0.034,,0.0275195,432.902,,2.75195,0.432902,,,,7.85398e-5
Test1,2-Recover,118.970,2.633,0.056,0.027,,0.0208256,343.775,,2.08256,0.343775,,,,7.85398e-5
Test1,2-Recover,119.303,2.651,0.038,0.027,,0.0141316,343.775,,1.41316,0.343775,,,,7.85398e-5
Test1,2-Recover,119.637,2.669,0.02,0.027,,0.00743771,343.775,,0.743771,0.343775,,,,7.85398e-5
Test1,2-Recover,119.970,2.687,0.002,0.027,,0.000743771,343.775,,0.0743771,0.343775,,,,7.85398e-5
Test1,3-Compress,120.280,2.678,0.011,0.027,,0.00409074,343.775,,0.409074,0.343775,,,,7.85398e-5
Test1,3-Compress,120.613,2.66,0.029,0.027,,0.0107847,343.775,,1.07847,0.343775,,,,7.85398e-5
Test1,3-Compress,120.947,2.642,0.047,0.027,,0.0174786,343.775,,1.74786,0.343775,,,,7.85398e-5
Test1,3-Compress,121.280,2.624,0.065,0.027,,0.0241726,343.775,,2.41726,0.343775,,,,7.85398e-5
Test1,3-Compress,121.613,2.607,0.082,0.027,,0.0304946,343.775,,3.04946,0.343775,,,,7.85398e-5
Test1,3-Compress,121.947,2.588,0.101,0.027,,0.0375604,343.775,,3.75604,0.343775,,,,7.85398e-5
Test1,3-Compress,122.280,2.57,0.119,0.027,,0.0442544,343.775,,4.42544,0.343775,,,,7.85398e-5
Test1,3-Compress,122.613,2.553,0.136,0.027,,0.0505764,343.775,,5.05764,0.343775,,,,7.85398e-5
Test1,3-Compress,122.947,2.534,0.155,0.027,,0.0576422,343.775,,5.76422,0.343775,,,,7.85398e-5
Test1,3-Compress,123.280,2.517,0.172,0.027,,0.0639643,343.775,,6.39643,0.343775,,,,7.85398e-5
Test1,3-Compress,123.613,2.499,0.19,0.027,,0.0706582,343.775,,7.06582,0.343775,,,,7.85398e-5
Test1,3-Compress,123.947,2.481,0.208,0.027,,0.0773522,343.775,,7.73522,0.343775,,,,7.85398e-5
Test1,3-Compress,124.280,2.463,0.226,0.027,,0.0840461,343.775,,8.40461,0.343775,,,,7.85398e-5
Test1,3-Compress,124.613,2.445,0.244,0.027,,0.0907401,343.775,,9.07401,0.343775,,,,7.85398e-5
Test1,3-Compress,124.947,2.426,0.263,0.027,,0.0978059,343.775,,9.78059,0.343775,,,,7.85398e-5
Test1,3-Compress,125.280,2.409,0.28,0.027,,0.104128,343.775,,10.4128,0.343775,,,,7.85398e-5
Test1,3-Compress,125.613,2.391,0.298,0.027,,0.110822,343.775,,11.0822,0.343775,,,,7.85398e-5
Test1,3-Compress,125.947,2.373,0.316,0.027,,0.117516,343.775,,11.7516,0.343775,,,,7.85398e-5
Test1,3-Compress,126.280,2.355,0.334,0.027,,0.12421,343.775,,12.421,0.343775,,,,7.85398e-5
Test1,3-Compress,126.613,2.337,0.352,0.027,,0.130904,343.775,,13.0904,0.343775,,,,7.85398e-5
Test1,3-Compress,126.947,2.319,0.37,0.034,,0.137598,432.902,,13.7598,0.432902,,,,7.85398e-5
Test1,3-Compress,127.280,2.301,0.388,0.041,,0.144292,522.028,,14.4292,0.522028,,,,7.85398e-5
Test1,3-Compress,127.613,2.283,0.406,0.048,,0.150985,611.155,,15.0985,0.611155,,,,7.85398e-5
Test1,3-Compress,127.947,2.265,0.424,0.034,,0.157679,432.902,,15.7679,0.432902,,,,7.85398e-5
Test1,3-Compress,128.280,2.248,0.441,0.027,,0.164001,343.775,,16.4001,0.343775,,,,7.85398e-5
Test1,3-Compress,128.613,2.23,0.459,0.048,,0.170695,611.155,,17.0695,0.611155,,,,7.85398e-5
Test1,3-Compress,128.947,2.211,0.478,0.048,,0.177761,611.155,,17.7761,0.611155,,,,7.85398e-5
Test1,3-Compress,129.280,2.194,0.495,0.034,,0.184083,432.902,,18.4083,0.432902,,,,7.85398e-5
Test1,3-Compress,129.613,2.176,0.513,0.041,,0.190777,522.028,,19.0777,0.522028,,,,7.85398e-5
Test1,3-Compress,129.947,2.158,0.531,0.041,,0.197471,522.028,,19.7471,0.522028,,,,7.85398e-5
Test1,3-Compress,130.280,2.14,0.549,0.041,,0.204165,522.028,,20.4165,0.522028,,,,7.85398e-5
Test1,3-Compress,130.613,2.122,0.567,0.041,,0.210859,522.028,,21.0859,0.522028,,,,7.85398e-5
Test1,3-Compress,130.947,2.104,0.585,0.041,,0.217553,522.028,,21.7553,0.522028,,,,7.85398e-5
Test1,3-Compress,131.280,2.086,0.603,0.034,,0.224247,432.902,,22.4247,0.432902,,,,7.85398e-5
Test1,3-Compress,131.613,2.068,0.621,0.041,,0.230941,522.028,,23.0941,0.522028,,,,7.85398e-5
Test1,3-Compress,131.947,2.05,0.639,0.048,,0.237635,611.155,,23.7635,0.611155,,,,7.85398e-5
Test1,3-Compress,132.280,2.032,0.657,0.034,,0.244329,432.902,,24.4329,0.432902,,,,7.85398e-5
Test1,3-Compress,132.613,2.014,0.675,0.041,,0.251023,522.028,,25.1023,0.522028,,,,7.85398e-5
Test1,3-Compress,132.947,1.996,0.693,0.041,,0.257717,522.028,,25.7717,0.522028,,,,7.85398e-5
Test1,3-Compress,133.280,1.978,0.711,0.034,,0.264411,432.902,,26.4411,0.432902,,,,7.85398e-5
Test1,3-Compress,133.613,1.961,0.728,0.027,,0.270733,343.775,,27.0733,0.343775,,,,7.85398e-5
Test1,3-Compress,133.947,1.942,0.747,0.048,,0.277798,611.155,,27.7798,0.611155,,,,7.85398e-5
Test1,3-Compress,134.280,1.924,0.765,0.054,,0.284492,687.549,,28.4492,0.687549,,,,7.85398e-5
Test1,3-Compress,134.613,1.906,0.783,0.061,,0.291186,776.676,,29.1186,0.776676,,,,7.85398e-5
Test1,3-Compress,134.947,1.889,0.8,0.068,,0.297508,865.803,,29.7508,0.865803,,,,7.85398e-5
Test1,3-Compress,135.280,1.871,0.818,0.068,,0.304202,865.803,,30.4202,0.865803,,,,7.85398e-5
Test1,3-Compress,135.613,1.853,0.836,0.075,,0.310896,954.93,,31.0896,0.95493,,,,7.85398e-5
Test1,3-Compress,135.947,1.834,0.855,0.075,,0.317962,954.93,,31.7962,0.95493,,,,7.85398e-5
Test1,3-Compress,136.280,1.817,0.872,0.082,,0.324284,1044.06,,32.4284,1.04406,,,,7.85398e-5
Test1,3-Compress,136.613,1.799,0.89,0.082,,0.330978,1044.06,,33.0978,1.04406,,,,7.85398e-5
Test1,3-Compress,136.947,1.781,0.908,0.082,,0.337672,1044.06,,33.7672,1.04406,,,,7.85398e-5
Test1,3-Compress,137.280,1.763,0.926,0.082,,0.344366,1044.06,,34.4366,1.04406,,,,7.85398e-5
Test1,3-Compress,137.613,1.745,0.944,0.082,,0.35106,1044.06,,35.106,1.04406,,,,7.85398e-5
Test1,3-Compress,137.947,1.727,0.962,0.082,,0.357754,1044.06,,35.7754,1.04406,,,,7.85398e-5
Test1,3-Compress,138.280,1.709,0.98,0.082,,0.364448,1044.06,,36.4448,1.04406,,,,7.85398e-5
Test1,3-Compress,138.613,1.691,0.998,0.082,,0.371142,1044.06,,37.1142,1.04406,,,,7.85398e-5
Test1,3-Compress,138.947,1.673,1.016,0.082,,0.377836,1044.06,,37.7836,1.04406,,,,7.85398e-5
Test1,3-Compress,139.280,1.655,1.034,0.082,,0.38453,1044.06,,38.453,1.04406,,,,7.85398e-5
Test1,3-Compress,139.613,1.637,1.052,0.082,,0.391224,1044.06,,39.1224,1.04406,,,,7.85398e-5
Test1,3-Compress,139.947,1.619,1.07,0.082,,0.397917,1044.06,,39.7917,1.04406,,,,7.85398e-5
Test1,3-Compress,140.280,1.601,1.088,0.082,,0.404611,1044.06,,40.4611,1.04406,,,,7.85398e-5
Test1,3-Compress,140.613,1.584,1.105,0.082,,0.410933,1044.06,,41.0933,1.04406,,,,7.85398e-5
Test1,3-Compress,140.947,1.565,1.124,0.082,,0.417999,1044.06,,41.7999,1.04406,,,,7.85398e-5
Test1,3-Compress,141.280,1.547,1.142,0.082,,0.424693,1044.06,,42.4693,1.04406,,,,7.85398e-5
Test1,3-Compress,141.613,1.53,1.159,0.082,,0.431015,1044.06,,43.1015,1.04406,,,,7.85398e-5
Test1,3-Compress,141.947,1.512,1.177,0.082,,0.437709,1044.06,,43.7709,1.04406,,,,7.85398e-5
Test1,3-Compress,142.280,1.494,1.195,0.082,,0.444403,1044.06,,44.4403,1.04406,,,,7.85398e-5
Test1,3-Compress,142.613,1.476,1.213,0.082,,0.451097,1044.06,,45.1097,1.04406,,,,7.85398e-5
Test1,3-Compress,142.947,1.458,1.231,0.095,,0.457791,1209.58,,45.7791,1.20958,,,,7.85398e-5
Test1,3-Compress,143.280,1.44,1.249,0.095,,0.464485,1209.58,,46.4485,1.20958,,,,7.85398e-5
Test1,3-Compress,143.613,1.422,1.267,0.102,,0.471179,1298.7,,47.1179,1.2987,,,,7.85398e-5
Test1,3-Compress,143.947,1.404,1.285,0.116,,0.477873,1476.96,,47.7873,1.47696,,,,7.85398e-5
Test1,3-Compress,144.280,1.386,1.303,0.116,,0.484567,1476.96,,48.4567,1.47696,,,,7.85398e-5
Test1,3-Compress,144.613,1.369,1.32,0.116,,0.490889,1476.96,,49.0889,1.47696,,,,7.85398e-5
Test1,3-Compress,144.947,1.35,1.339,0.116,,0.497955,1476.96,,49.7955,1.47696,,,,7.85398e-5
Test1,3-Compress,145.280,1.332,1.357,0.129,,0.504649,1642.48,,50.4649,1.64248,,,,7.85398e-5
Test1,3-Compress,145.613,1.314,1.375,0.136,,0.511343,1731.61,,51.1343,1.73161,,,,7.85398e-5
Test1,3-Compress,145.947,1.296,1.393,0.129,,0.518036,1642.48,,51.8036,1.64248,,,,7.85398e-5
Test1,3-Compress,146.280,1.278,1.411,0.136,,0.52473,1731.61,,52.473,1.73161,,,,7.85398e-5
Test1,3-Compress,146.613,1.261,1.428,0.136,,0.531052,1731.61,,53.1052,1.73161,,,,7.85398e-5
Test1,3-Compress,146.947,1.242,1.447,0.136,,0.538118,1731.61,,53.8118,1.73161,,,,7.85398e-5
Test1,3-Compress,147.280,1.225,1.464,0.136,,0.54444,1731.61,,54.444,1.73161,,,,7.85398e-5
Test1,3-Compress,147.613,1.207,1.482,0.136,,0.551134,1731.61,,55.1134,1.73161,,,,7.85398e-5
Test1,3-Compress,147.947,1.188,1.501,0.136,,0.5582,1731.61,,55.82,1.73161,,,,7.85398e-5
Test1,3-Compress,148.280,1.171,1.518,0.136,,0.564522,1731.61,,56.4522,1.73161,,,,7.85398e-5
Test1,3-Compress,148.613,1.153,1.536,0.136,,0.571216,1731.61,,57.1216,1.73161,,,,7.85398e-5
Test1,3-Compress,148.947,1.135,1.554,0.136,,0.57791,1731.61,,57.791,1.73161,,,,7.85398e-5
Test1,3-Compress,149.280,1.117,1.572,0.136,,0.584604,1731.61,,58.4604,1.73161,,,,7.85398e-5
Test1,3-Compress,149.613,1.099,1.59,0.136,,0.591298,1731.61,,59.1298,1.73161,,,,7.85398e-5
Test1,3-Compress,149.947,1.081,1.608,0.136,,0.597992,1731.61,,59.7992,1.73161,,,,7.85398e-5
Test1,3-Recover,150.267,1.085,1.604,0.136,,0.596504,1731.61,,59.6504,1.73161,,,,7.85398e-5
Test1,3-Recover,150.600,1.103,1.586,0.136,,0.58981,1731.61,,58.981,1.73161,,,,7.85398e-5
Test1,3-Recover,150.933,1.121,1.568,0.136,,0.583116,1731.61,,58.3116,1.73161,,,,7.85398e-5
Test1,3-Recover,151.267,1.139,1.55,0.136,,0.576422,1731.61,,57.6422,1.73161,,,,7.85398e-5
Test1,3-Recover,151.600,1.157,1.532,0.136,,0.569729,1731.61,,56.9729,1.73161,,,,7.85398e-5
Test1,3-Recover,151.933,1.175,1.514,0.136,,0.563035,1731.61,,56.3035,1.73161,,,,7.85398e-5
Test1,3-Recover,152.267,1.193,1.496,0.136,,0.556341,1731.61,,55.6341,1.73161,,,,7.85398e-5
Test1,3-Recover,152.600,1.211,1.478,0.136,,0.549647,1731.61,,54.9647,1.73161,,,,7.85398e-5
Test1,3-Recover,152.933,1.229,1.46,0.136,,0.542953,1731.61,,54.2953,1.73161,,,,7.85398e-5
Test1,3-Recover,153.267,1.247,1.442,0.136,,0.536259,1731.61,,53.6259,1.73161,,,,7.85398e-5
Test1,3-Recover,153.600,1.265,1.424,0.122,,0.529565,1553.35,,52.9565,1.55335,,,,7.85398e-5
Test1,3-Recover,153.933,1.283,1.406,0.129,,0.522871,1642.48,,52.2871,1.64248,,,,7.85398e-5
Test1,3-Recover,154.267,1.301,1.388,0.109,,0.516177,1387.83,,51.6177,1.38783,,,,7.85398e-5
Test1,3-Recover,154.600,1.319,1.37,0.102,,0.509483,1298.7,,50.9483,1.2987,,,,7.85398e-5
Test1,3-Recover,154.933,1.336,1.353,0.095,,0.503161,1209.58,,50.3161,1.20958,,,,7.85398e-5
Test1,3-Recover,155.267,1.355,1.334,0.095,,0.496095,1209.58,,49.6095,1.20958,,,,7.85398e-5
Test1,3-Recover,155.600,1.372,1.317,0.088,,0.489773,1120.45,,48.9773,1.12045,,,,7.85398e-5
Test1,3-Recover,155.933,1.39,1.299,0.088,,0.483079,1120.45,,48.3079,1.12045,,,,7.85398e-5
Test1,3-Recover,156.267,1.409,1.28,0.082,,0.476013,1044.06,,47.6013,1.04406,,,,7.85398e-5
Test1,3-Recover,156.600,1.427,1.262,0.088,,0.469319,1120.45,,46.9319,1.12045,,,,7.85398e-5
Test1,3-Recover,156.933,1.444,1.245,0.088,,0.462997,1120.45,,46.2997,1.12045,,,,7.85398e-5
Test1,3-Recover,157.267,1.462,1.227,0.082,,0.456303,1044.06,,45.6303,1.04406,,,,7.85398e-5
Test1,3-Recover,157.600,1.48,1.209,0.082,,0.44961,1044.06,,44.961,1.04406,,,,7.85398e-5
Test1,3-Recover,157.933,1.498,1.191,0.082,,0.442916,1044.06,,44.2916,1.04406,,,,7.85398e-5
Test1,3-Recover,158.267,1.516,1.173,0.082,,0.436222,1044.06,,43.6222,1.04406,,,,7.85398e-5
Test1,3-Recover,158.600,1.534,1.155,0.082,,0.429528,1044.06,,42.9528,1.04406,,,,7.85398e-5
Test1,3-Recover,158.933,1.552,1.137,0.082,,0.422834,1044.06,,42.2834,1.04406,,,,7.85398e-5
Test1,3-Recover,159.267,1.57,1.119,0.082,,0.41614,1044.06,,41.614,1.04406,,,,7.85398e-5
Test1,3-Recover,159.600,1.588,1.101,0.082,,0.409446,1044.06,,40.9446,1.04406,,,,7.85398e-5
Test1,3-Recover,159.933,1.605,1.084,0.082,,0.403124,1044.06,,40.3124,1.04406,,,,7.85398e-5
Test1,3-Recover,160.267,1.624,1.065,0.082,,0.396058,1044.06,,39.6058,1.04406,,,,7.85398e-5
Test1,3-Recover,160.600,1.642,1.047,0.082,,0.389364,1044.06,,38.9364,1.04406,,,,7.85398e-5
Test1,3-Recover,160.933,1.66,1.029,0.075,,0.38267,954.93,,38.267,0.95493,,,,7.85398e-5
Test1,3-Recover,161.267,1.678,1.011,0.082,,0.375976,1044.06,,37.5976,1.04406,,,,7.85398e-5
Test1,3-Recover,161.600,1.696,0.993,0.082,,0.369282,1044.06,,36.9282,1.04406,,,,7.85398e-5
Test1,3-Recover,161.933,1.713,0.976,0.075,,0.36296,954.93,,36.296,0.95493,,,,7.85398e-5
Test1,3-Recover,162.267,1.732,0.957,0.061,,0.355894,776.676,,35.5894,0.776676,,,,7.85398e-5
Test1,3-Recover,162.600,1.749,0.94,0.054,,0.349572,687.549,,34.9572,0.687549,,,,7.85398e-5
Test1,3-Recover,162.933,1.767,0.922,0.061,,0.342878,776.676,,34.2878,0.776676,,,,7.85398e-5
Test1,3-Recover,163.267,1.786,0.903,0.061,,0.335813,776.676,,33.5813,0.776676,,,,7.85398e-5
Test1,3-Recover,163.600,1.803,0.886,0.048,,0.329491,611.155,,32.9491,0.611155,,,,7.85398e-5
Test1,3-Recover,163.933,1.821,0.868,0.041,,0.322797,522.028,,32.2797,0.522028,,,,7.85398e-5
Test1,3-Recover,164.267,1.839,0.85,0.041,,0.316103,522.028,,31.6103,0.522028,,,,7.85398e-5
Test1,3-Recover,164.600,1.857,0.832,0.041,,0.309409,522.028,,30.9409,0.522028,,,,7.85398e-5
Test1,3-Recover,164.933,1.875,0.814,0.034,,0.302715,432.902,,30.2715,0.432902,,,,7.85398e-5
Test1,3-Recover,165.267,1.893,0.796,0.034,,0.296021,432.902,,29.6021,0.432902,,,,7.85398e-5
Test1,3-Recover,165.600,1.911,0.778,0.027,,0.289327,343.775,,28.9327,0.343775,,,,7.85398e-5
Test1,3-Recover,165.933,1.929,0.76,0.027,,0.282633,343.775,,28.2633,0.343775,,,,7.85398e-5
Test1,3-Recover,166.267,1.947,0.742,0.027,,0.275939,343.775,,27.5939,0.343775,,,,7.85398e-5
Test1,3-Recover,166.600,1.964,0.725,0.027,,0.269617,343.775,,26.9617,0.343775,,,,7.85398e-5
Test1,3-Recover,166.933,1.982,0.707,0.034,,0.262923,432.902,,26.2923,0.432902,,,,7.85398e-5
Test1,3-Recover,167.267,2.001,0.688,0.041,,0.255857,522.028,,25.5857,0.522028,,,,7.85398e-5
Test1,3-Recover,167.600,2.019,0.67,0.041,,0.249163,522.028,,24.9163,0.522028,,,,7.85398e-5
Test1,3-Recover,167.933,2.036,0.653,0.048,,0.242841,611.155,,24.2841,0.611155,,,,7.85398e-5
Test1,3-Recover,168.267,2.055,0.634,0.048,,0.235775,611.155,,23.5775,0.611155,,,,7.85398e-5
Test1,3-Recover,168.600,2.072,0.617,0.027,,0.229453,343.775,,22.9453,0.343775,,,,7.85398e-5
Test1,3-Recover,168.933,2.09,0.599,0.034,,0.222759,432.902,,22.2759,0.432902,,,,7.85398e-5
Test1,3-Recover,169.267,2.108,0.581,0.027,,0.216065,343.775,,21.6065,0.343775,,,,7.85398e-5
Test1,3-Recover,169.600,2.126,0.563,0.034,,0.209372,432.902,,20.9372,0.432902,,,,7.85398e-5
Test1,3-Recover,169.933,2.144,0.545,0.027,,0.202678,343.775,,20.2678,0.343775,,,,7.85398e-5
Test1,3-Recover,170.267,2.162,0.527,0.034,,0.195984,432.902,,19.5984,0.432902,,,,7.85398e-5
Test1,3-Recover,170.600,2.18,0.509,0.027,,0.18929,343.775,,18.929,0.343775,,,,7.85398e-5
Test1,3-Recover,170.933,2.198,0.491,0.027,,0.182596,343.775,,18.2596,0.343775,,,,7.85398e-5
Test1,3-Recover,171.267,2.216,0.473,0.027,,0.175902,343.775,,17.5902,0.343775,,,,7.85398e-5
Test1,3-Recover,171.600,2.234,0.455,0.027,,0.169208,343.775,,16.9208,0.343775,,,,7.85398e-5
Test1,3-Recover,171.933,2.252,0.437,0.027,,0.162514,343.775,,16.2514,0.343775,,,,7.85398e-5
Test1,3-Recover,172.267,2.27,0.419,0.027,,0.15582,343.775,,15.582,0.343775,,,,7.85398e-5
Test1,3-Recover,172.600,2.288,0.401,0.027,,0.149126,343.775,,14.9126,0.343775,,,,7.85398e-5
Test1,3-Recover,172.933,2.306,0.383,0.027,,0.142432,343.775,,14.2432,0.343775,,,,7.85398e-5
Test1,3-Recover,173.267,2.324,0.365,0.027,,0.135738,343.775,,13.5738,0.343775,,,,7.85398e-5
Test1,3-Recover,173.600,2.341,0.348,0.027,,0.129416,343.775,,12.9416,0.343775,,,,7.85398e-5
Test1,3-Recover,173.933,2.359,0.33,0.027,,0.122722,343.775,,12.2722,0.343775,,,,7.85398e-5
Test1,3-Recover,174.267,2.378,0.311,0.027,,0.115656,343.775,,11.5656,0.343775,,,,7.85398e-5
Test1,3-Recover,174.600,2.395,0.294,0.027,,0.109334,343.775,,10.9334,0.343775,,,,7.85398e-5
Test1,3-Recover,174.933,2.413,0.276,0.027,,0.10264,343.775,,10.264,0.343775,,,,7.85398e-5
Test1,3-Recover,175.267,2.432,0.257,0.027,,0.0955746,343.775,,9.55746,0.343775,,,,7.85398e-5
Test1,3-Recover,175.600,2.449,0.24,0.034,,0.0892525,432.902,,8.92525,0.432902,,,,7.85398e-5
Test1,3-Recover,175.933,2.467,0.222,0.034,,0.0825586,432.902,,8.25586,0.432902,,,,7.85398e-5
Test1,3-Recover,176.267,2.485,0.204,0.027,,0.0758646,343.775,,7.58646,0.343775,,,,7.85398e-5
Test1,3-Recover,176.600,2.503,0.186,0.027,,0.0691707,343.775,,6.91707,0.343775,,,,7.85398e-5
Test1,3-Recover,176.933,2.521,0.168,0.027,,0.0624768,343.775,,6.24768,0.343775,,,,7.85398e-5
Test1,3-Recover,177.267,2.539,0.15,0.027,,0.0557828,343.775,,5.57828,0.343775,,,,7.85398e-5
Test1,3-Recover,177.600,2.557,0.132,0.027,,0.0490889,343.775,,4.90889,0.343775,,,,7.85398e-5
Test1,3-Recover,177.933,2.575,0.114,0.027,,0.0423949,343.775,,4.23949,0.343775,,,,7.85398e-5
Test1,3-Recover,178.267,2.593,0.096,0.027,,0.035701,343.775,,3.5701,0.343775,,,,7.85398e-5
Test1,3-Recover,178.600,2.611,0.078,0.027,,0.0290071,343.775,,2.90071,0.343775,,,,7.85398e-5
Test1,3-Recover,178.933,2.628,0.061,0.027,,0.022685,343.775,,2.2685,0.343775,,,,7.85398e-5
Test1,3-Recover,179.267,2.647,0.042,0.027,,0.0156192,343.775,,1.56192,0.343775,,,,7.85398e-5
Test1,3-Recover,179.600,2.665,0.024,0.027,,0.00892525,343.775,,0.892525,0.343775,,,,7.85398e-5
Test1,3-Recover,179.933,2.683,0.006,0.027,,0.00223131,343.775,,0.223131,0.343775,,,,7.85398e-5
Test1,3-Recover,180.100,2.689,-0,0.027,,0,343.775,,0,0.343775,,,,7.85398e-5