File: data/gamma_1-1-0.25_3.csv
SetName,Cycle,Time_S,Size_mm,Displacement_mm,Force_N,,Strain,Stress(Pascal),,%Strain,Stress(kPa),,,,Area(m^2)
Test1,1-Compress,0.000,2.777,-0,0.004,,0,50.9296,,0,0.0509296,,,,7.85398e-5
Test1,1-Compress,0.367,2.757,0.02,0.004,,0.00720202,50.9296,,0.720202,0.0509296,,,,7.85398e-5
Test1,1-Compress,0.733,2.737,0.04,0.011,,0.014404,140.056,,1.4404,0.140056,,,,7.85398e-5
Test1,1-Compress,1.100,2.716,0.061,-0.003,,0.0219662,-38.1972,,2.19662,-0.0381972,,,,7.85398e-5
Test1,1-Compress,1.467,2.696,0.081,-0.003,,0.0291682,-38.1972,,2.91682,-0.0381972,,,,7.85398e-5
Test1,1-Compress,1.833,2.676,0.101,-0.003,,0.0363702,-38.1972,,3.63702,-0.0381972,,,,7.85398e-5
Test1,1-Compress,2.200,2.655,0.122,-0.003,,0.0439323,-38.1972,,4.39323,-0.0381972,,,,7.85398e-5
Test1,1-Compress,2.567,2.634,0.143,0.004,,0.0514944,50.9296,,5.14944,0.0509296,,,,7.85398e-5
Test1,1-Compress,2.933,2.615,0.162,0.004,,0.0583363,50.9296,,5.83363,0.0509296,,,,7.85398e-5
Test1,1-Compress,3.300,2.594,0.183,0.004,,0.0658985,50.9296,,6.58985,0.0509296,,,,7.85398e-5
Test1,1-Compress,3.667,2.573,0.204,0.004,,0.0734606,50.9296,,7.34606,0.0509296,,,,7.85398e-5
Test1,1-Compress,4.033,2.553,0.224,-0.003,,0.0806626,-38.1972,,8.06626,-0.0381972,,,,7.85398e-5
Test1,1-Compress,4.400,2.533,0.244,-0.003,,0.0878646,-38.1972,,8.78646,-0.0381972,,,,7.85398e-5
Test1,1-Compress,4.767,2.512,0.265,-0.003,,0.0954267,-38.1972,,9.54267,-0.0381972,,,,7.85398e-5
Test1,1-Compress,5.133,2.492,0.285,0.004,,0.102629,50.9296,,10.2629,0.0509296,,,,7.85398e-5
Test1,1-Compress,5.500,2.471,0.306,0.011,,0.110191,140.056,,11.0191,0.140056,,,,7.85398e-5
Test1,1-Compress,5.867,2.451,0.326,0.004,,0.117393,50.9296,,11.7393,0.0509296,,,,7.85398e-5
Test1,1-Compress,6.233,2.431,0.346,0.004,,0.124595,50.9296,,12.4595,0.0509296,,,,7.85398e-5
Test1,1-Compress,6.600,2.41,0.367,-0.003,,0.132157,-38.1972,,13.2157,-0.0381972,,,,7.85398e-5
Test1,1-Compress,6.967,2.39,0.387,-0.003,,0.139359,-38.1972,,13.9359,-0.0381972,,,,7.85398e-5
Test1,1-Compress,7.333,2.37,0.407,-0.003,,0.146561,-38.1972,,14.6561,-0.0381972,,,,7.85398e-5
Test1,1-Compress,7.700,2.349,0.428,0.004,,0.154123,50.9296,,15.4123,0.0509296,,,,7.85398e-5
Test1,1-Compress,8.067,2.329,0.448,0.011,,0.161325,140.056,,16.1325,0.140056,,,,7.85398e-5
Test1,1-Compress,8.433,2.308,0.469,0.011,,0.168887,140.056,,16.8887,0.140056,,,,7.85398e-5
Test1,1-Compress,8.800,2.288,0.489,-0.003,,0.176089,-38.1972,,17.6089,-0.0381972,,,,7.85398e-5
Test1,1-Compress,9.167,2.267,0.51,-0.003,,0.183651,-38.1972,,18.3651,-0.0381972,,,,7.85398e-5
Test1,1-Compress,9.533,2.248,0.529,-0.003,,0.190493,-38.1972,,19.0493,-0.0381972,,,,7.85398e-5
Test1,1-Compress,9.900,2.227,0.55,-0.003,,0.198055,-38.1972,,19.8055,-0.0381972,,,,7.85398e-5
Test1,1-Compress,10.267,2.206,0.571,0.004,,0.205618,50.9296,,20.5618,0.0509296,,,,7.85398e-5
Test1,1-Compress,10.633,2.186,0.591,0.011,,0.21282,140.056,,21.282,0.140056,,,,7.85398e-5
Test1,1-Compress,11.000,2.166,0.611,0.004,,0.220022,50.9296,,22.0022,0.0509296,,,,7.85398e-5
Test1,1-Compress,11.367,2.145,0.632,-0.003,,0.227584,-38.1972,,22.7584,-0.0381972,,,,7.85398e-5
Test1,1-Compress,11.733,2.125,0.652,-0.003,,0.234786,-38.1972,,23.4786,-0.0381972,,,,7.85398e-5
Test1,1-Compress,12.100,2.104,0.673,0.004,,0.242348,50.9296,,24.2348,0.0509296,,,,7.85398e-5
Test1,1-Compress,12.467,2.084,0.693,-0.003,,0.24955,-38.1972,,24.955,-0.0381972,,,,7.85398e-5
Test1,1-Compress,12.833,2.064,0.713,0.004,,0.256752,50.9296,,25.6752,0.0509296,,,,7.85398e-5
Test1,1-Compress,13.200,2.043,0.734,0.011,,0.264314,140.056,,26.4314,0.140056,,,,7.85398e-5
Test1,1-Compress,13.567,2.023,0.754,0.004,,0.271516,50.9296,,27.1516,0.0509296,,,,7.85398e-5
Test1,1-Compress,13.933,2.003,0.774,-0.003,,0.278718,-38.1972,,27.8718,-0.0381972,,,,7.85398e-5
Test1,1-Compress,14.300,1.982,0.795,-0.003,,0.28628,-38.1972,,28.628,-0.0381972,,,,7.85398e-5
Test1,1-Compress,14.667,1.961,0.816,0.004,,0.293842,50.9296,,29.3842,0.0509296,,,,7.85398e-5
Test1,1-Compress,15.033,1.941,0.836,-0.003,,0.301044,-38.1972,,30.1044,-0.0381972,,,,7.85398e-5
Test1,1-Compress,15.400,1.921,0.856,0.004,,0.308246,50.9296,,30.8246,0.0509296,,,,7.85398e-5
Test1,1-Compress,15.767,1.9,0.877,0.004,,0.315808,50.9296,,31.5808,0.0509296,,,,7.85398e-5
Test1,1-Compress,16.133,1.88,0.897,0.004,,0.32301,50.9296,,32.301,0.0509296,,,,7.85398e-5
Test1,1-Compress,16.500,1.86,0.917,0.011,,0.330212,140.056,,33.0212,0.140056,,,,7.85398e-5
Test1,1-Compress,16.867,1.839,0.938,0.018,,0.337775,229.183,,33.7775,0.229183,,,,7.85398e-5
Test1,1-Compress,17.233,1.819,0.958,0.004,,0.344977,50.9296,,34.4977,0.0509296,,,,7.85398e-5
Test1,1-Compress,17.600,1.799,0.978,0.004,,0.352179,50.9296,,35.2179,0.0509296,,,,7.85398e-5
Test1,1-Compress,17.967,1.778,0.999,0.004,,0.359741,50.9296,,35.9741,0.0509296,,,,7.85398e-5
Test1,1-Compress,18.333,1.758,1.019,0.011,,0.366943,140.056,,36.6943,0.140056,,,,7.85398e-5
Test1,1-Compress,18.700,1.737,1.04,0.018,,0.374505,229.183,,37.4505,0.229183,,,,7.85398e-5
Test1,1-Compress,19.067,1.717,1.06,0.011,,0.381707,140.056,,38.1707,0.140056,,,,7.85398e-5
Test1,1-Compress,19.433,1.697,1.08,0.011,,0.388909,140.056,,38.8909,0.140056,,,,7.85398e-5
Test1,1-Compress,19.800,1.676,1.101,0.004,,0.396471,50.9296,,39.6471,0.0509296,,,,7.85398e-5
Test1,1-Compress,20.167,1.656,1.121,0.004,,0.403673,50.9296,,40.3673,0.0509296,,,,7.85398e-5
Test1,1-Compress,20.533,1.635,1.142,0.004,,0.411235,50.9296,,41.1235,0.0509296,,,,7.85398e-5
Test1,1-Compress,20.900,1.615,1.162,0.018,,0.418437,229.183,,41.8437,0.229183,,,,7.85398e-5
Test1,1-Compress,21.267,1.594,1.183,0.018,,0.425999,229.183,,42.5999,0.229183,,,,7.85398e-5
Test1,1-Compress,21.633,1.574,1.203,0.025,,0.433201,318.31,,43.3201,0.31831,,,,7.85398e-5
Test1,1-Compress,22.000,1.554,1.223,0.018,,0.440403,229.183,,44.0403,0.229183,,,,7.85398e-5
Test1,1-Compress,22.367,1.533,1.244,0.011,,0.447965,140.056,,44.7965,0.140056,,,,7.85398e-5
Test1,1-Compress,22.733,1.513,1.264,0.031,,0.455167,394.704,,45.5167,0.394704,,,,7.85398e-5
Test1,1-Compress,23.100,1.493,1.284,0.025,,0.462369,318.31,,46.2369,0.31831,,,,7.85398e-5
Test1,1-Compress,23.467,1.472,1.305,0.031,,0.469932,394.704,,46.9932,0.394704,,,,7.85398e-5
Test1,1-Compress,23.833,1.452,1.325,0.031,,0.477134,394.704,,47.7134,0.394704,,,,7.85398e-5
Test1,1-Compress,24.200,1.431,1.346,0.025,,0.484696,318.31,,48.4696,0.31831,,,,7.85398e-5
Test1,1-Compress,24.567,1.411,1.366,0.011,,0.491898,140.056,,49.1898,0.140056,,,,7.85398e-5
Test1,1-Compress,24.933,1.391,1.386,0.031,,0.4991,394.704,,49.91,0.394704,,,,7.85398e-5
Test1,1-Compress,25.300,1.37,1.407,0.045,,0.506662,572.958,,50.6662,0.572958,,,,7.85398e-5
Test1,1-Compress,25.667,1.349,1.428,0.045,,0.514224,572.958,,51.4224,0.572958,,,,7.85398e-5
Test1,1-Compress,26.033,1.33,1.447,0.052,,0.521066,662.085,,52.1066,0.662085,,,,7.85398e-5
Test1,1-Compress,26.400,1.309,1.468,0.052,,0.528628,662.085,,52.8628,0.662085,,,,7.85398e-5
Test1,1-Compress,26.767,1.289,1.488,0.045,,0.53583,572.958,,53.583,0.572958,,,,7.85398e-5
Test1,1-Compress,27.133,1.268,1.509,0.052,,0.543392,662.085,,54.3392,0.662085,,,,7.85398e-5
Test1,1-Compress,27.500,1.248,1.529,0.052,,0.550594,662.085,,55.0594,0.662085,,,,7.85398e-5
Test1,1-Compress,27.867,1.227,1.55,0.052,,0.558156,662.085,,55.8156,0.662085,,,,7.85398e-5
Test1,1-Compress,28.233,1.207,1.57,0.045,,0.565358,572.958,,56.5358,0.572958,,,,7.85398e-5
Test1,1-Compress,28.600,1.187,1.59,0.059,,0.57256,751.211,,57.256,0.751211,,,,7.85398e-5
Test1,1-Compress,28.967,1.166,1.611,0.052,,0.580122,662.085,,58.0122,0.662085,,,,7.85398e-5
Test1,1-Compress,29.333,1.146,1.631,0.052,,0.587324,662.085,,58.7324,0.662085,,,,7.85398e-5
Test1,1-Compress,29.700,1.126,1.651,0.052,,0.594526,662.085,,59.4526,0.662085,,,,7.85398e-5
Test1,1-Recover,30.067,1.113,1.664,0.052,,0.599208,662.085,,59.9208,0.662085,,,,7.85398e-5
Test1,1-Recover,30.433,1.134,1.643,0.052,,0.591646,662.085,,59.1646,0.662085,,,,7.85398e-5
Test1,1-Recover,30.800,1.154,1.623,0.038,,0.584444,483.831,,58.4444,0.483831,,,,7.85398e-5
Test1,1-Recover,31.167,1.175,1.602,0.059,,0.576882,751.211,,57.6882,0.751211,,,,7.85398e-5
Test1,1-Recover,31.533,1.195,1.582,0.052,,0.56968,662.085,,56.968,0.662085,,,,7.85398e-5
Test1,1-Recover,31.900,1.216,1.561,0.045,,0.562117,572.958,,56.2117,0.572958,,,,7.85398e-5
Test1,1-Recover,32.267,1.236,1.541,0.045,,0.554915,572.958,,55.4915,0.572958,,,,7.85398e-5
Test1,1-Recover,32.633,1.256,1.521,0.045,,0.547713,572.958,,54.7713,0.572958,,,,7.85398e-5
Test1,1-Recover,33.000,1.276,1.501,0.025,,0.540511,318.31,,54.0511,0.31831,,,,7.85398e-5
Test1,1-Recover,33.367,1.297,1.48,0.025,,0.532949,318.31,,53.2949,0.31831,,,,7.85398e-5
Test1,1-Recover,33.733,1.317,1.46,0.045,,0.525747,572.958,,52.5747,0.572958,,,,7.85398e-5
Test1,1-Recover,34.100,1.338,1.439,0.045,,0.518185,572.958,,51.8185,0.572958,,,,7.85398e-5
Test1,1-Recover,34.467,1.358,1.419,0.038,,0.510983,483.831,,51.0983,0.483831,,,,7.85398e-5
Test1,1-Recover,34.833,1.378,1.399,0.018,,0.503781,229.183,,50.3781,0.229183,,,,7.85398e-5
Test1,1-Recover,35.200,1.399,1.378,0.004,,0.496219,50.9296,,49.6219,0.0509296,,,,7.85398e-5
Test1,1-Recover,35.567,1.42,1.357,0.025,,0.488657,318.31,,48.8657,0.31831,,,,7.85398e-5
Test1,1-Recover,35.933,1.439,1.338,0.031,,0.481815,394.704,,48.1815,0.394704,,,,7.85398e-5
Test1,1-Recover,36.300,1.46,1.317,0.031,,0.474253,394.704,,47.4253,0.394704,,,,7.85398e-5
Test1,1-Recover,36.667,1.481,1.296,0.025,,0.466691,318.31,,46.6691,0.31831,,,,7.85398e-5
Test1,1-Recover,37.033,1.501,1.276,0.018,,0.459489,229.183,,45.9489,0.229183,,,,7.85398e-5
Test1,1-Recover,37.400,1.521,1.256,0.011,,0.452287,140.056,,45.2287,0.140056,,,,7.85398e-5
Test1,1-Recover,37.767,1.542,1.235,0.004,,0.444725,50.9296,,44.4725,0.0509296,,,,7.85398e-5
Test1,1-Recover,38.133,1.562,1.215,0.004,,0.437523,50.9296,,43.7523,0.0509296,,,,7.85398e-5
Test1,1-Recover,38.500,1.583,1.194,0.011,,0.42996,140.056,,42.996,0.140056,,,,7.85398e-5
Test1,1-Recover,38.867,1.603,1.174,0.025,,0.422758,318.31,,42.2758,0.31831,,,,7.85398e-5
Test1,1-Recover,39.233,1.623,1.154,0.004,,0.415556,50.9296,,41.5556,0.0509296,,,,7.85398e-5
Test1,1-Recover,39.600,1.644,1.133,0.011,,0.407994,140.056,,40.7994,0.140056,,,,7.85398e-5
Test1,1-Recover,39.967,1.665,1.112,0.004,,0.400432,50.9296,,40.0432,0.0509296,,,,7.85398e-5
Test1,1-Recover,40.333,1.684,1.093,0.004,,0.39359,50.9296,,39.359,0.0509296,,,,7.85398e-5
Test1,1-Recover,40.700,1.705,1.072,0.011,,0.386028,140.056,,38.6028,0.140056,,,,7.85398e-5
Test1,1-Recover,41.067,1.725,1.052,0.011,,0.378826,140.056,,37.8826,0.140056,,,,7.85398e-5
Test1,1-Recover,41.433,1.746,1.031,0.025,,0.371264,318.31,,37.1264,0.31831,,,,7.85398e-5
Test1,1-Recover,41.800,1.766,1.011,0.004,,0.364062,50.9296,,36.4062,0.0509296,,,,7.85398e-5
Test1,1-Recover,42.167,1.787,0.99,0.004,,0.3565,50.9296,,35.65,0.0509296,,,,7.85398e-5
Test1,1-Recover,42.533,1.806,0.971,-0.003,,0.349658,-38.1972,,34.9658,-0.0381972,,,,7.85398e-5
Test1,1-Recover,42.900,1.828,0.949,0.004,,0.341736,50.9296,,34.1736,0.0509296,,,,7.85398e-5
Test1,1-Recover,43.267,1.848,0.929,0.011,,0.334534,140.056,,33.4534,0.140056,,,,7.85398e-5
Test1,1-Recover,43.633,1.868,0.909,0.004,,0.327332,50.9296,,32.7332,0.0509296,,,,7.85398e-5
Test1,1-Recover,44.000,1.888,0.889,-0.003,,0.32013,-38.1972,,32.013,-0.0381972,,,,7.85398e-5
Test1,1-Recover,44.367,1.909,0.868,-0.003,,0.312568,-38.1972,,31.2568,-0.0381972,,,,7.85398e-5
Test1,1-Recover,44.733,1.929,0.848,-0.003,,0.305366,-38.1972,,30.5366,-0.0381972,,,,7.85398e-5
Test1,1-Recover,45.100,1.95,0.827,-0.003,,0.297803,-38.1972,,29.7803,-0.0381972,,,,7.85398e-5
Test1,1-Recover,45.467,1.97,0.807,0.004,,0.290601,50.9296,,29.0601,0.0509296,,,,7.85398e-5
Test1,1-Recover,45.833,1.991,0.786,0.011,,0.283039,140.056,,28.3039,0.140056,,,,7.85398e-5
Test1,1-Recover,46.200,2.011,0.766,0.004,,0.275837,50.9296,,27.5837,0.0509296,,,,7.85398e-5
Test1,1-Recover,46.567,2.031,0.746,-0.003,,0.268635,-38.1972,,26.8635,-0.0381972,,,,7.85398e-5
Test1,1-Recover,46.933,2.051,0.726,-0.003,,0.261433,-38.1972,,26.1433,-0.0381972,,,,7.85398e-5
Test1,1-Recover,47.300,2.072,0.705,-0.003,,0.253871,-38.1972,,25.3871,-0.0381972,,,,7.85398e-5
Test1,1-Recover,47.667,2.093,0.684,-0.003,,0.246309,-38.1972,,24.6309,-0.0381972,,,,7.85398e-5
Test1,1-Recover,48.033,2.113,0.664,0.004,,0.239107,50.9296,,23.9107,0.0509296,,,,7.85398e-5
Test1,1-Recover,48.400,2.133,0.644,0.011,,0.231905,140.056,,23.1905,0.140056,,,,7.85398e-5
Test1,1-Recover,48.767,2.154,0.623,0.004,,0.224343,50.9296,,22.4343,0.0509296,,,,7.85398e-5
Test1,1-Recover,49.133,2.174,0.603,-0.003,,0.217141,-38.1972,,21.7141,-0.0381972,,,,7.85398e-5
Test1,1-Recover,49.500,2.195,0.582,-0.003,,0.209579,-38.1972,,20.9579,-0.0381972,,,,7.85398e-5
Test1,1-Recover,49.867,2.215,0.562,-0.003,,0.202377,-38.1972,,20.2377,-0.0381972,,,,7.85398e-5
Test1,1-Recover,50.233,2.235,0.542,-0.003,,0.195175,-38.1972,,19.5175,-0.0381972,,,,7.85398e-5
Test1,1-Recover,50.600,2.256,0.521,0.004,,0.187613,50.9296,,18.7613,0.0509296,,,,7.85398e-5
Test1,1-Recover,50.967,2.276,0.501,0.011,,0.180411,140.056,,18.0411,0.140056,,,,7.85398e-5
Test1,1-Recover,51.333,2.296,0.481,0.004,,0.173208,50.9296,,17.3208,0.0509296,,,,7.85398e-5
Test1,1-Recover,51.700,2.317,0.46,-0.003,,0.165646,-38.1972,,16.5646,-0.0381972,,,,7.85398e-5
Test1,1-Recover,52.067,2.337,0.44,-0.003,,0.158444,-38.1972,,15.8444,-0.0381972,,,,7.85398e-5
Test1,1-Recover,52.433,2.358,0.419,-0.003,,0.150882,-38.1972,,15.0882,-0.0381972,,,,7.85398e-5
Test1,1-Recover,52.800,2.378,0.399,0.004,,0.14368,50.9296,,14.368,0.0509296,,,,7.85398e-5
Test1,1-Recover,53.167,2.398,0.379,0.004,,0.136478,50.9296,,13.6478,0.0509296,,,,7.85398e-5
Test1,1-Recover,53.533,2.418,0.359,0.004,,0.129276,50.9296,,12.9276,0.0509296,,,,7.85398e-5
Test1,1-Recover,53.900,2.439,0.338,0.004,,0.121714,50.9296,,12.1714,0.0509296,,,,7.85398e-5
Test1,1-Recover,54.267,2.46,0.317,-0.003,,0.114152,-38.1972,,11.4152,-0.0381972,,,,7.85398e-5
Test1,1-Recover,54.633,2.48,0.297,-0.003,,0.10695,-38.1972,,10.695,-0.0381972,,,,7.85398e-5
Test1,1-Recover,55.000,2.5,0.277,-0.003,,0.0997479,-38.1972,,9.97479,-0.0381972,,,,7.85398e-5
Test1,1-Recover,55.367,2.521,0.256,0.004,,0.0921858,50.9296,,9.21858,0.0509296,,,,7.85398e-5
Test1,1-Recover,55.733,2.541,0.236,0.004,,0.0849838,50.9296,,8.49838,0.0509296,,,,7.85398e-5
Test1,1-Recover,56.100,2.561,0.216,0.004,,0.0777818,50.9296,,7.77818,0.0509296,,,,7.85398e-5
Test1,1-Recover,56.467,2.582,0.195,0.004,,0.0702197,50.9296,,7.02197,0.0509296,,,,7.85398e-5
Test1,1-Recover,56.833,2.602,0.175,-0.003,,0.0630176,-38.1972,,6.30176,-0.0381972,,,,7.85398e-5
Test1,1-Recover,57.200,2.623,0.154,-0.003,,0.0554555,-38.1972,,5.54555,-0.0381972,,,,7.85398e-5
Test1,1-Recover,57.567,2.643,0.134,-0.003,,0.0482535,-38.1972,,4.82535,-0.0381972,,,,7.85398e-5
Test1,1-Recover,57.933,2.663,0.114,-0.003,,0.0410515,-38.1972,,4.10515,-0.0381972,,,,7.85398e-5
Test1,1-Recover,58.300,2.684,0.093,0.004,,0.0334894,50.9296,,3.34894,0.0509296,,,,7.85398e-5
Test1,1-Recover,58.667,2.705,0.072,0.011,,0.0259273,140.056,,2.59273,0.140056,,,,7.85398e-5
Test1,1-Recover,59.033,2.724,0.053,-0.003,,0.0190853,-38.1972,,1.90853,-0.0381972,,,,7.85398e-5
Test1,1-Recover,59.400,2.745,0.032,-0.003,,0.0115232,-38.1972,,1.15232,-0.0381972,,,,7.85398e-5
Test1,1-Recover,59.767,2.765,0.012,-0.003,,0.00432121,-38.1972,,0.432121,-0.0381972,,,,7.85398e-5
Test1,2-Compress,60.117,2.773,0.004,-0.003,,0.0014404,-38.1972,,0.14404,-0.0381972,,,,7.85398e-5
Test1,2-Compress,60.483,2.753,0.024,0.004,,0.00864242,50.9296,,0.864242,0.0509296,,,,7.85398e-5
Test1,2-Compress,60.850,2.732,0.045,0.004,,0.0162045,50.9296,,1.62045,0.0509296,,,,7.85398e-5
Test1,2-Compress,61.217,2.711,0.066,0.004,,0.0237667,50.9296,,2.37667,0.0509296,,,,7.85398e-5
Test1,2-Compress,61.583,2.691,0.086,0.004,,0.0309687,50.9296,,3.09687,0.0509296,,,,7.85398e-5
Test1,2-Compress,61.950,2.671,0.106,-0.003,,0.0381707,-38.1972,,3.81707,-0.0381972,,,,7.85398e-5
Test1,2-Compress,62.317,2.651,0.126,-0.003,,0.0453727,-38.1972,,4.53727,-0.0381972,,,,7.85398e-5
Test1,2-Compress,62.683,2.63,0.147,-0.003,,0.0529348,-38.1972,,5.29348,-0.0381972,,,,7.85398e-5
Test1,2-Compress,63.050,2.61,0.167,0.004,,0.0601368,50.9296,,6.01368,0.0509296,,,,7.85398e-5
Test1,2-Compress,63.417,2.589,0.188,0.011,,0.067699,140.056,,6.7699,0.140056,,,,7.85398e-5
Test1,2-Compress,63.783,2.569,0.208,0.004,,0.074901,50.9296,,7.4901,0.0509296,,,,7.85398e-5
Test1,2-Compress,64.150,2.548,0.229,0.004,,0.0824631,50.9296,,8.24631,0.0509296,,,,7.85398e-5
Test1,2-Compress,64.517,2.528,0.249,-0.003,,0.0896651,-38.1972,,8.96651,-0.0381972,,,,7.85398e-5
Test1,2-Compress,64.883,2.508,0.269,-0.003,,0.0968671,-38.1972,,9.68671,-0.0381972,,,,7.85398e-5
Test1,2-Compress,65.250,2.488,0.289,-0.003,,0.104069,-38.1972,,10.4069,-0.0381972,,,,7.85398e-5
Test1,2-Compress,65.617,2.467,0.31,0.004,,0.111631,50.9296,,11.1631,0.0509296,,,,7.85398e-5
Test1,2-Compress,65.983,2.447,0.33,0.004,,0.118833,50.9296,,11.8833,0.0509296,,,,7.85398e-5
Test1,2-Compress,66.350,2.426,0.351,0.011,,0.126395,140.056,,12.6395,0.140056,,,,7.85398e-5
Test1,2-Compress,66.717,2.406,0.371,-0.003,,0.133597,-38.1972,,13.3597,-0.0381972,,,,7.85398e-5
Test1,2-Compress,67.083,2.386,0.391,-0.003,,0.140799,-38.1972,,14.0799,-0.0381972,,,,7.85398e-5
Test1,2-Compress,67.450,2.365,0.412,-0.003,,0.148362,-38.1972,,14.8362,-0.0381972,,,,7.85398e-5
Test1,2-Compress,67.817,2.344,0.433,-0.003,,0.155924,-38.1972,,15.5924,-0.0381972,,,,7.85398e-5
Test1,2-Compress,68.183,2.325,0.452,0.004,,0.162766,50.9296,,16.2766,0.0509296,,,,7.85398e-5
Test1,2-Compress,68.550,2.304,0.473,0.004,,0.170328,50.9296,,17.0328,0.0509296,,,,7.85398e-5
Test1,2-Compress,68.917,2.283,0.494,0.004,,0.17789,50.9296,,17.789,0.0509296,,,,7.85398e-5
Test1,2-Compress,69.283,2.263,0.514,-0.003,,0.185092,-38.1972,,18.5092,-0.0381972,,,,7.85398e-5
Test1,2-Compress,69.650,2.243,0.534,-0.003,,0.192294,-38.1972,,19.2294,-0.0381972,,,,7.85398e-5
Test1,2-Compress,70.017,2.222,0.555,-0.003,,0.199856,-38.1972,,19.9856,-0.0381972,,,,7.85398e-5
Test1,2-Compress,70.383,2.202,0.575,-0.003,,0.207058,-38.1972,,20.7058,-0.0381972,,,,7.85398e-5
Test1,2-Compress,70.750,2.181,0.596,0.004,,0.21462,50.9296,,21.462,0.0509296,,,,7.85398e-5
Test1,2-Compress,71.117,2.161,0.616,0.011,,0.221822,140.056,,22.1822,0.140056,,,,7.85398e-5
Test1,2-Compress,71.483,2.141,0.636,0.011,,0.229024,140.056,,22.9024,0.140056,,,,7.85398e-5
Test1,2-Compress,71.850,2.12,0.657,-0.003,,0.236586,-38.1972,,23.6586,-0.0381972,,,,7.85398e-5
Test1,2-Compress,72.217,2.099,0.678,-0.003,,0.244148,-38.1972,,24.4148,-0.0381972,,,,7.85398e-5
Test1,2-Compress,72.583,2.08,0.697,-0.003,,0.25099,-38.1972,,25.099,-0.0381972,,,,7.85398e-5
Test1,2-Compress,72.950,2.059,0.718,-0.003,,0.258552,-38.1972,,25.8552,-0.0381972,,,,7.85398e-5
Test1,2-Compress,73.317,2.039,0.738,0.004,,0.265754,50.9296,,26.5754,0.0509296,,,,7.85398e-5
Test1,2-Compress,73.683,2.018,0.759,0.011,,0.273317,140.056,,27.3317,0.140056,,,,7.85398e-5
Test1,2-Compress,74.050,1.998,0.779,0.004,,0.280519,50.9296,,28.0519,0.0509296,,,,7.85398e-5
Test1,2-Compress,74.417,1.977,0.8,-0.003,,0.288081,-38.1972,,28.8081,-0.0381972,,,,7.85398e-5
Test1,2-Compress,74.783,1.957,0.82,-0.003,,0.295283,-38.1972,,29.5283,-0.0381972,,,,7.85398e-5
Test1,2-Compress,75.150,1.936,0.841,0.004,,0.302845,50.9296,,30.2845,0.0509296,,,,7.85398e-5
Test1,2-Compress,75.517,1.916,0.861,0.004,,0.310047,50.9296,,31.0047,0.0509296,,,,7.85398e-5
Test1,2-Compress,75.883,1.896,0.881,0.004,,0.317249,50.9296,,31.7249,0.0509296,,,,7.85398e-5
Test1,2-Compress,76.250,1.876,0.901,0.011,,0.324451,140.056,,32.4451,0.140056,,,,7.85398e-5
Test1,2-Compress,76.617,1.855,0.922,0.025,,0.332013,318.31,,33.2013,0.31831,,,,7.85398e-5
Test1,2-Compress,76.983,1.835,0.942,0.011,,0.339215,140.056,,33.9215,0.140056,,,,7.85398e-5
Test1,2-Compress,77.350,1.814,0.963,0.004,,0.346777,50.9296,,34.6777,0.0509296,,,,7.85398e-5
Test1,2-Compress,77.717,1.794,0.983,0.004,,0.353979,50.9296,,35.3979,0.0509296,,,,7.85398e-5
Test1,2-Compress,78.083,1.773,1.004,0.004,,0.361541,50.9296,,36.1541,0.0509296,,,,7.85398e-5
Test1,2-Compress,78.450,1.753,1.024,0.004,,0.368743,50.9296,,36.8743,0.0509296,,,,7.85398e-5
Test1,2-Compress,78.817,1.733,1.044,0.018,,0.375945,229.183,,37.5945,0.229183,,,,7.85398e-5
Test1,2-Compress,79.183,1.713,1.064,0.011,,0.383147,140.056,,38.3147,0.140056,,,,7.85398e-5
Test1,2-Compress,79.550,1.692,1.085,0.018,,0.390709,229.183,,39.0709,0.229183,,,,7.85398e-5
Test1,2-Compress,79.917,1.671,1.106,0.011,,0.398272,140.056,,39.8272,0.140056,,,,7.85398e-5
Test1,2-Compress,80.283,1.651,1.126,0.011,,0.405474,140.056,,40.5474,0.140056,,,,7.85398e-5
Test1,2-Compress,80.650,1.631,1.146,0.004,,0.412676,50.9296,,41.2676,0.0509296,,,,7.85398e-5
Test1,2-Compress,81.017,1.61,1.167,0.004,,0.420238,50.9296,,42.0238,0.0509296,,,,7.85398e-5
Test1,2-Compress,81.383,1.59,1.187,0.025,,0.42744,318.31,,42.744,0.31831,,,,7.85398e-5
Test1,2-Compress,81.750,1.569,1.208,0.031,,0.435002,394.704,,43.5002,0.394704,,,,7.85398e-5
Test1,2-Compress,82.117,1.549,1.228,0.038,,0.442204,483.831,,44.2204,0.483831,,,,7.85398e-5
Test1,2-Compress,82.483,1.529,1.248,0.018,,0.449406,229.183,,44.9406,0.229183,,,,7.85398e-5
Test1,2-Compress,82.850,1.508,1.269,0.038,,0.456968,483.831,,45.6968,0.483831,,,,7.85398e-5
Test1,2-Compress,83.217,1.488,1.289,0.018,,0.46417,229.183,,46.417,0.229183,,,,7.85398e-5
Test1,2-Compress,83.583,1.468,1.309,0.025,,0.471372,318.31,,47.1372,0.31831,,,,7.85398e-5
Test1,2-Compress,83.950,1.447,1.33,0.045,,0.478934,572.958,,47.8934,0.572958,,,,7.85398e-5
Test1,2-Compress,84.317,1.427,1.35,0.045,,0.486136,572.958,,48.6136,0.572958,,,,7.85398e-5
Test1,2-Compress,84.683,1.406,1.371,0.045,,0.493698,572.958,,49.3698,0.572958,,,,7.85398e-5
Test1,2-Compress,85.050,1.386,1.391,0.038,,0.5009,483.831,,50.09,0.483831,,,,7.85398e-5
Test1,2-Compress,85.417,1.366,1.411,0.052,,0.508102,662.085,,50.8102,0.662085,,,,7.85398e-5
Test1,2-Compress,85.783,1.345,1.432,0.045,,0.515664,572.958,,51.5664,0.572958,,,,7.85398e-5
Test1,2-Compress,86.150,1.325,1.452,0.052,,0.522866,662.085,,52.2866,0.662085,,,,7.85398e-5
Test1,2-Compress,86.517,1.304,1.473,0.052,,0.530429,662.085,,53.0429,0.662085,,,,7.85398e-5
Test1,2-Compress,86.883,1.284,1.493,0.052,,0.537631,662.085,,53.7631,0.662085,,,,7.85398e-5
Test1,2-Compress,87.250,1.264,1.513,0.052,,0.544833,662.085,,54.4833,0.662085,,,,7.85398e-5
Test1,2-Compress,87.617,1.243,1.534,0.052,,0.552395,662.085,,55.2395,0.662085,,,,7.85398e-5
Test1,2-Compress,87.983,1.223,1.554,0.052,,0.559597,662.085,,55.9597,0.662085,,,,7.85398e-5
Test1,2-Compress,88.350,1.203,1.574,0.052,,0.566799,662.085,,56.6799,0.662085,,,,7.85398e-5
Test1,2-Compress,88.717,1.182,1.595,0.052,,0.574361,662.085,,57.4361,0.662085,,,,7.85398e-5
Test1,2-Compress,89.083,1.162,1.615,0.052,,0.581563,662.085,,58.1563,0.662085,,,,7.85398e-5
Test1,2-Compress,89.450,1.141,1.636,0.052,,0.589125,662.085,,58.9125,0.662085,,,,7.85398e-5
Test1,2-Compress,89.817,1.121,1.656,0.052,,0.596327,662.085,,59.6327,0.662085,,,,7.85398e-5
Test1,2-Recover,90.170,1.117,1.66,0.052,,0.597767,662.085,,59.7767,0.662085,,,,7.85398e-5
Test1,2-Recover,90.537,1.138,1.639,0.052,,0.590205,662.085,,59.0205,0.662085,,,,7.85398e-5
Test1,2-Recover,90.903,1.158,1.619,0.059,,0.583003,751.211,,58.3003,0.751211,,,,7.85398e-5
Test1,2-Recover,91.270,1.178,1.599,0.052,,0.575801,662.085,,57.5801,0.662085,,,,7.85398e-5
Test1,2-Recover,91.637,1.199,1.578,0.052,,0.568239,662.085,,56.8239,0.662085,,,,7.85398e-5
Test1,2-Recover,92.003,1.219,1.558,0.052,,0.561037,662.085,,56.1037,0.662085,,,,7.85398e-5
Test1,2-Recover,92.370,1.239,1.538,0.038,,0.553835,483.831,,55.3835,0.483831,,,,7.85398e-5
Test1,2-Recover,92.737,1.26,1.517,0.038,,0.546273,483.831,,54.6273,0.483831,,,,7.85398e-5
Test1,2-Recover,93.103,1.28,1.497,0.025,,0.539071,318.31,,53.9071,0.31831,,,,7.85398e-5
Test1,2-Recover,93.470,1.301,1.476,0.038,,0.531509,483.831,,53.1509,0.483831,,,,7.85398e-5
Test1,2-Recover,93.837,1.321,1.456,0.025,,0.524307,318.31,,52.4307,0.31831,,,,7.85398e-5
Test1,2-Recover,94.203,1.341,1.436,0.031,,0.517105,394.704,,51.7105,0.394704,,,,7.85398e-5
Test1,2-Recover,94.570,1.362,1.415,0.031,,0.509543,394.704,,50.9543,0.394704,,,,7.85398e-5
Test1,2-Recover,94.937,1.383,1.394,0.025,,0.501981,318.31,,50.1981,0.31831,,,,7.85398e-5
Test1,2-Recover,95.303,1.403,1.374,0.018,,0.494779,229.183,,49.4779,0.229183,,,,7.85398e-5
Test1,2-Recover,95.670,1.423,1.354,0.004,,0.487577,50.9296,,48.7577,0.0509296,,,,7.85398e-5
Test1,2-Recover,96.037,1.443,1.334,0.011,,0.480375,140.056,,48.0375,0.140056,,,,7.85398e-5
Test1,2-Recover,96.403,1.464,1.313,0.025,,0.472812,318.31,,47.2812,0.31831,,,,7.85398e-5
Test1,2-Recover,96.770,1.484,1.293,0.025,,0.46561,318.31,,46.561,0.31831,,,,7.85398e-5
Test1,2-Recover,97.137,1.505,1.272,0.011,,0.458048,140.056,,45.8048,0.140056,,,,7.85398e-5
Test1,2-Recover,97.503,1.525,1.252,0.011,,0.450846,140.056,,45.0846,0.140056,,,,7.85398e-5
Test1,2-Recover,97.870,1.545,1.232,0.011,,0.443644,140.056,,44.3644,0.140056,,,,7.85398e-5
Test1,2-Recover,98.237,1.566,1.211,0.004,,0.436082,50.9296,,43.6082,0.0509296,,,,7.85398e-5
Test1,2-Recover,98.603,1.586,1.191,0.004,,0.42888,50.9296,,42.888,0.0509296,,,,7.85398e-5
Test1,2-Recover,98.970,1.606,1.171,0.004,,0.421678,50.9296,,42.1678,0.0509296,,,,7.85398e-5
Test1,2-Recover,99.337,1.627,1.15,0.018,,0.414116,229.183,,41.4116,0.229183,,,,7.85398e-5
Test1,2-Recover,99.703,1.647,1.13,0.011,,0.406914,140.056,,40.6914,0.140056,,,,7.85398e-5
Test1,2-Recover,100.070,1.668,1.109,0.004,,0.399352,50.9296,,39.9352,0.0509296,,,,7.85398e-5
Test1,2-Recover,100.437,1.688,1.089,0.004,,0.39215,50.9296,,39.215,0.0509296,,,,7.85398e-5
Test1,2-Recover,100.803,1.708,1.069,0.004,,0.384948,50.9296,,38.4948,0.0509296,,,,7.85398e-5
Test1,2-Recover,101.170,1.729,1.048,0.011,,0.377386,140.056,,37.7386,0.140056,,,,7.85398e-5
Test1,2-Recover,101.537,1.75,1.027,0.011,,0.369824,140.056,,36.9824,0.140056,,,,7.85398e-5
Test1,2-Recover,101.903,1.769,1.008,0.004,,0.362982,50.9296,,36.2982,0.0509296,,,,7.85398e-5
Test1,2-Recover,102.270,1.79,0.987,0.004,,0.35542,50.9296,,35.542,0.0509296,,,,7.85398e-5
Test1,2-Recover,102.637,1.811,0.966,-0.003,,0.347857,-38.1972,,34.7857,-0.0381972,,,,7.85398e-5
Test1,2-Recover,103.003,1.831,0.946,0.004,,0.340655,50.9296,,34.0655,0.0509296,,,,7.85398e-5
Test1,2-Recover,103.370,1.851,0.926,0.004,,0.333453,50.9296,,33.3453,0.0509296,,,,7.85398e-5
Test1,2-Recover,103.737,1.872,0.905,0.011,,0.325891,140.056,,32.5891,0.140056,,,,7.85398e-5
Test1,2-Recover,104.103,1.892,0.885,0.011,,0.318689,140.056,,31.8689,0.140056,,,,7.85398e-5
Test1,2-Recover,104.470,1.913,0.864,0.004,,0.311127,50.9296,,31.1127,0.0509296,,,,7.85398e-5
Test1,2-Recover,104.837,1.933,0.844,-0.003,,0.303925,-38.1972,,30.3925,-0.0381972,,,,7.85398e-5
Test1,2-Recover,105.203,1.953,0.824,-0.003,,0.296723,-38.1972,,29.6723,-0.0381972,,,,7.85398e-5
Test1,2-Recover,105.570,1.973,0.804,-0.003,,0.289521,-38.1972,,28.9521,-0.0381972,,,,7.85398e-5
Test1,2-Recover,105.937,1.995,0.782,0.004,,0.281599,50.9296,,28.1599,0.0509296,,,,7.85398e-5
Test1,2-Recover,106.303,2.014,0.763,0.004,,0.274757,50.9296,,27.4757,0.0509296,,,,7.85398e-5
Test1,2-Recover,106.670,2.035,0.742,0.011,,0.267195,140.056,,26.7195,0.140056,,,,7.85398e-5
Test1,2-Recover,107.037,2.055,0.722,-0.003,,0.259993,-38.1972,,25.9993,-0.0381972,,,,7.85398e-5
Test1,2-Recover,107.403,2.076,0.701,-0.003,,0.252431,-38.1972,,25.2431,-0.0381972,,,,7.85398e-5
Test1,2-Recover,107.770,2.096,0.681,-0.003,,0.245229,-38.1972,,24.5229,-0.0381972,,,,7.85398e-5
Test1,2-Recover,108.137,2.117,0.66,-0.003,,0.237667,-38.1972,,23.7667,-0.0381972,,,,7.85398e-5
Test1,2-Recover,108.503,2.136,0.641,0.004,,0.230825,50.9296,,23.0825,0.0509296,,,,7.85398e-5
Test1,2-Recover,108.870,2.157,0.62,0.011,,0.223263,140.056,,22.3263,0.140056,,,,7.85398e-5
Test1,2-Recover,109.237,2.178,0.599,0.011,,0.2157,140.056,,21.57,0.140056,,,,7.85398e-5
Test1,2-Recover,109.603,2.198,0.579,-0.003,,0.208498,-38.1972,,20.8498,-0.0381972,,,,7.85398e-5
Test1,2-Recover,109.970,2.218,0.559,-0.003,,0.201296,-38.1972,,20.1296,-0.0381972,,,,7.85398e-5
Test1,2-Recover,110.337,2.239,0.538,-0.003,,0.193734,-38.1972,,19.3734,-0.0381972,,,,7.85398e-5
Test1,2-Recover,110.703,2.259,0.518,-0.003,,0.186532,-38.1972,,18.6532,-0.0381972,,,,7.85398e-5
Test1,2-Recover,111.070,2.28,0.497,0.004,,0.17897,50.9296,,17.897,0.0509296,,,,7.85398e-5
Test1,2-Recover,111.437,2.3,0.477,0.011,,0.171768,140.056,,17.1768,0.140056,,,,7.85398e-5
Test1,2-Recover,111.803,2.32,0.457,0.011,,0.164566,140.056,,16.4566,0.140056,,,,7.85398e-5
Test1,2-Recover,112.170,2.341,0.436,-0.003,,0.157004,-38.1972,,15.7004,-0.0381972,,,,7.85398e-5
Test1,2-Recover,112.537,2.361,0.416,-0.003,,0.149802,-38.1972,,14.9802,-0.0381972,,,,7.85398e-5
Test1,2-Recover,112.903,2.381,0.396,-0.003,,0.1426,-38.1972,,14.26,-0.0381972,,,,7.85398e-5
Test1,2-Recover,113.270,2.402,0.375,-0.003,,0.135038,-38.1972,,13.5038,-0.0381972,,,,7.85398e-5
Test1,2-Recover,113.637,2.423,0.354,0.004,,0.127476,50.9296,,12.7476,0.0509296,,,,7.85398e-5
Test1,2-Recover,114.003,2.443,0.334,0.011,,0.120274,140.056,,12.0274,0.140056,,,,7.85398e-5
Test1,2-Recover,114.370,2.463,0.314,0.004,,0.113072,50.9296,,11.3072,0.0509296,,,,7.85398e-5
Test1,2-Recover,114.737,2.484,0.293,-0.003,,0.10551,-38.1972,,10.551,-0.0381972,,,,7.85398e-5
Test1,2-Recover,115.103,2.504,0.273,-0.003,,0.0983075,-38.1972,,9.83075,-0.0381972,,,,7.85398e-5
Test1,2-Recover,115.470,2.525,0.252,-0.003,,0.0907454,-38.1972,,9.07454,-0.0381972,,,,7.85398e-5
Test1,2-Recover,115.837,2.545,0.232,-0.003,,0.0835434,-38.1972,,8.35434,-0.0381972,,,,7.85398e-5
Test1,2-Recover,116.203,2.565,0.212,-0.003,,0.0763414,-38.1972,,7.63414,-0.0381972,,,,7.85398e-5
Test1,2-Recover,116.570,2.586,0.191,0.011,,0.0687793,140.056,,6.87793,0.140056,,,,7.85398e-5
Test1,2-Recover,116.937,2.606,0.171,0.004,,0.0615772,50.9296,,6.15772,0.0509296,,,,7.85398e-5
Test1,2-Recover,117.303,2.626,0.151,-0.003,,0.0543752,-38.1972,,5.43752,-0.0381972,,,,7.85398e-5
Test1,2-Recover,117.670,2.647,0.13,-0.003,,0.0468131,-38.1972,,4.68131,-0.0381972,,,,7.85398e-5
Test1,2-Recover,118.037,2.667,0.11,-0.003,,0.0396111,-38.1972,,3.96111,-0.0381972,,,,7.85398e-5
Test1,2-Recover,118.403,2.688,0.089,0.004,,0.032049,50.9296,,3.2049,0.0509296,,,,7.85398e-5
Test1,2-Recover,118.770,2.708,0.069,-0.003,,0.024847,-38.1972,,2.4847,-0.0381972,,,,7.85398e-5
Test1,2-Recover,119.137,2.728,0.049,0.004,,0.0176449,50.9296,,1.76449,0.0509296,,,,7.85398e-5
Test1,2-Recover,119.503,2.748,0.029,0.004,,0.0104429,50.9296,,1.04429,0.0509296,,,,7.85398e-5
Test1,2-Recover,119.870,2.769,0.008,-0.003,,0.00288081,-38.1972,,0.288081,-0.0381972,,,,7.85398e-5
Test1,3-Compress,120.223,2.769,0.008,-0.003,,0.00288081,-38.1972,,0.288081,-0.0381972,,,,7.85398e-5
Test1,3-Compress,120.590,2.749,0.028,-0.003,,0.0100828,-38.1972,,1.00828,-0.0381972,,,,7.85398e-5
Test1,3-Compress,120.957,2.728,0.049,0.004,,0.0176449,50.9296,,1.76449,0.0509296,,,,7.85398e-5
Test1,3-Compress,121.323,2.708,0.069,0.004,,0.024847,50.9296,,2.4847,0.0509296,,,,7.85398e-5
Test1,3-Compress,121.690,2.688,0.089,0.011,,0.032049,140.056,,3.2049,0.140056,,,,7.85398e-5
Test1,3-Compress,122.057,2.667,0.11,-0.003,,0.0396111,-38.1972,,3.96111,-0.0381972,,,,7.85398e-5
Test1,3-Compress,122.423,2.647,0.13,-0.003,,0.0468131,-38.1972,,4.68131,-0.0381972,,,,7.85398e-5
Test1,3-Compress,122.790,2.626,0.151,-0.003,,0.0543752,-38.1972,,5.43752,-0.0381972,,,,7.85398e-5
Test1,3-Compress,123.157,2.606,0.171,-0.003,,0.0615772,-38.1972,,6.15772,-0.0381972,,,,7.85398e-5
Test1,3-Compress,123.523,2.586,0.191,0.004,,0.0687793,50.9296,,6.87793,0.0509296,,,,7.85398e-5
Test1,3-Compress,123.890,2.565,0.212,0.004,,0.0763414,50.9296,,7.63414,0.0509296,,,,7.85398e-5
Test1,3-Compress,124.257,2.544,0.233,0.011,,0.0839035,140.056,,8.39035,0.140056,,,,7.85398e-5
Test1,3-Compress,124.623,2.525,0.252,0.004,,0.0907454,50.9296,,9.07454,0.0509296,,,,7.85398e-5
Test1,3-Compress,124.990,2.504,0.273,-0.003,,0.0983075,-38.1972,,9.83075,-0.0381972,,,,7.85398e-5
Test1,3-Compress,125.357,2.484,0.293,-0.003,,0.10551,-38.1972,,10.551,-0.0381972,,,,7.85398e-5
Test1,3-Compress,125.723,2.463,0.314,-0.003,,0.113072,-38.1972,,11.3072,-0.0381972,,,,7.85398e-5
Test1,3-Compress,126.090,2.443,0.334,0.004,,0.120274,50.9296,,12.0274,0.0509296,,,,7.85398e-5
Test1,3-Compress,126.457,2.422,0.355,0.004,,0.127836,50.9296,,12.7836,0.0509296,,,,7.85398e-5
Test1,3-Compress,126.823,2.402,0.375,0.011,,0.135038,140.056,,13.5038,0.140056,,,,7.85398e-5
Test1,3-Compress,127.190,2.382,0.395,0.004,,0.14224,50.9296,,14.224,0.0509296,,,,7.85398e-5
Test1,3-Compress,127.557,2.361,0.416,-0.003,,0.149802,-38.1972,,14.9802,-0.0381972,,,,7.85398e-5
Test1,3-Compress,127.923,2.341,0.436,-0.003,,0.157004,-38.1972,,15.7004,-0.0381972,,,,7.85398e-5
Test1,3-Compress,128.290,2.321,0.456,-0.003,,0.164206,-38.1972,,16.4206,-0.0381972,,,,7.85398e-5
Test1,3-Compress,128.657,2.3,0.477,0.004,,0.171768,50.9296,,17.1768,0.0509296,,,,7.85398e-5
Test1,3-Compress,129.023,2.28,0.497,0.011,,0.17897,140.056,,17.897,0.140056,,,,7.85398e-5
Test1,3-Compress,129.390,2.259,0.518,0.011,,0.186532,140.056,,18.6532,0.140056,,,,7.85398e-5
Test1,3-Compress,129.757,2.239,0.538,-0.003,,0.193734,-38.1972,,19.3734,-0.0381972,,,,7.85398e-5
Test1,3-Compress,130.123,2.219,0.558,-0.003,,0.200936,-38.1972,,20.0936,-0.0381972,,,,7.85398e-5
Test1,3-Compress,130.490,2.198,0.579,-0.003,,0.208498,-38.1972,,20.8498,-0.0381972,,,,7.85398e-5
Test1,3-Compress,130.857,2.177,0.6,-0.003,,0.21606,-38.1972,,21.606,-0.0381972,,,,7.85398e-5
Test1,3-Compress,131.223,2.158,0.619,0.004,,0.222902,50.9296,,22.2902,0.0509296,,,,7.85398e-5
Test1,3-Compress,131.590,2.137,0.64,0.011,,0.230465,140.056,,23.0465,0.140056,,,,7.85398e-5
Test1,3-Compress,131.957,2.116,0.661,0.004,,0.238027,50.9296,,23.8027,0.0509296,,,,7.85398e-5
Test1,3-Compress,132.323,2.096,0.681,-0.003,,0.245229,-38.1972,,24.5229,-0.0381972,,,,7.85398e-5
Test1,3-Compress,132.690,2.076,0.701,-0.003,,0.252431,-38.1972,,25.2431,-0.0381972,,,,7.85398e-5
Test1,3-Compress,133.057,2.055,0.722,0.004,,0.259993,50.9296,,25.9993,0.0509296,,,,7.85398e-5
Test1,3-Compress,133.423,2.035,0.742,-0.003,,0.267195,-38.1972,,26.7195,-0.0381972,,,,7.85398e-5
Test1,3-Compress,133.790,2.014,0.763,0.004,,0.274757,50.9296,,27.4757,0.0509296,,,,7.85398e-5
Test1,3-Compress,134.157,1.994,0.783,0.011,,0.281959,140.056,,28.1959,0.140056,,,,7.85398e-5
Test1,3-Compress,134.523,1.974,0.803,0.011,,0.289161,140.056,,28.9161,0.140056,,,,7.85398e-5
Test1,3-Compress,134.890,1.954,0.823,0.004,,0.296363,50.9296,,29.6363,0.0509296,,,,7.85398e-5
Test1,3-Compress,135.257,1.932,0.845,0.004,,0.304285,50.9296,,30.4285,0.0509296,,,,7.85398e-5
Test1,3-Compress,135.623,1.913,0.864,0.004,,0.311127,50.9296,,31.1127,0.0509296,,,,7.85398e-5
Test1,3-Compress,135.990,1.892,0.885,0.004,,0.318689,50.9296,,31.8689,0.0509296,,,,7.85398e-5
Test1,3-Compress,136.357,1.872,0.905,0.004,,0.325891,50.9296,,32.5891,0.0509296,,,,7.85398e-5
Test1,3-Compress,136.723,1.851,0.926,0.011,,0.333453,140.056,,33.3453,0.140056,,,,7.85398e-5
Test1,3-Compress,137.090,1.831,0.946,0.011,,0.340655,140.056,,34.0655,0.140056,,,,7.85398e-5
Test1,3-Compress,137.457,1.81,0.967,0.011,,0.348218,140.056,,34.8218,0.140056,,,,7.85398e-5
Test1,3-Compress,137.823,1.791,0.986,0.011,,0.355059,140.056,,35.5059,0.140056,,,,7.85398e-5
Test1,3-Compress,138.190,1.77,1.007,0.004,,0.362622,50.9296,,36.2622,0.0509296,,,,7.85398e-5
Test1,3-Compress,138.557,1.749,1.028,0.004,,0.370184,50.9296,,37.0184,0.0509296,,,,7.85398e-5
Test1,3-Compress,138.923,1.729,1.048,0.004,,0.377386,50.9296,,37.7386,0.0509296,,,,7.85398e-5
Test1,3-Compress,139.290,1.709,1.068,0.018,,0.384588,229.183,,38.4588,0.229183,,,,7.85398e-5
Test1,3-Compress,139.657,1.688,1.089,0.031,,0.39215,394.704,,39.215,0.394704,,,,7.85398e-5
Test1,3-Compress,140.023,1.668,1.109,0.018,,0.399352,229.183,,39.9352,0.229183,,,,7.85398e-5
Test1,3-Compress,140.390,1.647,1.13,0.011,,0.406914,140.056,,40.6914,0.140056,,,,7.85398e-5
Test1,3-Compress,140.757,1.627,1.15,0.004,,0.414116,50.9296,,41.4116,0.0509296,,,,7.85398e-5
Test1,3-Compress,141.123,1.607,1.17,0.004,,0.421318,50.9296,,42.1318,0.0509296,,,,7.85398e-5
Test1,3-Compress,141.490,1.586,1.191,0.025,,0.42888,318.31,,42.888,0.31831,,,,7.85398e-5
Test1,3-Compress,141.857,1.566,1.211,0.031,,0.436082,394.704,,43.6082,0.394704,,,,7.85398e-5
Test1,3-Compress,142.223,1.546,1.231,0.031,,0.443284,394.704,,44.3284,0.394704,,,,7.85398e-5
Test1,3-Compress,142.590,1.525,1.252,0.031,,0.450846,394.704,,45.0846,0.394704,,,,7.85398e-5
Test1,3-Compress,142.957,1.504,1.273,0.038,,0.458408,483.831,,45.8408,0.483831,,,,7.85398e-5
Test1,3-Compress,143.323,1.484,1.293,0.025,,0.46561,318.31,,46.561,0.31831,,,,7.85398e-5
Test1,3-Compress,143.690,1.464,1.313,0.018,,0.472812,229.183,,47.2812,0.229183,,,,7.85398e-5
Test1,3-Compress,144.057,1.443,1.334,0.025,,0.480375,318.31,,48.0375,0.31831,,,,7.85398e-5
Test1,3-Compress,144.423,1.423,1.354,0.045,,0.487577,572.958,,48.7577,0.572958,,,,7.85398e-5
Test1,3-Compress,144.790,1.403,1.374,0.052,,0.494779,662.085,,49.4779,0.662085,,,,7.85398e-5
Test1,3-Compress,145.157,1.382,1.395,0.031,,0.502341,394.704,,50.2341,0.394704,,,,7.85398e-5
Test1,3-Compress,145.523,1.362,1.415,0.052,,0.509543,662.085,,50.9543,0.662085,,,,7.85398e-5
Test1,3-Compress,145.890,1.341,1.436,0.052,,0.517105,662.085,,51.7105,0.662085,,,,7.85398e-5
Test1,3-Compress,146.257,1.321,1.456,0.045,,0.524307,572.958,,52.4307,0.572958,,,,7.85398e-5
Test1,3-Compress,146.623,1.301,1.476,0.052,,0.531509,662.085,,53.1509,0.662085,,,,7.85398e-5
Test1,3-Compress,146.990,1.28,1.497,0.045,,0.539071,572.958,,53.9071,0.572958,,,,7.85398e-5
Test1,3-Compress,147.357,1.26,1.517,0.052,,0.546273,662.085,,54.6273,0.662085,,,,7.85398e-5
Test1,3-Compress,147.723,1.239,1.538,0.052,,0.553835,662.085,,55.3835,0.662085,,,,7.85398e-5
Test1,3-Compress,148.090,1.219,1.558,0.052,,0.561037,662.085,,56.1037,0.662085,,,,7.85398e-5
Test1,3-Compress,148.457,1.199,1.578,0.052,,0.568239,662.085,,56.8239,0.662085,,,,7.85398e-5
Test1,3-Compress,148.823,1.179,1.598,0.052,,0.575441,662.085,,57.5441,0.662085,,,,7.85398e-5
Test1,3-Compress,149.190,1.158,1.619,0.052,,0.583003,662.085,,58.3003,0.662085,,,,7.85398e-5
Test1,3-Compress,149.557,1.137,1.64,0.052,,0.590565,662.085,,59.0565,0.662085,,,,7.85398e-5
Test1,3-Compress,149.923,1.117,1.66,0.052,,0.597767,662.085,,59.7767,0.662085,,,,7.85398e-5
Test1,3-Recover,150.267,1.121,1.656,0.052,,0.596327,662.085,,59.6327,0.662085,,,,7.85398e-5
Test1,3-Recover,150.633,1.14,1.637,0.052,,0.589485,662.085,,58.9485,0.662085,,,,7.85398e-5
Test1,3-Recover,151.000,1.161,1.616,0.052,,0.581923,662.085,,58.1923,0.662085,,,,7.85398e-5
Test1,3-Recover,151.367,1.181,1.596,0.045,,0.574721,572.958,,57.4721,0.572958,,,,7.85398e-5
Test1,3-Recover,151.733,1.202,1.575,0.052,,0.567159,662.085,,56.7159,0.662085,,,,7.85398e-5
Test1,3-Recover,152.100,1.222,1.555,0.052,,0.559957,662.085,,55.9957,0.662085,,,,7.85398e-5
Test1,3-Recover,152.467,1.243,1.534,0.045,,0.552395,572.958,,55.2395,0.572958,,,,7.85398e-5
Test1,3-Recover,152.833,1.263,1.514,0.038,,0.545193,483.831,,54.5193,0.483831,,,,7.85398e-5
Test1,3-Recover,153.200,1.284,1.493,0.045,,0.537631,572.958,,53.7631,0.572958,,,,7.85398e-5
Test1,3-Recover,153.567,1.304,1.473,0.031,,0.530429,394.704,,53.0429,0.394704,,,,7.85398e-5
Test1,3-Recover,153.933,1.324,1.453,0.031,,0.523227,394.704,,52.3227,0.394704,,,,7.85398e-5
Test1,3-Recover,154.300,1.344,1.433,0.018,,0.516024,229.183,,51.6024,0.229183,,,,7.85398e-5
Test1,3-Recover,154.667,1.365,1.412,0.031,,0.508462,394.704,,50.8462,0.394704,,,,7.85398e-5
Test1,3-Recover,155.033,1.385,1.392,0.025,,0.50126,318.31,,50.126,0.31831,,,,7.85398e-5
Test1,3-Recover,155.400,1.406,1.371,0.018,,0.493698,229.183,,49.3698,0.229183,,,,7.85398e-5
Test1,3-Recover,155.767,1.426,1.351,0.011,,0.486496,140.056,,48.6496,0.140056,,,,7.85398e-5
Test1,3-Recover,156.133,1.447,1.33,0.004,,0.478934,50.9296,,47.8934,0.0509296,,,,7.85398e-5
Test1,3-Recover,156.500,1.467,1.31,0.004,,0.471732,50.9296,,47.1732,0.0509296,,,,7.85398e-5
Test1,3-Recover,156.867,1.488,1.289,0.018,,0.46417,229.183,,46.417,0.229183,,,,7.85398e-5
Test1,3-Recover,157.233,1.507,1.27,0.031,,0.457328,394.704,,45.7328,0.394704,,,,7.85398e-5
Test1,3-Recover,157.600,1.528,1.249,0.018,,0.449766,229.183,,44.9766,0.229183,,,,7.85398e-5
Test1,3-Recover,157.967,1.549,1.228,0.018,,0.442204,229.183,,44.2204,0.229183,,,,7.85398e-5
Test1,3-Recover,158.333,1.569,1.208,0.011,,0.435002,140.056,,43.5002,0.140056,,,,7.85398e-5
Test1,3-Recover,158.700,1.589,1.188,0.004,,0.4278,50.9296,,42.78,0.0509296,,,,7.85398e-5
Test1,3-Recover,159.067,1.61,1.167,0.004,,0.420238,50.9296,,42.0238,0.0509296,,,,7.85398e-5
Test1,3-Recover,159.433,1.63,1.147,0.011,,0.413036,140.056,,41.3036,0.140056,,,,7.85398e-5
Test1,3-Recover,159.800,1.651,1.126,0.011,,0.405474,140.056,,40.5474,0.140056,,,,7.85398e-5
Test1,3-Recover,160.167,1.671,1.106,0.011,,0.398272,140.056,,39.8272,0.140056,,,,7.85398e-5
Test1,3-Recover,160.533,1.691,1.086,0.011,,0.391069,140.056,,39.1069,0.140056,,,,7.85398e-5
Test1,3-Recover,160.900,1.712,1.065,0.004,,0.383507,50.9296,,38.3507,0.0509296,,,,7.85398e-5
Test1,3-Recover,161.267,1.733,1.044,0.004,,0.375945,50.9296,,37.5945,0.0509296,,,,7.85398e-5
Test1,3-Recover,161.633,1.752,1.025,0.004,,0.369103,50.9296,,36.9103,0.0509296,,,,7.85398e-5
Test1,3-Recover,162.000,1.773,1.004,0.011,,0.361541,140.056,,36.1541,0.140056,,,,7.85398e-5
Test1,3-Recover,162.367,1.793,0.984,0.004,,0.354339,50.9296,,35.4339,0.0509296,,,,7.85398e-5
Test1,3-Recover,162.733,1.814,0.963,0.004,,0.346777,50.9296,,34.6777,0.0509296,,,,7.85398e-5
Test1,3-Recover,163.100,1.834,0.943,-0.003,,0.339575,-38.1972,,33.9575,-0.0381972,,,,7.85398e-5
Test1,3-Recover,163.467,1.855,0.922,0.004,,0.332013,50.9296,,33.2013,0.0509296,,,,7.85398e-5
Test1,3-Recover,163.833,1.875,0.902,-0.003,,0.324811,-38.1972,,32.4811,-0.0381972,,,,7.85398e-5
Test1,3-Recover,164.200,1.896,0.881,0.004,,0.317249,50.9296,,31.7249,0.0509296,,,,7.85398e-5
Test1,3-Recover,164.567,1.916,0.861,0.011,,0.310047,140.056,,31.0047,0.140056,,,,7.85398e-5
Test1,3-Recover,164.933,1.936,0.841,0.004,,0.302845,50.9296,,30.2845,0.0509296,,,,7.85398e-5
Test1,3-Recover,165.300,1.956,0.821,-0.003,,0.295643,-38.1972,,29.5643,-0.0381972,,,,7.85398e-5
Test1,3-Recover,165.667,1.977,0.8,-0.003,,0.288081,-38.1972,,28.8081,-0.0381972,,,,7.85398e-5
Test1,3-Recover,166.033,1.997,0.78,-0.003,,0.280879,-38.1972,,28.0879,-0.0381972,,,,7.85398e-5
Test1,3-Recover,166.400,2.018,0.759,0.004,,0.273317,50.9296,,27.3317,0.0509296,,,,7.85398e-5
Test1,3-Recover,166.767,2.038,0.739,0.004,,0.266115,50.9296,,26.6115,0.0509296,,,,7.85398e-5
Test1,3-Recover,167.133,2.059,0.718,0.011,,0.258552,140.056,,25.8552,0.140056,,,,7.85398e-5
Test1,3-Recover,167.500,2.079,0.698,0.004,,0.25135,50.9296,,25.135,0.0509296,,,,7.85398e-5
Test1,3-Recover,167.867,2.099,0.678,-0.003,,0.244148,-38.1972,,24.4148,-0.0381972,,,,7.85398e-5
Test1,3-Recover,168.233,2.119,0.658,-0.003,,0.236946,-38.1972,,23.6946,-0.0381972,,,,7.85398e-5
Test1,3-Recover,168.600,2.14,0.637,-0.003,,0.229384,-38.1972,,22.9384,-0.0381972,,,,7.85398e-5
Test1,3-Recover,168.967,2.161,0.616,0.004,,0.221822,50.9296,,22.1822,0.0509296,,,,7.85398e-5
Test1,3-Recover,169.333,2.181,0.596,0.004,,0.21462,50.9296,,21.462,0.0509296,,,,7.85398e-5
Test1,3-Recover,169.700,2.201,0.576,0.011,,0.207418,140.056,,20.7418,0.140056,,,,7.85398e-5
Test1,3-Recover,170.067,2.222,0.555,0.004,,0.199856,50.9296,,19.9856,0.0509296,,,,7.85398e-5
Test1,3-Recover,170.433,2.242,0.535,-0.003,,0.192654,-38.1972,,19.2654,-0.0381972,,,,7.85398e-5
Test1,3-Recover,170.800,2.262,0.515,-0.003,,0.185452,-38.1972,,18.5452,-0.0381972,,,,7.85398e-5
Test1,3-Recover,171.167,2.283,0.494,-0.003,,0.17789,-38.1972,,17.789,-0.0381972,,,,7.85398e-5
Test1,3-Recover,171.533,2.303,0.474,-0.003,,0.170688,-38.1972,,17.0688,-0.0381972,,,,7.85398e-5
Test1,3-Recover,171.900,2.324,0.453,0.004,,0.163126,50.9296,,16.3126,0.0509296,,,,7.85398e-5
Test1,3-Recover,172.267,2.344,0.433,0.011,,0.155924,140.056,,15.5924,0.140056,,,,7.85398e-5
Test1,3-Recover,172.633,2.364,0.413,-0.003,,0.148722,-38.1972,,14.8722,-0.0381972,,,,7.85398e-5
Test1,3-Recover,173.000,2.385,0.392,-0.003,,0.14116,-38.1972,,14.116,-0.0381972,,,,7.85398e-5
Test1,3-Recover,173.367,2.405,0.372,-0.003,,0.133958,-38.1972,,13.3958,-0.0381972,,,,7.85398e-5
Test1,3-Recover,173.733,2.426,0.351,-0.003,,0.126395,-38.1972,,12.6395,-0.0381972,,,,7.85398e-5
Test1,3-Recover,174.100,2.446,0.331,0.004,,0.119193,50.9296,,11.9193,0.0509296,,,,7.85398e-5
Test1,3-Recover,174.467,2.466,0.311,0.004,,0.111991,50.9296,,11.1991,0.0509296,,,,7.85398e-5
Test1,3-Recover,174.833,2.487,0.29,0.011,,0.104429,140.056,,10.4429,0.140056,,,,7.85398e-5
Test1,3-Recover,175.200,2.507,0.27,-0.003,,0.0972272,-38.1972,,9.72272,-0.0381972,,,,7.85398e-5
Test1,3-Recover,175.567,2.528,0.249,-0.003,,0.0896651,-38.1972,,8.96651,-0.0381972,,,,7.85398e-5
Test1,3-Recover,175.933,2.548,0.229,-0.003,,0.0824631,-38.1972,,8.24631,-0.0381972,,,,7.85398e-5
Test1,3-Recover,176.300,2.568,0.209,-0.003,,0.0752611,-38.1972,,7.52611,-0.0381972,,,,7.85398e-5
Test1,3-Recover,176.667,2.589,0.188,0.004,,0.067699,50.9296,,6.7699,0.0509296,,,,7.85398e-5
Test1,3-Recover,177.033,2.609,0.168,0.004,,0.0604969,50.9296,,6.04969,0.0509296,,,,7.85398e-5
Test1,3-Recover,177.400,2.629,0.148,-0.003,,0.0532949,-38.1972,,5.32949,-0.0381972,,,,7.85398e-5
Test1,3-Recover,177.767,2.65,0.127,-0.003,,0.0457328,-38.1972,,4.57328,-0.0381972,,,,7.85398e-5
Test1,3-Recover,178.133,2.67,0.107,-0.003,,0.0385308,-38.1972,,3.85308,-0.0381972,,,,7.85398e-5
Test1,3-Recover,178.500,2.691,0.086,-0.003,,0.0309687,-38.1972,,3.09687,-0.0381972,,,,7.85398e-5
Test1,3-Recover,178.867,2.711,0.066,-0.003,,0.0237667,-38.1972,,2.37667,-0.0381972,,,,7.85398e-5
Test1,3-Recover,179.233,2.731,0.046,0.004,,0.0165646,50.9296,,1.65646,0.0509296,,,,7.85398e-5
Test1,3-Recover,179.600,2.752,0.025,0.004,,0.00900252,50.9296,,0.900252,0.0509296,,,,7.85398e-5
Test1,3-Recover,179.967,2.773,0.004,-0.003,,0.0014404,-38.1972,,0.14404,-0.0381972,,,,7.85398e-5
Test1,3-Recover,180.100,2.777,-0,-0.003,,0,-38.1972,,0,-0.0381972,,,,7.85398e-5