File: data/gamma_1-1-0.5_3.csv
SetName,Cycle,Time_S,Size_mm,Displacement_mm,Force_N,,Strain,Stress(Pascal),,%Strain,Stress(kPa),,,,Area(m^2)
Test1,1-Compress,0.000,3.363,-0,-0.003,,0,-38.1972,,0,-0.0381972,,,,7.85398e-5
Test1,1-Compress,0.367,3.339,0.024,-0.003,,0.00713649,-38.1972,,0.713649,-0.0381972,,,,7.85398e-5
Test1,1-Compress,0.733,3.315,0.048,0.004,,0.014273,50.9296,,1.4273,0.0509296,,,,7.85398e-5
Test1,1-Compress,1.100,3.289,0.074,0.004,,0.0220042,50.9296,,2.20042,0.0509296,,,,7.85398e-5
Test1,1-Compress,1.467,3.264,0.099,0.011,,0.029438,140.056,,2.9438,0.140056,,,,7.85398e-5
Test1,1-Compress,1.833,3.24,0.123,-0.003,,0.0365745,-38.1972,,3.65745,-0.0381972,,,,7.85398e-5
Test1,1-Compress,2.200,3.216,0.147,-0.003,,0.043711,-38.1972,,4.3711,-0.0381972,,,,7.85398e-5
Test1,1-Compress,2.567,3.19,0.173,-0.003,,0.0514422,-38.1972,,5.14422,-0.0381972,,,,7.85398e-5
Test1,1-Compress,2.933,3.166,0.197,-0.003,,0.0585787,-38.1972,,5.85787,-0.0381972,,,,7.85398e-5
Test1,1-Compress,3.300,3.141,0.222,0.004,,0.0660125,50.9296,,6.60125,0.0509296,,,,7.85398e-5
Test1,1-Compress,3.667,3.117,0.246,0.011,,0.073149,140.056,,7.3149,0.140056,,,,7.85398e-5
Test1,1-Compress,4.033,3.092,0.271,0.018,,0.0805828,229.183,,8.05828,0.229183,,,,7.85398e-5
Test1,1-Compress,4.400,3.067,0.296,-0.003,,0.0880167,-38.1972,,8.80167,-0.0381972,,,,7.85398e-5
Test1,1-Compress,4.767,3.042,0.321,-0.003,,0.0954505,-38.1972,,9.54505,-0.0381972,,,,7.85398e-5
Test1,1-Compress,5.133,3.018,0.345,-0.003,,0.102587,-38.1972,,10.2587,-0.0381972,,,,7.85398e-5
Test1,1-Compress,5.500,2.993,0.37,-0.003,,0.110021,-38.1972,,11.0021,-0.0381972,,,,7.85398e-5
Test1,1-Compress,5.867,2.968,0.395,0.004,,0.117455,50.9296,,11.7455,0.0509296,,,,7.85398e-5
Test1,1-Compress,6.233,2.944,0.419,0.011,,0.124591,140.056,,12.4591,0.140056,,,,7.85398e-5
Test1,1-Compress,6.600,2.919,0.444,0.004,,0.132025,50.9296,,13.2025,0.0509296,,,,7.85398e-5
Test1,1-Compress,6.967,2.894,0.469,-0.003,,0.139459,-38.1972,,13.9459,-0.0381972,,,,7.85398e-5
Test1,1-Compress,7.333,2.87,0.493,-0.003,,0.146595,-38.1972,,14.6595,-0.0381972,,,,7.85398e-5
Test1,1-Compress,7.700,2.845,0.518,-0.003,,0.154029,-38.1972,,15.4029,-0.0381972,,,,7.85398e-5
Test1,1-Compress,8.067,2.82,0.543,-0.003,,0.161463,-38.1972,,16.1463,-0.0381972,,,,7.85398e-5
Test1,1-Compress,8.433,2.796,0.567,0.004,,0.168599,50.9296,,16.8599,0.0509296,,,,7.85398e-5
Test1,1-Compress,8.800,2.771,0.592,0.004,,0.176033,50.9296,,17.6033,0.0509296,,,,7.85398e-5
Test1,1-Compress,9.167,2.746,0.617,0.004,,0.183467,50.9296,,18.3467,0.0509296,,,,7.85398e-5
Test1,1-Compress,9.533,2.722,0.641,-0.003,,0.190604,-38.1972,,19.0604,-0.0381972,,,,7.85398e-5
Test1,1-Compress,9.900,2.697,0.666,-0.003,,0.198037,-38.1972,,19.8037,-0.0381972,,,,7.85398e-5
Test1,1-Compress,10.267,2.672,0.691,-0.003,,0.205471,-38.1972,,20.5471,-0.0381972,,,,7.85398e-5
Test1,1-Compress,10.633,2.647,0.716,-0.003,,0.212905,-38.1972,,21.2905,-0.0381972,,,,7.85398e-5
Test1,1-Compress,11.000,2.622,0.741,0.004,,0.220339,50.9296,,22.0339,0.0509296,,,,7.85398e-5
Test1,1-Compress,11.367,2.598,0.765,0.011,,0.227475,140.056,,22.7475,0.140056,,,,7.85398e-5
Test1,1-Compress,11.733,2.573,0.79,0.004,,0.234909,50.9296,,23.4909,0.0509296,,,,7.85398e-5
Test1,1-Compress,12.100,2.548,0.815,0.004,,0.242343,50.9296,,24.2343,0.0509296,,,,7.85398e-5
Test1,1-Compress,12.467,2.523,0.84,-0.003,,0.249777,-38.1972,,24.9777,-0.0381972,,,,7.85398e-5
Test1,1-Compress,12.833,2.499,0.864,-0.003,,0.256913,-38.1972,,25.6913,-0.0381972,,,,7.85398e-5
Test1,1-Compress,13.200,2.474,0.889,0.004,,0.264347,50.9296,,26.4347,0.0509296,,,,7.85398e-5
Test1,1-Compress,13.567,2.449,0.914,0.004,,0.271781,50.9296,,27.1781,0.0509296,,,,7.85398e-5
Test1,1-Compress,13.933,2.425,0.938,0.011,,0.278918,140.056,,27.8918,0.140056,,,,7.85398e-5
Test1,1-Compress,14.300,2.4,0.963,0.011,,0.286351,140.056,,28.6351,0.140056,,,,7.85398e-5
Test1,1-Compress,14.667,2.375,0.988,0.011,,0.293785,140.056,,29.3785,0.140056,,,,7.85398e-5
Test1,1-Compress,15.033,2.351,1.012,0.004,,0.300922,50.9296,,30.0922,0.0509296,,,,7.85398e-5
Test1,1-Compress,15.400,2.326,1.037,0.004,,0.308356,50.9296,,30.8356,0.0509296,,,,7.85398e-5
Test1,1-Compress,15.767,2.301,1.062,0.004,,0.315789,50.9296,,31.5789,0.0509296,,,,7.85398e-5
Test1,1-Compress,16.133,2.277,1.086,0.004,,0.322926,50.9296,,32.2926,0.0509296,,,,7.85398e-5
Test1,1-Compress,16.500,2.252,1.111,0.011,,0.33036,140.056,,33.036,0.140056,,,,7.85398e-5
Test1,1-Compress,16.867,2.227,1.136,0.011,,0.337794,140.056,,33.7794,0.140056,,,,7.85398e-5
Test1,1-Compress,17.233,2.203,1.16,0.011,,0.34493,140.056,,34.493,0.140056,,,,7.85398e-5
Test1,1-Compress,17.600,2.178,1.185,-0.003,,0.352364,-38.1972,,35.2364,-0.0381972,,,,7.85398e-5
Test1,1-Compress,17.967,2.153,1.21,-0.003,,0.359798,-38.1972,,35.9798,-0.0381972,,,,7.85398e-5
Test1,1-Compress,18.333,2.129,1.234,0.004,,0.366934,50.9296,,36.6934,0.0509296,,,,7.85398e-5
Test1,1-Compress,18.700,2.104,1.259,0.011,,0.374368,140.056,,37.4368,0.140056,,,,7.85398e-5
Test1,1-Compress,19.067,2.079,1.284,0.025,,0.381802,318.31,,38.1802,0.31831,,,,7.85398e-5
Test1,1-Compress,19.433,2.055,1.308,0.025,,0.388938,318.31,,38.8938,0.31831,,,,7.85398e-5
Test1,1-Compress,19.800,2.03,1.333,0.011,,0.396372,140.056,,39.6372,0.140056,,,,7.85398e-5
Test1,1-Compress,20.167,2.004,1.359,0.004,,0.404103,50.9296,,40.4103,0.0509296,,,,7.85398e-5
Test1,1-Compress,20.533,1.981,1.382,0.004,,0.410943,50.9296,,41.0943,0.0509296,,,,7.85398e-5
Test1,1-Compress,20.900,1.956,1.407,0.004,,0.418376,50.9296,,41.8376,0.0509296,,,,7.85398e-5
Test1,1-Compress,21.267,1.931,1.432,0.011,,0.42581,140.056,,42.581,0.140056,,,,7.85398e-5
Test1,1-Compress,21.633,1.906,1.457,0.025,,0.433244,318.31,,43.3244,0.31831,,,,7.85398e-5
Test1,1-Compress,22.000,1.882,1.481,0.025,,0.440381,318.31,,44.0381,0.31831,,,,7.85398e-5
Test1,1-Compress,22.367,1.857,1.506,0.018,,0.447814,229.183,,44.7814,0.229183,,,,7.85398e-5
Test1,1-Compress,22.733,1.832,1.531,0.018,,0.455248,229.183,,45.5248,0.229183,,,,7.85398e-5
Test1,1-Compress,23.100,1.807,1.556,0.018,,0.462682,229.183,,46.2682,0.229183,,,,7.85398e-5
Test1,1-Compress,23.467,1.782,1.581,0.018,,0.470116,229.183,,47.0116,0.229183,,,,7.85398e-5
Test1,1-Compress,23.833,1.758,1.605,0.011,,0.477252,140.056,,47.7252,0.140056,,,,7.85398e-5
Test1,1-Compress,24.200,1.733,1.63,0.025,,0.484686,318.31,,48.4686,0.31831,,,,7.85398e-5
Test1,1-Compress,24.567,1.708,1.655,0.025,,0.49212,318.31,,49.212,0.31831,,,,7.85398e-5
Test1,1-Compress,24.933,1.684,1.679,0.031,,0.499257,394.704,,49.9257,0.394704,,,,7.85398e-5
Test1,1-Compress,25.300,1.659,1.704,0.018,,0.50669,229.183,,50.669,0.229183,,,,7.85398e-5
Test1,1-Compress,25.667,1.634,1.729,0.025,,0.514124,318.31,,51.4124,0.31831,,,,7.85398e-5
Test1,1-Compress,26.033,1.61,1.753,0.004,,0.521261,50.9296,,52.1261,0.0509296,,,,7.85398e-5
Test1,1-Compress,26.400,1.585,1.778,0.025,,0.528695,318.31,,52.8695,0.31831,,,,7.85398e-5
Test1,1-Compress,26.767,1.56,1.803,0.038,,0.536128,483.831,,53.6128,0.483831,,,,7.85398e-5
Test1,1-Compress,27.133,1.536,1.827,0.025,,0.543265,318.31,,54.3265,0.31831,,,,7.85398e-5
Test1,1-Compress,27.500,1.511,1.852,0.031,,0.550699,394.704,,55.0699,0.394704,,,,7.85398e-5
Test1,1-Compress,27.867,1.486,1.877,0.052,,0.558133,662.085,,55.8133,0.662085,,,,7.85398e-5
Test1,1-Compress,28.233,1.462,1.901,0.052,,0.565269,662.085,,56.5269,0.662085,,,,7.85398e-5
Test1,1-Compress,28.600,1.437,1.926,0.031,,0.572703,394.704,,57.2703,0.394704,,,,7.85398e-5
Test1,1-Compress,28.967,1.412,1.951,0.052,,0.580137,662.085,,58.0137,0.662085,,,,7.85398e-5
Test1,1-Compress,29.333,1.387,1.976,0.045,,0.587571,572.958,,58.7571,0.572958,,,,7.85398e-5
Test1,1-Compress,29.700,1.363,2,0.045,,0.594707,572.958,,59.4707,0.572958,,,,7.85398e-5
Test1,1-Recover,30.067,1.348,2.015,0.052,,0.599167,662.085,,59.9167,0.662085,,,,7.85398e-5
Test1,1-Recover,30.433,1.372,1.991,0.052,,0.592031,662.085,,59.2031,0.662085,,,,7.85398e-5
Test1,1-Recover,30.800,1.397,1.966,0.038,,0.584597,483.831,,58.4597,0.483831,,,,7.85398e-5
Test1,1-Recover,31.167,1.422,1.941,0.025,,0.577163,318.31,,57.7163,0.31831,,,,7.85398e-5
Test1,1-Recover,31.533,1.446,1.917,0.045,,0.570027,572.958,,57.0027,0.572958,,,,7.85398e-5
Test1,1-Recover,31.900,1.471,1.892,0.045,,0.562593,572.958,,56.2593,0.572958,,,,7.85398e-5
Test1,1-Recover,32.267,1.496,1.867,0.031,,0.555159,394.704,,55.5159,0.394704,,,,7.85398e-5
Test1,1-Recover,32.633,1.52,1.843,0.018,,0.548023,229.183,,54.8023,0.229183,,,,7.85398e-5
Test1,1-Recover,33.000,1.545,1.818,0.011,,0.540589,140.056,,54.0589,0.140056,,,,7.85398e-5
Test1,1-Recover,33.367,1.57,1.793,0.011,,0.533155,140.056,,53.3155,0.140056,,,,7.85398e-5
Test1,1-Recover,33.733,1.595,1.768,0.031,,0.525721,394.704,,52.5721,0.394704,,,,7.85398e-5
Test1,1-Recover,34.100,1.619,1.744,0.018,,0.518585,229.183,,51.8585,0.229183,,,,7.85398e-5
Test1,1-Recover,34.467,1.644,1.719,0.031,,0.511151,394.704,,51.1151,0.394704,,,,7.85398e-5
Test1,1-Recover,34.833,1.669,1.694,0.025,,0.503717,318.31,,50.3717,0.31831,,,,7.85398e-5
Test1,1-Recover,35.200,1.694,1.669,0.011,,0.496283,140.056,,49.6283,0.140056,,,,7.85398e-5
Test1,1-Recover,35.567,1.718,1.645,0.004,,0.489147,50.9296,,48.9147,0.0509296,,,,7.85398e-5
Test1,1-Recover,35.933,1.743,1.62,0.004,,0.481713,50.9296,,48.1713,0.0509296,,,,7.85398e-5
Test1,1-Recover,36.300,1.768,1.595,0.018,,0.474279,229.183,,47.4279,0.229183,,,,7.85398e-5
Test1,1-Recover,36.667,1.793,1.57,0.025,,0.466845,318.31,,46.6845,0.31831,,,,7.85398e-5
Test1,1-Recover,37.033,1.817,1.546,0.025,,0.459709,318.31,,45.9709,0.31831,,,,7.85398e-5
Test1,1-Recover,37.400,1.842,1.521,0.004,,0.452275,50.9296,,45.2275,0.0509296,,,,7.85398e-5
Test1,1-Recover,37.767,1.867,1.496,0.004,,0.444841,50.9296,,44.4841,0.0509296,,,,7.85398e-5
Test1,1-Recover,38.133,1.891,1.472,0.004,,0.437704,50.9296,,43.7704,0.0509296,,,,7.85398e-5
Test1,1-Recover,38.500,1.916,1.447,0.004,,0.430271,50.9296,,43.0271,0.0509296,,,,7.85398e-5
Test1,1-Recover,38.867,1.941,1.422,0.011,,0.422837,140.056,,42.2837,0.140056,,,,7.85398e-5
Test1,1-Recover,39.233,1.965,1.398,0.011,,0.4157,140.056,,41.57,0.140056,,,,7.85398e-5
Test1,1-Recover,39.600,1.99,1.373,0.004,,0.408266,50.9296,,40.8266,0.0509296,,,,7.85398e-5
Test1,1-Recover,39.967,2.015,1.348,0.011,,0.400833,140.056,,40.0833,0.140056,,,,7.85398e-5
Test1,1-Recover,40.333,2.039,1.324,0.011,,0.393696,140.056,,39.3696,0.140056,,,,7.85398e-5
Test1,1-Recover,40.700,2.064,1.299,-0.003,,0.386262,-38.1972,,38.6262,-0.0381972,,,,7.85398e-5
Test1,1-Recover,41.067,2.089,1.274,0.004,,0.378828,50.9296,,37.8828,0.0509296,,,,7.85398e-5
Test1,1-Recover,41.433,2.113,1.25,0.011,,0.371692,140.056,,37.1692,0.140056,,,,7.85398e-5
Test1,1-Recover,41.800,2.138,1.225,0.004,,0.364258,50.9296,,36.4258,0.0509296,,,,7.85398e-5
Test1,1-Recover,42.167,2.163,1.2,0.011,,0.356824,140.056,,35.6824,0.140056,,,,7.85398e-5
Test1,1-Recover,42.533,2.188,1.175,0.004,,0.34939,50.9296,,34.939,0.0509296,,,,7.85398e-5
Test1,1-Recover,42.900,2.212,1.151,0.004,,0.342254,50.9296,,34.2254,0.0509296,,,,7.85398e-5
Test1,1-Recover,43.267,2.237,1.126,-0.003,,0.33482,-38.1972,,33.482,-0.0381972,,,,7.85398e-5
Test1,1-Recover,43.633,2.261,1.102,0.004,,0.327684,50.9296,,32.7684,0.0509296,,,,7.85398e-5
Test1,1-Recover,44.000,2.287,1.076,0.011,,0.319952,140.056,,31.9952,0.140056,,,,7.85398e-5
Test1,1-Recover,44.367,2.311,1.052,0.004,,0.312816,50.9296,,31.2816,0.0509296,,,,7.85398e-5
Test1,1-Recover,44.733,2.335,1.028,-0.003,,0.305679,-38.1972,,30.5679,-0.0381972,,,,7.85398e-5
Test1,1-Recover,45.100,2.36,1.003,-0.003,,0.298246,-38.1972,,29.8246,-0.0381972,,,,7.85398e-5
Test1,1-Recover,45.467,2.386,0.977,-0.003,,0.290514,-38.1972,,29.0514,-0.0381972,,,,7.85398e-5
Test1,1-Recover,45.833,2.41,0.953,-0.003,,0.283378,-38.1972,,28.3378,-0.0381972,,,,7.85398e-5
Test1,1-Recover,46.200,2.434,0.929,0.004,,0.276241,50.9296,,27.6241,0.0509296,,,,7.85398e-5
Test1,1-Recover,46.567,2.459,0.904,0.011,,0.268808,140.056,,26.8808,0.140056,,,,7.85398e-5
Test1,1-Recover,46.933,2.484,0.879,0.004,,0.261374,50.9296,,26.1374,0.0509296,,,,7.85398e-5
Test1,1-Recover,47.300,2.509,0.854,-0.003,,0.25394,-38.1972,,25.394,-0.0381972,,,,7.85398e-5
Test1,1-Recover,47.667,2.533,0.83,-0.003,,0.246803,-38.1972,,24.6803,-0.0381972,,,,7.85398e-5
Test1,1-Recover,48.033,2.558,0.805,0.004,,0.23937,50.9296,,23.937,0.0509296,,,,7.85398e-5
Test1,1-Recover,48.400,2.583,0.78,0.004,,0.231936,50.9296,,23.1936,0.0509296,,,,7.85398e-5
Test1,1-Recover,48.767,2.608,0.755,0.004,,0.224502,50.9296,,22.4502,0.0509296,,,,7.85398e-5
Test1,1-Recover,49.133,2.632,0.731,0.011,,0.217365,140.056,,21.7365,0.140056,,,,7.85398e-5
Test1,1-Recover,49.500,2.657,0.706,0.004,,0.209932,50.9296,,20.9932,0.0509296,,,,7.85398e-5
Test1,1-Recover,49.867,2.682,0.681,-0.003,,0.202498,-38.1972,,20.2498,-0.0381972,,,,7.85398e-5
Test1,1-Recover,50.233,2.706,0.657,-0.003,,0.195361,-38.1972,,19.5361,-0.0381972,,,,7.85398e-5
Test1,1-Recover,50.600,2.731,0.632,-0.003,,0.187927,-38.1972,,18.7927,-0.0381972,,,,7.85398e-5
Test1,1-Recover,50.967,2.756,0.607,0.004,,0.180494,50.9296,,18.0494,0.0509296,,,,7.85398e-5
Test1,1-Recover,51.333,2.78,0.583,0.004,,0.173357,50.9296,,17.3357,0.0509296,,,,7.85398e-5
Test1,1-Recover,51.700,2.805,0.558,0.004,,0.165923,50.9296,,16.5923,0.0509296,,,,7.85398e-5
Test1,1-Recover,52.067,2.83,0.533,-0.003,,0.158489,-38.1972,,15.8489,-0.0381972,,,,7.85398e-5
Test1,1-Recover,52.433,2.854,0.509,-0.003,,0.151353,-38.1972,,15.1353,-0.0381972,,,,7.85398e-5
Test1,1-Recover,52.800,2.879,0.484,-0.003,,0.143919,-38.1972,,14.3919,-0.0381972,,,,7.85398e-5
Test1,1-Recover,53.167,2.904,0.459,-0.003,,0.136485,-38.1972,,13.6485,-0.0381972,,,,7.85398e-5
Test1,1-Recover,53.533,2.928,0.435,0.004,,0.129349,50.9296,,12.9349,0.0509296,,,,7.85398e-5
Test1,1-Recover,53.900,2.953,0.41,0.011,,0.121915,140.056,,12.1915,0.140056,,,,7.85398e-5
Test1,1-Recover,54.267,2.978,0.385,0.004,,0.114481,50.9296,,11.4481,0.0509296,,,,7.85398e-5
Test1,1-Recover,54.633,3.003,0.36,-0.003,,0.107047,-38.1972,,10.7047,-0.0381972,,,,7.85398e-5
Test1,1-Recover,55.000,3.027,0.336,-0.003,,0.0999108,-38.1972,,9.99108,-0.0381972,,,,7.85398e-5
Test1,1-Recover,55.367,3.052,0.311,-0.003,,0.092477,-38.1972,,9.2477,-0.0381972,,,,7.85398e-5
Test1,1-Recover,55.733,3.077,0.286,-0.003,,0.0850431,-38.1972,,8.50431,-0.0381972,,,,7.85398e-5
Test1,1-Recover,56.100,3.102,0.261,0.004,,0.0776093,50.9296,,7.76093,0.0509296,,,,7.85398e-5
Test1,1-Recover,56.467,3.126,0.237,0.011,,0.0704728,140.056,,7.04728,0.140056,,,,7.85398e-5
Test1,1-Recover,56.833,3.151,0.212,0.004,,0.063039,50.9296,,6.3039,0.0509296,,,,7.85398e-5
Test1,1-Recover,57.200,3.176,0.187,-0.003,,0.0556051,-38.1972,,5.56051,-0.0381972,,,,7.85398e-5
Test1,1-Recover,57.567,3.201,0.162,-0.003,,0.0481713,-38.1972,,4.81713,-0.0381972,,,,7.85398e-5
Test1,1-Recover,57.933,3.225,0.138,-0.003,,0.0410348,-38.1972,,4.10348,-0.0381972,,,,7.85398e-5
Test1,1-Recover,58.300,3.25,0.113,-0.003,,0.033601,-38.1972,,3.3601,-0.0381972,,,,7.85398e-5
Test1,1-Recover,58.667,3.275,0.088,0.004,,0.0261671,50.9296,,2.61671,0.0509296,,,,7.85398e-5
Test1,1-Recover,59.033,3.299,0.064,0.011,,0.0190306,140.056,,1.90306,0.140056,,,,7.85398e-5
Test1,1-Recover,59.400,3.324,0.039,0.004,,0.0115968,50.9296,,1.15968,0.0509296,,,,7.85398e-5
Test1,1-Recover,59.767,3.349,0.014,-0.003,,0.00416295,-38.1972,,0.416295,-0.0381972,,,,7.85398e-5
Test1,2-Compress,60.117,3.358,0.005,-0.003,,0.00148677,-38.1972,,0.148677,-0.0381972,,,,7.85398e-5
Test1,2-Compress,60.483,3.333,0.03,-0.003,,0.00892061,-38.1972,,0.892061,-0.0381972,,,,7.85398e-5
Test1,2-Compress,60.850,3.309,0.054,-0.003,,0.0160571,-38.1972,,1.60571,-0.0381972,,,,7.85398e-5
Test1,2-Compress,61.217,3.284,0.079,0.004,,0.0234909,50.9296,,2.34909,0.0509296,,,,7.85398e-5
Test1,2-Compress,61.583,3.259,0.104,0.011,,0.0309248,140.056,,3.09248,0.140056,,,,7.85398e-5
Test1,2-Compress,61.950,3.234,0.129,0.011,,0.0383586,140.056,,3.83586,0.140056,,,,7.85398e-5
Test1,2-Compress,62.317,3.21,0.153,-0.003,,0.0454951,-38.1972,,4.54951,-0.0381972,,,,7.85398e-5
Test1,2-Compress,62.683,3.185,0.178,-0.003,,0.0529289,-38.1972,,5.29289,-0.0381972,,,,7.85398e-5
Test1,2-Compress,63.050,3.16,0.203,-0.003,,0.0603628,-38.1972,,6.03628,-0.0381972,,,,7.85398e-5
Test1,2-Compress,63.417,3.135,0.228,-0.003,,0.0677966,-38.1972,,6.77966,-0.0381972,,,,7.85398e-5
Test1,2-Compress,63.783,3.111,0.252,0.004,,0.0749331,50.9296,,7.49331,0.0509296,,,,7.85398e-5
Test1,2-Compress,64.150,3.086,0.277,0.011,,0.0823669,140.056,,8.23669,0.140056,,,,7.85398e-5
Test1,2-Compress,64.517,3.061,0.302,0.004,,0.0898008,50.9296,,8.98008,0.0509296,,,,7.85398e-5
Test1,2-Compress,64.883,3.037,0.326,-0.003,,0.0969373,-38.1972,,9.69373,-0.0381972,,,,7.85398e-5
Test1,2-Compress,65.250,3.012,0.351,-0.003,,0.104371,-38.1972,,10.4371,-0.0381972,,,,7.85398e-5
Test1,2-Compress,65.617,2.987,0.376,-0.003,,0.111805,-38.1972,,11.1805,-0.0381972,,,,7.85398e-5
Test1,2-Compress,65.983,2.963,0.4,-0.003,,0.118941,-38.1972,,11.8941,-0.0381972,,,,7.85398e-5
Test1,2-Compress,66.350,2.938,0.425,0.004,,0.126375,50.9296,,12.6375,0.0509296,,,,7.85398e-5
Test1,2-Compress,66.717,2.913,0.45,0.011,,0.133809,140.056,,13.3809,0.140056,,,,7.85398e-5
Test1,2-Compress,67.083,2.889,0.474,0.011,,0.140946,140.056,,14.0946,0.140056,,,,7.85398e-5
Test1,2-Compress,67.450,2.864,0.499,-0.003,,0.148379,-38.1972,,14.8379,-0.0381972,,,,7.85398e-5
Test1,2-Compress,67.817,2.839,0.524,-0.003,,0.155813,-38.1972,,15.5813,-0.0381972,,,,7.85398e-5
Test1,2-Compress,68.183,2.815,0.548,-0.003,,0.16295,-38.1972,,16.295,-0.0381972,,,,7.85398e-5
Test1,2-Compress,68.550,2.79,0.573,-0.003,,0.170384,-38.1972,,17.0384,-0.0381972,,,,7.85398e-5
Test1,2-Compress,68.917,2.765,0.598,0.004,,0.177817,50.9296,,17.7817,0.0509296,,,,7.85398e-5
Test1,2-Compress,69.283,2.741,0.622,0.011,,0.184954,140.056,,18.4954,0.140056,,,,7.85398e-5
Test1,2-Compress,69.650,2.716,0.647,0.004,,0.192388,50.9296,,19.2388,0.0509296,,,,7.85398e-5
Test1,2-Compress,70.017,2.691,0.672,-0.003,,0.199822,-38.1972,,19.9822,-0.0381972,,,,7.85398e-5
Test1,2-Compress,70.383,2.667,0.696,0.004,,0.206958,50.9296,,20.6958,0.0509296,,,,7.85398e-5
Test1,2-Compress,70.750,2.642,0.721,0.004,,0.214392,50.9296,,21.4392,0.0509296,,,,7.85398e-5
Test1,2-Compress,71.117,2.617,0.746,0.004,,0.221826,50.9296,,22.1826,0.0509296,,,,7.85398e-5
Test1,2-Compress,71.483,2.592,0.771,0.004,,0.22926,50.9296,,22.926,0.0509296,,,,7.85398e-5
Test1,2-Compress,71.850,2.568,0.795,0.011,,0.236396,140.056,,23.6396,0.140056,,,,7.85398e-5
Test1,2-Compress,72.217,2.543,0.82,0.011,,0.24383,140.056,,24.383,0.140056,,,,7.85398e-5
Test1,2-Compress,72.583,2.518,0.845,0.004,,0.251264,50.9296,,25.1264,0.0509296,,,,7.85398e-5
Test1,2-Compress,72.950,2.493,0.87,0.004,,0.258698,50.9296,,25.8698,0.0509296,,,,7.85398e-5
Test1,2-Compress,73.317,2.469,0.894,0.004,,0.265834,50.9296,,26.5834,0.0509296,,,,7.85398e-5
Test1,2-Compress,73.683,2.444,0.919,0.004,,0.273268,50.9296,,27.3268,0.0509296,,,,7.85398e-5
Test1,2-Compress,74.050,2.419,0.944,0.004,,0.280702,50.9296,,28.0702,0.0509296,,,,7.85398e-5
Test1,2-Compress,74.417,2.394,0.969,0.018,,0.288136,229.183,,28.8136,0.229183,,,,7.85398e-5
Test1,2-Compress,74.783,2.37,0.993,0.031,,0.295272,394.704,,29.5272,0.394704,,,,7.85398e-5
Test1,2-Compress,75.150,2.345,1.018,0.011,,0.302706,140.056,,30.2706,0.140056,,,,7.85398e-5
Test1,2-Compress,75.517,2.32,1.043,0.004,,0.31014,50.9296,,31.014,0.0509296,,,,7.85398e-5
Test1,2-Compress,75.883,2.296,1.067,0.004,,0.317276,50.9296,,31.7276,0.0509296,,,,7.85398e-5
Test1,2-Compress,76.250,2.271,1.092,0.004,,0.32471,50.9296,,32.471,0.0509296,,,,7.85398e-5
Test1,2-Compress,76.617,2.246,1.117,0.011,,0.332144,140.056,,33.2144,0.140056,,,,7.85398e-5
Test1,2-Compress,76.983,2.222,1.141,0.018,,0.33928,229.183,,33.928,0.229183,,,,7.85398e-5
Test1,2-Compress,77.350,2.197,1.166,0.004,,0.346714,50.9296,,34.6714,0.0509296,,,,7.85398e-5
Test1,2-Compress,77.717,2.172,1.191,0.011,,0.354148,140.056,,35.4148,0.140056,,,,7.85398e-5
Test1,2-Compress,78.083,2.148,1.215,0.011,,0.361285,140.056,,36.1285,0.140056,,,,7.85398e-5
Test1,2-Compress,78.450,2.123,1.24,0.004,,0.368718,50.9296,,36.8718,0.0509296,,,,7.85398e-5
Test1,2-Compress,78.817,2.098,1.265,0.004,,0.376152,50.9296,,37.6152,0.0509296,,,,7.85398e-5
Test1,2-Compress,79.183,2.074,1.289,0.011,,0.383289,140.056,,38.3289,0.140056,,,,7.85398e-5
Test1,2-Compress,79.550,2.049,1.314,0.018,,0.390723,229.183,,39.0723,0.229183,,,,7.85398e-5
Test1,2-Compress,79.917,2.024,1.339,0.018,,0.398156,229.183,,39.8156,0.229183,,,,7.85398e-5
Test1,2-Compress,80.283,1.999,1.364,0.018,,0.40559,229.183,,40.559,0.229183,,,,7.85398e-5
Test1,2-Compress,80.650,1.975,1.388,0.011,,0.412727,140.056,,41.2727,0.140056,,,,7.85398e-5
Test1,2-Compress,81.017,1.95,1.413,0.004,,0.420161,50.9296,,42.0161,0.0509296,,,,7.85398e-5
Test1,2-Compress,81.383,1.926,1.437,0.004,,0.427297,50.9296,,42.7297,0.0509296,,,,7.85398e-5
Test1,2-Compress,81.750,1.9,1.463,0.011,,0.435028,140.056,,43.5028,0.140056,,,,7.85398e-5
Test1,2-Compress,82.117,1.876,1.487,0.031,,0.442165,394.704,,44.2165,0.394704,,,,7.85398e-5
Test1,2-Compress,82.483,1.852,1.511,0.038,,0.449301,483.831,,44.9301,0.483831,,,,7.85398e-5
Test1,2-Compress,82.850,1.827,1.536,0.025,,0.456735,318.31,,45.6735,0.31831,,,,7.85398e-5
Test1,2-Compress,83.217,1.801,1.562,0.011,,0.464466,140.056,,46.4466,0.140056,,,,7.85398e-5
Test1,2-Compress,83.583,1.777,1.586,0.025,,0.471603,318.31,,47.1603,0.31831,,,,7.85398e-5
Test1,2-Compress,83.950,1.753,1.61,0.011,,0.478739,140.056,,47.8739,0.140056,,,,7.85398e-5
Test1,2-Compress,84.317,1.728,1.635,0.038,,0.486173,483.831,,48.6173,0.483831,,,,7.85398e-5
Test1,2-Compress,84.683,1.703,1.66,0.038,,0.493607,483.831,,49.3607,0.483831,,,,7.85398e-5
Test1,2-Compress,85.050,1.678,1.685,0.031,,0.501041,394.704,,50.1041,0.394704,,,,7.85398e-5
Test1,2-Compress,85.417,1.653,1.71,0.038,,0.508475,483.831,,50.8475,0.483831,,,,7.85398e-5
Test1,2-Compress,85.783,1.629,1.734,0.038,,0.515611,483.831,,51.5611,0.483831,,,,7.85398e-5
Test1,2-Compress,86.150,1.604,1.759,0.031,,0.523045,394.704,,52.3045,0.394704,,,,7.85398e-5
Test1,2-Compress,86.517,1.579,1.784,0.031,,0.530479,394.704,,53.0479,0.394704,,,,7.85398e-5
Test1,2-Compress,86.883,1.555,1.808,0.038,,0.537615,483.831,,53.7615,0.483831,,,,7.85398e-5
Test1,2-Compress,87.250,1.53,1.833,0.045,,0.545049,572.958,,54.5049,0.572958,,,,7.85398e-5
Test1,2-Compress,87.617,1.505,1.858,0.052,,0.552483,662.085,,55.2483,0.662085,,,,7.85398e-5
Test1,2-Compress,87.983,1.481,1.882,0.052,,0.559619,662.085,,55.9619,0.662085,,,,7.85398e-5
Test1,2-Compress,88.350,1.456,1.907,0.052,,0.567053,662.085,,56.7053,0.662085,,,,7.85398e-5
Test1,2-Compress,88.717,1.431,1.932,0.045,,0.574487,572.958,,57.4487,0.572958,,,,7.85398e-5
Test1,2-Compress,89.083,1.407,1.956,0.052,,0.581624,662.085,,58.1624,0.662085,,,,7.85398e-5
Test1,2-Compress,89.450,1.382,1.981,0.045,,0.589057,572.958,,58.9057,0.572958,,,,7.85398e-5
Test1,2-Compress,89.817,1.357,2.006,0.052,,0.596491,662.085,,59.6491,0.662085,,,,7.85398e-5
Test1,2-Recover,90.170,1.352,2.011,0.052,,0.597978,662.085,,59.7978,0.662085,,,,7.85398e-5
Test1,2-Recover,90.537,1.376,1.987,0.052,,0.590842,662.085,,59.0842,0.662085,,,,7.85398e-5
Test1,2-Recover,90.903,1.401,1.962,0.052,,0.583408,662.085,,58.3408,0.662085,,,,7.85398e-5
Test1,2-Recover,91.270,1.426,1.937,0.038,,0.575974,483.831,,57.5974,0.483831,,,,7.85398e-5
Test1,2-Recover,91.637,1.451,1.912,0.031,,0.56854,394.704,,56.854,0.394704,,,,7.85398e-5
Test1,2-Recover,92.003,1.475,1.888,0.038,,0.561404,483.831,,56.1404,0.483831,,,,7.85398e-5
Test1,2-Recover,92.370,1.5,1.863,0.052,,0.55397,662.085,,55.397,0.662085,,,,7.85398e-5
Test1,2-Recover,92.737,1.525,1.838,0.045,,0.546536,572.958,,54.6536,0.572958,,,,7.85398e-5
Test1,2-Recover,93.103,1.549,1.814,0.045,,0.539399,572.958,,53.9399,0.572958,,,,7.85398e-5
Test1,2-Recover,93.470,1.574,1.789,0.025,,0.531966,318.31,,53.1966,0.31831,,,,7.85398e-5
Test1,2-Recover,93.837,1.599,1.764,0.045,,0.524532,572.958,,52.4532,0.572958,,,,7.85398e-5
Test1,2-Recover,94.203,1.623,1.74,0.011,,0.517395,140.056,,51.7395,0.140056,,,,7.85398e-5
Test1,2-Recover,94.570,1.648,1.715,0.031,,0.509961,394.704,,50.9961,0.394704,,,,7.85398e-5
Test1,2-Recover,94.937,1.673,1.69,0.031,,0.502528,394.704,,50.2528,0.394704,,,,7.85398e-5
Test1,2-Recover,95.303,1.697,1.666,0.031,,0.495391,394.704,,49.5391,0.394704,,,,7.85398e-5
Test1,2-Recover,95.670,1.722,1.641,0.031,,0.487957,394.704,,48.7957,0.394704,,,,7.85398e-5
Test1,2-Recover,96.037,1.747,1.616,0.011,,0.480523,140.056,,48.0523,0.140056,,,,7.85398e-5
Test1,2-Recover,96.403,1.771,1.592,0.025,,0.473387,318.31,,47.3387,0.31831,,,,7.85398e-5
Test1,2-Recover,96.770,1.796,1.567,0.004,,0.465953,50.9296,,46.5953,0.0509296,,,,7.85398e-5
Test1,2-Recover,97.137,1.821,1.542,0.025,,0.458519,318.31,,45.8519,0.31831,,,,7.85398e-5
Test1,2-Recover,97.503,1.846,1.517,0.025,,0.451085,318.31,,45.1085,0.31831,,,,7.85398e-5
Test1,2-Recover,97.870,1.87,1.493,0.018,,0.443949,229.183,,44.3949,0.229183,,,,7.85398e-5
Test1,2-Recover,98.237,1.895,1.468,0.011,,0.436515,140.056,,43.6515,0.140056,,,,7.85398e-5
Test1,2-Recover,98.603,1.92,1.443,0.011,,0.429081,140.056,,42.9081,0.140056,,,,7.85398e-5
Test1,2-Recover,98.970,1.945,1.418,0.004,,0.421647,50.9296,,42.1647,0.0509296,,,,7.85398e-5
Test1,2-Recover,99.337,1.969,1.394,0.011,,0.414511,140.056,,41.4511,0.140056,,,,7.85398e-5
Test1,2-Recover,99.703,1.994,1.369,0.018,,0.407077,229.183,,40.7077,0.229183,,,,7.85398e-5
Test1,2-Recover,100.070,2.019,1.344,0.031,,0.399643,394.704,,39.9643,0.394704,,,,7.85398e-5
Test1,2-Recover,100.437,2.044,1.319,0.018,,0.392209,229.183,,39.2209,0.229183,,,,7.85398e-5
Test1,2-Recover,100.803,2.068,1.295,0.011,,0.385073,140.056,,38.5073,0.140056,,,,7.85398e-5
Test1,2-Recover,101.170,2.093,1.27,0.004,,0.377639,50.9296,,37.7639,0.0509296,,,,7.85398e-5
Test1,2-Recover,101.537,2.118,1.245,0.004,,0.370205,50.9296,,37.0205,0.0509296,,,,7.85398e-5
Test1,2-Recover,101.903,2.142,1.221,0.004,,0.363069,50.9296,,36.3069,0.0509296,,,,7.85398e-5
Test1,2-Recover,102.270,2.167,1.196,0.018,,0.355635,229.183,,35.5635,0.229183,,,,7.85398e-5
Test1,2-Recover,102.637,2.192,1.171,0.004,,0.348201,50.9296,,34.8201,0.0509296,,,,7.85398e-5
Test1,2-Recover,103.003,2.216,1.147,0.011,,0.341065,140.056,,34.1065,0.140056,,,,7.85398e-5
Test1,2-Recover,103.370,2.241,1.122,-0.003,,0.333631,-38.1972,,33.3631,-0.0381972,,,,7.85398e-5
Test1,2-Recover,103.737,2.266,1.097,0.004,,0.326197,50.9296,,32.6197,0.0509296,,,,7.85398e-5
Test1,2-Recover,104.103,2.29,1.073,0.004,,0.31906,50.9296,,31.906,0.0509296,,,,7.85398e-5
Test1,2-Recover,104.470,2.315,1.048,0.011,,0.311627,140.056,,31.1627,0.140056,,,,7.85398e-5
Test1,2-Recover,104.837,2.34,1.023,0.004,,0.304193,50.9296,,30.4193,0.0509296,,,,7.85398e-5
Test1,2-Recover,105.203,2.364,0.999,0.018,,0.297056,229.183,,29.7056,0.229183,,,,7.85398e-5
Test1,2-Recover,105.570,2.389,0.974,0.004,,0.289622,50.9296,,28.9622,0.0509296,,,,7.85398e-5
Test1,2-Recover,105.937,2.414,0.949,-0.003,,0.282189,-38.1972,,28.2189,-0.0381972,,,,7.85398e-5
Test1,2-Recover,106.303,2.438,0.925,-0.003,,0.275052,-38.1972,,27.5052,-0.0381972,,,,7.85398e-5
Test1,2-Recover,106.670,2.463,0.9,0.004,,0.267618,50.9296,,26.7618,0.0509296,,,,7.85398e-5
Test1,2-Recover,107.037,2.488,0.875,0.011,,0.260184,140.056,,26.0184,0.140056,,,,7.85398e-5
Test1,2-Recover,107.403,2.512,0.851,0.004,,0.253048,50.9296,,25.3048,0.0509296,,,,7.85398e-5
Test1,2-Recover,107.770,2.537,0.826,0.004,,0.245614,50.9296,,24.5614,0.0509296,,,,7.85398e-5
Test1,2-Recover,108.137,2.562,0.801,0.004,,0.23818,50.9296,,23.818,0.0509296,,,,7.85398e-5
Test1,2-Recover,108.503,2.587,0.776,-0.003,,0.230746,-38.1972,,23.0746,-0.0381972,,,,7.85398e-5
Test1,2-Recover,108.870,2.611,0.752,-0.003,,0.22361,-38.1972,,22.361,-0.0381972,,,,7.85398e-5
Test1,2-Recover,109.237,2.636,0.727,0.004,,0.216176,50.9296,,21.6176,0.0509296,,,,7.85398e-5
Test1,2-Recover,109.603,2.661,0.702,0.018,,0.208742,229.183,,20.8742,0.229183,,,,7.85398e-5
Test1,2-Recover,109.970,2.686,0.677,0.004,,0.201308,50.9296,,20.1308,0.0509296,,,,7.85398e-5
Test1,2-Recover,110.337,2.71,0.653,-0.003,,0.194172,-38.1972,,19.4172,-0.0381972,,,,7.85398e-5
Test1,2-Recover,110.703,2.735,0.628,-0.003,,0.186738,-38.1972,,18.6738,-0.0381972,,,,7.85398e-5
Test1,2-Recover,111.070,2.76,0.603,-0.003,,0.179304,-38.1972,,17.9304,-0.0381972,,,,7.85398e-5
Test1,2-Recover,111.437,2.785,0.578,0.004,,0.17187,50.9296,,17.187,0.0509296,,,,7.85398e-5
Test1,2-Recover,111.803,2.809,0.554,0.004,,0.164734,50.9296,,16.4734,0.0509296,,,,7.85398e-5
Test1,2-Recover,112.170,2.834,0.529,0.011,,0.1573,140.056,,15.73,0.140056,,,,7.85398e-5
Test1,2-Recover,112.537,2.859,0.504,0.004,,0.149866,50.9296,,14.9866,0.0509296,,,,7.85398e-5
Test1,2-Recover,112.903,2.883,0.48,-0.003,,0.14273,-38.1972,,14.273,-0.0381972,,,,7.85398e-5
Test1,2-Recover,113.270,2.908,0.455,-0.003,,0.135296,-38.1972,,13.5296,-0.0381972,,,,7.85398e-5
Test1,2-Recover,113.637,2.933,0.43,-0.003,,0.127862,-38.1972,,12.7862,-0.0381972,,,,7.85398e-5
Test1,2-Recover,114.003,2.957,0.406,0.004,,0.120726,50.9296,,12.0726,0.0509296,,,,7.85398e-5
Test1,2-Recover,114.370,2.982,0.381,0.004,,0.113292,50.9296,,11.3292,0.0509296,,,,7.85398e-5
Test1,2-Recover,114.737,3.007,0.356,0.011,,0.105858,140.056,,10.5858,0.140056,,,,7.85398e-5
Test1,2-Recover,115.103,3.031,0.332,0.004,,0.0987214,50.9296,,9.87214,0.0509296,,,,7.85398e-5
Test1,2-Recover,115.470,3.056,0.307,-0.003,,0.0912875,-38.1972,,9.12875,-0.0381972,,,,7.85398e-5
Test1,2-Recover,115.837,3.081,0.282,-0.003,,0.0838537,-38.1972,,8.38537,-0.0381972,,,,7.85398e-5
Test1,2-Recover,116.203,3.105,0.258,-0.003,,0.0767172,-38.1972,,7.67172,-0.0381972,,,,7.85398e-5
Test1,2-Recover,116.570,3.13,0.233,0.004,,0.0692834,50.9296,,6.92834,0.0509296,,,,7.85398e-5
Test1,2-Recover,116.937,3.155,0.208,0.011,,0.0618495,140.056,,6.18495,0.140056,,,,7.85398e-5
Test1,2-Recover,117.303,3.18,0.183,0.004,,0.0544157,50.9296,,5.44157,0.0509296,,,,7.85398e-5
Test1,2-Recover,117.670,3.204,0.159,0.004,,0.0472792,50.9296,,4.72792,0.0509296,,,,7.85398e-5
Test1,2-Recover,118.037,3.229,0.134,-0.003,,0.0398454,-38.1972,,3.98454,-0.0381972,,,,7.85398e-5
Test1,2-Recover,118.403,3.253,0.11,-0.003,,0.0327089,-38.1972,,3.27089,-0.0381972,,,,7.85398e-5
Test1,2-Recover,118.770,3.279,0.084,-0.003,,0.0249777,-38.1972,,2.49777,-0.0381972,,,,7.85398e-5
Test1,2-Recover,119.137,3.303,0.06,0.004,,0.0178412,50.9296,,1.78412,0.0509296,,,,7.85398e-5
Test1,2-Recover,119.503,3.327,0.036,0.004,,0.0107047,50.9296,,1.07047,0.0509296,,,,7.85398e-5
Test1,2-Recover,119.870,3.352,0.011,0.011,,0.00327089,140.056,,0.327089,0.140056,,,,7.85398e-5
Test1,3-Compress,120.223,3.354,0.009,0.004,,0.00267618,50.9296,,0.267618,0.0509296,,,,7.85398e-5
Test1,3-Compress,120.590,3.329,0.034,-0.003,,0.01011,-38.1972,,1.011,-0.0381972,,,,7.85398e-5
Test1,3-Compress,120.957,3.304,0.059,-0.003,,0.0175439,-38.1972,,1.75439,-0.0381972,,,,7.85398e-5
Test1,3-Compress,121.323,3.28,0.083,-0.003,,0.0246803,-38.1972,,2.46803,-0.0381972,,,,7.85398e-5
Test1,3-Compress,121.690,3.255,0.108,0.004,,0.0321142,50.9296,,3.21142,0.0509296,,,,7.85398e-5
Test1,3-Compress,122.057,3.23,0.133,0.011,,0.039548,140.056,,3.9548,0.140056,,,,7.85398e-5
Test1,3-Compress,122.423,3.206,0.157,0.011,,0.0466845,140.056,,4.66845,0.140056,,,,7.85398e-5
Test1,3-Compress,122.790,3.181,0.182,-0.003,,0.0541183,-38.1972,,5.41183,-0.0381972,,,,7.85398e-5
Test1,3-Compress,123.157,3.156,0.207,-0.003,,0.0615522,-38.1972,,6.15522,-0.0381972,,,,7.85398e-5
Test1,3-Compress,123.523,3.132,0.231,-0.003,,0.0686887,-38.1972,,6.86887,-0.0381972,,,,7.85398e-5
Test1,3-Compress,123.890,3.107,0.256,-0.003,,0.0761225,-38.1972,,7.61225,-0.0381972,,,,7.85398e-5
Test1,3-Compress,124.257,3.082,0.281,0.004,,0.0835563,50.9296,,8.35563,0.0509296,,,,7.85398e-5
Test1,3-Compress,124.623,3.057,0.306,0.011,,0.0909902,140.056,,9.09902,0.140056,,,,7.85398e-5
Test1,3-Compress,124.990,3.032,0.331,0.004,,0.098424,50.9296,,9.8424,0.0509296,,,,7.85398e-5
Test1,3-Compress,125.357,3.008,0.355,-0.003,,0.105561,-38.1972,,10.5561,-0.0381972,,,,7.85398e-5
Test1,3-Compress,125.723,2.984,0.379,-0.003,,0.112697,-38.1972,,11.2697,-0.0381972,,,,7.85398e-5
Test1,3-Compress,126.090,2.958,0.405,0.004,,0.120428,50.9296,,12.0428,0.0509296,,,,7.85398e-5
Test1,3-Compress,126.457,2.933,0.43,-0.003,,0.127862,-38.1972,,12.7862,-0.0381972,,,,7.85398e-5
Test1,3-Compress,126.823,2.909,0.454,0.004,,0.134999,50.9296,,13.4999,0.0509296,,,,7.85398e-5
Test1,3-Compress,127.190,2.885,0.478,0.011,,0.142135,140.056,,14.2135,0.140056,,,,7.85398e-5
Test1,3-Compress,127.557,2.859,0.504,0.004,,0.149866,50.9296,,14.9866,0.0509296,,,,7.85398e-5
Test1,3-Compress,127.923,2.835,0.528,0.011,,0.157003,140.056,,15.7003,0.140056,,,,7.85398e-5
Test1,3-Compress,128.290,2.81,0.553,0.004,,0.164437,50.9296,,16.4437,0.0509296,,,,7.85398e-5
Test1,3-Compress,128.657,2.786,0.577,0.004,,0.171573,50.9296,,17.1573,0.0509296,,,,7.85398e-5
Test1,3-Compress,129.023,2.761,0.602,-0.003,,0.179007,-38.1972,,17.9007,-0.0381972,,,,7.85398e-5
Test1,3-Compress,129.390,2.736,0.627,0.004,,0.186441,50.9296,,18.6441,0.0509296,,,,7.85398e-5
Test1,3-Compress,129.757,2.711,0.652,0.011,,0.193875,140.056,,19.3875,0.140056,,,,7.85398e-5
Test1,3-Compress,130.123,2.687,0.676,0.004,,0.201011,50.9296,,20.1011,0.0509296,,,,7.85398e-5
Test1,3-Compress,130.490,2.662,0.701,0.011,,0.208445,140.056,,20.8445,0.140056,,,,7.85398e-5
Test1,3-Compress,130.857,2.637,0.726,0.004,,0.215879,50.9296,,21.5879,0.0509296,,,,7.85398e-5
Test1,3-Compress,131.223,2.613,0.75,0.004,,0.223015,50.9296,,22.3015,0.0509296,,,,7.85398e-5
Test1,3-Compress,131.590,2.588,0.775,0.004,,0.230449,50.9296,,23.0449,0.0509296,,,,7.85398e-5
Test1,3-Compress,131.957,2.563,0.8,0.004,,0.237883,50.9296,,23.7883,0.0509296,,,,7.85398e-5
Test1,3-Compress,132.323,2.539,0.824,0.011,,0.245019,140.056,,24.5019,0.140056,,,,7.85398e-5
Test1,3-Compress,132.690,2.514,0.849,0.025,,0.252453,318.31,,25.2453,0.31831,,,,7.85398e-5
Test1,3-Compress,133.057,2.489,0.874,0.018,,0.259887,229.183,,25.9887,0.229183,,,,7.85398e-5
Test1,3-Compress,133.423,2.465,0.898,0.011,,0.267023,140.056,,26.7023,0.140056,,,,7.85398e-5
Test1,3-Compress,133.790,2.44,0.923,0.011,,0.274457,140.056,,27.4457,0.140056,,,,7.85398e-5
Test1,3-Compress,134.157,2.415,0.948,0.004,,0.281891,50.9296,,28.1891,0.0509296,,,,7.85398e-5
Test1,3-Compress,134.523,2.391,0.972,0.004,,0.289028,50.9296,,28.9028,0.0509296,,,,7.85398e-5
Test1,3-Compress,134.890,2.366,0.997,0.018,,0.296461,229.183,,29.6461,0.229183,,,,7.85398e-5
Test1,3-Compress,135.257,2.341,1.022,0.025,,0.303895,318.31,,30.3895,0.31831,,,,7.85398e-5
Test1,3-Compress,135.623,2.316,1.047,0.011,,0.311329,140.056,,31.1329,0.140056,,,,7.85398e-5
Test1,3-Compress,135.990,2.292,1.071,0.018,,0.318466,229.183,,31.8466,0.229183,,,,7.85398e-5
Test1,3-Compress,136.357,2.267,1.096,0.004,,0.325899,50.9296,,32.5899,0.0509296,,,,7.85398e-5
Test1,3-Compress,136.723,2.242,1.121,0.004,,0.333333,50.9296,,33.3333,0.0509296,,,,7.85398e-5
Test1,3-Compress,137.090,2.217,1.146,0.004,,0.340767,50.9296,,34.0767,0.0509296,,,,7.85398e-5
Test1,3-Compress,137.457,2.193,1.17,0.018,,0.347904,229.183,,34.7904,0.229183,,,,7.85398e-5
Test1,3-Compress,137.823,2.168,1.195,0.025,,0.355337,318.31,,35.5337,0.31831,,,,7.85398e-5
Test1,3-Compress,138.190,2.143,1.22,0.018,,0.362771,229.183,,36.2771,0.229183,,,,7.85398e-5
Test1,3-Compress,138.557,2.118,1.245,0.011,,0.370205,140.056,,37.0205,0.140056,,,,7.85398e-5
Test1,3-Compress,138.923,2.094,1.269,0.011,,0.377342,140.056,,37.7342,0.140056,,,,7.85398e-5
Test1,3-Compress,139.290,2.069,1.294,0.004,,0.384775,50.9296,,38.4775,0.0509296,,,,7.85398e-5
Test1,3-Compress,139.657,2.044,1.319,0.018,,0.392209,229.183,,39.2209,0.229183,,,,7.85398e-5
Test1,3-Compress,140.023,2.02,1.343,0.018,,0.399346,229.183,,39.9346,0.229183,,,,7.85398e-5
Test1,3-Compress,140.390,1.995,1.368,0.038,,0.40678,483.831,,40.678,0.483831,,,,7.85398e-5
Test1,3-Compress,140.757,1.97,1.393,0.025,,0.414213,318.31,,41.4213,0.31831,,,,7.85398e-5
Test1,3-Compress,141.123,1.946,1.417,0.025,,0.42135,318.31,,42.135,0.31831,,,,7.85398e-5
Test1,3-Compress,141.490,1.921,1.442,0.011,,0.428784,140.056,,42.8784,0.140056,,,,7.85398e-5
Test1,3-Compress,141.857,1.896,1.467,0.004,,0.436218,50.9296,,43.6218,0.0509296,,,,7.85398e-5
Test1,3-Compress,142.223,1.872,1.491,0.018,,0.443354,229.183,,44.3354,0.229183,,,,7.85398e-5
Test1,3-Compress,142.590,1.847,1.516,0.025,,0.450788,318.31,,45.0788,0.31831,,,,7.85398e-5
Test1,3-Compress,142.957,1.822,1.541,0.038,,0.458222,483.831,,45.8222,0.483831,,,,7.85398e-5
Test1,3-Compress,143.323,1.798,1.565,0.025,,0.465358,318.31,,46.5358,0.31831,,,,7.85398e-5
Test1,3-Compress,143.690,1.773,1.59,0.038,,0.472792,483.831,,47.2792,0.483831,,,,7.85398e-5
Test1,3-Compress,144.057,1.748,1.615,0.018,,0.480226,229.183,,48.0226,0.229183,,,,7.85398e-5
Test1,3-Compress,144.423,1.724,1.639,0.045,,0.487362,572.958,,48.7362,0.572958,,,,7.85398e-5
Test1,3-Compress,144.790,1.699,1.664,0.018,,0.494796,229.183,,49.4796,0.229183,,,,7.85398e-5
Test1,3-Compress,145.157,1.674,1.689,0.052,,0.50223,662.085,,50.223,0.662085,,,,7.85398e-5
Test1,3-Compress,145.523,1.65,1.713,0.045,,0.509367,572.958,,50.9367,0.572958,,,,7.85398e-5
Test1,3-Compress,145.890,1.625,1.738,0.052,,0.5168,662.085,,51.68,0.662085,,,,7.85398e-5
Test1,3-Compress,146.257,1.6,1.763,0.031,,0.524234,394.704,,52.4234,0.394704,,,,7.85398e-5
Test1,3-Compress,146.623,1.575,1.788,0.045,,0.531668,572.958,,53.1668,0.572958,,,,7.85398e-5
Test1,3-Compress,146.990,1.551,1.812,0.052,,0.538805,662.085,,53.8805,0.662085,,,,7.85398e-5
Test1,3-Compress,147.357,1.526,1.837,0.038,,0.546238,483.831,,54.6238,0.483831,,,,7.85398e-5
Test1,3-Compress,147.723,1.501,1.862,0.052,,0.553672,662.085,,55.3672,0.662085,,,,7.85398e-5
Test1,3-Compress,148.090,1.476,1.887,0.052,,0.561106,662.085,,56.1106,0.662085,,,,7.85398e-5
Test1,3-Compress,148.457,1.451,1.912,0.052,,0.56854,662.085,,56.854,0.662085,,,,7.85398e-5
Test1,3-Compress,148.823,1.427,1.936,0.052,,0.575676,662.085,,57.5676,0.662085,,,,7.85398e-5
Test1,3-Compress,149.190,1.402,1.961,0.052,,0.58311,662.085,,58.311,0.662085,,,,7.85398e-5
Test1,3-Compress,149.557,1.377,1.986,0.052,,0.590544,662.085,,59.0544,0.662085,,,,7.85398e-5
Test1,3-Compress,149.923,1.353,2.01,0.052,,0.597681,662.085,,59.7681,0.662085,,,,7.85398e-5
Test1,3-Recover,150.277,1.357,2.006,0.059,,0.596491,751.211,,59.6491,0.751211,,,,7.85398e-5
Test1,3-Recover,150.643,1.381,1.982,0.052,,0.589355,662.085,,58.9355,0.662085,,,,7.85398e-5
Test1,3-Recover,151.010,1.406,1.957,0.052,,0.581921,662.085,,58.1921,0.662085,,,,7.85398e-5
Test1,3-Recover,151.377,1.431,1.932,0.052,,0.574487,662.085,,57.4487,0.662085,,,,7.85398e-5
Test1,3-Recover,151.743,1.455,1.908,0.045,,0.567351,572.958,,56.7351,0.572958,,,,7.85398e-5
Test1,3-Recover,152.110,1.48,1.883,0.052,,0.559917,662.085,,55.9917,0.662085,,,,7.85398e-5
Test1,3-Recover,152.477,1.505,1.858,0.025,,0.552483,318.31,,55.2483,0.31831,,,,7.85398e-5
Test1,3-Recover,152.843,1.53,1.833,0.045,,0.545049,572.958,,54.5049,0.572958,,,,7.85398e-5
Test1,3-Recover,153.210,1.554,1.809,0.038,,0.537913,483.831,,53.7913,0.483831,,,,7.85398e-5
Test1,3-Recover,153.577,1.579,1.784,0.045,,0.530479,572.958,,53.0479,0.572958,,,,7.85398e-5
Test1,3-Recover,153.943,1.603,1.76,0.052,,0.523342,662.085,,52.3342,0.662085,,,,7.85398e-5
Test1,3-Recover,154.310,1.629,1.734,0.038,,0.515611,483.831,,51.5611,0.483831,,,,7.85398e-5
Test1,3-Recover,154.677,1.653,1.71,0.031,,0.508475,394.704,,50.8475,0.394704,,,,7.85398e-5
Test1,3-Recover,155.043,1.677,1.686,0.038,,0.501338,483.831,,50.1338,0.483831,,,,7.85398e-5
Test1,3-Recover,155.410,1.702,1.661,0.025,,0.493904,318.31,,49.3904,0.31831,,,,7.85398e-5
Test1,3-Recover,155.777,1.728,1.635,0.038,,0.486173,483.831,,48.6173,0.483831,,,,7.85398e-5
Test1,3-Recover,156.143,1.752,1.611,0.018,,0.479037,229.183,,47.9037,0.229183,,,,7.85398e-5
Test1,3-Recover,156.510,1.776,1.587,0.025,,0.4719,318.31,,47.19,0.31831,,,,7.85398e-5
Test1,3-Recover,156.877,1.801,1.562,0.018,,0.464466,229.183,,46.4466,0.229183,,,,7.85398e-5
Test1,3-Recover,157.243,1.826,1.537,0.025,,0.457032,318.31,,45.7032,0.31831,,,,7.85398e-5
Test1,3-Recover,157.610,1.851,1.512,0.031,,0.449599,394.704,,44.9599,0.394704,,,,7.85398e-5
Test1,3-Recover,157.977,1.875,1.488,0.025,,0.442462,318.31,,44.2462,0.31831,,,,7.85398e-5
Test1,3-Recover,158.343,1.9,1.463,0.025,,0.435028,318.31,,43.5028,0.31831,,,,7.85398e-5
Test1,3-Recover,158.710,1.925,1.438,0.018,,0.427594,229.183,,42.7594,0.229183,,,,7.85398e-5
Test1,3-Recover,159.077,1.95,1.413,0.011,,0.420161,140.056,,42.0161,0.140056,,,,7.85398e-5
Test1,3-Recover,159.443,1.974,1.389,0.004,,0.413024,50.9296,,41.3024,0.0509296,,,,7.85398e-5
Test1,3-Recover,159.810,1.999,1.364,0.004,,0.40559,50.9296,,40.559,0.0509296,,,,7.85398e-5
Test1,3-Recover,160.177,2.024,1.339,0.018,,0.398156,229.183,,39.8156,0.229183,,,,7.85398e-5
Test1,3-Recover,160.543,2.048,1.315,0.018,,0.39102,229.183,,39.102,0.229183,,,,7.85398e-5
Test1,3-Recover,160.910,2.073,1.29,0.011,,0.383586,140.056,,38.3586,0.140056,,,,7.85398e-5
Test1,3-Recover,161.277,2.098,1.265,0.011,,0.376152,140.056,,37.6152,0.140056,,,,7.85398e-5
Test1,3-Recover,161.643,2.122,1.241,0.004,,0.369016,50.9296,,36.9016,0.0509296,,,,7.85398e-5
Test1,3-Recover,162.010,2.147,1.216,0.004,,0.361582,50.9296,,36.1582,0.0509296,,,,7.85398e-5
Test1,3-Recover,162.377,2.172,1.191,0.011,,0.354148,140.056,,35.4148,0.140056,,,,7.85398e-5
Test1,3-Recover,162.743,2.196,1.167,0.018,,0.347012,229.183,,34.7012,0.229183,,,,7.85398e-5
Test1,3-Recover,163.110,2.221,1.142,0.025,,0.339578,318.31,,33.9578,0.31831,,,,7.85398e-5
Test1,3-Recover,163.477,2.246,1.117,0.004,,0.332144,50.9296,,33.2144,0.0509296,,,,7.85398e-5
Test1,3-Recover,163.843,2.27,1.093,-0.003,,0.325007,-38.1972,,32.5007,-0.0381972,,,,7.85398e-5
Test1,3-Recover,164.210,2.295,1.068,0.004,,0.317574,50.9296,,31.7574,0.0509296,,,,7.85398e-5
Test1,3-Recover,164.577,2.32,1.043,0.004,,0.31014,50.9296,,31.014,0.0509296,,,,7.85398e-5
Test1,3-Recover,164.943,2.345,1.018,0.011,,0.302706,140.056,,30.2706,0.140056,,,,7.85398e-5
Test1,3-Recover,165.310,2.369,0.994,0.011,,0.295569,140.056,,29.5569,0.140056,,,,7.85398e-5
Test1,3-Recover,165.677,2.394,0.969,0.011,,0.288136,140.056,,28.8136,0.140056,,,,7.85398e-5
Test1,3-Recover,166.043,2.419,0.944,0.004,,0.280702,50.9296,,28.0702,0.0509296,,,,7.85398e-5
Test1,3-Recover,166.410,2.444,0.919,0.004,,0.273268,50.9296,,27.3268,0.0509296,,,,7.85398e-5
Test1,3-Recover,166.777,2.468,0.895,0.004,,0.266131,50.9296,,26.6131,0.0509296,,,,7.85398e-5
Test1,3-Recover,167.143,2.492,0.871,0.004,,0.258995,50.9296,,25.8995,0.0509296,,,,7.85398e-5
Test1,3-Recover,167.510,2.518,0.845,0.011,,0.251264,140.056,,25.1264,0.140056,,,,7.85398e-5
Test1,3-Recover,167.877,2.543,0.82,0.004,,0.24383,50.9296,,24.383,0.0509296,,,,7.85398e-5
Test1,3-Recover,168.243,2.567,0.796,0.004,,0.236693,50.9296,,23.6693,0.0509296,,,,7.85398e-5
Test1,3-Recover,168.610,2.592,0.771,0.004,,0.22926,50.9296,,22.926,0.0509296,,,,7.85398e-5
Test1,3-Recover,168.977,2.617,0.746,-0.003,,0.221826,-38.1972,,22.1826,-0.0381972,,,,7.85398e-5
Test1,3-Recover,169.343,2.641,0.722,0.004,,0.214689,50.9296,,21.4689,0.0509296,,,,7.85398e-5
Test1,3-Recover,169.710,2.666,0.697,0.004,,0.207255,50.9296,,20.7255,0.0509296,,,,7.85398e-5
Test1,3-Recover,170.077,2.691,0.672,0.011,,0.199822,140.056,,19.9822,0.140056,,,,7.85398e-5
Test1,3-Recover,170.443,2.715,0.648,0.004,,0.192685,50.9296,,19.2685,0.0509296,,,,7.85398e-5
Test1,3-Recover,170.810,2.74,0.623,-0.003,,0.185251,-38.1972,,18.5251,-0.0381972,,,,7.85398e-5
Test1,3-Recover,171.177,2.765,0.598,-0.003,,0.177817,-38.1972,,17.7817,-0.0381972,,,,7.85398e-5
Test1,3-Recover,171.543,2.789,0.574,-0.003,,0.170681,-38.1972,,17.0681,-0.0381972,,,,7.85398e-5
Test1,3-Recover,171.910,2.814,0.549,-0.003,,0.163247,-38.1972,,16.3247,-0.0381972,,,,7.85398e-5
Test1,3-Recover,172.277,2.839,0.524,0.004,,0.155813,50.9296,,15.5813,0.0509296,,,,7.85398e-5
Test1,3-Recover,172.643,2.863,0.5,0.011,,0.148677,140.056,,14.8677,0.140056,,,,7.85398e-5
Test1,3-Recover,173.010,2.888,0.475,0.004,,0.141243,50.9296,,14.1243,0.0509296,,,,7.85398e-5
Test1,3-Recover,173.377,2.913,0.45,-0.003,,0.133809,-38.1972,,13.3809,-0.0381972,,,,7.85398e-5
Test1,3-Recover,173.743,2.937,0.426,-0.003,,0.126673,-38.1972,,12.6673,-0.0381972,,,,7.85398e-5
Test1,3-Recover,174.110,2.962,0.401,-0.003,,0.119239,-38.1972,,11.9239,-0.0381972,,,,7.85398e-5
Test1,3-Recover,174.477,2.987,0.376,0.004,,0.111805,50.9296,,11.1805,0.0509296,,,,7.85398e-5
Test1,3-Recover,174.843,3.011,0.352,0.004,,0.104668,50.9296,,10.4668,0.0509296,,,,7.85398e-5
Test1,3-Recover,175.210,3.036,0.327,0.004,,0.0972346,50.9296,,9.72346,0.0509296,,,,7.85398e-5
Test1,3-Recover,175.577,3.061,0.302,0.004,,0.0898008,50.9296,,8.98008,0.0509296,,,,7.85398e-5
Test1,3-Recover,175.943,3.086,0.277,-0.003,,0.0823669,-38.1972,,8.23669,-0.0381972,,,,7.85398e-5
Test1,3-Recover,176.310,3.11,0.253,-0.003,,0.0752304,-38.1972,,7.52304,-0.0381972,,,,7.85398e-5
Test1,3-Recover,176.677,3.135,0.228,-0.003,,0.0677966,-38.1972,,6.77966,-0.0381972,,,,7.85398e-5
Test1,3-Recover,177.043,3.16,0.203,0.004,,0.0603628,50.9296,,6.03628,0.0509296,,,,7.85398e-5
Test1,3-Recover,177.410,3.185,0.178,0.004,,0.0529289,50.9296,,5.29289,0.0509296,,,,7.85398e-5
Test1,3-Recover,177.777,3.21,0.153,0.011,,0.0454951,140.056,,4.54951,0.140056,,,,7.85398e-5
Test1,3-Recover,178.143,3.234,0.129,0.011,,0.0383586,140.056,,3.83586,0.140056,,,,7.85398e-5
Test1,3-Recover,178.510,3.259,0.104,-0.003,,0.0309248,-38.1972,,3.09248,-0.0381972,,,,7.85398e-5
Test1,3-Recover,178.877,3.284,0.079,-0.003,,0.0234909,-38.1972,,2.34909,-0.0381972,,,,7.85398e-5
Test1,3-Recover,179.243,3.308,0.055,-0.003,,0.0163544,-38.1972,,1.63544,-0.0381972,,,,7.85398e-5
Test1,3-Recover,179.610,3.333,0.03,0.004,,0.00892061,50.9296,,0.892061,0.0509296,,,,7.85398e-5
Test1,3-Recover,179.977,3.358,0.005,0.004,,0.00148677,50.9296,,0.148677,0.0509296,,,,7.85398e-5
Test1,3-Recover,180.110,3.363,-0,-0.003,,0,-38.1972,,0,-0.0381972,,,,7.85398e-5