File: data/gamma_1-0.25_1.csv
SetName,Cycle,Time_S,Size_mm,Displacement_mm,Force_N,,Strain,Stress(Pascal),,%Strain,Stress(kPa),,,,Area(m^2)
Test1,1-Compress,0.000,2.069,-0,0.020,,0,254.648,,0,0.254648,,,,7.85398e-5
Test1,1-Compress,0.333,2.055,0.014,-0.000,,0.00676655,0,,0.676655,0,,,,7.85398e-5
Test1,1-Compress,0.667,2.041,0.028,0.007,,0.0135331,89.1268,,1.35331,0.0891268,,,,7.85398e-5
Test1,1-Compress,1.000,2.027,0.042,-0.000,,0.0202997,0,,2.02997,0,,,,7.85398e-5
Test1,1-Compress,1.333,2.014,0.055,0.007,,0.0265829,89.1268,,2.65829,0.0891268,,,,7.85398e-5
Test1,1-Compress,1.667,1.999,0.07,-0.000,,0.0338328,0,,3.38328,0,,,,7.85398e-5
Test1,1-Compress,2.000,1.986,0.083,0.007,,0.040116,89.1268,,4.0116,0.0891268,,,,7.85398e-5
Test1,1-Compress,2.333,1.972,0.097,0.007,,0.0468826,89.1268,,4.68826,0.0891268,,,,7.85398e-5
Test1,1-Compress,2.667,1.959,0.11,-0.000,,0.0531658,0,,5.31658,0,,,,7.85398e-5
Test1,1-Compress,3.000,1.945,0.124,0.007,,0.0599323,89.1268,,5.99323,0.0891268,,,,7.85398e-5
Test1,1-Compress,3.333,1.931,0.138,0.007,,0.0666989,89.1268,,6.66989,0.0891268,,,,7.85398e-5
Test1,1-Compress,3.667,1.917,0.152,-0.000,,0.0734654,0,,7.34654,0,,,,7.85398e-5
Test1,1-Compress,4.000,1.903,0.166,-0.000,,0.080232,0,,8.0232,0,,,,7.85398e-5
Test1,1-Compress,4.333,1.889,0.18,-0.000,,0.0869986,0,,8.69986,0,,,,7.85398e-5
Test1,1-Compress,4.667,1.875,0.194,-0.000,,0.0937651,0,,9.37651,0,,,,7.85398e-5
Test1,1-Compress,5.000,1.862,0.207,-0.000,,0.100048,0,,10.0048,0,,,,7.85398e-5
Test1,1-Compress,5.333,1.848,0.221,-0.000,,0.106815,0,,10.6815,0,,,,7.85398e-5
Test1,1-Compress,5.667,1.834,0.235,0.014,,0.113581,178.254,,11.3581,0.178254,,,,7.85398e-5
Test1,1-Compress,6.000,1.82,0.249,0.007,,0.120348,89.1268,,12.0348,0.0891268,,,,7.85398e-5
Test1,1-Compress,6.333,1.807,0.262,0.020,,0.126631,254.648,,12.6631,0.254648,,,,7.85398e-5
Test1,1-Compress,6.667,1.793,0.276,0.027,,0.133398,343.775,,13.3398,0.343775,,,,7.85398e-5
Test1,1-Compress,7.000,1.779,0.29,0.014,,0.140164,178.254,,14.0164,0.178254,,,,7.85398e-5
Test1,1-Compress,7.333,1.765,0.304,0.020,,0.146931,254.648,,14.6931,0.254648,,,,7.85398e-5
Test1,1-Compress,7.667,1.751,0.318,0.027,,0.153697,343.775,,15.3697,0.343775,,,,7.85398e-5
Test1,1-Compress,8.000,1.737,0.332,0.027,,0.160464,343.775,,16.0464,0.343775,,,,7.85398e-5
Test1,1-Compress,8.333,1.724,0.345,0.020,,0.166747,254.648,,16.6747,0.254648,,,,7.85398e-5
Test1,1-Compress,8.667,1.71,0.359,0.020,,0.173514,254.648,,17.3514,0.254648,,,,7.85398e-5
Test1,1-Compress,9.000,1.696,0.373,0.020,,0.18028,254.648,,18.028,0.254648,,,,7.85398e-5
Test1,1-Compress,9.333,1.682,0.387,0.014,,0.187047,178.254,,18.7047,0.178254,,,,7.85398e-5
Test1,1-Compress,9.667,1.668,0.401,0.034,,0.193813,432.902,,19.3813,0.432902,,,,7.85398e-5
Test1,1-Compress,10.000,1.654,0.415,0.014,,0.20058,178.254,,20.058,0.178254,,,,7.85398e-5
Test1,1-Compress,10.333,1.641,0.428,0.020,,0.206863,254.648,,20.6863,0.254648,,,,7.85398e-5
Test1,1-Compress,10.667,1.627,0.442,0.020,,0.21363,254.648,,21.363,0.254648,,,,7.85398e-5
Test1,1-Compress,11.000,1.613,0.456,0.007,,0.220396,89.1268,,22.0396,0.0891268,,,,7.85398e-5
Test1,1-Compress,11.333,1.6,0.469,0.027,,0.22668,343.775,,22.668,0.343775,,,,7.85398e-5
Test1,1-Compress,11.667,1.586,0.483,0.007,,0.233446,89.1268,,23.3446,0.0891268,,,,7.85398e-5
Test1,1-Compress,12.000,1.572,0.497,0.027,,0.240213,343.775,,24.0213,0.343775,,,,7.85398e-5
Test1,1-Compress,12.333,1.558,0.511,0.014,,0.246979,178.254,,24.6979,0.178254,,,,7.85398e-5
Test1,1-Compress,12.667,1.544,0.525,0.020,,0.253746,254.648,,25.3746,0.254648,,,,7.85398e-5
Test1,1-Compress,13.000,1.53,0.539,0.027,,0.260512,343.775,,26.0512,0.343775,,,,7.85398e-5
Test1,1-Compress,13.333,1.516,0.553,0.034,,0.267279,432.902,,26.7279,0.432902,,,,7.85398e-5
Test1,1-Compress,13.667,1.502,0.567,0.048,,0.274045,611.155,,27.4045,0.611155,,,,7.85398e-5
Test1,1-Compress,14.000,1.489,0.58,0.027,,0.280329,343.775,,28.0329,0.343775,,,,7.85398e-5
Test1,1-Compress,14.333,1.475,0.594,0.054,,0.287095,687.549,,28.7095,0.687549,,,,7.85398e-5
Test1,1-Compress,14.667,1.461,0.608,0.054,,0.293862,687.549,,29.3862,0.687549,,,,7.85398e-5
Test1,1-Compress,15.000,1.448,0.621,0.054,,0.300145,687.549,,30.0145,0.687549,,,,7.85398e-5
Test1,1-Compress,15.333,1.434,0.635,0.048,,0.306912,611.155,,30.6912,0.611155,,,,7.85398e-5
Test1,1-Compress,15.667,1.42,0.649,0.048,,0.313678,611.155,,31.3678,0.611155,,,,7.85398e-5
Test1,1-Compress,16.000,1.406,0.663,0.054,,0.320445,687.549,,32.0445,0.687549,,,,7.85398e-5
Test1,1-Compress,16.333,1.392,0.677,0.054,,0.327211,687.549,,32.7211,0.687549,,,,7.85398e-5
Test1,1-Compress,16.667,1.378,0.691,0.048,,0.333978,611.155,,33.3978,0.611155,,,,7.85398e-5
Test1,1-Compress,17.000,1.365,0.704,0.054,,0.340261,687.549,,34.0261,0.687549,,,,7.85398e-5
Test1,1-Compress,17.333,1.351,0.718,0.054,,0.347028,687.549,,34.7028,0.687549,,,,7.85398e-5
Test1,1-Compress,17.667,1.337,0.732,0.054,,0.353794,687.549,,35.3794,0.687549,,,,7.85398e-5
Test1,1-Compress,18.000,1.323,0.746,0.054,,0.360561,687.549,,36.0561,0.687549,,,,7.85398e-5
Test1,1-Compress,18.333,1.309,0.76,0.054,,0.367327,687.549,,36.7327,0.687549,,,,7.85398e-5
Test1,1-Compress,18.667,1.295,0.774,0.054,,0.374094,687.549,,37.4094,0.687549,,,,7.85398e-5
Test1,1-Compress,19.000,1.282,0.787,0.054,,0.380377,687.549,,38.0377,0.687549,,,,7.85398e-5
Test1,1-Compress,19.333,1.268,0.801,0.054,,0.387144,687.549,,38.7144,0.687549,,,,7.85398e-5
Test1,1-Compress,19.667,1.254,0.815,0.054,,0.39391,687.549,,39.391,0.687549,,,,7.85398e-5
Test1,1-Compress,20.000,1.24,0.829,0.054,,0.400677,687.549,,40.0677,0.687549,,,,7.85398e-5
Test1,1-Compress,20.333,1.227,0.842,0.054,,0.40696,687.549,,40.696,0.687549,,,,7.85398e-5
Test1,1-Compress,20.667,1.213,0.856,0.054,,0.413726,687.549,,41.3726,0.687549,,,,7.85398e-5
Test1,1-Compress,21.000,1.199,0.87,0.054,,0.420493,687.549,,42.0493,0.687549,,,,7.85398e-5
Test1,1-Compress,21.333,1.185,0.884,0.054,,0.42726,687.549,,42.726,0.687549,,,,7.85398e-5
Test1,1-Compress,21.667,1.171,0.898,0.054,,0.434026,687.549,,43.4026,0.687549,,,,7.85398e-5
Test1,1-Compress,22.000,1.157,0.912,0.054,,0.440793,687.549,,44.0793,0.687549,,,,7.85398e-5
Test1,1-Compress,22.333,1.143,0.926,0.054,,0.447559,687.549,,44.7559,0.687549,,,,7.85398e-5
Test1,1-Compress,22.667,1.13,0.939,0.054,,0.453842,687.549,,45.3842,0.687549,,,,7.85398e-5
Test1,1-Compress,23.000,1.116,0.953,0.054,,0.460609,687.549,,46.0609,0.687549,,,,7.85398e-5
Test1,1-Compress,23.333,1.103,0.966,0.054,,0.466892,687.549,,46.6892,0.687549,,,,7.85398e-5
Test1,1-Compress,23.667,1.088,0.981,0.054,,0.474142,687.549,,47.4142,0.687549,,,,7.85398e-5
Test1,1-Compress,24.000,1.075,0.994,0.054,,0.480425,687.549,,48.0425,0.687549,,,,7.85398e-5
Test1,1-Compress,24.333,1.061,1.008,0.054,,0.487192,687.549,,48.7192,0.687549,,,,7.85398e-5
Test1,1-Compress,24.667,1.047,1.022,0.054,,0.493958,687.549,,49.3958,0.687549,,,,7.85398e-5
Test1,1-Compress,25.000,1.033,1.036,0.054,,0.500725,687.549,,50.0725,0.687549,,,,7.85398e-5
Test1,1-Compress,25.333,1.019,1.05,0.054,,0.507492,687.549,,50.7492,0.687549,,,,7.85398e-5
Test1,1-Compress,25.667,1.006,1.063,0.054,,0.513775,687.549,,51.3775,0.687549,,,,7.85398e-5
Test1,1-Compress,26.000,0.992,1.077,0.061,,0.520541,776.676,,52.0541,0.776676,,,,7.85398e-5
Test1,1-Compress,26.333,0.978,1.091,0.061,,0.527308,776.676,,52.7308,0.776676,,,,7.85398e-5
Test1,1-Compress,26.667,0.964,1.105,0.061,,0.534074,776.676,,53.4074,0.776676,,,,7.85398e-5
Test1,1-Compress,27.000,0.95,1.119,0.061,,0.540841,776.676,,54.0841,0.776676,,,,7.85398e-5
Test1,1-Compress,27.333,0.937,1.132,0.054,,0.547124,687.549,,54.7124,0.687549,,,,7.85398e-5
Test1,1-Compress,27.667,0.922,1.147,0.054,,0.554374,687.549,,55.4374,0.687549,,,,7.85398e-5
Test1,1-Compress,28.000,0.909,1.16,0.054,,0.560657,687.549,,56.0657,0.687549,,,,7.85398e-5
Test1,1-Compress,28.333,0.895,1.174,0.061,,0.567424,776.676,,56.7424,0.776676,,,,7.85398e-5
Test1,1-Compress,28.667,0.881,1.188,0.061,,0.57419,776.676,,57.419,0.776676,,,,7.85398e-5
Test1,1-Compress,29.000,0.868,1.201,0.054,,0.580474,687.549,,58.0474,0.687549,,,,7.85398e-5
Test1,1-Compress,29.333,0.854,1.215,0.068,,0.58724,865.803,,58.724,0.865803,,,,7.85398e-5
Test1,1-Compress,29.667,0.84,1.229,0.068,,0.594007,865.803,,59.4007,0.865803,,,,7.85398e-5
Test1,1-Compress,30.000,0.828,1.241,0.088,,0.599807,1120.45,,59.9807,1.12045,,,,7.85398e-5
Test1,1-Recover,30.333,0.841,1.228,0.081,,0.593523,1031.32,,59.3523,1.03132,,,,7.85398e-5
Test1,1-Recover,30.667,0.855,1.214,0.088,,0.586757,1120.45,,58.6757,1.12045,,,,7.85398e-5
Test1,1-Recover,31.000,0.869,1.2,0.075,,0.57999,954.93,,57.999,0.95493,,,,7.85398e-5
Test1,1-Recover,31.333,0.882,1.187,0.068,,0.573707,865.803,,57.3707,0.865803,,,,7.85398e-5
Test1,1-Recover,31.667,0.896,1.173,0.054,,0.566941,687.549,,56.6941,0.687549,,,,7.85398e-5
Test1,1-Recover,32.000,0.91,1.159,0.068,,0.560174,865.803,,56.0174,0.865803,,,,7.85398e-5
Test1,1-Recover,32.333,0.924,1.145,0.054,,0.553407,687.549,,55.3407,0.687549,,,,7.85398e-5
Test1,1-Recover,32.667,0.938,1.131,0.054,,0.546641,687.549,,54.6641,0.687549,,,,7.85398e-5
Test1,1-Recover,33.000,0.952,1.117,0.054,,0.539874,687.549,,53.9874,0.687549,,,,7.85398e-5
Test1,1-Recover,33.333,0.965,1.104,0.054,,0.533591,687.549,,53.3591,0.687549,,,,7.85398e-5
Test1,1-Recover,33.667,0.979,1.09,0.054,,0.526825,687.549,,52.6825,0.687549,,,,7.85398e-5
Test1,1-Recover,34.000,0.993,1.076,0.054,,0.520058,687.549,,52.0058,0.687549,,,,7.85398e-5
Test1,1-Recover,34.333,1.007,1.062,0.054,,0.513291,687.549,,51.3291,0.687549,,,,7.85398e-5
Test1,1-Recover,34.667,1.021,1.048,0.054,,0.506525,687.549,,50.6525,0.687549,,,,7.85398e-5
Test1,1-Recover,35.000,1.034,1.035,0.054,,0.500242,687.549,,50.0242,0.687549,,,,7.85398e-5
Test1,1-Recover,35.333,1.048,1.021,0.054,,0.493475,687.549,,49.3475,0.687549,,,,7.85398e-5
Test1,1-Recover,35.667,1.062,1.007,0.054,,0.486709,687.549,,48.6709,0.687549,,,,7.85398e-5
Test1,1-Recover,36.000,1.076,0.993,0.054,,0.479942,687.549,,47.9942,0.687549,,,,7.85398e-5
Test1,1-Recover,36.333,1.09,0.979,0.054,,0.473175,687.549,,47.3175,0.687549,,,,7.85398e-5
Test1,1-Recover,36.667,1.104,0.965,0.048,,0.466409,611.155,,46.6409,0.611155,,,,7.85398e-5
Test1,1-Recover,37.000,1.117,0.952,0.048,,0.460126,611.155,,46.0126,0.611155,,,,7.85398e-5
Test1,1-Recover,37.333,1.131,0.938,0.041,,0.453359,522.028,,45.3359,0.522028,,,,7.85398e-5
Test1,1-Recover,37.667,1.145,0.924,0.054,,0.446593,687.549,,44.6593,0.687549,,,,7.85398e-5
Test1,1-Recover,38.000,1.159,0.91,0.048,,0.439826,611.155,,43.9826,0.611155,,,,7.85398e-5
Test1,1-Recover,38.333,1.172,0.897,0.054,,0.433543,687.549,,43.3543,0.687549,,,,7.85398e-5
Test1,1-Recover,38.667,1.186,0.883,0.054,,0.426776,687.549,,42.6776,0.687549,,,,7.85398e-5
Test1,1-Recover,39.000,1.2,0.869,0.054,,0.42001,687.549,,42.001,0.687549,,,,7.85398e-5
Test1,1-Recover,39.333,1.214,0.855,0.054,,0.413243,687.549,,41.3243,0.687549,,,,7.85398e-5
Test1,1-Recover,39.667,1.228,0.841,0.048,,0.406477,611.155,,40.6477,0.611155,,,,7.85398e-5
Test1,1-Recover,40.000,1.241,0.828,0.054,,0.400193,687.549,,40.0193,0.687549,,,,7.85398e-5
Test1,1-Recover,40.333,1.255,0.814,0.041,,0.393427,522.028,,39.3427,0.522028,,,,7.85398e-5
Test1,1-Recover,40.667,1.269,0.8,0.048,,0.38666,611.155,,38.666,0.611155,,,,7.85398e-5
Test1,1-Recover,41.000,1.283,0.786,0.041,,0.379894,522.028,,37.9894,0.522028,,,,7.85398e-5
Test1,1-Recover,41.333,1.297,0.772,0.041,,0.373127,522.028,,37.3127,0.522028,,,,7.85398e-5
Test1,1-Recover,41.667,1.311,0.758,0.048,,0.366361,611.155,,36.6361,0.611155,,,,7.85398e-5
Test1,1-Recover,42.000,1.325,0.744,0.027,,0.359594,343.775,,35.9594,0.343775,,,,7.85398e-5
Test1,1-Recover,42.333,1.338,0.731,0.014,,0.353311,178.254,,35.3311,0.178254,,,,7.85398e-5
Test1,1-Recover,42.667,1.352,0.717,0.007,,0.346544,89.1268,,34.6544,0.0891268,,,,7.85398e-5
Test1,1-Recover,43.000,1.366,0.703,0.027,,0.339778,343.775,,33.9778,0.343775,,,,7.85398e-5
Test1,1-Recover,43.333,1.379,0.69,0.014,,0.333494,178.254,,33.3494,0.178254,,,,7.85398e-5
Test1,1-Recover,43.667,1.394,0.675,-0.000,,0.326245,0,,32.6245,0,,,,7.85398e-5
Test1,1-Recover,44.000,1.407,0.662,0.014,,0.319961,178.254,,31.9961,0.178254,,,,7.85398e-5
Test1,1-Recover,44.333,1.421,0.648,0.014,,0.313195,178.254,,31.3195,0.178254,,,,7.85398e-5
Test1,1-Recover,44.667,1.435,0.634,-0.000,,0.306428,0,,30.6428,0,,,,7.85398e-5
Test1,1-Recover,45.000,1.449,0.62,0.007,,0.299662,89.1268,,29.9662,0.0891268,,,,7.85398e-5
Test1,1-Recover,45.333,1.463,0.606,0.020,,0.292895,254.648,,29.2895,0.254648,,,,7.85398e-5
Test1,1-Recover,45.667,1.476,0.593,0.014,,0.286612,178.254,,28.6612,0.178254,,,,7.85398e-5
Test1,1-Recover,46.000,1.49,0.579,0.014,,0.279845,178.254,,27.9845,0.178254,,,,7.85398e-5
Test1,1-Recover,46.333,1.504,0.565,0.027,,0.273079,343.775,,27.3079,0.343775,,,,7.85398e-5
Test1,1-Recover,46.667,1.518,0.551,0.014,,0.266312,178.254,,26.6312,0.178254,,,,7.85398e-5
Test1,1-Recover,47.000,1.532,0.537,0.014,,0.259546,178.254,,25.9546,0.178254,,,,7.85398e-5
Test1,1-Recover,47.333,1.545,0.524,0.007,,0.253262,89.1268,,25.3262,0.0891268,,,,7.85398e-5
Test1,1-Recover,47.667,1.559,0.51,0.014,,0.246496,178.254,,24.6496,0.178254,,,,7.85398e-5
Test1,1-Recover,48.000,1.573,0.496,0.014,,0.239729,178.254,,23.9729,0.178254,,,,7.85398e-5
Test1,1-Recover,48.333,1.587,0.482,0.014,,0.232963,178.254,,23.2963,0.178254,,,,7.85398e-5
Test1,1-Recover,48.667,1.601,0.468,0.007,,0.226196,89.1268,,22.6196,0.0891268,,,,7.85398e-5
Test1,1-Recover,49.000,1.614,0.455,0.014,,0.219913,178.254,,21.9913,0.178254,,,,7.85398e-5
Test1,1-Recover,49.333,1.628,0.441,0.007,,0.213146,89.1268,,21.3146,0.0891268,,,,7.85398e-5
Test1,1-Recover,49.667,1.642,0.427,-0.000,,0.20638,0,,20.638,0,,,,7.85398e-5
Test1,1-Recover,50.000,1.656,0.413,0.014,,0.199613,178.254,,19.9613,0.178254,,,,7.85398e-5
Test1,1-Recover,50.333,1.669,0.4,0.007,,0.19333,89.1268,,19.333,0.0891268,,,,7.85398e-5
Test1,1-Recover,50.667,1.684,0.385,-0.000,,0.18608,0,,18.608,0,,,,7.85398e-5
Test1,1-Recover,51.000,1.697,0.372,0.007,,0.179797,89.1268,,17.9797,0.0891268,,,,7.85398e-5
Test1,1-Recover,51.333,1.711,0.358,-0.000,,0.17303,0,,17.303,0,,,,7.85398e-5
Test1,1-Recover,51.667,1.725,0.344,-0.000,,0.166264,0,,16.6264,0,,,,7.85398e-5
Test1,1-Recover,52.000,1.738,0.331,-0.000,,0.159981,0,,15.9981,0,,,,7.85398e-5
Test1,1-Recover,52.333,1.752,0.317,-0.000,,0.153214,0,,15.3214,0,,,,7.85398e-5
Test1,1-Recover,52.667,1.766,0.303,-0.000,,0.146448,0,,14.6448,0,,,,7.85398e-5
Test1,1-Recover,53.000,1.78,0.289,-0.000,,0.139681,0,,13.9681,0,,,,7.85398e-5
Test1,1-Recover,53.333,1.794,0.275,-0.000,,0.132914,0,,13.2914,0,,,,7.85398e-5
Test1,1-Recover,53.667,1.808,0.261,0.007,,0.126148,89.1268,,12.6148,0.0891268,,,,7.85398e-5
Test1,1-Recover,54.000,1.822,0.247,-0.000,,0.119381,0,,11.9381,0,,,,7.85398e-5
Test1,1-Recover,54.333,1.835,0.234,0.007,,0.113098,89.1268,,11.3098,0.0891268,,,,7.85398e-5
Test1,1-Recover,54.667,1.849,0.22,-0.000,,0.106332,0,,10.6332,0,,,,7.85398e-5
Test1,1-Recover,55.000,1.863,0.206,-0.000,,0.099565,0,,9.9565,0,,,,7.85398e-5
Test1,1-Recover,55.333,1.877,0.192,-0.000,,0.0927985,0,,9.27985,0,,,,7.85398e-5
Test1,1-Recover,55.667,1.891,0.178,-0.000,,0.0860319,0,,8.60319,0,,,,7.85398e-5
Test1,1-Recover,56.000,1.904,0.165,-0.000,,0.0797487,0,,7.97487,0,,,,7.85398e-5
Test1,1-Recover,56.333,1.918,0.151,-0.000,,0.0729821,0,,7.29821,0,,,,7.85398e-5
Test1,1-Recover,56.667,1.932,0.137,-0.000,,0.0662156,0,,6.62156,0,,,,7.85398e-5
Test1,1-Recover,57.000,1.946,0.123,-0.000,,0.059449,0,,5.9449,0,,,,7.85398e-5
Test1,1-Recover,57.333,1.96,0.109,-0.000,,0.0526825,0,,5.26825,0,,,,7.85398e-5
Test1,1-Recover,57.667,1.973,0.096,-0.000,,0.0463992,0,,4.63992,0,,,,7.85398e-5
Test1,1-Recover,58.000,1.987,0.082,-0.000,,0.0396327,0,,3.96327,0,,,,7.85398e-5
Test1,1-Recover,58.333,2.001,0.068,-0.000,,0.0328661,0,,3.28661,0,,,,7.85398e-5
Test1,1-Recover,58.667,2.015,0.054,-0.000,,0.0260996,0,,2.60996,0,,,,7.85398e-5
Test1,1-Recover,59.000,2.029,0.04,-0.000,,0.019333,0,,1.9333,0,,,,7.85398e-5
Test1,1-Recover,59.333,2.042,0.027,-0.000,,0.0130498,0,,1.30498,0,,,,7.85398e-5
Test1,1-Recover,59.667,2.057,0.012,-0.000,,0.0057999,0,,0.57999,0,,,,7.85398e-5
Test1,1-Recover,60.000,2.069,-0,-0.000,,0,0,,0,0,,,,7.85398e-5
Test1,2-Compress,60.317,2.057,0.012,-0.000,,0.0057999,0,,0.57999,0,,,,7.85398e-5
Test1,2-Compress,60.650,2.043,0.026,-0.000,,0.0125665,0,,1.25665,0,,,,7.85398e-5
Test1,2-Compress,60.983,2.03,0.039,-0.000,,0.0188497,0,,1.88497,0,,,,7.85398e-5
Test1,2-Compress,61.317,2.016,0.053,-0.000,,0.0256162,0,,2.56162,0,,,,7.85398e-5
Test1,2-Compress,61.650,2.002,0.067,-0.000,,0.0323828,0,,3.23828,0,,,,7.85398e-5
Test1,2-Compress,61.983,1.988,0.081,-0.000,,0.0391493,0,,3.91493,0,,,,7.85398e-5
Test1,2-Compress,62.317,1.974,0.095,-0.000,,0.0459159,0,,4.59159,0,,,,7.85398e-5
Test1,2-Compress,62.650,1.961,0.108,0.007,,0.0521991,89.1268,,5.21991,0.0891268,,,,7.85398e-5
Test1,2-Compress,62.983,1.947,0.122,-0.000,,0.0589657,0,,5.89657,0,,,,7.85398e-5
Test1,2-Compress,63.317,1.933,0.136,-0.000,,0.0657322,0,,6.57322,0,,,,7.85398e-5
Test1,2-Compress,63.650,1.919,0.15,-0.000,,0.0724988,0,,7.24988,0,,,,7.85398e-5
Test1,2-Compress,63.983,1.905,0.164,-0.000,,0.0792653,0,,7.92653,0,,,,7.85398e-5
Test1,2-Compress,64.317,1.892,0.177,-0.000,,0.0855486,0,,8.55486,0,,,,7.85398e-5
Test1,2-Compress,64.650,1.878,0.191,0.007,,0.0923151,89.1268,,9.23151,0.0891268,,,,7.85398e-5
Test1,2-Compress,64.983,1.864,0.205,0.014,,0.0990817,178.254,,9.90817,0.178254,,,,7.85398e-5
Test1,2-Compress,65.317,1.85,0.219,0.007,,0.105848,89.1268,,10.5848,0.0891268,,,,7.85398e-5
Test1,2-Compress,65.650,1.836,0.233,0.007,,0.112615,89.1268,,11.2615,0.0891268,,,,7.85398e-5
Test1,2-Compress,65.983,1.823,0.246,0.014,,0.118898,178.254,,11.8898,0.178254,,,,7.85398e-5
Test1,2-Compress,66.317,1.808,0.261,0.007,,0.126148,89.1268,,12.6148,0.0891268,,,,7.85398e-5
Test1,2-Compress,66.650,1.795,0.274,0.007,,0.132431,89.1268,,13.2431,0.0891268,,,,7.85398e-5
Test1,2-Compress,66.983,1.781,0.288,0.007,,0.139198,89.1268,,13.9198,0.0891268,,,,7.85398e-5
Test1,2-Compress,67.317,1.767,0.302,-0.000,,0.145964,0,,14.5964,0,,,,7.85398e-5
Test1,2-Compress,67.650,1.754,0.315,0.007,,0.152247,89.1268,,15.2247,0.0891268,,,,7.85398e-5
Test1,2-Compress,67.983,1.74,0.329,0.007,,0.159014,89.1268,,15.9014,0.0891268,,,,7.85398e-5
Test1,2-Compress,68.317,1.726,0.343,-0.000,,0.165781,0,,16.5781,0,,,,7.85398e-5
Test1,2-Compress,68.650,1.712,0.357,-0.000,,0.172547,0,,17.2547,0,,,,7.85398e-5
Test1,2-Compress,68.983,1.698,0.371,-0.000,,0.179314,0,,17.9314,0,,,,7.85398e-5
Test1,2-Compress,69.317,1.684,0.385,-0.000,,0.18608,0,,18.608,0,,,,7.85398e-5
Test1,2-Compress,69.650,1.67,0.399,0.014,,0.192847,178.254,,19.2847,0.178254,,,,7.85398e-5
Test1,2-Compress,69.983,1.657,0.412,0.014,,0.19913,178.254,,19.913,0.178254,,,,7.85398e-5
Test1,2-Compress,70.317,1.643,0.426,0.027,,0.205897,343.775,,20.5897,0.343775,,,,7.85398e-5
Test1,2-Compress,70.650,1.629,0.44,0.034,,0.212663,432.902,,21.2663,0.432902,,,,7.85398e-5
Test1,2-Compress,70.983,1.615,0.454,0.041,,0.21943,522.028,,21.943,0.522028,,,,7.85398e-5
Test1,2-Compress,71.317,1.601,0.468,0.034,,0.226196,432.902,,22.6196,0.432902,,,,7.85398e-5
Test1,2-Compress,71.650,1.588,0.481,0.034,,0.232479,432.902,,23.2479,0.432902,,,,7.85398e-5
Test1,2-Compress,71.983,1.574,0.495,0.048,,0.239246,611.155,,23.9246,0.611155,,,,7.85398e-5
Test1,2-Compress,72.317,1.56,0.509,0.034,,0.246013,432.902,,24.6013,0.432902,,,,7.85398e-5
Test1,2-Compress,72.650,1.546,0.523,0.034,,0.252779,432.902,,25.2779,0.432902,,,,7.85398e-5
Test1,2-Compress,72.983,1.533,0.536,0.020,,0.259062,254.648,,25.9062,0.254648,,,,7.85398e-5
Test1,2-Compress,73.317,1.519,0.55,0.027,,0.265829,343.775,,26.5829,0.343775,,,,7.85398e-5
Test1,2-Compress,73.650,1.505,0.564,0.048,,0.272595,611.155,,27.2595,0.611155,,,,7.85398e-5
Test1,2-Compress,73.983,1.491,0.578,0.048,,0.279362,611.155,,27.9362,0.611155,,,,7.85398e-5
Test1,2-Compress,74.317,1.477,0.592,0.041,,0.286129,522.028,,28.6129,0.522028,,,,7.85398e-5
Test1,2-Compress,74.650,1.463,0.606,0.054,,0.292895,687.549,,29.2895,0.687549,,,,7.85398e-5
Test1,2-Compress,74.983,1.45,0.619,0.041,,0.299178,522.028,,29.9178,0.522028,,,,7.85398e-5
Test1,2-Compress,75.317,1.436,0.633,0.041,,0.305945,522.028,,30.5945,0.522028,,,,7.85398e-5
Test1,2-Compress,75.650,1.422,0.647,0.041,,0.312711,522.028,,31.2711,0.522028,,,,7.85398e-5
Test1,2-Compress,75.983,1.408,0.661,0.054,,0.319478,687.549,,31.9478,0.687549,,,,7.85398e-5
Test1,2-Compress,76.317,1.394,0.675,0.054,,0.326245,687.549,,32.6245,0.687549,,,,7.85398e-5
Test1,2-Compress,76.650,1.381,0.688,0.048,,0.332528,611.155,,33.2528,0.611155,,,,7.85398e-5
Test1,2-Compress,76.983,1.367,0.702,0.054,,0.339294,687.549,,33.9294,0.687549,,,,7.85398e-5
Test1,2-Compress,77.317,1.353,0.716,0.048,,0.346061,611.155,,34.6061,0.611155,,,,7.85398e-5
Test1,2-Compress,77.650,1.339,0.73,0.054,,0.352827,687.549,,35.2827,0.687549,,,,7.85398e-5
Test1,2-Compress,77.983,1.325,0.744,0.048,,0.359594,611.155,,35.9594,0.611155,,,,7.85398e-5
Test1,2-Compress,78.317,1.311,0.758,0.054,,0.366361,687.549,,36.6361,0.687549,,,,7.85398e-5
Test1,2-Compress,78.650,1.298,0.771,0.054,,0.372644,687.549,,37.2644,0.687549,,,,7.85398e-5
Test1,2-Compress,78.983,1.284,0.785,0.054,,0.37941,687.549,,37.941,0.687549,,,,7.85398e-5
Test1,2-Compress,79.317,1.27,0.799,0.054,,0.386177,687.549,,38.6177,0.687549,,,,7.85398e-5
Test1,2-Compress,79.650,1.256,0.813,0.054,,0.392943,687.549,,39.2943,0.687549,,,,7.85398e-5
Test1,2-Compress,79.983,1.243,0.826,0.054,,0.399227,687.549,,39.9227,0.687549,,,,7.85398e-5
Test1,2-Compress,80.317,1.228,0.841,0.054,,0.406477,687.549,,40.6477,0.687549,,,,7.85398e-5
Test1,2-Compress,80.650,1.215,0.854,0.054,,0.41276,687.549,,41.276,0.687549,,,,7.85398e-5
Test1,2-Compress,80.983,1.201,0.868,0.054,,0.419526,687.549,,41.9526,0.687549,,,,7.85398e-5
Test1,2-Compress,81.317,1.187,0.882,0.054,,0.426293,687.549,,42.6293,0.687549,,,,7.85398e-5
Test1,2-Compress,81.650,1.173,0.896,0.054,,0.433059,687.549,,43.3059,0.687549,,,,7.85398e-5
Test1,2-Compress,81.983,1.16,0.909,0.054,,0.439343,687.549,,43.9343,0.687549,,,,7.85398e-5
Test1,2-Compress,82.317,1.146,0.923,0.054,,0.446109,687.549,,44.6109,0.687549,,,,7.85398e-5
Test1,2-Compress,82.650,1.132,0.937,0.054,,0.452876,687.549,,45.2876,0.687549,,,,7.85398e-5
Test1,2-Compress,82.983,1.118,0.951,0.054,,0.459642,687.549,,45.9642,0.687549,,,,7.85398e-5
Test1,2-Compress,83.317,1.104,0.965,0.054,,0.466409,687.549,,46.6409,0.687549,,,,7.85398e-5
Test1,2-Compress,83.650,1.09,0.979,0.054,,0.473175,687.549,,47.3175,0.687549,,,,7.85398e-5
Test1,2-Compress,83.983,1.077,0.992,0.054,,0.479459,687.549,,47.9459,0.687549,,,,7.85398e-5
Test1,2-Compress,84.317,1.063,1.006,0.054,,0.486225,687.549,,48.6225,0.687549,,,,7.85398e-5
Test1,2-Compress,84.650,1.049,1.02,0.054,,0.492992,687.549,,49.2992,0.687549,,,,7.85398e-5
Test1,2-Compress,84.983,1.036,1.033,0.054,,0.499275,687.549,,49.9275,0.687549,,,,7.85398e-5
Test1,2-Compress,85.317,1.021,1.048,0.054,,0.506525,687.549,,50.6525,0.687549,,,,7.85398e-5
Test1,2-Compress,85.650,1.008,1.061,0.054,,0.512808,687.549,,51.2808,0.687549,,,,7.85398e-5
Test1,2-Compress,85.983,0.994,1.075,0.068,,0.519575,865.803,,51.9575,0.865803,,,,7.85398e-5
Test1,2-Compress,86.317,0.98,1.089,0.068,,0.526341,865.803,,52.6341,0.865803,,,,7.85398e-5
Test1,2-Compress,86.650,0.966,1.103,0.061,,0.533108,776.676,,53.3108,0.776676,,,,7.85398e-5
Test1,2-Compress,86.983,0.952,1.117,0.081,,0.539874,1031.32,,53.9874,1.03132,,,,7.85398e-5
Test1,2-Compress,87.317,0.939,1.13,0.088,,0.546158,1120.45,,54.6158,1.12045,,,,7.85398e-5
Test1,2-Compress,87.650,0.925,1.144,0.061,,0.552924,776.676,,55.2924,0.776676,,,,7.85398e-5
Test1,2-Compress,87.983,0.911,1.158,0.068,,0.559691,865.803,,55.9691,0.865803,,,,7.85398e-5
Test1,2-Compress,88.317,0.897,1.172,0.075,,0.566457,954.93,,56.6457,0.95493,,,,7.85398e-5
Test1,2-Compress,88.650,0.883,1.186,0.081,,0.573224,1031.32,,57.3224,1.03132,,,,7.85398e-5
Test1,2-Compress,88.983,0.87,1.199,0.075,,0.579507,954.93,,57.9507,0.95493,,,,7.85398e-5
Test1,2-Compress,89.317,0.855,1.214,0.075,,0.586757,954.93,,58.6757,0.95493,,,,7.85398e-5
Test1,2-Compress,89.650,0.842,1.227,0.075,,0.59304,954.93,,59.304,0.95493,,,,7.85398e-5
Test1,2-Compress,89.983,0.828,1.241,0.075,,0.599807,954.93,,59.9807,0.95493,,,,7.85398e-5
Test1,2-Recover,90.303,0.838,1.231,0.088,,0.594973,1120.45,,59.4973,1.12045,,,,7.85398e-5
Test1,2-Recover,90.637,0.852,1.217,0.061,,0.588207,776.676,,58.8207,0.776676,,,,7.85398e-5
Test1,2-Recover,90.970,0.866,1.203,0.061,,0.58144,776.676,,58.144,0.776676,,,,7.85398e-5
Test1,2-Recover,91.303,0.879,1.19,0.061,,0.575157,776.676,,57.5157,0.776676,,,,7.85398e-5
Test1,2-Recover,91.637,0.894,1.175,0.061,,0.567907,776.676,,56.7907,0.776676,,,,7.85398e-5
Test1,2-Recover,91.970,0.907,1.162,0.061,,0.561624,776.676,,56.1624,0.776676,,,,7.85398e-5
Test1,2-Recover,92.303,0.921,1.148,0.054,,0.554857,687.549,,55.4857,0.687549,,,,7.85398e-5
Test1,2-Recover,92.637,0.935,1.134,0.054,,0.548091,687.549,,54.8091,0.687549,,,,7.85398e-5
Test1,2-Recover,92.970,0.948,1.121,0.054,,0.541808,687.549,,54.1808,0.687549,,,,7.85398e-5
Test1,2-Recover,93.303,0.962,1.107,0.054,,0.535041,687.549,,53.5041,0.687549,,,,7.85398e-5
Test1,2-Recover,93.637,0.976,1.093,0.054,,0.528275,687.549,,52.8275,0.687549,,,,7.85398e-5
Test1,2-Recover,93.970,0.99,1.079,0.054,,0.521508,687.549,,52.1508,0.687549,,,,7.85398e-5
Test1,2-Recover,94.303,1.004,1.065,0.054,,0.514741,687.549,,51.4741,0.687549,,,,7.85398e-5
Test1,2-Recover,94.637,1.018,1.051,0.054,,0.507975,687.549,,50.7975,0.687549,,,,7.85398e-5
Test1,2-Recover,94.970,1.032,1.037,0.054,,0.501208,687.549,,50.1208,0.687549,,,,7.85398e-5
Test1,2-Recover,95.303,1.045,1.024,0.054,,0.494925,687.549,,49.4925,0.687549,,,,7.85398e-5
Test1,2-Recover,95.637,1.059,1.01,0.054,,0.488159,687.549,,48.8159,0.687549,,,,7.85398e-5
Test1,2-Recover,95.970,1.073,0.996,0.054,,0.481392,687.549,,48.1392,0.687549,,,,7.85398e-5
Test1,2-Recover,96.303,1.086,0.983,0.054,,0.475109,687.549,,47.5109,0.687549,,,,7.85398e-5
Test1,2-Recover,96.637,1.101,0.968,0.054,,0.467859,687.549,,46.7859,0.687549,,,,7.85398e-5
Test1,2-Recover,96.970,1.114,0.955,0.054,,0.461576,687.549,,46.1576,0.687549,,,,7.85398e-5
Test1,2-Recover,97.303,1.128,0.941,0.054,,0.454809,687.549,,45.4809,0.687549,,,,7.85398e-5
Test1,2-Recover,97.637,1.142,0.927,0.054,,0.448043,687.549,,44.8043,0.687549,,,,7.85398e-5
Test1,2-Recover,97.970,1.156,0.913,0.054,,0.441276,687.549,,44.1276,0.687549,,,,7.85398e-5
Test1,2-Recover,98.303,1.17,0.899,0.054,,0.434509,687.549,,43.4509,0.687549,,,,7.85398e-5
Test1,2-Recover,98.637,1.183,0.886,0.054,,0.428226,687.549,,42.8226,0.687549,,,,7.85398e-5
Test1,2-Recover,98.970,1.197,0.872,0.054,,0.42146,687.549,,42.146,0.687549,,,,7.85398e-5
Test1,2-Recover,99.303,1.211,0.858,0.054,,0.414693,687.549,,41.4693,0.687549,,,,7.85398e-5
Test1,2-Recover,99.637,1.225,0.844,0.041,,0.407927,522.028,,40.7927,0.522028,,,,7.85398e-5
Test1,2-Recover,99.970,1.239,0.83,0.041,,0.40116,522.028,,40.116,0.522028,,,,7.85398e-5
Test1,2-Recover,100.303,1.252,0.817,0.054,,0.394877,687.549,,39.4877,0.687549,,,,7.85398e-5
Test1,2-Recover,100.637,1.267,0.802,0.041,,0.387627,522.028,,38.7627,0.522028,,,,7.85398e-5
Test1,2-Recover,100.970,1.28,0.789,0.034,,0.381344,432.902,,38.1344,0.432902,,,,7.85398e-5
Test1,2-Recover,101.303,1.294,0.775,0.054,,0.374577,687.549,,37.4577,0.687549,,,,7.85398e-5
Test1,2-Recover,101.637,1.308,0.761,0.041,,0.367811,522.028,,36.7811,0.522028,,,,7.85398e-5
Test1,2-Recover,101.970,1.321,0.748,0.048,,0.361527,611.155,,36.1527,0.611155,,,,7.85398e-5
Test1,2-Recover,102.303,1.335,0.734,0.034,,0.354761,432.902,,35.4761,0.432902,,,,7.85398e-5
Test1,2-Recover,102.637,1.349,0.72,0.041,,0.347994,522.028,,34.7994,0.522028,,,,7.85398e-5
Test1,2-Recover,102.970,1.363,0.706,0.041,,0.341228,522.028,,34.1228,0.522028,,,,7.85398e-5
Test1,2-Recover,103.303,1.377,0.692,0.034,,0.334461,432.902,,33.4461,0.432902,,,,7.85398e-5
Test1,2-Recover,103.637,1.391,0.678,0.041,,0.327695,522.028,,32.7695,0.522028,,,,7.85398e-5
Test1,2-Recover,103.970,1.404,0.665,0.048,,0.321411,611.155,,32.1411,0.611155,,,,7.85398e-5
Test1,2-Recover,104.303,1.418,0.651,0.034,,0.314645,432.902,,31.4645,0.432902,,,,7.85398e-5
Test1,2-Recover,104.637,1.432,0.637,0.027,,0.307878,343.775,,30.7878,0.343775,,,,7.85398e-5
Test1,2-Recover,104.970,1.446,0.623,0.020,,0.301112,254.648,,30.1112,0.254648,,,,7.85398e-5
Test1,2-Recover,105.303,1.459,0.61,0.034,,0.294828,432.902,,29.4828,0.432902,,,,7.85398e-5
Test1,2-Recover,105.637,1.474,0.595,0.020,,0.287579,254.648,,28.7579,0.254648,,,,7.85398e-5
Test1,2-Recover,105.970,1.487,0.582,0.020,,0.281295,254.648,,28.1295,0.254648,,,,7.85398e-5
Test1,2-Recover,106.303,1.501,0.568,0.020,,0.274529,254.648,,27.4529,0.254648,,,,7.85398e-5
Test1,2-Recover,106.637,1.515,0.554,0.014,,0.267762,178.254,,26.7762,0.178254,,,,7.85398e-5
Test1,2-Recover,106.970,1.529,0.54,0.014,,0.260996,178.254,,26.0996,0.178254,,,,7.85398e-5
Test1,2-Recover,107.303,1.542,0.527,0.007,,0.254712,89.1268,,25.4712,0.0891268,,,,7.85398e-5
Test1,2-Recover,107.637,1.556,0.513,0.007,,0.247946,89.1268,,24.7946,0.0891268,,,,7.85398e-5
Test1,2-Recover,107.970,1.57,0.499,0.007,,0.241179,89.1268,,24.1179,0.0891268,,,,7.85398e-5
Test1,2-Recover,108.303,1.584,0.485,-0.000,,0.234413,0,,23.4413,0,,,,7.85398e-5
Test1,2-Recover,108.637,1.598,0.471,-0.000,,0.227646,0,,22.7646,0,,,,7.85398e-5
Test1,2-Recover,108.970,1.612,0.457,-0.000,,0.22088,0,,22.088,0,,,,7.85398e-5
Test1,2-Recover,109.303,1.625,0.444,-0.000,,0.214596,0,,21.4596,0,,,,7.85398e-5
Test1,2-Recover,109.637,1.639,0.43,-0.000,,0.20783,0,,20.783,0,,,,7.85398e-5
Test1,2-Recover,109.970,1.653,0.416,0.007,,0.201063,89.1268,,20.1063,0.0891268,,,,7.85398e-5
Test1,2-Recover,110.303,1.667,0.402,0.014,,0.194297,178.254,,19.4297,0.178254,,,,7.85398e-5
Test1,2-Recover,110.637,1.681,0.388,0.014,,0.18753,178.254,,18.753,0.178254,,,,7.85398e-5
Test1,2-Recover,110.970,1.694,0.375,0.014,,0.181247,178.254,,18.1247,0.178254,,,,7.85398e-5
Test1,2-Recover,111.303,1.708,0.361,0.014,,0.17448,178.254,,17.448,0.178254,,,,7.85398e-5
Test1,2-Recover,111.637,1.722,0.347,0.020,,0.167714,254.648,,16.7714,0.254648,,,,7.85398e-5
Test1,2-Recover,111.970,1.736,0.333,-0.000,,0.160947,0,,16.0947,0,,,,7.85398e-5
Test1,2-Recover,112.303,1.75,0.319,-0.000,,0.154181,0,,15.4181,0,,,,7.85398e-5
Test1,2-Recover,112.637,1.764,0.305,-0.000,,0.147414,0,,14.7414,0,,,,7.85398e-5
Test1,2-Recover,112.970,1.777,0.292,-0.000,,0.141131,0,,14.1131,0,,,,7.85398e-5
Test1,2-Recover,113.303,1.791,0.278,-0.000,,0.134364,0,,13.4364,0,,,,7.85398e-5
Test1,2-Recover,113.637,1.805,0.264,-0.000,,0.127598,0,,12.7598,0,,,,7.85398e-5
Test1,2-Recover,113.970,1.819,0.25,-0.000,,0.120831,0,,12.0831,0,,,,7.85398e-5
Test1,2-Recover,114.303,1.832,0.237,0.007,,0.114548,89.1268,,11.4548,0.0891268,,,,7.85398e-5
Test1,2-Recover,114.637,1.846,0.223,-0.000,,0.107782,0,,10.7782,0,,,,7.85398e-5
Test1,2-Recover,114.970,1.86,0.209,-0.000,,0.101015,0,,10.1015,0,,,,7.85398e-5
Test1,2-Recover,115.303,1.874,0.195,-0.000,,0.0942484,0,,9.42484,0,,,,7.85398e-5
Test1,2-Recover,115.637,1.888,0.181,-0.000,,0.0874819,0,,8.74819,0,,,,7.85398e-5
Test1,2-Recover,115.970,1.901,0.168,-0.000,,0.0811986,0,,8.11986,0,,,,7.85398e-5
Test1,2-Recover,116.303,1.915,0.154,-0.000,,0.0744321,0,,7.44321,0,,,,7.85398e-5
Test1,2-Recover,116.637,1.929,0.14,-0.000,,0.0676655,0,,6.76655,0,,,,7.85398e-5
Test1,2-Recover,116.970,1.943,0.126,-0.000,,0.060899,0,,6.0899,0,,,,7.85398e-5
Test1,2-Recover,117.303,1.957,0.112,-0.000,,0.0541324,0,,5.41324,0,,,,7.85398e-5
Test1,2-Recover,117.637,1.971,0.098,-0.000,,0.0473659,0,,4.73659,0,,,,7.85398e-5
Test1,2-Recover,117.970,1.985,0.084,0.007,,0.0405993,89.1268,,4.05993,0.0891268,,,,7.85398e-5
Test1,2-Recover,118.303,1.998,0.071,-0.000,,0.0343161,0,,3.43161,0,,,,7.85398e-5
Test1,2-Recover,118.637,2.012,0.057,-0.000,,0.0275495,0,,2.75495,0,,,,7.85398e-5
Test1,2-Recover,118.970,2.026,0.043,0.007,,0.020783,89.1268,,2.0783,0.0891268,,,,7.85398e-5
Test1,2-Recover,119.303,2.039,0.03,0.007,,0.0144998,89.1268,,1.44998,0.0891268,,,,7.85398e-5
Test1,2-Recover,119.637,2.054,0.015,-0.000,,0.00724988,0,,0.724988,0,,,,7.85398e-5
Test1,2-Recover,119.970,2.067,0.002,-0.000,,0.000966651,0,,0.0966651,0,,,,7.85398e-5
Test1,3-Compress,120.290,2.06,0.009,-0.000,,0.00434993,0,,0.434993,0,,,,7.85398e-5
Test1,3-Compress,120.623,2.046,0.023,-0.000,,0.0111165,0,,1.11165,0,,,,7.85398e-5
Test1,3-Compress,120.957,2.032,0.037,-0.000,,0.017883,0,,1.7883,0,,,,7.85398e-5
Test1,3-Compress,121.290,2.018,0.051,-0.000,,0.0246496,0,,2.46496,0,,,,7.85398e-5
Test1,3-Compress,121.623,2.005,0.064,-0.000,,0.0309328,0,,3.09328,0,,,,7.85398e-5
Test1,3-Compress,121.957,1.991,0.078,-0.000,,0.0376994,0,,3.76994,0,,,,7.85398e-5
Test1,3-Compress,122.290,1.977,0.092,-0.000,,0.0444659,0,,4.44659,0,,,,7.85398e-5
Test1,3-Compress,122.623,1.964,0.105,-0.000,,0.0507492,0,,5.07492,0,,,,7.85398e-5
Test1,3-Compress,122.957,1.949,0.12,-0.000,,0.057999,0,,5.7999,0,,,,7.85398e-5
Test1,3-Compress,123.290,1.936,0.133,-0.000,,0.0642823,0,,6.42823,0,,,,7.85398e-5
Test1,3-Compress,123.623,1.922,0.147,-0.000,,0.0710488,0,,7.10488,0,,,,7.85398e-5
Test1,3-Compress,123.957,1.908,0.161,-0.000,,0.0778154,0,,7.78154,0,,,,7.85398e-5
Test1,3-Compress,124.290,1.894,0.175,-0.000,,0.0845819,0,,8.45819,0,,,,7.85398e-5
Test1,3-Compress,124.623,1.88,0.189,-0.000,,0.0913485,0,,9.13485,0,,,,7.85398e-5
Test1,3-Compress,124.957,1.866,0.203,-0.000,,0.098115,0,,9.8115,0,,,,7.85398e-5
Test1,3-Compress,125.290,1.853,0.216,-0.000,,0.104398,0,,10.4398,0,,,,7.85398e-5
Test1,3-Compress,125.623,1.839,0.23,-0.000,,0.111165,0,,11.1165,0,,,,7.85398e-5
Test1,3-Compress,125.957,1.825,0.244,-0.000,,0.117931,0,,11.7931,0,,,,7.85398e-5
Test1,3-Compress,126.290,1.811,0.258,0.007,,0.124698,89.1268,,12.4698,0.0891268,,,,7.85398e-5
Test1,3-Compress,126.623,1.798,0.271,0.007,,0.130981,89.1268,,13.0981,0.0891268,,,,7.85398e-5
Test1,3-Compress,126.957,1.783,0.286,0.020,,0.138231,254.648,,13.8231,0.254648,,,,7.85398e-5
Test1,3-Compress,127.290,1.77,0.299,0.014,,0.144514,178.254,,14.4514,0.178254,,,,7.85398e-5
Test1,3-Compress,127.623,1.756,0.313,0.014,,0.151281,178.254,,15.1281,0.178254,,,,7.85398e-5
Test1,3-Compress,127.957,1.742,0.327,0.027,,0.158047,343.775,,15.8047,0.343775,,,,7.85398e-5
Test1,3-Compress,128.290,1.729,0.34,0.027,,0.164331,343.775,,16.4331,0.343775,,,,7.85398e-5
Test1,3-Compress,128.623,1.715,0.354,0.014,,0.171097,178.254,,17.1097,0.178254,,,,7.85398e-5
Test1,3-Compress,128.957,1.701,0.368,0.020,,0.177864,254.648,,17.7864,0.254648,,,,7.85398e-5
Test1,3-Compress,129.290,1.687,0.382,0.020,,0.18463,254.648,,18.463,0.254648,,,,7.85398e-5
Test1,3-Compress,129.623,1.673,0.396,0.020,,0.191397,254.648,,19.1397,0.254648,,,,7.85398e-5
Test1,3-Compress,129.957,1.659,0.41,0.020,,0.198163,254.648,,19.8163,0.254648,,,,7.85398e-5
Test1,3-Compress,130.290,1.645,0.424,0.027,,0.20493,343.775,,20.493,0.343775,,,,7.85398e-5
Test1,3-Compress,130.623,1.632,0.437,0.014,,0.211213,178.254,,21.1213,0.178254,,,,7.85398e-5
Test1,3-Compress,130.957,1.618,0.451,0.014,,0.21798,178.254,,21.798,0.178254,,,,7.85398e-5
Test1,3-Compress,131.290,1.604,0.465,0.014,,0.224746,178.254,,22.4746,0.178254,,,,7.85398e-5
Test1,3-Compress,131.623,1.591,0.478,0.027,,0.231029,343.775,,23.1029,0.343775,,,,7.85398e-5
Test1,3-Compress,131.957,1.576,0.493,0.027,,0.238279,343.775,,23.8279,0.343775,,,,7.85398e-5
Test1,3-Compress,132.290,1.563,0.506,0.014,,0.244563,178.254,,24.4563,0.178254,,,,7.85398e-5
Test1,3-Compress,132.623,1.549,0.52,0.014,,0.251329,178.254,,25.1329,0.178254,,,,7.85398e-5
Test1,3-Compress,132.957,1.535,0.534,0.027,,0.258096,343.775,,25.8096,0.343775,,,,7.85398e-5
Test1,3-Compress,133.290,1.521,0.548,0.041,,0.264862,522.028,,26.4862,0.522028,,,,7.85398e-5
Test1,3-Compress,133.623,1.507,0.562,0.041,,0.271629,522.028,,27.1629,0.522028,,,,7.85398e-5
Test1,3-Compress,133.957,1.494,0.575,0.041,,0.277912,522.028,,27.7912,0.522028,,,,7.85398e-5
Test1,3-Compress,134.290,1.48,0.589,0.027,,0.284679,343.775,,28.4679,0.343775,,,,7.85398e-5
Test1,3-Compress,134.623,1.466,0.603,0.034,,0.291445,432.902,,29.1445,0.432902,,,,7.85398e-5
Test1,3-Compress,134.957,1.452,0.617,0.041,,0.298212,522.028,,29.8212,0.522028,,,,7.85398e-5
Test1,3-Compress,135.290,1.438,0.631,0.048,,0.304978,611.155,,30.4978,0.611155,,,,7.85398e-5
Test1,3-Compress,135.623,1.425,0.644,0.054,,0.311261,687.549,,31.1261,0.687549,,,,7.85398e-5
Test1,3-Compress,135.957,1.411,0.658,0.054,,0.318028,687.549,,31.8028,0.687549,,,,7.85398e-5
Test1,3-Compress,136.290,1.397,0.672,0.054,,0.324795,687.549,,32.4795,0.687549,,,,7.85398e-5
Test1,3-Compress,136.623,1.383,0.686,0.054,,0.331561,687.549,,33.1561,0.687549,,,,7.85398e-5
Test1,3-Compress,136.957,1.37,0.699,0.054,,0.337844,687.549,,33.7844,0.687549,,,,7.85398e-5
Test1,3-Compress,137.290,1.356,0.713,0.054,,0.344611,687.549,,34.4611,0.687549,,,,7.85398e-5
Test1,3-Compress,137.623,1.342,0.727,0.054,,0.351377,687.549,,35.1377,0.687549,,,,7.85398e-5
Test1,3-Compress,137.957,1.328,0.741,0.054,,0.358144,687.549,,35.8144,0.687549,,,,7.85398e-5
Test1,3-Compress,138.290,1.314,0.755,0.054,,0.364911,687.549,,36.4911,0.687549,,,,7.85398e-5
Test1,3-Compress,138.623,1.301,0.768,0.054,,0.371194,687.549,,37.1194,0.687549,,,,7.85398e-5
Test1,3-Compress,138.957,1.286,0.783,0.054,,0.378444,687.549,,37.8444,0.687549,,,,7.85398e-5
Test1,3-Compress,139.290,1.272,0.797,0.054,,0.38521,687.549,,38.521,0.687549,,,,7.85398e-5
Test1,3-Compress,139.623,1.259,0.81,0.054,,0.391493,687.549,,39.1493,0.687549,,,,7.85398e-5
Test1,3-Compress,139.957,1.245,0.824,0.054,,0.39826,687.549,,39.826,0.687549,,,,7.85398e-5
Test1,3-Compress,140.290,1.232,0.837,0.054,,0.404543,687.549,,40.4543,0.687549,,,,7.85398e-5
Test1,3-Compress,140.623,1.218,0.851,0.054,,0.41131,687.549,,41.131,0.687549,,,,7.85398e-5
Test1,3-Compress,140.957,1.204,0.865,0.054,,0.418076,687.549,,41.8076,0.687549,,,,7.85398e-5
Test1,3-Compress,141.290,1.19,0.879,0.054,,0.424843,687.549,,42.4843,0.687549,,,,7.85398e-5
Test1,3-Compress,141.623,1.176,0.893,0.054,,0.431609,687.549,,43.1609,0.687549,,,,7.85398e-5
Test1,3-Compress,141.957,1.162,0.907,0.054,,0.438376,687.549,,43.8376,0.687549,,,,7.85398e-5
Test1,3-Compress,142.290,1.148,0.921,0.054,,0.445143,687.549,,44.5143,0.687549,,,,7.85398e-5
Test1,3-Compress,142.623,1.135,0.934,0.054,,0.451426,687.549,,45.1426,0.687549,,,,7.85398e-5
Test1,3-Compress,142.957,1.121,0.948,0.054,,0.458192,687.549,,45.8192,0.687549,,,,7.85398e-5
Test1,3-Compress,143.290,1.107,0.962,0.054,,0.464959,687.549,,46.4959,0.687549,,,,7.85398e-5
Test1,3-Compress,143.623,1.094,0.975,0.054,,0.471242,687.549,,47.1242,0.687549,,,,7.85398e-5
Test1,3-Compress,143.957,1.079,0.99,0.054,,0.478492,687.549,,47.8492,0.687549,,,,7.85398e-5
Test1,3-Compress,144.290,1.066,1.003,0.054,,0.484775,687.549,,48.4775,0.687549,,,,7.85398e-5
Test1,3-Compress,144.623,1.052,1.017,0.061,,0.491542,776.676,,49.1542,0.776676,,,,7.85398e-5
Test1,3-Compress,144.957,1.038,1.031,0.061,,0.498308,776.676,,49.8308,0.776676,,,,7.85398e-5
Test1,3-Compress,145.290,1.024,1.045,0.061,,0.505075,776.676,,50.5075,0.776676,,,,7.85398e-5
Test1,3-Compress,145.623,1.01,1.059,0.061,,0.511841,776.676,,51.1841,0.776676,,,,7.85398e-5
Test1,3-Compress,145.957,0.997,1.072,0.054,,0.518125,687.549,,51.8125,0.687549,,,,7.85398e-5
Test1,3-Compress,146.290,0.983,1.086,0.054,,0.524891,687.549,,52.4891,0.687549,,,,7.85398e-5
Test1,3-Compress,146.623,0.969,1.1,0.054,,0.531658,687.549,,53.1658,0.687549,,,,7.85398e-5
Test1,3-Compress,146.957,0.955,1.114,0.061,,0.538424,776.676,,53.8424,0.776676,,,,7.85398e-5
Test1,3-Compress,147.290,0.941,1.128,0.068,,0.545191,865.803,,54.5191,0.865803,,,,7.85398e-5
Test1,3-Compress,147.623,0.928,1.141,0.061,,0.551474,776.676,,55.1474,0.776676,,,,7.85398e-5
Test1,3-Compress,147.957,0.913,1.156,0.061,,0.558724,776.676,,55.8724,0.776676,,,,7.85398e-5
Test1,3-Compress,148.290,0.9,1.169,0.061,,0.565007,776.676,,56.5007,0.776676,,,,7.85398e-5
Test1,3-Compress,148.623,0.886,1.183,0.061,,0.571774,776.676,,57.1774,0.776676,,,,7.85398e-5
Test1,3-Compress,148.957,0.872,1.197,0.054,,0.57854,687.549,,57.854,0.687549,,,,7.85398e-5
Test1,3-Compress,149.290,0.859,1.21,0.061,,0.584824,776.676,,58.4824,0.776676,,,,7.85398e-5
Test1,3-Compress,149.623,0.845,1.224,0.054,,0.59159,687.549,,59.159,0.687549,,,,7.85398e-5
Test1,3-Compress,149.957,0.831,1.238,0.061,,0.598357,776.676,,59.8357,0.776676,,,,7.85398e-5
Test1,3-Recover,150.277,0.836,1.233,0.075,,0.59594,954.93,,59.594,0.95493,,,,7.85398e-5
Test1,3-Recover,150.610,0.849,1.22,0.061,,0.589657,776.676,,58.9657,0.776676,,,,7.85398e-5
Test1,3-Recover,150.943,0.863,1.206,0.068,,0.58289,865.803,,58.289,0.865803,,,,7.85398e-5
Test1,3-Recover,151.277,0.877,1.192,0.068,,0.576124,865.803,,57.6124,0.865803,,,,7.85398e-5
Test1,3-Recover,151.610,0.891,1.178,0.061,,0.569357,776.676,,56.9357,0.776676,,,,7.85398e-5
Test1,3-Recover,151.943,0.904,1.165,0.075,,0.563074,954.93,,56.3074,0.95493,,,,7.85398e-5
Test1,3-Recover,152.277,0.919,1.15,0.075,,0.555824,954.93,,55.5824,0.95493,,,,7.85398e-5
Test1,3-Recover,152.610,0.932,1.137,0.061,,0.549541,776.676,,54.9541,0.776676,,,,7.85398e-5
Test1,3-Recover,152.943,0.946,1.123,0.054,,0.542774,687.549,,54.2774,0.687549,,,,7.85398e-5
Test1,3-Recover,153.277,0.96,1.109,0.061,,0.536008,776.676,,53.6008,0.776676,,,,7.85398e-5
Test1,3-Recover,153.610,0.974,1.095,0.061,,0.529241,776.676,,52.9241,0.776676,,,,7.85398e-5
Test1,3-Recover,153.943,0.987,1.082,0.061,,0.522958,776.676,,52.2958,0.776676,,,,7.85398e-5
Test1,3-Recover,154.277,1.001,1.068,0.061,,0.516191,776.676,,51.6191,0.776676,,,,7.85398e-5
Test1,3-Recover,154.610,1.015,1.054,0.054,,0.509425,687.549,,50.9425,0.687549,,,,7.85398e-5
Test1,3-Recover,154.943,1.029,1.04,0.054,,0.502658,687.549,,50.2658,0.687549,,,,7.85398e-5
Test1,3-Recover,155.277,1.043,1.026,0.054,,0.495892,687.549,,49.5892,0.687549,,,,7.85398e-5
Test1,3-Recover,155.610,1.057,1.012,0.054,,0.489125,687.549,,48.9125,0.687549,,,,7.85398e-5
Test1,3-Recover,155.943,1.07,0.999,0.054,,0.482842,687.549,,48.2842,0.687549,,,,7.85398e-5
Test1,3-Recover,156.277,1.084,0.985,0.054,,0.476075,687.549,,47.6075,0.687549,,,,7.85398e-5
Test1,3-Recover,156.610,1.098,0.971,0.054,,0.469309,687.549,,46.9309,0.687549,,,,7.85398e-5
Test1,3-Recover,156.943,1.111,0.958,0.054,,0.463026,687.549,,46.3026,0.687549,,,,7.85398e-5
Test1,3-Recover,157.277,1.126,0.943,0.054,,0.455776,687.549,,45.5776,0.687549,,,,7.85398e-5
Test1,3-Recover,157.610,1.139,0.93,0.054,,0.449493,687.549,,44.9493,0.687549,,,,7.85398e-5
Test1,3-Recover,157.943,1.153,0.916,0.054,,0.442726,687.549,,44.2726,0.687549,,,,7.85398e-5
Test1,3-Recover,158.277,1.167,0.902,0.054,,0.435959,687.549,,43.5959,0.687549,,,,7.85398e-5
Test1,3-Recover,158.610,1.181,0.888,0.048,,0.429193,611.155,,42.9193,0.611155,,,,7.85398e-5
Test1,3-Recover,158.943,1.195,0.874,0.048,,0.422426,611.155,,42.2426,0.611155,,,,7.85398e-5
Test1,3-Recover,159.277,1.208,0.861,0.048,,0.416143,611.155,,41.6143,0.611155,,,,7.85398e-5
Test1,3-Recover,159.610,1.222,0.847,0.054,,0.409377,687.549,,40.9377,0.687549,,,,7.85398e-5
Test1,3-Recover,159.943,1.236,0.833,0.054,,0.40261,687.549,,40.261,0.687549,,,,7.85398e-5
Test1,3-Recover,160.277,1.25,0.819,0.054,,0.395843,687.549,,39.5843,0.687549,,,,7.85398e-5
Test1,3-Recover,160.610,1.264,0.805,0.054,,0.389077,687.549,,38.9077,0.687549,,,,7.85398e-5
Test1,3-Recover,160.943,1.277,0.792,0.048,,0.382794,611.155,,38.2794,0.611155,,,,7.85398e-5
Test1,3-Recover,161.277,1.291,0.778,0.048,,0.376027,611.155,,37.6027,0.611155,,,,7.85398e-5
Test1,3-Recover,161.610,1.305,0.764,0.054,,0.369261,687.549,,36.9261,0.687549,,,,7.85398e-5
Test1,3-Recover,161.943,1.319,0.75,0.034,,0.362494,432.902,,36.2494,0.432902,,,,7.85398e-5
Test1,3-Recover,162.277,1.333,0.736,0.027,,0.355727,343.775,,35.5727,0.343775,,,,7.85398e-5
Test1,3-Recover,162.610,1.346,0.723,0.054,,0.349444,687.549,,34.9444,0.687549,,,,7.85398e-5
Test1,3-Recover,162.943,1.36,0.709,0.034,,0.342678,432.902,,34.2678,0.432902,,,,7.85398e-5
Test1,3-Recover,163.277,1.374,0.695,0.020,,0.335911,254.648,,33.5911,0.254648,,,,7.85398e-5
Test1,3-Recover,163.610,1.388,0.681,0.027,,0.329145,343.775,,32.9145,0.343775,,,,7.85398e-5
Test1,3-Recover,163.943,1.402,0.667,0.020,,0.322378,254.648,,32.2378,0.254648,,,,7.85398e-5
Test1,3-Recover,164.277,1.416,0.653,0.020,,0.315611,254.648,,31.5611,0.254648,,,,7.85398e-5
Test1,3-Recover,164.610,1.43,0.639,0.034,,0.308845,432.902,,30.8845,0.432902,,,,7.85398e-5
Test1,3-Recover,164.943,1.443,0.626,0.007,,0.302562,89.1268,,30.2562,0.0891268,,,,7.85398e-5
Test1,3-Recover,165.277,1.457,0.612,-0.000,,0.295795,0,,29.5795,0,,,,7.85398e-5
Test1,3-Recover,165.610,1.47,0.599,-0.000,,0.289512,0,,28.9512,0,,,,7.85398e-5
Test1,3-Recover,165.943,1.484,0.585,-0.000,,0.282745,0,,28.2745,0,,,,7.85398e-5
Test1,3-Recover,166.277,1.499,0.57,0.007,,0.275495,89.1268,,27.5495,0.0891268,,,,7.85398e-5
Test1,3-Recover,166.610,1.512,0.557,0.014,,0.269212,178.254,,26.9212,0.178254,,,,7.85398e-5
Test1,3-Recover,166.943,1.526,0.543,0.007,,0.262446,89.1268,,26.2446,0.0891268,,,,7.85398e-5
Test1,3-Recover,167.277,1.54,0.529,0.027,,0.255679,343.775,,25.5679,0.343775,,,,7.85398e-5
Test1,3-Recover,167.610,1.554,0.515,0.020,,0.248913,254.648,,24.8913,0.254648,,,,7.85398e-5
Test1,3-Recover,167.943,1.568,0.501,0.027,,0.242146,343.775,,24.2146,0.343775,,,,7.85398e-5
Test1,3-Recover,168.277,1.581,0.488,0.007,,0.235863,89.1268,,23.5863,0.0891268,,,,7.85398e-5
Test1,3-Recover,168.610,1.595,0.474,0.007,,0.229096,89.1268,,22.9096,0.0891268,,,,7.85398e-5
Test1,3-Recover,168.943,1.609,0.46,0.014,,0.22233,178.254,,22.233,0.178254,,,,7.85398e-5
Test1,3-Recover,169.277,1.623,0.446,0.007,,0.215563,89.1268,,21.5563,0.0891268,,,,7.85398e-5
Test1,3-Recover,169.610,1.636,0.433,0.014,,0.20928,178.254,,20.928,0.178254,,,,7.85398e-5
Test1,3-Recover,169.943,1.65,0.419,-0.000,,0.202513,0,,20.2513,0,,,,7.85398e-5
Test1,3-Recover,170.277,1.664,0.405,0.007,,0.195747,89.1268,,19.5747,0.0891268,,,,7.85398e-5
Test1,3-Recover,170.610,1.678,0.391,0.007,,0.18898,89.1268,,18.898,0.0891268,,,,7.85398e-5
Test1,3-Recover,170.943,1.692,0.377,-0.000,,0.182214,0,,18.2214,0,,,,7.85398e-5
Test1,3-Recover,171.277,1.705,0.364,0.007,,0.17593,89.1268,,17.593,0.0891268,,,,7.85398e-5
Test1,3-Recover,171.610,1.719,0.35,0.007,,0.169164,89.1268,,16.9164,0.0891268,,,,7.85398e-5
Test1,3-Recover,171.943,1.733,0.336,-0.000,,0.162397,0,,16.2397,0,,,,7.85398e-5
Test1,3-Recover,172.277,1.747,0.322,-0.000,,0.155631,0,,15.5631,0,,,,7.85398e-5
Test1,3-Recover,172.610,1.761,0.308,-0.000,,0.148864,0,,14.8864,0,,,,7.85398e-5
Test1,3-Recover,172.943,1.774,0.295,-0.000,,0.142581,0,,14.2581,0,,,,7.85398e-5
Test1,3-Recover,173.277,1.789,0.28,-0.000,,0.135331,0,,13.5331,0,,,,7.85398e-5
Test1,3-Recover,173.610,1.802,0.267,-0.000,,0.129048,0,,12.9048,0,,,,7.85398e-5
Test1,3-Recover,173.943,1.816,0.253,-0.000,,0.122281,0,,12.2281,0,,,,7.85398e-5
Test1,3-Recover,174.277,1.83,0.239,-0.000,,0.115515,0,,11.5515,0,,,,7.85398e-5
Test1,3-Recover,174.610,1.843,0.226,-0.000,,0.109232,0,,10.9232,0,,,,7.85398e-5
Test1,3-Recover,174.943,1.857,0.212,0.007,,0.102465,89.1268,,10.2465,0.0891268,,,,7.85398e-5
Test1,3-Recover,175.277,1.871,0.198,0.007,,0.0956984,89.1268,,9.56984,0.0891268,,,,7.85398e-5
Test1,3-Recover,175.610,1.885,0.184,-0.000,,0.0889319,0,,8.89319,0,,,,7.85398e-5
Test1,3-Recover,175.943,1.899,0.17,-0.000,,0.0821653,0,,8.21653,0,,,,7.85398e-5
Test1,3-Recover,176.277,1.913,0.156,-0.000,,0.0753987,0,,7.53987,0,,,,7.85398e-5
Test1,3-Recover,176.610,1.927,0.142,-0.000,,0.0686322,0,,6.86322,0,,,,7.85398e-5
Test1,3-Recover,176.943,1.94,0.129,-0.000,,0.062349,0,,6.2349,0,,,,7.85398e-5
Test1,3-Recover,177.277,1.954,0.115,-0.000,,0.0555824,0,,5.55824,0,,,,7.85398e-5
Test1,3-Recover,177.610,1.968,0.101,-0.000,,0.0488159,0,,4.88159,0,,,,7.85398e-5
Test1,3-Recover,177.943,1.981,0.088,-0.000,,0.0425326,0,,4.25326,0,,,,7.85398e-5
Test1,3-Recover,178.277,1.996,0.073,-0.000,,0.0352827,0,,3.52827,0,,,,7.85398e-5
Test1,3-Recover,178.610,2.009,0.06,-0.000,,0.0289995,0,,2.89995,0,,,,7.85398e-5
Test1,3-Recover,178.943,2.023,0.046,-0.000,,0.022233,0,,2.2233,0,,,,7.85398e-5
Test1,3-Recover,179.277,2.037,0.032,-0.000,,0.0154664,0,,1.54664,0,,,,7.85398e-5
Test1,3-Recover,179.610,2.051,0.018,-0.000,,0.00869986,0,,0.869986,0,,,,7.85398e-5
Test1,3-Recover,179.943,2.064,0.005,-0.000,,0.00241663,0,,0.241663,0,,,,7.85398e-5
Test1,3-Recover,180.110,2.069,-0,-0.000,,0,0,,0,0,,,,7.85398e-5