File: data/gamma_1-1-1_2.csv
SetName,Cycle,Time_S,Size_mm,Displacement_mm,Force_N,,Strain,Stress(Pascal),,%Strain,Stress(kPa),,,,Area(m^2)
Test1,1-Compress,0.000,2.556,-0,-0.005,,0,-63.662,,0,-0.063662,,,,7.85398e-5
Test1,1-Compress,0.333,2.539,0.017,-0.005,,0.00665102,-63.662,,0.665102,-0.063662,,,,7.85398e-5
Test1,1-Compress,0.667,2.522,0.034,-0.005,,0.013302,-63.662,,1.3302,-0.063662,,,,7.85398e-5
Test1,1-Compress,1.000,2.505,0.051,-0.005,,0.0199531,-63.662,,1.99531,-0.063662,,,,7.85398e-5
Test1,1-Compress,1.333,2.488,0.068,-0.005,,0.0266041,-63.662,,2.66041,-0.063662,,,,7.85398e-5
Test1,1-Compress,1.667,2.471,0.085,-0.005,,0.0332551,-63.662,,3.32551,-0.063662,,,,7.85398e-5
Test1,1-Compress,2.000,2.454,0.102,-0.005,,0.0399061,-63.662,,3.99061,-0.063662,,,,7.85398e-5
Test1,1-Compress,2.333,2.437,0.119,-0.005,,0.0465571,-63.662,,4.65571,-0.063662,,,,7.85398e-5
Test1,1-Compress,2.667,2.419,0.137,-0.005,,0.0535994,-63.662,,5.35994,-0.063662,,,,7.85398e-5
Test1,1-Compress,3.000,2.403,0.153,0.002,,0.0598592,25.4648,,5.98592,0.0254648,,,,7.85398e-5
Test1,1-Compress,3.333,2.386,0.17,0.002,,0.0665102,25.4648,,6.65102,0.0254648,,,,7.85398e-5
Test1,1-Compress,3.667,2.368,0.188,0.002,,0.0735524,25.4648,,7.35524,0.0254648,,,,7.85398e-5
Test1,1-Compress,4.000,2.351,0.205,0.002,,0.0802034,25.4648,,8.02034,0.0254648,,,,7.85398e-5
Test1,1-Compress,4.333,2.334,0.222,0.002,,0.0868545,25.4648,,8.68545,0.0254648,,,,7.85398e-5
Test1,1-Compress,4.667,2.317,0.239,0.009,,0.0935055,114.592,,9.35055,0.114592,,,,7.85398e-5
Test1,1-Compress,5.000,2.3,0.256,0.009,,0.100156,114.592,,10.0156,0.114592,,,,7.85398e-5
Test1,1-Compress,5.333,2.283,0.273,0.009,,0.106808,114.592,,10.6808,0.114592,,,,7.85398e-5
Test1,1-Compress,5.667,2.266,0.29,0.016,,0.113459,203.718,,11.3459,0.203718,,,,7.85398e-5
Test1,1-Compress,6.000,2.249,0.307,0.009,,0.12011,114.592,,12.011,0.114592,,,,7.85398e-5
Test1,1-Compress,6.333,2.232,0.324,0.016,,0.126761,203.718,,12.6761,0.203718,,,,7.85398e-5
Test1,1-Compress,6.667,2.215,0.341,0.002,,0.133412,25.4648,,13.3412,0.0254648,,,,7.85398e-5
Test1,1-Compress,7.000,2.197,0.359,0.029,,0.140454,369.24,,14.0454,0.36924,,,,7.85398e-5
Test1,1-Compress,7.333,2.181,0.375,0.016,,0.146714,203.718,,14.6714,0.203718,,,,7.85398e-5
Test1,1-Compress,7.667,2.163,0.393,0.016,,0.153756,203.718,,15.3756,0.203718,,,,7.85398e-5
Test1,1-Compress,8.000,2.147,0.409,0.009,,0.160016,114.592,,16.0016,0.114592,,,,7.85398e-5
Test1,1-Compress,8.333,2.129,0.427,0.009,,0.167058,114.592,,16.7058,0.114592,,,,7.85398e-5
Test1,1-Compress,8.667,2.112,0.444,0.016,,0.173709,203.718,,17.3709,0.203718,,,,7.85398e-5
Test1,1-Compress,9.000,2.095,0.461,0.009,,0.18036,114.592,,18.036,0.114592,,,,7.85398e-5
Test1,1-Compress,9.333,2.078,0.478,0.009,,0.187011,114.592,,18.7011,0.114592,,,,7.85398e-5
Test1,1-Compress,9.667,2.061,0.495,0.002,,0.193662,25.4648,,19.3662,0.0254648,,,,7.85398e-5
Test1,1-Compress,10.000,2.044,0.512,0.009,,0.200313,114.592,,20.0313,0.114592,,,,7.85398e-5
Test1,1-Compress,10.333,2.027,0.529,0.002,,0.206964,25.4648,,20.6964,0.0254648,,,,7.85398e-5
Test1,1-Compress,10.667,2.01,0.546,0.002,,0.213615,25.4648,,21.3615,0.0254648,,,,7.85398e-5
Test1,1-Compress,11.000,1.993,0.563,0.009,,0.220266,114.592,,22.0266,0.114592,,,,7.85398e-5
Test1,1-Compress,11.333,1.976,0.58,0.036,,0.226917,458.366,,22.6917,0.458366,,,,7.85398e-5
Test1,1-Compress,11.667,1.959,0.597,0.016,,0.233568,203.718,,23.3568,0.203718,,,,7.85398e-5
Test1,1-Compress,12.000,1.941,0.615,0.009,,0.24061,114.592,,24.061,0.114592,,,,7.85398e-5
Test1,1-Compress,12.333,1.925,0.631,0.043,,0.24687,547.493,,24.687,0.547493,,,,7.85398e-5
Test1,1-Compress,12.667,1.907,0.649,0.016,,0.253912,203.718,,25.3912,0.203718,,,,7.85398e-5
Test1,1-Compress,13.000,1.891,0.665,0.036,,0.260172,458.366,,26.0172,0.458366,,,,7.85398e-5
Test1,1-Compress,13.333,1.873,0.683,0.022,,0.267214,280.113,,26.7214,0.280113,,,,7.85398e-5
Test1,1-Compress,13.667,1.856,0.7,0.029,,0.273865,369.24,,27.3865,0.36924,,,,7.85398e-5
Test1,1-Compress,14.000,1.839,0.717,0.043,,0.280516,547.493,,28.0516,0.547493,,,,7.85398e-5
Test1,1-Compress,14.333,1.823,0.733,0.043,,0.286776,547.493,,28.6776,0.547493,,,,7.85398e-5
Test1,1-Compress,14.667,1.805,0.751,0.050,,0.293818,636.62,,29.3818,0.63662,,,,7.85398e-5
Test1,1-Compress,15.000,1.788,0.768,0.043,,0.300469,547.493,,30.0469,0.547493,,,,7.85398e-5
Test1,1-Compress,15.333,1.771,0.785,0.043,,0.307121,547.493,,30.7121,0.547493,,,,7.85398e-5
Test1,1-Compress,15.667,1.754,0.802,0.050,,0.313772,636.62,,31.3772,0.63662,,,,7.85398e-5
Test1,1-Compress,16.000,1.737,0.819,0.050,,0.320423,636.62,,32.0423,0.63662,,,,7.85398e-5
Test1,1-Compress,16.333,1.72,0.836,0.050,,0.327074,636.62,,32.7074,0.63662,,,,7.85398e-5
Test1,1-Compress,16.667,1.702,0.854,0.050,,0.334116,636.62,,33.4116,0.63662,,,,7.85398e-5
Test1,1-Compress,17.000,1.685,0.871,0.050,,0.340767,636.62,,34.0767,0.63662,,,,7.85398e-5
Test1,1-Compress,17.333,1.669,0.887,0.050,,0.347027,636.62,,34.7027,0.63662,,,,7.85398e-5
Test1,1-Compress,17.667,1.651,0.905,0.050,,0.354069,636.62,,35.4069,0.63662,,,,7.85398e-5
Test1,1-Compress,18.000,1.634,0.922,0.050,,0.36072,636.62,,36.072,0.63662,,,,7.85398e-5
Test1,1-Compress,18.333,1.617,0.939,0.050,,0.367371,636.62,,36.7371,0.63662,,,,7.85398e-5
Test1,1-Compress,18.667,1.6,0.956,0.050,,0.374022,636.62,,37.4022,0.63662,,,,7.85398e-5
Test1,1-Compress,19.000,1.583,0.973,0.050,,0.380673,636.62,,38.0673,0.63662,,,,7.85398e-5
Test1,1-Compress,19.333,1.567,0.989,0.050,,0.386933,636.62,,38.6933,0.63662,,,,7.85398e-5
Test1,1-Compress,19.667,1.549,1.007,0.050,,0.393975,636.62,,39.3975,0.63662,,,,7.85398e-5
Test1,1-Compress,20.000,1.532,1.024,0.050,,0.400626,636.62,,40.0626,0.63662,,,,7.85398e-5
Test1,1-Compress,20.333,1.515,1.041,0.050,,0.407277,636.62,,40.7277,0.63662,,,,7.85398e-5
Test1,1-Compress,20.667,1.498,1.058,0.050,,0.413928,636.62,,41.3928,0.63662,,,,7.85398e-5
Test1,1-Compress,21.000,1.481,1.075,0.050,,0.420579,636.62,,42.0579,0.63662,,,,7.85398e-5
Test1,1-Compress,21.333,1.464,1.092,0.050,,0.42723,636.62,,42.723,0.63662,,,,7.85398e-5
Test1,1-Compress,21.667,1.446,1.11,0.050,,0.434272,636.62,,43.4272,0.63662,,,,7.85398e-5
Test1,1-Compress,22.000,1.429,1.127,0.050,,0.440923,636.62,,44.0923,0.63662,,,,7.85398e-5
Test1,1-Compress,22.333,1.413,1.143,0.050,,0.447183,636.62,,44.7183,0.63662,,,,7.85398e-5
Test1,1-Compress,22.667,1.395,1.161,0.050,,0.454225,636.62,,45.4225,0.63662,,,,7.85398e-5
Test1,1-Compress,23.000,1.378,1.178,0.050,,0.460876,636.62,,46.0876,0.63662,,,,7.85398e-5
Test1,1-Compress,23.333,1.361,1.195,0.050,,0.467527,636.62,,46.7527,0.63662,,,,7.85398e-5
Test1,1-Compress,23.667,1.344,1.212,0.050,,0.474178,636.62,,47.4178,0.63662,,,,7.85398e-5
Test1,1-Compress,24.000,1.327,1.229,0.050,,0.480829,636.62,,48.0829,0.63662,,,,7.85398e-5
Test1,1-Compress,24.333,1.31,1.246,0.050,,0.48748,636.62,,48.748,0.63662,,,,7.85398e-5
Test1,1-Compress,24.667,1.293,1.263,0.050,,0.494131,636.62,,49.4131,0.63662,,,,7.85398e-5
Test1,1-Compress,25.000,1.276,1.28,0.050,,0.500782,636.62,,50.0782,0.63662,,,,7.85398e-5
Test1,1-Compress,25.333,1.259,1.297,0.050,,0.507433,636.62,,50.7433,0.63662,,,,7.85398e-5
Test1,1-Compress,25.667,1.242,1.314,0.050,,0.514085,636.62,,51.4085,0.63662,,,,7.85398e-5
Test1,1-Compress,26.000,1.225,1.331,0.050,,0.520736,636.62,,52.0736,0.63662,,,,7.85398e-5
Test1,1-Compress,26.333,1.207,1.349,0.050,,0.527778,636.62,,52.7778,0.63662,,,,7.85398e-5
Test1,1-Compress,26.667,1.19,1.366,0.050,,0.534429,636.62,,53.4429,0.63662,,,,7.85398e-5
Test1,1-Compress,27.000,1.173,1.383,0.050,,0.54108,636.62,,54.108,0.63662,,,,7.85398e-5
Test1,1-Compress,27.333,1.157,1.399,0.050,,0.54734,636.62,,54.734,0.63662,,,,7.85398e-5
Test1,1-Compress,27.667,1.139,1.417,0.050,,0.554382,636.62,,55.4382,0.63662,,,,7.85398e-5
Test1,1-Compress,28.000,1.122,1.434,0.050,,0.561033,636.62,,56.1033,0.63662,,,,7.85398e-5
Test1,1-Compress,28.333,1.105,1.451,0.056,,0.567684,713.014,,56.7684,0.713014,,,,7.85398e-5
Test1,1-Compress,28.667,1.088,1.468,0.056,,0.574335,713.014,,57.4335,0.713014,,,,7.85398e-5
Test1,1-Compress,29.000,1.071,1.485,0.056,,0.580986,713.014,,58.0986,0.713014,,,,7.85398e-5
Test1,1-Compress,29.333,1.054,1.502,0.056,,0.587637,713.014,,58.7637,0.713014,,,,7.85398e-5
Test1,1-Compress,29.667,1.037,1.519,0.056,,0.594288,713.014,,59.4288,0.713014,,,,7.85398e-5
Test1,1-Compress,30.000,1.022,1.534,0.056,,0.600156,713.014,,60.0156,0.713014,,,,7.85398e-5
Test1,1-Recover,30.333,1.038,1.518,0.056,,0.593897,713.014,,59.3897,0.713014,,,,7.85398e-5
Test1,1-Recover,30.667,1.055,1.501,0.050,,0.587246,636.62,,58.7246,0.63662,,,,7.85398e-5
Test1,1-Recover,31.000,1.072,1.484,0.050,,0.580595,636.62,,58.0595,0.63662,,,,7.85398e-5
Test1,1-Recover,31.333,1.089,1.467,0.050,,0.573944,636.62,,57.3944,0.63662,,,,7.85398e-5
Test1,1-Recover,31.667,1.106,1.45,0.050,,0.567293,636.62,,56.7293,0.63662,,,,7.85398e-5
Test1,1-Recover,32.000,1.123,1.433,0.050,,0.560642,636.62,,56.0642,0.63662,,,,7.85398e-5
Test1,1-Recover,32.333,1.14,1.416,0.050,,0.553991,636.62,,55.3991,0.63662,,,,7.85398e-5
Test1,1-Recover,32.667,1.158,1.398,0.050,,0.546948,636.62,,54.6948,0.63662,,,,7.85398e-5
Test1,1-Recover,33.000,1.175,1.381,0.050,,0.540297,636.62,,54.0297,0.63662,,,,7.85398e-5
Test1,1-Recover,33.333,1.191,1.365,0.050,,0.534038,636.62,,53.4038,0.63662,,,,7.85398e-5
Test1,1-Recover,33.667,1.209,1.347,0.050,,0.526995,636.62,,52.6995,0.63662,,,,7.85398e-5
Test1,1-Recover,34.000,1.226,1.33,0.050,,0.520344,636.62,,52.0344,0.63662,,,,7.85398e-5
Test1,1-Recover,34.333,1.243,1.313,0.050,,0.513693,636.62,,51.3693,0.63662,,,,7.85398e-5
Test1,1-Recover,34.667,1.26,1.296,0.050,,0.507042,636.62,,50.7042,0.63662,,,,7.85398e-5
Test1,1-Recover,35.000,1.277,1.279,0.050,,0.500391,636.62,,50.0391,0.63662,,,,7.85398e-5
Test1,1-Recover,35.333,1.294,1.262,0.050,,0.49374,636.62,,49.374,0.63662,,,,7.85398e-5
Test1,1-Recover,35.667,1.311,1.245,0.050,,0.487089,636.62,,48.7089,0.63662,,,,7.85398e-5
Test1,1-Recover,36.000,1.328,1.228,0.050,,0.480438,636.62,,48.0438,0.63662,,,,7.85398e-5
Test1,1-Recover,36.333,1.345,1.211,0.043,,0.473787,547.493,,47.3787,0.547493,,,,7.85398e-5
Test1,1-Recover,36.667,1.362,1.194,0.043,,0.467136,547.493,,46.7136,0.547493,,,,7.85398e-5
Test1,1-Recover,37.000,1.379,1.177,0.036,,0.460485,458.366,,46.0485,0.458366,,,,7.85398e-5
Test1,1-Recover,37.333,1.397,1.159,0.050,,0.453443,636.62,,45.3443,0.63662,,,,7.85398e-5
Test1,1-Recover,37.667,1.414,1.142,0.050,,0.446792,636.62,,44.6792,0.63662,,,,7.85398e-5
Test1,1-Recover,38.000,1.431,1.125,0.050,,0.440141,636.62,,44.0141,0.63662,,,,7.85398e-5
Test1,1-Recover,38.333,1.447,1.109,0.050,,0.433881,636.62,,43.3881,0.63662,,,,7.85398e-5
Test1,1-Recover,38.667,1.465,1.091,0.043,,0.426839,547.493,,42.6839,0.547493,,,,7.85398e-5
Test1,1-Recover,39.000,1.482,1.074,0.043,,0.420188,547.493,,42.0188,0.547493,,,,7.85398e-5
Test1,1-Recover,39.333,1.499,1.057,0.043,,0.413537,547.493,,41.3537,0.547493,,,,7.85398e-5
Test1,1-Recover,39.667,1.516,1.04,0.043,,0.406886,547.493,,40.6886,0.547493,,,,7.85398e-5
Test1,1-Recover,40.000,1.533,1.023,0.043,,0.400235,547.493,,40.0235,0.547493,,,,7.85398e-5
Test1,1-Recover,40.333,1.55,1.006,0.029,,0.393584,369.24,,39.3584,0.36924,,,,7.85398e-5
Test1,1-Recover,40.667,1.568,0.988,0.029,,0.386541,369.24,,38.6541,0.36924,,,,7.85398e-5
Test1,1-Recover,41.000,1.584,0.972,0.029,,0.380282,369.24,,38.0282,0.36924,,,,7.85398e-5
Test1,1-Recover,41.333,1.601,0.955,0.036,,0.373631,458.366,,37.3631,0.458366,,,,7.85398e-5
Test1,1-Recover,41.667,1.618,0.938,0.016,,0.36698,203.718,,36.698,0.203718,,,,7.85398e-5
Test1,1-Recover,42.000,1.635,0.921,0.002,,0.360329,25.4648,,36.0329,0.0254648,,,,7.85398e-5
Test1,1-Recover,42.333,1.653,0.903,0.016,,0.353286,203.718,,35.3286,0.203718,,,,7.85398e-5
Test1,1-Recover,42.667,1.67,0.886,0.009,,0.346635,114.592,,34.6635,0.114592,,,,7.85398e-5
Test1,1-Recover,43.000,1.687,0.869,0.016,,0.339984,203.718,,33.9984,0.203718,,,,7.85398e-5
Test1,1-Recover,43.333,1.703,0.853,0.002,,0.333725,25.4648,,33.3725,0.0254648,,,,7.85398e-5
Test1,1-Recover,43.667,1.721,0.835,0.002,,0.326682,25.4648,,32.6682,0.0254648,,,,7.85398e-5
Test1,1-Recover,44.000,1.738,0.818,0.009,,0.320031,114.592,,32.0031,0.114592,,,,7.85398e-5
Test1,1-Recover,44.333,1.755,0.801,0.009,,0.31338,114.592,,31.338,0.114592,,,,7.85398e-5
Test1,1-Recover,44.667,1.772,0.784,0.016,,0.306729,203.718,,30.6729,0.203718,,,,7.85398e-5
Test1,1-Recover,45.000,1.789,0.767,0.016,,0.300078,203.718,,30.0078,0.203718,,,,7.85398e-5
Test1,1-Recover,45.333,1.806,0.75,0.016,,0.293427,203.718,,29.3427,0.203718,,,,7.85398e-5
Test1,1-Recover,45.667,1.824,0.732,0.016,,0.286385,203.718,,28.6385,0.203718,,,,7.85398e-5
Test1,1-Recover,46.000,1.84,0.716,0.022,,0.280125,280.113,,28.0125,0.280113,,,,7.85398e-5
Test1,1-Recover,46.333,1.857,0.699,0.016,,0.273474,203.718,,27.3474,0.203718,,,,7.85398e-5
Test1,1-Recover,46.667,1.874,0.682,0.009,,0.266823,114.592,,26.6823,0.114592,,,,7.85398e-5
Test1,1-Recover,47.000,1.892,0.664,0.022,,0.259781,280.113,,25.9781,0.280113,,,,7.85398e-5
Test1,1-Recover,47.333,1.908,0.648,0.002,,0.253521,25.4648,,25.3521,0.0254648,,,,7.85398e-5
Test1,1-Recover,47.667,1.926,0.63,0.016,,0.246479,203.718,,24.6479,0.203718,,,,7.85398e-5
Test1,1-Recover,48.000,1.943,0.613,0.002,,0.239828,25.4648,,23.9828,0.0254648,,,,7.85398e-5
Test1,1-Recover,48.333,1.96,0.596,0.009,,0.233177,114.592,,23.3177,0.114592,,,,7.85398e-5
Test1,1-Recover,48.667,1.977,0.579,0.002,,0.226526,25.4648,,22.6526,0.0254648,,,,7.85398e-5
Test1,1-Recover,49.000,1.994,0.562,0.002,,0.219875,25.4648,,21.9875,0.0254648,,,,7.85398e-5
Test1,1-Recover,49.333,2.011,0.545,0.002,,0.213224,25.4648,,21.3224,0.0254648,,,,7.85398e-5
Test1,1-Recover,49.667,2.028,0.528,0.002,,0.206573,25.4648,,20.6573,0.0254648,,,,7.85398e-5
Test1,1-Recover,50.000,2.045,0.511,0.002,,0.199922,25.4648,,19.9922,0.0254648,,,,7.85398e-5
Test1,1-Recover,50.333,2.062,0.494,-0.005,,0.193271,-63.662,,19.3271,-0.063662,,,,7.85398e-5
Test1,1-Recover,50.667,2.08,0.476,-0.005,,0.186228,-63.662,,18.6228,-0.063662,,,,7.85398e-5
Test1,1-Recover,51.000,2.096,0.46,0.002,,0.179969,25.4648,,17.9969,0.0254648,,,,7.85398e-5
Test1,1-Recover,51.333,2.113,0.443,0.002,,0.173318,25.4648,,17.3318,0.0254648,,,,7.85398e-5
Test1,1-Recover,51.667,2.13,0.426,0.002,,0.166667,25.4648,,16.6667,0.0254648,,,,7.85398e-5
Test1,1-Recover,52.000,2.148,0.408,0.002,,0.159624,25.4648,,15.9624,0.0254648,,,,7.85398e-5
Test1,1-Recover,52.333,2.164,0.392,0.002,,0.153365,25.4648,,15.3365,0.0254648,,,,7.85398e-5
Test1,1-Recover,52.667,2.182,0.374,0.009,,0.146322,114.592,,14.6322,0.114592,,,,7.85398e-5
Test1,1-Recover,53.000,2.199,0.357,0.009,,0.139671,114.592,,13.9671,0.114592,,,,7.85398e-5
Test1,1-Recover,53.333,2.216,0.34,0.009,,0.13302,114.592,,13.302,0.114592,,,,7.85398e-5
Test1,1-Recover,53.667,2.233,0.323,0.009,,0.126369,114.592,,12.6369,0.114592,,,,7.85398e-5
Test1,1-Recover,54.000,2.25,0.306,0.016,,0.119718,203.718,,11.9718,0.203718,,,,7.85398e-5
Test1,1-Recover,54.333,2.267,0.289,0.009,,0.113067,114.592,,11.3067,0.114592,,,,7.85398e-5
Test1,1-Recover,54.667,2.284,0.272,0.002,,0.106416,25.4648,,10.6416,0.0254648,,,,7.85398e-5
Test1,1-Recover,55.000,2.301,0.255,-0.005,,0.0997653,-63.662,,9.97653,-0.063662,,,,7.85398e-5
Test1,1-Recover,55.333,2.318,0.238,0.002,,0.0931142,25.4648,,9.31142,0.0254648,,,,7.85398e-5
Test1,1-Recover,55.667,2.336,0.22,0.002,,0.086072,25.4648,,8.6072,0.0254648,,,,7.85398e-5
Test1,1-Recover,56.000,2.352,0.204,-0.005,,0.0798122,-63.662,,7.98122,-0.063662,,,,7.85398e-5
Test1,1-Recover,56.333,2.369,0.187,-0.005,,0.0731612,-63.662,,7.31612,-0.063662,,,,7.85398e-5
Test1,1-Recover,56.667,2.387,0.169,0.002,,0.0661189,25.4648,,6.61189,0.0254648,,,,7.85398e-5
Test1,1-Recover,57.000,2.404,0.152,-0.005,,0.0594679,-63.662,,5.94679,-0.063662,,,,7.85398e-5
Test1,1-Recover,57.333,2.421,0.135,-0.005,,0.0528169,-63.662,,5.28169,-0.063662,,,,7.85398e-5
Test1,1-Recover,57.667,2.438,0.118,-0.005,,0.0461659,-63.662,,4.61659,-0.063662,,,,7.85398e-5
Test1,1-Recover,58.000,2.455,0.101,-0.005,,0.0395149,-63.662,,3.95149,-0.063662,,,,7.85398e-5
Test1,1-Recover,58.333,2.472,0.084,-0.005,,0.0328638,-63.662,,3.28638,-0.063662,,,,7.85398e-5
Test1,1-Recover,58.667,2.489,0.067,-0.005,,0.0262128,-63.662,,2.62128,-0.063662,,,,7.85398e-5
Test1,1-Recover,59.000,2.506,0.05,0.002,,0.0195618,25.4648,,1.95618,0.0254648,,,,7.85398e-5
Test1,1-Recover,59.333,2.523,0.033,0.002,,0.0129108,25.4648,,1.29108,0.0254648,,,,7.85398e-5
Test1,1-Recover,59.667,2.54,0.016,0.002,,0.00625978,25.4648,,0.625978,0.0254648,,,,7.85398e-5
Test1,1-Recover,60.000,2.556,-0,0.002,,0,25.4648,,0,0.0254648,,,,7.85398e-5
Test1,2-Compress,60.317,2.542,0.014,0.002,,0.00547731,25.4648,,0.547731,0.0254648,,,,7.85398e-5
Test1,2-Compress,60.650,2.525,0.031,0.002,,0.0121283,25.4648,,1.21283,0.0254648,,,,7.85398e-5
Test1,2-Compress,60.983,2.508,0.048,0.002,,0.0187793,25.4648,,1.87793,0.0254648,,,,7.85398e-5
Test1,2-Compress,61.317,2.49,0.066,0.016,,0.0258216,203.718,,2.58216,0.203718,,,,7.85398e-5
Test1,2-Compress,61.650,2.474,0.082,0.002,,0.0320814,25.4648,,3.20814,0.0254648,,,,7.85398e-5
Test1,2-Compress,61.983,2.457,0.099,0.009,,0.0387324,114.592,,3.87324,0.114592,,,,7.85398e-5
Test1,2-Compress,62.317,2.439,0.117,0.009,,0.0457746,114.592,,4.57746,0.114592,,,,7.85398e-5
Test1,2-Compress,62.650,2.422,0.134,0.009,,0.0524257,114.592,,5.24257,0.114592,,,,7.85398e-5
Test1,2-Compress,62.983,2.406,0.15,0.002,,0.0586854,25.4648,,5.86854,0.0254648,,,,7.85398e-5
Test1,2-Compress,63.317,2.388,0.168,-0.005,,0.0657277,-63.662,,6.57277,-0.063662,,,,7.85398e-5
Test1,2-Compress,63.650,2.371,0.185,-0.005,,0.0723787,-63.662,,7.23787,-0.063662,,,,7.85398e-5
Test1,2-Compress,63.983,2.354,0.202,-0.005,,0.0790297,-63.662,,7.90297,-0.063662,,,,7.85398e-5
Test1,2-Compress,64.317,2.337,0.219,0.002,,0.0856808,25.4648,,8.56808,0.0254648,,,,7.85398e-5
Test1,2-Compress,64.650,2.32,0.236,-0.005,,0.0923318,-63.662,,9.23318,-0.063662,,,,7.85398e-5
Test1,2-Compress,64.983,2.303,0.253,-0.005,,0.0989828,-63.662,,9.89828,-0.063662,,,,7.85398e-5
Test1,2-Compress,65.317,2.286,0.27,0.002,,0.105634,25.4648,,10.5634,0.0254648,,,,7.85398e-5
Test1,2-Compress,65.650,2.268,0.288,0.002,,0.112676,25.4648,,11.2676,0.0254648,,,,7.85398e-5
Test1,2-Compress,65.983,2.252,0.304,0.002,,0.118936,25.4648,,11.8936,0.0254648,,,,7.85398e-5
Test1,2-Compress,66.317,2.234,0.322,-0.005,,0.125978,-63.662,,12.5978,-0.063662,,,,7.85398e-5
Test1,2-Compress,66.650,2.218,0.338,0.002,,0.132238,25.4648,,13.2238,0.0254648,,,,7.85398e-5
Test1,2-Compress,66.983,2.2,0.356,0.002,,0.13928,25.4648,,13.928,0.0254648,,,,7.85398e-5
Test1,2-Compress,67.317,2.183,0.373,0.002,,0.145931,25.4648,,14.5931,0.0254648,,,,7.85398e-5
Test1,2-Compress,67.650,2.166,0.39,0.002,,0.152582,25.4648,,15.2582,0.0254648,,,,7.85398e-5
Test1,2-Compress,67.983,2.15,0.406,0.002,,0.158842,25.4648,,15.8842,0.0254648,,,,7.85398e-5
Test1,2-Compress,68.317,2.132,0.424,0.002,,0.165884,25.4648,,16.5884,0.0254648,,,,7.85398e-5
Test1,2-Compress,68.650,2.115,0.441,0.002,,0.172535,25.4648,,17.2535,0.0254648,,,,7.85398e-5
Test1,2-Compress,68.983,2.098,0.458,0.009,,0.179186,114.592,,17.9186,0.114592,,,,7.85398e-5
Test1,2-Compress,69.317,2.081,0.475,0.009,,0.185837,114.592,,18.5837,0.114592,,,,7.85398e-5
Test1,2-Compress,69.650,2.064,0.492,0.016,,0.192488,203.718,,19.2488,0.203718,,,,7.85398e-5
Test1,2-Compress,69.983,2.047,0.509,0.016,,0.199139,203.718,,19.9139,0.203718,,,,7.85398e-5
Test1,2-Compress,70.317,2.03,0.526,0.002,,0.20579,25.4648,,20.579,0.0254648,,,,7.85398e-5
Test1,2-Compress,70.650,2.012,0.544,0.016,,0.212833,203.718,,21.2833,0.203718,,,,7.85398e-5
Test1,2-Compress,70.983,1.996,0.56,0.029,,0.219092,369.24,,21.9092,0.36924,,,,7.85398e-5
Test1,2-Compress,71.317,1.978,0.578,0.029,,0.226135,369.24,,22.6135,0.36924,,,,7.85398e-5
Test1,2-Compress,71.650,1.962,0.594,0.022,,0.232394,280.113,,23.2394,0.280113,,,,7.85398e-5
Test1,2-Compress,71.983,1.944,0.612,0.022,,0.239437,280.113,,23.9437,0.280113,,,,7.85398e-5
Test1,2-Compress,72.317,1.927,0.629,0.016,,0.246088,203.718,,24.6088,0.203718,,,,7.85398e-5
Test1,2-Compress,72.650,1.91,0.646,0.022,,0.252739,280.113,,25.2739,0.280113,,,,7.85398e-5
Test1,2-Compress,72.983,1.894,0.662,0.036,,0.258998,458.366,,25.8998,0.458366,,,,7.85398e-5
Test1,2-Compress,73.317,1.876,0.68,0.022,,0.266041,280.113,,26.6041,0.280113,,,,7.85398e-5
Test1,2-Compress,73.650,1.859,0.697,0.036,,0.272692,458.366,,27.2692,0.458366,,,,7.85398e-5
Test1,2-Compress,73.983,1.842,0.714,0.029,,0.279343,369.24,,27.9343,0.36924,,,,7.85398e-5
Test1,2-Compress,74.317,1.825,0.731,0.009,,0.285994,114.592,,28.5994,0.114592,,,,7.85398e-5
Test1,2-Compress,74.650,1.808,0.748,0.029,,0.292645,369.24,,29.2645,0.36924,,,,7.85398e-5
Test1,2-Compress,74.983,1.791,0.765,0.043,,0.299296,547.493,,29.9296,0.547493,,,,7.85398e-5
Test1,2-Compress,75.317,1.773,0.783,0.029,,0.306338,369.24,,30.6338,0.36924,,,,7.85398e-5
Test1,2-Compress,75.650,1.756,0.8,0.022,,0.312989,280.113,,31.2989,0.280113,,,,7.85398e-5
Test1,2-Compress,75.983,1.74,0.816,0.029,,0.319249,369.24,,31.9249,0.36924,,,,7.85398e-5
Test1,2-Compress,76.317,1.722,0.834,0.050,,0.326291,636.62,,32.6291,0.63662,,,,7.85398e-5
Test1,2-Compress,76.650,1.705,0.851,0.043,,0.332942,547.493,,33.2942,0.547493,,,,7.85398e-5
Test1,2-Compress,76.983,1.688,0.868,0.036,,0.339593,458.366,,33.9593,0.458366,,,,7.85398e-5
Test1,2-Compress,77.317,1.671,0.885,0.036,,0.346244,458.366,,34.6244,0.458366,,,,7.85398e-5
Test1,2-Compress,77.650,1.654,0.902,0.036,,0.352895,458.366,,35.2895,0.458366,,,,7.85398e-5
Test1,2-Compress,77.983,1.637,0.919,0.056,,0.359546,713.014,,35.9546,0.713014,,,,7.85398e-5
Test1,2-Compress,78.317,1.62,0.936,0.043,,0.366197,547.493,,36.6197,0.547493,,,,7.85398e-5
Test1,2-Compress,78.650,1.603,0.953,0.050,,0.372848,636.62,,37.2848,0.63662,,,,7.85398e-5
Test1,2-Compress,78.983,1.586,0.97,0.050,,0.379499,636.62,,37.9499,0.63662,,,,7.85398e-5
Test1,2-Compress,79.317,1.569,0.987,0.050,,0.38615,636.62,,38.615,0.63662,,,,7.85398e-5
Test1,2-Compress,79.650,1.552,1.004,0.050,,0.392801,636.62,,39.2801,0.63662,,,,7.85398e-5
Test1,2-Compress,79.983,1.535,1.021,0.050,,0.399452,636.62,,39.9452,0.63662,,,,7.85398e-5
Test1,2-Compress,80.317,1.517,1.039,0.050,,0.406495,636.62,,40.6495,0.63662,,,,7.85398e-5
Test1,2-Compress,80.650,1.5,1.056,0.050,,0.413146,636.62,,41.3146,0.63662,,,,7.85398e-5
Test1,2-Compress,80.983,1.484,1.072,0.050,,0.419405,636.62,,41.9405,0.63662,,,,7.85398e-5
Test1,2-Compress,81.317,1.466,1.09,0.050,,0.426448,636.62,,42.6448,0.63662,,,,7.85398e-5
Test1,2-Compress,81.650,1.449,1.107,0.050,,0.433099,636.62,,43.3099,0.63662,,,,7.85398e-5
Test1,2-Compress,81.983,1.432,1.124,0.050,,0.43975,636.62,,43.975,0.63662,,,,7.85398e-5
Test1,2-Compress,82.317,1.415,1.141,0.050,,0.446401,636.62,,44.6401,0.63662,,,,7.85398e-5
Test1,2-Compress,82.650,1.398,1.158,0.050,,0.453052,636.62,,45.3052,0.63662,,,,7.85398e-5
Test1,2-Compress,82.983,1.381,1.175,0.050,,0.459703,636.62,,45.9703,0.63662,,,,7.85398e-5
Test1,2-Compress,83.317,1.364,1.192,0.050,,0.466354,636.62,,46.6354,0.63662,,,,7.85398e-5
Test1,2-Compress,83.650,1.347,1.209,0.050,,0.473005,636.62,,47.3005,0.63662,,,,7.85398e-5
Test1,2-Compress,83.983,1.33,1.226,0.050,,0.479656,636.62,,47.9656,0.63662,,,,7.85398e-5
Test1,2-Compress,84.317,1.313,1.243,0.050,,0.486307,636.62,,48.6307,0.63662,,,,7.85398e-5
Test1,2-Compress,84.650,1.296,1.26,0.050,,0.492958,636.62,,49.2958,0.63662,,,,7.85398e-5
Test1,2-Compress,84.983,1.278,1.278,0.056,,0.5,713.014,,50,0.713014,,,,7.85398e-5
Test1,2-Compress,85.317,1.261,1.295,0.056,,0.506651,713.014,,50.6651,0.713014,,,,7.85398e-5
Test1,2-Compress,85.650,1.244,1.312,0.050,,0.513302,636.62,,51.3302,0.63662,,,,7.85398e-5
Test1,2-Compress,85.983,1.228,1.328,0.050,,0.519562,636.62,,51.9562,0.63662,,,,7.85398e-5
Test1,2-Compress,86.317,1.21,1.346,0.050,,0.526604,636.62,,52.6604,0.63662,,,,7.85398e-5
Test1,2-Compress,86.650,1.193,1.363,0.056,,0.533255,713.014,,53.3255,0.713014,,,,7.85398e-5
Test1,2-Compress,86.983,1.176,1.38,0.050,,0.539906,636.62,,53.9906,0.63662,,,,7.85398e-5
Test1,2-Compress,87.317,1.159,1.397,0.050,,0.546557,636.62,,54.6557,0.63662,,,,7.85398e-5
Test1,2-Compress,87.650,1.142,1.414,0.050,,0.553208,636.62,,55.3208,0.63662,,,,7.85398e-5
Test1,2-Compress,87.983,1.125,1.431,0.050,,0.559859,636.62,,55.9859,0.63662,,,,7.85398e-5
Test1,2-Compress,88.317,1.107,1.449,0.050,,0.566901,636.62,,56.6901,0.63662,,,,7.85398e-5
Test1,2-Compress,88.650,1.091,1.465,0.050,,0.573161,636.62,,57.3161,0.63662,,,,7.85398e-5
Test1,2-Compress,88.983,1.074,1.482,0.056,,0.579812,713.014,,57.9812,0.713014,,,,7.85398e-5
Test1,2-Compress,89.317,1.057,1.499,0.056,,0.586463,713.014,,58.6463,0.713014,,,,7.85398e-5
Test1,2-Compress,89.650,1.04,1.516,0.056,,0.593114,713.014,,59.3114,0.713014,,,,7.85398e-5
Test1,2-Compress,89.983,1.022,1.534,0.056,,0.600156,713.014,,60.0156,0.713014,,,,7.85398e-5
Test1,2-Recover,90.303,1.034,1.522,0.050,,0.595462,636.62,,59.5462,0.63662,,,,7.85398e-5
Test1,2-Recover,90.637,1.051,1.505,0.050,,0.588811,636.62,,58.8811,0.63662,,,,7.85398e-5
Test1,2-Recover,90.970,1.069,1.487,0.050,,0.581768,636.62,,58.1768,0.63662,,,,7.85398e-5
Test1,2-Recover,91.303,1.086,1.47,0.050,,0.575117,636.62,,57.5117,0.63662,,,,7.85398e-5
Test1,2-Recover,91.637,1.103,1.453,0.050,,0.568466,636.62,,56.8466,0.63662,,,,7.85398e-5
Test1,2-Recover,91.970,1.12,1.436,0.050,,0.561815,636.62,,56.1815,0.63662,,,,7.85398e-5
Test1,2-Recover,92.303,1.137,1.419,0.050,,0.555164,636.62,,55.5164,0.63662,,,,7.85398e-5
Test1,2-Recover,92.637,1.154,1.402,0.050,,0.548513,636.62,,54.8513,0.63662,,,,7.85398e-5
Test1,2-Recover,92.970,1.171,1.385,0.050,,0.541862,636.62,,54.1862,0.63662,,,,7.85398e-5
Test1,2-Recover,93.303,1.188,1.368,0.050,,0.535211,636.62,,53.5211,0.63662,,,,7.85398e-5
Test1,2-Recover,93.637,1.205,1.351,0.056,,0.52856,713.014,,52.856,0.713014,,,,7.85398e-5
Test1,2-Recover,93.970,1.222,1.334,0.063,,0.521909,802.141,,52.1909,0.802141,,,,7.85398e-5
Test1,2-Recover,94.303,1.239,1.317,0.050,,0.515258,636.62,,51.5258,0.63662,,,,7.85398e-5
Test1,2-Recover,94.637,1.257,1.299,0.050,,0.508216,636.62,,50.8216,0.63662,,,,7.85398e-5
Test1,2-Recover,94.970,1.273,1.283,0.050,,0.501956,636.62,,50.1956,0.63662,,,,7.85398e-5
Test1,2-Recover,95.303,1.29,1.266,0.050,,0.495305,636.62,,49.5305,0.63662,,,,7.85398e-5
Test1,2-Recover,95.637,1.307,1.249,0.050,,0.488654,636.62,,48.8654,0.63662,,,,7.85398e-5
Test1,2-Recover,95.970,1.325,1.231,0.050,,0.481612,636.62,,48.1612,0.63662,,,,7.85398e-5
Test1,2-Recover,96.303,1.342,1.214,0.050,,0.474961,636.62,,47.4961,0.63662,,,,7.85398e-5
Test1,2-Recover,96.637,1.359,1.197,0.050,,0.46831,636.62,,46.831,0.63662,,,,7.85398e-5
Test1,2-Recover,96.970,1.376,1.18,0.050,,0.461659,636.62,,46.1659,0.63662,,,,7.85398e-5
Test1,2-Recover,97.303,1.393,1.163,0.050,,0.455008,636.62,,45.5008,0.63662,,,,7.85398e-5
Test1,2-Recover,97.637,1.41,1.146,0.050,,0.448357,636.62,,44.8357,0.63662,,,,7.85398e-5
Test1,2-Recover,97.970,1.427,1.129,0.050,,0.441706,636.62,,44.1706,0.63662,,,,7.85398e-5
Test1,2-Recover,98.303,1.444,1.112,0.050,,0.435055,636.62,,43.5055,0.63662,,,,7.85398e-5
Test1,2-Recover,98.637,1.461,1.095,0.043,,0.428404,547.493,,42.8404,0.547493,,,,7.85398e-5
Test1,2-Recover,98.970,1.478,1.078,0.036,,0.421753,458.366,,42.1753,0.458366,,,,7.85398e-5
Test1,2-Recover,99.303,1.495,1.061,0.043,,0.415102,547.493,,41.5102,0.547493,,,,7.85398e-5
Test1,2-Recover,99.637,1.513,1.043,0.043,,0.408059,547.493,,40.8059,0.547493,,,,7.85398e-5
Test1,2-Recover,99.970,1.529,1.027,0.029,,0.4018,369.24,,40.18,0.36924,,,,7.85398e-5
Test1,2-Recover,100.303,1.546,1.01,0.029,,0.395149,369.24,,39.5149,0.36924,,,,7.85398e-5
Test1,2-Recover,100.637,1.564,0.992,0.043,,0.388106,547.493,,38.8106,0.547493,,,,7.85398e-5
Test1,2-Recover,100.970,1.581,0.975,0.043,,0.381455,547.493,,38.1455,0.547493,,,,7.85398e-5
Test1,2-Recover,101.303,1.598,0.958,0.036,,0.374804,458.366,,37.4804,0.458366,,,,7.85398e-5
Test1,2-Recover,101.637,1.615,0.941,0.029,,0.368153,369.24,,36.8153,0.36924,,,,7.85398e-5
Test1,2-Recover,101.970,1.632,0.924,0.022,,0.361502,280.113,,36.1502,0.280113,,,,7.85398e-5
Test1,2-Recover,102.303,1.649,0.907,0.022,,0.354851,280.113,,35.4851,0.280113,,,,7.85398e-5
Test1,2-Recover,102.637,1.667,0.889,0.043,,0.347809,547.493,,34.7809,0.547493,,,,7.85398e-5
Test1,2-Recover,102.970,1.683,0.873,0.029,,0.341549,369.24,,34.1549,0.36924,,,,7.85398e-5
Test1,2-Recover,103.303,1.7,0.856,0.036,,0.334898,458.366,,33.4898,0.458366,,,,7.85398e-5
Test1,2-Recover,103.637,1.717,0.839,0.029,,0.328247,369.24,,32.8247,0.36924,,,,7.85398e-5
Test1,2-Recover,103.970,1.734,0.822,0.022,,0.321596,280.113,,32.1596,0.280113,,,,7.85398e-5
Test1,2-Recover,104.303,1.751,0.805,0.022,,0.314945,280.113,,31.4945,0.280113,,,,7.85398e-5
Test1,2-Recover,104.637,1.769,0.787,0.022,,0.307903,280.113,,30.7903,0.280113,,,,7.85398e-5
Test1,2-Recover,104.970,1.785,0.771,0.016,,0.301643,203.718,,30.1643,0.203718,,,,7.85398e-5
Test1,2-Recover,105.303,1.802,0.754,0.016,,0.294992,203.718,,29.4992,0.203718,,,,7.85398e-5
Test1,2-Recover,105.637,1.82,0.736,0.002,,0.28795,25.4648,,28.795,0.0254648,,,,7.85398e-5
Test1,2-Recover,105.970,1.837,0.719,0.002,,0.281299,25.4648,,28.1299,0.0254648,,,,7.85398e-5
Test1,2-Recover,106.303,1.854,0.702,0.022,,0.274648,280.113,,27.4648,0.280113,,,,7.85398e-5
Test1,2-Recover,106.637,1.871,0.685,0.002,,0.267997,25.4648,,26.7997,0.0254648,,,,7.85398e-5
Test1,2-Recover,106.970,1.888,0.668,0.002,,0.261346,25.4648,,26.1346,0.0254648,,,,7.85398e-5
Test1,2-Recover,107.303,1.905,0.651,0.002,,0.254695,25.4648,,25.4695,0.0254648,,,,7.85398e-5
Test1,2-Recover,107.637,1.923,0.633,0.002,,0.247653,25.4648,,24.7653,0.0254648,,,,7.85398e-5
Test1,2-Recover,107.970,1.939,0.617,0.002,,0.241393,25.4648,,24.1393,0.0254648,,,,7.85398e-5
Test1,2-Recover,108.303,1.956,0.6,0.002,,0.234742,25.4648,,23.4742,0.0254648,,,,7.85398e-5
Test1,2-Recover,108.637,1.973,0.583,0.002,,0.228091,25.4648,,22.8091,0.0254648,,,,7.85398e-5
Test1,2-Recover,108.970,1.991,0.565,0.002,,0.221049,25.4648,,22.1049,0.0254648,,,,7.85398e-5
Test1,2-Recover,109.303,2.007,0.549,0.009,,0.214789,114.592,,21.4789,0.114592,,,,7.85398e-5
Test1,2-Recover,109.637,2.025,0.531,0.009,,0.207746,114.592,,20.7746,0.114592,,,,7.85398e-5
Test1,2-Recover,109.970,2.041,0.515,0.009,,0.201487,114.592,,20.1487,0.114592,,,,7.85398e-5
Test1,2-Recover,110.303,2.059,0.497,0.009,,0.194444,114.592,,19.4444,0.114592,,,,7.85398e-5
Test1,2-Recover,110.637,2.076,0.48,0.009,,0.187793,114.592,,18.7793,0.114592,,,,7.85398e-5
Test1,2-Recover,110.970,2.093,0.463,0.009,,0.181142,114.592,,18.1142,0.114592,,,,7.85398e-5
Test1,2-Recover,111.303,2.11,0.446,0.002,,0.174491,25.4648,,17.4491,0.0254648,,,,7.85398e-5
Test1,2-Recover,111.637,2.127,0.429,0.002,,0.16784,25.4648,,16.784,0.0254648,,,,7.85398e-5
Test1,2-Recover,111.970,2.144,0.412,0.002,,0.161189,25.4648,,16.1189,0.0254648,,,,7.85398e-5
Test1,2-Recover,112.303,2.161,0.395,0.009,,0.154538,114.592,,15.4538,0.114592,,,,7.85398e-5
Test1,2-Recover,112.637,2.179,0.377,0.002,,0.147496,25.4648,,14.7496,0.0254648,,,,7.85398e-5
Test1,2-Recover,112.970,2.195,0.361,-0.005,,0.141236,-63.662,,14.1236,-0.063662,,,,7.85398e-5
Test1,2-Recover,113.303,2.212,0.344,-0.005,,0.134585,-63.662,,13.4585,-0.063662,,,,7.85398e-5
Test1,2-Recover,113.637,2.229,0.327,0.002,,0.127934,25.4648,,12.7934,0.0254648,,,,7.85398e-5
Test1,2-Recover,113.970,2.247,0.309,0.002,,0.120892,25.4648,,12.0892,0.0254648,,,,7.85398e-5
Test1,2-Recover,114.303,2.263,0.293,-0.005,,0.114632,-63.662,,11.4632,-0.063662,,,,7.85398e-5
Test1,2-Recover,114.637,2.281,0.275,0.002,,0.10759,25.4648,,10.759,0.0254648,,,,7.85398e-5
Test1,2-Recover,114.970,2.297,0.259,-0.005,,0.10133,-63.662,,10.133,-0.063662,,,,7.85398e-5
Test1,2-Recover,115.303,2.315,0.241,-0.005,,0.0942879,-63.662,,9.42879,-0.063662,,,,7.85398e-5
Test1,2-Recover,115.637,2.332,0.224,0.002,,0.0876369,25.4648,,8.76369,0.0254648,,,,7.85398e-5
Test1,2-Recover,115.970,2.349,0.207,0.002,,0.0809859,25.4648,,8.09859,0.0254648,,,,7.85398e-5
Test1,2-Recover,116.303,2.366,0.19,0.002,,0.0743349,25.4648,,7.43349,0.0254648,,,,7.85398e-5
Test1,2-Recover,116.637,2.383,0.173,0.002,,0.0676839,25.4648,,6.76839,0.0254648,,,,7.85398e-5
Test1,2-Recover,116.970,2.4,0.156,0.002,,0.0610329,25.4648,,6.10329,0.0254648,,,,7.85398e-5
Test1,2-Recover,117.303,2.417,0.139,0.002,,0.0543818,25.4648,,5.43818,0.0254648,,,,7.85398e-5
Test1,2-Recover,117.637,2.435,0.121,0.009,,0.0473396,114.592,,4.73396,0.114592,,,,7.85398e-5
Test1,2-Recover,117.970,2.451,0.105,0.009,,0.0410798,114.592,,4.10798,0.114592,,,,7.85398e-5
Test1,2-Recover,118.303,2.468,0.088,0.009,,0.0344288,114.592,,3.44288,0.114592,,,,7.85398e-5
Test1,2-Recover,118.637,2.486,0.07,0.009,,0.0273865,114.592,,2.73865,0.114592,,,,7.85398e-5
Test1,2-Recover,118.970,2.503,0.053,0.002,,0.0207355,25.4648,,2.07355,0.0254648,,,,7.85398e-5
Test1,2-Recover,119.303,2.519,0.037,0.002,,0.0144757,25.4648,,1.44757,0.0254648,,,,7.85398e-5
Test1,2-Recover,119.637,2.537,0.019,-0.005,,0.00743349,-63.662,,0.743349,-0.063662,,,,7.85398e-5
Test1,2-Recover,119.970,2.554,0.002,-0.005,,0.000782473,-63.662,,0.0782473,-0.063662,,,,7.85398e-5
Test1,3-Compress,120.280,2.546,0.01,-0.005,,0.00391236,-63.662,,0.391236,-0.063662,,,,7.85398e-5
Test1,3-Compress,120.613,2.528,0.028,-0.005,,0.0109546,-63.662,,1.09546,-0.063662,,,,7.85398e-5
Test1,3-Compress,120.947,2.511,0.045,-0.005,,0.0176056,-63.662,,1.76056,-0.063662,,,,7.85398e-5
Test1,3-Compress,121.280,2.494,0.062,-0.005,,0.0242567,-63.662,,2.42567,-0.063662,,,,7.85398e-5
Test1,3-Compress,121.613,2.478,0.078,-0.005,,0.0305164,-63.662,,3.05164,-0.063662,,,,7.85398e-5
Test1,3-Compress,121.947,2.46,0.096,-0.005,,0.0375587,-63.662,,3.75587,-0.063662,,,,7.85398e-5
Test1,3-Compress,122.280,2.443,0.113,-0.005,,0.0442097,-63.662,,4.42097,-0.063662,,,,7.85398e-5
Test1,3-Compress,122.613,2.426,0.13,-0.005,,0.0508607,-63.662,,5.08607,-0.063662,,,,7.85398e-5
Test1,3-Compress,122.947,2.409,0.147,-0.005,,0.0575117,-63.662,,5.75117,-0.063662,,,,7.85398e-5
Test1,3-Compress,123.280,2.392,0.164,-0.005,,0.0641628,-63.662,,6.41628,-0.063662,,,,7.85398e-5
Test1,3-Compress,123.613,2.375,0.181,-0.005,,0.0708138,-63.662,,7.08138,-0.063662,,,,7.85398e-5
Test1,3-Compress,123.947,2.358,0.198,-0.005,,0.0774648,-63.662,,7.74648,-0.063662,,,,7.85398e-5
Test1,3-Compress,124.280,2.341,0.215,0.002,,0.0841158,25.4648,,8.41158,0.0254648,,,,7.85398e-5
Test1,3-Compress,124.613,2.324,0.232,0.002,,0.0907668,25.4648,,9.07668,0.0254648,,,,7.85398e-5
Test1,3-Compress,124.947,2.307,0.249,0.002,,0.0974178,25.4648,,9.74178,0.0254648,,,,7.85398e-5
Test1,3-Compress,125.280,2.29,0.266,0.002,,0.104069,25.4648,,10.4069,0.0254648,,,,7.85398e-5
Test1,3-Compress,125.613,2.272,0.284,0.002,,0.111111,25.4648,,11.1111,0.0254648,,,,7.85398e-5
Test1,3-Compress,125.947,2.255,0.301,0.009,,0.117762,114.592,,11.7762,0.114592,,,,7.85398e-5
Test1,3-Compress,126.280,2.238,0.318,0.009,,0.124413,114.592,,12.4413,0.114592,,,,7.85398e-5
Test1,3-Compress,126.613,2.222,0.334,0.009,,0.130673,114.592,,13.0673,0.114592,,,,7.85398e-5
Test1,3-Compress,126.947,2.204,0.352,0.009,,0.137715,114.592,,13.7715,0.114592,,,,7.85398e-5
Test1,3-Compress,127.280,2.187,0.369,0.002,,0.144366,25.4648,,14.4366,0.0254648,,,,7.85398e-5
Test1,3-Compress,127.613,2.17,0.386,0.009,,0.151017,114.592,,15.1017,0.114592,,,,7.85398e-5
Test1,3-Compress,127.947,2.153,0.403,-0.005,,0.157668,-63.662,,15.7668,-0.063662,,,,7.85398e-5
Test1,3-Compress,128.280,2.136,0.42,0.002,,0.164319,25.4648,,16.4319,0.0254648,,,,7.85398e-5
Test1,3-Compress,128.613,2.119,0.437,0.009,,0.17097,114.592,,17.097,0.114592,,,,7.85398e-5
Test1,3-Compress,128.947,2.101,0.455,0.009,,0.178013,114.592,,17.8013,0.114592,,,,7.85398e-5
Test1,3-Compress,129.280,2.085,0.471,0.009,,0.184272,114.592,,18.4272,0.114592,,,,7.85398e-5
Test1,3-Compress,129.613,2.068,0.488,0.009,,0.190923,114.592,,19.0923,0.114592,,,,7.85398e-5
Test1,3-Compress,129.947,2.051,0.505,0.009,,0.197574,114.592,,19.7574,0.114592,,,,7.85398e-5
Test1,3-Compress,130.280,2.033,0.523,0.009,,0.204617,114.592,,20.4617,0.114592,,,,7.85398e-5
Test1,3-Compress,130.613,2.016,0.54,0.009,,0.211268,114.592,,21.1268,0.114592,,,,7.85398e-5
Test1,3-Compress,130.947,1.999,0.557,0.009,,0.217919,114.592,,21.7919,0.114592,,,,7.85398e-5
Test1,3-Compress,131.280,1.982,0.574,0.002,,0.22457,25.4648,,22.457,0.0254648,,,,7.85398e-5
Test1,3-Compress,131.613,1.965,0.591,0.002,,0.231221,25.4648,,23.1221,0.0254648,,,,7.85398e-5
Test1,3-Compress,131.947,1.948,0.608,0.002,,0.237872,25.4648,,23.7872,0.0254648,,,,7.85398e-5
Test1,3-Compress,132.280,1.931,0.625,0.002,,0.244523,25.4648,,24.4523,0.0254648,,,,7.85398e-5
Test1,3-Compress,132.613,1.914,0.642,0.009,,0.251174,114.592,,25.1174,0.114592,,,,7.85398e-5
Test1,3-Compress,132.947,1.897,0.659,0.009,,0.257825,114.592,,25.7825,0.114592,,,,7.85398e-5
Test1,3-Compress,133.280,1.88,0.676,0.022,,0.264476,280.113,,26.4476,0.280113,,,,7.85398e-5
Test1,3-Compress,133.613,1.863,0.693,0.002,,0.271127,25.4648,,27.1127,0.0254648,,,,7.85398e-5
Test1,3-Compress,133.947,1.845,0.711,0.022,,0.278169,280.113,,27.8169,0.280113,,,,7.85398e-5
Test1,3-Compress,134.280,1.829,0.727,0.022,,0.284429,280.113,,28.4429,0.280113,,,,7.85398e-5
Test1,3-Compress,134.613,1.812,0.744,0.022,,0.29108,280.113,,29.108,0.280113,,,,7.85398e-5
Test1,3-Compress,134.947,1.795,0.761,0.036,,0.297731,458.366,,29.7731,0.458366,,,,7.85398e-5
Test1,3-Compress,135.280,1.777,0.779,0.036,,0.304773,458.366,,30.4773,0.458366,,,,7.85398e-5
Test1,3-Compress,135.613,1.76,0.796,0.043,,0.311424,547.493,,31.1424,0.547493,,,,7.85398e-5
Test1,3-Compress,135.947,1.743,0.813,0.050,,0.318075,636.62,,31.8075,0.63662,,,,7.85398e-5
Test1,3-Compress,136.280,1.726,0.83,0.036,,0.324726,458.366,,32.4726,0.458366,,,,7.85398e-5
Test1,3-Compress,136.613,1.709,0.847,0.043,,0.331377,547.493,,33.1377,0.547493,,,,7.85398e-5
Test1,3-Compress,136.947,1.692,0.864,0.050,,0.338028,636.62,,33.8028,0.63662,,,,7.85398e-5
Test1,3-Compress,137.280,1.675,0.881,0.043,,0.344679,547.493,,34.4679,0.547493,,,,7.85398e-5
Test1,3-Compress,137.613,1.658,0.898,0.043,,0.35133,547.493,,35.133,0.547493,,,,7.85398e-5
Test1,3-Compress,137.947,1.641,0.915,0.050,,0.357981,636.62,,35.7981,0.63662,,,,7.85398e-5
Test1,3-Compress,138.280,1.624,0.932,0.050,,0.364632,636.62,,36.4632,0.63662,,,,7.85398e-5
Test1,3-Compress,138.613,1.607,0.949,0.050,,0.371283,636.62,,37.1283,0.63662,,,,7.85398e-5
Test1,3-Compress,138.947,1.589,0.967,0.050,,0.378326,636.62,,37.8326,0.63662,,,,7.85398e-5
Test1,3-Compress,139.280,1.573,0.983,0.050,,0.384585,636.62,,38.4585,0.63662,,,,7.85398e-5
Test1,3-Compress,139.613,1.556,1,0.050,,0.391236,636.62,,39.1236,0.63662,,,,7.85398e-5
Test1,3-Compress,139.947,1.538,1.018,0.050,,0.398279,636.62,,39.8279,0.63662,,,,7.85398e-5
Test1,3-Compress,140.280,1.521,1.035,0.050,,0.40493,636.62,,40.493,0.63662,,,,7.85398e-5
Test1,3-Compress,140.613,1.504,1.052,0.050,,0.411581,636.62,,41.1581,0.63662,,,,7.85398e-5
Test1,3-Compress,140.947,1.487,1.069,0.050,,0.418232,636.62,,41.8232,0.63662,,,,7.85398e-5
Test1,3-Compress,141.280,1.47,1.086,0.050,,0.424883,636.62,,42.4883,0.63662,,,,7.85398e-5
Test1,3-Compress,141.613,1.453,1.103,0.050,,0.431534,636.62,,43.1534,0.63662,,,,7.85398e-5
Test1,3-Compress,141.947,1.436,1.12,0.043,,0.438185,547.493,,43.8185,0.547493,,,,7.85398e-5
Test1,3-Compress,142.280,1.419,1.137,0.050,,0.444836,636.62,,44.4836,0.63662,,,,7.85398e-5
Test1,3-Compress,142.613,1.402,1.154,0.056,,0.451487,713.014,,45.1487,0.713014,,,,7.85398e-5
Test1,3-Compress,142.947,1.385,1.171,0.050,,0.458138,636.62,,45.8138,0.63662,,,,7.85398e-5
Test1,3-Compress,143.280,1.368,1.188,0.056,,0.464789,713.014,,46.4789,0.713014,,,,7.85398e-5
Test1,3-Compress,143.613,1.351,1.205,0.050,,0.47144,636.62,,47.144,0.63662,,,,7.85398e-5
Test1,3-Compress,143.947,1.333,1.223,0.050,,0.478482,636.62,,47.8482,0.63662,,,,7.85398e-5
Test1,3-Compress,144.280,1.317,1.239,0.050,,0.484742,636.62,,48.4742,0.63662,,,,7.85398e-5
Test1,3-Compress,144.613,1.3,1.256,0.050,,0.491393,636.62,,49.1393,0.63662,,,,7.85398e-5
Test1,3-Compress,144.947,1.282,1.274,0.050,,0.498435,636.62,,49.8435,0.63662,,,,7.85398e-5
Test1,3-Compress,145.280,1.265,1.291,0.050,,0.505086,636.62,,50.5086,0.63662,,,,7.85398e-5
Test1,3-Compress,145.613,1.248,1.308,0.050,,0.511737,636.62,,51.1737,0.63662,,,,7.85398e-5
Test1,3-Compress,145.947,1.231,1.325,0.050,,0.518388,636.62,,51.8388,0.63662,,,,7.85398e-5
Test1,3-Compress,146.280,1.214,1.342,0.050,,0.525039,636.62,,52.5039,0.63662,,,,7.85398e-5
Test1,3-Compress,146.613,1.197,1.359,0.050,,0.53169,636.62,,53.169,0.63662,,,,7.85398e-5
Test1,3-Compress,146.947,1.179,1.377,0.050,,0.538732,636.62,,53.8732,0.63662,,,,7.85398e-5
Test1,3-Compress,147.280,1.163,1.393,0.056,,0.544992,713.014,,54.4992,0.713014,,,,7.85398e-5
Test1,3-Compress,147.613,1.146,1.41,0.050,,0.551643,636.62,,55.1643,0.63662,,,,7.85398e-5
Test1,3-Compress,147.947,1.129,1.427,0.050,,0.558294,636.62,,55.8294,0.63662,,,,7.85398e-5
Test1,3-Compress,148.280,1.111,1.445,0.056,,0.565336,713.014,,56.5336,0.713014,,,,7.85398e-5
Test1,3-Compress,148.613,1.095,1.461,0.056,,0.571596,713.014,,57.1596,0.713014,,,,7.85398e-5
Test1,3-Compress,148.947,1.077,1.479,0.050,,0.578638,636.62,,57.8638,0.63662,,,,7.85398e-5
Test1,3-Compress,149.280,1.061,1.495,0.050,,0.584898,636.62,,58.4898,0.63662,,,,7.85398e-5
Test1,3-Compress,149.613,1.043,1.513,0.050,,0.591941,636.62,,59.1941,0.63662,,,,7.85398e-5
Test1,3-Compress,149.947,1.026,1.53,0.050,,0.598592,636.62,,59.8592,0.63662,,,,7.85398e-5
Test1,3-Recover,150.267,1.031,1.525,0.056,,0.596635,713.014,,59.6635,0.713014,,,,7.85398e-5
Test1,3-Recover,150.600,1.047,1.509,0.050,,0.590376,636.62,,59.0376,0.63662,,,,7.85398e-5
Test1,3-Recover,150.933,1.065,1.491,0.056,,0.583333,713.014,,58.3333,0.713014,,,,7.85398e-5
Test1,3-Recover,151.267,1.082,1.474,0.063,,0.576682,802.141,,57.6682,0.802141,,,,7.85398e-5
Test1,3-Recover,151.600,1.099,1.457,0.050,,0.570031,636.62,,57.0031,0.63662,,,,7.85398e-5
Test1,3-Recover,151.933,1.116,1.44,0.050,,0.56338,636.62,,56.338,0.63662,,,,7.85398e-5
Test1,3-Recover,152.267,1.133,1.423,0.050,,0.556729,636.62,,55.6729,0.63662,,,,7.85398e-5
Test1,3-Recover,152.600,1.15,1.406,0.050,,0.550078,636.62,,55.0078,0.63662,,,,7.85398e-5
Test1,3-Recover,152.933,1.167,1.389,0.050,,0.543427,636.62,,54.3427,0.63662,,,,7.85398e-5
Test1,3-Recover,153.267,1.184,1.372,0.050,,0.536776,636.62,,53.6776,0.63662,,,,7.85398e-5
Test1,3-Recover,153.600,1.201,1.355,0.050,,0.530125,636.62,,53.0125,0.63662,,,,7.85398e-5
Test1,3-Recover,153.933,1.218,1.338,0.050,,0.523474,636.62,,52.3474,0.63662,,,,7.85398e-5
Test1,3-Recover,154.267,1.236,1.32,0.050,,0.516432,636.62,,51.6432,0.63662,,,,7.85398e-5
Test1,3-Recover,154.600,1.253,1.303,0.050,,0.509781,636.62,,50.9781,0.63662,,,,7.85398e-5
Test1,3-Recover,154.933,1.269,1.287,0.050,,0.503521,636.62,,50.3521,0.63662,,,,7.85398e-5
Test1,3-Recover,155.267,1.287,1.269,0.050,,0.496479,636.62,,49.6479,0.63662,,,,7.85398e-5
Test1,3-Recover,155.600,1.304,1.252,0.050,,0.489828,636.62,,48.9828,0.63662,,,,7.85398e-5
Test1,3-Recover,155.933,1.321,1.235,0.050,,0.483177,636.62,,48.3177,0.63662,,,,7.85398e-5
Test1,3-Recover,156.267,1.338,1.218,0.050,,0.476526,636.62,,47.6526,0.63662,,,,7.85398e-5
Test1,3-Recover,156.600,1.355,1.201,0.050,,0.469875,636.62,,46.9875,0.63662,,,,7.85398e-5
Test1,3-Recover,156.933,1.372,1.184,0.050,,0.463224,636.62,,46.3224,0.63662,,,,7.85398e-5
Test1,3-Recover,157.267,1.389,1.167,0.050,,0.456573,636.62,,45.6573,0.63662,,,,7.85398e-5
Test1,3-Recover,157.600,1.406,1.15,0.036,,0.449922,458.366,,44.9922,0.458366,,,,7.85398e-5
Test1,3-Recover,157.933,1.423,1.133,0.043,,0.443271,547.493,,44.3271,0.547493,,,,7.85398e-5
Test1,3-Recover,158.267,1.44,1.116,0.043,,0.43662,547.493,,43.662,0.547493,,,,7.85398e-5
Test1,3-Recover,158.600,1.457,1.099,0.043,,0.429969,547.493,,42.9969,0.547493,,,,7.85398e-5
Test1,3-Recover,158.933,1.474,1.082,0.043,,0.423318,547.493,,42.3318,0.547493,,,,7.85398e-5
Test1,3-Recover,159.267,1.492,1.064,0.050,,0.416275,636.62,,41.6275,0.63662,,,,7.85398e-5
Test1,3-Recover,159.600,1.509,1.047,0.043,,0.409624,547.493,,40.9624,0.547493,,,,7.85398e-5
Test1,3-Recover,159.933,1.525,1.031,0.043,,0.403365,547.493,,40.3365,0.547493,,,,7.85398e-5
Test1,3-Recover,160.267,1.543,1.013,0.043,,0.396322,547.493,,39.6322,0.547493,,,,7.85398e-5
Test1,3-Recover,160.600,1.56,0.996,0.043,,0.389671,547.493,,38.9671,0.547493,,,,7.85398e-5
Test1,3-Recover,160.933,1.577,0.979,0.050,,0.38302,636.62,,38.302,0.63662,,,,7.85398e-5
Test1,3-Recover,161.267,1.594,0.962,0.036,,0.376369,458.366,,37.6369,0.458366,,,,7.85398e-5
Test1,3-Recover,161.600,1.611,0.945,0.036,,0.369718,458.366,,36.9718,0.458366,,,,7.85398e-5
Test1,3-Recover,161.933,1.628,0.928,0.029,,0.363067,369.24,,36.3067,0.36924,,,,7.85398e-5
Test1,3-Recover,162.267,1.645,0.911,0.036,,0.356416,458.366,,35.6416,0.458366,,,,7.85398e-5
Test1,3-Recover,162.600,1.662,0.894,0.029,,0.349765,369.24,,34.9765,0.36924,,,,7.85398e-5
Test1,3-Recover,162.933,1.679,0.877,0.016,,0.343114,203.718,,34.3114,0.203718,,,,7.85398e-5
Test1,3-Recover,163.267,1.696,0.86,0.022,,0.336463,280.113,,33.6463,0.280113,,,,7.85398e-5
Test1,3-Recover,163.600,1.713,0.843,0.022,,0.329812,280.113,,32.9812,0.280113,,,,7.85398e-5
Test1,3-Recover,163.933,1.731,0.825,0.016,,0.32277,203.718,,32.277,0.203718,,,,7.85398e-5
Test1,3-Recover,164.267,1.748,0.808,0.002,,0.316119,25.4648,,31.6119,0.0254648,,,,7.85398e-5
Test1,3-Recover,164.600,1.765,0.791,0.016,,0.309468,203.718,,30.9468,0.203718,,,,7.85398e-5
Test1,3-Recover,164.933,1.781,0.775,0.016,,0.303208,203.718,,30.3208,0.203718,,,,7.85398e-5
Test1,3-Recover,165.267,1.799,0.757,0.009,,0.296166,114.592,,29.6166,0.114592,,,,7.85398e-5
Test1,3-Recover,165.600,1.816,0.74,0.002,,0.289515,25.4648,,28.9515,0.0254648,,,,7.85398e-5
Test1,3-Recover,165.933,1.833,0.723,0.009,,0.282864,114.592,,28.2864,0.114592,,,,7.85398e-5
Test1,3-Recover,166.267,1.85,0.706,0.016,,0.276213,203.718,,27.6213,0.203718,,,,7.85398e-5
Test1,3-Recover,166.600,1.867,0.689,0.009,,0.269562,114.592,,26.9562,0.114592,,,,7.85398e-5
Test1,3-Recover,166.933,1.884,0.672,0.016,,0.262911,203.718,,26.2911,0.203718,,,,7.85398e-5
Test1,3-Recover,167.267,1.901,0.655,0.009,,0.25626,114.592,,25.626,0.114592,,,,7.85398e-5
Test1,3-Recover,167.600,1.918,0.638,0.016,,0.249609,203.718,,24.9609,0.203718,,,,7.85398e-5
Test1,3-Recover,167.933,1.935,0.621,0.016,,0.242958,203.718,,24.2958,0.203718,,,,7.85398e-5
Test1,3-Recover,168.267,1.952,0.604,0.022,,0.236307,280.113,,23.6307,0.280113,,,,7.85398e-5
Test1,3-Recover,168.600,1.969,0.587,0.016,,0.229656,203.718,,22.9656,0.203718,,,,7.85398e-5
Test1,3-Recover,168.933,1.987,0.569,0.022,,0.222613,280.113,,22.2613,0.280113,,,,7.85398e-5
Test1,3-Recover,169.267,2.004,0.552,0.009,,0.215962,114.592,,21.5962,0.114592,,,,7.85398e-5
Test1,3-Recover,169.600,2.021,0.535,0.016,,0.209311,203.718,,20.9311,0.203718,,,,7.85398e-5
Test1,3-Recover,169.933,2.037,0.519,-0.005,,0.203052,-63.662,,20.3052,-0.063662,,,,7.85398e-5
Test1,3-Recover,170.267,2.055,0.501,0.009,,0.196009,114.592,,19.6009,0.114592,,,,7.85398e-5
Test1,3-Recover,170.600,2.072,0.484,0.002,,0.189358,25.4648,,18.9358,0.0254648,,,,7.85398e-5
Test1,3-Recover,170.933,2.089,0.467,-0.005,,0.182707,-63.662,,18.2707,-0.063662,,,,7.85398e-5
Test1,3-Recover,171.267,2.106,0.45,0.002,,0.176056,25.4648,,17.6056,0.0254648,,,,7.85398e-5
Test1,3-Recover,171.600,2.123,0.433,0.002,,0.169405,25.4648,,16.9405,0.0254648,,,,7.85398e-5
Test1,3-Recover,171.933,2.14,0.416,0.002,,0.162754,25.4648,,16.2754,0.0254648,,,,7.85398e-5
Test1,3-Recover,172.267,2.158,0.398,0.002,,0.155712,25.4648,,15.5712,0.0254648,,,,7.85398e-5
Test1,3-Recover,172.600,2.174,0.382,0.002,,0.149452,25.4648,,14.9452,0.0254648,,,,7.85398e-5
Test1,3-Recover,172.933,2.191,0.365,0.002,,0.142801,25.4648,,14.2801,0.0254648,,,,7.85398e-5
Test1,3-Recover,173.267,2.208,0.348,0.002,,0.13615,25.4648,,13.615,0.0254648,,,,7.85398e-5
Test1,3-Recover,173.600,2.226,0.33,0.002,,0.129108,25.4648,,12.9108,0.0254648,,,,7.85398e-5
Test1,3-Recover,173.933,2.243,0.313,0.002,,0.122457,25.4648,,12.2457,0.0254648,,,,7.85398e-5
Test1,3-Recover,174.267,2.26,0.296,0.009,,0.115806,114.592,,11.5806,0.114592,,,,7.85398e-5
Test1,3-Recover,174.600,2.277,0.279,0.009,,0.109155,114.592,,10.9155,0.114592,,,,7.85398e-5
Test1,3-Recover,174.933,2.294,0.262,0.002,,0.102504,25.4648,,10.2504,0.0254648,,,,7.85398e-5
Test1,3-Recover,175.267,2.311,0.245,0.009,,0.0958529,114.592,,9.58529,0.114592,,,,7.85398e-5
Test1,3-Recover,175.600,2.328,0.228,0.009,,0.0892019,114.592,,8.92019,0.114592,,,,7.85398e-5
Test1,3-Recover,175.933,2.345,0.211,0.002,,0.0825509,25.4648,,8.25509,0.0254648,,,,7.85398e-5
Test1,3-Recover,176.267,2.362,0.194,0.009,,0.0758998,114.592,,7.58998,0.114592,,,,7.85398e-5
Test1,3-Recover,176.600,2.379,0.177,-0.005,,0.0692488,-63.662,,6.92488,-0.063662,,,,7.85398e-5
Test1,3-Recover,176.933,2.396,0.16,-0.005,,0.0625978,-63.662,,6.25978,-0.063662,,,,7.85398e-5
Test1,3-Recover,177.267,2.414,0.142,-0.005,,0.0555556,-63.662,,5.55556,-0.063662,,,,7.85398e-5
Test1,3-Recover,177.600,2.43,0.126,-0.005,,0.0492958,-63.662,,4.92958,-0.063662,,,,7.85398e-5
Test1,3-Recover,177.933,2.447,0.109,-0.005,,0.0426448,-63.662,,4.26448,-0.063662,,,,7.85398e-5
Test1,3-Recover,178.267,2.464,0.092,-0.005,,0.0359937,-63.662,,3.59937,-0.063662,,,,7.85398e-5
Test1,3-Recover,178.600,2.482,0.074,-0.005,,0.0289515,-63.662,,2.89515,-0.063662,,,,7.85398e-5
Test1,3-Recover,178.933,2.499,0.057,-0.005,,0.0223005,-63.662,,2.23005,-0.063662,,,,7.85398e-5
Test1,3-Recover,179.267,2.516,0.04,0.002,,0.0156495,25.4648,,1.56495,0.0254648,,,,7.85398e-5
Test1,3-Recover,179.600,2.533,0.023,-0.005,,0.00899844,-63.662,,0.899844,-0.063662,,,,7.85398e-5
Test1,3-Recover,179.933,2.55,0.006,-0.005,,0.00234742,-63.662,,0.234742,-0.063662,,,,7.85398e-5
Test1,3-Recover,180.100,2.556,-0,0.002,,0,25.4648,,0,0.0254648,,,,7.85398e-5