File: data/gamma_1-0.25_2.csv
SetName,Cycle,Time_S,Size_mm,Displacement_mm,Force_N,,Strain,Stress(Pascal),,%Strain,Stress(kPa),,,,Area(m^2)
Test1,1-Compress,0.000,3.066,-0,-0.027,,0,-343.775,,0,-0.343775,,,,7.85398e-5
Test1,1-Compress,0.333,3.046,0.02,-0.027,,0.00652316,-343.775,,0.652316,-0.343775,,,,7.85398e-5
Test1,1-Compress,0.667,3.025,0.041,-0.027,,0.0133725,-343.775,,1.33725,-0.343775,,,,7.85398e-5
Test1,1-Compress,1.000,3.005,0.061,-0.027,,0.0198956,-343.775,,1.98956,-0.343775,,,,7.85398e-5
Test1,1-Compress,1.333,2.985,0.081,-0.027,,0.0264188,-343.775,,2.64188,-0.343775,,,,7.85398e-5
Test1,1-Compress,1.667,2.964,0.102,-0.027,,0.0332681,-343.775,,3.32681,-0.343775,,,,7.85398e-5
Test1,1-Compress,2.000,2.944,0.122,-0.020,,0.0397913,-254.648,,3.97913,-0.254648,,,,7.85398e-5
Test1,1-Compress,2.333,2.923,0.143,-0.027,,0.0466406,-343.775,,4.66406,-0.343775,,,,7.85398e-5
Test1,1-Compress,2.667,2.902,0.164,-0.020,,0.0534899,-254.648,,5.34899,-0.254648,,,,7.85398e-5
Test1,1-Compress,3.000,2.882,0.184,-0.020,,0.060013,-254.648,,6.0013,-0.254648,,,,7.85398e-5
Test1,1-Compress,3.333,2.862,0.204,-0.020,,0.0665362,-254.648,,6.65362,-0.254648,,,,7.85398e-5
Test1,1-Compress,3.667,2.841,0.225,-0.020,,0.0733855,-254.648,,7.33855,-0.254648,,,,7.85398e-5
Test1,1-Compress,4.000,2.821,0.245,-0.027,,0.0799087,-343.775,,7.99087,-0.343775,,,,7.85398e-5
Test1,1-Compress,4.333,2.8,0.266,-0.020,,0.086758,-254.648,,8.6758,-0.254648,,,,7.85398e-5
Test1,1-Compress,4.667,2.779,0.287,-0.020,,0.0936073,-254.648,,9.36073,-0.254648,,,,7.85398e-5
Test1,1-Compress,5.000,2.759,0.307,-0.020,,0.10013,-254.648,,10.013,-0.254648,,,,7.85398e-5
Test1,1-Compress,5.333,2.739,0.327,-0.020,,0.106654,-254.648,,10.6654,-0.254648,,,,7.85398e-5
Test1,1-Compress,5.667,2.718,0.348,-0.014,,0.113503,-178.254,,11.3503,-0.178254,,,,7.85398e-5
Test1,1-Compress,6.000,2.698,0.368,-0.007,,0.120026,-89.1268,,12.0026,-0.0891268,,,,7.85398e-5
Test1,1-Compress,6.333,2.678,0.388,-0.007,,0.126549,-89.1268,,12.6549,-0.0891268,,,,7.85398e-5
Test1,1-Compress,6.667,2.657,0.409,0.007,,0.133399,89.1268,,13.3399,0.0891268,,,,7.85398e-5
Test1,1-Compress,7.000,2.636,0.43,0.007,,0.140248,89.1268,,14.0248,0.0891268,,,,7.85398e-5
Test1,1-Compress,7.333,2.616,0.45,0.007,,0.146771,89.1268,,14.6771,0.0891268,,,,7.85398e-5
Test1,1-Compress,7.667,2.595,0.471,0.007,,0.15362,89.1268,,15.362,0.0891268,,,,7.85398e-5
Test1,1-Compress,8.000,2.575,0.491,0.020,,0.160144,254.648,,16.0144,0.254648,,,,7.85398e-5
Test1,1-Compress,8.333,2.555,0.511,0.014,,0.166667,178.254,,16.6667,0.178254,,,,7.85398e-5
Test1,1-Compress,8.667,2.534,0.532,0.014,,0.173516,178.254,,17.3516,0.178254,,,,7.85398e-5
Test1,1-Compress,9.000,2.514,0.552,0.020,,0.180039,254.648,,18.0039,0.254648,,,,7.85398e-5
Test1,1-Compress,9.333,2.493,0.573,0.014,,0.186888,178.254,,18.6888,0.178254,,,,7.85398e-5
Test1,1-Compress,9.667,2.472,0.594,0.020,,0.193738,254.648,,19.3738,0.254648,,,,7.85398e-5
Test1,1-Compress,10.000,2.452,0.614,0.027,,0.200261,343.775,,20.0261,0.343775,,,,7.85398e-5
Test1,1-Compress,10.333,2.432,0.634,0.020,,0.206784,254.648,,20.6784,0.254648,,,,7.85398e-5
Test1,1-Compress,10.667,2.411,0.655,0.027,,0.213633,343.775,,21.3633,0.343775,,,,7.85398e-5
Test1,1-Compress,11.000,2.391,0.675,0.027,,0.220157,343.775,,22.0157,0.343775,,,,7.85398e-5
Test1,1-Compress,11.333,2.371,0.695,0.020,,0.22668,254.648,,22.668,0.254648,,,,7.85398e-5
Test1,1-Compress,11.667,2.35,0.716,0.014,,0.233529,178.254,,23.3529,0.178254,,,,7.85398e-5
Test1,1-Compress,12.000,2.329,0.737,0.027,,0.240378,343.775,,24.0378,0.343775,,,,7.85398e-5
Test1,1-Compress,12.333,2.309,0.757,0.027,,0.246902,343.775,,24.6902,0.343775,,,,7.85398e-5
Test1,1-Compress,12.667,2.288,0.778,0.027,,0.253751,343.775,,25.3751,0.343775,,,,7.85398e-5
Test1,1-Compress,13.000,2.268,0.798,0.027,,0.260274,343.775,,26.0274,0.343775,,,,7.85398e-5
Test1,1-Compress,13.333,2.248,0.818,0.027,,0.266797,343.775,,26.6797,0.343775,,,,7.85398e-5
Test1,1-Compress,13.667,2.227,0.839,0.020,,0.273646,254.648,,27.3646,0.254648,,,,7.85398e-5
Test1,1-Compress,14.000,2.206,0.86,0.027,,0.280496,343.775,,28.0496,0.343775,,,,7.85398e-5
Test1,1-Compress,14.333,2.186,0.88,0.034,,0.287019,432.902,,28.7019,0.432902,,,,7.85398e-5
Test1,1-Compress,14.667,2.165,0.901,0.027,,0.293868,343.775,,29.3868,0.343775,,,,7.85398e-5
Test1,1-Compress,15.000,2.145,0.921,0.027,,0.300391,343.775,,30.0391,0.343775,,,,7.85398e-5
Test1,1-Compress,15.333,2.125,0.941,0.027,,0.306915,343.775,,30.6915,0.343775,,,,7.85398e-5
Test1,1-Compress,15.667,2.104,0.962,0.034,,0.313764,432.902,,31.3764,0.432902,,,,7.85398e-5
Test1,1-Compress,16.000,2.084,0.982,0.027,,0.320287,343.775,,32.0287,0.343775,,,,7.85398e-5
Test1,1-Compress,16.333,2.063,1.003,0.027,,0.327136,343.775,,32.7136,0.343775,,,,7.85398e-5
Test1,1-Compress,16.667,2.043,1.023,0.027,,0.333659,343.775,,33.3659,0.343775,,,,7.85398e-5
Test1,1-Compress,17.000,2.022,1.044,0.027,,0.340509,343.775,,34.0509,0.343775,,,,7.85398e-5
Test1,1-Compress,17.333,2.002,1.064,0.027,,0.347032,343.775,,34.7032,0.343775,,,,7.85398e-5
Test1,1-Compress,17.667,1.981,1.085,0.027,,0.353881,343.775,,35.3881,0.343775,,,,7.85398e-5
Test1,1-Compress,18.000,1.961,1.105,0.027,,0.360404,343.775,,36.0404,0.343775,,,,7.85398e-5
Test1,1-Compress,18.333,1.94,1.126,0.027,,0.367254,343.775,,36.7254,0.343775,,,,7.85398e-5
Test1,1-Compress,18.667,1.92,1.146,0.027,,0.373777,343.775,,37.3777,0.343775,,,,7.85398e-5
Test1,1-Compress,19.000,1.899,1.167,0.034,,0.380626,432.902,,38.0626,0.432902,,,,7.85398e-5
Test1,1-Compress,19.333,1.879,1.187,0.034,,0.387149,432.902,,38.7149,0.432902,,,,7.85398e-5
Test1,1-Compress,19.667,1.858,1.208,0.034,,0.393999,432.902,,39.3999,0.432902,,,,7.85398e-5
Test1,1-Compress,20.000,1.838,1.228,0.027,,0.400522,343.775,,40.0522,0.343775,,,,7.85398e-5
Test1,1-Compress,20.333,1.818,1.248,0.034,,0.407045,432.902,,40.7045,0.432902,,,,7.85398e-5
Test1,1-Compress,20.667,1.797,1.269,0.027,,0.413894,343.775,,41.3894,0.343775,,,,7.85398e-5
Test1,1-Compress,21.000,1.777,1.289,0.027,,0.420417,343.775,,42.0417,0.343775,,,,7.85398e-5
Test1,1-Compress,21.333,1.756,1.31,0.027,,0.427267,343.775,,42.7267,0.343775,,,,7.85398e-5
Test1,1-Compress,21.667,1.735,1.331,0.027,,0.434116,343.775,,43.4116,0.343775,,,,7.85398e-5
Test1,1-Compress,22.000,1.715,1.351,0.027,,0.440639,343.775,,44.0639,0.343775,,,,7.85398e-5
Test1,1-Compress,22.333,1.695,1.371,0.041,,0.447162,522.028,,44.7162,0.522028,,,,7.85398e-5
Test1,1-Compress,22.667,1.674,1.392,0.041,,0.454012,522.028,,45.4012,0.522028,,,,7.85398e-5
Test1,1-Compress,23.000,1.654,1.412,0.054,,0.460535,687.549,,46.0535,0.687549,,,,7.85398e-5
Test1,1-Compress,23.333,1.634,1.432,0.054,,0.467058,687.549,,46.7058,0.687549,,,,7.85398e-5
Test1,1-Compress,23.667,1.612,1.454,0.068,,0.474234,865.803,,47.4234,0.865803,,,,7.85398e-5
Test1,1-Compress,24.000,1.593,1.473,0.061,,0.480431,776.676,,48.0431,0.776676,,,,7.85398e-5
Test1,1-Compress,24.333,1.572,1.494,0.068,,0.48728,865.803,,48.728,0.865803,,,,7.85398e-5
Test1,1-Compress,24.667,1.551,1.515,0.068,,0.494129,865.803,,49.4129,0.865803,,,,7.85398e-5
Test1,1-Compress,25.000,1.531,1.535,0.068,,0.500652,865.803,,50.0652,0.865803,,,,7.85398e-5
Test1,1-Compress,25.333,1.511,1.555,0.061,,0.507175,776.676,,50.7175,0.776676,,,,7.85398e-5
Test1,1-Compress,25.667,1.49,1.576,0.082,,0.514025,1044.06,,51.4025,1.04406,,,,7.85398e-5
Test1,1-Compress,26.000,1.469,1.597,0.082,,0.520874,1044.06,,52.0874,1.04406,,,,7.85398e-5
Test1,1-Compress,26.333,1.449,1.617,0.082,,0.527397,1044.06,,52.7397,1.04406,,,,7.85398e-5
Test1,1-Compress,26.667,1.428,1.638,0.082,,0.534247,1044.06,,53.4247,1.04406,,,,7.85398e-5
Test1,1-Compress,27.000,1.408,1.658,0.082,,0.54077,1044.06,,54.077,1.04406,,,,7.85398e-5
Test1,1-Compress,27.333,1.388,1.678,0.082,,0.547293,1044.06,,54.7293,1.04406,,,,7.85398e-5
Test1,1-Compress,27.667,1.367,1.699,0.082,,0.554142,1044.06,,55.4142,1.04406,,,,7.85398e-5
Test1,1-Compress,28.000,1.346,1.72,0.082,,0.560992,1044.06,,56.0992,1.04406,,,,7.85398e-5
Test1,1-Compress,28.333,1.327,1.739,0.082,,0.567189,1044.06,,56.7189,1.04406,,,,7.85398e-5
Test1,1-Compress,28.667,1.305,1.761,0.082,,0.574364,1044.06,,57.4364,1.04406,,,,7.85398e-5
Test1,1-Compress,29.000,1.285,1.781,0.082,,0.580887,1044.06,,58.0887,1.04406,,,,7.85398e-5
Test1,1-Compress,29.333,1.265,1.801,0.082,,0.58741,1044.06,,58.741,1.04406,,,,7.85398e-5
Test1,1-Compress,29.667,1.244,1.822,0.082,,0.59426,1044.06,,59.426,1.04406,,,,7.85398e-5
Test1,1-Compress,30.000,1.226,1.84,0.082,,0.60013,1044.06,,60.013,1.04406,,,,7.85398e-5
Test1,1-Recover,30.333,1.245,1.821,0.082,,0.593933,1044.06,,59.3933,1.04406,,,,7.85398e-5
Test1,1-Recover,30.667,1.266,1.8,0.075,,0.587084,954.93,,58.7084,0.95493,,,,7.85398e-5
Test1,1-Recover,31.000,1.286,1.78,0.082,,0.580561,1044.06,,58.0561,1.04406,,,,7.85398e-5
Test1,1-Recover,31.333,1.306,1.76,0.082,,0.574038,1044.06,,57.4038,1.04406,,,,7.85398e-5
Test1,1-Recover,31.667,1.327,1.739,0.082,,0.567189,1044.06,,56.7189,1.04406,,,,7.85398e-5
Test1,1-Recover,32.000,1.347,1.719,0.082,,0.560665,1044.06,,56.0665,1.04406,,,,7.85398e-5
Test1,1-Recover,32.333,1.368,1.698,0.082,,0.553816,1044.06,,55.3816,1.04406,,,,7.85398e-5
Test1,1-Recover,32.667,1.389,1.677,0.061,,0.546967,776.676,,54.6967,0.776676,,,,7.85398e-5
Test1,1-Recover,33.000,1.409,1.657,0.075,,0.540444,954.93,,54.0444,0.95493,,,,7.85398e-5
Test1,1-Recover,33.333,1.429,1.637,0.061,,0.53392,776.676,,53.392,0.776676,,,,7.85398e-5
Test1,1-Recover,33.667,1.45,1.616,0.048,,0.527071,611.155,,52.7071,0.611155,,,,7.85398e-5
Test1,1-Recover,34.000,1.47,1.596,0.054,,0.520548,687.549,,52.0548,0.687549,,,,7.85398e-5
Test1,1-Recover,34.333,1.491,1.575,0.034,,0.513699,432.902,,51.3699,0.432902,,,,7.85398e-5
Test1,1-Recover,34.667,1.512,1.554,0.034,,0.506849,432.902,,50.6849,0.432902,,,,7.85398e-5
Test1,1-Recover,35.000,1.532,1.534,0.034,,0.500326,432.902,,50.0326,0.432902,,,,7.85398e-5
Test1,1-Recover,35.333,1.552,1.514,0.034,,0.493803,432.902,,49.3803,0.432902,,,,7.85398e-5
Test1,1-Recover,35.667,1.573,1.493,0.034,,0.486954,432.902,,48.6954,0.432902,,,,7.85398e-5
Test1,1-Recover,36.000,1.593,1.473,0.034,,0.480431,432.902,,48.0431,0.432902,,,,7.85398e-5
Test1,1-Recover,36.333,1.613,1.453,0.034,,0.473907,432.902,,47.3907,0.432902,,,,7.85398e-5
Test1,1-Recover,36.667,1.634,1.432,0.027,,0.467058,343.775,,46.7058,0.343775,,,,7.85398e-5
Test1,1-Recover,37.000,1.655,1.411,0.027,,0.460209,343.775,,46.0209,0.343775,,,,7.85398e-5
Test1,1-Recover,37.333,1.675,1.391,0.027,,0.453686,343.775,,45.3686,0.343775,,,,7.85398e-5
Test1,1-Recover,37.667,1.696,1.37,0.027,,0.446836,343.775,,44.6836,0.343775,,,,7.85398e-5
Test1,1-Recover,38.000,1.716,1.35,0.027,,0.440313,343.775,,44.0313,0.343775,,,,7.85398e-5
Test1,1-Recover,38.333,1.736,1.33,0.034,,0.43379,432.902,,43.379,0.432902,,,,7.85398e-5
Test1,1-Recover,38.667,1.757,1.309,0.027,,0.426941,343.775,,42.6941,0.343775,,,,7.85398e-5
Test1,1-Recover,39.000,1.778,1.288,0.027,,0.420091,343.775,,42.0091,0.343775,,,,7.85398e-5
Test1,1-Recover,39.333,1.798,1.268,0.027,,0.413568,343.775,,41.3568,0.343775,,,,7.85398e-5
Test1,1-Recover,39.667,1.819,1.247,0.027,,0.406719,343.775,,40.6719,0.343775,,,,7.85398e-5
Test1,1-Recover,40.000,1.839,1.227,0.027,,0.400196,343.775,,40.0196,0.343775,,,,7.85398e-5
Test1,1-Recover,40.333,1.859,1.207,0.027,,0.393673,343.775,,39.3673,0.343775,,,,7.85398e-5
Test1,1-Recover,40.667,1.88,1.186,0.027,,0.386823,343.775,,38.6823,0.343775,,,,7.85398e-5
Test1,1-Recover,41.000,1.9,1.166,0.027,,0.3803,343.775,,38.03,0.343775,,,,7.85398e-5
Test1,1-Recover,41.333,1.921,1.145,0.027,,0.373451,343.775,,37.3451,0.343775,,,,7.85398e-5
Test1,1-Recover,41.667,1.941,1.125,0.027,,0.366928,343.775,,36.6928,0.343775,,,,7.85398e-5
Test1,1-Recover,42.000,1.962,1.104,0.027,,0.360078,343.775,,36.0078,0.343775,,,,7.85398e-5
Test1,1-Recover,42.333,1.982,1.084,0.027,,0.353555,343.775,,35.3555,0.343775,,,,7.85398e-5
Test1,1-Recover,42.667,2.003,1.063,0.020,,0.346706,254.648,,34.6706,0.254648,,,,7.85398e-5
Test1,1-Recover,43.000,2.023,1.043,0.027,,0.340183,343.775,,34.0183,0.343775,,,,7.85398e-5
Test1,1-Recover,43.333,2.044,1.022,0.007,,0.333333,89.1268,,33.3333,0.0891268,,,,7.85398e-5
Test1,1-Recover,43.667,2.064,1.002,0.020,,0.32681,254.648,,32.681,0.254648,,,,7.85398e-5
Test1,1-Recover,44.000,2.085,0.981,0.020,,0.319961,254.648,,31.9961,0.254648,,,,7.85398e-5
Test1,1-Recover,44.333,2.105,0.961,0.020,,0.313438,254.648,,31.3438,0.254648,,,,7.85398e-5
Test1,1-Recover,44.667,2.126,0.94,0.014,,0.306588,178.254,,30.6588,0.178254,,,,7.85398e-5
Test1,1-Recover,45.000,2.146,0.92,-0.014,,0.300065,-178.254,,30.0065,-0.178254,,,,7.85398e-5
Test1,1-Recover,45.333,2.166,0.9,-0.007,,0.293542,-89.1268,,29.3542,-0.0891268,,,,7.85398e-5
Test1,1-Recover,45.667,2.187,0.879,0.007,,0.286693,89.1268,,28.6693,0.0891268,,,,7.85398e-5
Test1,1-Recover,46.000,2.207,0.859,0.007,,0.28017,89.1268,,28.017,0.0891268,,,,7.85398e-5
Test1,1-Recover,46.333,2.228,0.838,0.007,,0.27332,89.1268,,27.332,0.0891268,,,,7.85398e-5
Test1,1-Recover,46.667,2.248,0.818,0.000,,0.266797,0,,26.6797,0,,,,7.85398e-5
Test1,1-Recover,47.000,2.269,0.797,0.014,,0.259948,178.254,,25.9948,0.178254,,,,7.85398e-5
Test1,1-Recover,47.333,2.289,0.777,0.000,,0.253425,0,,25.3425,0,,,,7.85398e-5
Test1,1-Recover,47.667,2.31,0.756,-0.007,,0.246575,-89.1268,,24.6575,-0.0891268,,,,7.85398e-5
Test1,1-Recover,48.000,2.33,0.736,0.000,,0.240052,0,,24.0052,0,,,,7.85398e-5
Test1,1-Recover,48.333,2.351,0.715,0.000,,0.233203,0,,23.3203,0,,,,7.85398e-5
Test1,1-Recover,48.667,2.371,0.695,-0.014,,0.22668,-178.254,,22.668,-0.178254,,,,7.85398e-5
Test1,1-Recover,49.000,2.392,0.674,-0.014,,0.21983,-178.254,,21.983,-0.178254,,,,7.85398e-5
Test1,1-Recover,49.333,2.412,0.654,-0.020,,0.213307,-254.648,,21.3307,-0.254648,,,,7.85398e-5
Test1,1-Recover,49.667,2.433,0.633,-0.007,,0.206458,-89.1268,,20.6458,-0.0891268,,,,7.85398e-5
Test1,1-Recover,50.000,2.453,0.613,-0.014,,0.199935,-178.254,,19.9935,-0.178254,,,,7.85398e-5
Test1,1-Recover,50.333,2.473,0.593,-0.020,,0.193412,-254.648,,19.3412,-0.254648,,,,7.85398e-5
Test1,1-Recover,50.667,2.494,0.572,-0.020,,0.186562,-254.648,,18.6562,-0.254648,,,,7.85398e-5
Test1,1-Recover,51.000,2.514,0.552,-0.020,,0.180039,-254.648,,18.0039,-0.254648,,,,7.85398e-5
Test1,1-Recover,51.333,2.535,0.531,-0.020,,0.17319,-254.648,,17.319,-0.254648,,,,7.85398e-5
Test1,1-Recover,51.667,2.556,0.51,-0.020,,0.166341,-254.648,,16.6341,-0.254648,,,,7.85398e-5
Test1,1-Recover,52.000,2.576,0.49,-0.027,,0.159817,-343.775,,15.9817,-0.343775,,,,7.85398e-5
Test1,1-Recover,52.333,2.596,0.47,-0.020,,0.153294,-254.648,,15.3294,-0.254648,,,,7.85398e-5
Test1,1-Recover,52.667,2.617,0.449,-0.020,,0.146445,-254.648,,14.6445,-0.254648,,,,7.85398e-5
Test1,1-Recover,53.000,2.637,0.429,-0.020,,0.139922,-254.648,,13.9922,-0.254648,,,,7.85398e-5
Test1,1-Recover,53.333,2.657,0.409,-0.020,,0.133399,-254.648,,13.3399,-0.254648,,,,7.85398e-5
Test1,1-Recover,53.667,2.679,0.387,-0.014,,0.126223,-178.254,,12.6223,-0.178254,,,,7.85398e-5
Test1,1-Recover,54.000,2.699,0.367,-0.014,,0.1197,-178.254,,11.97,-0.178254,,,,7.85398e-5
Test1,1-Recover,54.333,2.719,0.347,-0.014,,0.113177,-178.254,,11.3177,-0.178254,,,,7.85398e-5
Test1,1-Recover,54.667,2.74,0.326,-0.014,,0.106327,-178.254,,10.6327,-0.178254,,,,7.85398e-5
Test1,1-Recover,55.000,2.76,0.306,-0.014,,0.0998043,-178.254,,9.98043,-0.178254,,,,7.85398e-5
Test1,1-Recover,55.333,2.78,0.286,-0.014,,0.0932811,-178.254,,9.32811,-0.178254,,,,7.85398e-5
Test1,1-Recover,55.667,2.801,0.265,-0.020,,0.0864318,-254.648,,8.64318,-0.254648,,,,7.85398e-5
Test1,1-Recover,56.000,2.822,0.244,-0.020,,0.0795825,-254.648,,7.95825,-0.254648,,,,7.85398e-5
Test1,1-Recover,56.333,2.842,0.224,-0.027,,0.0730594,-343.775,,7.30594,-0.343775,,,,7.85398e-5
Test1,1-Recover,56.667,2.863,0.203,-0.027,,0.06621,-343.775,,6.621,-0.343775,,,,7.85398e-5
Test1,1-Recover,57.000,2.883,0.183,-0.027,,0.0596869,-343.775,,5.96869,-0.343775,,,,7.85398e-5
Test1,1-Recover,57.333,2.903,0.163,-0.027,,0.0531637,-343.775,,5.31637,-0.343775,,,,7.85398e-5
Test1,1-Recover,57.667,2.924,0.142,-0.027,,0.0463144,-343.775,,4.63144,-0.343775,,,,7.85398e-5
Test1,1-Recover,58.000,2.945,0.121,-0.027,,0.0394651,-343.775,,3.94651,-0.343775,,,,7.85398e-5
Test1,1-Recover,58.333,2.965,0.101,-0.027,,0.0329419,-343.775,,3.29419,-0.343775,,,,7.85398e-5
Test1,1-Recover,58.667,2.986,0.08,-0.027,,0.0260926,-343.775,,2.60926,-0.343775,,,,7.85398e-5
Test1,1-Recover,59.000,3.006,0.06,-0.027,,0.0195695,-343.775,,1.95695,-0.343775,,,,7.85398e-5
Test1,1-Recover,59.333,3.026,0.04,-0.027,,0.0130463,-343.775,,1.30463,-0.343775,,,,7.85398e-5
Test1,1-Recover,59.667,3.047,0.019,-0.027,,0.006197,-343.775,,0.6197,-0.343775,,,,7.85398e-5
Test1,1-Recover,60.000,3.066,-0,-0.027,,0,-343.775,,0,-0.343775,,,,7.85398e-5
Test1,2-Compress,60.317,3.049,0.017,-0.027,,0.00554468,-343.775,,0.554468,-0.343775,,,,7.85398e-5
Test1,2-Compress,60.650,3.028,0.038,-0.020,,0.012394,-254.648,,1.2394,-0.254648,,,,7.85398e-5
Test1,2-Compress,60.983,3.008,0.058,-0.020,,0.0189172,-254.648,,1.89172,-0.254648,,,,7.85398e-5
Test1,2-Compress,61.317,2.987,0.079,-0.020,,0.0257665,-254.648,,2.57665,-0.254648,,,,7.85398e-5
Test1,2-Compress,61.650,2.967,0.099,-0.020,,0.0322896,-254.648,,3.22896,-0.254648,,,,7.85398e-5
Test1,2-Compress,61.983,2.947,0.119,-0.020,,0.0388128,-254.648,,3.88128,-0.254648,,,,7.85398e-5
Test1,2-Compress,62.317,2.926,0.14,-0.014,,0.0456621,-178.254,,4.56621,-0.178254,,,,7.85398e-5
Test1,2-Compress,62.650,2.906,0.16,-0.020,,0.0521853,-254.648,,5.21853,-0.254648,,,,7.85398e-5
Test1,2-Compress,62.983,2.885,0.181,-0.020,,0.0590346,-254.648,,5.90346,-0.254648,,,,7.85398e-5
Test1,2-Compress,63.317,2.865,0.201,-0.014,,0.0655577,-178.254,,6.55577,-0.178254,,,,7.85398e-5
Test1,2-Compress,63.650,2.844,0.222,-0.014,,0.072407,-178.254,,7.2407,-0.178254,,,,7.85398e-5
Test1,2-Compress,63.983,2.824,0.242,-0.020,,0.0789302,-254.648,,7.89302,-0.254648,,,,7.85398e-5
Test1,2-Compress,64.317,2.803,0.263,-0.020,,0.0857795,-254.648,,8.57795,-0.254648,,,,7.85398e-5
Test1,2-Compress,64.650,2.783,0.283,-0.020,,0.0923027,-254.648,,9.23027,-0.254648,,,,7.85398e-5
Test1,2-Compress,64.983,2.762,0.304,-0.014,,0.099152,-178.254,,9.9152,-0.178254,,,,7.85398e-5
Test1,2-Compress,65.317,2.742,0.324,-0.027,,0.105675,-343.775,,10.5675,-0.343775,,,,7.85398e-5
Test1,2-Compress,65.650,2.722,0.344,-0.020,,0.112198,-254.648,,11.2198,-0.254648,,,,7.85398e-5
Test1,2-Compress,65.983,2.701,0.365,-0.014,,0.119048,-178.254,,11.9048,-0.178254,,,,7.85398e-5
Test1,2-Compress,66.317,2.68,0.386,-0.020,,0.125897,-254.648,,12.5897,-0.254648,,,,7.85398e-5
Test1,2-Compress,66.650,2.66,0.406,-0.020,,0.13242,-254.648,,13.242,-0.254648,,,,7.85398e-5
Test1,2-Compress,66.983,2.64,0.426,-0.014,,0.138943,-178.254,,13.8943,-0.178254,,,,7.85398e-5
Test1,2-Compress,67.317,2.619,0.447,-0.014,,0.145793,-178.254,,14.5793,-0.178254,,,,7.85398e-5
Test1,2-Compress,67.650,2.599,0.467,-0.014,,0.152316,-178.254,,15.2316,-0.178254,,,,7.85398e-5
Test1,2-Compress,67.983,2.578,0.488,-0.014,,0.159165,-178.254,,15.9165,-0.178254,,,,7.85398e-5
Test1,2-Compress,68.317,2.557,0.509,-0.020,,0.166014,-254.648,,16.6014,-0.254648,,,,7.85398e-5
Test1,2-Compress,68.650,2.537,0.529,0.000,,0.172538,0,,17.2538,0,,,,7.85398e-5
Test1,2-Compress,68.983,2.517,0.549,0.007,,0.179061,89.1268,,17.9061,0.0891268,,,,7.85398e-5
Test1,2-Compress,69.317,2.496,0.57,0.000,,0.18591,0,,18.591,0,,,,7.85398e-5
Test1,2-Compress,69.650,2.476,0.59,-0.014,,0.192433,-178.254,,19.2433,-0.178254,,,,7.85398e-5
Test1,2-Compress,69.983,2.456,0.61,-0.007,,0.198956,-89.1268,,19.8956,-0.0891268,,,,7.85398e-5
Test1,2-Compress,70.317,2.434,0.632,0.020,,0.206132,254.648,,20.6132,0.254648,,,,7.85398e-5
Test1,2-Compress,70.650,2.414,0.652,-0.007,,0.212655,-89.1268,,21.2655,-0.0891268,,,,7.85398e-5
Test1,2-Compress,70.983,2.394,0.672,0.027,,0.219178,343.775,,21.9178,0.343775,,,,7.85398e-5
Test1,2-Compress,71.317,2.373,0.693,0.007,,0.226027,89.1268,,22.6027,0.0891268,,,,7.85398e-5
Test1,2-Compress,71.650,2.353,0.713,0.027,,0.232551,343.775,,23.2551,0.343775,,,,7.85398e-5
Test1,2-Compress,71.983,2.333,0.733,0.027,,0.239074,343.775,,23.9074,0.343775,,,,7.85398e-5
Test1,2-Compress,72.317,2.312,0.754,0.027,,0.245923,343.775,,24.5923,0.343775,,,,7.85398e-5
Test1,2-Compress,72.650,2.292,0.774,0.027,,0.252446,343.775,,25.2446,0.343775,,,,7.85398e-5
Test1,2-Compress,72.983,2.271,0.795,0.027,,0.259295,343.775,,25.9295,0.343775,,,,7.85398e-5
Test1,2-Compress,73.317,2.25,0.816,0.027,,0.266145,343.775,,26.6145,0.343775,,,,7.85398e-5
Test1,2-Compress,73.650,2.23,0.836,0.027,,0.272668,343.775,,27.2668,0.343775,,,,7.85398e-5
Test1,2-Compress,73.983,2.21,0.856,0.027,,0.279191,343.775,,27.9191,0.343775,,,,7.85398e-5
Test1,2-Compress,74.317,2.189,0.877,0.027,,0.28604,343.775,,28.604,0.343775,,,,7.85398e-5
Test1,2-Compress,74.650,2.168,0.898,0.027,,0.29289,343.775,,29.289,0.343775,,,,7.85398e-5
Test1,2-Compress,74.983,2.149,0.917,0.027,,0.299087,343.775,,29.9087,0.343775,,,,7.85398e-5
Test1,2-Compress,75.317,2.128,0.938,0.027,,0.305936,343.775,,30.5936,0.343775,,,,7.85398e-5
Test1,2-Compress,75.650,2.107,0.959,0.027,,0.312785,343.775,,31.2785,0.343775,,,,7.85398e-5
Test1,2-Compress,75.983,2.087,0.979,0.027,,0.319309,343.775,,31.9309,0.343775,,,,7.85398e-5
Test1,2-Compress,76.317,2.066,1,0.027,,0.326158,343.775,,32.6158,0.343775,,,,7.85398e-5
Test1,2-Compress,76.650,2.046,1.02,0.027,,0.332681,343.775,,33.2681,0.343775,,,,7.85398e-5
Test1,2-Compress,76.983,2.026,1.04,0.027,,0.339204,343.775,,33.9204,0.343775,,,,7.85398e-5
Test1,2-Compress,77.317,2.005,1.061,0.034,,0.346053,432.902,,34.6053,0.432902,,,,7.85398e-5
Test1,2-Compress,77.650,1.984,1.082,0.027,,0.352903,343.775,,35.2903,0.343775,,,,7.85398e-5
Test1,2-Compress,77.983,1.964,1.102,0.027,,0.359426,343.775,,35.9426,0.343775,,,,7.85398e-5
Test1,2-Compress,78.317,1.943,1.123,0.027,,0.366275,343.775,,36.6275,0.343775,,,,7.85398e-5
Test1,2-Compress,78.650,1.923,1.143,0.027,,0.372798,343.775,,37.2798,0.343775,,,,7.85398e-5
Test1,2-Compress,78.983,1.902,1.164,0.027,,0.379648,343.775,,37.9648,0.343775,,,,7.85398e-5
Test1,2-Compress,79.317,1.882,1.184,0.034,,0.386171,432.902,,38.6171,0.432902,,,,7.85398e-5
Test1,2-Compress,79.650,1.862,1.204,0.027,,0.392694,343.775,,39.2694,0.343775,,,,7.85398e-5
Test1,2-Compress,79.983,1.841,1.225,0.027,,0.399543,343.775,,39.9543,0.343775,,,,7.85398e-5
Test1,2-Compress,80.317,1.821,1.245,0.034,,0.406067,432.902,,40.6067,0.432902,,,,7.85398e-5
Test1,2-Compress,80.650,1.8,1.266,0.027,,0.412916,343.775,,41.2916,0.343775,,,,7.85398e-5
Test1,2-Compress,80.983,1.78,1.286,0.034,,0.419439,432.902,,41.9439,0.432902,,,,7.85398e-5
Test1,2-Compress,81.317,1.759,1.307,0.034,,0.426288,432.902,,42.6288,0.432902,,,,7.85398e-5
Test1,2-Compress,81.650,1.739,1.327,0.027,,0.432811,343.775,,43.2811,0.343775,,,,7.85398e-5
Test1,2-Compress,81.983,1.718,1.348,0.041,,0.439661,522.028,,43.9661,0.522028,,,,7.85398e-5
Test1,2-Compress,82.317,1.698,1.368,0.041,,0.446184,522.028,,44.6184,0.522028,,,,7.85398e-5
Test1,2-Compress,82.650,1.677,1.389,0.041,,0.453033,522.028,,45.3033,0.522028,,,,7.85398e-5
Test1,2-Compress,82.983,1.657,1.409,0.041,,0.459556,522.028,,45.9556,0.522028,,,,7.85398e-5
Test1,2-Compress,83.317,1.636,1.43,0.048,,0.466406,611.155,,46.6406,0.611155,,,,7.85398e-5
Test1,2-Compress,83.650,1.616,1.45,0.041,,0.472929,522.028,,47.2929,0.522028,,,,7.85398e-5
Test1,2-Compress,83.983,1.596,1.47,0.041,,0.479452,522.028,,47.9452,0.522028,,,,7.85398e-5
Test1,2-Compress,84.317,1.575,1.491,0.034,,0.486301,432.902,,48.6301,0.432902,,,,7.85398e-5
Test1,2-Compress,84.650,1.555,1.511,0.054,,0.492825,687.549,,49.2825,0.687549,,,,7.85398e-5
Test1,2-Compress,84.983,1.534,1.532,0.048,,0.499674,611.155,,49.9674,0.611155,,,,7.85398e-5
Test1,2-Compress,85.317,1.513,1.553,0.054,,0.506523,687.549,,50.6523,0.687549,,,,7.85398e-5
Test1,2-Compress,85.650,1.493,1.573,0.082,,0.513046,1044.06,,51.3046,1.04406,,,,7.85398e-5
Test1,2-Compress,85.983,1.473,1.593,0.075,,0.519569,954.93,,51.9569,0.95493,,,,7.85398e-5
Test1,2-Compress,86.317,1.452,1.614,0.061,,0.526419,776.676,,52.6419,0.776676,,,,7.85398e-5
Test1,2-Compress,86.650,1.432,1.634,0.068,,0.532942,865.803,,53.2942,0.865803,,,,7.85398e-5
Test1,2-Compress,86.983,1.411,1.655,0.082,,0.539791,1044.06,,53.9791,1.04406,,,,7.85398e-5
Test1,2-Compress,87.317,1.39,1.676,0.068,,0.546641,865.803,,54.6641,0.865803,,,,7.85398e-5
Test1,2-Compress,87.650,1.37,1.696,0.075,,0.553164,954.93,,55.3164,0.95493,,,,7.85398e-5
Test1,2-Compress,87.983,1.35,1.716,0.082,,0.559687,1044.06,,55.9687,1.04406,,,,7.85398e-5
Test1,2-Compress,88.317,1.329,1.737,0.082,,0.566536,1044.06,,56.6536,1.04406,,,,7.85398e-5
Test1,2-Compress,88.650,1.309,1.757,0.082,,0.573059,1044.06,,57.3059,1.04406,,,,7.85398e-5
Test1,2-Compress,88.983,1.289,1.777,0.082,,0.579583,1044.06,,57.9583,1.04406,,,,7.85398e-5
Test1,2-Compress,89.317,1.268,1.798,0.082,,0.586432,1044.06,,58.6432,1.04406,,,,7.85398e-5
Test1,2-Compress,89.650,1.247,1.819,0.082,,0.593281,1044.06,,59.3281,1.04406,,,,7.85398e-5
Test1,2-Compress,89.983,1.227,1.839,0.082,,0.599804,1044.06,,59.9804,1.04406,,,,7.85398e-5
Test1,2-Recover,90.303,1.241,1.825,0.082,,0.595238,1044.06,,59.5238,1.04406,,,,7.85398e-5
Test1,2-Recover,90.637,1.262,1.804,0.082,,0.588389,1044.06,,58.8389,1.04406,,,,7.85398e-5
Test1,2-Recover,90.970,1.282,1.784,0.082,,0.581866,1044.06,,58.1866,1.04406,,,,7.85398e-5
Test1,2-Recover,91.303,1.302,1.764,0.082,,0.575342,1044.06,,57.5342,1.04406,,,,7.85398e-5
Test1,2-Recover,91.637,1.323,1.743,0.082,,0.568493,1044.06,,56.8493,1.04406,,,,7.85398e-5
Test1,2-Recover,91.970,1.343,1.723,0.082,,0.56197,1044.06,,56.197,1.04406,,,,7.85398e-5
Test1,2-Recover,92.303,1.364,1.702,0.082,,0.555121,1044.06,,55.5121,1.04406,,,,7.85398e-5
Test1,2-Recover,92.637,1.384,1.682,0.068,,0.548598,865.803,,54.8598,0.865803,,,,7.85398e-5
Test1,2-Recover,92.970,1.405,1.661,0.048,,0.541748,611.155,,54.1748,0.611155,,,,7.85398e-5
Test1,2-Recover,93.303,1.425,1.641,0.034,,0.535225,432.902,,53.5225,0.432902,,,,7.85398e-5
Test1,2-Recover,93.637,1.446,1.62,0.027,,0.528376,343.775,,52.8376,0.343775,,,,7.85398e-5
Test1,2-Recover,93.970,1.466,1.6,0.034,,0.521853,432.902,,52.1853,0.432902,,,,7.85398e-5
Test1,2-Recover,94.303,1.487,1.579,0.027,,0.515003,343.775,,51.5003,0.343775,,,,7.85398e-5
Test1,2-Recover,94.637,1.507,1.559,0.041,,0.50848,522.028,,50.848,0.522028,,,,7.85398e-5
Test1,2-Recover,94.970,1.528,1.538,0.034,,0.501631,432.902,,50.1631,0.432902,,,,7.85398e-5
Test1,2-Recover,95.303,1.548,1.518,0.034,,0.495108,432.902,,49.5108,0.432902,,,,7.85398e-5
Test1,2-Recover,95.637,1.569,1.497,0.034,,0.488258,432.902,,48.8258,0.432902,,,,7.85398e-5
Test1,2-Recover,95.970,1.589,1.477,0.041,,0.481735,522.028,,48.1735,0.522028,,,,7.85398e-5
Test1,2-Recover,96.303,1.609,1.457,0.041,,0.475212,522.028,,47.5212,0.522028,,,,7.85398e-5
Test1,2-Recover,96.637,1.63,1.436,0.041,,0.468363,522.028,,46.8363,0.522028,,,,7.85398e-5
Test1,2-Recover,96.970,1.65,1.416,0.027,,0.46184,343.775,,46.184,0.343775,,,,7.85398e-5
Test1,2-Recover,97.303,1.671,1.395,0.027,,0.45499,343.775,,45.499,0.343775,,,,7.85398e-5
Test1,2-Recover,97.637,1.692,1.374,0.027,,0.448141,343.775,,44.8141,0.343775,,,,7.85398e-5
Test1,2-Recover,97.970,1.712,1.354,0.027,,0.441618,343.775,,44.1618,0.343775,,,,7.85398e-5
Test1,2-Recover,98.303,1.732,1.334,0.027,,0.435095,343.775,,43.5095,0.343775,,,,7.85398e-5
Test1,2-Recover,98.637,1.753,1.313,0.027,,0.428245,343.775,,42.8245,0.343775,,,,7.85398e-5
Test1,2-Recover,98.970,1.773,1.293,0.027,,0.421722,343.775,,42.1722,0.343775,,,,7.85398e-5
Test1,2-Recover,99.303,1.794,1.272,0.027,,0.414873,343.775,,41.4873,0.343775,,,,7.85398e-5
Test1,2-Recover,99.637,1.815,1.251,0.027,,0.408023,343.775,,40.8023,0.343775,,,,7.85398e-5
Test1,2-Recover,99.970,1.834,1.232,0.027,,0.401826,343.775,,40.1826,0.343775,,,,7.85398e-5
Test1,2-Recover,100.303,1.855,1.211,0.027,,0.394977,343.775,,39.4977,0.343775,,,,7.85398e-5
Test1,2-Recover,100.637,1.876,1.19,0.027,,0.388128,343.775,,38.8128,0.343775,,,,7.85398e-5
Test1,2-Recover,100.970,1.896,1.17,0.027,,0.381605,343.775,,38.1605,0.343775,,,,7.85398e-5
Test1,2-Recover,101.303,1.916,1.15,0.027,,0.375082,343.775,,37.5082,0.343775,,,,7.85398e-5
Test1,2-Recover,101.637,1.937,1.129,0.027,,0.368232,343.775,,36.8232,0.343775,,,,7.85398e-5
Test1,2-Recover,101.970,1.958,1.108,0.027,,0.361383,343.775,,36.1383,0.343775,,,,7.85398e-5
Test1,2-Recover,102.303,1.978,1.088,0.027,,0.35486,343.775,,35.486,0.343775,,,,7.85398e-5
Test1,2-Recover,102.637,1.999,1.067,0.027,,0.34801,343.775,,34.801,0.343775,,,,7.85398e-5
Test1,2-Recover,102.970,2.019,1.047,0.014,,0.341487,178.254,,34.1487,0.178254,,,,7.85398e-5
Test1,2-Recover,103.303,2.039,1.027,0.014,,0.334964,178.254,,33.4964,0.178254,,,,7.85398e-5
Test1,2-Recover,103.637,2.06,1.006,0.027,,0.328115,343.775,,32.8115,0.343775,,,,7.85398e-5
Test1,2-Recover,103.970,2.081,0.985,0.020,,0.321265,254.648,,32.1265,0.254648,,,,7.85398e-5
Test1,2-Recover,104.303,2.1,0.966,0.014,,0.315068,178.254,,31.5068,0.178254,,,,7.85398e-5
Test1,2-Recover,104.637,2.122,0.944,0.027,,0.307893,343.775,,30.7893,0.343775,,,,7.85398e-5
Test1,2-Recover,104.970,2.142,0.924,0.014,,0.30137,178.254,,30.137,0.178254,,,,7.85398e-5
Test1,2-Recover,105.303,2.162,0.904,0.014,,0.294847,178.254,,29.4847,0.178254,,,,7.85398e-5
Test1,2-Recover,105.637,2.183,0.883,0.007,,0.287997,89.1268,,28.7997,0.0891268,,,,7.85398e-5
Test1,2-Recover,105.970,2.203,0.863,0.000,,0.281474,0,,28.1474,0,,,,7.85398e-5
Test1,2-Recover,106.303,2.224,0.842,0.000,,0.274625,0,,27.4625,0,,,,7.85398e-5
Test1,2-Recover,106.637,2.244,0.822,0.000,,0.268102,0,,26.8102,0,,,,7.85398e-5
Test1,2-Recover,106.970,2.265,0.801,0.007,,0.261252,89.1268,,26.1252,0.0891268,,,,7.85398e-5
Test1,2-Recover,107.303,2.285,0.781,-0.007,,0.254729,-89.1268,,25.4729,-0.0891268,,,,7.85398e-5
Test1,2-Recover,107.637,2.306,0.76,-0.014,,0.24788,-178.254,,24.788,-0.178254,,,,7.85398e-5
Test1,2-Recover,107.970,2.326,0.74,-0.014,,0.241357,-178.254,,24.1357,-0.178254,,,,7.85398e-5
Test1,2-Recover,108.303,2.346,0.72,-0.020,,0.234834,-254.648,,23.4834,-0.254648,,,,7.85398e-5
Test1,2-Recover,108.637,2.367,0.699,-0.020,,0.227984,-254.648,,22.7984,-0.254648,,,,7.85398e-5
Test1,2-Recover,108.970,2.388,0.678,-0.020,,0.221135,-254.648,,22.1135,-0.254648,,,,7.85398e-5
Test1,2-Recover,109.303,2.408,0.658,-0.020,,0.214612,-254.648,,21.4612,-0.254648,,,,7.85398e-5
Test1,2-Recover,109.637,2.428,0.638,-0.020,,0.208089,-254.648,,20.8089,-0.254648,,,,7.85398e-5
Test1,2-Recover,109.970,2.449,0.617,-0.020,,0.201239,-254.648,,20.1239,-0.254648,,,,7.85398e-5
Test1,2-Recover,110.303,2.469,0.597,-0.020,,0.194716,-254.648,,19.4716,-0.254648,,,,7.85398e-5
Test1,2-Recover,110.637,2.49,0.576,-0.014,,0.187867,-178.254,,18.7867,-0.178254,,,,7.85398e-5
Test1,2-Recover,110.970,2.51,0.556,-0.014,,0.181344,-178.254,,18.1344,-0.178254,,,,7.85398e-5
Test1,2-Recover,111.303,2.531,0.535,-0.007,,0.174494,-89.1268,,17.4494,-0.0891268,,,,7.85398e-5
Test1,2-Recover,111.637,2.551,0.515,-0.014,,0.167971,-178.254,,16.7971,-0.178254,,,,7.85398e-5
Test1,2-Recover,111.970,2.572,0.494,-0.020,,0.161122,-254.648,,16.1122,-0.254648,,,,7.85398e-5
Test1,2-Recover,112.303,2.592,0.474,-0.007,,0.154599,-89.1268,,15.4599,-0.0891268,,,,7.85398e-5
Test1,2-Recover,112.637,2.613,0.453,-0.014,,0.14775,-178.254,,14.775,-0.178254,,,,7.85398e-5
Test1,2-Recover,112.970,2.633,0.433,-0.014,,0.141226,-178.254,,14.1226,-0.178254,,,,7.85398e-5
Test1,2-Recover,113.303,2.654,0.412,-0.020,,0.134377,-254.648,,13.4377,-0.254648,,,,7.85398e-5
Test1,2-Recover,113.637,2.674,0.392,-0.027,,0.127854,-343.775,,12.7854,-0.343775,,,,7.85398e-5
Test1,2-Recover,113.970,2.694,0.372,-0.020,,0.121331,-254.648,,12.1331,-0.254648,,,,7.85398e-5
Test1,2-Recover,114.303,2.715,0.351,-0.027,,0.114481,-343.775,,11.4481,-0.343775,,,,7.85398e-5
Test1,2-Recover,114.637,2.736,0.33,-0.027,,0.107632,-343.775,,10.7632,-0.343775,,,,7.85398e-5
Test1,2-Recover,114.970,2.756,0.31,-0.027,,0.101109,-343.775,,10.1109,-0.343775,,,,7.85398e-5
Test1,2-Recover,115.303,2.776,0.29,-0.020,,0.0945858,-254.648,,9.45858,-0.254648,,,,7.85398e-5
Test1,2-Recover,115.637,2.797,0.269,-0.020,,0.0877365,-254.648,,8.77365,-0.254648,,,,7.85398e-5
Test1,2-Recover,115.970,2.817,0.249,-0.027,,0.0812133,-343.775,,8.12133,-0.343775,,,,7.85398e-5
Test1,2-Recover,116.303,2.838,0.228,-0.027,,0.074364,-343.775,,7.4364,-0.343775,,,,7.85398e-5
Test1,2-Recover,116.637,2.859,0.207,-0.027,,0.0675147,-343.775,,6.75147,-0.343775,,,,7.85398e-5
Test1,2-Recover,116.970,2.879,0.187,-0.020,,0.0609915,-254.648,,6.09915,-0.254648,,,,7.85398e-5
Test1,2-Recover,117.303,2.899,0.167,-0.020,,0.0544684,-254.648,,5.44684,-0.254648,,,,7.85398e-5
Test1,2-Recover,117.637,2.92,0.146,-0.020,,0.047619,-254.648,,4.7619,-0.254648,,,,7.85398e-5
Test1,2-Recover,117.970,2.94,0.126,-0.020,,0.0410959,-254.648,,4.10959,-0.254648,,,,7.85398e-5
Test1,2-Recover,118.303,2.96,0.106,-0.020,,0.0345727,-254.648,,3.45727,-0.254648,,,,7.85398e-5
Test1,2-Recover,118.637,2.982,0.084,-0.014,,0.0273973,-178.254,,2.73973,-0.178254,,,,7.85398e-5
Test1,2-Recover,118.970,3.002,0.064,-0.014,,0.0208741,-178.254,,2.08741,-0.178254,,,,7.85398e-5
Test1,2-Recover,119.303,3.022,0.044,-0.014,,0.0143509,-178.254,,1.43509,-0.178254,,,,7.85398e-5
Test1,2-Recover,119.637,3.043,0.023,-0.020,,0.00750163,-254.648,,0.750163,-0.254648,,,,7.85398e-5
Test1,2-Recover,119.970,3.063,0.003,-0.027,,0.000978474,-343.775,,0.0978474,-0.343775,,,,7.85398e-5
Test1,3-Compress,120.280,3.053,0.013,-0.020,,0.00424005,-254.648,,0.424005,-0.254648,,,,7.85398e-5
Test1,3-Compress,120.613,3.033,0.033,-0.020,,0.0107632,-254.648,,1.07632,-0.254648,,,,7.85398e-5
Test1,3-Compress,120.947,3.013,0.053,-0.020,,0.0172864,-254.648,,1.72864,-0.254648,,,,7.85398e-5
Test1,3-Compress,121.280,2.992,0.074,-0.027,,0.0241357,-343.775,,2.41357,-0.343775,,,,7.85398e-5
Test1,3-Compress,121.613,2.972,0.094,-0.027,,0.0306588,-343.775,,3.06588,-0.343775,,,,7.85398e-5
Test1,3-Compress,121.947,2.951,0.115,-0.027,,0.0375082,-343.775,,3.75082,-0.343775,,,,7.85398e-5
Test1,3-Compress,122.280,2.931,0.135,-0.027,,0.0440313,-343.775,,4.40313,-0.343775,,,,7.85398e-5
Test1,3-Compress,122.613,2.911,0.155,-0.027,,0.0505545,-343.775,,5.05545,-0.343775,,,,7.85398e-5
Test1,3-Compress,122.947,2.89,0.176,-0.027,,0.0574038,-343.775,,5.74038,-0.343775,,,,7.85398e-5
Test1,3-Compress,123.280,2.869,0.197,-0.027,,0.0642531,-343.775,,6.42531,-0.343775,,,,7.85398e-5
Test1,3-Compress,123.613,2.849,0.217,-0.027,,0.0707763,-343.775,,7.07763,-0.343775,,,,7.85398e-5
Test1,3-Compress,123.947,2.828,0.238,-0.027,,0.0776256,-343.775,,7.76256,-0.343775,,,,7.85398e-5
Test1,3-Compress,124.280,2.808,0.258,-0.027,,0.0841487,-343.775,,8.41487,-0.343775,,,,7.85398e-5
Test1,3-Compress,124.613,2.788,0.278,-0.027,,0.0906719,-343.775,,9.06719,-0.343775,,,,7.85398e-5
Test1,3-Compress,124.947,2.767,0.299,-0.027,,0.0975212,-343.775,,9.75212,-0.343775,,,,7.85398e-5
Test1,3-Compress,125.280,2.747,0.319,-0.027,,0.104044,-343.775,,10.4044,-0.343775,,,,7.85398e-5
Test1,3-Compress,125.613,2.726,0.34,-0.020,,0.110894,-254.648,,11.0894,-0.254648,,,,7.85398e-5
Test1,3-Compress,125.947,2.705,0.361,-0.020,,0.117743,-254.648,,11.7743,-0.254648,,,,7.85398e-5
Test1,3-Compress,126.280,2.685,0.381,-0.020,,0.124266,-254.648,,12.4266,-0.254648,,,,7.85398e-5
Test1,3-Compress,126.613,2.665,0.401,-0.020,,0.130789,-254.648,,13.0789,-0.254648,,,,7.85398e-5
Test1,3-Compress,126.947,2.644,0.422,-0.020,,0.137639,-254.648,,13.7639,-0.254648,,,,7.85398e-5
Test1,3-Compress,127.280,2.624,0.442,-0.014,,0.144162,-178.254,,14.4162,-0.178254,,,,7.85398e-5
Test1,3-Compress,127.613,2.603,0.463,-0.014,,0.151011,-178.254,,15.1011,-0.178254,,,,7.85398e-5
Test1,3-Compress,127.947,2.583,0.483,-0.014,,0.157534,-178.254,,15.7534,-0.178254,,,,7.85398e-5
Test1,3-Compress,128.280,2.562,0.504,0.007,,0.164384,89.1268,,16.4384,0.0891268,,,,7.85398e-5
Test1,3-Compress,128.613,2.542,0.524,0.000,,0.170907,0,,17.0907,0,,,,7.85398e-5
Test1,3-Compress,128.947,2.521,0.545,0.000,,0.177756,0,,17.7756,0,,,,7.85398e-5
Test1,3-Compress,129.280,2.501,0.565,0.000,,0.184279,0,,18.4279,0,,,,7.85398e-5
Test1,3-Compress,129.613,2.481,0.585,0.014,,0.190802,178.254,,19.0802,0.178254,,,,7.85398e-5
Test1,3-Compress,129.947,2.459,0.607,0.020,,0.197978,254.648,,19.7978,0.254648,,,,7.85398e-5
Test1,3-Compress,130.280,2.44,0.626,0.000,,0.204175,0,,20.4175,0,,,,7.85398e-5
Test1,3-Compress,130.613,2.419,0.647,0.000,,0.211024,0,,21.1024,0,,,,7.85398e-5
Test1,3-Compress,130.947,2.398,0.668,0.027,,0.217873,343.775,,21.7873,0.343775,,,,7.85398e-5
Test1,3-Compress,131.280,2.378,0.688,0.020,,0.224397,254.648,,22.4397,0.254648,,,,7.85398e-5
Test1,3-Compress,131.613,2.358,0.708,0.020,,0.23092,254.648,,23.092,0.254648,,,,7.85398e-5
Test1,3-Compress,131.947,2.337,0.729,0.014,,0.237769,178.254,,23.7769,0.178254,,,,7.85398e-5
Test1,3-Compress,132.280,2.317,0.749,0.014,,0.244292,178.254,,24.4292,0.178254,,,,7.85398e-5
Test1,3-Compress,132.613,2.296,0.77,0.027,,0.251142,343.775,,25.1142,0.343775,,,,7.85398e-5
Test1,3-Compress,132.947,2.275,0.791,0.027,,0.257991,343.775,,25.7991,0.343775,,,,7.85398e-5
Test1,3-Compress,133.280,2.255,0.811,0.027,,0.264514,343.775,,26.4514,0.343775,,,,7.85398e-5
Test1,3-Compress,133.613,2.235,0.831,0.027,,0.271037,343.775,,27.1037,0.343775,,,,7.85398e-5
Test1,3-Compress,133.947,2.214,0.852,0.027,,0.277886,343.775,,27.7886,0.343775,,,,7.85398e-5
Test1,3-Compress,134.280,2.194,0.872,0.027,,0.28441,343.775,,28.441,0.343775,,,,7.85398e-5
Test1,3-Compress,134.613,2.174,0.892,0.027,,0.290933,343.775,,29.0933,0.343775,,,,7.85398e-5
Test1,3-Compress,134.947,2.153,0.913,0.027,,0.297782,343.775,,29.7782,0.343775,,,,7.85398e-5
Test1,3-Compress,135.280,2.132,0.934,0.027,,0.304631,343.775,,30.4631,0.343775,,,,7.85398e-5
Test1,3-Compress,135.613,2.112,0.954,0.027,,0.311155,343.775,,31.1155,0.343775,,,,7.85398e-5
Test1,3-Compress,135.947,2.091,0.975,0.027,,0.318004,343.775,,31.8004,0.343775,,,,7.85398e-5
Test1,3-Compress,136.280,2.071,0.995,0.027,,0.324527,343.775,,32.4527,0.343775,,,,7.85398e-5
Test1,3-Compress,136.613,2.051,1.015,0.034,,0.33105,432.902,,33.105,0.432902,,,,7.85398e-5
Test1,3-Compress,136.947,2.03,1.036,0.027,,0.3379,343.775,,33.79,0.343775,,,,7.85398e-5
Test1,3-Compress,137.280,2.009,1.057,0.034,,0.344749,432.902,,34.4749,0.432902,,,,7.85398e-5
Test1,3-Compress,137.613,1.989,1.077,0.027,,0.351272,343.775,,35.1272,0.343775,,,,7.85398e-5
Test1,3-Compress,137.947,1.968,1.098,0.027,,0.358121,343.775,,35.8121,0.343775,,,,7.85398e-5
Test1,3-Compress,138.280,1.948,1.118,0.027,,0.364644,343.775,,36.4644,0.343775,,,,7.85398e-5
Test1,3-Compress,138.613,1.928,1.138,0.027,,0.371168,343.775,,37.1168,0.343775,,,,7.85398e-5
Test1,3-Compress,138.947,1.907,1.159,0.027,,0.378017,343.775,,37.8017,0.343775,,,,7.85398e-5
Test1,3-Compress,139.280,1.887,1.179,0.027,,0.38454,343.775,,38.454,0.343775,,,,7.85398e-5
Test1,3-Compress,139.613,1.866,1.2,0.034,,0.391389,432.902,,39.1389,0.432902,,,,7.85398e-5
Test1,3-Compress,139.947,1.846,1.22,0.034,,0.397913,432.902,,39.7913,0.432902,,,,7.85398e-5
Test1,3-Compress,140.280,1.825,1.241,0.027,,0.404762,343.775,,40.4762,0.343775,,,,7.85398e-5
Test1,3-Compress,140.613,1.805,1.261,0.034,,0.411285,432.902,,41.1285,0.432902,,,,7.85398e-5
Test1,3-Compress,140.947,1.784,1.282,0.034,,0.418134,432.902,,41.8134,0.432902,,,,7.85398e-5
Test1,3-Compress,141.280,1.764,1.302,0.034,,0.424658,432.902,,42.4658,0.432902,,,,7.85398e-5
Test1,3-Compress,141.613,1.743,1.323,0.027,,0.431507,343.775,,43.1507,0.343775,,,,7.85398e-5
Test1,3-Compress,141.947,1.723,1.343,0.034,,0.43803,432.902,,43.803,0.432902,,,,7.85398e-5
Test1,3-Compress,142.280,1.702,1.364,0.027,,0.444879,343.775,,44.4879,0.343775,,,,7.85398e-5
Test1,3-Compress,142.613,1.682,1.384,0.027,,0.451402,343.775,,45.1402,0.343775,,,,7.85398e-5
Test1,3-Compress,142.947,1.662,1.404,0.027,,0.457926,343.775,,45.7926,0.343775,,,,7.85398e-5
Test1,3-Compress,143.280,1.641,1.425,0.041,,0.464775,522.028,,46.4775,0.522028,,,,7.85398e-5
Test1,3-Compress,143.613,1.621,1.445,0.034,,0.471298,432.902,,47.1298,0.432902,,,,7.85398e-5
Test1,3-Compress,143.947,1.6,1.466,0.048,,0.478147,611.155,,47.8147,0.611155,,,,7.85398e-5
Test1,3-Compress,144.280,1.58,1.486,0.061,,0.484671,776.676,,48.4671,0.776676,,,,7.85398e-5
Test1,3-Compress,144.613,1.559,1.507,0.061,,0.49152,776.676,,49.152,0.776676,,,,7.85398e-5
Test1,3-Compress,144.947,1.538,1.528,0.068,,0.498369,865.803,,49.8369,0.865803,,,,7.85398e-5
Test1,3-Compress,145.280,1.518,1.548,0.068,,0.504892,865.803,,50.4892,0.865803,,,,7.85398e-5
Test1,3-Compress,145.613,1.498,1.568,0.061,,0.511416,776.676,,51.1416,0.776676,,,,7.85398e-5
Test1,3-Compress,145.947,1.477,1.589,0.082,,0.518265,1044.06,,51.8265,1.04406,,,,7.85398e-5
Test1,3-Compress,146.280,1.457,1.609,0.082,,0.524788,1044.06,,52.4788,1.04406,,,,7.85398e-5
Test1,3-Compress,146.613,1.436,1.63,0.082,,0.531637,1044.06,,53.1637,1.04406,,,,7.85398e-5
Test1,3-Compress,146.947,1.415,1.651,0.082,,0.538487,1044.06,,53.8487,1.04406,,,,7.85398e-5
Test1,3-Compress,147.280,1.396,1.67,0.082,,0.544684,1044.06,,54.4684,1.04406,,,,7.85398e-5
Test1,3-Compress,147.613,1.375,1.691,0.082,,0.551533,1044.06,,55.1533,1.04406,,,,7.85398e-5
Test1,3-Compress,147.947,1.354,1.712,0.082,,0.558382,1044.06,,55.8382,1.04406,,,,7.85398e-5
Test1,3-Compress,148.280,1.334,1.732,0.082,,0.564905,1044.06,,56.4905,1.04406,,,,7.85398e-5
Test1,3-Compress,148.613,1.314,1.752,0.082,,0.571429,1044.06,,57.1429,1.04406,,,,7.85398e-5
Test1,3-Compress,148.947,1.293,1.773,0.082,,0.578278,1044.06,,57.8278,1.04406,,,,7.85398e-5
Test1,3-Compress,149.280,1.272,1.794,0.082,,0.585127,1044.06,,58.5127,1.04406,,,,7.85398e-5
Test1,3-Compress,149.613,1.252,1.814,0.082,,0.59165,1044.06,,59.165,1.04406,,,,7.85398e-5
Test1,3-Compress,149.947,1.231,1.835,0.082,,0.5985,1044.06,,59.85,1.04406,,,,7.85398e-5
Test1,3-Recover,150.267,1.237,1.829,0.082,,0.596543,1044.06,,59.6543,1.04406,,,,7.85398e-5
Test1,3-Recover,150.600,1.257,1.809,0.082,,0.59002,1044.06,,59.002,1.04406,,,,7.85398e-5
Test1,3-Recover,150.933,1.277,1.789,0.082,,0.583496,1044.06,,58.3496,1.04406,,,,7.85398e-5
Test1,3-Recover,151.267,1.298,1.768,0.082,,0.576647,1044.06,,57.6647,1.04406,,,,7.85398e-5
Test1,3-Recover,151.600,1.318,1.748,0.082,,0.570124,1044.06,,57.0124,1.04406,,,,7.85398e-5
Test1,3-Recover,151.933,1.338,1.728,0.082,,0.563601,1044.06,,56.3601,1.04406,,,,7.85398e-5
Test1,3-Recover,152.267,1.359,1.707,0.075,,0.556751,954.93,,55.6751,0.95493,,,,7.85398e-5
Test1,3-Recover,152.600,1.38,1.686,0.082,,0.549902,1044.06,,54.9902,1.04406,,,,7.85398e-5
Test1,3-Recover,152.933,1.4,1.666,0.075,,0.543379,954.93,,54.3379,0.95493,,,,7.85398e-5
Test1,3-Recover,153.267,1.421,1.645,0.075,,0.53653,954.93,,53.653,0.95493,,,,7.85398e-5
Test1,3-Recover,153.600,1.441,1.625,0.068,,0.530007,865.803,,53.0007,0.865803,,,,7.85398e-5
Test1,3-Recover,153.933,1.462,1.604,0.061,,0.523157,776.676,,52.3157,0.776676,,,,7.85398e-5
Test1,3-Recover,154.267,1.482,1.584,0.061,,0.516634,776.676,,51.6634,0.776676,,,,7.85398e-5
Test1,3-Recover,154.600,1.502,1.564,0.068,,0.510111,865.803,,51.0111,0.865803,,,,7.85398e-5
Test1,3-Recover,154.933,1.523,1.543,0.048,,0.503262,611.155,,50.3262,0.611155,,,,7.85398e-5
Test1,3-Recover,155.267,1.543,1.523,0.041,,0.496738,522.028,,49.6738,0.522028,,,,7.85398e-5
Test1,3-Recover,155.600,1.564,1.502,0.041,,0.489889,522.028,,48.9889,0.522028,,,,7.85398e-5
Test1,3-Recover,155.933,1.584,1.482,0.034,,0.483366,432.902,,48.3366,0.432902,,,,7.85398e-5
Test1,3-Recover,156.267,1.605,1.461,0.034,,0.476517,432.902,,47.6517,0.432902,,,,7.85398e-5
Test1,3-Recover,156.600,1.625,1.441,0.034,,0.469993,432.902,,46.9993,0.432902,,,,7.85398e-5
Test1,3-Recover,156.933,1.646,1.42,0.034,,0.463144,432.902,,46.3144,0.432902,,,,7.85398e-5
Test1,3-Recover,157.267,1.667,1.399,0.034,,0.456295,432.902,,45.6295,0.432902,,,,7.85398e-5
Test1,3-Recover,157.600,1.687,1.379,0.027,,0.449772,343.775,,44.9772,0.343775,,,,7.85398e-5
Test1,3-Recover,157.933,1.707,1.359,0.027,,0.443249,343.775,,44.3249,0.343775,,,,7.85398e-5
Test1,3-Recover,158.267,1.728,1.338,0.027,,0.436399,343.775,,43.6399,0.343775,,,,7.85398e-5
Test1,3-Recover,158.600,1.748,1.318,0.027,,0.429876,343.775,,42.9876,0.343775,,,,7.85398e-5
Test1,3-Recover,158.933,1.768,1.298,0.027,,0.423353,343.775,,42.3353,0.343775,,,,7.85398e-5
Test1,3-Recover,159.267,1.789,1.277,0.027,,0.416504,343.775,,41.6504,0.343775,,,,7.85398e-5
Test1,3-Recover,159.600,1.809,1.257,0.034,,0.40998,432.902,,40.998,0.432902,,,,7.85398e-5
Test1,3-Recover,159.933,1.83,1.236,0.027,,0.403131,343.775,,40.3131,0.343775,,,,7.85398e-5
Test1,3-Recover,160.267,1.851,1.215,0.034,,0.396282,432.902,,39.6282,0.432902,,,,7.85398e-5
Test1,3-Recover,160.600,1.871,1.195,0.027,,0.389759,343.775,,38.9759,0.343775,,,,7.85398e-5
Test1,3-Recover,160.933,1.891,1.175,0.027,,0.383235,343.775,,38.3235,0.343775,,,,7.85398e-5
Test1,3-Recover,161.267,1.912,1.154,0.034,,0.376386,432.902,,37.6386,0.432902,,,,7.85398e-5
Test1,3-Recover,161.600,1.932,1.134,0.027,,0.369863,343.775,,36.9863,0.343775,,,,7.85398e-5
Test1,3-Recover,161.933,1.953,1.113,0.027,,0.363014,343.775,,36.3014,0.343775,,,,7.85398e-5
Test1,3-Recover,162.267,1.974,1.092,0.027,,0.356164,343.775,,35.6164,0.343775,,,,7.85398e-5
Test1,3-Recover,162.600,1.994,1.072,0.027,,0.349641,343.775,,34.9641,0.343775,,,,7.85398e-5
Test1,3-Recover,162.933,2.014,1.052,0.020,,0.343118,254.648,,34.3118,0.254648,,,,7.85398e-5
Test1,3-Recover,163.267,2.035,1.031,0.027,,0.336269,343.775,,33.6269,0.343775,,,,7.85398e-5
Test1,3-Recover,163.600,2.055,1.011,0.027,,0.329746,343.775,,32.9746,0.343775,,,,7.85398e-5
Test1,3-Recover,163.933,2.075,0.991,0.020,,0.323222,254.648,,32.3222,0.254648,,,,7.85398e-5
Test1,3-Recover,164.267,2.096,0.97,0.027,,0.316373,343.775,,31.6373,0.343775,,,,7.85398e-5
Test1,3-Recover,164.600,2.117,0.949,0.020,,0.309524,254.648,,30.9524,0.254648,,,,7.85398e-5
Test1,3-Recover,164.933,2.137,0.929,0.020,,0.303001,254.648,,30.3001,0.254648,,,,7.85398e-5
Test1,3-Recover,165.267,2.158,0.908,0.000,,0.296151,0,,29.6151,0,,,,7.85398e-5
Test1,3-Recover,165.600,2.178,0.888,-0.014,,0.289628,-178.254,,28.9628,-0.178254,,,,7.85398e-5
Test1,3-Recover,165.933,2.198,0.868,0.007,,0.283105,89.1268,,28.3105,0.0891268,,,,7.85398e-5
Test1,3-Recover,166.267,2.219,0.847,0.000,,0.276256,0,,27.6256,0,,,,7.85398e-5
Test1,3-Recover,166.600,2.24,0.826,-0.020,,0.269406,-254.648,,26.9406,-0.254648,,,,7.85398e-5
Test1,3-Recover,166.933,2.26,0.806,-0.014,,0.262883,-178.254,,26.2883,-0.178254,,,,7.85398e-5
Test1,3-Recover,167.267,2.281,0.785,0.000,,0.256034,0,,25.6034,0,,,,7.85398e-5
Test1,3-Recover,167.600,2.301,0.765,-0.007,,0.249511,-89.1268,,24.9511,-0.0891268,,,,7.85398e-5
Test1,3-Recover,167.933,2.321,0.745,0.000,,0.242988,0,,24.2988,0,,,,7.85398e-5
Test1,3-Recover,168.267,2.342,0.724,-0.007,,0.236138,-89.1268,,23.6138,-0.0891268,,,,7.85398e-5
Test1,3-Recover,168.600,2.362,0.704,-0.007,,0.229615,-89.1268,,22.9615,-0.0891268,,,,7.85398e-5
Test1,3-Recover,168.933,2.383,0.683,-0.014,,0.222766,-178.254,,22.2766,-0.178254,,,,7.85398e-5
Test1,3-Recover,169.267,2.403,0.663,-0.007,,0.216243,-89.1268,,21.6243,-0.0891268,,,,7.85398e-5
Test1,3-Recover,169.600,2.424,0.642,0.000,,0.209393,0,,20.9393,0,,,,7.85398e-5
Test1,3-Recover,169.933,2.444,0.622,-0.020,,0.20287,-254.648,,20.287,-0.254648,,,,7.85398e-5
Test1,3-Recover,170.267,2.465,0.601,-0.014,,0.196021,-178.254,,19.6021,-0.178254,,,,7.85398e-5
Test1,3-Recover,170.600,2.485,0.581,-0.014,,0.189498,-178.254,,18.9498,-0.178254,,,,7.85398e-5
Test1,3-Recover,170.933,2.505,0.561,-0.020,,0.182975,-254.648,,18.2975,-0.254648,,,,7.85398e-5
Test1,3-Recover,171.267,2.526,0.54,-0.020,,0.176125,-254.648,,17.6125,-0.254648,,,,7.85398e-5
Test1,3-Recover,171.600,2.547,0.519,-0.020,,0.169276,-254.648,,16.9276,-0.254648,,,,7.85398e-5
Test1,3-Recover,171.933,2.567,0.499,-0.020,,0.162753,-254.648,,16.2753,-0.254648,,,,7.85398e-5
Test1,3-Recover,172.267,2.588,0.478,-0.020,,0.155903,-254.648,,15.5903,-0.254648,,,,7.85398e-5
Test1,3-Recover,172.600,2.608,0.458,-0.020,,0.14938,-254.648,,14.938,-0.254648,,,,7.85398e-5
Test1,3-Recover,172.933,2.628,0.438,-0.020,,0.142857,-254.648,,14.2857,-0.254648,,,,7.85398e-5
Test1,3-Recover,173.267,2.649,0.417,-0.020,,0.136008,-254.648,,13.6008,-0.254648,,,,7.85398e-5
Test1,3-Recover,173.600,2.669,0.397,-0.027,,0.129485,-343.775,,12.9485,-0.343775,,,,7.85398e-5
Test1,3-Recover,173.933,2.69,0.376,-0.020,,0.122635,-254.648,,12.2635,-0.254648,,,,7.85398e-5
Test1,3-Recover,174.267,2.711,0.355,-0.020,,0.115786,-254.648,,11.5786,-0.254648,,,,7.85398e-5
Test1,3-Recover,174.600,2.731,0.335,-0.020,,0.109263,-254.648,,10.9263,-0.254648,,,,7.85398e-5
Test1,3-Recover,174.933,2.751,0.315,-0.020,,0.10274,-254.648,,10.274,-0.254648,,,,7.85398e-5
Test1,3-Recover,175.267,2.772,0.294,-0.020,,0.0958904,-254.648,,9.58904,-0.254648,,,,7.85398e-5
Test1,3-Recover,175.600,2.792,0.274,-0.014,,0.0893673,-178.254,,8.93673,-0.178254,,,,7.85398e-5
Test1,3-Recover,175.933,2.813,0.253,-0.014,,0.0825179,-178.254,,8.25179,-0.178254,,,,7.85398e-5
Test1,3-Recover,176.267,2.833,0.233,-0.020,,0.0759948,-254.648,,7.59948,-0.254648,,,,7.85398e-5
Test1,3-Recover,176.600,2.854,0.212,-0.014,,0.0691455,-178.254,,6.91455,-0.178254,,,,7.85398e-5
Test1,3-Recover,176.933,2.874,0.192,-0.020,,0.0626223,-254.648,,6.26223,-0.254648,,,,7.85398e-5
Test1,3-Recover,177.267,2.895,0.171,-0.027,,0.055773,-343.775,,5.5773,-0.343775,,,,7.85398e-5
Test1,3-Recover,177.600,2.915,0.151,-0.020,,0.0492498,-254.648,,4.92498,-0.254648,,,,7.85398e-5
Test1,3-Recover,177.933,2.935,0.131,-0.027,,0.0427267,-343.775,,4.27267,-0.343775,,,,7.85398e-5
Test1,3-Recover,178.267,2.956,0.11,-0.027,,0.0358774,-343.775,,3.58774,-0.343775,,,,7.85398e-5
Test1,3-Recover,178.600,2.976,0.09,-0.027,,0.0293542,-343.775,,2.93542,-0.343775,,,,7.85398e-5
Test1,3-Recover,178.933,2.997,0.069,-0.027,,0.0225049,-343.775,,2.25049,-0.343775,,,,7.85398e-5
Test1,3-Recover,179.267,3.018,0.048,-0.027,,0.0156556,-343.775,,1.56556,-0.343775,,,,7.85398e-5
Test1,3-Recover,179.600,3.038,0.028,-0.027,,0.00913242,-343.775,,0.913242,-0.343775,,,,7.85398e-5
Test1,3-Recover,179.933,3.058,0.008,-0.027,,0.00260926,-343.775,,0.260926,-0.343775,,,,7.85398e-5
Test1,3-Recover,180.100,3.066,-0,-0.020,,0,-254.648,,0,-0.254648,,,,7.85398e-5