File: data/gamma_1-1-0_1.csv
SetName,Cycle,Time_S,Size_mm,Displacement_mm,Force_N,,Strain,Stress(Pascal),,%Strain,Stress(kPa),,,,Area(m^2)
Test1,1-Compress,0.000,1.776,-0,-0.000,,0,0,,0,0,,,,7.85398e-5
Test1,1-Compress,0.033,1.774,0.002,-0.000,,0.00112613,0,,0.112613,0,,,,7.85398e-5
Test1,1-Compress,0.367,1.763,0.013,-0.000,,0.00731982,0,,0.731982,0,,,,7.85398e-5
Test1,1-Compress,0.700,1.751,0.025,-0.000,,0.0140766,0,,1.40766,0,,,,7.85398e-5
Test1,1-Compress,1.033,1.739,0.037,-0.000,,0.0208333,0,,2.08333,0,,,,7.85398e-5
Test1,1-Compress,1.367,1.727,0.049,-0.000,,0.0275901,0,,2.75901,0,,,,7.85398e-5
Test1,1-Compress,1.700,1.715,0.061,-0.000,,0.0343468,0,,3.43468,0,,,,7.85398e-5
Test1,1-Compress,2.033,1.703,0.073,-0.000,,0.0411036,0,,4.11036,0,,,,7.85398e-5
Test1,1-Compress,2.367,1.691,0.085,-0.000,,0.0478604,0,,4.78604,0,,,,7.85398e-5
Test1,1-Compress,2.700,1.679,0.097,-0.000,,0.0546171,0,,5.46171,0,,,,7.85398e-5
Test1,1-Compress,3.033,1.668,0.108,-0.000,,0.0608108,0,,6.08108,0,,,,7.85398e-5
Test1,1-Compress,3.367,1.656,0.12,-0.000,,0.0675676,0,,6.75676,0,,,,7.85398e-5
Test1,1-Compress,3.700,1.644,0.132,-0.000,,0.0743243,0,,7.43243,0,,,,7.85398e-5
Test1,1-Compress,4.033,1.633,0.143,-0.000,,0.080518,0,,8.0518,0,,,,7.85398e-5
Test1,1-Compress,4.367,1.62,0.156,-0.000,,0.0878378,0,,8.78378,0,,,,7.85398e-5
Test1,1-Compress,4.700,1.608,0.168,-0.000,,0.0945946,0,,9.45946,0,,,,7.85398e-5
Test1,1-Compress,5.033,1.597,0.179,-0.000,,0.100788,0,,10.0788,0,,,,7.85398e-5
Test1,1-Compress,5.367,1.584,0.192,-0.000,,0.108108,0,,10.8108,0,,,,7.85398e-5
Test1,1-Compress,5.700,1.573,0.203,-0.000,,0.114302,0,,11.4302,0,,,,7.85398e-5
Test1,1-Compress,6.033,1.561,0.215,-0.000,,0.121059,0,,12.1059,0,,,,7.85398e-5
Test1,1-Compress,6.367,1.549,0.227,-0.000,,0.127815,0,,12.7815,0,,,,7.85398e-5
Test1,1-Compress,6.700,1.537,0.239,-0.000,,0.134572,0,,13.4572,0,,,,7.85398e-5
Test1,1-Compress,7.033,1.526,0.25,0.007,,0.140766,89.1268,,14.0766,0.0891268,,,,7.85398e-5
Test1,1-Compress,7.367,1.513,0.263,-0.000,,0.148086,0,,14.8086,0,,,,7.85398e-5
Test1,1-Compress,7.700,1.502,0.274,-0.000,,0.154279,0,,15.4279,0,,,,7.85398e-5
Test1,1-Compress,8.033,1.49,0.286,0.007,,0.161036,89.1268,,16.1036,0.0891268,,,,7.85398e-5
Test1,1-Compress,8.367,1.478,0.298,0.014,,0.167793,178.254,,16.7793,0.178254,,,,7.85398e-5
Test1,1-Compress,8.700,1.466,0.31,0.007,,0.17455,89.1268,,17.455,0.0891268,,,,7.85398e-5
Test1,1-Compress,9.033,1.454,0.322,0.007,,0.181306,89.1268,,18.1306,0.0891268,,,,7.85398e-5
Test1,1-Compress,9.367,1.442,0.334,0.007,,0.188063,89.1268,,18.8063,0.0891268,,,,7.85398e-5
Test1,1-Compress,9.700,1.431,0.345,0.007,,0.194257,89.1268,,19.4257,0.0891268,,,,7.85398e-5
Test1,1-Compress,10.033,1.419,0.357,0.007,,0.201014,89.1268,,20.1014,0.0891268,,,,7.85398e-5
Test1,1-Compress,10.367,1.407,0.369,-0.000,,0.20777,0,,20.777,0,,,,7.85398e-5
Test1,1-Compress,10.700,1.395,0.381,0.007,,0.214527,89.1268,,21.4527,0.0891268,,,,7.85398e-5
Test1,1-Compress,11.033,1.383,0.393,0.007,,0.221284,89.1268,,22.1284,0.0891268,,,,7.85398e-5
Test1,1-Compress,11.367,1.371,0.405,0.007,,0.228041,89.1268,,22.8041,0.0891268,,,,7.85398e-5
Test1,1-Compress,11.700,1.359,0.417,-0.000,,0.234797,0,,23.4797,0,,,,7.85398e-5
Test1,1-Compress,12.033,1.347,0.429,-0.000,,0.241554,0,,24.1554,0,,,,7.85398e-5
Test1,1-Compress,12.367,1.336,0.44,-0.000,,0.247748,0,,24.7748,0,,,,7.85398e-5
Test1,1-Compress,12.700,1.324,0.452,-0.000,,0.254505,0,,25.4505,0,,,,7.85398e-5
Test1,1-Compress,13.033,1.312,0.464,-0.000,,0.261261,0,,26.1261,0,,,,7.85398e-5
Test1,1-Compress,13.367,1.3,0.476,0.014,,0.268018,178.254,,26.8018,0.178254,,,,7.85398e-5
Test1,1-Compress,13.700,1.288,0.488,0.027,,0.274775,343.775,,27.4775,0.343775,,,,7.85398e-5
Test1,1-Compress,14.033,1.276,0.5,0.027,,0.281532,343.775,,28.1532,0.343775,,,,7.85398e-5
Test1,1-Compress,14.367,1.264,0.512,0.034,,0.288288,432.902,,28.8288,0.432902,,,,7.85398e-5
Test1,1-Compress,14.700,1.252,0.524,0.034,,0.295045,432.902,,29.5045,0.432902,,,,7.85398e-5
Test1,1-Compress,15.033,1.24,0.536,0.054,,0.301802,687.549,,30.1802,0.687549,,,,7.85398e-5
Test1,1-Compress,15.367,1.229,0.547,0.041,,0.307995,522.028,,30.7995,0.522028,,,,7.85398e-5
Test1,1-Compress,15.700,1.217,0.559,0.048,,0.314752,611.155,,31.4752,0.611155,,,,7.85398e-5
Test1,1-Compress,16.033,1.205,0.571,0.027,,0.321509,343.775,,32.1509,0.343775,,,,7.85398e-5
Test1,1-Compress,16.367,1.193,0.583,0.041,,0.328266,522.028,,32.8266,0.522028,,,,7.85398e-5
Test1,1-Compress,16.700,1.181,0.595,0.041,,0.335023,522.028,,33.5023,0.522028,,,,7.85398e-5
Test1,1-Compress,17.033,1.17,0.606,0.041,,0.341216,522.028,,34.1216,0.522028,,,,7.85398e-5
Test1,1-Compress,17.367,1.157,0.619,0.048,,0.348536,611.155,,34.8536,0.611155,,,,7.85398e-5
Test1,1-Compress,17.700,1.145,0.631,0.054,,0.355293,687.549,,35.5293,0.687549,,,,7.85398e-5
Test1,1-Compress,18.033,1.134,0.642,0.041,,0.361486,522.028,,36.1486,0.522028,,,,7.85398e-5
Test1,1-Compress,18.367,1.122,0.654,0.054,,0.368243,687.549,,36.8243,0.687549,,,,7.85398e-5
Test1,1-Compress,18.700,1.11,0.666,0.054,,0.375,687.549,,37.5,0.687549,,,,7.85398e-5
Test1,1-Compress,19.033,1.099,0.677,0.054,,0.381194,687.549,,38.1194,0.687549,,,,7.85398e-5
Test1,1-Compress,19.367,1.086,0.69,0.054,,0.388514,687.549,,38.8514,0.687549,,,,7.85398e-5
Test1,1-Compress,19.700,1.075,0.701,0.054,,0.394707,687.549,,39.4707,0.687549,,,,7.85398e-5
Test1,1-Compress,20.033,1.063,0.713,0.054,,0.401464,687.549,,40.1464,0.687549,,,,7.85398e-5
Test1,1-Compress,20.367,1.051,0.725,0.054,,0.408221,687.549,,40.8221,0.687549,,,,7.85398e-5
Test1,1-Compress,20.700,1.039,0.737,0.054,,0.414977,687.549,,41.4977,0.687549,,,,7.85398e-5
Test1,1-Compress,21.033,1.027,0.749,0.054,,0.421734,687.549,,42.1734,0.687549,,,,7.85398e-5
Test1,1-Compress,21.367,1.015,0.761,0.054,,0.428491,687.549,,42.8491,0.687549,,,,7.85398e-5
Test1,1-Compress,21.700,1.004,0.772,0.054,,0.434685,687.549,,43.4685,0.687549,,,,7.85398e-5
Test1,1-Compress,22.033,0.992,0.784,0.054,,0.441441,687.549,,44.1441,0.687549,,,,7.85398e-5
Test1,1-Compress,22.367,0.98,0.796,0.054,,0.448198,687.549,,44.8198,0.687549,,,,7.85398e-5
Test1,1-Compress,22.700,0.968,0.808,0.054,,0.454955,687.549,,45.4955,0.687549,,,,7.85398e-5
Test1,1-Compress,23.033,0.956,0.82,0.054,,0.461712,687.549,,46.1712,0.687549,,,,7.85398e-5
Test1,1-Compress,23.367,0.944,0.832,0.054,,0.468468,687.549,,46.8468,0.687549,,,,7.85398e-5
Test1,1-Compress,23.700,0.932,0.844,0.061,,0.475225,776.676,,47.5225,0.776676,,,,7.85398e-5
Test1,1-Compress,24.033,0.92,0.856,0.061,,0.481982,776.676,,48.1982,0.776676,,,,7.85398e-5
Test1,1-Compress,24.367,0.908,0.868,0.061,,0.488739,776.676,,48.8739,0.776676,,,,7.85398e-5
Test1,1-Compress,24.700,0.897,0.879,0.061,,0.494932,776.676,,49.4932,0.776676,,,,7.85398e-5
Test1,1-Compress,25.033,0.885,0.891,0.061,,0.501689,776.676,,50.1689,0.776676,,,,7.85398e-5
Test1,1-Compress,25.367,0.873,0.903,0.061,,0.508446,776.676,,50.8446,0.776676,,,,7.85398e-5
Test1,1-Compress,25.700,0.861,0.915,0.061,,0.515203,776.676,,51.5203,0.776676,,,,7.85398e-5
Test1,1-Compress,26.033,0.849,0.927,0.061,,0.521959,776.676,,52.1959,0.776676,,,,7.85398e-5
Test1,1-Compress,26.367,0.837,0.939,0.061,,0.528716,776.676,,52.8716,0.776676,,,,7.85398e-5
Test1,1-Compress,26.700,0.825,0.951,0.061,,0.535473,776.676,,53.5473,0.776676,,,,7.85398e-5
Test1,1-Compress,27.033,0.813,0.963,0.068,,0.54223,865.803,,54.223,0.865803,,,,7.85398e-5
Test1,1-Compress,27.367,0.802,0.974,0.054,,0.548423,687.549,,54.8423,0.687549,,,,7.85398e-5
Test1,1-Compress,27.700,0.79,0.986,0.061,,0.55518,776.676,,55.518,0.776676,,,,7.85398e-5
Test1,1-Compress,28.033,0.778,0.998,0.082,,0.561937,1044.06,,56.1937,1.04406,,,,7.85398e-5
Test1,1-Compress,28.367,0.766,1.01,0.054,,0.568694,687.549,,56.8694,0.687549,,,,7.85398e-5
Test1,1-Compress,28.700,0.754,1.022,0.068,,0.57545,865.803,,57.545,0.865803,,,,7.85398e-5
Test1,1-Compress,29.033,0.743,1.033,0.095,,0.581644,1209.58,,58.1644,1.20958,,,,7.85398e-5
Test1,1-Compress,29.367,0.73,1.046,0.082,,0.588964,1044.06,,58.8964,1.04406,,,,7.85398e-5
Test1,1-Compress,29.700,0.718,1.058,0.102,,0.595721,1298.7,,59.5721,1.2987,,,,7.85398e-5
Test1,1-Recover,30.033,0.71,1.066,0.102,,0.600225,1298.7,,60.0225,1.2987,,,,7.85398e-5
Test1,1-Recover,30.367,0.723,1.053,0.109,,0.592905,1387.83,,59.2905,1.38783,,,,7.85398e-5
Test1,1-Recover,30.700,0.734,1.042,0.088,,0.586712,1120.45,,58.6712,1.12045,,,,7.85398e-5
Test1,1-Recover,31.033,0.746,1.03,0.095,,0.579955,1209.58,,57.9955,1.20958,,,,7.85398e-5
Test1,1-Recover,31.367,0.758,1.018,0.095,,0.573198,1209.58,,57.3198,1.20958,,,,7.85398e-5
Test1,1-Recover,31.700,0.77,1.006,0.088,,0.566441,1120.45,,56.6441,1.12045,,,,7.85398e-5
Test1,1-Recover,32.033,0.781,0.995,0.075,,0.560248,954.93,,56.0248,0.95493,,,,7.85398e-5
Test1,1-Recover,32.367,0.794,0.982,0.061,,0.552928,776.676,,55.2928,0.776676,,,,7.85398e-5
Test1,1-Recover,32.700,0.806,0.97,0.061,,0.546171,776.676,,54.6171,0.776676,,,,7.85398e-5
Test1,1-Recover,33.033,0.817,0.959,0.068,,0.539977,865.803,,53.9977,0.865803,,,,7.85398e-5
Test1,1-Recover,33.367,0.829,0.947,0.061,,0.533221,776.676,,53.3221,0.776676,,,,7.85398e-5
Test1,1-Recover,33.700,0.841,0.935,0.054,,0.526464,687.549,,52.6464,0.687549,,,,7.85398e-5
Test1,1-Recover,34.033,0.853,0.923,0.054,,0.519707,687.549,,51.9707,0.687549,,,,7.85398e-5
Test1,1-Recover,34.367,0.865,0.911,0.054,,0.51295,687.549,,51.295,0.687549,,,,7.85398e-5
Test1,1-Recover,34.700,0.876,0.9,0.054,,0.506757,687.549,,50.6757,0.687549,,,,7.85398e-5
Test1,1-Recover,35.033,0.888,0.888,0.054,,0.5,687.549,,50,0.687549,,,,7.85398e-5
Test1,1-Recover,35.367,0.9,0.876,0.054,,0.493243,687.549,,49.3243,0.687549,,,,7.85398e-5
Test1,1-Recover,35.700,0.912,0.864,0.054,,0.486486,687.549,,48.6486,0.687549,,,,7.85398e-5
Test1,1-Recover,36.033,0.924,0.852,0.054,,0.47973,687.549,,47.973,0.687549,,,,7.85398e-5
Test1,1-Recover,36.367,0.936,0.84,0.054,,0.472973,687.549,,47.2973,0.687549,,,,7.85398e-5
Test1,1-Recover,36.700,0.948,0.828,0.048,,0.466216,611.155,,46.6216,0.611155,,,,7.85398e-5
Test1,1-Recover,37.033,0.96,0.816,0.048,,0.459459,611.155,,45.9459,0.611155,,,,7.85398e-5
Test1,1-Recover,37.367,0.972,0.804,0.048,,0.452703,611.155,,45.2703,0.611155,,,,7.85398e-5
Test1,1-Recover,37.700,0.983,0.793,0.054,,0.446509,687.549,,44.6509,0.687549,,,,7.85398e-5
Test1,1-Recover,38.033,0.995,0.781,0.054,,0.439752,687.549,,43.9752,0.687549,,,,7.85398e-5
Test1,1-Recover,38.367,1.007,0.769,0.054,,0.432995,687.549,,43.2995,0.687549,,,,7.85398e-5
Test1,1-Recover,38.700,1.019,0.757,0.054,,0.426239,687.549,,42.6239,0.687549,,,,7.85398e-5
Test1,1-Recover,39.033,1.031,0.745,0.054,,0.419482,687.549,,41.9482,0.687549,,,,7.85398e-5
Test1,1-Recover,39.367,1.043,0.733,0.054,,0.412725,687.549,,41.2725,0.687549,,,,7.85398e-5
Test1,1-Recover,39.700,1.055,0.721,0.054,,0.405968,687.549,,40.5968,0.687549,,,,7.85398e-5
Test1,1-Recover,40.033,1.066,0.71,0.048,,0.399775,611.155,,39.9775,0.611155,,,,7.85398e-5
Test1,1-Recover,40.367,1.078,0.698,0.034,,0.393018,432.902,,39.3018,0.432902,,,,7.85398e-5
Test1,1-Recover,40.700,1.09,0.686,0.027,,0.386261,343.775,,38.6261,0.343775,,,,7.85398e-5
Test1,1-Recover,41.033,1.102,0.674,0.027,,0.379505,343.775,,37.9505,0.343775,,,,7.85398e-5
Test1,1-Recover,41.367,1.114,0.662,0.027,,0.372748,343.775,,37.2748,0.343775,,,,7.85398e-5
Test1,1-Recover,41.700,1.126,0.65,0.020,,0.365991,254.648,,36.5991,0.254648,,,,7.85398e-5
Test1,1-Recover,42.033,1.138,0.638,0.007,,0.359234,89.1268,,35.9234,0.0891268,,,,7.85398e-5
Test1,1-Recover,42.367,1.15,0.626,0.020,,0.352477,254.648,,35.2477,0.254648,,,,7.85398e-5
Test1,1-Recover,42.700,1.161,0.615,0.007,,0.346284,89.1268,,34.6284,0.0891268,,,,7.85398e-5
Test1,1-Recover,43.033,1.173,0.603,0.007,,0.339527,89.1268,,33.9527,0.0891268,,,,7.85398e-5
Test1,1-Recover,43.367,1.185,0.591,0.007,,0.33277,89.1268,,33.277,0.0891268,,,,7.85398e-5
Test1,1-Recover,43.700,1.197,0.579,-0.000,,0.326014,0,,32.6014,0,,,,7.85398e-5
Test1,1-Recover,44.033,1.208,0.568,-0.000,,0.31982,0,,31.982,0,,,,7.85398e-5
Test1,1-Recover,44.367,1.221,0.555,0.007,,0.3125,89.1268,,31.25,0.0891268,,,,7.85398e-5
Test1,1-Recover,44.700,1.233,0.543,-0.000,,0.305743,0,,30.5743,0,,,,7.85398e-5
Test1,1-Recover,45.033,1.244,0.532,0.007,,0.29955,89.1268,,29.955,0.0891268,,,,7.85398e-5
Test1,1-Recover,45.367,1.256,0.52,0.007,,0.292793,89.1268,,29.2793,0.0891268,,,,7.85398e-5
Test1,1-Recover,45.700,1.268,0.508,0.007,,0.286036,89.1268,,28.6036,0.0891268,,,,7.85398e-5
Test1,1-Recover,46.033,1.28,0.496,0.014,,0.279279,178.254,,27.9279,0.178254,,,,7.85398e-5
Test1,1-Recover,46.367,1.292,0.484,0.014,,0.272523,178.254,,27.2523,0.178254,,,,7.85398e-5
Test1,1-Recover,46.700,1.304,0.472,-0.000,,0.265766,0,,26.5766,0,,,,7.85398e-5
Test1,1-Recover,47.033,1.315,0.461,-0.000,,0.259572,0,,25.9572,0,,,,7.85398e-5
Test1,1-Recover,47.367,1.328,0.448,0.007,,0.252252,89.1268,,25.2252,0.0891268,,,,7.85398e-5
Test1,1-Recover,47.700,1.339,0.437,-0.000,,0.246059,0,,24.6059,0,,,,7.85398e-5
Test1,1-Recover,48.033,1.351,0.425,0.007,,0.239302,89.1268,,23.9302,0.0891268,,,,7.85398e-5
Test1,1-Recover,48.367,1.363,0.413,-0.000,,0.232545,0,,23.2545,0,,,,7.85398e-5
Test1,1-Recover,48.700,1.375,0.401,-0.000,,0.225788,0,,22.5788,0,,,,7.85398e-5
Test1,1-Recover,49.033,1.387,0.389,-0.000,,0.219032,0,,21.9032,0,,,,7.85398e-5
Test1,1-Recover,49.367,1.399,0.377,-0.000,,0.212275,0,,21.2275,0,,,,7.85398e-5
Test1,1-Recover,49.700,1.41,0.366,-0.000,,0.206081,0,,20.6081,0,,,,7.85398e-5
Test1,1-Recover,50.033,1.422,0.354,-0.000,,0.199324,0,,19.9324,0,,,,7.85398e-5
Test1,1-Recover,50.367,1.434,0.342,-0.000,,0.192568,0,,19.2568,0,,,,7.85398e-5
Test1,1-Recover,50.700,1.446,0.33,-0.000,,0.185811,0,,18.5811,0,,,,7.85398e-5
Test1,1-Recover,51.033,1.458,0.318,-0.000,,0.179054,0,,17.9054,0,,,,7.85398e-5
Test1,1-Recover,51.367,1.47,0.306,-0.000,,0.172297,0,,17.2297,0,,,,7.85398e-5
Test1,1-Recover,51.700,1.482,0.294,-0.000,,0.165541,0,,16.5541,0,,,,7.85398e-5
Test1,1-Recover,52.033,1.494,0.282,-0.000,,0.158784,0,,15.8784,0,,,,7.85398e-5
Test1,1-Recover,52.367,1.505,0.271,-0.000,,0.15259,0,,15.259,0,,,,7.85398e-5
Test1,1-Recover,52.700,1.517,0.259,-0.000,,0.145833,0,,14.5833,0,,,,7.85398e-5
Test1,1-Recover,53.033,1.529,0.247,-0.000,,0.139077,0,,13.9077,0,,,,7.85398e-5
Test1,1-Recover,53.367,1.541,0.235,-0.000,,0.13232,0,,13.232,0,,,,7.85398e-5
Test1,1-Recover,53.700,1.553,0.223,-0.007,,0.125563,-89.1268,,12.5563,-0.0891268,,,,7.85398e-5
Test1,1-Recover,54.033,1.565,0.211,0.007,,0.118806,89.1268,,11.8806,0.0891268,,,,7.85398e-5
Test1,1-Recover,54.367,1.577,0.199,-0.000,,0.11205,0,,11.205,0,,,,7.85398e-5
Test1,1-Recover,54.700,1.589,0.187,-0.000,,0.105293,0,,10.5293,0,,,,7.85398e-5
Test1,1-Recover,55.033,1.6,0.176,-0.000,,0.0990991,0,,9.90991,0,,,,7.85398e-5
Test1,1-Recover,55.367,1.612,0.164,-0.007,,0.0923423,-89.1268,,9.23423,-0.0891268,,,,7.85398e-5
Test1,1-Recover,55.700,1.624,0.152,-0.000,,0.0855856,0,,8.55856,0,,,,7.85398e-5
Test1,1-Recover,56.033,1.636,0.14,-0.000,,0.0788288,0,,7.88288,0,,,,7.85398e-5
Test1,1-Recover,56.367,1.648,0.128,-0.000,,0.0720721,0,,7.20721,0,,,,7.85398e-5
Test1,1-Recover,56.700,1.66,0.116,-0.000,,0.0653153,0,,6.53153,0,,,,7.85398e-5
Test1,1-Recover,57.033,1.671,0.105,-0.000,,0.0591216,0,,5.91216,0,,,,7.85398e-5
Test1,1-Recover,57.367,1.683,0.093,-0.000,,0.0523649,0,,5.23649,0,,,,7.85398e-5
Test1,1-Recover,57.700,1.695,0.081,-0.000,,0.0456081,0,,4.56081,0,,,,7.85398e-5
Test1,1-Recover,58.033,1.707,0.069,-0.007,,0.0388514,-89.1268,,3.88514,-0.0891268,,,,7.85398e-5
Test1,1-Recover,58.367,1.719,0.057,-0.007,,0.0320946,-89.1268,,3.20946,-0.0891268,,,,7.85398e-5
Test1,1-Recover,58.700,1.731,0.045,-0.007,,0.0253378,-89.1268,,2.53378,-0.0891268,,,,7.85398e-5
Test1,1-Recover,59.033,1.742,0.034,-0.020,,0.0191441,-254.648,,1.91441,-0.254648,,,,7.85398e-5
Test1,1-Recover,59.367,1.755,0.021,-0.007,,0.0118243,-89.1268,,1.18243,-0.0891268,,,,7.85398e-5
Test1,1-Recover,59.700,1.766,0.01,-0.027,,0.00563063,-343.775,,0.563063,-0.343775,,,,7.85398e-5
Test1,1-Recover,60.033,1.776,-0,-0.020,,0,-254.648,,0,-0.254648,,,,7.85398e-5
Test1,2-Compress,60.350,1.765,0.011,-0.014,,0.00619369,-178.254,,0.619369,-0.178254,,,,7.85398e-5
Test1,2-Compress,60.683,1.753,0.023,-0.014,,0.0129505,-178.254,,1.29505,-0.178254,,,,7.85398e-5
Test1,2-Compress,61.017,1.74,0.036,-0.000,,0.0202703,0,,2.02703,0,,,,7.85398e-5
Test1,2-Compress,61.350,1.729,0.047,-0.020,,0.026464,-254.648,,2.6464,-0.254648,,,,7.85398e-5
Test1,2-Compress,61.683,1.717,0.059,-0.000,,0.0332207,0,,3.32207,0,,,,7.85398e-5
Test1,2-Compress,62.017,1.705,0.071,-0.000,,0.0399775,0,,3.99775,0,,,,7.85398e-5
Test1,2-Compress,62.350,1.693,0.083,-0.007,,0.0467342,-89.1268,,4.67342,-0.0891268,,,,7.85398e-5
Test1,2-Compress,62.683,1.682,0.094,-0.000,,0.0529279,0,,5.29279,0,,,,7.85398e-5
Test1,2-Compress,63.017,1.669,0.107,-0.000,,0.0602477,0,,6.02477,0,,,,7.85398e-5
Test1,2-Compress,63.350,1.658,0.118,-0.000,,0.0664414,0,,6.64414,0,,,,7.85398e-5
Test1,2-Compress,63.683,1.646,0.13,-0.000,,0.0731982,0,,7.31982,0,,,,7.85398e-5
Test1,2-Compress,64.017,1.634,0.142,-0.000,,0.079955,0,,7.9955,0,,,,7.85398e-5
Test1,2-Compress,64.350,1.622,0.154,-0.000,,0.0867117,0,,8.67117,0,,,,7.85398e-5
Test1,2-Compress,64.683,1.61,0.166,-0.000,,0.0934685,0,,9.34685,0,,,,7.85398e-5
Test1,2-Compress,65.017,1.598,0.178,-0.000,,0.100225,0,,10.0225,0,,,,7.85398e-5
Test1,2-Compress,65.350,1.587,0.189,-0.000,,0.106419,0,,10.6419,0,,,,7.85398e-5
Test1,2-Compress,65.683,1.575,0.201,-0.000,,0.113176,0,,11.3176,0,,,,7.85398e-5
Test1,2-Compress,66.017,1.563,0.213,-0.000,,0.119932,0,,11.9932,0,,,,7.85398e-5
Test1,2-Compress,66.350,1.551,0.225,-0.000,,0.126689,0,,12.6689,0,,,,7.85398e-5
Test1,2-Compress,66.683,1.539,0.237,-0.000,,0.133446,0,,13.3446,0,,,,7.85398e-5
Test1,2-Compress,67.017,1.527,0.249,-0.000,,0.140203,0,,14.0203,0,,,,7.85398e-5
Test1,2-Compress,67.350,1.515,0.261,-0.000,,0.146959,0,,14.6959,0,,,,7.85398e-5
Test1,2-Compress,67.683,1.503,0.273,-0.000,,0.153716,0,,15.3716,0,,,,7.85398e-5
Test1,2-Compress,68.017,1.492,0.284,-0.000,,0.15991,0,,15.991,0,,,,7.85398e-5
Test1,2-Compress,68.350,1.48,0.296,-0.000,,0.166667,0,,16.6667,0,,,,7.85398e-5
Test1,2-Compress,68.683,1.468,0.308,-0.000,,0.173423,0,,17.3423,0,,,,7.85398e-5
Test1,2-Compress,69.017,1.456,0.32,-0.000,,0.18018,0,,18.018,0,,,,7.85398e-5
Test1,2-Compress,69.350,1.444,0.332,0.007,,0.186937,89.1268,,18.6937,0.0891268,,,,7.85398e-5
Test1,2-Compress,69.683,1.432,0.344,0.007,,0.193694,89.1268,,19.3694,0.0891268,,,,7.85398e-5
Test1,2-Compress,70.017,1.42,0.356,-0.000,,0.20045,0,,20.045,0,,,,7.85398e-5
Test1,2-Compress,70.350,1.408,0.368,0.014,,0.207207,178.254,,20.7207,0.178254,,,,7.85398e-5
Test1,2-Compress,70.683,1.397,0.379,0.007,,0.213401,89.1268,,21.3401,0.0891268,,,,7.85398e-5
Test1,2-Compress,71.017,1.385,0.391,0.014,,0.220158,178.254,,22.0158,0.178254,,,,7.85398e-5
Test1,2-Compress,71.350,1.373,0.403,0.007,,0.226914,89.1268,,22.6914,0.0891268,,,,7.85398e-5
Test1,2-Compress,71.683,1.361,0.415,0.014,,0.233671,178.254,,23.3671,0.178254,,,,7.85398e-5
Test1,2-Compress,72.017,1.349,0.427,0.020,,0.240428,254.648,,24.0428,0.254648,,,,7.85398e-5
Test1,2-Compress,72.350,1.337,0.439,0.014,,0.247185,178.254,,24.7185,0.178254,,,,7.85398e-5
Test1,2-Compress,72.683,1.326,0.45,0.007,,0.253378,89.1268,,25.3378,0.0891268,,,,7.85398e-5
Test1,2-Compress,73.017,1.313,0.463,0.020,,0.260698,254.648,,26.0698,0.254648,,,,7.85398e-5
Test1,2-Compress,73.350,1.302,0.474,0.014,,0.266892,178.254,,26.6892,0.178254,,,,7.85398e-5
Test1,2-Compress,73.683,1.29,0.486,0.014,,0.273649,178.254,,27.3649,0.178254,,,,7.85398e-5
Test1,2-Compress,74.017,1.278,0.498,0.007,,0.280405,89.1268,,28.0405,0.0891268,,,,7.85398e-5
Test1,2-Compress,74.350,1.266,0.51,0.007,,0.287162,89.1268,,28.7162,0.0891268,,,,7.85398e-5
Test1,2-Compress,74.683,1.255,0.521,0.014,,0.293356,178.254,,29.3356,0.178254,,,,7.85398e-5
Test1,2-Compress,75.017,1.242,0.534,0.014,,0.300676,178.254,,30.0676,0.178254,,,,7.85398e-5
Test1,2-Compress,75.350,1.231,0.545,0.014,,0.306869,178.254,,30.6869,0.178254,,,,7.85398e-5
Test1,2-Compress,75.683,1.219,0.557,0.014,,0.313626,178.254,,31.3626,0.178254,,,,7.85398e-5
Test1,2-Compress,76.017,1.207,0.569,0.020,,0.320383,254.648,,32.0383,0.254648,,,,7.85398e-5
Test1,2-Compress,76.350,1.195,0.581,0.034,,0.32714,432.902,,32.714,0.432902,,,,7.85398e-5
Test1,2-Compress,76.683,1.183,0.593,0.027,,0.333896,343.775,,33.3896,0.343775,,,,7.85398e-5
Test1,2-Compress,77.017,1.171,0.605,0.027,,0.340653,343.775,,34.0653,0.343775,,,,7.85398e-5
Test1,2-Compress,77.350,1.16,0.616,0.014,,0.346847,178.254,,34.6847,0.178254,,,,7.85398e-5
Test1,2-Compress,77.683,1.148,0.628,0.027,,0.353604,343.775,,35.3604,0.343775,,,,7.85398e-5
Test1,2-Compress,78.017,1.136,0.64,0.041,,0.36036,522.028,,36.036,0.522028,,,,7.85398e-5
Test1,2-Compress,78.350,1.124,0.652,0.034,,0.367117,432.902,,36.7117,0.432902,,,,7.85398e-5
Test1,2-Compress,78.683,1.112,0.664,0.054,,0.373874,687.549,,37.3874,0.687549,,,,7.85398e-5
Test1,2-Compress,79.017,1.1,0.676,0.054,,0.380631,687.549,,38.0631,0.687549,,,,7.85398e-5
Test1,2-Compress,79.350,1.088,0.688,0.054,,0.387387,687.549,,38.7387,0.687549,,,,7.85398e-5
Test1,2-Compress,79.683,1.076,0.7,0.054,,0.394144,687.549,,39.4144,0.687549,,,,7.85398e-5
Test1,2-Compress,80.017,1.065,0.711,0.054,,0.400338,687.549,,40.0338,0.687549,,,,7.85398e-5
Test1,2-Compress,80.350,1.053,0.723,0.054,,0.407095,687.549,,40.7095,0.687549,,,,7.85398e-5
Test1,2-Compress,80.683,1.041,0.735,0.054,,0.413851,687.549,,41.3851,0.687549,,,,7.85398e-5
Test1,2-Compress,81.017,1.029,0.747,0.054,,0.420608,687.549,,42.0608,0.687549,,,,7.85398e-5
Test1,2-Compress,81.350,1.017,0.759,0.054,,0.427365,687.549,,42.7365,0.687549,,,,7.85398e-5
Test1,2-Compress,81.683,1.005,0.771,0.054,,0.434122,687.549,,43.4122,0.687549,,,,7.85398e-5
Test1,2-Compress,82.017,0.993,0.783,0.054,,0.440878,687.549,,44.0878,0.687549,,,,7.85398e-5
Test1,2-Compress,82.350,0.981,0.795,0.054,,0.447635,687.549,,44.7635,0.687549,,,,7.85398e-5
Test1,2-Compress,82.683,0.97,0.806,0.054,,0.453829,687.549,,45.3829,0.687549,,,,7.85398e-5
Test1,2-Compress,83.017,0.958,0.818,0.054,,0.460586,687.549,,46.0586,0.687549,,,,7.85398e-5
Test1,2-Compress,83.350,0.946,0.83,0.054,,0.467342,687.549,,46.7342,0.687549,,,,7.85398e-5
Test1,2-Compress,83.683,0.934,0.842,0.054,,0.474099,687.549,,47.4099,0.687549,,,,7.85398e-5
Test1,2-Compress,84.017,0.922,0.854,0.054,,0.480856,687.549,,48.0856,0.687549,,,,7.85398e-5
Test1,2-Compress,84.350,0.91,0.866,0.054,,0.487613,687.549,,48.7613,0.687549,,,,7.85398e-5
Test1,2-Compress,84.683,0.899,0.877,0.054,,0.493806,687.549,,49.3806,0.687549,,,,7.85398e-5
Test1,2-Compress,85.017,0.886,0.89,0.054,,0.501126,687.549,,50.1126,0.687549,,,,7.85398e-5
Test1,2-Compress,85.350,0.875,0.901,0.061,,0.50732,776.676,,50.732,0.776676,,,,7.85398e-5
Test1,2-Compress,85.683,0.863,0.913,0.061,,0.514077,776.676,,51.4077,0.776676,,,,7.85398e-5
Test1,2-Compress,86.017,0.851,0.925,0.054,,0.520833,687.549,,52.0833,0.687549,,,,7.85398e-5
Test1,2-Compress,86.350,0.839,0.937,0.054,,0.52759,687.549,,52.759,0.687549,,,,7.85398e-5
Test1,2-Compress,86.683,0.827,0.949,0.068,,0.534347,865.803,,53.4347,0.865803,,,,7.85398e-5
Test1,2-Compress,87.017,0.815,0.961,0.082,,0.541104,1044.06,,54.1104,1.04406,,,,7.85398e-5
Test1,2-Compress,87.350,0.804,0.972,0.075,,0.547297,954.93,,54.7297,0.95493,,,,7.85398e-5
Test1,2-Compress,87.683,0.792,0.984,0.068,,0.554054,865.803,,55.4054,0.865803,,,,7.85398e-5
Test1,2-Compress,88.017,0.779,0.997,0.075,,0.561374,954.93,,56.1374,0.95493,,,,7.85398e-5
Test1,2-Compress,88.350,0.768,1.008,0.095,,0.567568,1209.58,,56.7568,1.20958,,,,7.85398e-5
Test1,2-Compress,88.683,0.756,1.02,0.088,,0.574324,1120.45,,57.4324,1.12045,,,,7.85398e-5
Test1,2-Compress,89.017,0.744,1.032,0.082,,0.581081,1044.06,,58.1081,1.04406,,,,7.85398e-5
Test1,2-Compress,89.350,0.732,1.044,0.088,,0.587838,1120.45,,58.7838,1.12045,,,,7.85398e-5
Test1,2-Compress,89.683,0.721,1.055,0.088,,0.594032,1120.45,,59.4032,1.12045,,,,7.85398e-5
Test1,2-Compress,90.017,0.71,1.066,0.102,,0.600225,1298.7,,60.0225,1.2987,,,,7.85398e-5
Test1,2-Recover,90.337,0.72,1.056,0.082,,0.594595,1044.06,,59.4595,1.04406,,,,7.85398e-5
Test1,2-Recover,90.670,0.732,1.044,0.082,,0.587838,1044.06,,58.7838,1.04406,,,,7.85398e-5
Test1,2-Recover,91.003,0.743,1.033,0.088,,0.581644,1120.45,,58.1644,1.12045,,,,7.85398e-5
Test1,2-Recover,91.337,0.756,1.02,0.061,,0.574324,776.676,,57.4324,0.776676,,,,7.85398e-5
Test1,2-Recover,91.670,0.768,1.008,0.061,,0.567568,776.676,,56.7568,0.776676,,,,7.85398e-5
Test1,2-Recover,92.003,0.779,0.997,0.061,,0.561374,776.676,,56.1374,0.776676,,,,7.85398e-5
Test1,2-Recover,92.337,0.791,0.985,0.054,,0.554617,687.549,,55.4617,0.687549,,,,7.85398e-5
Test1,2-Recover,92.670,0.803,0.973,0.054,,0.54786,687.549,,54.786,0.687549,,,,7.85398e-5
Test1,2-Recover,93.003,0.815,0.961,0.054,,0.541104,687.549,,54.1104,0.687549,,,,7.85398e-5
Test1,2-Recover,93.337,0.827,0.949,0.054,,0.534347,687.549,,53.4347,0.687549,,,,7.85398e-5
Test1,2-Recover,93.670,0.839,0.937,0.054,,0.52759,687.549,,52.759,0.687549,,,,7.85398e-5
Test1,2-Recover,94.003,0.85,0.926,0.054,,0.521396,687.549,,52.1396,0.687549,,,,7.85398e-5
Test1,2-Recover,94.337,0.863,0.913,0.054,,0.514077,687.549,,51.4077,0.687549,,,,7.85398e-5
Test1,2-Recover,94.670,0.874,0.902,0.054,,0.507883,687.549,,50.7883,0.687549,,,,7.85398e-5
Test1,2-Recover,95.003,0.886,0.89,0.054,,0.501126,687.549,,50.1126,0.687549,,,,7.85398e-5
Test1,2-Recover,95.337,0.898,0.878,0.054,,0.494369,687.549,,49.4369,0.687549,,,,7.85398e-5
Test1,2-Recover,95.670,0.91,0.866,0.054,,0.487613,687.549,,48.7613,0.687549,,,,7.85398e-5
Test1,2-Recover,96.003,0.921,0.855,0.054,,0.481419,687.549,,48.1419,0.687549,,,,7.85398e-5
Test1,2-Recover,96.337,0.934,0.842,0.054,,0.474099,687.549,,47.4099,0.687549,,,,7.85398e-5
Test1,2-Recover,96.670,0.945,0.831,0.054,,0.467905,687.549,,46.7905,0.687549,,,,7.85398e-5
Test1,2-Recover,97.003,0.957,0.819,0.054,,0.461149,687.549,,46.1149,0.687549,,,,7.85398e-5
Test1,2-Recover,97.337,0.969,0.807,0.054,,0.454392,687.549,,45.4392,0.687549,,,,7.85398e-5
Test1,2-Recover,97.670,0.981,0.795,0.054,,0.447635,687.549,,44.7635,0.687549,,,,7.85398e-5
Test1,2-Recover,98.003,0.993,0.783,0.054,,0.440878,687.549,,44.0878,0.687549,,,,7.85398e-5
Test1,2-Recover,98.337,1.005,0.771,0.054,,0.434122,687.549,,43.4122,0.687549,,,,7.85398e-5
Test1,2-Recover,98.670,1.016,0.76,0.054,,0.427928,687.549,,42.7928,0.687549,,,,7.85398e-5
Test1,2-Recover,99.003,1.028,0.748,0.054,,0.421171,687.549,,42.1171,0.687549,,,,7.85398e-5
Test1,2-Recover,99.337,1.04,0.736,0.027,,0.414414,343.775,,41.4414,0.343775,,,,7.85398e-5
Test1,2-Recover,99.670,1.052,0.724,0.041,,0.407658,522.028,,40.7658,0.522028,,,,7.85398e-5
Test1,2-Recover,100.003,1.064,0.712,0.014,,0.400901,178.254,,40.0901,0.178254,,,,7.85398e-5
Test1,2-Recover,100.337,1.076,0.7,0.054,,0.394144,687.549,,39.4144,0.687549,,,,7.85398e-5
Test1,2-Recover,100.670,1.088,0.688,0.027,,0.387387,343.775,,38.7387,0.343775,,,,7.85398e-5
Test1,2-Recover,101.003,1.1,0.676,0.014,,0.380631,178.254,,38.0631,0.178254,,,,7.85398e-5
Test1,2-Recover,101.337,1.111,0.665,0.014,,0.374437,178.254,,37.4437,0.178254,,,,7.85398e-5
Test1,2-Recover,101.670,1.123,0.653,0.034,,0.36768,432.902,,36.768,0.432902,,,,7.85398e-5
Test1,2-Recover,102.003,1.135,0.641,0.027,,0.360923,343.775,,36.0923,0.343775,,,,7.85398e-5
Test1,2-Recover,102.337,1.147,0.629,0.027,,0.354167,343.775,,35.4167,0.343775,,,,7.85398e-5
Test1,2-Recover,102.670,1.159,0.617,0.027,,0.34741,343.775,,34.741,0.343775,,,,7.85398e-5
Test1,2-Recover,103.003,1.171,0.605,0.020,,0.340653,254.648,,34.0653,0.254648,,,,7.85398e-5
Test1,2-Recover,103.337,1.183,0.593,0.020,,0.333896,254.648,,33.3896,0.254648,,,,7.85398e-5
Test1,2-Recover,103.670,1.195,0.581,0.020,,0.32714,254.648,,32.714,0.254648,,,,7.85398e-5
Test1,2-Recover,104.003,1.206,0.57,0.027,,0.320946,343.775,,32.0946,0.343775,,,,7.85398e-5
Test1,2-Recover,104.337,1.218,0.558,0.007,,0.314189,89.1268,,31.4189,0.0891268,,,,7.85398e-5
Test1,2-Recover,104.670,1.23,0.546,0.007,,0.307432,89.1268,,30.7432,0.0891268,,,,7.85398e-5
Test1,2-Recover,105.003,1.242,0.534,0.020,,0.300676,254.648,,30.0676,0.254648,,,,7.85398e-5
Test1,2-Recover,105.337,1.254,0.522,0.007,,0.293919,89.1268,,29.3919,0.0891268,,,,7.85398e-5
Test1,2-Recover,105.670,1.266,0.51,0.007,,0.287162,89.1268,,28.7162,0.0891268,,,,7.85398e-5
Test1,2-Recover,106.003,1.277,0.499,0.014,,0.280968,178.254,,28.0968,0.178254,,,,7.85398e-5
Test1,2-Recover,106.337,1.29,0.486,0.007,,0.273649,89.1268,,27.3649,0.0891268,,,,7.85398e-5
Test1,2-Recover,106.670,1.301,0.475,0.007,,0.267455,89.1268,,26.7455,0.0891268,,,,7.85398e-5
Test1,2-Recover,107.003,1.313,0.463,0.007,,0.260698,89.1268,,26.0698,0.0891268,,,,7.85398e-5
Test1,2-Recover,107.337,1.325,0.451,0.007,,0.253941,89.1268,,25.3941,0.0891268,,,,7.85398e-5
Test1,2-Recover,107.670,1.337,0.439,0.007,,0.247185,89.1268,,24.7185,0.0891268,,,,7.85398e-5
Test1,2-Recover,108.003,1.348,0.428,-0.000,,0.240991,0,,24.0991,0,,,,7.85398e-5
Test1,2-Recover,108.337,1.361,0.415,-0.000,,0.233671,0,,23.3671,0,,,,7.85398e-5
Test1,2-Recover,108.670,1.372,0.404,-0.000,,0.227477,0,,22.7477,0,,,,7.85398e-5
Test1,2-Recover,109.003,1.384,0.392,-0.000,,0.220721,0,,22.0721,0,,,,7.85398e-5
Test1,2-Recover,109.337,1.396,0.38,-0.000,,0.213964,0,,21.3964,0,,,,7.85398e-5
Test1,2-Recover,109.670,1.408,0.368,-0.000,,0.207207,0,,20.7207,0,,,,7.85398e-5
Test1,2-Recover,110.003,1.42,0.356,-0.000,,0.20045,0,,20.045,0,,,,7.85398e-5
Test1,2-Recover,110.337,1.432,0.344,-0.000,,0.193694,0,,19.3694,0,,,,7.85398e-5
Test1,2-Recover,110.670,1.443,0.333,0.007,,0.1875,89.1268,,18.75,0.0891268,,,,7.85398e-5
Test1,2-Recover,111.003,1.455,0.321,0.007,,0.180743,89.1268,,18.0743,0.0891268,,,,7.85398e-5
Test1,2-Recover,111.337,1.468,0.308,-0.000,,0.173423,0,,17.3423,0,,,,7.85398e-5
Test1,2-Recover,111.670,1.479,0.297,-0.000,,0.16723,0,,16.723,0,,,,7.85398e-5
Test1,2-Recover,112.003,1.491,0.285,-0.000,,0.160473,0,,16.0473,0,,,,7.85398e-5
Test1,2-Recover,112.337,1.503,0.273,-0.000,,0.153716,0,,15.3716,0,,,,7.85398e-5
Test1,2-Recover,112.670,1.515,0.261,-0.000,,0.146959,0,,14.6959,0,,,,7.85398e-5
Test1,2-Recover,113.003,1.527,0.249,-0.000,,0.140203,0,,14.0203,0,,,,7.85398e-5
Test1,2-Recover,113.337,1.538,0.238,-0.000,,0.134009,0,,13.4009,0,,,,7.85398e-5
Test1,2-Recover,113.670,1.55,0.226,-0.000,,0.127252,0,,12.7252,0,,,,7.85398e-5
Test1,2-Recover,114.003,1.562,0.214,-0.000,,0.120495,0,,12.0495,0,,,,7.85398e-5
Test1,2-Recover,114.337,1.574,0.202,-0.000,,0.113739,0,,11.3739,0,,,,7.85398e-5
Test1,2-Recover,114.670,1.586,0.19,-0.000,,0.106982,0,,10.6982,0,,,,7.85398e-5
Test1,2-Recover,115.003,1.598,0.178,-0.000,,0.100225,0,,10.0225,0,,,,7.85398e-5
Test1,2-Recover,115.337,1.61,0.166,-0.000,,0.0934685,0,,9.34685,0,,,,7.85398e-5
Test1,2-Recover,115.670,1.622,0.154,-0.000,,0.0867117,0,,8.67117,0,,,,7.85398e-5
Test1,2-Recover,116.003,1.634,0.142,-0.000,,0.079955,0,,7.9955,0,,,,7.85398e-5
Test1,2-Recover,116.337,1.645,0.131,-0.000,,0.0737613,0,,7.37613,0,,,,7.85398e-5
Test1,2-Recover,116.670,1.657,0.119,-0.000,,0.0670045,0,,6.70045,0,,,,7.85398e-5
Test1,2-Recover,117.003,1.669,0.107,-0.000,,0.0602477,0,,6.02477,0,,,,7.85398e-5
Test1,2-Recover,117.337,1.681,0.095,-0.014,,0.053491,-178.254,,5.3491,-0.178254,,,,7.85398e-5
Test1,2-Recover,117.670,1.693,0.083,-0.034,,0.0467342,-432.902,,4.67342,-0.432902,,,,7.85398e-5
Test1,2-Recover,118.003,1.704,0.072,-0.007,,0.0405405,-89.1268,,4.05405,-0.0891268,,,,7.85398e-5
Test1,2-Recover,118.337,1.717,0.059,-0.014,,0.0332207,-178.254,,3.32207,-0.178254,,,,7.85398e-5
Test1,2-Recover,118.670,1.729,0.047,-0.007,,0.026464,-89.1268,,2.6464,-0.0891268,,,,7.85398e-5
Test1,2-Recover,119.003,1.74,0.036,-0.014,,0.0202703,-178.254,,2.02703,-0.178254,,,,7.85398e-5
Test1,2-Recover,119.337,1.752,0.024,-0.000,,0.0135135,0,,1.35135,0,,,,7.85398e-5
Test1,2-Recover,119.670,1.764,0.012,-0.007,,0.00675676,-89.1268,,0.675676,-0.0891268,,,,7.85398e-5
Test1,2-Recover,120.003,1.776,-0,-0.020,,0,-254.648,,0,-0.254648,,,,7.85398e-5
Test1,3-Compress,120.313,1.767,0.009,-0.007,,0.00506757,-89.1268,,0.506757,-0.0891268,,,,7.85398e-5
Test1,3-Compress,120.647,1.755,0.021,-0.007,,0.0118243,-89.1268,,1.18243,-0.0891268,,,,7.85398e-5
Test1,3-Compress,120.980,1.743,0.033,-0.000,,0.0185811,0,,1.85811,0,,,,7.85398e-5
Test1,3-Compress,121.313,1.732,0.044,-0.000,,0.0247748,0,,2.47748,0,,,,7.85398e-5
Test1,3-Compress,121.647,1.72,0.056,-0.000,,0.0315315,0,,3.15315,0,,,,7.85398e-5
Test1,3-Compress,121.980,1.708,0.068,-0.000,,0.0382883,0,,3.82883,0,,,,7.85398e-5
Test1,3-Compress,122.313,1.696,0.08,-0.000,,0.045045,0,,4.5045,0,,,,7.85398e-5
Test1,3-Compress,122.647,1.684,0.092,-0.000,,0.0518018,0,,5.18018,0,,,,7.85398e-5
Test1,3-Compress,122.980,1.672,0.104,-0.000,,0.0585586,0,,5.85586,0,,,,7.85398e-5
Test1,3-Compress,123.313,1.661,0.115,-0.000,,0.0647523,0,,6.47523,0,,,,7.85398e-5
Test1,3-Compress,123.647,1.648,0.128,-0.000,,0.0720721,0,,7.20721,0,,,,7.85398e-5
Test1,3-Compress,123.980,1.637,0.139,-0.000,,0.0782658,0,,7.82658,0,,,,7.85398e-5
Test1,3-Compress,124.313,1.625,0.151,-0.000,,0.0850225,0,,8.50225,0,,,,7.85398e-5
Test1,3-Compress,124.647,1.613,0.163,-0.000,,0.0917793,0,,9.17793,0,,,,7.85398e-5
Test1,3-Compress,124.980,1.601,0.175,-0.000,,0.098536,0,,9.8536,0,,,,7.85398e-5
Test1,3-Compress,125.313,1.589,0.187,-0.000,,0.105293,0,,10.5293,0,,,,7.85398e-5
Test1,3-Compress,125.647,1.577,0.199,-0.000,,0.11205,0,,11.205,0,,,,7.85398e-5
Test1,3-Compress,125.980,1.566,0.21,-0.000,,0.118243,0,,11.8243,0,,,,7.85398e-5
Test1,3-Compress,126.313,1.554,0.222,-0.000,,0.125,0,,12.5,0,,,,7.85398e-5
Test1,3-Compress,126.647,1.542,0.234,-0.000,,0.131757,0,,13.1757,0,,,,7.85398e-5
Test1,3-Compress,126.980,1.53,0.246,-0.000,,0.138514,0,,13.8514,0,,,,7.85398e-5
Test1,3-Compress,127.313,1.518,0.258,-0.000,,0.14527,0,,14.527,0,,,,7.85398e-5
Test1,3-Compress,127.647,1.506,0.27,-0.000,,0.152027,0,,15.2027,0,,,,7.85398e-5
Test1,3-Compress,127.980,1.494,0.282,-0.000,,0.158784,0,,15.8784,0,,,,7.85398e-5
Test1,3-Compress,128.313,1.482,0.294,-0.000,,0.165541,0,,16.5541,0,,,,7.85398e-5
Test1,3-Compress,128.647,1.47,0.306,-0.000,,0.172297,0,,17.2297,0,,,,7.85398e-5
Test1,3-Compress,128.980,1.459,0.317,-0.000,,0.178491,0,,17.8491,0,,,,7.85398e-5
Test1,3-Compress,129.313,1.447,0.329,-0.000,,0.185248,0,,18.5248,0,,,,7.85398e-5
Test1,3-Compress,129.647,1.435,0.341,-0.000,,0.192005,0,,19.2005,0,,,,7.85398e-5
Test1,3-Compress,129.980,1.423,0.353,-0.000,,0.198761,0,,19.8761,0,,,,7.85398e-5
Test1,3-Compress,130.313,1.411,0.365,0.007,,0.205518,89.1268,,20.5518,0.0891268,,,,7.85398e-5
Test1,3-Compress,130.647,1.399,0.377,0.007,,0.212275,89.1268,,21.2275,0.0891268,,,,7.85398e-5
Test1,3-Compress,130.980,1.387,0.389,-0.000,,0.219032,0,,21.9032,0,,,,7.85398e-5
Test1,3-Compress,131.313,1.376,0.4,0.007,,0.225225,89.1268,,22.5225,0.0891268,,,,7.85398e-5
Test1,3-Compress,131.647,1.364,0.412,0.007,,0.231982,89.1268,,23.1982,0.0891268,,,,7.85398e-5
Test1,3-Compress,131.980,1.352,0.424,0.007,,0.238739,89.1268,,23.8739,0.0891268,,,,7.85398e-5
Test1,3-Compress,132.313,1.34,0.436,0.007,,0.245495,89.1268,,24.5495,0.0891268,,,,7.85398e-5
Test1,3-Compress,132.647,1.328,0.448,0.007,,0.252252,89.1268,,25.2252,0.0891268,,,,7.85398e-5
Test1,3-Compress,132.980,1.316,0.46,-0.000,,0.259009,0,,25.9009,0,,,,7.85398e-5
Test1,3-Compress,133.313,1.304,0.472,-0.000,,0.265766,0,,26.5766,0,,,,7.85398e-5
Test1,3-Compress,133.647,1.292,0.484,-0.000,,0.272523,0,,27.2523,0,,,,7.85398e-5
Test1,3-Compress,133.980,1.281,0.495,0.007,,0.278716,89.1268,,27.8716,0.0891268,,,,7.85398e-5
Test1,3-Compress,134.313,1.269,0.507,0.014,,0.285473,178.254,,28.5473,0.178254,,,,7.85398e-5
Test1,3-Compress,134.647,1.257,0.519,0.027,,0.29223,343.775,,29.223,0.343775,,,,7.85398e-5
Test1,3-Compress,134.980,1.245,0.531,0.027,,0.298986,343.775,,29.8986,0.343775,,,,7.85398e-5
Test1,3-Compress,135.313,1.234,0.542,0.041,,0.30518,522.028,,30.518,0.522028,,,,7.85398e-5
Test1,3-Compress,135.647,1.221,0.555,0.027,,0.3125,343.775,,31.25,0.343775,,,,7.85398e-5
Test1,3-Compress,135.980,1.21,0.566,0.041,,0.318694,522.028,,31.8694,0.522028,,,,7.85398e-5
Test1,3-Compress,136.313,1.198,0.578,0.048,,0.32545,611.155,,32.545,0.611155,,,,7.85398e-5
Test1,3-Compress,136.647,1.186,0.59,0.041,,0.332207,522.028,,33.2207,0.522028,,,,7.85398e-5
Test1,3-Compress,136.980,1.174,0.602,0.027,,0.338964,343.775,,33.8964,0.343775,,,,7.85398e-5
Test1,3-Compress,137.313,1.162,0.614,0.041,,0.345721,522.028,,34.5721,0.522028,,,,7.85398e-5
Test1,3-Compress,137.647,1.15,0.626,0.048,,0.352477,611.155,,35.2477,0.611155,,,,7.85398e-5
Test1,3-Compress,137.980,1.139,0.637,0.054,,0.358671,687.549,,35.8671,0.687549,,,,7.85398e-5
Test1,3-Compress,138.313,1.127,0.649,0.054,,0.365428,687.549,,36.5428,0.687549,,,,7.85398e-5
Test1,3-Compress,138.647,1.115,0.661,0.048,,0.372185,611.155,,37.2185,0.611155,,,,7.85398e-5
Test1,3-Compress,138.980,1.103,0.673,0.054,,0.378941,687.549,,37.8941,0.687549,,,,7.85398e-5
Test1,3-Compress,139.313,1.091,0.685,0.054,,0.385698,687.549,,38.5698,0.687549,,,,7.85398e-5
Test1,3-Compress,139.647,1.079,0.697,0.054,,0.392455,687.549,,39.2455,0.687549,,,,7.85398e-5
Test1,3-Compress,139.980,1.067,0.709,0.054,,0.399212,687.549,,39.9212,0.687549,,,,7.85398e-5
Test1,3-Compress,140.313,1.055,0.721,0.054,,0.405968,687.549,,40.5968,0.687549,,,,7.85398e-5
Test1,3-Compress,140.647,1.043,0.733,0.048,,0.412725,611.155,,41.2725,0.611155,,,,7.85398e-5
Test1,3-Compress,140.980,1.032,0.744,0.054,,0.418919,687.549,,41.8919,0.687549,,,,7.85398e-5
Test1,3-Compress,141.313,1.02,0.756,0.054,,0.425676,687.549,,42.5676,0.687549,,,,7.85398e-5
Test1,3-Compress,141.647,1.008,0.768,0.054,,0.432432,687.549,,43.2432,0.687549,,,,7.85398e-5
Test1,3-Compress,141.980,0.996,0.78,0.054,,0.439189,687.549,,43.9189,0.687549,,,,7.85398e-5
Test1,3-Compress,142.313,0.984,0.792,0.048,,0.445946,611.155,,44.5946,0.611155,,,,7.85398e-5
Test1,3-Compress,142.647,0.972,0.804,0.054,,0.452703,687.549,,45.2703,0.687549,,,,7.85398e-5
Test1,3-Compress,142.980,0.96,0.816,0.054,,0.459459,687.549,,45.9459,0.687549,,,,7.85398e-5
Test1,3-Compress,143.313,0.949,0.827,0.054,,0.465653,687.549,,46.5653,0.687549,,,,7.85398e-5
Test1,3-Compress,143.647,0.937,0.839,0.054,,0.47241,687.549,,47.241,0.687549,,,,7.85398e-5
Test1,3-Compress,143.980,0.925,0.851,0.054,,0.479167,687.549,,47.9167,0.687549,,,,7.85398e-5
Test1,3-Compress,144.313,0.913,0.863,0.054,,0.485923,687.549,,48.5923,0.687549,,,,7.85398e-5
Test1,3-Compress,144.647,0.901,0.875,0.054,,0.49268,687.549,,49.268,0.687549,,,,7.85398e-5
Test1,3-Compress,144.980,0.889,0.887,0.068,,0.499437,865.803,,49.9437,0.865803,,,,7.85398e-5
Test1,3-Compress,145.313,0.877,0.899,0.068,,0.506194,865.803,,50.6194,0.865803,,,,7.85398e-5
Test1,3-Compress,145.647,0.865,0.911,0.061,,0.51295,776.676,,51.295,0.776676,,,,7.85398e-5
Test1,3-Compress,145.980,0.854,0.922,0.068,,0.519144,865.803,,51.9144,0.865803,,,,7.85398e-5
Test1,3-Compress,146.313,0.842,0.934,0.068,,0.525901,865.803,,52.5901,0.865803,,,,7.85398e-5
Test1,3-Compress,146.647,0.83,0.946,0.068,,0.532658,865.803,,53.2658,0.865803,,,,7.85398e-5
Test1,3-Compress,146.980,0.818,0.958,0.061,,0.539414,776.676,,53.9414,0.776676,,,,7.85398e-5
Test1,3-Compress,147.313,0.807,0.969,0.068,,0.545608,865.803,,54.5608,0.865803,,,,7.85398e-5
Test1,3-Compress,147.647,0.794,0.982,0.061,,0.552928,776.676,,55.2928,0.776676,,,,7.85398e-5
Test1,3-Compress,147.980,0.782,0.994,0.068,,0.559685,865.803,,55.9685,0.865803,,,,7.85398e-5
Test1,3-Compress,148.313,0.771,1.005,0.068,,0.565878,865.803,,56.5878,0.865803,,,,7.85398e-5
Test1,3-Compress,148.647,0.759,1.017,0.068,,0.572635,865.803,,57.2635,0.865803,,,,7.85398e-5
Test1,3-Compress,148.980,0.747,1.029,0.061,,0.579392,776.676,,57.9392,0.776676,,,,7.85398e-5
Test1,3-Compress,149.313,0.735,1.041,0.068,,0.586149,865.803,,58.6149,0.865803,,,,7.85398e-5
Test1,3-Compress,149.647,0.723,1.053,0.095,,0.592905,1209.58,,59.2905,1.20958,,,,7.85398e-5
Test1,3-Compress,149.980,0.711,1.065,0.102,,0.599662,1298.7,,59.9662,1.2987,,,,7.85398e-5
Test1,3-Recover,150.300,0.717,1.059,0.082,,0.596284,1044.06,,59.6284,1.04406,,,,7.85398e-5
Test1,3-Recover,150.633,0.729,1.047,0.082,,0.589527,1044.06,,58.9527,1.04406,,,,7.85398e-5
Test1,3-Recover,150.967,0.741,1.035,0.075,,0.58277,954.93,,58.277,0.95493,,,,7.85398e-5
Test1,3-Recover,151.300,0.753,1.023,0.068,,0.576014,865.803,,57.6014,0.865803,,,,7.85398e-5
Test1,3-Recover,151.633,0.765,1.011,0.075,,0.569257,954.93,,56.9257,0.95493,,,,7.85398e-5
Test1,3-Recover,151.967,0.777,0.999,0.082,,0.5625,1044.06,,56.25,1.04406,,,,7.85398e-5
Test1,3-Recover,152.300,0.788,0.988,0.088,,0.556306,1120.45,,55.6306,1.12045,,,,7.85398e-5
Test1,3-Recover,152.633,0.8,0.976,0.068,,0.54955,865.803,,54.955,0.865803,,,,7.85398e-5
Test1,3-Recover,152.967,0.812,0.964,0.068,,0.542793,865.803,,54.2793,0.865803,,,,7.85398e-5
Test1,3-Recover,153.300,0.824,0.952,0.061,,0.536036,776.676,,53.6036,0.776676,,,,7.85398e-5
Test1,3-Recover,153.633,0.836,0.94,0.061,,0.529279,776.676,,52.9279,0.776676,,,,7.85398e-5
Test1,3-Recover,153.967,0.848,0.928,0.054,,0.522523,687.549,,52.2523,0.687549,,,,7.85398e-5
Test1,3-Recover,154.300,0.86,0.916,0.054,,0.515766,687.549,,51.5766,0.687549,,,,7.85398e-5
Test1,3-Recover,154.633,0.871,0.905,0.054,,0.509572,687.549,,50.9572,0.687549,,,,7.85398e-5
Test1,3-Recover,154.967,0.883,0.893,0.054,,0.502815,687.549,,50.2815,0.687549,,,,7.85398e-5
Test1,3-Recover,155.300,0.895,0.881,0.054,,0.496059,687.549,,49.6059,0.687549,,,,7.85398e-5
Test1,3-Recover,155.633,0.907,0.869,0.054,,0.489302,687.549,,48.9302,0.687549,,,,7.85398e-5
Test1,3-Recover,155.967,0.919,0.857,0.054,,0.482545,687.549,,48.2545,0.687549,,,,7.85398e-5
Test1,3-Recover,156.300,0.931,0.845,0.054,,0.475788,687.549,,47.5788,0.687549,,,,7.85398e-5
Test1,3-Recover,156.633,0.942,0.834,0.054,,0.469595,687.549,,46.9595,0.687549,,,,7.85398e-5
Test1,3-Recover,156.967,0.955,0.821,0.054,,0.462275,687.549,,46.2275,0.687549,,,,7.85398e-5
Test1,3-Recover,157.300,0.966,0.81,0.054,,0.456081,687.549,,45.6081,0.687549,,,,7.85398e-5
Test1,3-Recover,157.633,0.978,0.798,0.054,,0.449324,687.549,,44.9324,0.687549,,,,7.85398e-5
Test1,3-Recover,157.967,0.99,0.786,0.048,,0.442568,611.155,,44.2568,0.611155,,,,7.85398e-5
Test1,3-Recover,158.300,1.002,0.774,0.034,,0.435811,432.902,,43.5811,0.432902,,,,7.85398e-5
Test1,3-Recover,158.633,1.014,0.762,0.048,,0.429054,611.155,,42.9054,0.611155,,,,7.85398e-5
Test1,3-Recover,158.967,1.026,0.75,0.048,,0.422297,611.155,,42.2297,0.611155,,,,7.85398e-5
Test1,3-Recover,159.300,1.038,0.738,0.027,,0.415541,343.775,,41.5541,0.343775,,,,7.85398e-5
Test1,3-Recover,159.633,1.049,0.727,0.048,,0.409347,611.155,,40.9347,0.611155,,,,7.85398e-5
Test1,3-Recover,159.967,1.061,0.715,0.041,,0.40259,522.028,,40.259,0.522028,,,,7.85398e-5
Test1,3-Recover,160.300,1.073,0.703,0.048,,0.395833,611.155,,39.5833,0.611155,,,,7.85398e-5
Test1,3-Recover,160.633,1.085,0.691,0.048,,0.389077,611.155,,38.9077,0.611155,,,,7.85398e-5
Test1,3-Recover,160.967,1.097,0.679,0.041,,0.38232,522.028,,38.232,0.522028,,,,7.85398e-5
Test1,3-Recover,161.300,1.109,0.667,0.027,,0.375563,343.775,,37.5563,0.343775,,,,7.85398e-5
Test1,3-Recover,161.633,1.121,0.655,0.027,,0.368806,343.775,,36.8806,0.343775,,,,7.85398e-5
Test1,3-Recover,161.967,1.133,0.643,0.020,,0.36205,254.648,,36.205,0.254648,,,,7.85398e-5
Test1,3-Recover,162.300,1.144,0.632,0.020,,0.355856,254.648,,35.5856,0.254648,,,,7.85398e-5
Test1,3-Recover,162.633,1.156,0.62,0.020,,0.349099,254.648,,34.9099,0.254648,,,,7.85398e-5
Test1,3-Recover,162.967,1.168,0.608,0.014,,0.342342,178.254,,34.2342,0.178254,,,,7.85398e-5
Test1,3-Recover,163.300,1.18,0.596,0.007,,0.335586,89.1268,,33.5586,0.0891268,,,,7.85398e-5
Test1,3-Recover,163.633,1.192,0.584,0.007,,0.328829,89.1268,,32.8829,0.0891268,,,,7.85398e-5
Test1,3-Recover,163.967,1.204,0.572,0.007,,0.322072,89.1268,,32.2072,0.0891268,,,,7.85398e-5
Test1,3-Recover,164.300,1.216,0.56,-0.000,,0.315315,0,,31.5315,0,,,,7.85398e-5
Test1,3-Recover,164.633,1.227,0.549,-0.000,,0.309122,0,,30.9122,0,,,,7.85398e-5
Test1,3-Recover,164.967,1.239,0.537,-0.000,,0.302365,0,,30.2365,0,,,,7.85398e-5
Test1,3-Recover,165.300,1.251,0.525,-0.000,,0.295608,0,,29.5608,0,,,,7.85398e-5
Test1,3-Recover,165.633,1.263,0.513,-0.000,,0.288851,0,,28.8851,0,,,,7.85398e-5
Test1,3-Recover,165.967,1.275,0.501,-0.000,,0.282095,0,,28.2095,0,,,,7.85398e-5
Test1,3-Recover,166.300,1.287,0.489,-0.000,,0.275338,0,,27.5338,0,,,,7.85398e-5
Test1,3-Recover,166.633,1.298,0.478,0.007,,0.269144,89.1268,,26.9144,0.0891268,,,,7.85398e-5
Test1,3-Recover,166.967,1.311,0.465,0.007,,0.261824,89.1268,,26.1824,0.0891268,,,,7.85398e-5
Test1,3-Recover,167.300,1.322,0.454,-0.000,,0.255631,0,,25.5631,0,,,,7.85398e-5
Test1,3-Recover,167.633,1.334,0.442,-0.000,,0.248874,0,,24.8874,0,,,,7.85398e-5
Test1,3-Recover,167.967,1.346,0.43,0.014,,0.242117,178.254,,24.2117,0.178254,,,,7.85398e-5
Test1,3-Recover,168.300,1.358,0.418,-0.000,,0.23536,0,,23.536,0,,,,7.85398e-5
Test1,3-Recover,168.633,1.37,0.406,-0.000,,0.228604,0,,22.8604,0,,,,7.85398e-5
Test1,3-Recover,168.967,1.382,0.394,0.007,,0.221847,89.1268,,22.1847,0.0891268,,,,7.85398e-5
Test1,3-Recover,169.300,1.393,0.383,-0.000,,0.215653,0,,21.5653,0,,,,7.85398e-5
Test1,3-Recover,169.633,1.405,0.371,-0.000,,0.208896,0,,20.8896,0,,,,7.85398e-5
Test1,3-Recover,169.967,1.417,0.359,-0.000,,0.20214,0,,20.214,0,,,,7.85398e-5
Test1,3-Recover,170.300,1.429,0.347,-0.000,,0.195383,0,,19.5383,0,,,,7.85398e-5
Test1,3-Recover,170.633,1.441,0.335,-0.000,,0.188626,0,,18.8626,0,,,,7.85398e-5
Test1,3-Recover,170.967,1.453,0.323,-0.000,,0.181869,0,,18.1869,0,,,,7.85398e-5
Test1,3-Recover,171.300,1.465,0.311,-0.000,,0.175113,0,,17.5113,0,,,,7.85398e-5
Test1,3-Recover,171.633,1.476,0.3,-0.000,,0.168919,0,,16.8919,0,,,,7.85398e-5
Test1,3-Recover,171.967,1.488,0.288,-0.000,,0.162162,0,,16.2162,0,,,,7.85398e-5
Test1,3-Recover,172.300,1.5,0.276,-0.000,,0.155405,0,,15.5405,0,,,,7.85398e-5
Test1,3-Recover,172.633,1.512,0.264,-0.000,,0.148649,0,,14.8649,0,,,,7.85398e-5
Test1,3-Recover,172.967,1.524,0.252,0.007,,0.141892,89.1268,,14.1892,0.0891268,,,,7.85398e-5
Test1,3-Recover,173.300,1.536,0.24,-0.000,,0.135135,0,,13.5135,0,,,,7.85398e-5
Test1,3-Recover,173.633,1.548,0.228,-0.000,,0.128378,0,,12.8378,0,,,,7.85398e-5
Test1,3-Recover,173.967,1.56,0.216,-0.000,,0.121622,0,,12.1622,0,,,,7.85398e-5
Test1,3-Recover,174.300,1.571,0.205,-0.007,,0.115428,-89.1268,,11.5428,-0.0891268,,,,7.85398e-5
Test1,3-Recover,174.633,1.583,0.193,-0.000,,0.108671,0,,10.8671,0,,,,7.85398e-5
Test1,3-Recover,174.967,1.595,0.181,-0.000,,0.101914,0,,10.1914,0,,,,7.85398e-5
Test1,3-Recover,175.300,1.607,0.169,-0.000,,0.0951577,0,,9.51577,0,,,,7.85398e-5
Test1,3-Recover,175.633,1.619,0.157,-0.000,,0.0884009,0,,8.84009,0,,,,7.85398e-5
Test1,3-Recover,175.967,1.631,0.145,-0.000,,0.0816441,0,,8.16441,0,,,,7.85398e-5
Test1,3-Recover,176.300,1.643,0.133,-0.000,,0.0748874,0,,7.48874,0,,,,7.85398e-5
Test1,3-Recover,176.633,1.654,0.122,-0.000,,0.0686937,0,,6.86937,0,,,,7.85398e-5
Test1,3-Recover,176.967,1.667,0.109,-0.000,,0.0613739,0,,6.13739,0,,,,7.85398e-5
Test1,3-Recover,177.300,1.678,0.098,-0.000,,0.0551802,0,,5.51802,0,,,,7.85398e-5
Test1,3-Recover,177.633,1.69,0.086,-0.000,,0.0484234,0,,4.84234,0,,,,7.85398e-5
Test1,3-Recover,177.967,1.702,0.074,-0.014,,0.0416667,-178.254,,4.16667,-0.178254,,,,7.85398e-5
Test1,3-Recover,178.300,1.714,0.062,-0.027,,0.0349099,-343.775,,3.49099,-0.343775,,,,7.85398e-5
Test1,3-Recover,178.633,1.726,0.05,-0.020,,0.0281532,-254.648,,2.81532,-0.254648,,,,7.85398e-5
Test1,3-Recover,178.967,1.738,0.038,-0.000,,0.0213964,0,,2.13964,0,,,,7.85398e-5
Test1,3-Recover,179.300,1.749,0.027,-0.000,,0.0152027,0,,1.52027,0,,,,7.85398e-5
Test1,3-Recover,179.633,1.761,0.015,-0.027,,0.00844595,-343.775,,0.844595,-0.343775,,,,7.85398e-5
Test1,3-Recover,179.967,1.773,0.003,-0.007,,0.00168919,-89.1268,,0.168919,-0.0891268,,,,7.85398e-5
Test1,3-Recover,180.100,1.776,-0,-0.007,,0,-89.1268,,0,-0.0891268,,,,7.85398e-5