File: data/gamma_1-1_1.csv
SetName,Cycle,Time_S,Size_mm,Displacement_mm,Force_N,,Strain,Stress(Pascal),,%Strain,Stress(kPa),,,,Area(m^2)
Test1,1-Compress,0.000,4.25,-0,-0.007,,0,-89.1268,,0,-0.0891268,,,,7.85398e-5
Test1,1-Compress,0.333,4.223,0.027,0.000,,0.00635294,0,,0.635294,0,,,,7.85398e-5
Test1,1-Compress,0.667,4.194,0.056,0.014,,0.0131765,178.254,,1.31765,0.178254,,,,7.85398e-5
Test1,1-Compress,1.000,4.166,0.084,0.000,,0.0197647,0,,1.97647,0,,,,7.85398e-5
Test1,1-Compress,1.333,4.138,0.112,0.007,,0.0263529,89.1268,,2.63529,0.0891268,,,,7.85398e-5
Test1,1-Compress,1.667,4.109,0.141,-0.007,,0.0331765,-89.1268,,3.31765,-0.0891268,,,,7.85398e-5
Test1,1-Compress,2.000,4.081,0.169,0.014,,0.0397647,178.254,,3.97647,0.178254,,,,7.85398e-5
Test1,1-Compress,2.333,4.052,0.198,-0.007,,0.0465882,-89.1268,,4.65882,-0.0891268,,,,7.85398e-5
Test1,1-Compress,2.667,4.024,0.226,0.007,,0.0531765,89.1268,,5.31765,0.0891268,,,,7.85398e-5
Test1,1-Compress,3.000,3.996,0.254,-0.007,,0.0597647,-89.1268,,5.97647,-0.0891268,,,,7.85398e-5
Test1,1-Compress,3.333,3.967,0.283,0.014,,0.0665882,178.254,,6.65882,0.178254,,,,7.85398e-5
Test1,1-Compress,3.667,3.939,0.311,0.027,,0.0731765,343.775,,7.31765,0.343775,,,,7.85398e-5
Test1,1-Compress,4.000,3.911,0.339,0.007,,0.0797647,89.1268,,7.97647,0.0891268,,,,7.85398e-5
Test1,1-Compress,4.333,3.882,0.368,0.027,,0.0865882,343.775,,8.65882,0.343775,,,,7.85398e-5
Test1,1-Compress,4.667,3.853,0.397,0.027,,0.0934118,343.775,,9.34118,0.343775,,,,7.85398e-5
Test1,1-Compress,5.000,3.825,0.425,-0.007,,0.1,-89.1268,,10,-0.0891268,,,,7.85398e-5
Test1,1-Compress,5.333,3.797,0.453,0.014,,0.106588,178.254,,10.6588,0.178254,,,,7.85398e-5
Test1,1-Compress,5.667,3.768,0.482,0.014,,0.113412,178.254,,11.3412,0.178254,,,,7.85398e-5
Test1,1-Compress,6.000,3.74,0.51,0.014,,0.12,178.254,,12,0.178254,,,,7.85398e-5
Test1,1-Compress,6.333,3.712,0.538,0.027,,0.126588,343.775,,12.6588,0.343775,,,,7.85398e-5
Test1,1-Compress,6.667,3.683,0.567,0.020,,0.133412,254.648,,13.3412,0.254648,,,,7.85398e-5
Test1,1-Compress,7.000,3.655,0.595,0.027,,0.14,343.775,,14,0.343775,,,,7.85398e-5
Test1,1-Compress,7.333,3.627,0.623,0.027,,0.146588,343.775,,14.6588,0.343775,,,,7.85398e-5
Test1,1-Compress,7.667,3.598,0.652,0.020,,0.153412,254.648,,15.3412,0.254648,,,,7.85398e-5
Test1,1-Compress,8.000,3.57,0.68,0.027,,0.16,343.775,,16,0.343775,,,,7.85398e-5
Test1,1-Compress,8.333,3.542,0.708,0.027,,0.166588,343.775,,16.6588,0.343775,,,,7.85398e-5
Test1,1-Compress,8.667,3.513,0.737,0.027,,0.173412,343.775,,17.3412,0.343775,,,,7.85398e-5
Test1,1-Compress,9.000,3.485,0.765,0.027,,0.18,343.775,,18,0.343775,,,,7.85398e-5
Test1,1-Compress,9.333,3.457,0.793,0.027,,0.186588,343.775,,18.6588,0.343775,,,,7.85398e-5
Test1,1-Compress,9.667,3.428,0.822,0.027,,0.193412,343.775,,19.3412,0.343775,,,,7.85398e-5
Test1,1-Compress,10.000,3.4,0.85,0.027,,0.2,343.775,,20,0.343775,,,,7.85398e-5
Test1,1-Compress,10.333,3.372,0.878,0.027,,0.206588,343.775,,20.6588,0.343775,,,,7.85398e-5
Test1,1-Compress,10.667,3.343,0.907,0.027,,0.213412,343.775,,21.3412,0.343775,,,,7.85398e-5
Test1,1-Compress,11.000,3.315,0.935,0.027,,0.22,343.775,,22,0.343775,,,,7.85398e-5
Test1,1-Compress,11.333,3.286,0.964,0.027,,0.226824,343.775,,22.6824,0.343775,,,,7.85398e-5
Test1,1-Compress,11.667,3.258,0.992,0.027,,0.233412,343.775,,23.3412,0.343775,,,,7.85398e-5
Test1,1-Compress,12.000,3.229,1.021,0.027,,0.240235,343.775,,24.0235,0.343775,,,,7.85398e-5
Test1,1-Compress,12.333,3.201,1.049,0.027,,0.246824,343.775,,24.6824,0.343775,,,,7.85398e-5
Test1,1-Compress,12.667,3.173,1.077,0.027,,0.253412,343.775,,25.3412,0.343775,,,,7.85398e-5
Test1,1-Compress,13.000,3.144,1.106,0.027,,0.260235,343.775,,26.0235,0.343775,,,,7.85398e-5
Test1,1-Compress,13.333,3.116,1.134,0.027,,0.266824,343.775,,26.6824,0.343775,,,,7.85398e-5
Test1,1-Compress,13.667,3.087,1.163,0.034,,0.273647,432.902,,27.3647,0.432902,,,,7.85398e-5
Test1,1-Compress,14.000,3.059,1.191,0.027,,0.280235,343.775,,28.0235,0.343775,,,,7.85398e-5
Test1,1-Compress,14.333,3.031,1.219,0.027,,0.286824,343.775,,28.6824,0.343775,,,,7.85398e-5
Test1,1-Compress,14.667,3.002,1.248,0.027,,0.293647,343.775,,29.3647,0.343775,,,,7.85398e-5
Test1,1-Compress,15.000,2.974,1.276,0.027,,0.300235,343.775,,30.0235,0.343775,,,,7.85398e-5
Test1,1-Compress,15.333,2.946,1.304,0.027,,0.306824,343.775,,30.6824,0.343775,,,,7.85398e-5
Test1,1-Compress,15.667,2.917,1.333,0.027,,0.313647,343.775,,31.3647,0.343775,,,,7.85398e-5
Test1,1-Compress,16.000,2.889,1.361,0.027,,0.320235,343.775,,32.0235,0.343775,,,,7.85398e-5
Test1,1-Compress,16.333,2.861,1.389,0.027,,0.326824,343.775,,32.6824,0.343775,,,,7.85398e-5
Test1,1-Compress,16.667,2.832,1.418,0.027,,0.333647,343.775,,33.3647,0.343775,,,,7.85398e-5
Test1,1-Compress,17.000,2.804,1.446,0.027,,0.340235,343.775,,34.0235,0.343775,,,,7.85398e-5
Test1,1-Compress,17.333,2.776,1.474,0.027,,0.346824,343.775,,34.6824,0.343775,,,,7.85398e-5
Test1,1-Compress,17.667,2.747,1.503,0.034,,0.353647,432.902,,35.3647,0.432902,,,,7.85398e-5
Test1,1-Compress,18.000,2.719,1.531,0.034,,0.360235,432.902,,36.0235,0.432902,,,,7.85398e-5
Test1,1-Compress,18.333,2.69,1.56,0.034,,0.367059,432.902,,36.7059,0.432902,,,,7.85398e-5
Test1,1-Compress,18.667,2.662,1.588,0.027,,0.373647,343.775,,37.3647,0.343775,,,,7.85398e-5
Test1,1-Compress,19.000,2.633,1.617,0.034,,0.380471,432.902,,38.0471,0.432902,,,,7.85398e-5
Test1,1-Compress,19.333,2.606,1.644,0.034,,0.386824,432.902,,38.6824,0.432902,,,,7.85398e-5
Test1,1-Compress,19.667,2.577,1.673,0.034,,0.393647,432.902,,39.3647,0.432902,,,,7.85398e-5
Test1,1-Compress,20.000,2.548,1.702,0.027,,0.400471,343.775,,40.0471,0.343775,,,,7.85398e-5
Test1,1-Compress,20.333,2.521,1.729,0.034,,0.406824,432.902,,40.6824,0.432902,,,,7.85398e-5
Test1,1-Compress,20.667,2.492,1.758,0.027,,0.413647,343.775,,41.3647,0.343775,,,,7.85398e-5
Test1,1-Compress,21.000,2.463,1.787,0.027,,0.420471,343.775,,42.0471,0.343775,,,,7.85398e-5
Test1,1-Compress,21.333,2.435,1.815,0.041,,0.427059,522.028,,42.7059,0.522028,,,,7.85398e-5
Test1,1-Compress,21.667,2.406,1.844,0.041,,0.433882,522.028,,43.3882,0.522028,,,,7.85398e-5
Test1,1-Compress,22.000,2.378,1.872,0.048,,0.440471,611.155,,44.0471,0.611155,,,,7.85398e-5
Test1,1-Compress,22.333,2.35,1.9,0.061,,0.447059,776.676,,44.7059,0.776676,,,,7.85398e-5
Test1,1-Compress,22.667,2.321,1.929,0.054,,0.453882,687.549,,45.3882,0.687549,,,,7.85398e-5
Test1,1-Compress,23.000,2.293,1.957,0.061,,0.460471,776.676,,46.0471,0.776676,,,,7.85398e-5
Test1,1-Compress,23.333,2.265,1.985,0.068,,0.467059,865.803,,46.7059,0.865803,,,,7.85398e-5
Test1,1-Compress,23.667,2.236,2.014,0.061,,0.473882,776.676,,47.3882,0.776676,,,,7.85398e-5
Test1,1-Compress,24.000,2.208,2.042,0.068,,0.480471,865.803,,48.0471,0.865803,,,,7.85398e-5
Test1,1-Compress,24.333,2.18,2.07,0.068,,0.487059,865.803,,48.7059,0.865803,,,,7.85398e-5
Test1,1-Compress,24.667,2.151,2.099,0.075,,0.493882,954.93,,49.3882,0.95493,,,,7.85398e-5
Test1,1-Compress,25.000,2.123,2.127,0.054,,0.500471,687.549,,50.0471,0.687549,,,,7.85398e-5
Test1,1-Compress,25.333,2.095,2.155,0.082,,0.507059,1044.06,,50.7059,1.04406,,,,7.85398e-5
Test1,1-Compress,25.667,2.066,2.184,0.061,,0.513882,776.676,,51.3882,0.776676,,,,7.85398e-5
Test1,1-Compress,26.000,2.037,2.213,0.061,,0.520706,776.676,,52.0706,0.776676,,,,7.85398e-5
Test1,1-Compress,26.333,2.01,2.24,0.082,,0.527059,1044.06,,52.7059,1.04406,,,,7.85398e-5
Test1,1-Compress,26.667,1.981,2.269,0.075,,0.533882,954.93,,53.3882,0.95493,,,,7.85398e-5
Test1,1-Compress,27.000,1.952,2.298,0.082,,0.540706,1044.06,,54.0706,1.04406,,,,7.85398e-5
Test1,1-Compress,27.333,1.925,2.325,0.082,,0.547059,1044.06,,54.7059,1.04406,,,,7.85398e-5
Test1,1-Compress,27.667,1.896,2.354,0.082,,0.553882,1044.06,,55.3882,1.04406,,,,7.85398e-5
Test1,1-Compress,28.000,1.867,2.383,0.082,,0.560706,1044.06,,56.0706,1.04406,,,,7.85398e-5
Test1,1-Compress,28.333,1.839,2.411,0.082,,0.567294,1044.06,,56.7294,1.04406,,,,7.85398e-5
Test1,1-Compress,28.667,1.81,2.44,0.082,,0.574118,1044.06,,57.4118,1.04406,,,,7.85398e-5
Test1,1-Compress,29.000,1.782,2.468,0.082,,0.580706,1044.06,,58.0706,1.04406,,,,7.85398e-5
Test1,1-Compress,29.333,1.754,2.496,0.082,,0.587294,1044.06,,58.7294,1.04406,,,,7.85398e-5
Test1,1-Compress,29.667,1.725,2.525,0.082,,0.594118,1044.06,,59.4118,1.04406,,,,7.85398e-5
Test1,1-Compress,30.000,1.7,2.55,0.082,,0.6,1044.06,,60,1.04406,,,,7.85398e-5
Test1,1-Recover,30.333,1.726,2.524,0.082,,0.593882,1044.06,,59.3882,1.04406,,,,7.85398e-5
Test1,1-Recover,30.667,1.755,2.495,0.082,,0.587059,1044.06,,58.7059,1.04406,,,,7.85398e-5
Test1,1-Recover,31.000,1.783,2.467,0.082,,0.580471,1044.06,,58.0471,1.04406,,,,7.85398e-5
Test1,1-Recover,31.333,1.811,2.439,0.082,,0.573882,1044.06,,57.3882,1.04406,,,,7.85398e-5
Test1,1-Recover,31.667,1.84,2.41,0.082,,0.567059,1044.06,,56.7059,1.04406,,,,7.85398e-5
Test1,1-Recover,32.000,1.868,2.382,0.082,,0.560471,1044.06,,56.0471,1.04406,,,,7.85398e-5
Test1,1-Recover,32.333,1.896,2.354,0.082,,0.553882,1044.06,,55.3882,1.04406,,,,7.85398e-5
Test1,1-Recover,32.667,1.925,2.325,0.061,,0.547059,776.676,,54.7059,0.776676,,,,7.85398e-5
Test1,1-Recover,33.000,1.953,2.297,0.068,,0.540471,865.803,,54.0471,0.865803,,,,7.85398e-5
Test1,1-Recover,33.333,1.981,2.269,0.075,,0.533882,954.93,,53.3882,0.95493,,,,7.85398e-5
Test1,1-Recover,33.667,2.01,2.24,0.075,,0.527059,954.93,,52.7059,0.95493,,,,7.85398e-5
Test1,1-Recover,34.000,2.038,2.212,0.061,,0.520471,776.676,,52.0471,0.776676,,,,7.85398e-5
Test1,1-Recover,34.333,2.066,2.184,0.041,,0.513882,522.028,,51.3882,0.522028,,,,7.85398e-5
Test1,1-Recover,34.667,2.095,2.155,0.048,,0.507059,611.155,,50.7059,0.611155,,,,7.85398e-5
Test1,1-Recover,35.000,2.123,2.127,0.041,,0.500471,522.028,,50.0471,0.522028,,,,7.85398e-5
Test1,1-Recover,35.333,2.151,2.099,0.048,,0.493882,611.155,,49.3882,0.611155,,,,7.85398e-5
Test1,1-Recover,35.667,2.18,2.07,0.034,,0.487059,432.902,,48.7059,0.432902,,,,7.85398e-5
Test1,1-Recover,36.000,2.208,2.042,0.027,,0.480471,343.775,,48.0471,0.343775,,,,7.85398e-5
Test1,1-Recover,36.333,2.236,2.014,0.027,,0.473882,343.775,,47.3882,0.343775,,,,7.85398e-5
Test1,1-Recover,36.667,2.265,1.985,0.027,,0.467059,343.775,,46.7059,0.343775,,,,7.85398e-5
Test1,1-Recover,37.000,2.294,1.956,0.027,,0.460235,343.775,,46.0235,0.343775,,,,7.85398e-5
Test1,1-Recover,37.333,2.322,1.928,0.034,,0.453647,432.902,,45.3647,0.432902,,,,7.85398e-5
Test1,1-Recover,37.667,2.351,1.899,0.034,,0.446824,432.902,,44.6824,0.432902,,,,7.85398e-5
Test1,1-Recover,38.000,2.379,1.871,0.034,,0.440235,432.902,,44.0235,0.432902,,,,7.85398e-5
Test1,1-Recover,38.333,2.407,1.843,0.027,,0.433647,343.775,,43.3647,0.343775,,,,7.85398e-5
Test1,1-Recover,38.667,2.436,1.814,0.034,,0.426824,432.902,,42.6824,0.432902,,,,7.85398e-5
Test1,1-Recover,39.000,2.464,1.786,0.027,,0.420235,343.775,,42.0235,0.343775,,,,7.85398e-5
Test1,1-Recover,39.333,2.492,1.758,0.027,,0.413647,343.775,,41.3647,0.343775,,,,7.85398e-5
Test1,1-Recover,39.667,2.521,1.729,0.027,,0.406824,343.775,,40.6824,0.343775,,,,7.85398e-5
Test1,1-Recover,40.000,2.549,1.701,0.027,,0.400235,343.775,,40.0235,0.343775,,,,7.85398e-5
Test1,1-Recover,40.333,2.577,1.673,0.027,,0.393647,343.775,,39.3647,0.343775,,,,7.85398e-5
Test1,1-Recover,40.667,2.606,1.644,0.027,,0.386824,343.775,,38.6824,0.343775,,,,7.85398e-5
Test1,1-Recover,41.000,2.634,1.616,0.027,,0.380235,343.775,,38.0235,0.343775,,,,7.85398e-5
Test1,1-Recover,41.333,2.662,1.588,0.027,,0.373647,343.775,,37.3647,0.343775,,,,7.85398e-5
Test1,1-Recover,41.667,2.691,1.559,0.027,,0.366824,343.775,,36.6824,0.343775,,,,7.85398e-5
Test1,1-Recover,42.000,2.719,1.531,0.027,,0.360235,343.775,,36.0235,0.343775,,,,7.85398e-5
Test1,1-Recover,42.333,2.747,1.503,0.027,,0.353647,343.775,,35.3647,0.343775,,,,7.85398e-5
Test1,1-Recover,42.667,2.776,1.474,0.027,,0.346824,343.775,,34.6824,0.343775,,,,7.85398e-5
Test1,1-Recover,43.000,2.804,1.446,0.027,,0.340235,343.775,,34.0235,0.343775,,,,7.85398e-5
Test1,1-Recover,43.333,2.832,1.418,0.027,,0.333647,343.775,,33.3647,0.343775,,,,7.85398e-5
Test1,1-Recover,43.667,2.861,1.389,0.027,,0.326824,343.775,,32.6824,0.343775,,,,7.85398e-5
Test1,1-Recover,44.000,2.889,1.361,0.027,,0.320235,343.775,,32.0235,0.343775,,,,7.85398e-5
Test1,1-Recover,44.333,2.918,1.332,0.034,,0.313412,432.902,,31.3412,0.432902,,,,7.85398e-5
Test1,1-Recover,44.667,2.947,1.303,0.027,,0.306588,343.775,,30.6588,0.343775,,,,7.85398e-5
Test1,1-Recover,45.000,2.975,1.275,0.027,,0.3,343.775,,30,0.343775,,,,7.85398e-5
Test1,1-Recover,45.333,3.003,1.247,0.020,,0.293412,254.648,,29.3412,0.254648,,,,7.85398e-5
Test1,1-Recover,45.667,3.032,1.218,0.027,,0.286588,343.775,,28.6588,0.343775,,,,7.85398e-5
Test1,1-Recover,46.000,3.06,1.19,0.034,,0.28,432.902,,28,0.432902,,,,7.85398e-5
Test1,1-Recover,46.333,3.088,1.162,0.027,,0.273412,343.775,,27.3412,0.343775,,,,7.85398e-5
Test1,1-Recover,46.667,3.117,1.133,0.027,,0.266588,343.775,,26.6588,0.343775,,,,7.85398e-5
Test1,1-Recover,47.000,3.145,1.105,0.027,,0.26,343.775,,26,0.343775,,,,7.85398e-5
Test1,1-Recover,47.333,3.173,1.077,0.027,,0.253412,343.775,,25.3412,0.343775,,,,7.85398e-5
Test1,1-Recover,47.667,3.202,1.048,0.027,,0.246588,343.775,,24.6588,0.343775,,,,7.85398e-5
Test1,1-Recover,48.000,3.23,1.02,0.027,,0.24,343.775,,24,0.343775,,,,7.85398e-5
Test1,1-Recover,48.333,3.258,0.992,0.027,,0.233412,343.775,,23.3412,0.343775,,,,7.85398e-5
Test1,1-Recover,48.667,3.287,0.963,0.027,,0.226588,343.775,,22.6588,0.343775,,,,7.85398e-5
Test1,1-Recover,49.000,3.315,0.935,0.027,,0.22,343.775,,22,0.343775,,,,7.85398e-5
Test1,1-Recover,49.333,3.343,0.907,0.027,,0.213412,343.775,,21.3412,0.343775,,,,7.85398e-5
Test1,1-Recover,49.667,3.372,0.878,0.027,,0.206588,343.775,,20.6588,0.343775,,,,7.85398e-5
Test1,1-Recover,50.000,3.4,0.85,0.027,,0.2,343.775,,20,0.343775,,,,7.85398e-5
Test1,1-Recover,50.333,3.428,0.822,0.027,,0.193412,343.775,,19.3412,0.343775,,,,7.85398e-5
Test1,1-Recover,50.667,3.457,0.793,0.027,,0.186588,343.775,,18.6588,0.343775,,,,7.85398e-5
Test1,1-Recover,51.000,3.485,0.765,0.027,,0.18,343.775,,18,0.343775,,,,7.85398e-5
Test1,1-Recover,51.333,3.514,0.736,0.007,,0.173176,89.1268,,17.3176,0.0891268,,,,7.85398e-5
Test1,1-Recover,51.667,3.542,0.708,0.027,,0.166588,343.775,,16.6588,0.343775,,,,7.85398e-5
Test1,1-Recover,52.000,3.571,0.679,0.027,,0.159765,343.775,,15.9765,0.343775,,,,7.85398e-5
Test1,1-Recover,52.333,3.599,0.651,0.027,,0.153176,343.775,,15.3176,0.343775,,,,7.85398e-5
Test1,1-Recover,52.667,3.627,0.623,0.027,,0.146588,343.775,,14.6588,0.343775,,,,7.85398e-5
Test1,1-Recover,53.000,3.656,0.594,0.027,,0.139765,343.775,,13.9765,0.343775,,,,7.85398e-5
Test1,1-Recover,53.333,3.684,0.566,0.020,,0.133176,254.648,,13.3176,0.254648,,,,7.85398e-5
Test1,1-Recover,53.667,3.713,0.537,0.020,,0.126353,254.648,,12.6353,0.254648,,,,7.85398e-5
Test1,1-Recover,54.000,3.741,0.509,0.014,,0.119765,178.254,,11.9765,0.178254,,,,7.85398e-5
Test1,1-Recover,54.333,3.769,0.481,0.020,,0.113176,254.648,,11.3176,0.254648,,,,7.85398e-5
Test1,1-Recover,54.667,3.798,0.452,0.027,,0.106353,343.775,,10.6353,0.343775,,,,7.85398e-5
Test1,1-Recover,55.000,3.826,0.424,0.014,,0.0997647,178.254,,9.97647,0.178254,,,,7.85398e-5
Test1,1-Recover,55.333,3.854,0.396,0.027,,0.0931765,343.775,,9.31765,0.343775,,,,7.85398e-5
Test1,1-Recover,55.667,3.883,0.367,0.027,,0.0863529,343.775,,8.63529,0.343775,,,,7.85398e-5
Test1,1-Recover,56.000,3.911,0.339,0.027,,0.0797647,343.775,,7.97647,0.343775,,,,7.85398e-5
Test1,1-Recover,56.333,3.939,0.311,0.027,,0.0731765,343.775,,7.31765,0.343775,,,,7.85398e-5
Test1,1-Recover,56.667,3.968,0.282,0.027,,0.0663529,343.775,,6.63529,0.343775,,,,7.85398e-5
Test1,1-Recover,57.000,3.996,0.254,0.020,,0.0597647,254.648,,5.97647,0.254648,,,,7.85398e-5
Test1,1-Recover,57.333,4.024,0.226,0.014,,0.0531765,178.254,,5.31765,0.178254,,,,7.85398e-5
Test1,1-Recover,57.667,4.053,0.197,0.014,,0.0463529,178.254,,4.63529,0.178254,,,,7.85398e-5
Test1,1-Recover,58.000,4.081,0.169,0.027,,0.0397647,343.775,,3.97647,0.343775,,,,7.85398e-5
Test1,1-Recover,58.333,4.109,0.141,0.007,,0.0331765,89.1268,,3.31765,0.0891268,,,,7.85398e-5
Test1,1-Recover,58.667,4.138,0.112,0.014,,0.0263529,178.254,,2.63529,0.178254,,,,7.85398e-5
Test1,1-Recover,59.000,4.166,0.084,0.014,,0.0197647,178.254,,1.97647,0.178254,,,,7.85398e-5
Test1,1-Recover,59.333,4.194,0.056,0.020,,0.0131765,254.648,,1.31765,0.254648,,,,7.85398e-5
Test1,1-Recover,59.667,4.223,0.027,0.027,,0.00635294,343.775,,0.635294,0.343775,,,,7.85398e-5
Test1,1-Recover,60.000,4.25,-0,0.007,,0,89.1268,,0,0.0891268,,,,7.85398e-5
Test1,2-Compress,60.317,4.227,0.023,0.027,,0.00541176,343.775,,0.541176,0.343775,,,,7.85398e-5
Test1,2-Compress,60.650,4.199,0.051,-0.007,,0.012,-89.1268,,1.2,-0.0891268,,,,7.85398e-5
Test1,2-Compress,60.983,4.171,0.079,0.014,,0.0185882,178.254,,1.85882,0.178254,,,,7.85398e-5
Test1,2-Compress,61.317,4.142,0.108,0.007,,0.0254118,89.1268,,2.54118,0.0891268,,,,7.85398e-5
Test1,2-Compress,61.650,4.113,0.137,0.014,,0.0322353,178.254,,3.22353,0.178254,,,,7.85398e-5
Test1,2-Compress,61.983,4.085,0.165,0.020,,0.0388235,254.648,,3.88235,0.254648,,,,7.85398e-5
Test1,2-Compress,62.317,4.056,0.194,0.020,,0.0456471,254.648,,4.56471,0.254648,,,,7.85398e-5
Test1,2-Compress,62.650,4.028,0.222,0.020,,0.0522353,254.648,,5.22353,0.254648,,,,7.85398e-5
Test1,2-Compress,62.983,4,0.25,0.020,,0.0588235,254.648,,5.88235,0.254648,,,,7.85398e-5
Test1,2-Compress,63.317,3.971,0.279,0.027,,0.0656471,343.775,,6.56471,0.343775,,,,7.85398e-5
Test1,2-Compress,63.650,3.943,0.307,0.027,,0.0722353,343.775,,7.22353,0.343775,,,,7.85398e-5
Test1,2-Compress,63.983,3.915,0.335,0.027,,0.0788235,343.775,,7.88235,0.343775,,,,7.85398e-5
Test1,2-Compress,64.317,3.886,0.364,0.020,,0.0856471,254.648,,8.56471,0.254648,,,,7.85398e-5
Test1,2-Compress,64.650,3.858,0.392,0.027,,0.0922353,343.775,,9.22353,0.343775,,,,7.85398e-5
Test1,2-Compress,64.983,3.83,0.42,0.027,,0.0988235,343.775,,9.88235,0.343775,,,,7.85398e-5
Test1,2-Compress,65.317,3.801,0.449,0.020,,0.105647,254.648,,10.5647,0.254648,,,,7.85398e-5
Test1,2-Compress,65.650,3.773,0.477,0.027,,0.112235,343.775,,11.2235,0.343775,,,,7.85398e-5
Test1,2-Compress,65.983,3.745,0.505,0.027,,0.118824,343.775,,11.8824,0.343775,,,,7.85398e-5
Test1,2-Compress,66.317,3.716,0.534,0.020,,0.125647,254.648,,12.5647,0.254648,,,,7.85398e-5
Test1,2-Compress,66.650,3.688,0.562,0.027,,0.132235,343.775,,13.2235,0.343775,,,,7.85398e-5
Test1,2-Compress,66.983,3.66,0.59,0.014,,0.138824,178.254,,13.8824,0.178254,,,,7.85398e-5
Test1,2-Compress,67.317,3.631,0.619,0.027,,0.145647,343.775,,14.5647,0.343775,,,,7.85398e-5
Test1,2-Compress,67.650,3.603,0.647,0.027,,0.152235,343.775,,15.2235,0.343775,,,,7.85398e-5
Test1,2-Compress,67.983,3.575,0.675,0.027,,0.158824,343.775,,15.8824,0.343775,,,,7.85398e-5
Test1,2-Compress,68.317,3.546,0.704,0.020,,0.165647,254.648,,16.5647,0.254648,,,,7.85398e-5
Test1,2-Compress,68.650,3.517,0.733,0.027,,0.172471,343.775,,17.2471,0.343775,,,,7.85398e-5
Test1,2-Compress,68.983,3.489,0.761,0.034,,0.179059,432.902,,17.9059,0.432902,,,,7.85398e-5
Test1,2-Compress,69.317,3.46,0.79,0.020,,0.185882,254.648,,18.5882,0.254648,,,,7.85398e-5
Test1,2-Compress,69.650,3.432,0.818,0.020,,0.192471,254.648,,19.2471,0.254648,,,,7.85398e-5
Test1,2-Compress,69.983,3.404,0.846,0.027,,0.199059,343.775,,19.9059,0.343775,,,,7.85398e-5
Test1,2-Compress,70.317,3.375,0.875,0.034,,0.205882,432.902,,20.5882,0.432902,,,,7.85398e-5
Test1,2-Compress,70.650,3.347,0.903,0.027,,0.212471,343.775,,21.2471,0.343775,,,,7.85398e-5
Test1,2-Compress,70.983,3.319,0.931,0.027,,0.219059,343.775,,21.9059,0.343775,,,,7.85398e-5
Test1,2-Compress,71.317,3.29,0.96,0.027,,0.225882,343.775,,22.5882,0.343775,,,,7.85398e-5
Test1,2-Compress,71.650,3.262,0.988,0.027,,0.232471,343.775,,23.2471,0.343775,,,,7.85398e-5
Test1,2-Compress,71.983,3.234,1.016,0.027,,0.239059,343.775,,23.9059,0.343775,,,,7.85398e-5
Test1,2-Compress,72.317,3.205,1.045,0.027,,0.245882,343.775,,24.5882,0.343775,,,,7.85398e-5
Test1,2-Compress,72.650,3.177,1.073,0.027,,0.252471,343.775,,25.2471,0.343775,,,,7.85398e-5
Test1,2-Compress,72.983,3.149,1.101,0.027,,0.259059,343.775,,25.9059,0.343775,,,,7.85398e-5
Test1,2-Compress,73.317,3.12,1.13,0.027,,0.265882,343.775,,26.5882,0.343775,,,,7.85398e-5
Test1,2-Compress,73.650,3.092,1.158,0.027,,0.272471,343.775,,27.2471,0.343775,,,,7.85398e-5
Test1,2-Compress,73.983,3.064,1.186,0.027,,0.279059,343.775,,27.9059,0.343775,,,,7.85398e-5
Test1,2-Compress,74.317,3.035,1.215,0.027,,0.285882,343.775,,28.5882,0.343775,,,,7.85398e-5
Test1,2-Compress,74.650,3.007,1.243,0.027,,0.292471,343.775,,29.2471,0.343775,,,,7.85398e-5
Test1,2-Compress,74.983,2.979,1.271,0.027,,0.299059,343.775,,29.9059,0.343775,,,,7.85398e-5
Test1,2-Compress,75.317,2.95,1.3,0.027,,0.305882,343.775,,30.5882,0.343775,,,,7.85398e-5
Test1,2-Compress,75.650,2.922,1.328,0.027,,0.312471,343.775,,31.2471,0.343775,,,,7.85398e-5
Test1,2-Compress,75.983,2.893,1.357,0.027,,0.319294,343.775,,31.9294,0.343775,,,,7.85398e-5
Test1,2-Compress,76.317,2.864,1.386,0.027,,0.326118,343.775,,32.6118,0.343775,,,,7.85398e-5
Test1,2-Compress,76.650,2.837,1.413,0.027,,0.332471,343.775,,33.2471,0.343775,,,,7.85398e-5
Test1,2-Compress,76.983,2.808,1.442,0.034,,0.339294,432.902,,33.9294,0.432902,,,,7.85398e-5
Test1,2-Compress,77.317,2.779,1.471,0.027,,0.346118,343.775,,34.6118,0.343775,,,,7.85398e-5
Test1,2-Compress,77.650,2.752,1.498,0.027,,0.352471,343.775,,35.2471,0.343775,,,,7.85398e-5
Test1,2-Compress,77.983,2.723,1.527,0.027,,0.359294,343.775,,35.9294,0.343775,,,,7.85398e-5
Test1,2-Compress,78.317,2.694,1.556,0.041,,0.366118,522.028,,36.6118,0.522028,,,,7.85398e-5
Test1,2-Compress,78.650,2.666,1.584,0.041,,0.372706,522.028,,37.2706,0.522028,,,,7.85398e-5
Test1,2-Compress,78.983,2.638,1.612,0.048,,0.379294,611.155,,37.9294,0.611155,,,,7.85398e-5
Test1,2-Compress,79.317,2.609,1.641,0.041,,0.386118,522.028,,38.6118,0.522028,,,,7.85398e-5
Test1,2-Compress,79.650,2.581,1.669,0.034,,0.392706,432.902,,39.2706,0.432902,,,,7.85398e-5
Test1,2-Compress,79.983,2.553,1.697,0.048,,0.399294,611.155,,39.9294,0.611155,,,,7.85398e-5
Test1,2-Compress,80.317,2.524,1.726,0.048,,0.406118,611.155,,40.6118,0.611155,,,,7.85398e-5
Test1,2-Compress,80.650,2.496,1.754,0.034,,0.412706,432.902,,41.2706,0.432902,,,,7.85398e-5
Test1,2-Compress,80.983,2.468,1.782,0.048,,0.419294,611.155,,41.9294,0.611155,,,,7.85398e-5
Test1,2-Compress,81.317,2.439,1.811,0.048,,0.426118,611.155,,42.6118,0.611155,,,,7.85398e-5
Test1,2-Compress,81.650,2.411,1.839,0.041,,0.432706,522.028,,43.2706,0.522028,,,,7.85398e-5
Test1,2-Compress,81.983,2.383,1.867,0.041,,0.439294,522.028,,43.9294,0.522028,,,,7.85398e-5
Test1,2-Compress,82.317,2.354,1.896,0.041,,0.446118,522.028,,44.6118,0.522028,,,,7.85398e-5
Test1,2-Compress,82.650,2.326,1.924,0.041,,0.452706,522.028,,45.2706,0.522028,,,,7.85398e-5
Test1,2-Compress,82.983,2.297,1.953,0.041,,0.459529,522.028,,45.9529,0.522028,,,,7.85398e-5
Test1,2-Compress,83.317,2.269,1.981,0.068,,0.466118,865.803,,46.6118,0.865803,,,,7.85398e-5
Test1,2-Compress,83.650,2.241,2.009,0.054,,0.472706,687.549,,47.2706,0.687549,,,,7.85398e-5
Test1,2-Compress,83.983,2.212,2.038,0.048,,0.479529,611.155,,47.9529,0.611155,,,,7.85398e-5
Test1,2-Compress,84.317,2.184,2.066,0.048,,0.486118,611.155,,48.6118,0.611155,,,,7.85398e-5
Test1,2-Compress,84.650,2.156,2.094,0.068,,0.492706,865.803,,49.2706,0.865803,,,,7.85398e-5
Test1,2-Compress,84.983,2.127,2.123,0.068,,0.499529,865.803,,49.9529,0.865803,,,,7.85398e-5
Test1,2-Compress,85.317,2.098,2.152,0.061,,0.506353,776.676,,50.6353,0.776676,,,,7.85398e-5
Test1,2-Compress,85.650,2.07,2.18,0.068,,0.512941,865.803,,51.2941,0.865803,,,,7.85398e-5
Test1,2-Compress,85.983,2.042,2.208,0.061,,0.519529,776.676,,51.9529,0.776676,,,,7.85398e-5
Test1,2-Compress,86.317,2.013,2.237,0.068,,0.526353,865.803,,52.6353,0.865803,,,,7.85398e-5
Test1,2-Compress,86.650,1.985,2.265,0.075,,0.532941,954.93,,53.2941,0.95493,,,,7.85398e-5
Test1,2-Compress,86.983,1.957,2.293,0.082,,0.539529,1044.06,,53.9529,1.04406,,,,7.85398e-5
Test1,2-Compress,87.317,1.928,2.322,0.082,,0.546353,1044.06,,54.6353,1.04406,,,,7.85398e-5
Test1,2-Compress,87.650,1.9,2.35,0.082,,0.552941,1044.06,,55.2941,1.04406,,,,7.85398e-5
Test1,2-Compress,87.983,1.872,2.378,0.082,,0.559529,1044.06,,55.9529,1.04406,,,,7.85398e-5
Test1,2-Compress,88.317,1.843,2.407,0.082,,0.566353,1044.06,,56.6353,1.04406,,,,7.85398e-5
Test1,2-Compress,88.650,1.815,2.435,0.082,,0.572941,1044.06,,57.2941,1.04406,,,,7.85398e-5
Test1,2-Compress,88.983,1.787,2.463,0.082,,0.579529,1044.06,,57.9529,1.04406,,,,7.85398e-5
Test1,2-Compress,89.317,1.758,2.492,0.082,,0.586353,1044.06,,58.6353,1.04406,,,,7.85398e-5
Test1,2-Compress,89.650,1.73,2.52,0.082,,0.592941,1044.06,,59.2941,1.04406,,,,7.85398e-5
Test1,2-Compress,89.983,1.701,2.549,0.082,,0.599765,1044.06,,59.9765,1.04406,,,,7.85398e-5
Test1,2-Recover,90.303,1.72,2.53,0.082,,0.595294,1044.06,,59.5294,1.04406,,,,7.85398e-5
Test1,2-Recover,90.637,1.749,2.501,0.082,,0.588471,1044.06,,58.8471,1.04406,,,,7.85398e-5
Test1,2-Recover,90.970,1.777,2.473,0.082,,0.581882,1044.06,,58.1882,1.04406,,,,7.85398e-5
Test1,2-Recover,91.303,1.805,2.445,0.082,,0.575294,1044.06,,57.5294,1.04406,,,,7.85398e-5
Test1,2-Recover,91.637,1.834,2.416,0.082,,0.568471,1044.06,,56.8471,1.04406,,,,7.85398e-5
Test1,2-Recover,91.970,1.862,2.388,0.082,,0.561882,1044.06,,56.1882,1.04406,,,,7.85398e-5
Test1,2-Recover,92.303,1.89,2.36,0.082,,0.555294,1044.06,,55.5294,1.04406,,,,7.85398e-5
Test1,2-Recover,92.637,1.919,2.331,0.075,,0.548471,954.93,,54.8471,0.95493,,,,7.85398e-5
Test1,2-Recover,92.970,1.947,2.303,0.075,,0.541882,954.93,,54.1882,0.95493,,,,7.85398e-5
Test1,2-Recover,93.303,1.975,2.275,0.054,,0.535294,687.549,,53.5294,0.687549,,,,7.85398e-5
Test1,2-Recover,93.637,2.004,2.246,0.048,,0.528471,611.155,,52.8471,0.611155,,,,7.85398e-5
Test1,2-Recover,93.970,2.032,2.218,0.061,,0.521882,776.676,,52.1882,0.776676,,,,7.85398e-5
Test1,2-Recover,94.303,2.061,2.189,0.061,,0.515059,776.676,,51.5059,0.776676,,,,7.85398e-5
Test1,2-Recover,94.637,2.09,2.16,0.054,,0.508235,687.549,,50.8235,0.687549,,,,7.85398e-5
Test1,2-Recover,94.970,2.117,2.133,0.068,,0.501882,865.803,,50.1882,0.865803,,,,7.85398e-5
Test1,2-Recover,95.303,2.146,2.104,0.054,,0.495059,687.549,,49.5059,0.687549,,,,7.85398e-5
Test1,2-Recover,95.637,2.175,2.075,0.054,,0.488235,687.549,,48.8235,0.687549,,,,7.85398e-5
Test1,2-Recover,95.970,2.202,2.048,0.061,,0.481882,776.676,,48.1882,0.776676,,,,7.85398e-5
Test1,2-Recover,96.303,2.231,2.019,0.048,,0.475059,611.155,,47.5059,0.611155,,,,7.85398e-5
Test1,2-Recover,96.637,2.26,1.99,0.054,,0.468235,687.549,,46.8235,0.687549,,,,7.85398e-5
Test1,2-Recover,96.970,2.288,1.962,0.034,,0.461647,432.902,,46.1647,0.432902,,,,7.85398e-5
Test1,2-Recover,97.303,2.316,1.934,0.034,,0.455059,432.902,,45.5059,0.432902,,,,7.85398e-5
Test1,2-Recover,97.637,2.345,1.905,0.041,,0.448235,522.028,,44.8235,0.522028,,,,7.85398e-5
Test1,2-Recover,97.970,2.373,1.877,0.041,,0.441647,522.028,,44.1647,0.522028,,,,7.85398e-5
Test1,2-Recover,98.303,2.401,1.849,0.027,,0.435059,343.775,,43.5059,0.343775,,,,7.85398e-5
Test1,2-Recover,98.637,2.43,1.82,0.034,,0.428235,432.902,,42.8235,0.432902,,,,7.85398e-5
Test1,2-Recover,98.970,2.458,1.792,0.034,,0.421647,432.902,,42.1647,0.432902,,,,7.85398e-5
Test1,2-Recover,99.303,2.486,1.764,0.034,,0.415059,432.902,,41.5059,0.432902,,,,7.85398e-5
Test1,2-Recover,99.637,2.515,1.735,0.027,,0.408235,343.775,,40.8235,0.343775,,,,7.85398e-5
Test1,2-Recover,99.970,2.543,1.707,0.027,,0.401647,343.775,,40.1647,0.343775,,,,7.85398e-5
Test1,2-Recover,100.303,2.571,1.679,0.034,,0.395059,432.902,,39.5059,0.432902,,,,7.85398e-5
Test1,2-Recover,100.637,2.6,1.65,0.027,,0.388235,343.775,,38.8235,0.343775,,,,7.85398e-5
Test1,2-Recover,100.970,2.628,1.622,0.027,,0.381647,343.775,,38.1647,0.343775,,,,7.85398e-5
Test1,2-Recover,101.303,2.657,1.593,0.027,,0.374824,343.775,,37.4824,0.343775,,,,7.85398e-5
Test1,2-Recover,101.637,2.685,1.565,0.027,,0.368235,343.775,,36.8235,0.343775,,,,7.85398e-5
Test1,2-Recover,101.970,2.713,1.537,0.041,,0.361647,522.028,,36.1647,0.522028,,,,7.85398e-5
Test1,2-Recover,102.303,2.742,1.508,0.034,,0.354824,432.902,,35.4824,0.432902,,,,7.85398e-5
Test1,2-Recover,102.637,2.77,1.48,0.034,,0.348235,432.902,,34.8235,0.432902,,,,7.85398e-5
Test1,2-Recover,102.970,2.798,1.452,0.027,,0.341647,343.775,,34.1647,0.343775,,,,7.85398e-5
Test1,2-Recover,103.303,2.827,1.423,0.027,,0.334824,343.775,,33.4824,0.343775,,,,7.85398e-5
Test1,2-Recover,103.637,2.855,1.395,0.027,,0.328235,343.775,,32.8235,0.343775,,,,7.85398e-5
Test1,2-Recover,103.970,2.884,1.366,0.027,,0.321412,343.775,,32.1412,0.343775,,,,7.85398e-5
Test1,2-Recover,104.303,2.912,1.338,0.027,,0.314824,343.775,,31.4824,0.343775,,,,7.85398e-5
Test1,2-Recover,104.637,2.941,1.309,0.027,,0.308,343.775,,30.8,0.343775,,,,7.85398e-5
Test1,2-Recover,104.970,2.969,1.281,0.027,,0.301412,343.775,,30.1412,0.343775,,,,7.85398e-5
Test1,2-Recover,105.303,2.997,1.253,0.027,,0.294824,343.775,,29.4824,0.343775,,,,7.85398e-5
Test1,2-Recover,105.637,3.026,1.224,0.027,,0.288,343.775,,28.8,0.343775,,,,7.85398e-5
Test1,2-Recover,105.970,3.054,1.196,0.027,,0.281412,343.775,,28.1412,0.343775,,,,7.85398e-5
Test1,2-Recover,106.303,3.082,1.168,0.027,,0.274824,343.775,,27.4824,0.343775,,,,7.85398e-5
Test1,2-Recover,106.637,3.111,1.139,0.027,,0.268,343.775,,26.8,0.343775,,,,7.85398e-5
Test1,2-Recover,106.970,3.139,1.111,0.027,,0.261412,343.775,,26.1412,0.343775,,,,7.85398e-5
Test1,2-Recover,107.303,3.167,1.083,0.027,,0.254824,343.775,,25.4824,0.343775,,,,7.85398e-5
Test1,2-Recover,107.637,3.196,1.054,0.027,,0.248,343.775,,24.8,0.343775,,,,7.85398e-5
Test1,2-Recover,107.970,3.224,1.026,0.027,,0.241412,343.775,,24.1412,0.343775,,,,7.85398e-5
Test1,2-Recover,108.303,3.252,0.998,0.027,,0.234824,343.775,,23.4824,0.343775,,,,7.85398e-5
Test1,2-Recover,108.637,3.281,0.969,0.027,,0.228,343.775,,22.8,0.343775,,,,7.85398e-5
Test1,2-Recover,108.970,3.309,0.941,0.027,,0.221412,343.775,,22.1412,0.343775,,,,7.85398e-5
Test1,2-Recover,109.303,3.337,0.913,0.027,,0.214824,343.775,,21.4824,0.343775,,,,7.85398e-5
Test1,2-Recover,109.637,3.366,0.884,0.020,,0.208,254.648,,20.8,0.254648,,,,7.85398e-5
Test1,2-Recover,109.970,3.394,0.856,0.027,,0.201412,343.775,,20.1412,0.343775,,,,7.85398e-5
Test1,2-Recover,110.303,3.422,0.828,0.027,,0.194824,343.775,,19.4824,0.343775,,,,7.85398e-5
Test1,2-Recover,110.637,3.451,0.799,0.027,,0.188,343.775,,18.8,0.343775,,,,7.85398e-5
Test1,2-Recover,110.970,3.48,0.77,0.027,,0.181176,343.775,,18.1176,0.343775,,,,7.85398e-5
Test1,2-Recover,111.303,3.508,0.742,0.027,,0.174588,343.775,,17.4588,0.343775,,,,7.85398e-5
Test1,2-Recover,111.637,3.537,0.713,0.027,,0.167765,343.775,,16.7765,0.343775,,,,7.85398e-5
Test1,2-Recover,111.970,3.565,0.685,0.027,,0.161176,343.775,,16.1176,0.343775,,,,7.85398e-5
Test1,2-Recover,112.303,3.593,0.657,0.027,,0.154588,343.775,,15.4588,0.343775,,,,7.85398e-5
Test1,2-Recover,112.637,3.622,0.628,0.027,,0.147765,343.775,,14.7765,0.343775,,,,7.85398e-5
Test1,2-Recover,112.970,3.65,0.6,0.027,,0.141176,343.775,,14.1176,0.343775,,,,7.85398e-5
Test1,2-Recover,113.303,3.678,0.572,0.027,,0.134588,343.775,,13.4588,0.343775,,,,7.85398e-5
Test1,2-Recover,113.637,3.707,0.543,0.027,,0.127765,343.775,,12.7765,0.343775,,,,7.85398e-5
Test1,2-Recover,113.970,3.735,0.515,0.027,,0.121176,343.775,,12.1176,0.343775,,,,7.85398e-5
Test1,2-Recover,114.303,3.763,0.487,0.027,,0.114588,343.775,,11.4588,0.343775,,,,7.85398e-5
Test1,2-Recover,114.637,3.792,0.458,0.027,,0.107765,343.775,,10.7765,0.343775,,,,7.85398e-5
Test1,2-Recover,114.970,3.82,0.43,0.027,,0.101176,343.775,,10.1176,0.343775,,,,7.85398e-5
Test1,2-Recover,115.303,3.848,0.402,0.027,,0.0945882,343.775,,9.45882,0.343775,,,,7.85398e-5
Test1,2-Recover,115.637,3.877,0.373,0.027,,0.0877647,343.775,,8.77647,0.343775,,,,7.85398e-5
Test1,2-Recover,115.970,3.905,0.345,0.014,,0.0811765,178.254,,8.11765,0.178254,,,,7.85398e-5
Test1,2-Recover,116.303,3.933,0.317,0.007,,0.0745882,89.1268,,7.45882,0.0891268,,,,7.85398e-5
Test1,2-Recover,116.637,3.962,0.288,0.014,,0.0677647,178.254,,6.77647,0.178254,,,,7.85398e-5
Test1,2-Recover,116.970,3.99,0.26,0.020,,0.0611765,254.648,,6.11765,0.254648,,,,7.85398e-5
Test1,2-Recover,117.303,4.018,0.232,0.020,,0.0545882,254.648,,5.45882,0.254648,,,,7.85398e-5
Test1,2-Recover,117.637,4.047,0.203,0.027,,0.0477647,343.775,,4.77647,0.343775,,,,7.85398e-5
Test1,2-Recover,117.970,4.076,0.174,0.020,,0.0409412,254.648,,4.09412,0.254648,,,,7.85398e-5
Test1,2-Recover,118.303,4.104,0.146,0.020,,0.0343529,254.648,,3.43529,0.254648,,,,7.85398e-5
Test1,2-Recover,118.637,4.133,0.117,0.027,,0.0275294,343.775,,2.75294,0.343775,,,,7.85398e-5
Test1,2-Recover,118.970,4.161,0.089,0.027,,0.0209412,343.775,,2.09412,0.343775,,,,7.85398e-5
Test1,2-Recover,119.303,4.189,0.061,0.027,,0.0143529,343.775,,1.43529,0.343775,,,,7.85398e-5
Test1,2-Recover,119.637,4.218,0.032,0.020,,0.00752941,254.648,,0.752941,0.254648,,,,7.85398e-5
Test1,2-Recover,119.970,4.246,0.004,0.027,,0.000941176,343.775,,0.0941176,0.343775,,,,7.85398e-5
Test1,3-Compress,120.280,4.233,0.017,0.020,,0.004,254.648,,0.4,0.254648,,,,7.85398e-5
Test1,3-Compress,120.613,4.205,0.045,0.027,,0.0105882,343.775,,1.05882,0.343775,,,,7.85398e-5
Test1,3-Compress,120.947,4.176,0.074,0.027,,0.0174118,343.775,,1.74118,0.343775,,,,7.85398e-5
Test1,3-Compress,121.280,4.148,0.102,0.027,,0.024,343.775,,2.4,0.343775,,,,7.85398e-5
Test1,3-Compress,121.613,4.12,0.13,0.020,,0.0305882,254.648,,3.05882,0.254648,,,,7.85398e-5
Test1,3-Compress,121.947,4.091,0.159,0.020,,0.0374118,254.648,,3.74118,0.254648,,,,7.85398e-5
Test1,3-Compress,122.280,4.063,0.187,0.027,,0.044,343.775,,4.4,0.343775,,,,7.85398e-5
Test1,3-Compress,122.613,4.035,0.215,0.027,,0.0505882,343.775,,5.05882,0.343775,,,,7.85398e-5
Test1,3-Compress,122.947,4.006,0.244,0.014,,0.0574118,178.254,,5.74118,0.178254,,,,7.85398e-5
Test1,3-Compress,123.280,3.978,0.272,0.027,,0.064,343.775,,6.4,0.343775,,,,7.85398e-5
Test1,3-Compress,123.613,3.95,0.3,0.027,,0.0705882,343.775,,7.05882,0.343775,,,,7.85398e-5
Test1,3-Compress,123.947,3.921,0.329,0.027,,0.0774118,343.775,,7.74118,0.343775,,,,7.85398e-5
Test1,3-Compress,124.280,3.893,0.357,0.027,,0.084,343.775,,8.4,0.343775,,,,7.85398e-5
Test1,3-Compress,124.613,3.865,0.385,0.027,,0.0905882,343.775,,9.05882,0.343775,,,,7.85398e-5
Test1,3-Compress,124.947,3.836,0.414,0.020,,0.0974118,254.648,,9.74118,0.254648,,,,7.85398e-5
Test1,3-Compress,125.280,3.808,0.442,0.027,,0.104,343.775,,10.4,0.343775,,,,7.85398e-5
Test1,3-Compress,125.613,3.78,0.47,0.020,,0.110588,254.648,,11.0588,0.254648,,,,7.85398e-5
Test1,3-Compress,125.947,3.751,0.499,0.027,,0.117412,343.775,,11.7412,0.343775,,,,7.85398e-5
Test1,3-Compress,126.280,3.722,0.528,0.027,,0.124235,343.775,,12.4235,0.343775,,,,7.85398e-5
Test1,3-Compress,126.613,3.695,0.555,0.027,,0.130588,343.775,,13.0588,0.343775,,,,7.85398e-5
Test1,3-Compress,126.947,3.666,0.584,0.027,,0.137412,343.775,,13.7412,0.343775,,,,7.85398e-5
Test1,3-Compress,127.280,3.637,0.613,0.027,,0.144235,343.775,,14.4235,0.343775,,,,7.85398e-5
Test1,3-Compress,127.613,3.61,0.64,0.027,,0.150588,343.775,,15.0588,0.343775,,,,7.85398e-5
Test1,3-Compress,127.947,3.581,0.669,0.027,,0.157412,343.775,,15.7412,0.343775,,,,7.85398e-5
Test1,3-Compress,128.280,3.552,0.698,0.027,,0.164235,343.775,,16.4235,0.343775,,,,7.85398e-5
Test1,3-Compress,128.613,3.524,0.726,0.027,,0.170824,343.775,,17.0824,0.343775,,,,7.85398e-5
Test1,3-Compress,128.947,3.495,0.755,0.027,,0.177647,343.775,,17.7647,0.343775,,,,7.85398e-5
Test1,3-Compress,129.280,3.467,0.783,0.027,,0.184235,343.775,,18.4235,0.343775,,,,7.85398e-5
Test1,3-Compress,129.613,3.439,0.811,0.027,,0.190824,343.775,,19.0824,0.343775,,,,7.85398e-5
Test1,3-Compress,129.947,3.41,0.84,0.027,,0.197647,343.775,,19.7647,0.343775,,,,7.85398e-5
Test1,3-Compress,130.280,3.382,0.868,0.027,,0.204235,343.775,,20.4235,0.343775,,,,7.85398e-5
Test1,3-Compress,130.613,3.354,0.896,0.027,,0.210824,343.775,,21.0824,0.343775,,,,7.85398e-5
Test1,3-Compress,130.947,3.325,0.925,0.027,,0.217647,343.775,,21.7647,0.343775,,,,7.85398e-5
Test1,3-Compress,131.280,3.297,0.953,0.027,,0.224235,343.775,,22.4235,0.343775,,,,7.85398e-5
Test1,3-Compress,131.613,3.269,0.981,0.027,,0.230824,343.775,,23.0824,0.343775,,,,7.85398e-5
Test1,3-Compress,131.947,3.24,1.01,0.027,,0.237647,343.775,,23.7647,0.343775,,,,7.85398e-5
Test1,3-Compress,132.280,3.212,1.038,0.027,,0.244235,343.775,,24.4235,0.343775,,,,7.85398e-5
Test1,3-Compress,132.613,3.184,1.066,0.027,,0.250824,343.775,,25.0824,0.343775,,,,7.85398e-5
Test1,3-Compress,132.947,3.155,1.095,0.027,,0.257647,343.775,,25.7647,0.343775,,,,7.85398e-5
Test1,3-Compress,133.280,3.127,1.123,0.027,,0.264235,343.775,,26.4235,0.343775,,,,7.85398e-5
Test1,3-Compress,133.613,3.099,1.151,0.027,,0.270824,343.775,,27.0824,0.343775,,,,7.85398e-5
Test1,3-Compress,133.947,3.07,1.18,0.027,,0.277647,343.775,,27.7647,0.343775,,,,7.85398e-5
Test1,3-Compress,134.280,3.042,1.208,0.027,,0.284235,343.775,,28.4235,0.343775,,,,7.85398e-5
Test1,3-Compress,134.613,3.014,1.236,0.034,,0.290824,432.902,,29.0824,0.432902,,,,7.85398e-5
Test1,3-Compress,134.947,2.985,1.265,0.027,,0.297647,343.775,,29.7647,0.343775,,,,7.85398e-5
Test1,3-Compress,135.280,2.956,1.294,0.027,,0.304471,343.775,,30.4471,0.343775,,,,7.85398e-5
Test1,3-Compress,135.613,2.928,1.322,0.027,,0.311059,343.775,,31.1059,0.343775,,,,7.85398e-5
Test1,3-Compress,135.947,2.899,1.351,0.034,,0.317882,432.902,,31.7882,0.432902,,,,7.85398e-5
Test1,3-Compress,136.280,2.871,1.379,0.027,,0.324471,343.775,,32.4471,0.343775,,,,7.85398e-5
Test1,3-Compress,136.613,2.843,1.407,0.034,,0.331059,432.902,,33.1059,0.432902,,,,7.85398e-5
Test1,3-Compress,136.947,2.814,1.436,0.027,,0.337882,343.775,,33.7882,0.343775,,,,7.85398e-5
Test1,3-Compress,137.280,2.786,1.464,0.027,,0.344471,343.775,,34.4471,0.343775,,,,7.85398e-5
Test1,3-Compress,137.613,2.758,1.492,0.034,,0.351059,432.902,,35.1059,0.432902,,,,7.85398e-5
Test1,3-Compress,137.947,2.729,1.521,0.034,,0.357882,432.902,,35.7882,0.432902,,,,7.85398e-5
Test1,3-Compress,138.280,2.701,1.549,0.034,,0.364471,432.902,,36.4471,0.432902,,,,7.85398e-5
Test1,3-Compress,138.613,2.673,1.577,0.048,,0.371059,611.155,,37.1059,0.611155,,,,7.85398e-5
Test1,3-Compress,138.947,2.644,1.606,0.034,,0.377882,432.902,,37.7882,0.432902,,,,7.85398e-5
Test1,3-Compress,139.280,2.616,1.634,0.041,,0.384471,522.028,,38.4471,0.522028,,,,7.85398e-5
Test1,3-Compress,139.613,2.588,1.662,0.034,,0.391059,432.902,,39.1059,0.432902,,,,7.85398e-5
Test1,3-Compress,139.947,2.559,1.691,0.034,,0.397882,432.902,,39.7882,0.432902,,,,7.85398e-5
Test1,3-Compress,140.280,2.531,1.719,0.034,,0.404471,432.902,,40.4471,0.432902,,,,7.85398e-5
Test1,3-Compress,140.613,2.503,1.747,0.034,,0.411059,432.902,,41.1059,0.432902,,,,7.85398e-5
Test1,3-Compress,140.947,2.474,1.776,0.034,,0.417882,432.902,,41.7882,0.432902,,,,7.85398e-5
Test1,3-Compress,141.280,2.446,1.804,0.027,,0.424471,343.775,,42.4471,0.343775,,,,7.85398e-5
Test1,3-Compress,141.613,2.418,1.832,0.027,,0.431059,343.775,,43.1059,0.343775,,,,7.85398e-5
Test1,3-Compress,141.947,2.389,1.861,0.027,,0.437882,343.775,,43.7882,0.343775,,,,7.85398e-5
Test1,3-Compress,142.280,2.36,1.89,0.027,,0.444706,343.775,,44.4706,0.343775,,,,7.85398e-5
Test1,3-Compress,142.613,2.332,1.918,0.027,,0.451294,343.775,,45.1294,0.343775,,,,7.85398e-5
Test1,3-Compress,142.947,2.303,1.947,0.041,,0.458118,522.028,,45.8118,0.522028,,,,7.85398e-5
Test1,3-Compress,143.280,2.275,1.975,0.061,,0.464706,776.676,,46.4706,0.776676,,,,7.85398e-5
Test1,3-Compress,143.613,2.247,2.003,0.061,,0.471294,776.676,,47.1294,0.776676,,,,7.85398e-5
Test1,3-Compress,143.947,2.218,2.032,0.054,,0.478118,687.549,,47.8118,0.687549,,,,7.85398e-5
Test1,3-Compress,144.280,2.19,2.06,0.068,,0.484706,865.803,,48.4706,0.865803,,,,7.85398e-5
Test1,3-Compress,144.613,2.162,2.088,0.075,,0.491294,954.93,,49.1294,0.95493,,,,7.85398e-5
Test1,3-Compress,144.947,2.133,2.117,0.082,,0.498118,1044.06,,49.8118,1.04406,,,,7.85398e-5
Test1,3-Compress,145.280,2.105,2.145,0.075,,0.504706,954.93,,50.4706,0.95493,,,,7.85398e-5
Test1,3-Compress,145.613,2.077,2.173,0.075,,0.511294,954.93,,51.1294,0.95493,,,,7.85398e-5
Test1,3-Compress,145.947,2.048,2.202,0.082,,0.518118,1044.06,,51.8118,1.04406,,,,7.85398e-5
Test1,3-Compress,146.280,2.02,2.23,0.082,,0.524706,1044.06,,52.4706,1.04406,,,,7.85398e-5
Test1,3-Compress,146.613,1.992,2.258,0.082,,0.531294,1044.06,,53.1294,1.04406,,,,7.85398e-5
Test1,3-Compress,146.947,1.963,2.287,0.082,,0.538118,1044.06,,53.8118,1.04406,,,,7.85398e-5
Test1,3-Compress,147.280,1.935,2.315,0.082,,0.544706,1044.06,,54.4706,1.04406,,,,7.85398e-5
Test1,3-Compress,147.613,1.907,2.343,0.082,,0.551294,1044.06,,55.1294,1.04406,,,,7.85398e-5
Test1,3-Compress,147.947,1.878,2.372,0.082,,0.558118,1044.06,,55.8118,1.04406,,,,7.85398e-5
Test1,3-Compress,148.280,1.85,2.4,0.082,,0.564706,1044.06,,56.4706,1.04406,,,,7.85398e-5
Test1,3-Compress,148.613,1.822,2.428,0.082,,0.571294,1044.06,,57.1294,1.04406,,,,7.85398e-5
Test1,3-Compress,148.947,1.793,2.457,0.082,,0.578118,1044.06,,57.8118,1.04406,,,,7.85398e-5
Test1,3-Compress,149.280,1.765,2.485,0.082,,0.584706,1044.06,,58.4706,1.04406,,,,7.85398e-5
Test1,3-Compress,149.613,1.736,2.514,0.082,,0.591529,1044.06,,59.1529,1.04406,,,,7.85398e-5
Test1,3-Compress,149.947,1.707,2.543,0.082,,0.598353,1044.06,,59.8353,1.04406,,,,7.85398e-5
Test1,3-Recover,150.267,1.714,2.536,0.082,,0.596706,1044.06,,59.6706,1.04406,,,,7.85398e-5
Test1,3-Recover,150.600,1.742,2.508,0.082,,0.590118,1044.06,,59.0118,1.04406,,,,7.85398e-5
Test1,3-Recover,150.933,1.77,2.48,0.082,,0.583529,1044.06,,58.3529,1.04406,,,,7.85398e-5
Test1,3-Recover,151.267,1.799,2.451,0.075,,0.576706,954.93,,57.6706,0.95493,,,,7.85398e-5
Test1,3-Recover,151.600,1.827,2.423,0.082,,0.570118,1044.06,,57.0118,1.04406,,,,7.85398e-5
Test1,3-Recover,151.933,1.855,2.395,0.082,,0.563529,1044.06,,56.3529,1.04406,,,,7.85398e-5
Test1,3-Recover,152.267,1.884,2.366,0.082,,0.556706,1044.06,,55.6706,1.04406,,,,7.85398e-5
Test1,3-Recover,152.600,1.912,2.338,0.082,,0.550118,1044.06,,55.0118,1.04406,,,,7.85398e-5
Test1,3-Recover,152.933,1.94,2.31,0.075,,0.543529,954.93,,54.3529,0.95493,,,,7.85398e-5
Test1,3-Recover,153.267,1.969,2.281,0.082,,0.536706,1044.06,,53.6706,1.04406,,,,7.85398e-5
Test1,3-Recover,153.600,1.997,2.253,0.068,,0.530118,865.803,,53.0118,0.865803,,,,7.85398e-5
Test1,3-Recover,153.933,2.026,2.224,0.061,,0.523294,776.676,,52.3294,0.776676,,,,7.85398e-5
Test1,3-Recover,154.267,2.055,2.195,0.068,,0.516471,865.803,,51.6471,0.865803,,,,7.85398e-5
Test1,3-Recover,154.600,2.083,2.167,0.048,,0.509882,611.155,,50.9882,0.611155,,,,7.85398e-5
Test1,3-Recover,154.933,2.111,2.139,0.048,,0.503294,611.155,,50.3294,0.611155,,,,7.85398e-5
Test1,3-Recover,155.267,2.14,2.11,0.041,,0.496471,522.028,,49.6471,0.522028,,,,7.85398e-5
Test1,3-Recover,155.600,2.168,2.082,0.041,,0.489882,522.028,,48.9882,0.522028,,,,7.85398e-5
Test1,3-Recover,155.933,2.196,2.054,0.041,,0.483294,522.028,,48.3294,0.522028,,,,7.85398e-5
Test1,3-Recover,156.267,2.225,2.025,0.034,,0.476471,432.902,,47.6471,0.432902,,,,7.85398e-5
Test1,3-Recover,156.600,2.253,1.997,0.034,,0.469882,432.902,,46.9882,0.432902,,,,7.85398e-5
Test1,3-Recover,156.933,2.281,1.969,0.034,,0.463294,432.902,,46.3294,0.432902,,,,7.85398e-5
Test1,3-Recover,157.267,2.31,1.94,0.034,,0.456471,432.902,,45.6471,0.432902,,,,7.85398e-5
Test1,3-Recover,157.600,2.338,1.912,0.027,,0.449882,343.775,,44.9882,0.343775,,,,7.85398e-5
Test1,3-Recover,157.933,2.366,1.884,0.027,,0.443294,343.775,,44.3294,0.343775,,,,7.85398e-5
Test1,3-Recover,158.267,2.395,1.855,0.034,,0.436471,432.902,,43.6471,0.432902,,,,7.85398e-5
Test1,3-Recover,158.600,2.423,1.827,0.027,,0.429882,343.775,,42.9882,0.343775,,,,7.85398e-5
Test1,3-Recover,158.933,2.451,1.799,0.027,,0.423294,343.775,,42.3294,0.343775,,,,7.85398e-5
Test1,3-Recover,159.267,2.48,1.77,0.034,,0.416471,432.902,,41.6471,0.432902,,,,7.85398e-5
Test1,3-Recover,159.600,2.508,1.742,0.034,,0.409882,432.902,,40.9882,0.432902,,,,7.85398e-5
Test1,3-Recover,159.933,2.536,1.714,0.027,,0.403294,343.775,,40.3294,0.343775,,,,7.85398e-5
Test1,3-Recover,160.267,2.565,1.685,0.034,,0.396471,432.902,,39.6471,0.432902,,,,7.85398e-5
Test1,3-Recover,160.600,2.593,1.657,0.027,,0.389882,343.775,,38.9882,0.343775,,,,7.85398e-5
Test1,3-Recover,160.933,2.622,1.628,0.027,,0.383059,343.775,,38.3059,0.343775,,,,7.85398e-5
Test1,3-Recover,161.267,2.651,1.599,0.027,,0.376235,343.775,,37.6235,0.343775,,,,7.85398e-5
Test1,3-Recover,161.600,2.679,1.571,0.027,,0.369647,343.775,,36.9647,0.343775,,,,7.85398e-5
Test1,3-Recover,161.933,2.707,1.543,0.027,,0.363059,343.775,,36.3059,0.343775,,,,7.85398e-5
Test1,3-Recover,162.267,2.736,1.514,0.027,,0.356235,343.775,,35.6235,0.343775,,,,7.85398e-5
Test1,3-Recover,162.600,2.763,1.487,0.027,,0.349882,343.775,,34.9882,0.343775,,,,7.85398e-5
Test1,3-Recover,162.933,2.792,1.458,0.027,,0.343059,343.775,,34.3059,0.343775,,,,7.85398e-5
Test1,3-Recover,163.267,2.821,1.429,0.027,,0.336235,343.775,,33.6235,0.343775,,,,7.85398e-5
Test1,3-Recover,163.600,2.849,1.401,0.027,,0.329647,343.775,,32.9647,0.343775,,,,7.85398e-5
Test1,3-Recover,163.933,2.877,1.373,0.027,,0.323059,343.775,,32.3059,0.343775,,,,7.85398e-5
Test1,3-Recover,164.267,2.906,1.344,0.027,,0.316235,343.775,,31.6235,0.343775,,,,7.85398e-5
Test1,3-Recover,164.600,2.934,1.316,0.027,,0.309647,343.775,,30.9647,0.343775,,,,7.85398e-5
Test1,3-Recover,164.933,2.962,1.288,0.027,,0.303059,343.775,,30.3059,0.343775,,,,7.85398e-5
Test1,3-Recover,165.267,2.991,1.259,0.027,,0.296235,343.775,,29.6235,0.343775,,,,7.85398e-5
Test1,3-Recover,165.600,3.019,1.231,0.027,,0.289647,343.775,,28.9647,0.343775,,,,7.85398e-5
Test1,3-Recover,165.933,3.047,1.203,0.027,,0.283059,343.775,,28.3059,0.343775,,,,7.85398e-5
Test1,3-Recover,166.267,3.076,1.174,0.027,,0.276235,343.775,,27.6235,0.343775,,,,7.85398e-5
Test1,3-Recover,166.600,3.104,1.146,0.027,,0.269647,343.775,,26.9647,0.343775,,,,7.85398e-5
Test1,3-Recover,166.933,3.132,1.118,0.027,,0.263059,343.775,,26.3059,0.343775,,,,7.85398e-5
Test1,3-Recover,167.267,3.161,1.089,0.034,,0.256235,432.902,,25.6235,0.432902,,,,7.85398e-5
Test1,3-Recover,167.600,3.189,1.061,0.027,,0.249647,343.775,,24.9647,0.343775,,,,7.85398e-5
Test1,3-Recover,167.933,3.218,1.032,0.027,,0.242824,343.775,,24.2824,0.343775,,,,7.85398e-5
Test1,3-Recover,168.267,3.247,1.003,0.027,,0.236,343.775,,23.6,0.343775,,,,7.85398e-5
Test1,3-Recover,168.600,3.274,0.976,0.027,,0.229647,343.775,,22.9647,0.343775,,,,7.85398e-5
Test1,3-Recover,168.933,3.303,0.947,0.027,,0.222824,343.775,,22.2824,0.343775,,,,7.85398e-5
Test1,3-Recover,169.267,3.332,0.918,0.027,,0.216,343.775,,21.6,0.343775,,,,7.85398e-5
Test1,3-Recover,169.600,3.359,0.891,0.027,,0.209647,343.775,,20.9647,0.343775,,,,7.85398e-5
Test1,3-Recover,169.933,3.388,0.862,0.027,,0.202824,343.775,,20.2824,0.343775,,,,7.85398e-5
Test1,3-Recover,170.267,3.417,0.833,0.027,,0.196,343.775,,19.6,0.343775,,,,7.85398e-5
Test1,3-Recover,170.600,3.445,0.805,0.027,,0.189412,343.775,,18.9412,0.343775,,,,7.85398e-5
Test1,3-Recover,170.933,3.473,0.777,0.027,,0.182824,343.775,,18.2824,0.343775,,,,7.85398e-5
Test1,3-Recover,171.267,3.502,0.748,0.027,,0.176,343.775,,17.6,0.343775,,,,7.85398e-5
Test1,3-Recover,171.600,3.53,0.72,0.027,,0.169412,343.775,,16.9412,0.343775,,,,7.85398e-5
Test1,3-Recover,171.933,3.558,0.692,0.027,,0.162824,343.775,,16.2824,0.343775,,,,7.85398e-5
Test1,3-Recover,172.267,3.587,0.663,0.027,,0.156,343.775,,15.6,0.343775,,,,7.85398e-5
Test1,3-Recover,172.600,3.615,0.635,0.020,,0.149412,254.648,,14.9412,0.254648,,,,7.85398e-5
Test1,3-Recover,172.933,3.643,0.607,0.027,,0.142824,343.775,,14.2824,0.343775,,,,7.85398e-5
Test1,3-Recover,173.267,3.672,0.578,0.027,,0.136,343.775,,13.6,0.343775,,,,7.85398e-5
Test1,3-Recover,173.600,3.7,0.55,0.027,,0.129412,343.775,,12.9412,0.343775,,,,7.85398e-5
Test1,3-Recover,173.933,3.728,0.522,0.014,,0.122824,178.254,,12.2824,0.178254,,,,7.85398e-5
Test1,3-Recover,174.267,3.757,0.493,0.027,,0.116,343.775,,11.6,0.343775,,,,7.85398e-5
Test1,3-Recover,174.600,3.785,0.465,0.027,,0.109412,343.775,,10.9412,0.343775,,,,7.85398e-5
Test1,3-Recover,174.933,3.813,0.437,0.027,,0.102824,343.775,,10.2824,0.343775,,,,7.85398e-5
Test1,3-Recover,175.267,3.842,0.408,0.027,,0.096,343.775,,9.6,0.343775,,,,7.85398e-5
Test1,3-Recover,175.600,3.87,0.38,0.027,,0.0894118,343.775,,8.94118,0.343775,,,,7.85398e-5
Test1,3-Recover,175.933,3.899,0.351,0.020,,0.0825882,254.648,,8.25882,0.254648,,,,7.85398e-5
Test1,3-Recover,176.267,3.927,0.323,0.027,,0.076,343.775,,7.6,0.343775,,,,7.85398e-5
Test1,3-Recover,176.600,3.955,0.295,0.027,,0.0694118,343.775,,6.94118,0.343775,,,,7.85398e-5
Test1,3-Recover,176.933,3.984,0.266,0.027,,0.0625882,343.775,,6.25882,0.343775,,,,7.85398e-5
Test1,3-Recover,177.267,4.012,0.238,0.020,,0.056,254.648,,5.6,0.254648,,,,7.85398e-5
Test1,3-Recover,177.600,4.041,0.209,0.020,,0.0491765,254.648,,4.91765,0.254648,,,,7.85398e-5
Test1,3-Recover,177.933,4.069,0.181,0.014,,0.0425882,178.254,,4.25882,0.178254,,,,7.85398e-5
Test1,3-Recover,178.267,4.098,0.152,0.014,,0.0357647,178.254,,3.57647,0.178254,,,,7.85398e-5
Test1,3-Recover,178.600,4.126,0.124,0.027,,0.0291765,343.775,,2.91765,0.343775,,,,7.85398e-5
Test1,3-Recover,178.933,4.154,0.096,0.027,,0.0225882,343.775,,2.25882,0.343775,,,,7.85398e-5
Test1,3-Recover,179.267,4.183,0.067,0.020,,0.0157647,254.648,,1.57647,0.254648,,,,7.85398e-5
Test1,3-Recover,179.600,4.211,0.039,0.020,,0.00917647,254.648,,0.917647,0.254648,,,,7.85398e-5
Test1,3-Recover,179.933,4.239,0.011,0.020,,0.00258824,254.648,,0.258824,0.254648,,,,7.85398e-5
Test1,3-Recover,180.100,4.25,-0,0.020,,0,254.648,,0,0.254648,,,,7.85398e-5