File: data/gamma_1-1_3.csv
SetName,Cycle,Time_S,Size_mm,Displacement_mm,Force_N,,Strain,Stress(Pascal),,%Strain,Stress(kPa),,,,Area(m^2)
Test1,1-Compress,0.000,3.043,-0,0.004,,0,50.9296,,0,0.0509296,,,,7.85398e-5
Test1,1-Compress,0.333,3.023,0.02,0.004,,0.00657246,50.9296,,0.657246,0.0509296,,,,7.85398e-5
Test1,1-Compress,0.667,3.003,0.04,0.004,,0.0131449,50.9296,,1.31449,0.0509296,,,,7.85398e-5
Test1,1-Compress,1.000,2.983,0.06,0.004,,0.0197174,50.9296,,1.97174,0.0509296,,,,7.85398e-5
Test1,1-Compress,1.333,2.962,0.081,0.004,,0.0266185,50.9296,,2.66185,0.0509296,,,,7.85398e-5
Test1,1-Compress,1.667,2.942,0.101,0.011,,0.0331909,140.056,,3.31909,0.140056,,,,7.85398e-5
Test1,1-Compress,2.000,2.921,0.122,0.011,,0.040092,140.056,,4.0092,0.140056,,,,7.85398e-5
Test1,1-Compress,2.333,2.902,0.141,0.004,,0.0463359,50.9296,,4.63359,0.0509296,,,,7.85398e-5
Test1,1-Compress,2.667,2.881,0.162,0.011,,0.0532369,140.056,,5.32369,0.140056,,,,7.85398e-5
Test1,1-Compress,3.000,2.861,0.182,0.004,,0.0598094,50.9296,,5.98094,0.0509296,,,,7.85398e-5
Test1,1-Compress,3.333,2.84,0.203,0.004,,0.0667105,50.9296,,6.67105,0.0509296,,,,7.85398e-5
Test1,1-Compress,3.667,2.82,0.223,-0.003,,0.0732829,-38.1972,,7.32829,-0.0381972,,,,7.85398e-5
Test1,1-Compress,4.000,2.8,0.243,-0.003,,0.0798554,-38.1972,,7.98554,-0.0381972,,,,7.85398e-5
Test1,1-Compress,4.333,2.78,0.263,-0.003,,0.0864279,-38.1972,,8.64279,-0.0381972,,,,7.85398e-5
Test1,1-Compress,4.667,2.759,0.284,0.004,,0.093329,50.9296,,9.3329,0.0509296,,,,7.85398e-5
Test1,1-Compress,5.000,2.739,0.304,-0.003,,0.0999014,-38.1972,,9.99014,-0.0381972,,,,7.85398e-5
Test1,1-Compress,5.333,2.719,0.324,0.011,,0.106474,140.056,,10.6474,0.140056,,,,7.85398e-5
Test1,1-Compress,5.667,2.698,0.345,0.004,,0.113375,50.9296,,11.3375,0.0509296,,,,7.85398e-5
Test1,1-Compress,6.000,2.678,0.365,0.011,,0.119947,140.056,,11.9947,0.140056,,,,7.85398e-5
Test1,1-Compress,6.333,2.657,0.386,0.004,,0.126849,50.9296,,12.6849,0.0509296,,,,7.85398e-5
Test1,1-Compress,6.667,2.637,0.406,0.011,,0.133421,140.056,,13.3421,0.140056,,,,7.85398e-5
Test1,1-Compress,7.000,2.617,0.426,0.004,,0.139993,50.9296,,13.9993,0.0509296,,,,7.85398e-5
Test1,1-Compress,7.333,2.597,0.446,0.004,,0.146566,50.9296,,14.6566,0.0509296,,,,7.85398e-5
Test1,1-Compress,7.667,2.576,0.467,0.004,,0.153467,50.9296,,15.3467,0.0509296,,,,7.85398e-5
Test1,1-Compress,8.000,2.556,0.487,0.004,,0.160039,50.9296,,16.0039,0.0509296,,,,7.85398e-5
Test1,1-Compress,8.333,2.536,0.507,0.004,,0.166612,50.9296,,16.6612,0.0509296,,,,7.85398e-5
Test1,1-Compress,8.667,2.515,0.528,0.004,,0.173513,50.9296,,17.3513,0.0509296,,,,7.85398e-5
Test1,1-Compress,9.000,2.495,0.548,0.004,,0.180085,50.9296,,18.0085,0.0509296,,,,7.85398e-5
Test1,1-Compress,9.333,2.475,0.568,0.011,,0.186658,140.056,,18.6658,0.140056,,,,7.85398e-5
Test1,1-Compress,9.667,2.454,0.589,0.011,,0.193559,140.056,,19.3559,0.140056,,,,7.85398e-5
Test1,1-Compress,10.000,2.434,0.609,0.018,,0.200131,229.183,,20.0131,0.229183,,,,7.85398e-5
Test1,1-Compress,10.333,2.414,0.629,0.011,,0.206704,140.056,,20.6704,0.140056,,,,7.85398e-5
Test1,1-Compress,10.667,2.393,0.65,0.025,,0.213605,318.31,,21.3605,0.31831,,,,7.85398e-5
Test1,1-Compress,11.000,2.373,0.67,0.018,,0.220177,229.183,,22.0177,0.229183,,,,7.85398e-5
Test1,1-Compress,11.333,2.353,0.69,0.018,,0.22675,229.183,,22.675,0.229183,,,,7.85398e-5
Test1,1-Compress,11.667,2.332,0.711,0.018,,0.233651,229.183,,23.3651,0.229183,,,,7.85398e-5
Test1,1-Compress,12.000,2.312,0.731,0.011,,0.240223,140.056,,24.0223,0.140056,,,,7.85398e-5
Test1,1-Compress,12.333,2.292,0.751,0.018,,0.246796,229.183,,24.6796,0.229183,,,,7.85398e-5
Test1,1-Compress,12.667,2.271,0.772,0.018,,0.253697,229.183,,25.3697,0.229183,,,,7.85398e-5
Test1,1-Compress,13.000,2.251,0.792,0.004,,0.260269,50.9296,,26.0269,0.0509296,,,,7.85398e-5
Test1,1-Compress,13.333,2.231,0.812,0.011,,0.266842,140.056,,26.6842,0.140056,,,,7.85398e-5
Test1,1-Compress,13.667,2.21,0.833,0.011,,0.273743,140.056,,27.3743,0.140056,,,,7.85398e-5
Test1,1-Compress,14.000,2.19,0.853,0.011,,0.280315,140.056,,28.0315,0.140056,,,,7.85398e-5
Test1,1-Compress,14.333,2.17,0.873,0.004,,0.286888,50.9296,,28.6888,0.0509296,,,,7.85398e-5
Test1,1-Compress,14.667,2.149,0.894,0.018,,0.293789,229.183,,29.3789,0.229183,,,,7.85398e-5
Test1,1-Compress,15.000,2.129,0.914,0.004,,0.300361,50.9296,,30.0361,0.0509296,,,,7.85398e-5
Test1,1-Compress,15.333,2.109,0.934,0.004,,0.306934,50.9296,,30.6934,0.0509296,,,,7.85398e-5
Test1,1-Compress,15.667,2.089,0.954,0.004,,0.313506,50.9296,,31.3506,0.0509296,,,,7.85398e-5
Test1,1-Compress,16.000,2.068,0.975,0.004,,0.320407,50.9296,,32.0407,0.0509296,,,,7.85398e-5
Test1,1-Compress,16.333,2.048,0.995,0.011,,0.32698,140.056,,32.698,0.140056,,,,7.85398e-5
Test1,1-Compress,16.667,2.027,1.016,0.004,,0.333881,50.9296,,33.3881,0.0509296,,,,7.85398e-5
Test1,1-Compress,17.000,2.007,1.036,0.004,,0.340453,50.9296,,34.0453,0.0509296,,,,7.85398e-5
Test1,1-Compress,17.333,1.987,1.056,0.018,,0.347026,229.183,,34.7026,0.229183,,,,7.85398e-5
Test1,1-Compress,17.667,1.966,1.077,0.018,,0.353927,229.183,,35.3927,0.229183,,,,7.85398e-5
Test1,1-Compress,18.000,1.946,1.097,0.025,,0.3605,318.31,,36.05,0.31831,,,,7.85398e-5
Test1,1-Compress,18.333,1.926,1.117,0.025,,0.367072,318.31,,36.7072,0.31831,,,,7.85398e-5
Test1,1-Compress,18.667,1.906,1.137,0.025,,0.373644,318.31,,37.3644,0.31831,,,,7.85398e-5
Test1,1-Compress,19.000,1.885,1.158,0.031,,0.380546,394.704,,38.0546,0.394704,,,,7.85398e-5
Test1,1-Compress,19.333,1.865,1.178,0.025,,0.387118,318.31,,38.7118,0.31831,,,,7.85398e-5
Test1,1-Compress,19.667,1.844,1.199,0.025,,0.394019,318.31,,39.4019,0.31831,,,,7.85398e-5
Test1,1-Compress,20.000,1.825,1.218,0.031,,0.400263,394.704,,40.0263,0.394704,,,,7.85398e-5
Test1,1-Compress,20.333,1.804,1.239,0.038,,0.407164,483.831,,40.7164,0.483831,,,,7.85398e-5
Test1,1-Compress,20.667,1.784,1.259,0.018,,0.413736,229.183,,41.3736,0.229183,,,,7.85398e-5
Test1,1-Compress,21.000,1.764,1.279,0.025,,0.420309,318.31,,42.0309,0.31831,,,,7.85398e-5
Test1,1-Compress,21.333,1.743,1.3,0.031,,0.42721,394.704,,42.721,0.394704,,,,7.85398e-5
Test1,1-Compress,21.667,1.723,1.32,0.025,,0.433782,318.31,,43.3782,0.31831,,,,7.85398e-5
Test1,1-Compress,22.000,1.702,1.341,0.031,,0.440684,394.704,,44.0684,0.394704,,,,7.85398e-5
Test1,1-Compress,22.333,1.683,1.36,0.031,,0.446927,394.704,,44.6927,0.394704,,,,7.85398e-5
Test1,1-Compress,22.667,1.662,1.381,0.018,,0.453828,229.183,,45.3828,0.229183,,,,7.85398e-5
Test1,1-Compress,23.000,1.642,1.401,0.045,,0.460401,572.958,,46.0401,0.572958,,,,7.85398e-5
Test1,1-Compress,23.333,1.621,1.422,0.031,,0.467302,394.704,,46.7302,0.394704,,,,7.85398e-5
Test1,1-Compress,23.667,1.601,1.442,0.025,,0.473874,318.31,,47.3874,0.31831,,,,7.85398e-5
Test1,1-Compress,24.000,1.58,1.463,0.031,,0.480776,394.704,,48.0776,0.394704,,,,7.85398e-5
Test1,1-Compress,24.333,1.561,1.482,0.025,,0.487019,318.31,,48.7019,0.31831,,,,7.85398e-5
Test1,1-Compress,24.667,1.54,1.503,0.045,,0.49392,572.958,,49.392,0.572958,,,,7.85398e-5
Test1,1-Compress,25.000,1.52,1.523,0.025,,0.500493,318.31,,50.0493,0.31831,,,,7.85398e-5
Test1,1-Compress,25.333,1.5,1.543,0.025,,0.507065,318.31,,50.7065,0.31831,,,,7.85398e-5
Test1,1-Compress,25.667,1.479,1.564,0.052,,0.513966,662.085,,51.3966,0.662085,,,,7.85398e-5
Test1,1-Compress,26.000,1.459,1.584,0.045,,0.520539,572.958,,52.0539,0.572958,,,,7.85398e-5
Test1,1-Compress,26.333,1.438,1.605,0.052,,0.52744,662.085,,52.744,0.662085,,,,7.85398e-5
Test1,1-Compress,26.667,1.418,1.625,0.045,,0.534012,572.958,,53.4012,0.572958,,,,7.85398e-5
Test1,1-Compress,27.000,1.398,1.645,0.052,,0.540585,662.085,,54.0585,0.662085,,,,7.85398e-5
Test1,1-Compress,27.333,1.378,1.665,0.045,,0.547157,572.958,,54.7157,0.572958,,,,7.85398e-5
Test1,1-Compress,27.667,1.357,1.686,0.045,,0.554058,572.958,,55.4058,0.572958,,,,7.85398e-5
Test1,1-Compress,28.000,1.337,1.706,0.052,,0.560631,662.085,,56.0631,0.662085,,,,7.85398e-5
Test1,1-Compress,28.333,1.317,1.726,0.052,,0.567203,662.085,,56.7203,0.662085,,,,7.85398e-5
Test1,1-Compress,28.667,1.296,1.747,0.052,,0.574105,662.085,,57.4105,0.662085,,,,7.85398e-5
Test1,1-Compress,29.000,1.276,1.767,0.052,,0.580677,662.085,,58.0677,0.662085,,,,7.85398e-5
Test1,1-Compress,29.333,1.256,1.787,0.052,,0.587249,662.085,,58.7249,0.662085,,,,7.85398e-5
Test1,1-Compress,29.667,1.235,1.808,0.052,,0.594151,662.085,,59.4151,0.662085,,,,7.85398e-5
Test1,1-Compress,30.000,1.217,1.826,0.052,,0.600066,662.085,,60.0066,0.662085,,,,7.85398e-5
Test1,1-Recover,30.333,1.236,1.807,0.052,,0.593822,662.085,,59.3822,0.662085,,,,7.85398e-5
Test1,1-Recover,30.667,1.257,1.786,0.052,,0.586921,662.085,,58.6921,0.662085,,,,7.85398e-5
Test1,1-Recover,31.000,1.277,1.766,0.052,,0.580348,662.085,,58.0348,0.662085,,,,7.85398e-5
Test1,1-Recover,31.333,1.297,1.746,0.052,,0.573776,662.085,,57.3776,0.662085,,,,7.85398e-5
Test1,1-Recover,31.667,1.317,1.726,0.045,,0.567203,572.958,,56.7203,0.572958,,,,7.85398e-5
Test1,1-Recover,32.000,1.338,1.705,0.038,,0.560302,483.831,,56.0302,0.483831,,,,7.85398e-5
Test1,1-Recover,32.333,1.358,1.685,0.045,,0.55373,572.958,,55.373,0.572958,,,,7.85398e-5
Test1,1-Recover,32.667,1.379,1.664,0.045,,0.546829,572.958,,54.6829,0.572958,,,,7.85398e-5
Test1,1-Recover,33.000,1.399,1.644,0.038,,0.540256,483.831,,54.0256,0.483831,,,,7.85398e-5
Test1,1-Recover,33.333,1.419,1.624,0.045,,0.533684,572.958,,53.3684,0.572958,,,,7.85398e-5
Test1,1-Recover,33.667,1.439,1.604,0.052,,0.527111,662.085,,52.7111,0.662085,,,,7.85398e-5
Test1,1-Recover,34.000,1.46,1.583,0.045,,0.52021,572.958,,52.021,0.572958,,,,7.85398e-5
Test1,1-Recover,34.333,1.48,1.563,0.045,,0.513638,572.958,,51.3638,0.572958,,,,7.85398e-5
Test1,1-Recover,34.667,1.501,1.542,0.038,,0.506737,483.831,,50.6737,0.483831,,,,7.85398e-5
Test1,1-Recover,35.000,1.521,1.522,0.038,,0.500164,483.831,,50.0164,0.483831,,,,7.85398e-5
Test1,1-Recover,35.333,1.54,1.503,0.038,,0.49392,483.831,,49.392,0.483831,,,,7.85398e-5
Test1,1-Recover,35.667,1.562,1.481,0.045,,0.486691,572.958,,48.6691,0.572958,,,,7.85398e-5
Test1,1-Recover,36.000,1.581,1.462,0.031,,0.480447,394.704,,48.0447,0.394704,,,,7.85398e-5
Test1,1-Recover,36.333,1.602,1.441,0.031,,0.473546,394.704,,47.3546,0.394704,,,,7.85398e-5
Test1,1-Recover,36.667,1.622,1.421,0.038,,0.466973,483.831,,46.6973,0.483831,,,,7.85398e-5
Test1,1-Recover,37.000,1.643,1.4,0.025,,0.460072,318.31,,46.0072,0.31831,,,,7.85398e-5
Test1,1-Recover,37.333,1.663,1.38,0.025,,0.4535,318.31,,45.35,0.31831,,,,7.85398e-5
Test1,1-Recover,37.667,1.683,1.36,0.031,,0.446927,394.704,,44.6927,0.394704,,,,7.85398e-5
Test1,1-Recover,38.000,1.703,1.34,0.025,,0.440355,318.31,,44.0355,0.31831,,,,7.85398e-5
Test1,1-Recover,38.333,1.724,1.319,0.018,,0.433454,229.183,,43.3454,0.229183,,,,7.85398e-5
Test1,1-Recover,38.667,1.744,1.299,0.018,,0.426881,229.183,,42.6881,0.229183,,,,7.85398e-5
Test1,1-Recover,39.000,1.764,1.279,0.004,,0.420309,50.9296,,42.0309,0.0509296,,,,7.85398e-5
Test1,1-Recover,39.333,1.785,1.258,0.018,,0.413408,229.183,,41.3408,0.229183,,,,7.85398e-5
Test1,1-Recover,39.667,1.805,1.238,0.004,,0.406835,50.9296,,40.6835,0.0509296,,,,7.85398e-5
Test1,1-Recover,40.000,1.826,1.217,0.004,,0.399934,50.9296,,39.9934,0.0509296,,,,7.85398e-5
Test1,1-Recover,40.333,1.845,1.198,0.004,,0.39369,50.9296,,39.369,0.0509296,,,,7.85398e-5
Test1,1-Recover,40.667,1.866,1.177,0.004,,0.386789,50.9296,,38.6789,0.0509296,,,,7.85398e-5
Test1,1-Recover,41.000,1.886,1.157,0.011,,0.380217,140.056,,38.0217,0.140056,,,,7.85398e-5
Test1,1-Recover,41.333,1.906,1.137,0.004,,0.373644,50.9296,,37.3644,0.0509296,,,,7.85398e-5
Test1,1-Recover,41.667,1.927,1.116,0.011,,0.366743,140.056,,36.6743,0.140056,,,,7.85398e-5
Test1,1-Recover,42.000,1.947,1.096,0.011,,0.360171,140.056,,36.0171,0.140056,,,,7.85398e-5
Test1,1-Recover,42.333,1.967,1.076,0.018,,0.353598,229.183,,35.3598,0.229183,,,,7.85398e-5
Test1,1-Recover,42.667,1.988,1.055,0.025,,0.346697,318.31,,34.6697,0.31831,,,,7.85398e-5
Test1,1-Recover,43.000,2.008,1.035,0.025,,0.340125,318.31,,34.0125,0.31831,,,,7.85398e-5
Test1,1-Recover,43.333,2.028,1.015,0.018,,0.333552,229.183,,33.3552,0.229183,,,,7.85398e-5
Test1,1-Recover,43.667,2.049,0.994,0.011,,0.326651,140.056,,32.6651,0.140056,,,,7.85398e-5
Test1,1-Recover,44.000,2.069,0.974,0.025,,0.320079,318.31,,32.0079,0.31831,,,,7.85398e-5
Test1,1-Recover,44.333,2.09,0.953,0.025,,0.313178,318.31,,31.3178,0.31831,,,,7.85398e-5
Test1,1-Recover,44.667,2.11,0.933,0.011,,0.306605,140.056,,30.6605,0.140056,,,,7.85398e-5
Test1,1-Recover,45.000,2.13,0.913,0.011,,0.300033,140.056,,30.0033,0.140056,,,,7.85398e-5
Test1,1-Recover,45.333,2.15,0.893,0.018,,0.29346,229.183,,29.346,0.229183,,,,7.85398e-5
Test1,1-Recover,45.667,2.171,0.872,0.011,,0.286559,140.056,,28.6559,0.140056,,,,7.85398e-5
Test1,1-Recover,46.000,2.191,0.852,0.004,,0.279987,50.9296,,27.9987,0.0509296,,,,7.85398e-5
Test1,1-Recover,46.333,2.211,0.832,0.011,,0.273414,140.056,,27.3414,0.140056,,,,7.85398e-5
Test1,1-Recover,46.667,2.232,0.811,0.011,,0.266513,140.056,,26.6513,0.140056,,,,7.85398e-5
Test1,1-Recover,47.000,2.252,0.791,0.004,,0.259941,50.9296,,25.9941,0.0509296,,,,7.85398e-5
Test1,1-Recover,47.333,2.272,0.771,0.004,,0.253368,50.9296,,25.3368,0.0509296,,,,7.85398e-5
Test1,1-Recover,47.667,2.293,0.75,0.004,,0.246467,50.9296,,24.6467,0.0509296,,,,7.85398e-5
Test1,1-Recover,48.000,2.313,0.73,0.004,,0.239895,50.9296,,23.9895,0.0509296,,,,7.85398e-5
Test1,1-Recover,48.333,2.333,0.71,0.004,,0.233322,50.9296,,23.3322,0.0509296,,,,7.85398e-5
Test1,1-Recover,48.667,2.354,0.689,0.004,,0.226421,50.9296,,22.6421,0.0509296,,,,7.85398e-5
Test1,1-Recover,49.000,2.374,0.669,0.004,,0.219849,50.9296,,21.9849,0.0509296,,,,7.85398e-5
Test1,1-Recover,49.333,2.394,0.649,0.004,,0.213276,50.9296,,21.3276,0.0509296,,,,7.85398e-5
Test1,1-Recover,49.667,2.415,0.628,0.011,,0.206375,140.056,,20.6375,0.140056,,,,7.85398e-5
Test1,1-Recover,50.000,2.435,0.608,0.011,,0.199803,140.056,,19.9803,0.140056,,,,7.85398e-5
Test1,1-Recover,50.333,2.455,0.588,0.011,,0.19323,140.056,,19.323,0.140056,,,,7.85398e-5
Test1,1-Recover,50.667,2.476,0.567,0.025,,0.186329,318.31,,18.6329,0.31831,,,,7.85398e-5
Test1,1-Recover,51.000,2.496,0.547,0.011,,0.179757,140.056,,17.9757,0.140056,,,,7.85398e-5
Test1,1-Recover,51.333,2.516,0.527,0.011,,0.173184,140.056,,17.3184,0.140056,,,,7.85398e-5
Test1,1-Recover,51.667,2.537,0.506,0.011,,0.166283,140.056,,16.6283,0.140056,,,,7.85398e-5
Test1,1-Recover,52.000,2.557,0.486,0.018,,0.159711,229.183,,15.9711,0.229183,,,,7.85398e-5
Test1,1-Recover,52.333,2.577,0.466,0.004,,0.153138,50.9296,,15.3138,0.0509296,,,,7.85398e-5
Test1,1-Recover,52.667,2.598,0.445,0.011,,0.146237,140.056,,14.6237,0.140056,,,,7.85398e-5
Test1,1-Recover,53.000,2.618,0.425,0.011,,0.139665,140.056,,13.9665,0.140056,,,,7.85398e-5
Test1,1-Recover,53.333,2.638,0.405,0.004,,0.133092,50.9296,,13.3092,0.0509296,,,,7.85398e-5
Test1,1-Recover,53.667,2.658,0.385,0.004,,0.12652,50.9296,,12.652,0.0509296,,,,7.85398e-5
Test1,1-Recover,54.000,2.679,0.364,0.004,,0.119619,50.9296,,11.9619,0.0509296,,,,7.85398e-5
Test1,1-Recover,54.333,2.699,0.344,0.004,,0.113046,50.9296,,11.3046,0.0509296,,,,7.85398e-5
Test1,1-Recover,54.667,2.72,0.323,0.004,,0.106145,50.9296,,10.6145,0.0509296,,,,7.85398e-5
Test1,1-Recover,55.000,2.74,0.303,-0.003,,0.0995728,-38.1972,,9.95728,-0.0381972,,,,7.85398e-5
Test1,1-Recover,55.333,2.76,0.283,-0.003,,0.0930003,-38.1972,,9.30003,-0.0381972,,,,7.85398e-5
Test1,1-Recover,55.667,2.781,0.262,0.004,,0.0860992,50.9296,,8.60992,0.0509296,,,,7.85398e-5
Test1,1-Recover,56.000,2.8,0.243,0.004,,0.0798554,50.9296,,7.98554,0.0509296,,,,7.85398e-5
Test1,1-Recover,56.333,2.821,0.222,0.004,,0.0729543,50.9296,,7.29543,0.0509296,,,,7.85398e-5
Test1,1-Recover,56.667,2.841,0.202,0.004,,0.0663819,50.9296,,6.63819,0.0509296,,,,7.85398e-5
Test1,1-Recover,57.000,2.862,0.181,0.004,,0.0594808,50.9296,,5.94808,0.0509296,,,,7.85398e-5
Test1,1-Recover,57.333,2.882,0.161,0.011,,0.0529083,140.056,,5.29083,0.140056,,,,7.85398e-5
Test1,1-Recover,57.667,2.903,0.14,0.004,,0.0460072,50.9296,,4.60072,0.0509296,,,,7.85398e-5
Test1,1-Recover,58.000,2.922,0.121,0.018,,0.0397634,229.183,,3.97634,0.229183,,,,7.85398e-5
Test1,1-Recover,58.333,2.943,0.1,0.011,,0.0328623,140.056,,3.28623,0.140056,,,,7.85398e-5
Test1,1-Recover,58.667,2.963,0.08,0.018,,0.0262898,229.183,,2.62898,0.229183,,,,7.85398e-5
Test1,1-Recover,59.000,2.984,0.059,0.004,,0.0193888,50.9296,,1.93888,0.0509296,,,,7.85398e-5
Test1,1-Recover,59.333,3.004,0.039,0.011,,0.0128163,140.056,,1.28163,0.140056,,,,7.85398e-5
Test1,1-Recover,59.667,3.024,0.019,0.018,,0.00624384,229.183,,0.624384,0.229183,,,,7.85398e-5
Test1,1-Recover,60.000,3.043,-0,0.011,,0,140.056,,0,0.140056,,,,7.85398e-5
Test1,2-Compress,60.317,3.026,0.017,-0.003,,0.00558659,-38.1972,,0.558659,-0.0381972,,,,7.85398e-5
Test1,2-Compress,60.650,3.006,0.037,0.011,,0.0121591,140.056,,1.21591,0.140056,,,,7.85398e-5
Test1,2-Compress,60.983,2.986,0.057,0.004,,0.0187315,50.9296,,1.87315,0.0509296,,,,7.85398e-5
Test1,2-Compress,61.317,2.965,0.078,0.004,,0.0256326,50.9296,,2.56326,0.0509296,,,,7.85398e-5
Test1,2-Compress,61.650,2.945,0.098,0.004,,0.0322051,50.9296,,3.22051,0.0509296,,,,7.85398e-5
Test1,2-Compress,61.983,2.925,0.118,0.004,,0.0387775,50.9296,,3.87775,0.0509296,,,,7.85398e-5
Test1,2-Compress,62.317,2.904,0.139,0.004,,0.0456786,50.9296,,4.56786,0.0509296,,,,7.85398e-5
Test1,2-Compress,62.650,2.884,0.159,-0.003,,0.0522511,-38.1972,,5.22511,-0.0381972,,,,7.85398e-5
Test1,2-Compress,62.983,2.864,0.179,0.004,,0.0588235,50.9296,,5.88235,0.0509296,,,,7.85398e-5
Test1,2-Compress,63.317,2.843,0.2,0.004,,0.0657246,50.9296,,6.57246,0.0509296,,,,7.85398e-5
Test1,2-Compress,63.650,2.823,0.22,0.004,,0.0722971,50.9296,,7.22971,0.0509296,,,,7.85398e-5
Test1,2-Compress,63.983,2.803,0.24,-0.003,,0.0788695,-38.1972,,7.88695,-0.0381972,,,,7.85398e-5
Test1,2-Compress,64.317,2.783,0.26,0.004,,0.085442,50.9296,,8.5442,0.0509296,,,,7.85398e-5
Test1,2-Compress,64.650,2.762,0.281,0.004,,0.0923431,50.9296,,9.23431,0.0509296,,,,7.85398e-5
Test1,2-Compress,64.983,2.742,0.301,0.004,,0.0989155,50.9296,,9.89155,0.0509296,,,,7.85398e-5
Test1,2-Compress,65.317,2.721,0.322,0.004,,0.105817,50.9296,,10.5817,0.0509296,,,,7.85398e-5
Test1,2-Compress,65.650,2.701,0.342,0.004,,0.112389,50.9296,,11.2389,0.0509296,,,,7.85398e-5
Test1,2-Compress,65.983,2.681,0.362,0.004,,0.118962,50.9296,,11.8962,0.0509296,,,,7.85398e-5
Test1,2-Compress,66.317,2.66,0.383,0.011,,0.125863,140.056,,12.5863,0.140056,,,,7.85398e-5
Test1,2-Compress,66.650,2.64,0.403,0.011,,0.132435,140.056,,13.2435,0.140056,,,,7.85398e-5
Test1,2-Compress,66.983,2.62,0.423,0.011,,0.139008,140.056,,13.9008,0.140056,,,,7.85398e-5
Test1,2-Compress,67.317,2.599,0.444,0.011,,0.145909,140.056,,14.5909,0.140056,,,,7.85398e-5
Test1,2-Compress,67.650,2.579,0.464,0.018,,0.152481,229.183,,15.2481,0.229183,,,,7.85398e-5
Test1,2-Compress,67.983,2.559,0.484,0.031,,0.159054,394.704,,15.9054,0.394704,,,,7.85398e-5
Test1,2-Compress,68.317,2.538,0.505,0.018,,0.165955,229.183,,16.5955,0.229183,,,,7.85398e-5
Test1,2-Compress,68.650,2.519,0.524,0.011,,0.172198,140.056,,17.2198,0.140056,,,,7.85398e-5
Test1,2-Compress,68.983,2.498,0.545,0.018,,0.1791,229.183,,17.91,0.229183,,,,7.85398e-5
Test1,2-Compress,69.317,2.478,0.565,0.011,,0.185672,140.056,,18.5672,0.140056,,,,7.85398e-5
Test1,2-Compress,69.650,2.457,0.586,0.011,,0.192573,140.056,,19.2573,0.140056,,,,7.85398e-5
Test1,2-Compress,69.983,2.437,0.606,0.011,,0.199146,140.056,,19.9146,0.140056,,,,7.85398e-5
Test1,2-Compress,70.317,2.417,0.626,0.004,,0.205718,50.9296,,20.5718,0.0509296,,,,7.85398e-5
Test1,2-Compress,70.650,2.396,0.647,0.004,,0.212619,50.9296,,21.2619,0.0509296,,,,7.85398e-5
Test1,2-Compress,70.983,2.376,0.667,0.011,,0.219192,140.056,,21.9192,0.140056,,,,7.85398e-5
Test1,2-Compress,71.317,2.356,0.687,0.004,,0.225764,50.9296,,22.5764,0.0509296,,,,7.85398e-5
Test1,2-Compress,71.650,2.336,0.707,0.004,,0.232337,50.9296,,23.2337,0.0509296,,,,7.85398e-5
Test1,2-Compress,71.983,2.315,0.728,0.004,,0.239238,50.9296,,23.9238,0.0509296,,,,7.85398e-5
Test1,2-Compress,72.317,2.295,0.748,0.004,,0.24581,50.9296,,24.581,0.0509296,,,,7.85398e-5
Test1,2-Compress,72.650,2.274,0.769,0.004,,0.252711,50.9296,,25.2711,0.0509296,,,,7.85398e-5
Test1,2-Compress,72.983,2.255,0.788,0.004,,0.258955,50.9296,,25.8955,0.0509296,,,,7.85398e-5
Test1,2-Compress,73.317,2.234,0.809,0.004,,0.265856,50.9296,,26.5856,0.0509296,,,,7.85398e-5
Test1,2-Compress,73.650,2.214,0.829,0.004,,0.272429,50.9296,,27.2429,0.0509296,,,,7.85398e-5
Test1,2-Compress,73.983,2.194,0.849,0.011,,0.279001,140.056,,27.9001,0.140056,,,,7.85398e-5
Test1,2-Compress,74.317,2.173,0.87,0.011,,0.285902,140.056,,28.5902,0.140056,,,,7.85398e-5
Test1,2-Compress,74.650,2.153,0.89,0.018,,0.292475,229.183,,29.2475,0.229183,,,,7.85398e-5
Test1,2-Compress,74.983,2.132,0.911,0.025,,0.299376,318.31,,29.9376,0.31831,,,,7.85398e-5
Test1,2-Compress,75.317,2.112,0.931,0.025,,0.305948,318.31,,30.5948,0.31831,,,,7.85398e-5
Test1,2-Compress,75.650,2.092,0.951,0.018,,0.312521,229.183,,31.2521,0.229183,,,,7.85398e-5
Test1,2-Compress,75.983,2.072,0.971,0.025,,0.319093,318.31,,31.9093,0.31831,,,,7.85398e-5
Test1,2-Compress,76.317,2.051,0.992,0.031,,0.325994,394.704,,32.5994,0.394704,,,,7.85398e-5
Test1,2-Compress,76.650,2.031,1.012,0.025,,0.332567,318.31,,33.2567,0.31831,,,,7.85398e-5
Test1,2-Compress,76.983,2.01,1.033,0.018,,0.339468,229.183,,33.9468,0.229183,,,,7.85398e-5
Test1,2-Compress,77.317,1.99,1.053,0.018,,0.34604,229.183,,34.604,0.229183,,,,7.85398e-5
Test1,2-Compress,77.650,1.97,1.073,0.018,,0.352613,229.183,,35.2613,0.229183,,,,7.85398e-5
Test1,2-Compress,77.983,1.95,1.093,0.018,,0.359185,229.183,,35.9185,0.229183,,,,7.85398e-5
Test1,2-Compress,78.317,1.929,1.114,0.025,,0.366086,318.31,,36.6086,0.31831,,,,7.85398e-5
Test1,2-Compress,78.650,1.909,1.134,0.018,,0.372659,229.183,,37.2659,0.229183,,,,7.85398e-5
Test1,2-Compress,78.983,1.889,1.154,0.011,,0.379231,140.056,,37.9231,0.140056,,,,7.85398e-5
Test1,2-Compress,79.317,1.868,1.175,0.025,,0.386132,318.31,,38.6132,0.31831,,,,7.85398e-5
Test1,2-Compress,79.650,1.848,1.195,0.018,,0.392705,229.183,,39.2705,0.229183,,,,7.85398e-5
Test1,2-Compress,79.983,1.828,1.215,0.018,,0.399277,229.183,,39.9277,0.229183,,,,7.85398e-5
Test1,2-Compress,80.317,1.807,1.236,0.031,,0.406178,394.704,,40.6178,0.394704,,,,7.85398e-5
Test1,2-Compress,80.650,1.787,1.256,0.031,,0.412751,394.704,,41.2751,0.394704,,,,7.85398e-5
Test1,2-Compress,80.983,1.767,1.276,0.025,,0.419323,318.31,,41.9323,0.31831,,,,7.85398e-5
Test1,2-Compress,81.317,1.746,1.297,0.004,,0.426224,50.9296,,42.6224,0.0509296,,,,7.85398e-5
Test1,2-Compress,81.650,1.726,1.317,0.004,,0.432797,50.9296,,43.2797,0.0509296,,,,7.85398e-5
Test1,2-Compress,81.983,1.706,1.337,0.025,,0.439369,318.31,,43.9369,0.31831,,,,7.85398e-5
Test1,2-Compress,82.317,1.685,1.358,0.031,,0.44627,394.704,,44.627,0.394704,,,,7.85398e-5
Test1,2-Compress,82.650,1.665,1.378,0.025,,0.452843,318.31,,45.2843,0.31831,,,,7.85398e-5
Test1,2-Compress,82.983,1.645,1.398,0.045,,0.459415,572.958,,45.9415,0.572958,,,,7.85398e-5
Test1,2-Compress,83.317,1.624,1.419,0.045,,0.466316,572.958,,46.6316,0.572958,,,,7.85398e-5
Test1,2-Compress,83.650,1.604,1.439,0.038,,0.472889,483.831,,47.2889,0.483831,,,,7.85398e-5
Test1,2-Compress,83.983,1.584,1.459,0.045,,0.479461,572.958,,47.9461,0.572958,,,,7.85398e-5
Test1,2-Compress,84.317,1.563,1.48,0.052,,0.486362,662.085,,48.6362,0.662085,,,,7.85398e-5
Test1,2-Compress,84.650,1.543,1.5,0.052,,0.492935,662.085,,49.2935,0.662085,,,,7.85398e-5
Test1,2-Compress,84.983,1.523,1.52,0.038,,0.499507,483.831,,49.9507,0.483831,,,,7.85398e-5
Test1,2-Compress,85.317,1.502,1.541,0.031,,0.506408,394.704,,50.6408,0.394704,,,,7.85398e-5
Test1,2-Compress,85.650,1.482,1.561,0.031,,0.512981,394.704,,51.2981,0.394704,,,,7.85398e-5
Test1,2-Compress,85.983,1.462,1.581,0.052,,0.519553,662.085,,51.9553,0.662085,,,,7.85398e-5
Test1,2-Compress,86.317,1.441,1.602,0.052,,0.526454,662.085,,52.6454,0.662085,,,,7.85398e-5
Test1,2-Compress,86.650,1.421,1.622,0.052,,0.533027,662.085,,53.3027,0.662085,,,,7.85398e-5
Test1,2-Compress,86.983,1.401,1.642,0.045,,0.539599,572.958,,53.9599,0.572958,,,,7.85398e-5
Test1,2-Compress,87.317,1.38,1.663,0.038,,0.5465,483.831,,54.65,0.483831,,,,7.85398e-5
Test1,2-Compress,87.650,1.36,1.683,0.052,,0.553073,662.085,,55.3073,0.662085,,,,7.85398e-5
Test1,2-Compress,87.983,1.34,1.703,0.045,,0.559645,572.958,,55.9645,0.572958,,,,7.85398e-5
Test1,2-Compress,88.317,1.319,1.724,0.038,,0.566546,483.831,,56.6546,0.483831,,,,7.85398e-5
Test1,2-Compress,88.650,1.299,1.744,0.052,,0.573119,662.085,,57.3119,0.662085,,,,7.85398e-5
Test1,2-Compress,88.983,1.279,1.764,0.052,,0.579691,662.085,,57.9691,0.662085,,,,7.85398e-5
Test1,2-Compress,89.317,1.259,1.784,0.052,,0.586264,662.085,,58.6264,0.662085,,,,7.85398e-5
Test1,2-Compress,89.650,1.238,1.805,0.052,,0.593165,662.085,,59.3165,0.662085,,,,7.85398e-5
Test1,2-Compress,89.983,1.218,1.825,0.052,,0.599737,662.085,,59.9737,0.662085,,,,7.85398e-5
Test1,2-Recover,90.303,1.232,1.811,0.052,,0.595136,662.085,,59.5136,0.662085,,,,7.85398e-5
Test1,2-Recover,90.637,1.253,1.79,0.045,,0.588235,572.958,,58.8235,0.572958,,,,7.85398e-5
Test1,2-Recover,90.970,1.272,1.771,0.052,,0.581991,662.085,,58.1991,0.662085,,,,7.85398e-5
Test1,2-Recover,91.303,1.293,1.75,0.045,,0.57509,572.958,,57.509,0.572958,,,,7.85398e-5
Test1,2-Recover,91.637,1.313,1.73,0.052,,0.568518,662.085,,56.8518,0.662085,,,,7.85398e-5
Test1,2-Recover,91.970,1.334,1.709,0.052,,0.561617,662.085,,56.1617,0.662085,,,,7.85398e-5
Test1,2-Recover,92.303,1.354,1.689,0.052,,0.555044,662.085,,55.5044,0.662085,,,,7.85398e-5
Test1,2-Recover,92.637,1.374,1.669,0.052,,0.548472,662.085,,54.8472,0.662085,,,,7.85398e-5
Test1,2-Recover,92.970,1.395,1.648,0.038,,0.541571,483.831,,54.1571,0.483831,,,,7.85398e-5
Test1,2-Recover,93.303,1.414,1.629,0.031,,0.535327,394.704,,53.5327,0.394704,,,,7.85398e-5
Test1,2-Recover,93.637,1.436,1.607,0.045,,0.528097,572.958,,52.8097,0.572958,,,,7.85398e-5
Test1,2-Recover,93.970,1.455,1.588,0.045,,0.521853,572.958,,52.1853,0.572958,,,,7.85398e-5
Test1,2-Recover,94.303,1.476,1.567,0.038,,0.514952,483.831,,51.4952,0.483831,,,,7.85398e-5
Test1,2-Recover,94.637,1.496,1.547,0.031,,0.50838,394.704,,50.838,0.394704,,,,7.85398e-5
Test1,2-Recover,94.970,1.517,1.526,0.038,,0.501479,483.831,,50.1479,0.483831,,,,7.85398e-5
Test1,2-Recover,95.303,1.536,1.507,0.045,,0.495235,572.958,,49.5235,0.572958,,,,7.85398e-5
Test1,2-Recover,95.637,1.557,1.486,0.025,,0.488334,318.31,,48.8334,0.31831,,,,7.85398e-5
Test1,2-Recover,95.970,1.577,1.466,0.031,,0.481761,394.704,,48.1761,0.394704,,,,7.85398e-5
Test1,2-Recover,96.303,1.598,1.445,0.038,,0.47486,483.831,,47.486,0.483831,,,,7.85398e-5
Test1,2-Recover,96.637,1.618,1.425,0.025,,0.468288,318.31,,46.8288,0.31831,,,,7.85398e-5
Test1,2-Recover,96.970,1.638,1.405,0.004,,0.461715,50.9296,,46.1715,0.0509296,,,,7.85398e-5
Test1,2-Recover,97.303,1.659,1.384,0.038,,0.454814,483.831,,45.4814,0.483831,,,,7.85398e-5
Test1,2-Recover,97.637,1.679,1.364,0.038,,0.448242,483.831,,44.8242,0.483831,,,,7.85398e-5
Test1,2-Recover,97.970,1.7,1.343,0.011,,0.441341,140.056,,44.1341,0.140056,,,,7.85398e-5
Test1,2-Recover,98.303,1.719,1.324,0.011,,0.435097,140.056,,43.5097,0.140056,,,,7.85398e-5
Test1,2-Recover,98.637,1.74,1.303,0.038,,0.428196,483.831,,42.8196,0.483831,,,,7.85398e-5
Test1,2-Recover,98.970,1.76,1.283,0.031,,0.421623,394.704,,42.1623,0.394704,,,,7.85398e-5
Test1,2-Recover,99.303,1.78,1.263,0.025,,0.415051,318.31,,41.5051,0.31831,,,,7.85398e-5
Test1,2-Recover,99.637,1.801,1.242,0.031,,0.40815,394.704,,40.815,0.394704,,,,7.85398e-5
Test1,2-Recover,99.970,1.821,1.222,0.038,,0.401577,483.831,,40.1577,0.483831,,,,7.85398e-5
Test1,2-Recover,100.303,1.841,1.202,0.025,,0.395005,318.31,,39.5005,0.31831,,,,7.85398e-5
Test1,2-Recover,100.637,1.862,1.181,0.018,,0.388104,229.183,,38.8104,0.229183,,,,7.85398e-5
Test1,2-Recover,100.970,1.882,1.161,0.031,,0.381531,394.704,,38.1531,0.394704,,,,7.85398e-5
Test1,2-Recover,101.303,1.902,1.141,0.038,,0.374959,483.831,,37.4959,0.483831,,,,7.85398e-5
Test1,2-Recover,101.637,1.923,1.12,0.025,,0.368058,318.31,,36.8058,0.31831,,,,7.85398e-5
Test1,2-Recover,101.970,1.943,1.1,0.018,,0.361485,229.183,,36.1485,0.229183,,,,7.85398e-5
Test1,2-Recover,102.303,1.963,1.08,0.031,,0.354913,394.704,,35.4913,0.394704,,,,7.85398e-5
Test1,2-Recover,102.637,1.984,1.059,0.011,,0.348012,140.056,,34.8012,0.140056,,,,7.85398e-5
Test1,2-Recover,102.970,2.004,1.039,0.011,,0.341439,140.056,,34.1439,0.140056,,,,7.85398e-5
Test1,2-Recover,103.303,2.024,1.019,0.018,,0.334867,229.183,,33.4867,0.229183,,,,7.85398e-5
Test1,2-Recover,103.637,2.045,0.998,0.011,,0.327966,140.056,,32.7966,0.140056,,,,7.85398e-5
Test1,2-Recover,103.970,2.065,0.978,0.004,,0.321393,50.9296,,32.1393,0.0509296,,,,7.85398e-5
Test1,2-Recover,104.303,2.085,0.958,0.004,,0.314821,50.9296,,31.4821,0.0509296,,,,7.85398e-5
Test1,2-Recover,104.637,2.106,0.937,0.004,,0.30792,50.9296,,30.792,0.0509296,,,,7.85398e-5
Test1,2-Recover,104.970,2.126,0.917,0.004,,0.301347,50.9296,,30.1347,0.0509296,,,,7.85398e-5
Test1,2-Recover,105.303,2.146,0.897,0.004,,0.294775,50.9296,,29.4775,0.0509296,,,,7.85398e-5
Test1,2-Recover,105.637,2.167,0.876,0.004,,0.287874,50.9296,,28.7874,0.0509296,,,,7.85398e-5
Test1,2-Recover,105.970,2.187,0.856,0.011,,0.281301,140.056,,28.1301,0.140056,,,,7.85398e-5
Test1,2-Recover,106.303,2.207,0.836,0.011,,0.274729,140.056,,27.4729,0.140056,,,,7.85398e-5
Test1,2-Recover,106.637,2.228,0.815,0.018,,0.267828,229.183,,26.7828,0.229183,,,,7.85398e-5
Test1,2-Recover,106.970,2.248,0.795,0.018,,0.261255,229.183,,26.1255,0.229183,,,,7.85398e-5
Test1,2-Recover,107.303,2.268,0.775,0.018,,0.254683,229.183,,25.4683,0.229183,,,,7.85398e-5
Test1,2-Recover,107.637,2.289,0.754,0.025,,0.247782,318.31,,24.7782,0.31831,,,,7.85398e-5
Test1,2-Recover,107.970,2.309,0.734,0.011,,0.241209,140.056,,24.1209,0.140056,,,,7.85398e-5
Test1,2-Recover,108.303,2.329,0.714,0.011,,0.234637,140.056,,23.4637,0.140056,,,,7.85398e-5
Test1,2-Recover,108.637,2.35,0.693,0.011,,0.227736,140.056,,22.7736,0.140056,,,,7.85398e-5
Test1,2-Recover,108.970,2.37,0.673,0.011,,0.221163,140.056,,22.1163,0.140056,,,,7.85398e-5
Test1,2-Recover,109.303,2.39,0.653,0.011,,0.214591,140.056,,21.4591,0.140056,,,,7.85398e-5
Test1,2-Recover,109.637,2.411,0.632,0.004,,0.20769,50.9296,,20.769,0.0509296,,,,7.85398e-5
Test1,2-Recover,109.970,2.431,0.612,0.004,,0.201117,50.9296,,20.1117,0.0509296,,,,7.85398e-5
Test1,2-Recover,110.303,2.451,0.592,0.004,,0.194545,50.9296,,19.4545,0.0509296,,,,7.85398e-5
Test1,2-Recover,110.637,2.472,0.571,0.004,,0.187644,50.9296,,18.7644,0.0509296,,,,7.85398e-5
Test1,2-Recover,110.970,2.492,0.551,0.004,,0.181071,50.9296,,18.1071,0.0509296,,,,7.85398e-5
Test1,2-Recover,111.303,2.512,0.531,0.004,,0.174499,50.9296,,17.4499,0.0509296,,,,7.85398e-5
Test1,2-Recover,111.637,2.532,0.511,0.004,,0.167926,50.9296,,16.7926,0.0509296,,,,7.85398e-5
Test1,2-Recover,111.970,2.553,0.49,-0.003,,0.161025,-38.1972,,16.1025,-0.0381972,,,,7.85398e-5
Test1,2-Recover,112.303,2.573,0.47,0.004,,0.154453,50.9296,,15.4453,0.0509296,,,,7.85398e-5
Test1,2-Recover,112.637,2.593,0.45,0.004,,0.14788,50.9296,,14.788,0.0509296,,,,7.85398e-5
Test1,2-Recover,112.970,2.614,0.429,0.004,,0.140979,50.9296,,14.0979,0.0509296,,,,7.85398e-5
Test1,2-Recover,113.303,2.634,0.409,0.004,,0.134407,50.9296,,13.4407,0.0509296,,,,7.85398e-5
Test1,2-Recover,113.637,2.655,0.388,0.004,,0.127506,50.9296,,12.7506,0.0509296,,,,7.85398e-5
Test1,2-Recover,113.970,2.674,0.369,0.004,,0.121262,50.9296,,12.1262,0.0509296,,,,7.85398e-5
Test1,2-Recover,114.303,2.695,0.348,0.004,,0.114361,50.9296,,11.4361,0.0509296,,,,7.85398e-5
Test1,2-Recover,114.637,2.715,0.328,0.011,,0.107788,140.056,,10.7788,0.140056,,,,7.85398e-5
Test1,2-Recover,114.970,2.736,0.307,0.004,,0.100887,50.9296,,10.0887,0.0509296,,,,7.85398e-5
Test1,2-Recover,115.303,2.756,0.287,0.011,,0.0943148,140.056,,9.43148,0.140056,,,,7.85398e-5
Test1,2-Recover,115.637,2.777,0.266,0.011,,0.0874137,140.056,,8.74137,0.140056,,,,7.85398e-5
Test1,2-Recover,115.970,2.796,0.247,0.011,,0.0811699,140.056,,8.11699,0.140056,,,,7.85398e-5
Test1,2-Recover,116.303,2.817,0.226,0.011,,0.0742688,140.056,,7.42688,0.140056,,,,7.85398e-5
Test1,2-Recover,116.637,2.837,0.206,-0.003,,0.0676964,-38.1972,,6.76964,-0.0381972,,,,7.85398e-5
Test1,2-Recover,116.970,2.857,0.186,0.004,,0.0611239,50.9296,,6.11239,0.0509296,,,,7.85398e-5
Test1,2-Recover,117.303,2.878,0.165,0.004,,0.0542228,50.9296,,5.42228,0.0509296,,,,7.85398e-5
Test1,2-Recover,117.637,2.898,0.145,0.004,,0.0476503,50.9296,,4.76503,0.0509296,,,,7.85398e-5
Test1,2-Recover,117.970,2.919,0.124,0.004,,0.0407493,50.9296,,4.07493,0.0509296,,,,7.85398e-5
Test1,2-Recover,118.303,2.938,0.105,0.004,,0.0345054,50.9296,,3.45054,0.0509296,,,,7.85398e-5
Test1,2-Recover,118.637,2.959,0.084,0.004,,0.0276043,50.9296,,2.76043,0.0509296,,,,7.85398e-5
Test1,2-Recover,118.970,2.979,0.064,-0.003,,0.0210319,-38.1972,,2.10319,-0.0381972,,,,7.85398e-5
Test1,2-Recover,119.303,3,0.043,0.004,,0.0141308,50.9296,,1.41308,0.0509296,,,,7.85398e-5
Test1,2-Recover,119.637,3.02,0.023,0.004,,0.00755833,50.9296,,0.755833,0.0509296,,,,7.85398e-5
Test1,2-Recover,119.970,3.04,0.003,-0.003,,0.000985869,-38.1972,,0.0985869,-0.0381972,,,,7.85398e-5
Test1,3-Compress,120.280,3.031,0.012,0.004,,0.00394348,50.9296,,0.394348,0.0509296,,,,7.85398e-5
Test1,3-Compress,120.613,3.011,0.032,0.004,,0.0105159,50.9296,,1.05159,0.0509296,,,,7.85398e-5
Test1,3-Compress,120.947,2.99,0.053,-0.003,,0.017417,-38.1972,,1.7417,-0.0381972,,,,7.85398e-5
Test1,3-Compress,121.280,2.97,0.073,0.004,,0.0239895,50.9296,,2.39895,0.0509296,,,,7.85398e-5
Test1,3-Compress,121.613,2.95,0.093,0.004,,0.0305619,50.9296,,3.05619,0.0509296,,,,7.85398e-5
Test1,3-Compress,121.947,2.929,0.114,0.004,,0.037463,50.9296,,3.7463,0.0509296,,,,7.85398e-5
Test1,3-Compress,122.280,2.909,0.134,0.004,,0.0440355,50.9296,,4.40355,0.0509296,,,,7.85398e-5
Test1,3-Compress,122.613,2.889,0.154,0.004,,0.050608,50.9296,,5.0608,0.0509296,,,,7.85398e-5
Test1,3-Compress,122.947,2.868,0.175,0.011,,0.057509,140.056,,5.7509,0.140056,,,,7.85398e-5
Test1,3-Compress,123.280,2.848,0.195,0.011,,0.0640815,140.056,,6.40815,0.140056,,,,7.85398e-5
Test1,3-Compress,123.613,2.828,0.215,0.011,,0.070654,140.056,,7.0654,0.140056,,,,7.85398e-5
Test1,3-Compress,123.947,2.807,0.236,0.011,,0.077555,140.056,,7.7555,0.140056,,,,7.85398e-5
Test1,3-Compress,124.280,2.787,0.256,0.018,,0.0841275,229.183,,8.41275,0.229183,,,,7.85398e-5
Test1,3-Compress,124.613,2.767,0.276,0.011,,0.0907,140.056,,9.07,0.140056,,,,7.85398e-5
Test1,3-Compress,124.947,2.746,0.297,0.025,,0.0976011,318.31,,9.76011,0.31831,,,,7.85398e-5
Test1,3-Compress,125.280,2.726,0.317,0.004,,0.104174,50.9296,,10.4174,0.0509296,,,,7.85398e-5
Test1,3-Compress,125.613,2.706,0.337,0.011,,0.110746,140.056,,11.0746,0.140056,,,,7.85398e-5
Test1,3-Compress,125.947,2.686,0.357,0.011,,0.117318,140.056,,11.7318,0.140056,,,,7.85398e-5
Test1,3-Compress,126.280,2.665,0.378,0.011,,0.12422,140.056,,12.422,0.140056,,,,7.85398e-5
Test1,3-Compress,126.613,2.645,0.398,-0.003,,0.130792,-38.1972,,13.0792,-0.0381972,,,,7.85398e-5
Test1,3-Compress,126.947,2.624,0.419,0.004,,0.137693,50.9296,,13.7693,0.0509296,,,,7.85398e-5
Test1,3-Compress,127.280,2.604,0.439,0.011,,0.144266,140.056,,14.4266,0.140056,,,,7.85398e-5
Test1,3-Compress,127.613,2.584,0.459,0.004,,0.150838,50.9296,,15.0838,0.0509296,,,,7.85398e-5
Test1,3-Compress,127.947,2.563,0.48,0.004,,0.157739,50.9296,,15.7739,0.0509296,,,,7.85398e-5
Test1,3-Compress,128.280,2.543,0.5,0.004,,0.164312,50.9296,,16.4312,0.0509296,,,,7.85398e-5
Test1,3-Compress,128.613,2.523,0.52,0.004,,0.170884,50.9296,,17.0884,0.0509296,,,,7.85398e-5
Test1,3-Compress,128.947,2.503,0.54,0.004,,0.177456,50.9296,,17.7456,0.0509296,,,,7.85398e-5
Test1,3-Compress,129.280,2.482,0.561,0.004,,0.184358,50.9296,,18.4358,0.0509296,,,,7.85398e-5
Test1,3-Compress,129.613,2.462,0.581,0.004,,0.19093,50.9296,,19.093,0.0509296,,,,7.85398e-5
Test1,3-Compress,129.947,2.441,0.602,0.004,,0.197831,50.9296,,19.7831,0.0509296,,,,7.85398e-5
Test1,3-Compress,130.280,2.422,0.621,0.004,,0.204075,50.9296,,20.4075,0.0509296,,,,7.85398e-5
Test1,3-Compress,130.613,2.401,0.642,0.004,,0.210976,50.9296,,21.0976,0.0509296,,,,7.85398e-5
Test1,3-Compress,130.947,2.381,0.662,0.011,,0.217548,140.056,,21.7548,0.140056,,,,7.85398e-5
Test1,3-Compress,131.280,2.36,0.683,0.011,,0.22445,140.056,,22.445,0.140056,,,,7.85398e-5
Test1,3-Compress,131.613,2.34,0.703,0.018,,0.231022,229.183,,23.1022,0.229183,,,,7.85398e-5
Test1,3-Compress,131.947,2.32,0.723,0.011,,0.237594,140.056,,23.7594,0.140056,,,,7.85398e-5
Test1,3-Compress,132.280,2.299,0.744,0.018,,0.244496,229.183,,24.4496,0.229183,,,,7.85398e-5
Test1,3-Compress,132.613,2.279,0.764,0.018,,0.251068,229.183,,25.1068,0.229183,,,,7.85398e-5
Test1,3-Compress,132.947,2.259,0.784,0.018,,0.25764,229.183,,25.764,0.229183,,,,7.85398e-5
Test1,3-Compress,133.280,2.239,0.804,0.011,,0.264213,140.056,,26.4213,0.140056,,,,7.85398e-5
Test1,3-Compress,133.613,2.218,0.825,0.011,,0.271114,140.056,,27.1114,0.140056,,,,7.85398e-5
Test1,3-Compress,133.947,2.198,0.845,0.018,,0.277686,229.183,,27.7686,0.229183,,,,7.85398e-5
Test1,3-Compress,134.280,2.177,0.866,0.018,,0.284588,229.183,,28.4588,0.229183,,,,7.85398e-5
Test1,3-Compress,134.613,2.158,0.885,0.004,,0.290831,50.9296,,29.0831,0.0509296,,,,7.85398e-5
Test1,3-Compress,134.947,2.137,0.906,0.004,,0.297733,50.9296,,29.7733,0.0509296,,,,7.85398e-5
Test1,3-Compress,135.280,2.117,0.926,0.011,,0.304305,140.056,,30.4305,0.140056,,,,7.85398e-5
Test1,3-Compress,135.613,2.096,0.947,0.011,,0.311206,140.056,,31.1206,0.140056,,,,7.85398e-5
Test1,3-Compress,135.947,2.076,0.967,0.004,,0.317779,50.9296,,31.7779,0.0509296,,,,7.85398e-5
Test1,3-Compress,136.280,2.056,0.987,0.004,,0.324351,50.9296,,32.4351,0.0509296,,,,7.85398e-5
Test1,3-Compress,136.613,2.035,1.008,0.004,,0.331252,50.9296,,33.1252,0.0509296,,,,7.85398e-5
Test1,3-Compress,136.947,2.015,1.028,0.004,,0.337825,50.9296,,33.7825,0.0509296,,,,7.85398e-5
Test1,3-Compress,137.280,1.995,1.048,0.004,,0.344397,50.9296,,34.4397,0.0509296,,,,7.85398e-5
Test1,3-Compress,137.613,1.975,1.068,0.004,,0.350969,50.9296,,35.0969,0.0509296,,,,7.85398e-5
Test1,3-Compress,137.947,1.954,1.089,0.004,,0.357871,50.9296,,35.7871,0.0509296,,,,7.85398e-5
Test1,3-Compress,138.280,1.934,1.109,0.004,,0.364443,50.9296,,36.4443,0.0509296,,,,7.85398e-5
Test1,3-Compress,138.613,1.914,1.129,0.018,,0.371015,229.183,,37.1015,0.229183,,,,7.85398e-5
Test1,3-Compress,138.947,1.893,1.15,0.011,,0.377917,140.056,,37.7917,0.140056,,,,7.85398e-5
Test1,3-Compress,139.280,1.873,1.17,0.018,,0.384489,229.183,,38.4489,0.229183,,,,7.85398e-5
Test1,3-Compress,139.613,1.853,1.19,0.018,,0.391061,229.183,,39.1061,0.229183,,,,7.85398e-5
Test1,3-Compress,139.947,1.832,1.211,0.018,,0.397963,229.183,,39.7963,0.229183,,,,7.85398e-5
Test1,3-Compress,140.280,1.812,1.231,0.025,,0.404535,318.31,,40.4535,0.31831,,,,7.85398e-5
Test1,3-Compress,140.613,1.792,1.251,0.031,,0.411107,394.704,,41.1107,0.394704,,,,7.85398e-5
Test1,3-Compress,140.947,1.771,1.272,0.038,,0.418009,483.831,,41.8009,0.483831,,,,7.85398e-5
Test1,3-Compress,141.280,1.751,1.292,0.038,,0.424581,483.831,,42.4581,0.483831,,,,7.85398e-5
Test1,3-Compress,141.613,1.731,1.312,0.025,,0.431153,318.31,,43.1153,0.31831,,,,7.85398e-5
Test1,3-Compress,141.947,1.71,1.333,0.031,,0.438055,394.704,,43.8055,0.394704,,,,7.85398e-5
Test1,3-Compress,142.280,1.69,1.353,0.031,,0.444627,394.704,,44.4627,0.394704,,,,7.85398e-5
Test1,3-Compress,142.613,1.67,1.373,0.031,,0.451199,394.704,,45.1199,0.394704,,,,7.85398e-5
Test1,3-Compress,142.947,1.649,1.394,0.018,,0.458101,229.183,,45.8101,0.229183,,,,7.85398e-5
Test1,3-Compress,143.280,1.629,1.414,0.025,,0.464673,318.31,,46.4673,0.31831,,,,7.85398e-5
Test1,3-Compress,143.613,1.609,1.434,0.031,,0.471245,394.704,,47.1245,0.394704,,,,7.85398e-5
Test1,3-Compress,143.947,1.588,1.455,0.038,,0.478147,483.831,,47.8147,0.483831,,,,7.85398e-5
Test1,3-Compress,144.280,1.568,1.475,0.038,,0.484719,483.831,,48.4719,0.483831,,,,7.85398e-5
Test1,3-Compress,144.613,1.548,1.495,0.025,,0.491291,318.31,,49.1291,0.31831,,,,7.85398e-5
Test1,3-Compress,144.947,1.527,1.516,0.038,,0.498193,483.831,,49.8193,0.483831,,,,7.85398e-5
Test1,3-Compress,145.280,1.507,1.536,0.011,,0.504765,140.056,,50.4765,0.140056,,,,7.85398e-5
Test1,3-Compress,145.613,1.487,1.556,0.018,,0.511337,229.183,,51.1337,0.229183,,,,7.85398e-5
Test1,3-Compress,145.947,1.466,1.577,0.038,,0.518239,483.831,,51.8239,0.483831,,,,7.85398e-5
Test1,3-Compress,146.280,1.446,1.597,0.038,,0.524811,483.831,,52.4811,0.483831,,,,7.85398e-5
Test1,3-Compress,146.613,1.426,1.617,0.038,,0.531384,483.831,,53.1384,0.483831,,,,7.85398e-5
Test1,3-Compress,146.947,1.405,1.638,0.031,,0.538285,394.704,,53.8285,0.394704,,,,7.85398e-5
Test1,3-Compress,147.280,1.385,1.658,0.045,,0.544857,572.958,,54.4857,0.572958,,,,7.85398e-5
Test1,3-Compress,147.613,1.365,1.678,0.045,,0.55143,572.958,,55.143,0.572958,,,,7.85398e-5
Test1,3-Compress,147.947,1.344,1.699,0.038,,0.558331,483.831,,55.8331,0.483831,,,,7.85398e-5
Test1,3-Compress,148.280,1.324,1.719,0.045,,0.564903,572.958,,56.4903,0.572958,,,,7.85398e-5
Test1,3-Compress,148.613,1.304,1.739,0.052,,0.571476,662.085,,57.1476,0.662085,,,,7.85398e-5
Test1,3-Compress,148.947,1.283,1.76,0.052,,0.578377,662.085,,57.8377,0.662085,,,,7.85398e-5
Test1,3-Compress,149.280,1.263,1.78,0.052,,0.584949,662.085,,58.4949,0.662085,,,,7.85398e-5
Test1,3-Compress,149.613,1.243,1.8,0.052,,0.591522,662.085,,59.1522,0.662085,,,,7.85398e-5
Test1,3-Compress,149.947,1.222,1.821,0.052,,0.598423,662.085,,59.8423,0.662085,,,,7.85398e-5
Test1,3-Recover,150.267,1.228,1.815,0.052,,0.596451,662.085,,59.6451,0.662085,,,,7.85398e-5
Test1,3-Recover,150.600,1.248,1.795,0.052,,0.589878,662.085,,58.9878,0.662085,,,,7.85398e-5
Test1,3-Recover,150.933,1.268,1.775,0.052,,0.583306,662.085,,58.3306,0.662085,,,,7.85398e-5
Test1,3-Recover,151.267,1.288,1.755,0.052,,0.576733,662.085,,57.6733,0.662085,,,,7.85398e-5
Test1,3-Recover,151.600,1.309,1.734,0.052,,0.569832,662.085,,56.9832,0.662085,,,,7.85398e-5
Test1,3-Recover,151.933,1.329,1.714,0.052,,0.56326,662.085,,56.326,0.662085,,,,7.85398e-5
Test1,3-Recover,152.267,1.35,1.693,0.045,,0.556359,572.958,,55.6359,0.572958,,,,7.85398e-5
Test1,3-Recover,152.600,1.37,1.673,0.038,,0.549786,483.831,,54.9786,0.483831,,,,7.85398e-5
Test1,3-Recover,152.933,1.39,1.653,0.038,,0.543214,483.831,,54.3214,0.483831,,,,7.85398e-5
Test1,3-Recover,153.267,1.41,1.633,0.018,,0.536641,229.183,,53.6641,0.229183,,,,7.85398e-5
Test1,3-Recover,153.600,1.431,1.612,0.018,,0.52974,229.183,,52.974,0.229183,,,,7.85398e-5
Test1,3-Recover,153.933,1.451,1.592,0.004,,0.523168,50.9296,,52.3168,0.0509296,,,,7.85398e-5
Test1,3-Recover,154.267,1.471,1.572,0.011,,0.516595,140.056,,51.6595,0.140056,,,,7.85398e-5
Test1,3-Recover,154.600,1.492,1.551,0.045,,0.509694,572.958,,50.9694,0.572958,,,,7.85398e-5
Test1,3-Recover,154.933,1.511,1.532,0.018,,0.503451,229.183,,50.3451,0.229183,,,,7.85398e-5
Test1,3-Recover,155.267,1.533,1.51,0.031,,0.496221,394.704,,49.6221,0.394704,,,,7.85398e-5
Test1,3-Recover,155.600,1.552,1.491,0.031,,0.489977,394.704,,48.9977,0.394704,,,,7.85398e-5
Test1,3-Recover,155.933,1.573,1.47,0.045,,0.483076,572.958,,48.3076,0.572958,,,,7.85398e-5
Test1,3-Recover,156.267,1.593,1.45,0.031,,0.476503,394.704,,47.6503,0.394704,,,,7.85398e-5
Test1,3-Recover,156.600,1.613,1.43,0.025,,0.469931,318.31,,46.9931,0.31831,,,,7.85398e-5
Test1,3-Recover,156.933,1.634,1.409,0.038,,0.46303,483.831,,46.303,0.483831,,,,7.85398e-5
Test1,3-Recover,157.267,1.654,1.389,0.045,,0.456457,572.958,,45.6457,0.572958,,,,7.85398e-5
Test1,3-Recover,157.600,1.674,1.369,0.038,,0.449885,483.831,,44.9885,0.483831,,,,7.85398e-5
Test1,3-Recover,157.933,1.694,1.349,0.025,,0.443313,318.31,,44.3313,0.31831,,,,7.85398e-5
Test1,3-Recover,158.267,1.715,1.328,0.025,,0.436411,318.31,,43.6411,0.31831,,,,7.85398e-5
Test1,3-Recover,158.600,1.735,1.308,0.025,,0.429839,318.31,,42.9839,0.31831,,,,7.85398e-5
Test1,3-Recover,158.933,1.756,1.287,0.018,,0.422938,229.183,,42.2938,0.229183,,,,7.85398e-5
Test1,3-Recover,159.267,1.776,1.267,0.018,,0.416365,229.183,,41.6365,0.229183,,,,7.85398e-5
Test1,3-Recover,159.600,1.797,1.246,0.011,,0.409464,140.056,,40.9464,0.140056,,,,7.85398e-5
Test1,3-Recover,159.933,1.816,1.227,0.018,,0.403221,229.183,,40.3221,0.229183,,,,7.85398e-5
Test1,3-Recover,160.267,1.837,1.206,0.018,,0.396319,229.183,,39.6319,0.229183,,,,7.85398e-5
Test1,3-Recover,160.600,1.857,1.186,0.011,,0.389747,140.056,,38.9747,0.140056,,,,7.85398e-5
Test1,3-Recover,160.933,1.877,1.166,0.004,,0.383174,50.9296,,38.3174,0.0509296,,,,7.85398e-5
Test1,3-Recover,161.267,1.898,1.145,0.011,,0.376273,140.056,,37.6273,0.140056,,,,7.85398e-5
Test1,3-Recover,161.600,1.918,1.125,0.004,,0.369701,50.9296,,36.9701,0.0509296,,,,7.85398e-5
Test1,3-Recover,161.933,1.938,1.105,0.004,,0.363128,50.9296,,36.3128,0.0509296,,,,7.85398e-5
Test1,3-Recover,162.267,1.959,1.084,0.004,,0.356227,50.9296,,35.6227,0.0509296,,,,7.85398e-5
Test1,3-Recover,162.600,1.979,1.064,0.004,,0.349655,50.9296,,34.9655,0.0509296,,,,7.85398e-5
Test1,3-Recover,162.933,1.999,1.044,0.004,,0.343082,50.9296,,34.3082,0.0509296,,,,7.85398e-5
Test1,3-Recover,163.267,2.02,1.023,0.011,,0.336181,140.056,,33.6181,0.140056,,,,7.85398e-5
Test1,3-Recover,163.600,2.04,1.003,0.018,,0.329609,229.183,,32.9609,0.229183,,,,7.85398e-5
Test1,3-Recover,163.933,2.06,0.983,0.011,,0.323036,140.056,,32.3036,0.140056,,,,7.85398e-5
Test1,3-Recover,164.267,2.081,0.962,0.025,,0.316135,318.31,,31.6135,0.31831,,,,7.85398e-5
Test1,3-Recover,164.600,2.101,0.942,0.025,,0.309563,318.31,,30.9563,0.31831,,,,7.85398e-5
Test1,3-Recover,164.933,2.121,0.922,0.018,,0.30299,229.183,,30.299,0.229183,,,,7.85398e-5
Test1,3-Recover,165.267,2.142,0.901,0.011,,0.296089,140.056,,29.6089,0.140056,,,,7.85398e-5
Test1,3-Recover,165.600,2.162,0.881,0.025,,0.289517,318.31,,28.9517,0.31831,,,,7.85398e-5
Test1,3-Recover,165.933,2.182,0.861,0.011,,0.282944,140.056,,28.2944,0.140056,,,,7.85398e-5
Test1,3-Recover,166.267,2.203,0.84,0.011,,0.276043,140.056,,27.6043,0.140056,,,,7.85398e-5
Test1,3-Recover,166.600,2.223,0.82,0.004,,0.269471,50.9296,,26.9471,0.0509296,,,,7.85398e-5
Test1,3-Recover,166.933,2.243,0.8,0.011,,0.262898,140.056,,26.2898,0.140056,,,,7.85398e-5
Test1,3-Recover,167.267,2.264,0.779,0.011,,0.255997,140.056,,25.5997,0.140056,,,,7.85398e-5
Test1,3-Recover,167.600,2.284,0.759,0.004,,0.249425,50.9296,,24.9425,0.0509296,,,,7.85398e-5
Test1,3-Recover,167.933,2.304,0.739,0.004,,0.242852,50.9296,,24.2852,0.0509296,,,,7.85398e-5
Test1,3-Recover,168.267,2.325,0.718,0.004,,0.235951,50.9296,,23.5951,0.0509296,,,,7.85398e-5
Test1,3-Recover,168.600,2.345,0.698,-0.003,,0.229379,-38.1972,,22.9379,-0.0381972,,,,7.85398e-5
Test1,3-Recover,168.933,2.365,0.678,0.004,,0.222806,50.9296,,22.2806,0.0509296,,,,7.85398e-5
Test1,3-Recover,169.267,2.386,0.657,-0.003,,0.215905,-38.1972,,21.5905,-0.0381972,,,,7.85398e-5
Test1,3-Recover,169.600,2.406,0.637,0.004,,0.209333,50.9296,,20.9333,0.0509296,,,,7.85398e-5
Test1,3-Recover,169.933,2.426,0.617,0.004,,0.20276,50.9296,,20.276,0.0509296,,,,7.85398e-5
Test1,3-Recover,170.267,2.447,0.596,0.004,,0.195859,50.9296,,19.5859,0.0509296,,,,7.85398e-5
Test1,3-Recover,170.600,2.467,0.576,0.004,,0.189287,50.9296,,18.9287,0.0509296,,,,7.85398e-5
Test1,3-Recover,170.933,2.487,0.556,0.004,,0.182714,50.9296,,18.2714,0.0509296,,,,7.85398e-5
Test1,3-Recover,171.267,2.508,0.535,0.011,,0.175813,140.056,,17.5813,0.140056,,,,7.85398e-5
Test1,3-Recover,171.600,2.528,0.515,0.011,,0.169241,140.056,,16.9241,0.140056,,,,7.85398e-5
Test1,3-Recover,171.933,2.548,0.495,0.018,,0.162668,229.183,,16.2668,0.229183,,,,7.85398e-5
Test1,3-Recover,172.267,2.569,0.474,0.011,,0.155767,140.056,,15.5767,0.140056,,,,7.85398e-5
Test1,3-Recover,172.600,2.589,0.454,0.004,,0.149195,50.9296,,14.9195,0.0509296,,,,7.85398e-5
Test1,3-Recover,172.933,2.609,0.434,0.004,,0.142622,50.9296,,14.2622,0.0509296,,,,7.85398e-5
Test1,3-Recover,173.267,2.629,0.414,0.004,,0.13605,50.9296,,13.605,0.0509296,,,,7.85398e-5
Test1,3-Recover,173.600,2.65,0.393,-0.003,,0.129149,-38.1972,,12.9149,-0.0381972,,,,7.85398e-5
Test1,3-Recover,173.933,2.67,0.373,0.011,,0.122576,140.056,,12.2576,0.140056,,,,7.85398e-5
Test1,3-Recover,174.267,2.69,0.353,-0.003,,0.116004,-38.1972,,11.6004,-0.0381972,,,,7.85398e-5
Test1,3-Recover,174.600,2.711,0.332,0.004,,0.109103,50.9296,,10.9103,0.0509296,,,,7.85398e-5
Test1,3-Recover,174.933,2.731,0.312,0.004,,0.10253,50.9296,,10.253,0.0509296,,,,7.85398e-5
Test1,3-Recover,175.267,2.752,0.291,-0.003,,0.0956293,-38.1972,,9.56293,-0.0381972,,,,7.85398e-5
Test1,3-Recover,175.600,2.771,0.272,-0.003,,0.0893855,-38.1972,,8.93855,-0.0381972,,,,7.85398e-5
Test1,3-Recover,175.933,2.792,0.251,-0.003,,0.0824844,-38.1972,,8.24844,-0.0381972,,,,7.85398e-5
Test1,3-Recover,176.267,2.812,0.231,0.004,,0.0759119,50.9296,,7.59119,0.0509296,,,,7.85398e-5
Test1,3-Recover,176.600,2.833,0.21,0.004,,0.0690108,50.9296,,6.90108,0.0509296,,,,7.85398e-5
Test1,3-Recover,176.933,2.853,0.19,-0.003,,0.0624384,-38.1972,,6.24384,-0.0381972,,,,7.85398e-5
Test1,3-Recover,177.267,2.873,0.17,-0.003,,0.0558659,-38.1972,,5.58659,-0.0381972,,,,7.85398e-5
Test1,3-Recover,177.600,2.893,0.15,0.004,,0.0492935,50.9296,,4.92935,0.0509296,,,,7.85398e-5
Test1,3-Recover,177.933,2.914,0.129,0.004,,0.0423924,50.9296,,4.23924,0.0509296,,,,7.85398e-5
Test1,3-Recover,178.267,2.934,0.109,0.004,,0.0358199,50.9296,,3.58199,0.0509296,,,,7.85398e-5
Test1,3-Recover,178.600,2.954,0.089,0.004,,0.0292475,50.9296,,2.92475,0.0509296,,,,7.85398e-5
Test1,3-Recover,178.933,2.975,0.068,0.011,,0.0223464,140.056,,2.23464,0.140056,,,,7.85398e-5
Test1,3-Recover,179.267,2.995,0.048,0.011,,0.0157739,140.056,,1.57739,0.140056,,,,7.85398e-5
Test1,3-Recover,179.600,3.016,0.027,0.011,,0.00887282,140.056,,0.887282,0.140056,,,,7.85398e-5
Test1,3-Recover,179.933,3.035,0.008,0.018,,0.00262898,229.183,,0.262898,0.229183,,,,7.85398e-5
Test1,3-Recover,180.100,3.043,-0,0.004,,0,50.9296,,0,0.0509296,,,,7.85398e-5