File: data/gamma_1-1-0_3.csv
SetName,Cycle,Time_S,Size_mm,Displacement_mm,Force_N,,Strain,Stress(Pascal),,%Strain,Stress(kPa),,,,Area(m^2)
Test1,1-Compress,0.000,1.574,-0,-0.005,,0,-63.662,,0,-0.063662,,,,7.85398e-5
Test1,1-Compress,0.333,1.563,0.011,0.009,,0.00698856,114.592,,0.698856,0.114592,,,,7.85398e-5
Test1,1-Compress,0.667,1.553,0.021,0.002,,0.0133418,25.4648,,1.33418,0.0254648,,,,7.85398e-5
Test1,1-Compress,1.000,1.542,0.032,0.002,,0.0203304,25.4648,,2.03304,0.0254648,,,,7.85398e-5
Test1,1-Compress,1.333,1.532,0.042,0.002,,0.0266836,25.4648,,2.66836,0.0254648,,,,7.85398e-5
Test1,1-Compress,1.667,1.521,0.053,-0.005,,0.0336722,-63.662,,3.36722,-0.063662,,,,7.85398e-5
Test1,1-Compress,2.000,1.51,0.064,-0.005,,0.0406607,-63.662,,4.06607,-0.063662,,,,7.85398e-5
Test1,1-Compress,2.333,1.501,0.073,-0.005,,0.0463787,-63.662,,4.63787,-0.063662,,,,7.85398e-5
Test1,1-Compress,2.667,1.489,0.085,-0.005,,0.0540025,-63.662,,5.40025,-0.063662,,,,7.85398e-5
Test1,1-Compress,3.000,1.479,0.095,-0.005,,0.0603558,-63.662,,6.03558,-0.063662,,,,7.85398e-5
Test1,1-Compress,3.333,1.469,0.105,-0.005,,0.066709,-63.662,,6.6709,-0.063662,,,,7.85398e-5
Test1,1-Compress,3.667,1.458,0.116,-0.005,,0.0736976,-63.662,,7.36976,-0.063662,,,,7.85398e-5
Test1,1-Compress,4.000,1.448,0.126,0.002,,0.0800508,25.4648,,8.00508,0.0254648,,,,7.85398e-5
Test1,1-Compress,4.333,1.437,0.137,0.002,,0.0870394,25.4648,,8.70394,0.0254648,,,,7.85398e-5
Test1,1-Compress,4.667,1.427,0.147,0.002,,0.0933926,25.4648,,9.33926,0.0254648,,,,7.85398e-5
Test1,1-Compress,5.000,1.416,0.158,-0.005,,0.100381,-63.662,,10.0381,-0.063662,,,,7.85398e-5
Test1,1-Compress,5.333,1.405,0.169,0.002,,0.10737,25.4648,,10.737,0.0254648,,,,7.85398e-5
Test1,1-Compress,5.667,1.395,0.179,0.002,,0.113723,25.4648,,11.3723,0.0254648,,,,7.85398e-5
Test1,1-Compress,6.000,1.384,0.19,0.002,,0.120712,25.4648,,12.0712,0.0254648,,,,7.85398e-5
Test1,1-Compress,6.333,1.374,0.2,0.002,,0.127065,25.4648,,12.7065,0.0254648,,,,7.85398e-5
Test1,1-Compress,6.667,1.363,0.211,0.002,,0.134053,25.4648,,13.4053,0.0254648,,,,7.85398e-5
Test1,1-Compress,7.000,1.353,0.221,0.002,,0.140407,25.4648,,14.0407,0.0254648,,,,7.85398e-5
Test1,1-Compress,7.333,1.343,0.231,0.009,,0.14676,114.592,,14.676,0.114592,,,,7.85398e-5
Test1,1-Compress,7.667,1.332,0.242,0.016,,0.153748,203.718,,15.3748,0.203718,,,,7.85398e-5
Test1,1-Compress,8.000,1.322,0.252,0.016,,0.160102,203.718,,16.0102,0.203718,,,,7.85398e-5
Test1,1-Compress,8.333,1.311,0.263,0.016,,0.16709,203.718,,16.709,0.203718,,,,7.85398e-5
Test1,1-Compress,8.667,1.301,0.273,0.022,,0.173443,280.113,,17.3443,0.280113,,,,7.85398e-5
Test1,1-Compress,9.000,1.29,0.284,0.022,,0.180432,280.113,,18.0432,0.280113,,,,7.85398e-5
Test1,1-Compress,9.333,1.279,0.295,0.036,,0.187421,458.366,,18.7421,0.458366,,,,7.85398e-5
Test1,1-Compress,9.667,1.269,0.305,0.029,,0.193774,369.24,,19.3774,0.36924,,,,7.85398e-5
Test1,1-Compress,10.000,1.258,0.316,0.029,,0.200762,369.24,,20.0762,0.36924,,,,7.85398e-5
Test1,1-Compress,10.333,1.248,0.326,0.043,,0.207116,547.493,,20.7116,0.547493,,,,7.85398e-5
Test1,1-Compress,10.667,1.237,0.337,0.029,,0.214104,369.24,,21.4104,0.36924,,,,7.85398e-5
Test1,1-Compress,11.000,1.227,0.347,0.036,,0.220457,458.366,,22.0457,0.458366,,,,7.85398e-5
Test1,1-Compress,11.333,1.217,0.357,0.022,,0.226811,280.113,,22.6811,0.280113,,,,7.85398e-5
Test1,1-Compress,11.667,1.206,0.368,0.036,,0.233799,458.366,,23.3799,0.458366,,,,7.85398e-5
Test1,1-Compress,12.000,1.196,0.378,0.036,,0.240152,458.366,,24.0152,0.458366,,,,7.85398e-5
Test1,1-Compress,12.333,1.185,0.389,0.036,,0.247141,458.366,,24.7141,0.458366,,,,7.85398e-5
Test1,1-Compress,12.667,1.174,0.4,0.043,,0.25413,547.493,,25.413,0.547493,,,,7.85398e-5
Test1,1-Compress,13.000,1.164,0.41,0.036,,0.260483,458.366,,26.0483,0.458366,,,,7.85398e-5
Test1,1-Compress,13.333,1.153,0.421,0.043,,0.267471,547.493,,26.7471,0.547493,,,,7.85398e-5
Test1,1-Compress,13.667,1.143,0.431,0.043,,0.273825,547.493,,27.3825,0.547493,,,,7.85398e-5
Test1,1-Compress,14.000,1.132,0.442,0.029,,0.280813,369.24,,28.0813,0.36924,,,,7.85398e-5
Test1,1-Compress,14.333,1.122,0.452,0.036,,0.287166,458.366,,28.7166,0.458366,,,,7.85398e-5
Test1,1-Compress,14.667,1.111,0.463,0.043,,0.294155,547.493,,29.4155,0.547493,,,,7.85398e-5
Test1,1-Compress,15.000,1.101,0.473,0.036,,0.300508,458.366,,30.0508,0.458366,,,,7.85398e-5
Test1,1-Compress,15.333,1.091,0.483,0.043,,0.306861,547.493,,30.6861,0.547493,,,,7.85398e-5
Test1,1-Compress,15.667,1.08,0.494,0.050,,0.31385,636.62,,31.385,0.63662,,,,7.85398e-5
Test1,1-Compress,16.000,1.07,0.504,0.050,,0.320203,636.62,,32.0203,0.63662,,,,7.85398e-5
Test1,1-Compress,16.333,1.059,0.515,0.050,,0.327192,636.62,,32.7192,0.63662,,,,7.85398e-5
Test1,1-Compress,16.667,1.048,0.526,0.050,,0.33418,636.62,,33.418,0.63662,,,,7.85398e-5
Test1,1-Compress,17.000,1.038,0.536,0.050,,0.340534,636.62,,34.0534,0.63662,,,,7.85398e-5
Test1,1-Compress,17.333,1.027,0.547,0.050,,0.347522,636.62,,34.7522,0.63662,,,,7.85398e-5
Test1,1-Compress,17.667,1.017,0.557,0.050,,0.353875,636.62,,35.3875,0.63662,,,,7.85398e-5
Test1,1-Compress,18.000,1.006,0.568,0.050,,0.360864,636.62,,36.0864,0.63662,,,,7.85398e-5
Test1,1-Compress,18.333,0.996,0.578,0.050,,0.367217,636.62,,36.7217,0.63662,,,,7.85398e-5
Test1,1-Compress,18.667,0.985,0.589,0.050,,0.374206,636.62,,37.4206,0.63662,,,,7.85398e-5
Test1,1-Compress,19.000,0.975,0.599,0.050,,0.380559,636.62,,38.0559,0.63662,,,,7.85398e-5
Test1,1-Compress,19.333,0.965,0.609,0.050,,0.386912,636.62,,38.6912,0.63662,,,,7.85398e-5
Test1,1-Compress,19.667,0.954,0.62,0.050,,0.393901,636.62,,39.3901,0.63662,,,,7.85398e-5
Test1,1-Compress,20.000,0.943,0.631,0.050,,0.400889,636.62,,40.0889,0.63662,,,,7.85398e-5
Test1,1-Compress,20.333,0.933,0.641,0.050,,0.407243,636.62,,40.7243,0.63662,,,,7.85398e-5
Test1,1-Compress,20.667,0.922,0.652,0.050,,0.414231,636.62,,41.4231,0.63662,,,,7.85398e-5
Test1,1-Compress,21.000,0.912,0.662,0.050,,0.420584,636.62,,42.0584,0.63662,,,,7.85398e-5
Test1,1-Compress,21.333,0.901,0.673,0.050,,0.427573,636.62,,42.7573,0.63662,,,,7.85398e-5
Test1,1-Compress,21.667,0.891,0.683,0.050,,0.433926,636.62,,43.3926,0.63662,,,,7.85398e-5
Test1,1-Compress,22.000,0.88,0.694,0.050,,0.440915,636.62,,44.0915,0.63662,,,,7.85398e-5
Test1,1-Compress,22.333,0.87,0.704,0.050,,0.447268,636.62,,44.7268,0.63662,,,,7.85398e-5
Test1,1-Compress,22.667,0.859,0.715,0.050,,0.454257,636.62,,45.4257,0.63662,,,,7.85398e-5
Test1,1-Compress,23.000,0.849,0.725,0.050,,0.46061,636.62,,46.061,0.63662,,,,7.85398e-5
Test1,1-Compress,23.333,0.839,0.735,0.050,,0.466963,636.62,,46.6963,0.63662,,,,7.85398e-5
Test1,1-Compress,23.667,0.828,0.746,0.063,,0.473952,802.141,,47.3952,0.802141,,,,7.85398e-5
Test1,1-Compress,24.000,0.817,0.757,0.063,,0.48094,802.141,,48.094,0.802141,,,,7.85398e-5
Test1,1-Compress,24.333,0.807,0.767,0.056,,0.487294,713.014,,48.7294,0.713014,,,,7.85398e-5
Test1,1-Compress,24.667,0.796,0.778,0.063,,0.494282,802.141,,49.4282,0.802141,,,,7.85398e-5
Test1,1-Compress,25.000,0.786,0.788,0.063,,0.500635,802.141,,50.0635,0.802141,,,,7.85398e-5
Test1,1-Compress,25.333,0.775,0.799,0.070,,0.507624,891.268,,50.7624,0.891268,,,,7.85398e-5
Test1,1-Compress,25.667,0.765,0.809,0.070,,0.513977,891.268,,51.3977,0.891268,,,,7.85398e-5
Test1,1-Compress,26.000,0.754,0.82,0.077,,0.520966,980.395,,52.0966,0.980395,,,,7.85398e-5
Test1,1-Compress,26.333,0.744,0.83,0.070,,0.527319,891.268,,52.7319,0.891268,,,,7.85398e-5
Test1,1-Compress,26.667,0.733,0.841,0.077,,0.534307,980.395,,53.4307,0.980395,,,,7.85398e-5
Test1,1-Compress,27.000,0.723,0.851,0.077,,0.540661,980.395,,54.0661,0.980395,,,,7.85398e-5
Test1,1-Compress,27.333,0.712,0.862,0.070,,0.547649,891.268,,54.7649,0.891268,,,,7.85398e-5
Test1,1-Compress,27.667,0.702,0.872,0.083,,0.554003,1056.79,,55.4003,1.05679,,,,7.85398e-5
Test1,1-Compress,28.000,0.691,0.883,0.063,,0.560991,802.141,,56.0991,0.802141,,,,7.85398e-5
Test1,1-Compress,28.333,0.681,0.893,0.077,,0.567344,980.395,,56.7344,0.980395,,,,7.85398e-5
Test1,1-Compress,28.667,0.67,0.904,0.083,,0.574333,1056.79,,57.4333,1.05679,,,,7.85398e-5
Test1,1-Compress,29.000,0.66,0.914,0.083,,0.580686,1056.79,,58.0686,1.05679,,,,7.85398e-5
Test1,1-Compress,29.333,0.649,0.925,0.083,,0.587675,1056.79,,58.7675,1.05679,,,,7.85398e-5
Test1,1-Compress,29.667,0.639,0.935,0.083,,0.594028,1056.79,,59.4028,1.05679,,,,7.85398e-5
Test1,1-Compress,30.000,0.63,0.944,0.077,,0.599746,980.395,,59.9746,0.980395,,,,7.85398e-5
Test1,1-Recover,30.333,0.64,0.934,0.063,,0.593393,802.141,,59.3393,0.802141,,,,7.85398e-5
Test1,1-Recover,30.667,0.651,0.923,0.083,,0.586404,1056.79,,58.6404,1.05679,,,,7.85398e-5
Test1,1-Recover,31.000,0.661,0.913,0.070,,0.580051,891.268,,58.0051,0.891268,,,,7.85398e-5
Test1,1-Recover,31.333,0.672,0.902,0.063,,0.573062,802.141,,57.3062,0.802141,,,,7.85398e-5
Test1,1-Recover,31.667,0.682,0.892,0.056,,0.566709,713.014,,56.6709,0.713014,,,,7.85398e-5
Test1,1-Recover,32.000,0.693,0.881,0.063,,0.55972,802.141,,55.972,0.802141,,,,7.85398e-5
Test1,1-Recover,32.333,0.703,0.871,0.070,,0.553367,891.268,,55.3367,0.891268,,,,7.85398e-5
Test1,1-Recover,32.667,0.714,0.86,0.070,,0.546379,891.268,,54.6379,0.891268,,,,7.85398e-5
Test1,1-Recover,33.000,0.724,0.85,0.083,,0.540025,1056.79,,54.0025,1.05679,,,,7.85398e-5
Test1,1-Recover,33.333,0.735,0.839,0.056,,0.533037,713.014,,53.3037,0.713014,,,,7.85398e-5
Test1,1-Recover,33.667,0.745,0.829,0.063,,0.526684,802.141,,52.6684,0.802141,,,,7.85398e-5
Test1,1-Recover,34.000,0.756,0.818,0.063,,0.519695,802.141,,51.9695,0.802141,,,,7.85398e-5
Test1,1-Recover,34.333,0.766,0.808,0.050,,0.513342,636.62,,51.3342,0.63662,,,,7.85398e-5
Test1,1-Recover,34.667,0.777,0.797,0.056,,0.506353,713.014,,50.6353,0.713014,,,,7.85398e-5
Test1,1-Recover,35.000,0.787,0.787,0.050,,0.5,636.62,,50,0.63662,,,,7.85398e-5
Test1,1-Recover,35.333,0.798,0.776,0.050,,0.493011,636.62,,49.3011,0.63662,,,,7.85398e-5
Test1,1-Recover,35.667,0.808,0.766,0.050,,0.486658,636.62,,48.6658,0.63662,,,,7.85398e-5
Test1,1-Recover,36.000,0.819,0.755,0.050,,0.47967,636.62,,47.967,0.63662,,,,7.85398e-5
Test1,1-Recover,36.333,0.829,0.745,0.050,,0.473316,636.62,,47.3316,0.63662,,,,7.85398e-5
Test1,1-Recover,36.667,0.84,0.734,0.050,,0.466328,636.62,,46.6328,0.63662,,,,7.85398e-5
Test1,1-Recover,37.000,0.85,0.724,0.050,,0.459975,636.62,,45.9975,0.63662,,,,7.85398e-5
Test1,1-Recover,37.333,0.861,0.713,0.050,,0.452986,636.62,,45.2986,0.63662,,,,7.85398e-5
Test1,1-Recover,37.667,0.871,0.703,0.050,,0.446633,636.62,,44.6633,0.63662,,,,7.85398e-5
Test1,1-Recover,38.000,0.882,0.692,0.050,,0.439644,636.62,,43.9644,0.63662,,,,7.85398e-5
Test1,1-Recover,38.333,0.892,0.682,0.050,,0.433291,636.62,,43.3291,0.63662,,,,7.85398e-5
Test1,1-Recover,38.667,0.903,0.671,0.050,,0.426302,636.62,,42.6302,0.63662,,,,7.85398e-5
Test1,1-Recover,39.000,0.913,0.661,0.043,,0.419949,547.493,,41.9949,0.547493,,,,7.85398e-5
Test1,1-Recover,39.333,0.924,0.65,0.050,,0.412961,636.62,,41.2961,0.63662,,,,7.85398e-5
Test1,1-Recover,39.667,0.934,0.64,0.050,,0.406607,636.62,,40.6607,0.63662,,,,7.85398e-5
Test1,1-Recover,40.000,0.945,0.629,0.050,,0.399619,636.62,,39.9619,0.63662,,,,7.85398e-5
Test1,1-Recover,40.333,0.955,0.619,0.043,,0.393266,547.493,,39.3266,0.547493,,,,7.85398e-5
Test1,1-Recover,40.667,0.966,0.608,0.050,,0.386277,636.62,,38.6277,0.63662,,,,7.85398e-5
Test1,1-Recover,41.000,0.976,0.598,0.050,,0.379924,636.62,,37.9924,0.63662,,,,7.85398e-5
Test1,1-Recover,41.333,0.987,0.587,0.050,,0.372935,636.62,,37.2935,0.63662,,,,7.85398e-5
Test1,1-Recover,41.667,0.997,0.577,0.050,,0.366582,636.62,,36.6582,0.63662,,,,7.85398e-5
Test1,1-Recover,42.000,1.008,0.566,0.050,,0.359593,636.62,,35.9593,0.63662,,,,7.85398e-5
Test1,1-Recover,42.333,1.018,0.556,0.050,,0.35324,636.62,,35.324,0.63662,,,,7.85398e-5
Test1,1-Recover,42.667,1.029,0.545,0.036,,0.346252,458.366,,34.6252,0.458366,,,,7.85398e-5
Test1,1-Recover,43.000,1.039,0.535,0.043,,0.339898,547.493,,33.9898,0.547493,,,,7.85398e-5
Test1,1-Recover,43.333,1.05,0.524,0.043,,0.33291,547.493,,33.291,0.547493,,,,7.85398e-5
Test1,1-Recover,43.667,1.06,0.514,0.036,,0.326557,458.366,,32.6557,0.458366,,,,7.85398e-5
Test1,1-Recover,44.000,1.071,0.503,0.022,,0.319568,280.113,,31.9568,0.280113,,,,7.85398e-5
Test1,1-Recover,44.333,1.081,0.493,0.022,,0.313215,280.113,,31.3215,0.280113,,,,7.85398e-5
Test1,1-Recover,44.667,1.092,0.482,0.022,,0.306226,280.113,,30.6226,0.280113,,,,7.85398e-5
Test1,1-Recover,45.000,1.102,0.472,0.022,,0.299873,280.113,,29.9873,0.280113,,,,7.85398e-5
Test1,1-Recover,45.333,1.113,0.461,0.002,,0.292884,25.4648,,29.2884,0.0254648,,,,7.85398e-5
Test1,1-Recover,45.667,1.123,0.451,0.002,,0.286531,25.4648,,28.6531,0.0254648,,,,7.85398e-5
Test1,1-Recover,46.000,1.134,0.44,0.002,,0.279543,25.4648,,27.9543,0.0254648,,,,7.85398e-5
Test1,1-Recover,46.333,1.144,0.43,0.002,,0.273189,25.4648,,27.3189,0.0254648,,,,7.85398e-5
Test1,1-Recover,46.667,1.155,0.419,0.009,,0.266201,114.592,,26.6201,0.114592,,,,7.85398e-5
Test1,1-Recover,47.000,1.165,0.409,0.002,,0.259848,25.4648,,25.9848,0.0254648,,,,7.85398e-5
Test1,1-Recover,47.333,1.176,0.398,0.009,,0.252859,114.592,,25.2859,0.114592,,,,7.85398e-5
Test1,1-Recover,47.667,1.186,0.388,0.009,,0.246506,114.592,,24.6506,0.114592,,,,7.85398e-5
Test1,1-Recover,48.000,1.197,0.377,0.009,,0.239517,114.592,,23.9517,0.114592,,,,7.85398e-5
Test1,1-Recover,48.333,1.207,0.367,0.016,,0.233164,203.718,,23.3164,0.203718,,,,7.85398e-5
Test1,1-Recover,48.667,1.218,0.356,0.022,,0.226175,280.113,,22.6175,0.280113,,,,7.85398e-5
Test1,1-Recover,49.000,1.228,0.346,0.009,,0.219822,114.592,,21.9822,0.114592,,,,7.85398e-5
Test1,1-Recover,49.333,1.239,0.335,0.009,,0.212834,114.592,,21.2834,0.114592,,,,7.85398e-5
Test1,1-Recover,49.667,1.249,0.325,0.009,,0.20648,114.592,,20.648,0.114592,,,,7.85398e-5
Test1,1-Recover,50.000,1.26,0.314,0.009,,0.199492,114.592,,19.9492,0.114592,,,,7.85398e-5
Test1,1-Recover,50.333,1.27,0.304,-0.005,,0.193139,-63.662,,19.3139,-0.063662,,,,7.85398e-5
Test1,1-Recover,50.667,1.281,0.293,-0.005,,0.18615,-63.662,,18.615,-0.063662,,,,7.85398e-5
Test1,1-Recover,51.000,1.291,0.283,0.002,,0.179797,25.4648,,17.9797,0.0254648,,,,7.85398e-5
Test1,1-Recover,51.333,1.302,0.272,0.002,,0.172808,25.4648,,17.2808,0.0254648,,,,7.85398e-5
Test1,1-Recover,51.667,1.312,0.262,-0.005,,0.166455,-63.662,,16.6455,-0.063662,,,,7.85398e-5
Test1,1-Recover,52.000,1.323,0.251,-0.005,,0.159466,-63.662,,15.9466,-0.063662,,,,7.85398e-5
Test1,1-Recover,52.333,1.333,0.241,-0.005,,0.153113,-63.662,,15.3113,-0.063662,,,,7.85398e-5
Test1,1-Recover,52.667,1.344,0.23,-0.005,,0.146125,-63.662,,14.6125,-0.063662,,,,7.85398e-5
Test1,1-Recover,53.000,1.354,0.22,-0.005,,0.139771,-63.662,,13.9771,-0.063662,,,,7.85398e-5
Test1,1-Recover,53.333,1.365,0.209,-0.005,,0.132783,-63.662,,13.2783,-0.063662,,,,7.85398e-5
Test1,1-Recover,53.667,1.375,0.199,0.002,,0.126429,25.4648,,12.6429,0.0254648,,,,7.85398e-5
Test1,1-Recover,54.000,1.386,0.188,0.002,,0.119441,25.4648,,11.9441,0.0254648,,,,7.85398e-5
Test1,1-Recover,54.333,1.396,0.178,0.002,,0.113088,25.4648,,11.3088,0.0254648,,,,7.85398e-5
Test1,1-Recover,54.667,1.407,0.167,0.002,,0.106099,25.4648,,10.6099,0.0254648,,,,7.85398e-5
Test1,1-Recover,55.000,1.417,0.157,0.002,,0.0997459,25.4648,,9.97459,0.0254648,,,,7.85398e-5
Test1,1-Recover,55.333,1.428,0.146,0.009,,0.0927573,114.592,,9.27573,0.114592,,,,7.85398e-5
Test1,1-Recover,55.667,1.438,0.136,0.009,,0.0864041,114.592,,8.64041,0.114592,,,,7.85398e-5
Test1,1-Recover,56.000,1.449,0.125,0.016,,0.0794155,203.718,,7.94155,0.203718,,,,7.85398e-5
Test1,1-Recover,56.333,1.459,0.115,0.009,,0.0730623,114.592,,7.30623,0.114592,,,,7.85398e-5
Test1,1-Recover,56.667,1.47,0.104,0.002,,0.0660737,25.4648,,6.60737,0.0254648,,,,7.85398e-5
Test1,1-Recover,57.000,1.48,0.094,0.002,,0.0597205,25.4648,,5.97205,0.0254648,,,,7.85398e-5
Test1,1-Recover,57.333,1.491,0.083,0.002,,0.0527319,25.4648,,5.27319,0.0254648,,,,7.85398e-5
Test1,1-Recover,57.667,1.502,0.072,-0.005,,0.0457433,-63.662,,4.57433,-0.063662,,,,7.85398e-5
Test1,1-Recover,58.000,1.512,0.062,-0.005,,0.0393901,-63.662,,3.93901,-0.063662,,,,7.85398e-5
Test1,1-Recover,58.333,1.522,0.052,-0.005,,0.0330368,-63.662,,3.30368,-0.063662,,,,7.85398e-5
Test1,1-Recover,58.667,1.533,0.041,-0.005,,0.0260483,-63.662,,2.60483,-0.063662,,,,7.85398e-5
Test1,1-Recover,59.000,1.543,0.031,-0.005,,0.019695,-63.662,,1.9695,-0.063662,,,,7.85398e-5
Test1,1-Recover,59.333,1.554,0.02,-0.005,,0.0127065,-63.662,,1.27065,-0.063662,,,,7.85398e-5
Test1,1-Recover,59.667,1.565,0.009,-0.005,,0.00571792,-63.662,,0.571792,-0.063662,,,,7.85398e-5
Test1,1-Recover,60.000,1.574,-0,-0.005,,0,-63.662,,0,-0.063662,,,,7.85398e-5
Test1,2-Compress,60.317,1.565,0.009,-0.005,,0.00571792,-63.662,,0.571792,-0.063662,,,,7.85398e-5
Test1,2-Compress,60.650,1.554,0.02,-0.005,,0.0127065,-63.662,,1.27065,-0.063662,,,,7.85398e-5
Test1,2-Compress,60.983,1.544,0.03,-0.005,,0.0190597,-63.662,,1.90597,-0.063662,,,,7.85398e-5
Test1,2-Compress,61.317,1.533,0.041,-0.005,,0.0260483,-63.662,,2.60483,-0.063662,,,,7.85398e-5
Test1,2-Compress,61.650,1.523,0.051,-0.005,,0.0324015,-63.662,,3.24015,-0.063662,,,,7.85398e-5
Test1,2-Compress,61.983,1.512,0.062,-0.005,,0.0393901,-63.662,,3.93901,-0.063662,,,,7.85398e-5
Test1,2-Compress,62.317,1.502,0.072,0.002,,0.0457433,25.4648,,4.57433,0.0254648,,,,7.85398e-5
Test1,2-Compress,62.650,1.491,0.083,0.002,,0.0527319,25.4648,,5.27319,0.0254648,,,,7.85398e-5
Test1,2-Compress,62.983,1.481,0.093,0.002,,0.0590851,25.4648,,5.90851,0.0254648,,,,7.85398e-5
Test1,2-Compress,63.317,1.47,0.104,0.002,,0.0660737,25.4648,,6.60737,0.0254648,,,,7.85398e-5
Test1,2-Compress,63.650,1.46,0.114,0.002,,0.0724269,25.4648,,7.24269,0.0254648,,,,7.85398e-5
Test1,2-Compress,63.983,1.449,0.125,0.009,,0.0794155,114.592,,7.94155,0.114592,,,,7.85398e-5
Test1,2-Compress,64.317,1.438,0.136,0.009,,0.0864041,114.592,,8.64041,0.114592,,,,7.85398e-5
Test1,2-Compress,64.650,1.428,0.146,0.009,,0.0927573,114.592,,9.27573,0.114592,,,,7.85398e-5
Test1,2-Compress,64.983,1.418,0.156,0.009,,0.0991105,114.592,,9.91105,0.114592,,,,7.85398e-5
Test1,2-Compress,65.317,1.407,0.167,0.016,,0.106099,203.718,,10.6099,0.203718,,,,7.85398e-5
Test1,2-Compress,65.650,1.397,0.177,0.009,,0.112452,114.592,,11.2452,0.114592,,,,7.85398e-5
Test1,2-Compress,65.983,1.386,0.188,0.022,,0.119441,280.113,,11.9441,0.280113,,,,7.85398e-5
Test1,2-Compress,66.317,1.375,0.199,0.009,,0.126429,114.592,,12.6429,0.114592,,,,7.85398e-5
Test1,2-Compress,66.650,1.365,0.209,0.002,,0.132783,25.4648,,13.2783,0.0254648,,,,7.85398e-5
Test1,2-Compress,66.983,1.355,0.219,0.009,,0.139136,114.592,,13.9136,0.114592,,,,7.85398e-5
Test1,2-Compress,67.317,1.344,0.23,0.009,,0.146125,114.592,,14.6125,0.114592,,,,7.85398e-5
Test1,2-Compress,67.650,1.334,0.24,0.002,,0.152478,25.4648,,15.2478,0.0254648,,,,7.85398e-5
Test1,2-Compress,67.983,1.323,0.251,0.009,,0.159466,114.592,,15.9466,0.114592,,,,7.85398e-5
Test1,2-Compress,68.317,1.312,0.262,0.009,,0.166455,114.592,,16.6455,0.114592,,,,7.85398e-5
Test1,2-Compress,68.650,1.302,0.272,0.009,,0.172808,114.592,,17.2808,0.114592,,,,7.85398e-5
Test1,2-Compress,68.983,1.292,0.282,0.009,,0.179161,114.592,,17.9161,0.114592,,,,7.85398e-5
Test1,2-Compress,69.317,1.281,0.293,0.002,,0.18615,25.4648,,18.615,0.0254648,,,,7.85398e-5
Test1,2-Compress,69.650,1.271,0.303,0.009,,0.192503,114.592,,19.2503,0.114592,,,,7.85398e-5
Test1,2-Compress,69.983,1.26,0.314,0.022,,0.199492,280.113,,19.9492,0.280113,,,,7.85398e-5
Test1,2-Compress,70.317,1.249,0.325,0.009,,0.20648,114.592,,20.648,0.114592,,,,7.85398e-5
Test1,2-Compress,70.650,1.239,0.335,0.002,,0.212834,25.4648,,21.2834,0.0254648,,,,7.85398e-5
Test1,2-Compress,70.983,1.229,0.345,0.022,,0.219187,280.113,,21.9187,0.280113,,,,7.85398e-5
Test1,2-Compress,71.317,1.218,0.356,0.022,,0.226175,280.113,,22.6175,0.280113,,,,7.85398e-5
Test1,2-Compress,71.650,1.207,0.367,0.016,,0.233164,203.718,,23.3164,0.203718,,,,7.85398e-5
Test1,2-Compress,71.983,1.197,0.377,0.002,,0.239517,25.4648,,23.9517,0.0254648,,,,7.85398e-5
Test1,2-Compress,72.317,1.186,0.388,0.029,,0.246506,369.24,,24.6506,0.36924,,,,7.85398e-5
Test1,2-Compress,72.650,1.176,0.398,0.029,,0.252859,369.24,,25.2859,0.36924,,,,7.85398e-5
Test1,2-Compress,72.983,1.166,0.408,0.050,,0.259212,636.62,,25.9212,0.63662,,,,7.85398e-5
Test1,2-Compress,73.317,1.155,0.419,0.036,,0.266201,458.366,,26.6201,0.458366,,,,7.85398e-5
Test1,2-Compress,73.650,1.144,0.43,0.043,,0.273189,547.493,,27.3189,0.547493,,,,7.85398e-5
Test1,2-Compress,73.983,1.134,0.44,0.043,,0.279543,547.493,,27.9543,0.547493,,,,7.85398e-5
Test1,2-Compress,74.317,1.123,0.451,0.043,,0.286531,547.493,,28.6531,0.547493,,,,7.85398e-5
Test1,2-Compress,74.650,1.113,0.461,0.050,,0.292884,636.62,,29.2884,0.63662,,,,7.85398e-5
Test1,2-Compress,74.983,1.103,0.471,0.050,,0.299238,636.62,,29.9238,0.63662,,,,7.85398e-5
Test1,2-Compress,75.317,1.092,0.482,0.050,,0.306226,636.62,,30.6226,0.63662,,,,7.85398e-5
Test1,2-Compress,75.650,1.081,0.493,0.050,,0.313215,636.62,,31.3215,0.63662,,,,7.85398e-5
Test1,2-Compress,75.983,1.071,0.503,0.050,,0.319568,636.62,,31.9568,0.63662,,,,7.85398e-5
Test1,2-Compress,76.317,1.06,0.514,0.050,,0.326557,636.62,,32.6557,0.63662,,,,7.85398e-5
Test1,2-Compress,76.650,1.05,0.524,0.050,,0.33291,636.62,,33.291,0.63662,,,,7.85398e-5
Test1,2-Compress,76.983,1.04,0.534,0.050,,0.339263,636.62,,33.9263,0.63662,,,,7.85398e-5
Test1,2-Compress,77.317,1.029,0.545,0.050,,0.346252,636.62,,34.6252,0.63662,,,,7.85398e-5
Test1,2-Compress,77.650,1.018,0.556,0.050,,0.35324,636.62,,35.324,0.63662,,,,7.85398e-5
Test1,2-Compress,77.983,1.008,0.566,0.050,,0.359593,636.62,,35.9593,0.63662,,,,7.85398e-5
Test1,2-Compress,78.317,0.997,0.577,0.050,,0.366582,636.62,,36.6582,0.63662,,,,7.85398e-5
Test1,2-Compress,78.650,0.987,0.587,0.050,,0.372935,636.62,,37.2935,0.63662,,,,7.85398e-5
Test1,2-Compress,78.983,0.976,0.598,0.050,,0.379924,636.62,,37.9924,0.63662,,,,7.85398e-5
Test1,2-Compress,79.317,0.966,0.608,0.050,,0.386277,636.62,,38.6277,0.63662,,,,7.85398e-5
Test1,2-Compress,79.650,0.955,0.619,0.050,,0.393266,636.62,,39.3266,0.63662,,,,7.85398e-5
Test1,2-Compress,79.983,0.945,0.629,0.050,,0.399619,636.62,,39.9619,0.63662,,,,7.85398e-5
Test1,2-Compress,80.317,0.935,0.639,0.056,,0.405972,713.014,,40.5972,0.713014,,,,7.85398e-5
Test1,2-Compress,80.650,0.924,0.65,0.056,,0.412961,713.014,,41.2961,0.713014,,,,7.85398e-5
Test1,2-Compress,80.983,0.913,0.661,0.056,,0.419949,713.014,,41.9949,0.713014,,,,7.85398e-5
Test1,2-Compress,81.317,0.903,0.671,0.056,,0.426302,713.014,,42.6302,0.713014,,,,7.85398e-5
Test1,2-Compress,81.650,0.892,0.682,0.050,,0.433291,636.62,,43.3291,0.63662,,,,7.85398e-5
Test1,2-Compress,81.983,0.882,0.692,0.050,,0.439644,636.62,,43.9644,0.63662,,,,7.85398e-5
Test1,2-Compress,82.317,0.871,0.703,0.056,,0.446633,713.014,,44.6633,0.713014,,,,7.85398e-5
Test1,2-Compress,82.650,0.861,0.713,0.056,,0.452986,713.014,,45.2986,0.713014,,,,7.85398e-5
Test1,2-Compress,82.983,0.85,0.724,0.056,,0.459975,713.014,,45.9975,0.713014,,,,7.85398e-5
Test1,2-Compress,83.317,0.84,0.734,0.056,,0.466328,713.014,,46.6328,0.713014,,,,7.85398e-5
Test1,2-Compress,83.650,0.83,0.744,0.063,,0.472681,802.141,,47.2681,0.802141,,,,7.85398e-5
Test1,2-Compress,83.983,0.819,0.755,0.056,,0.47967,713.014,,47.967,0.713014,,,,7.85398e-5
Test1,2-Compress,84.317,0.809,0.765,0.056,,0.486023,713.014,,48.6023,0.713014,,,,7.85398e-5
Test1,2-Compress,84.650,0.798,0.776,0.063,,0.493011,802.141,,49.3011,0.802141,,,,7.85398e-5
Test1,2-Compress,84.983,0.787,0.787,0.056,,0.5,713.014,,50,0.713014,,,,7.85398e-5
Test1,2-Compress,85.317,0.777,0.797,0.056,,0.506353,713.014,,50.6353,0.713014,,,,7.85398e-5
Test1,2-Compress,85.650,0.766,0.808,0.056,,0.513342,713.014,,51.3342,0.713014,,,,7.85398e-5
Test1,2-Compress,85.983,0.756,0.818,0.063,,0.519695,802.141,,51.9695,0.802141,,,,7.85398e-5
Test1,2-Compress,86.317,0.745,0.829,0.056,,0.526684,713.014,,52.6684,0.713014,,,,7.85398e-5
Test1,2-Compress,86.650,0.735,0.839,0.056,,0.533037,713.014,,53.3037,0.713014,,,,7.85398e-5
Test1,2-Compress,86.983,0.725,0.849,0.050,,0.53939,636.62,,53.939,0.63662,,,,7.85398e-5
Test1,2-Compress,87.317,0.714,0.86,0.050,,0.546379,636.62,,54.6379,0.63662,,,,7.85398e-5
Test1,2-Compress,87.650,0.704,0.87,0.056,,0.552732,713.014,,55.2732,0.713014,,,,7.85398e-5
Test1,2-Compress,87.983,0.693,0.881,0.063,,0.55972,802.141,,55.972,0.802141,,,,7.85398e-5
Test1,2-Compress,88.317,0.682,0.892,0.077,,0.566709,980.395,,56.6709,0.980395,,,,7.85398e-5
Test1,2-Compress,88.650,0.672,0.902,0.070,,0.573062,891.268,,57.3062,0.891268,,,,7.85398e-5
Test1,2-Compress,88.983,0.661,0.913,0.090,,0.580051,1145.92,,58.0051,1.14592,,,,7.85398e-5
Test1,2-Compress,89.317,0.651,0.923,0.090,,0.586404,1145.92,,58.6404,1.14592,,,,7.85398e-5
Test1,2-Compress,89.650,0.64,0.934,0.083,,0.593393,1056.79,,59.3393,1.05679,,,,7.85398e-5
Test1,2-Compress,89.983,0.63,0.944,0.097,,0.599746,1235.04,,59.9746,1.23504,,,,7.85398e-5
Test1,2-Recover,90.303,0.638,0.936,0.104,,0.594663,1324.17,,59.4663,1.32417,,,,7.85398e-5
Test1,2-Recover,90.637,0.649,0.925,0.097,,0.587675,1235.04,,58.7675,1.23504,,,,7.85398e-5
Test1,2-Recover,90.970,0.659,0.915,0.090,,0.581321,1145.92,,58.1321,1.14592,,,,7.85398e-5
Test1,2-Recover,91.303,0.669,0.905,0.083,,0.574968,1056.79,,57.4968,1.05679,,,,7.85398e-5
Test1,2-Recover,91.637,0.68,0.894,0.070,,0.56798,891.268,,56.798,0.891268,,,,7.85398e-5
Test1,2-Recover,91.970,0.69,0.884,0.070,,0.561626,891.268,,56.1626,0.891268,,,,7.85398e-5
Test1,2-Recover,92.303,0.701,0.873,0.063,,0.554638,802.141,,55.4638,0.802141,,,,7.85398e-5
Test1,2-Recover,92.637,0.711,0.863,0.063,,0.548285,802.141,,54.8285,0.802141,,,,7.85398e-5
Test1,2-Recover,92.970,0.722,0.852,0.056,,0.541296,713.014,,54.1296,0.713014,,,,7.85398e-5
Test1,2-Recover,93.303,0.733,0.841,0.056,,0.534307,713.014,,53.4307,0.713014,,,,7.85398e-5
Test1,2-Recover,93.637,0.743,0.831,0.056,,0.527954,713.014,,52.7954,0.713014,,,,7.85398e-5
Test1,2-Recover,93.970,0.754,0.82,0.056,,0.520966,713.014,,52.0966,0.713014,,,,7.85398e-5
Test1,2-Recover,94.303,0.764,0.81,0.050,,0.514612,636.62,,51.4612,0.63662,,,,7.85398e-5
Test1,2-Recover,94.637,0.775,0.799,0.050,,0.507624,636.62,,50.7624,0.63662,,,,7.85398e-5
Test1,2-Recover,94.970,0.785,0.789,0.050,,0.501271,636.62,,50.1271,0.63662,,,,7.85398e-5
Test1,2-Recover,95.303,0.795,0.779,0.050,,0.494917,636.62,,49.4917,0.63662,,,,7.85398e-5
Test1,2-Recover,95.637,0.806,0.768,0.050,,0.487929,636.62,,48.7929,0.63662,,,,7.85398e-5
Test1,2-Recover,95.970,0.816,0.758,0.050,,0.481576,636.62,,48.1576,0.63662,,,,7.85398e-5
Test1,2-Recover,96.303,0.827,0.747,0.050,,0.474587,636.62,,47.4587,0.63662,,,,7.85398e-5
Test1,2-Recover,96.637,0.838,0.736,0.050,,0.467598,636.62,,46.7598,0.63662,,,,7.85398e-5
Test1,2-Recover,96.970,0.848,0.726,0.050,,0.461245,636.62,,46.1245,0.63662,,,,7.85398e-5
Test1,2-Recover,97.303,0.859,0.715,0.050,,0.454257,636.62,,45.4257,0.63662,,,,7.85398e-5
Test1,2-Recover,97.637,0.869,0.705,0.050,,0.447903,636.62,,44.7903,0.63662,,,,7.85398e-5
Test1,2-Recover,97.970,0.88,0.694,0.050,,0.440915,636.62,,44.0915,0.63662,,,,7.85398e-5
Test1,2-Recover,98.303,0.89,0.684,0.056,,0.434562,713.014,,43.4562,0.713014,,,,7.85398e-5
Test1,2-Recover,98.637,0.901,0.673,0.050,,0.427573,636.62,,42.7573,0.63662,,,,7.85398e-5
Test1,2-Recover,98.970,0.911,0.663,0.050,,0.42122,636.62,,42.122,0.63662,,,,7.85398e-5
Test1,2-Recover,99.303,0.921,0.653,0.050,,0.414867,636.62,,41.4867,0.63662,,,,7.85398e-5
Test1,2-Recover,99.637,0.932,0.642,0.050,,0.407878,636.62,,40.7878,0.63662,,,,7.85398e-5
Test1,2-Recover,99.970,0.942,0.632,0.050,,0.401525,636.62,,40.1525,0.63662,,,,7.85398e-5
Test1,2-Recover,100.303,0.953,0.621,0.050,,0.394536,636.62,,39.4536,0.63662,,,,7.85398e-5
Test1,2-Recover,100.637,0.964,0.61,0.050,,0.387548,636.62,,38.7548,0.63662,,,,7.85398e-5
Test1,2-Recover,100.970,0.974,0.6,0.050,,0.381194,636.62,,38.1194,0.63662,,,,7.85398e-5
Test1,2-Recover,101.303,0.985,0.589,0.050,,0.374206,636.62,,37.4206,0.63662,,,,7.85398e-5
Test1,2-Recover,101.637,0.995,0.579,0.050,,0.367853,636.62,,36.7853,0.63662,,,,7.85398e-5
Test1,2-Recover,101.970,1.006,0.568,0.036,,0.360864,458.366,,36.0864,0.458366,,,,7.85398e-5
Test1,2-Recover,102.303,1.016,0.558,0.050,,0.354511,636.62,,35.4511,0.63662,,,,7.85398e-5
Test1,2-Recover,102.637,1.027,0.547,0.029,,0.347522,369.24,,34.7522,0.36924,,,,7.85398e-5
Test1,2-Recover,102.970,1.037,0.537,0.016,,0.341169,203.718,,34.1169,0.203718,,,,7.85398e-5
Test1,2-Recover,103.303,1.047,0.527,0.029,,0.334816,369.24,,33.4816,0.36924,,,,7.85398e-5
Test1,2-Recover,103.637,1.058,0.516,0.029,,0.327827,369.24,,32.7827,0.36924,,,,7.85398e-5
Test1,2-Recover,103.970,1.069,0.505,0.036,,0.320839,458.366,,32.0839,0.458366,,,,7.85398e-5
Test1,2-Recover,104.303,1.079,0.495,0.016,,0.314485,203.718,,31.4485,0.203718,,,,7.85398e-5
Test1,2-Recover,104.637,1.09,0.484,0.029,,0.307497,369.24,,30.7497,0.36924,,,,7.85398e-5
Test1,2-Recover,104.970,1.1,0.474,0.029,,0.301144,369.24,,30.1144,0.36924,,,,7.85398e-5
Test1,2-Recover,105.303,1.111,0.463,0.036,,0.294155,458.366,,29.4155,0.458366,,,,7.85398e-5
Test1,2-Recover,105.637,1.121,0.453,0.036,,0.287802,458.366,,28.7802,0.458366,,,,7.85398e-5
Test1,2-Recover,105.970,1.132,0.442,0.029,,0.280813,369.24,,28.0813,0.36924,,,,7.85398e-5
Test1,2-Recover,106.303,1.142,0.432,0.036,,0.27446,458.366,,27.446,0.458366,,,,7.85398e-5
Test1,2-Recover,106.637,1.153,0.421,0.029,,0.267471,369.24,,26.7471,0.36924,,,,7.85398e-5
Test1,2-Recover,106.970,1.163,0.411,0.029,,0.261118,369.24,,26.1118,0.36924,,,,7.85398e-5
Test1,2-Recover,107.303,1.173,0.401,0.022,,0.254765,280.113,,25.4765,0.280113,,,,7.85398e-5
Test1,2-Recover,107.637,1.184,0.39,0.016,,0.247776,203.718,,24.7776,0.203718,,,,7.85398e-5
Test1,2-Recover,107.970,1.195,0.379,0.016,,0.240788,203.718,,24.0788,0.203718,,,,7.85398e-5
Test1,2-Recover,108.303,1.205,0.369,0.009,,0.234435,114.592,,23.4435,0.114592,,,,7.85398e-5
Test1,2-Recover,108.637,1.216,0.358,0.002,,0.227446,25.4648,,22.7446,0.0254648,,,,7.85398e-5
Test1,2-Recover,108.970,1.226,0.348,0.002,,0.221093,25.4648,,22.1093,0.0254648,,,,7.85398e-5
Test1,2-Recover,109.303,1.237,0.337,0.002,,0.214104,25.4648,,21.4104,0.0254648,,,,7.85398e-5
Test1,2-Recover,109.637,1.247,0.327,0.002,,0.207751,25.4648,,20.7751,0.0254648,,,,7.85398e-5
Test1,2-Recover,109.970,1.258,0.316,0.002,,0.200762,25.4648,,20.0762,0.0254648,,,,7.85398e-5
Test1,2-Recover,110.303,1.268,0.306,0.002,,0.194409,25.4648,,19.4409,0.0254648,,,,7.85398e-5
Test1,2-Recover,110.637,1.279,0.295,0.002,,0.187421,25.4648,,18.7421,0.0254648,,,,7.85398e-5
Test1,2-Recover,110.970,1.289,0.285,0.002,,0.181067,25.4648,,18.1067,0.0254648,,,,7.85398e-5
Test1,2-Recover,111.303,1.3,0.274,0.002,,0.174079,25.4648,,17.4079,0.0254648,,,,7.85398e-5
Test1,2-Recover,111.637,1.31,0.264,0.002,,0.167726,25.4648,,16.7726,0.0254648,,,,7.85398e-5
Test1,2-Recover,111.970,1.321,0.253,0.002,,0.160737,25.4648,,16.0737,0.0254648,,,,7.85398e-5
Test1,2-Recover,112.303,1.331,0.243,0.009,,0.154384,114.592,,15.4384,0.114592,,,,7.85398e-5
Test1,2-Recover,112.637,1.342,0.232,0.009,,0.147395,114.592,,14.7395,0.114592,,,,7.85398e-5
Test1,2-Recover,112.970,1.352,0.222,0.002,,0.141042,25.4648,,14.1042,0.0254648,,,,7.85398e-5
Test1,2-Recover,113.303,1.363,0.211,0.009,,0.134053,114.592,,13.4053,0.114592,,,,7.85398e-5
Test1,2-Recover,113.637,1.373,0.201,0.009,,0.1277,114.592,,12.77,0.114592,,,,7.85398e-5
Test1,2-Recover,113.970,1.384,0.19,0.009,,0.120712,114.592,,12.0712,0.114592,,,,7.85398e-5
Test1,2-Recover,114.303,1.394,0.18,0.002,,0.114358,25.4648,,11.4358,0.0254648,,,,7.85398e-5
Test1,2-Recover,114.637,1.405,0.169,-0.005,,0.10737,-63.662,,10.737,-0.063662,,,,7.85398e-5
Test1,2-Recover,114.970,1.415,0.159,-0.005,,0.101017,-63.662,,10.1017,-0.063662,,,,7.85398e-5
Test1,2-Recover,115.303,1.426,0.148,-0.005,,0.094028,-63.662,,9.4028,-0.063662,,,,7.85398e-5
Test1,2-Recover,115.637,1.436,0.138,-0.005,,0.0876747,-63.662,,8.76747,-0.063662,,,,7.85398e-5
Test1,2-Recover,115.970,1.447,0.127,-0.005,,0.0806861,-63.662,,8.06861,-0.063662,,,,7.85398e-5
Test1,2-Recover,116.303,1.457,0.117,-0.005,,0.0743329,-63.662,,7.43329,-0.063662,,,,7.85398e-5
Test1,2-Recover,116.637,1.468,0.106,-0.005,,0.0673443,-63.662,,6.73443,-0.063662,,,,7.85398e-5
Test1,2-Recover,116.970,1.478,0.096,-0.005,,0.0609911,-63.662,,6.09911,-0.063662,,,,7.85398e-5
Test1,2-Recover,117.303,1.489,0.085,-0.005,,0.0540025,-63.662,,5.40025,-0.063662,,,,7.85398e-5
Test1,2-Recover,117.637,1.5,0.074,-0.005,,0.047014,-63.662,,4.7014,-0.063662,,,,7.85398e-5
Test1,2-Recover,117.970,1.51,0.064,-0.005,,0.0406607,-63.662,,4.06607,-0.063662,,,,7.85398e-5
Test1,2-Recover,118.303,1.52,0.054,-0.005,,0.0343075,-63.662,,3.43075,-0.063662,,,,7.85398e-5
Test1,2-Recover,118.637,1.531,0.043,0.002,,0.0273189,25.4648,,2.73189,0.0254648,,,,7.85398e-5
Test1,2-Recover,118.970,1.541,0.033,0.002,,0.0209657,25.4648,,2.09657,0.0254648,,,,7.85398e-5
Test1,2-Recover,119.303,1.552,0.022,0.002,,0.0139771,25.4648,,1.39771,0.0254648,,,,7.85398e-5
Test1,2-Recover,119.637,1.563,0.011,0.002,,0.00698856,25.4648,,0.698856,0.0254648,,,,7.85398e-5
Test1,2-Recover,119.970,1.573,0.001,0.002,,0.000635324,25.4648,,0.0635324,0.0254648,,,,7.85398e-5
Test1,3-Compress,120.280,1.567,0.007,0.002,,0.00444727,25.4648,,0.444727,0.0254648,,,,7.85398e-5
Test1,3-Compress,120.613,1.557,0.017,0.002,,0.0108005,25.4648,,1.08005,0.0254648,,,,7.85398e-5
Test1,3-Compress,120.947,1.546,0.028,0.002,,0.0177891,25.4648,,1.77891,0.0254648,,,,7.85398e-5
Test1,3-Compress,121.280,1.536,0.038,0.002,,0.0241423,25.4648,,2.41423,0.0254648,,,,7.85398e-5
Test1,3-Compress,121.613,1.525,0.049,0.002,,0.0311309,25.4648,,3.11309,0.0254648,,,,7.85398e-5
Test1,3-Compress,121.947,1.515,0.059,0.009,,0.0374841,114.592,,3.74841,0.114592,,,,7.85398e-5
Test1,3-Compress,122.280,1.504,0.07,0.002,,0.0444727,25.4648,,4.44727,0.0254648,,,,7.85398e-5
Test1,3-Compress,122.613,1.494,0.08,0.009,,0.0508259,114.592,,5.08259,0.114592,,,,7.85398e-5
Test1,3-Compress,122.947,1.483,0.091,-0.005,,0.0578145,-63.662,,5.78145,-0.063662,,,,7.85398e-5
Test1,3-Compress,123.280,1.472,0.102,-0.005,,0.064803,-63.662,,6.4803,-0.063662,,,,7.85398e-5
Test1,3-Compress,123.613,1.462,0.112,0.002,,0.0711563,25.4648,,7.11563,0.0254648,,,,7.85398e-5
Test1,3-Compress,123.947,1.451,0.123,-0.005,,0.0781449,-63.662,,7.81449,-0.063662,,,,7.85398e-5
Test1,3-Compress,124.280,1.441,0.133,-0.005,,0.0844981,-63.662,,8.44981,-0.063662,,,,7.85398e-5
Test1,3-Compress,124.613,1.431,0.143,0.002,,0.0908513,25.4648,,9.08513,0.0254648,,,,7.85398e-5
Test1,3-Compress,124.947,1.42,0.154,0.002,,0.0978399,25.4648,,9.78399,0.0254648,,,,7.85398e-5
Test1,3-Compress,125.280,1.41,0.164,-0.005,,0.104193,-63.662,,10.4193,-0.063662,,,,7.85398e-5
Test1,3-Compress,125.613,1.399,0.175,0.002,,0.111182,25.4648,,11.1182,0.0254648,,,,7.85398e-5
Test1,3-Compress,125.947,1.389,0.185,0.002,,0.117535,25.4648,,11.7535,0.0254648,,,,7.85398e-5
Test1,3-Compress,126.280,1.378,0.196,0.002,,0.124524,25.4648,,12.4524,0.0254648,,,,7.85398e-5
Test1,3-Compress,126.613,1.368,0.206,0.002,,0.130877,25.4648,,13.0877,0.0254648,,,,7.85398e-5
Test1,3-Compress,126.947,1.357,0.217,0.002,,0.137865,25.4648,,13.7865,0.0254648,,,,7.85398e-5
Test1,3-Compress,127.280,1.346,0.228,0.002,,0.144854,25.4648,,14.4854,0.0254648,,,,7.85398e-5
Test1,3-Compress,127.613,1.336,0.238,0.002,,0.151207,25.4648,,15.1207,0.0254648,,,,7.85398e-5
Test1,3-Compress,127.947,1.325,0.249,0.002,,0.158196,25.4648,,15.8196,0.0254648,,,,7.85398e-5
Test1,3-Compress,128.280,1.315,0.259,0.002,,0.164549,25.4648,,16.4549,0.0254648,,,,7.85398e-5
Test1,3-Compress,128.613,1.305,0.269,0.009,,0.170902,114.592,,17.0902,0.114592,,,,7.85398e-5
Test1,3-Compress,128.947,1.294,0.28,0.016,,0.177891,203.718,,17.7891,0.203718,,,,7.85398e-5
Test1,3-Compress,129.280,1.284,0.29,0.022,,0.184244,280.113,,18.4244,0.280113,,,,7.85398e-5
Test1,3-Compress,129.613,1.273,0.301,0.022,,0.191233,280.113,,19.1233,0.280113,,,,7.85398e-5
Test1,3-Compress,129.947,1.263,0.311,0.029,,0.197586,369.24,,19.7586,0.36924,,,,7.85398e-5
Test1,3-Compress,130.280,1.252,0.322,0.029,,0.204574,369.24,,20.4574,0.36924,,,,7.85398e-5
Test1,3-Compress,130.613,1.241,0.333,0.036,,0.211563,458.366,,21.1563,0.458366,,,,7.85398e-5
Test1,3-Compress,130.947,1.231,0.343,0.022,,0.217916,280.113,,21.7916,0.280113,,,,7.85398e-5
Test1,3-Compress,131.280,1.22,0.354,0.050,,0.224905,636.62,,22.4905,0.63662,,,,7.85398e-5
Test1,3-Compress,131.613,1.21,0.364,0.043,,0.231258,547.493,,23.1258,0.547493,,,,7.85398e-5
Test1,3-Compress,131.947,1.199,0.375,0.022,,0.238247,280.113,,23.8247,0.280113,,,,7.85398e-5
Test1,3-Compress,132.280,1.189,0.385,0.043,,0.2446,547.493,,24.46,0.547493,,,,7.85398e-5
Test1,3-Compress,132.613,1.179,0.395,0.050,,0.250953,636.62,,25.0953,0.63662,,,,7.85398e-5
Test1,3-Compress,132.947,1.168,0.406,0.036,,0.257942,458.366,,25.7942,0.458366,,,,7.85398e-5
Test1,3-Compress,133.280,1.158,0.416,0.016,,0.264295,203.718,,26.4295,0.203718,,,,7.85398e-5
Test1,3-Compress,133.613,1.147,0.427,0.043,,0.271283,547.493,,27.1283,0.547493,,,,7.85398e-5
Test1,3-Compress,133.947,1.137,0.437,0.043,,0.277637,547.493,,27.7637,0.547493,,,,7.85398e-5
Test1,3-Compress,134.280,1.126,0.448,0.050,,0.284625,636.62,,28.4625,0.63662,,,,7.85398e-5
Test1,3-Compress,134.613,1.115,0.459,0.036,,0.291614,458.366,,29.1614,0.458366,,,,7.85398e-5
Test1,3-Compress,134.947,1.105,0.469,0.050,,0.297967,636.62,,29.7967,0.63662,,,,7.85398e-5
Test1,3-Compress,135.280,1.094,0.48,0.050,,0.304956,636.62,,30.4956,0.63662,,,,7.85398e-5
Test1,3-Compress,135.613,1.084,0.49,0.050,,0.311309,636.62,,31.1309,0.63662,,,,7.85398e-5
Test1,3-Compress,135.947,1.073,0.501,0.050,,0.318297,636.62,,31.8297,0.63662,,,,7.85398e-5
Test1,3-Compress,136.280,1.063,0.511,0.050,,0.324651,636.62,,32.4651,0.63662,,,,7.85398e-5
Test1,3-Compress,136.613,1.053,0.521,0.050,,0.331004,636.62,,33.1004,0.63662,,,,7.85398e-5
Test1,3-Compress,136.947,1.042,0.532,0.050,,0.337992,636.62,,33.7992,0.63662,,,,7.85398e-5
Test1,3-Compress,137.280,1.032,0.542,0.050,,0.344346,636.62,,34.4346,0.63662,,,,7.85398e-5
Test1,3-Compress,137.613,1.021,0.553,0.050,,0.351334,636.62,,35.1334,0.63662,,,,7.85398e-5
Test1,3-Compress,137.947,1.01,0.564,0.050,,0.358323,636.62,,35.8323,0.63662,,,,7.85398e-5
Test1,3-Compress,138.280,1,0.574,0.050,,0.364676,636.62,,36.4676,0.63662,,,,7.85398e-5
Test1,3-Compress,138.613,0.989,0.585,0.050,,0.371665,636.62,,37.1665,0.63662,,,,7.85398e-5
Test1,3-Compress,138.947,0.979,0.595,0.050,,0.378018,636.62,,37.8018,0.63662,,,,7.85398e-5
Test1,3-Compress,139.280,0.968,0.606,0.050,,0.385006,636.62,,38.5006,0.63662,,,,7.85398e-5
Test1,3-Compress,139.613,0.958,0.616,0.050,,0.39136,636.62,,39.136,0.63662,,,,7.85398e-5
Test1,3-Compress,139.947,0.947,0.627,0.050,,0.398348,636.62,,39.8348,0.63662,,,,7.85398e-5
Test1,3-Compress,140.280,0.937,0.637,0.050,,0.404701,636.62,,40.4701,0.63662,,,,7.85398e-5
Test1,3-Compress,140.613,0.927,0.647,0.050,,0.411055,636.62,,41.1055,0.63662,,,,7.85398e-5
Test1,3-Compress,140.947,0.916,0.658,0.050,,0.418043,636.62,,41.8043,0.63662,,,,7.85398e-5
Test1,3-Compress,141.280,0.906,0.668,0.050,,0.424396,636.62,,42.4396,0.63662,,,,7.85398e-5
Test1,3-Compress,141.613,0.895,0.679,0.050,,0.431385,636.62,,43.1385,0.63662,,,,7.85398e-5
Test1,3-Compress,141.947,0.884,0.69,0.050,,0.438374,636.62,,43.8374,0.63662,,,,7.85398e-5
Test1,3-Compress,142.280,0.874,0.7,0.050,,0.444727,636.62,,44.4727,0.63662,,,,7.85398e-5
Test1,3-Compress,142.613,0.863,0.711,0.050,,0.451715,636.62,,45.1715,0.63662,,,,7.85398e-5
Test1,3-Compress,142.947,0.853,0.721,0.056,,0.458069,713.014,,45.8069,0.713014,,,,7.85398e-5
Test1,3-Compress,143.280,0.842,0.732,0.050,,0.465057,636.62,,46.5057,0.63662,,,,7.85398e-5
Test1,3-Compress,143.613,0.832,0.742,0.050,,0.47141,636.62,,47.141,0.63662,,,,7.85398e-5
Test1,3-Compress,143.947,0.821,0.753,0.050,,0.478399,636.62,,47.8399,0.63662,,,,7.85398e-5
Test1,3-Compress,144.280,0.811,0.763,0.050,,0.484752,636.62,,48.4752,0.63662,,,,7.85398e-5
Test1,3-Compress,144.613,0.801,0.773,0.050,,0.491105,636.62,,49.1105,0.63662,,,,7.85398e-5
Test1,3-Compress,144.947,0.79,0.784,0.050,,0.498094,636.62,,49.8094,0.63662,,,,7.85398e-5
Test1,3-Compress,145.280,0.779,0.795,0.070,,0.505083,891.268,,50.5083,0.891268,,,,7.85398e-5
Test1,3-Compress,145.613,0.769,0.805,0.056,,0.511436,713.014,,51.1436,0.713014,,,,7.85398e-5
Test1,3-Compress,145.947,0.758,0.816,0.077,,0.518424,980.395,,51.8424,0.980395,,,,7.85398e-5
Test1,3-Compress,146.280,0.748,0.826,0.070,,0.524778,891.268,,52.4778,0.891268,,,,7.85398e-5
Test1,3-Compress,146.613,0.737,0.837,0.077,,0.531766,980.395,,53.1766,0.980395,,,,7.85398e-5
Test1,3-Compress,146.947,0.727,0.847,0.083,,0.538119,1056.79,,53.8119,1.05679,,,,7.85398e-5
Test1,3-Compress,147.280,0.716,0.858,0.077,,0.545108,980.395,,54.5108,0.980395,,,,7.85398e-5
Test1,3-Compress,147.613,0.706,0.868,0.083,,0.551461,1056.79,,55.1461,1.05679,,,,7.85398e-5
Test1,3-Compress,147.947,0.695,0.879,0.083,,0.55845,1056.79,,55.845,1.05679,,,,7.85398e-5
Test1,3-Compress,148.280,0.685,0.889,0.090,,0.564803,1145.92,,56.4803,1.14592,,,,7.85398e-5
Test1,3-Compress,148.613,0.675,0.899,0.077,,0.571156,980.395,,57.1156,0.980395,,,,7.85398e-5
Test1,3-Compress,148.947,0.664,0.91,0.097,,0.578145,1235.04,,57.8145,1.23504,,,,7.85398e-5
Test1,3-Compress,149.280,0.653,0.921,0.090,,0.585133,1145.92,,58.5133,1.14592,,,,7.85398e-5
Test1,3-Compress,149.613,0.643,0.931,0.090,,0.591487,1145.92,,59.1487,1.14592,,,,7.85398e-5
Test1,3-Compress,149.947,0.632,0.942,0.090,,0.598475,1145.92,,59.8475,1.14592,,,,7.85398e-5
Test1,3-Recover,150.267,0.636,0.938,0.104,,0.595934,1324.17,,59.5934,1.32417,,,,7.85398e-5
Test1,3-Recover,150.600,0.646,0.928,0.083,,0.589581,1056.79,,58.9581,1.05679,,,,7.85398e-5
Test1,3-Recover,150.933,0.656,0.918,0.077,,0.583227,980.395,,58.3227,0.980395,,,,7.85398e-5
Test1,3-Recover,151.267,0.667,0.907,0.083,,0.576239,1056.79,,57.6239,1.05679,,,,7.85398e-5
Test1,3-Recover,151.600,0.677,0.897,0.070,,0.569886,891.268,,56.9886,0.891268,,,,7.85398e-5
Test1,3-Recover,151.933,0.688,0.886,0.056,,0.562897,713.014,,56.2897,0.713014,,,,7.85398e-5
Test1,3-Recover,152.267,0.699,0.875,0.056,,0.555909,713.014,,55.5909,0.713014,,,,7.85398e-5
Test1,3-Recover,152.600,0.709,0.865,0.050,,0.549555,636.62,,54.9555,0.63662,,,,7.85398e-5
Test1,3-Recover,152.933,0.719,0.855,0.050,,0.543202,636.62,,54.3202,0.63662,,,,7.85398e-5
Test1,3-Recover,153.267,0.73,0.844,0.056,,0.536213,713.014,,53.6213,0.713014,,,,7.85398e-5
Test1,3-Recover,153.600,0.741,0.833,0.050,,0.529225,636.62,,52.9225,0.63662,,,,7.85398e-5
Test1,3-Recover,153.933,0.751,0.823,0.056,,0.522872,713.014,,52.2872,0.713014,,,,7.85398e-5
Test1,3-Recover,154.267,0.762,0.812,0.050,,0.515883,636.62,,51.5883,0.63662,,,,7.85398e-5
Test1,3-Recover,154.600,0.772,0.802,0.070,,0.50953,891.268,,50.953,0.891268,,,,7.85398e-5
Test1,3-Recover,154.933,0.782,0.792,0.063,,0.503177,802.141,,50.3177,0.802141,,,,7.85398e-5
Test1,3-Recover,155.267,0.793,0.781,0.050,,0.496188,636.62,,49.6188,0.63662,,,,7.85398e-5
Test1,3-Recover,155.600,0.804,0.77,0.050,,0.489199,636.62,,48.9199,0.63662,,,,7.85398e-5
Test1,3-Recover,155.933,0.814,0.76,0.050,,0.482846,636.62,,48.2846,0.63662,,,,7.85398e-5
Test1,3-Recover,156.267,0.825,0.749,0.050,,0.475858,636.62,,47.5858,0.63662,,,,7.85398e-5
Test1,3-Recover,156.600,0.835,0.739,0.050,,0.469504,636.62,,46.9504,0.63662,,,,7.85398e-5
Test1,3-Recover,156.933,0.845,0.729,0.050,,0.463151,636.62,,46.3151,0.63662,,,,7.85398e-5
Test1,3-Recover,157.267,0.856,0.718,0.050,,0.456163,636.62,,45.6163,0.63662,,,,7.85398e-5
Test1,3-Recover,157.600,0.867,0.707,0.050,,0.449174,636.62,,44.9174,0.63662,,,,7.85398e-5
Test1,3-Recover,157.933,0.877,0.697,0.050,,0.442821,636.62,,44.2821,0.63662,,,,7.85398e-5
Test1,3-Recover,158.267,0.888,0.686,0.050,,0.435832,636.62,,43.5832,0.63662,,,,7.85398e-5
Test1,3-Recover,158.600,0.898,0.676,0.050,,0.429479,636.62,,42.9479,0.63662,,,,7.85398e-5
Test1,3-Recover,158.933,0.908,0.666,0.050,,0.423126,636.62,,42.3126,0.63662,,,,7.85398e-5
Test1,3-Recover,159.267,0.919,0.655,0.050,,0.416137,636.62,,41.6137,0.63662,,,,7.85398e-5
Test1,3-Recover,159.600,0.93,0.644,0.050,,0.409149,636.62,,40.9149,0.63662,,,,7.85398e-5
Test1,3-Recover,159.933,0.94,0.634,0.050,,0.402795,636.62,,40.2795,0.63662,,,,7.85398e-5
Test1,3-Recover,160.267,0.951,0.623,0.050,,0.395807,636.62,,39.5807,0.63662,,,,7.85398e-5
Test1,3-Recover,160.600,0.961,0.613,0.050,,0.389454,636.62,,38.9454,0.63662,,,,7.85398e-5
Test1,3-Recover,160.933,0.972,0.602,0.043,,0.382465,547.493,,38.2465,0.547493,,,,7.85398e-5
Test1,3-Recover,161.267,0.982,0.592,0.036,,0.376112,458.366,,37.6112,0.458366,,,,7.85398e-5
Test1,3-Recover,161.600,0.993,0.581,0.043,,0.369123,547.493,,36.9123,0.547493,,,,7.85398e-5
Test1,3-Recover,161.933,1.003,0.571,0.050,,0.36277,636.62,,36.277,0.63662,,,,7.85398e-5
Test1,3-Recover,162.267,1.014,0.56,0.043,,0.355781,547.493,,35.5781,0.547493,,,,7.85398e-5
Test1,3-Recover,162.600,1.024,0.55,0.043,,0.349428,547.493,,34.9428,0.547493,,,,7.85398e-5
Test1,3-Recover,162.933,1.035,0.539,0.050,,0.34244,636.62,,34.244,0.63662,,,,7.85398e-5
Test1,3-Recover,163.267,1.045,0.529,0.029,,0.336086,369.24,,33.6086,0.36924,,,,7.85398e-5
Test1,3-Recover,163.600,1.056,0.518,0.036,,0.329098,458.366,,32.9098,0.458366,,,,7.85398e-5
Test1,3-Recover,163.933,1.066,0.508,0.050,,0.322745,636.62,,32.2745,0.63662,,,,7.85398e-5
Test1,3-Recover,164.267,1.077,0.497,0.043,,0.315756,547.493,,31.5756,0.547493,,,,7.85398e-5
Test1,3-Recover,164.600,1.087,0.487,0.050,,0.309403,636.62,,30.9403,0.63662,,,,7.85398e-5
Test1,3-Recover,164.933,1.098,0.476,0.022,,0.302414,280.113,,30.2414,0.280113,,,,7.85398e-5
Test1,3-Recover,165.267,1.108,0.466,0.029,,0.296061,369.24,,29.6061,0.36924,,,,7.85398e-5
Test1,3-Recover,165.600,1.119,0.455,0.022,,0.289072,280.113,,28.9072,0.280113,,,,7.85398e-5
Test1,3-Recover,165.933,1.129,0.445,0.016,,0.282719,203.718,,28.2719,0.203718,,,,7.85398e-5
Test1,3-Recover,166.267,1.14,0.434,0.009,,0.275731,114.592,,27.5731,0.114592,,,,7.85398e-5
Test1,3-Recover,166.600,1.15,0.424,0.002,,0.269377,25.4648,,26.9377,0.0254648,,,,7.85398e-5
Test1,3-Recover,166.933,1.161,0.413,0.002,,0.262389,25.4648,,26.2389,0.0254648,,,,7.85398e-5
Test1,3-Recover,167.267,1.172,0.402,0.002,,0.2554,25.4648,,25.54,0.0254648,,,,7.85398e-5
Test1,3-Recover,167.600,1.182,0.392,0.002,,0.249047,25.4648,,24.9047,0.0254648,,,,7.85398e-5
Test1,3-Recover,167.933,1.192,0.382,0.002,,0.242694,25.4648,,24.2694,0.0254648,,,,7.85398e-5
Test1,3-Recover,168.267,1.203,0.371,0.002,,0.235705,25.4648,,23.5705,0.0254648,,,,7.85398e-5
Test1,3-Recover,168.600,1.213,0.361,0.009,,0.229352,114.592,,22.9352,0.114592,,,,7.85398e-5
Test1,3-Recover,168.933,1.224,0.35,0.009,,0.222363,114.592,,22.2363,0.114592,,,,7.85398e-5
Test1,3-Recover,169.267,1.235,0.339,0.009,,0.215375,114.592,,21.5375,0.114592,,,,7.85398e-5
Test1,3-Recover,169.600,1.245,0.329,0.016,,0.209022,203.718,,20.9022,0.203718,,,,7.85398e-5
Test1,3-Recover,169.933,1.255,0.319,0.002,,0.202668,25.4648,,20.2668,0.0254648,,,,7.85398e-5
Test1,3-Recover,170.267,1.266,0.308,0.016,,0.19568,203.718,,19.568,0.203718,,,,7.85398e-5
Test1,3-Recover,170.600,1.276,0.298,0.016,,0.189327,203.718,,18.9327,0.203718,,,,7.85398e-5
Test1,3-Recover,170.933,1.287,0.287,0.002,,0.182338,25.4648,,18.2338,0.0254648,,,,7.85398e-5
Test1,3-Recover,171.267,1.298,0.276,0.002,,0.175349,25.4648,,17.5349,0.0254648,,,,7.85398e-5
Test1,3-Recover,171.600,1.308,0.266,0.009,,0.168996,114.592,,16.8996,0.114592,,,,7.85398e-5
Test1,3-Recover,171.933,1.318,0.256,0.002,,0.162643,25.4648,,16.2643,0.0254648,,,,7.85398e-5
Test1,3-Recover,172.267,1.329,0.245,0.002,,0.155654,25.4648,,15.5654,0.0254648,,,,7.85398e-5
Test1,3-Recover,172.600,1.339,0.235,-0.005,,0.149301,-63.662,,14.9301,-0.063662,,,,7.85398e-5
Test1,3-Recover,172.933,1.35,0.224,0.002,,0.142313,25.4648,,14.2313,0.0254648,,,,7.85398e-5
Test1,3-Recover,173.267,1.361,0.213,-0.005,,0.135324,-63.662,,13.5324,-0.063662,,,,7.85398e-5
Test1,3-Recover,173.600,1.371,0.203,-0.005,,0.128971,-63.662,,12.8971,-0.063662,,,,7.85398e-5
Test1,3-Recover,173.933,1.381,0.193,-0.005,,0.122618,-63.662,,12.2618,-0.063662,,,,7.85398e-5
Test1,3-Recover,174.267,1.392,0.182,-0.005,,0.115629,-63.662,,11.5629,-0.063662,,,,7.85398e-5
Test1,3-Recover,174.600,1.403,0.171,-0.005,,0.10864,-63.662,,10.864,-0.063662,,,,7.85398e-5
Test1,3-Recover,174.933,1.413,0.161,-0.005,,0.102287,-63.662,,10.2287,-0.063662,,,,7.85398e-5
Test1,3-Recover,175.267,1.424,0.15,0.002,,0.0952986,25.4648,,9.52986,0.0254648,,,,7.85398e-5
Test1,3-Recover,175.600,1.434,0.14,0.002,,0.0889454,25.4648,,8.89454,0.0254648,,,,7.85398e-5
Test1,3-Recover,175.933,1.444,0.13,0.002,,0.0825921,25.4648,,8.25921,0.0254648,,,,7.85398e-5
Test1,3-Recover,176.267,1.455,0.119,0.002,,0.0756036,25.4648,,7.56036,0.0254648,,,,7.85398e-5
Test1,3-Recover,176.600,1.466,0.108,0.002,,0.068615,25.4648,,6.8615,0.0254648,,,,7.85398e-5
Test1,3-Recover,176.933,1.476,0.098,0.002,,0.0622618,25.4648,,6.22618,0.0254648,,,,7.85398e-5
Test1,3-Recover,177.267,1.487,0.087,0.009,,0.0552732,114.592,,5.52732,0.114592,,,,7.85398e-5
Test1,3-Recover,177.600,1.497,0.077,0.009,,0.0489199,114.592,,4.89199,0.114592,,,,7.85398e-5
Test1,3-Recover,177.933,1.507,0.067,0.009,,0.0425667,114.592,,4.25667,0.114592,,,,7.85398e-5
Test1,3-Recover,178.267,1.518,0.056,0.002,,0.0355781,25.4648,,3.55781,0.0254648,,,,7.85398e-5
Test1,3-Recover,178.600,1.529,0.045,0.002,,0.0285896,25.4648,,2.85896,0.0254648,,,,7.85398e-5
Test1,3-Recover,178.933,1.539,0.035,0.002,,0.0222363,25.4648,,2.22363,0.0254648,,,,7.85398e-5
Test1,3-Recover,179.267,1.55,0.024,-0.005,,0.0152478,-63.662,,1.52478,-0.063662,,,,7.85398e-5
Test1,3-Recover,179.600,1.56,0.014,-0.005,,0.00889454,-63.662,,0.889454,-0.063662,,,,7.85398e-5
Test1,3-Recover,179.933,1.57,0.004,-0.005,,0.0025413,-63.662,,0.25413,-0.063662,,,,7.85398e-5
Test1,3-Recover,180.100,1.574,-0,0.002,,0,25.4648,,0,0.0254648,,,,7.85398e-5